Workbook

Sheet Assumptions
A1: ROUND TERMS — KNOBS
A2: Series F pre-money | B2: 1400000000 | C2: USD | D2: Series F pre-money valuation
A3: Series F primary raise | B3: 30000000 | C3: USD | D3: New Series F primary capital
A4: Series F secondary raise | B4: 15000000 | C4: USD | D4: Secondary tender from founders
A5: Tender PPS multiplier | B5: 0.85 | C5: fraction | D5: Tender PPS = mult x F_PPS
A6: ESOP refresh target % (post-F FD) | B6: 0.13 | C6: fraction | D6: Post-F option pool as fraction of post-F FD
A7: Our fund check | B7: 10000000 | C7: USD | D7: 1/3 of primary
A8: F_LEAD primary check | B8: 20000000 | C8: USD | D8: 2/3 of primary
A9: Option strike | B9: 1 | C9: USD | D9: Option exercise price
A10: EXIT SCENARIOS
A11: Exit 1 | B11: 700000000 | C11: USD
A12: Exit 2 | B12: 1200000000 | C12: USD
A13: Exit 3 (sensitivity) | B13: 2000000000 | C13: USD
A14: Exit 4 | B14: 4000000000 | C14: USD
A15: Exit 5 | B15: 8000000000 | C15: USD
A16: PRIOR-ROUND OCPs (for AD)
A17: Seed OCP | B17: 1 | C17: USD/share
A18: A OCP | B18: 3 | C18: USD/share
A19: B OCP | B19: 10 | C19: USD/share
A20: C OCP | B20: 25 | C20: USD/share
A21: D OCP (post-E NCP) | B21: 58.118347 | C21: USD/share | D21: D's effective OCP for F's AD = post-E NCP $58.118347
A22: D original OCP | B22: 60 | C22: USD/share | D22: D original $60 — used for compound v3·v4 ratio
A23: E OCP | B23: 49.158311 | C23: USD/share
A24: PRIOR-ROUND ORIGINAL INVESTMENTS
A25: Seed invested | B25: 5000000 | C25: USD
A26: A invested | B26: 15000000 | C26: USD
A27: B invested | B27: 30000000 | C27: USD
A28: C invested | B28: 60000000 | C28: USD
A29: D invested | B29: 100000000 | C29: USD
A30: E invested | B30: 300000000 | C30: USD
A31: PRIOR-ROUND SHARE COUNTS (pre-F)
A32: Seed shares | B32: 5000000 | C32: shares
A33: A shares | B33: 5000000 | C33: shares
A34: B shares | B34: 3000000 | C34: shares
A35: C shares | B35: 2400000 | C35: shares
A36: D original shares | B36: 1666667 | C36: shares | D36: Issued at $60
A37: D post-E shares | B37: 1720627 | C37: shares | D37: Reflects E-round AD (v3)
A38: E shares | B38: 6102667 | C38: shares | D38: 10x 610,267 + 1x 610,264
A39: FOUNDERS / RSAs / OPTIONS
A40: Founder F1 (CEO) common | B40: 4000000 | C40: shares | D40: 50% of founders
...

Sheet Pro-Forma
A1: POST-F CAP TABLE
A2: Stakeholder | B2: Common (post-tender) | C2: Preferred class | D2: Preferred shares | E2: As-converted | F2: % of post-F FD | G2: Notes
A3: F1 (CEO) | B3: =Assumptions!$B$40-Assumptions!$B$48*Assumptions!$B$90 | E3: =B3 | F3: =E3/Assumptions!$B$74 | G3: pro-rata of tender to F_LEAD
A4: F2 (CTO) | B4: =Assumptions!$B$41-Assumptions!$B$49*Assumptions!$B$90 | E4: =B4 | F4: =E4/Assumptions!$B$74
A5: F3 (CSO) | B5: =Assumptions!$B$42-Assumptions!$B$50*Assumptions!$B$90 | E5: =B5 | F5: =E5/Assumptions!$B$74
A6: RSAs (employees) | B6: =Assumptions!$B$43 | E6: =B6 | F6: =E6/Assumptions!$B$74
A7: Seed preferred | C7: Seed | D7: =Assumptions!$B$32 | E7: =D7 | F7: =E7/Assumptions!$B$74 | G7: Seed AD dormant
A8: Series A preferred | C8: A | D8: =Assumptions!$B$33 | E8: =D8 | F8: =E8/Assumptions!$B$74 | G8: A AD dormant
A9: Series B preferred | C9: B | D9: =Assumptions!$B$34 | E9: =D9 | F9: =E9/Assumptions!$B$74 | G9: B AD dormant
A10: Series C preferred | C10: C | D10: =Assumptions!$B$35 | E10: =D10 | F10: =E10/Assumptions!$B$74 | G10: C AD dormant
A11: Series D preferred | C11: D | D11: =Assumptions!$B$77 | E11: =D11 | F11: =E11/Assumptions!$B$74 | G11: D AD triggered: see AD block
A12: Series E preferred | C12: E | D12: =Assumptions!$B$79 | E12: =D12 | F12: =E12/Assumptions!$B$74 | G12: E AD triggered: see AD block
A13: F_LEAD Series F primary | C13: F | D13: =Assumptions!$B$8/Assumptions!$B$72 | E13: =D13 | F13: =E13/Assumptions!$B$74 | G13: $20M / F_PPS
A14: F_LEAD secondary common | B14: =Assumptions!$B$90 | E14: =B14 | F14: =E14/Assumptions!$B$74 | G14: $15M / tender_pps
A15: Our fund Series F primary | C15: F | D15: =Assumptions!$B$7/Assumptions!$B$72 | E15: =D15 | F15: =E15/Assumptions!$B$74 | G15: $10M / F_PPS
A16: Note A converted (NA1) | B16: =Assumptions!$B$83 | E16: =B16 | F16: =E16/Assumptions!$B$74 | G16: common-equiv
A17: Note B converted (NB1) | B17: =Assumptions!$B$87 | E17: =B17 | F17: =E17/Assumptions!$B$74 | G17: common-equiv
A18: Issued options | B18: =Assumptions!$B$44 | E18: =B18 | F18: =E18/Assumptions!$B$74
A19: Unissued options (incl ESOP top-up) | B19: =Assumptions!$B$45+Assumptions!$B$75 | E19: =B19 | F19: =E19/Assumptions!$B$74 | G19: pre-existing + topup
A20: Total post-F FD | E20: =SUM(E3:E19) | F20: =E20/Assumptions!$B$74
A22: ANTI-DILUTION BLOCK (Broad-Based WA)
A23: Class | B23: OCP for AD | C23: F_PPS | D23: Trigger (F_PPS<OCP) | E23: New CP | F23: New ratio | G23: As-converted shares | H23: Notes
A24: Seed | B24: =Assumptions!$B$17 | C24: =Assumptions!$B$72 | D24: =IF(Assumptions!$B$72<Assumptions!$B$17,"TRIGGERED","dormant") | E24: n/a (dormant) | F24: 1 | G24: =Assumptions!$B$32 | H24: F_PPS > OCP — dormant
A25: A | B25: =Assumptions!$B$18 | C25: =Assumptions!$B$72 | D25: =IF(Assumptions!$B$72<Assumptions!$B$18,"TRIGGERED","dormant") | E25: n/a (dormant) | F25: 1 | G25: =Assumptions!$B$33 | H25: dormant
A26: B | B26: =Assumptions!$B$19 | C26: =Assumptions!$B$72 | D26: =IF(Assumptions!$B$72<Assumptions!$B$19,"TRIGGERED","dormant") | E26: n/a (dormant) | F26: 1 | G26: =Assumptions!$B$34 | H26: dormant
A27: C | B27: =Assumptions!$B$20 | C27: =Assumptions!$B$72 | D27: =IF(Assumptions!$B$72<Assumptions!$B$20,"TRIGGERED","dormant") | E27: n/a (dormant) | F27: 1 | G27: =Assumptions!$B$35 | H27: dormant
A28: D | B28: =Assumptions!$B$21 | C28: =Assumptions!$B$72 | D28: =IF(Assumptions!$B$72<Assumptions!$B$21,"TRIGGERED","dormant") | E28: =Assumptions!$B$21*(Assumptions!$B$59+Assumptions!$B$60/Assumptions!$B$21)/(Assumptions!$B$59+Assumptions!$B$60/Assumptions!$B$72) | F28: =Assumptions!$B$22/(Assumptions!$B$21*(Assumptions!$B$59+Assumptions!$B$60/Assumptions!$B$21)/(Assumptions!$B$59+Assumptions!$B$60/Assumptions!$B$72)) | G28: =Assumptions!$B$36*Assumptions!$B$22/(Assumptions!$B$21*(Assumptions!$B$59+Assumptions!$B$60/Assumptions!$B$21)/(Assumptions!$B$59+Assumptions!$B$60/Assumptions!$B$72)) | H28: compound v3·v4 vs $60 OCP
A29: E | B29: =Assumptions!$B$23 | C29: =Assumptions!$B$72 | D29: =IF(Assumptions!$B$72<Assumptions!$B$23,"TRIGGERED","dormant") | E29: =Assumptions!$B$23*(Assumptions!$B$59+Assumptions!$B$60/Assumptions!$B$23)/(Assumptions!$B$59+Assumptions!$B$60/Assumptions!$B$72) | F29: =Assumptions!$B$23/(Assumptions!$B$23*(Assumptions!$B$59+Assumptions!$B$60/Assumptions!$B$23)/(Assumptions!$B$59+Assumptions!$B$60/Assumptions!$B$72)) | G29: =Assumptions!$B$38*Assumptions!$B$23/(Assumptions!$B$23*(Assumptions!$B$59+Assumptions!$B$60/Assumptions!$B$23)/(Assumptions!$B$59+Assumptions!$B$60/Assumptions!$B$72)) | H29: broad-based WA
A31: NOTES CONVERSION BLOCK
A32: Note | B32: Cap-implied PPS | C32: Discount-implied PPS | D32: Conv PPS | E32: Branch | F32: Shares issued | G32: FD-at-conv | H32: Notes
A33: Note A | B33: =Assumptions!$B$53/(Assumptions!$B$47+Assumptions!$B$75+Assumptions!$B$87) | C33: =Assumptions!$B$72*(1-Assumptions!$B$54) | D33: =MIN(B33,C33) | E33: =IF(B33<C33,"cap","discount") | F33: =Assumptions!$B$52/D33 | G33: =(Assumptions!$B$47+Assumptions!$B$75+Assumptions!$B$87) | H33: FD = preF_FD + dESOP + Note B shares
A34: Note B | B34: =Assumptions!$B$56/(Assumptions!$B$47+Assumptions!$B$75+Assumptions!$B$83) | C34: =Assumptions!$B$72*(1-Assumptions!$B$57) | D34: =MIN(B34,C34) | E34: =IF(B34<C34,"cap","discount") | F34: =Assumptions!$B$55/D34 | G34: =(Assumptions!$B$47+Assumptions!$B$75+Assumptions!$B$83) | H34: FD = preF_FD + dESOP + Note A shares
A36: TENDER BLOCK
A37: Item | B37: Formula | C37: Value | D37: Notes
A38: Tender PPS | B38: =0.85 × F_PPS | C38: =Assumptions!$B$5*Assumptions!$B$72 | D38: no new shares — secondary
A39: Tender shares | B39: =$15M / tender PPS | C39: =Assumptions!$B$4/(Assumptions!$B$5*Assumptions!$B$72) | D39: shifted from founders to F_LEAD
A40: F1 share-out (50%) | C40: =Assumptions!$B$48*Assumptions!$B$4/(Assumptions!$B$5*Assumptions!$B$72)
A41: F2 share-out (31.25%) | C41: =Assumptions!$B$49*Assumptions!$B$4/(Assumptions!$B$5*Assumptions!$B$72)
A42: F3 share-out (18.75%) | C42: =Assumptions!$B$50*Assumptions!$B$4/(Assumptions!$B$5*Assumptions!$B$72)
A43: F_LEAD secondary holding | C43: =Assumptions!$B$4/(Assumptions!$B$5*Assumptions!$B$72) | D43: =tender shares (acquired from founders)
...

Sheet Waterfall
A1: WATERFALL — five exits, 1× non-participating with conversion election
A2: Class / Item | B2: =Assumptions!$B$11 | C2: =Assumptions!$B$12 | D2: =Assumptions!$B$13 | E2: =Assumptions!$B$14 | F2: =Assumptions!$B$15
A3: — Pref proceeds walked top-down (if class elects "preference") —
A4: — ELECTIONS (IF pref>=convert per equilibrium pool) —
A5: F election | B5: =IF(Assumptions!$B$3>=Assumptions!$B$88*Assumptions!$B$95,"preference","convert") | C5: =IF(Assumptions!$B$3>=Assumptions!$B$88*Assumptions!$B$99,"preference","convert") | D5: =IF(Assumptions!$B$3>=Assumptions!$B$88*Assumptions!$B$103,"preference","convert") | E5: =IF(Assumptions!$B$3>=Assumptions!$B$88*Assumptions!$B$107,"preference","convert") | F5: =IF(Assumptions!$B$3>=Assumptions!$B$88*Assumptions!$B$111,"preference","convert")
A6: E election | B6: =IF(Assumptions!$B$30>=Assumptions!$B$79*Assumptions!$B$95,"preference","convert") | C6: =IF(Assumptions!$B$30>=Assumptions!$B$79*Assumptions!$B$99,"preference","convert") | D6: =IF(Assumptions!$B$30>=Assumptions!$B$79*Assumptions!$B$103,"preference","convert") | E6: =IF(Assumptions!$B$30>=Assumptions!$B$79*Assumptions!$B$107,"preference","convert") | F6: =IF(Assumptions!$B$30>=Assumptions!$B$79*Assumptions!$B$111,"preference","convert")
A7: D election | B7: =IF(Assumptions!$B$29>=Assumptions!$B$77*Assumptions!$B$95,"preference","convert") | C7: =IF(Assumptions!$B$29>=Assumptions!$B$77*Assumptions!$B$99,"preference","convert") | D7: =IF(Assumptions!$B$29>=Assumptions!$B$77*Assumptions!$B$103,"preference","convert") | E7: =IF(Assumptions!$B$29>=Assumptions!$B$77*Assumptions!$B$107,"preference","convert") | F7: =IF(Assumptions!$B$29>=Assumptions!$B$77*Assumptions!$B$111,"preference","convert")
A8: C election | B8: =IF(Assumptions!$B$28>=Assumptions!$B$35*Assumptions!$B$95,"preference","convert") | C8: =IF(Assumptions!$B$28>=Assumptions!$B$35*Assumptions!$B$99,"preference","convert") | D8: =IF(Assumptions!$B$28>=Assumptions!$B$35*Assumptions!$B$103,"preference","convert") | E8: =IF(Assumptions!$B$28>=Assumptions!$B$35*Assumptions!$B$107,"preference","convert") | F8: =IF(Assumptions!$B$28>=Assumptions!$B$35*Assumptions!$B$111,"preference","convert")
A9: B election | B9: =IF(Assumptions!$B$27>=Assumptions!$B$34*Assumptions!$B$95,"preference","convert") | C9: =IF(Assumptions!$B$27>=Assumptions!$B$34*Assumptions!$B$99,"preference","convert") | D9: =IF(Assumptions!$B$27>=Assumptions!$B$34*Assumptions!$B$103,"preference","convert") | E9: =IF(Assumptions!$B$27>=Assumptions!$B$34*Assumptions!$B$107,"preference","convert") | F9: =IF(Assumptions!$B$27>=Assumptions!$B$34*Assumptions!$B$111,"preference","convert")
A10: A election | B10: =IF(Assumptions!$B$26>=Assumptions!$B$33*Assumptions!$B$95,"preference","convert") | C10: =IF(Assumptions!$B$26>=Assumptions!$B$33*Assumptions!$B$99,"preference","convert") | D10: =IF(Assumptions!$B$26>=Assumptions!$B$33*Assumptions!$B$103,"preference","convert") | E10: =IF(Assumptions!$B$26>=Assumptions!$B$33*Assumptions!$B$107,"preference","convert") | F10: =IF(Assumptions!$B$26>=Assumptions!$B$33*Assumptions!$B$111,"preference","convert")
A11: Seed election | B11: =IF(Assumptions!$B$25>=Assumptions!$B$32*Assumptions!$B$95,"preference","convert") | C11: =IF(Assumptions!$B$25>=Assumptions!$B$32*Assumptions!$B$99,"preference","convert") | D11: =IF(Assumptions!$B$25>=Assumptions!$B$32*Assumptions!$B$103,"preference","convert") | E11: =IF(Assumptions!$B$25>=Assumptions!$B$32*Assumptions!$B$107,"preference","convert") | F11: =IF(Assumptions!$B$25>=Assumptions!$B$32*Assumptions!$B$111,"preference","convert")
A13: — PREF PROCEEDS WALK (top-down, only if elects pref) —
A14: F pref paid | B14: =IF(B5="preference",MIN(Assumptions!$B$3,MAX(0,Assumptions!$B$11)),0) | C14: =IF(C5="preference",MIN(Assumptions!$B$3,MAX(0,Assumptions!$B$12)),0) | D14: =IF(D5="preference",MIN(Assumptions!$B$3,MAX(0,Assumptions!$B$13)),0) | E14: =IF(E5="preference",MIN(Assumptions!$B$3,MAX(0,Assumptions!$B$14)),0) | F14: =IF(F5="preference",MIN(Assumptions!$B$3,MAX(0,Assumptions!$B$15)),0)
A15: E pref paid | B15: =IF(B6="preference",MIN(Assumptions!$B$30,MAX(0,(Assumptions!$B$11-B14))),0) | C15: =IF(C6="preference",MIN(Assumptions!$B$30,MAX(0,(Assumptions!$B$12-C14))),0) | D15: =IF(D6="preference",MIN(Assumptions!$B$30,MAX(0,(Assumptions!$B$13-D14))),0) | E15: =IF(E6="preference",MIN(Assumptions!$B$30,MAX(0,(Assumptions!$B$14-E14))),0) | F15: =IF(F6="preference",MIN(Assumptions!$B$30,MAX(0,(Assumptions!$B$15-F14))),0)
A16: D pref paid | B16: =IF(B7="preference",MIN(Assumptions!$B$29,MAX(0,((Assumptions!$B$11-B14)-B15))),0) | C16: =IF(C7="preference",MIN(Assumptions!$B$29,MAX(0,((Assumptions!$B$12-C14)-C15))),0) | D16: =IF(D7="preference",MIN(Assumptions!$B$29,MAX(0,((Assumptions!$B$13-D14)-D15))),0) | E16: =IF(E7="preference",MIN(Assumptions!$B$29,MAX(0,((Assumptions!$B$14-E14)-E15))),0) | F16: =IF(F7="preference",MIN(Assumptions!$B$29,MAX(0,((Assumptions!$B$15-F14)-F15))),0)
A17: C pref paid | B17: =IF(B8="preference",MIN(Assumptions!$B$28,MAX(0,(((Assumptions!$B$11-B14)-B15)-B16))),0) | C17: =IF(C8="preference",MIN(Assumptions!$B$28,MAX(0,(((Assumptions!$B$12-C14)-C15)-C16))),0) | D17: =IF(D8="preference",MIN(Assumptions!$B$28,MAX(0,(((Assumptions!$B$13-D14)-D15)-D16))),0) | E17: =IF(E8="preference",MIN(Assumptions!$B$28,MAX(0,(((Assumptions!$B$14-E14)-E15)-E16))),0) | F17: =IF(F8="preference",MIN(Assumptions!$B$28,MAX(0,(((Assumptions!$B$15-F14)-F15)-F16))),0)
A18: B pref paid | B18: =IF(B9="preference",MIN(Assumptions!$B$27,MAX(0,((((Assumptions!$B$11-B14)-B15)-B16)-B17))),0) | C18: =IF(C9="preference",MIN(Assumptions!$B$27,MAX(0,((((Assumptions!$B$12-C14)-C15)-C16)-C17))),0) | D18: =IF(D9="preference",MIN(Assumptions!$B$27,MAX(0,((((Assumptions!$B$13-D14)-D15)-D16)-D17))),0) | E18: =IF(E9="preference",MIN(Assumptions!$B$27,MAX(0,((((Assumptions!$B$14-E14)-E15)-E16)-E17))),0) | F18: =IF(F9="preference",MIN(Assumptions!$B$27,MAX(0,((((Assumptions!$B$15-F14)-F15)-F16)-F17))),0)
A19: A pref paid | B19: =IF(B10="preference",MIN(Assumptions!$B$26,MAX(0,(((((Assumptions!$B$11-B14)-B15)-B16)-B17)-B18))),0) | C19: =IF(C10="preference",MIN(Assumptions!$B$26,MAX(0,(((((Assumptions!$B$12-C14)-C15)-C16)-C17)-C18))),0) | D19: =IF(D10="preference",MIN(Assumptions!$B$26,MAX(0,(((((Assumptions!$B$13-D14)-D15)-D16)-D17)-D18))),0) | E19: =IF(E10="preference",MIN(Assumptions!$B$26,MAX(0,(((((Assumptions!$B$14-E14)-E15)-E16)-E17)-E18))),0) | F19: =IF(F10="preference",MIN(Assumptions!$B$26,MAX(0,(((((Assumptions!$B$15-F14)-F15)-F16)-F17)-F18))),0)
A20: Seed pref paid | B20: =IF(B11="preference",MIN(Assumptions!$B$25,MAX(0,((((((Assumptions!$B$11-B14)-B15)-B16)-B17)-B18)-B19))),0) | C20: =IF(C11="preference",MIN(Assumptions!$B$25,MAX(0,((((((Assumptions!$B$12-C14)-C15)-C16)-C17)-C18)-C19))),0) | D20: =IF(D11="preference",MIN(Assumptions!$B$25,MAX(0,((((((Assumptions!$B$13-D14)-D15)-D16)-D17)-D18)-D19))),0) | E20: =IF(E11="preference",MIN(Assumptions!$B$25,MAX(0,((((((Assumptions!$B$14-E14)-E15)-E16)-E17)-E18)-E19))),0) | F20: =IF(F11="preference",MIN(Assumptions!$B$25,MAX(0,((((((Assumptions!$B$15-F14)-F15)-F16)-F17)-F18)-F19))),0)
A21: Remaining after all prefs | B21: =MAX(0,(((((((Assumptions!$B$11-B14)-B15)-B16)-B17)-B18)-B19)-B20)) | C21: =MAX(0,(((((((Assumptions!$B$12-C14)-C15)-C16)-C17)-C18)-C19)-C20)) | D21: =MAX(0,(((((((Assumptions!$B$13-D14)-D15)-D16)-D17)-D18)-D19)-D20)) | E21: =MAX(0,(((((((Assumptions!$B$14-E14)-E15)-E16)-E17)-E18)-E19)-E20)) | F21: =MAX(0,(((((((Assumptions!$B$15-F14)-F15)-F16)-F17)-F18)-F19)-F20))
A23: — CONVERT POOL —
A24: Common + RSAs (always in pool) | B24: =Assumptions!$B$40+Assumptions!$B$41+Assumptions!$B$42+Assumptions!$B$43 | C24: =Assumptions!$B$40+Assumptions!$B$41+Assumptions!$B$42+Assumptions!$B$43 | D24: =Assumptions!$B$40+Assumptions!$B$41+Assumptions!$B$42+Assumptions!$B$43 | E24: =Assumptions!$B$40+Assumptions!$B$41+Assumptions!$B$42+Assumptions!$B$43 | F24: =Assumptions!$B$40+Assumptions!$B$41+Assumptions!$B$42+Assumptions!$B$43
A25: Notes A+B (always in pool) | B25: =Assumptions!$B$83+Assumptions!$B$87 | C25: =Assumptions!$B$83+Assumptions!$B$87 | D25: =Assumptions!$B$83+Assumptions!$B$87 | E25: =Assumptions!$B$83+Assumptions!$B$87 | F25: =Assumptions!$B$83+Assumptions!$B$87
A26: F shares (if convert) | B26: =IF(B5="convert",Assumptions!$B$88,0) | C26: =IF(C5="convert",Assumptions!$B$88,0) | D26: =IF(D5="convert",Assumptions!$B$88,0) | E26: =IF(E5="convert",Assumptions!$B$88,0) | F26: =IF(F5="convert",Assumptions!$B$88,0)
A27: E shares (if convert) | B27: =IF(B6="convert",Assumptions!$B$79,0) | C27: =IF(C6="convert",Assumptions!$B$79,0) | D27: =IF(D6="convert",Assumptions!$B$79,0) | E27: =IF(E6="convert",Assumptions!$B$79,0) | F27: =IF(F6="convert",Assumptions!$B$79,0)
A28: D shares (if convert) | B28: =IF(B7="convert",Assumptions!$B$77,0) | C28: =IF(C7="convert",Assumptions!$B$77,0) | D28: =IF(D7="convert",Assumptions!$B$77,0) | E28: =IF(E7="convert",Assumptions!$B$77,0) | F28: =IF(F7="convert",Assumptions!$B$77,0)
A29: C shares (if convert) | B29: =IF(B8="convert",Assumptions!$B$35,0) | C29: =IF(C8="convert",Assumptions!$B$35,0) | D29: =IF(D8="convert",Assumptions!$B$35,0) | E29: =IF(E8="convert",Assumptions!$B$35,0) | F29: =IF(F8="convert",Assumptions!$B$35,0)
A30: B shares (if convert) | B30: =IF(B9="convert",Assumptions!$B$34,0) | C30: =IF(C9="convert",Assumptions!$B$34,0) | D30: =IF(D9="convert",Assumptions!$B$34,0) | E30: =IF(E9="convert",Assumptions!$B$34,0) | F30: =IF(F9="convert",Assumptions!$B$34,0)
A31: A shares (if convert) | B31: =IF(B10="convert",Assumptions!$B$33,0) | C31: =IF(C10="convert",Assumptions!$B$33,0) | D31: =IF(D10="convert",Assumptions!$B$33,0) | E31: =IF(E10="convert",Assumptions!$B$33,0) | F31: =IF(F10="convert",Assumptions!$B$33,0)
A32: Seed shares (if convert) | B32: =IF(B11="convert",Assumptions!$B$32,0) | C32: =IF(C11="convert",Assumptions!$B$32,0) | D32: =IF(D11="convert",Assumptions!$B$32,0) | E32: =IF(E11="convert",Assumptions!$B$32,0) | F32: =IF(F11="convert",Assumptions!$B$32,0)
A33: Convert pool (excl options) | B33: =SUM(B24:B32) | C33: =SUM(C24:C32) | D33: =SUM(D24:D32) | E33: =SUM(E24:E32) | F33: =SUM(F24:F32)
A34: Options ITM? (1=yes) | B34: =IF(B21/B33>Assumptions!$B$9,1,0) | C34: =IF(C21/C33>Assumptions!$B$9,1,0) | D34: =IF(D21/D33>Assumptions!$B$9,1,0) | E34: =IF(E21/E33>Assumptions!$B$9,1,0) | F34: =IF(F21/F33>Assumptions!$B$9,1,0)
A35: PPS at exit | B35: =IF(B34=1,(B21+Assumptions!$B$44*Assumptions!$B$9)/(B33+Assumptions!$B$44),B21/B33) | C35: =IF(C34=1,(C21+Assumptions!$B$44*Assumptions!$B$9)/(C33+Assumptions!$B$44),C21/C33) | D35: =IF(D34=1,(D21+Assumptions!$B$44*Assumptions!$B$9)/(D33+Assumptions!$B$44),D21/D33) | E35: =IF(E34=1,(E21+Assumptions!$B$44*Assumptions!$B$9)/(E33+Assumptions!$B$44),E21/E33) | F35: =IF(F34=1,(F21+Assumptions!$B$44*Assumptions!$B$9)/(F33+Assumptions!$B$44),F21/F33)
A37: — ACTUAL PROCEEDS BY CLASS / GROUP —
A38: F proceeds | B38: =IF(B5="preference",B14,Assumptions!$B$88*B35) | C38: =IF(C5="preference",C14,Assumptions!$B$88*C35) | D38: =IF(D5="preference",D14,Assumptions!$B$88*D35) | E38: =IF(E5="preference",E14,Assumptions!$B$88*E35) | F38: =IF(F5="preference",F14,Assumptions!$B$88*F35)
A39: E proceeds | B39: =IF(B6="preference",B15,Assumptions!$B$79*B35) | C39: =IF(C6="preference",C15,Assumptions!$B$79*C35) | D39: =IF(D6="preference",D15,Assumptions!$B$79*D35) | E39: =IF(E6="preference",E15,Assumptions!$B$79*E35) | F39: =IF(F6="preference",F15,Assumptions!$B$79*F35)
A40: D proceeds | B40: =IF(B7="preference",B16,Assumptions!$B$77*B35) | C40: =IF(C7="preference",C16,Assumptions!$B$77*C35) | D40: =IF(D7="preference",D16,Assumptions!$B$77*D35) | E40: =IF(E7="preference",E16,Assumptions!$B$77*E35) | F40: =IF(F7="preference",F16,Assumptions!$B$77*F35)
A41: C proceeds | B41: =IF(B8="preference",B17,Assumptions!$B$35*B35) | C41: =IF(C8="preference",C17,Assumptions!$B$35*C35) | D41: =IF(D8="preference",D17,Assumptions!$B$35*D35) | E41: =IF(E8="preference",E17,Assumptions!$B$35*E35) | F41: =IF(F8="preference",F17,Assumptions!$B$35*F35)
A42: B proceeds | B42: =IF(B9="preference",B18,Assumptions!$B$34*B35) | C42: =IF(C9="preference",C18,Assumptions!$B$34*C35) | D42: =IF(D9="preference",D18,Assumptions!$B$34*D35) | E42: =IF(E9="preference",E18,Assumptions!$B$34*E35) | F42: =IF(F9="preference",F18,Assumptions!$B$34*F35)
A43: A proceeds | B43: =IF(B10="preference",B19,Assumptions!$B$33*B35) | C43: =IF(C10="preference",C19,Assumptions!$B$33*C35) | D43: =IF(D10="preference",D19,Assumptions!$B$33*D35) | E43: =IF(E10="preference",E19,Assumptions!$B$33*E35) | F43: =IF(F10="preference",F19,Assumptions!$B$33*F35)
...

Sheet Sensitivity
A1: SENSITIVITY 3×3 — ESOP × Pre-money @ $2B exit
A2: Cell value: our $10M check post-F % of T_F / $ proceeds at $2B exit
A3: ESOP \ Pre-money | B3: =Assumptions!$B$65 | C3: =Assumptions!$B$66 | D3: =Assumptions!$B$67
A4: =Assumptions!$B$62 | B4: =TEXT((Assumptions!$B$7/Assumptions!$B$113)/Assumptions!$B$114,"0.0000%")&" / $"&TEXT(Assumptions!$B$115/3,"#,##0")&" (NA="&Assumptions!$B$116&", NB="&Assumptions!$B$117&") | C4: =TEXT((Assumptions!$B$7/Assumptions!$B$118)/Assumptions!$B$119,"0.0000%")&" / $"&TEXT(Assumptions!$B$120/3,"#,##0")&" (NA="&Assumptions!$B$121&", NB="&Assumptions!$B$122&") | D4: =TEXT((Assumptions!$B$7/Assumptions!$B$123)/Assumptions!$B$124,"0.0000%")&" / $"&TEXT(Assumptions!$B$125/3,"#,##0")&" (NA="&Assumptions!$B$126&", NB="&Assumptions!$B$127&")
A5: =Assumptions!$B$63 | B5: =TEXT((Assumptions!$B$7/Assumptions!$B$128)/Assumptions!$B$129,"0.0000%")&" / $"&TEXT(Assumptions!$B$130/3,"#,##0")&" (NA="&Assumptions!$B$131&", NB="&Assumptions!$B$132&") | C5: =TEXT((Assumptions!$B$7/Assumptions!$B$133)/Assumptions!$B$134,"0.0000%")&" / $"&TEXT(Assumptions!$B$135/3,"#,##0")&" (NA="&Assumptions!$B$136&", NB="&Assumptions!$B$137&") | D5: =TEXT((Assumptions!$B$7/Assumptions!$B$138)/Assumptions!$B$139,"0.0000%")&" / $"&TEXT(Assumptions!$B$140/3,"#,##0")&" (NA="&Assumptions!$B$141&", NB="&Assumptions!$B$142&")
A6: =Assumptions!$B$64 | B6: =TEXT((Assumptions!$B$7/Assumptions!$B$143)/Assumptions!$B$144,"0.0000%")&" / $"&TEXT(Assumptions!$B$145/3,"#,##0")&" (NA="&Assumptions!$B$146&", NB="&Assumptions!$B$147&") | C6: =TEXT((Assumptions!$B$7/Assumptions!$B$148)/Assumptions!$B$149,"0.0000%")&" / $"&TEXT(Assumptions!$B$150/3,"#,##0")&" (NA="&Assumptions!$B$151&", NB="&Assumptions!$B$152&") | D6: =TEXT((Assumptions!$B$7/Assumptions!$B$153)/Assumptions!$B$154,"0.0000%")&" / $"&TEXT(Assumptions!$B$155/3,"#,##0")&" (NA="&Assumptions!$B$156&", NB="&Assumptions!$B$157&")
A8: — DETAIL: per-cell post-F % and $ proceeds —
A9: esop | B9: pre | C9: F_PPS | D9: T_F | E9: our % | F9: F class proc @$2B | G9: our $ (1/3 of F class) | H9: NA branch | I9: NB branch
A10: =Assumptions!$B$62 | B10: =Assumptions!$B$65 | C10: =Assumptions!$B$113 | D10: =Assumptions!$B$114 | E10: =(Assumptions!$B$7/Assumptions!$B$113)/Assumptions!$B$114 | F10: =Assumptions!$B$115 | G10: =Assumptions!$B$115/3 | H10: =Assumptions!$B$116 | I10: =Assumptions!$B$117
A11: =Assumptions!$B$62 | B11: =Assumptions!$B$66 | C11: =Assumptions!$B$118 | D11: =Assumptions!$B$119 | E11: =(Assumptions!$B$7/Assumptions!$B$118)/Assumptions!$B$119 | F11: =Assumptions!$B$120 | G11: =Assumptions!$B$120/3 | H11: =Assumptions!$B$121 | I11: =Assumptions!$B$122
A12: =Assumptions!$B$62 | B12: =Assumptions!$B$67 | C12: =Assumptions!$B$123 | D12: =Assumptions!$B$124 | E12: =(Assumptions!$B$7/Assumptions!$B$123)/Assumptions!$B$124 | F12: =Assumptions!$B$125 | G12: =Assumptions!$B$125/3 | H12: =Assumptions!$B$126 | I12: =Assumptions!$B$127
A13: =Assumptions!$B$63 | B13: =Assumptions!$B$65 | C13: =Assumptions!$B$128 | D13: =Assumptions!$B$129 | E13: =(Assumptions!$B$7/Assumptions!$B$128)/Assumptions!$B$129 | F13: =Assumptions!$B$130 | G13: =Assumptions!$B$130/3 | H13: =Assumptions!$B$131 | I13: =Assumptions!$B$132
A14: =Assumptions!$B$63 | B14: =Assumptions!$B$66 | C14: =Assumptions!$B$133 | D14: =Assumptions!$B$134 | E14: =(Assumptions!$B$7/Assumptions!$B$133)/Assumptions!$B$134 | F14: =Assumptions!$B$135 | G14: =Assumptions!$B$135/3 | H14: =Assumptions!$B$136 | I14: =Assumptions!$B$137
A15: =Assumptions!$B$63 | B15: =Assumptions!$B$67 | C15: =Assumptions!$B$138 | D15: =Assumptions!$B$139 | E15: =(Assumptions!$B$7/Assumptions!$B$138)/Assumptions!$B$139 | F15: =Assumptions!$B$140 | G15: =Assumptions!$B$140/3 | H15: =Assumptions!$B$141 | I15: =Assumptions!$B$142
A16: =Assumptions!$B$64 | B16: =Assumptions!$B$65 | C16: =Assumptions!$B$143 | D16: =Assumptions!$B$144 | E16: =(Assumptions!$B$7/Assumptions!$B$143)/Assumptions!$B$144 | F16: =Assumptions!$B$145 | G16: =Assumptions!$B$145/3 | H16: =Assumptions!$B$146 | I16: =Assumptions!$B$147
A17: =Assumptions!$B$64 | B17: =Assumptions!$B$66 | C17: =Assumptions!$B$148 | D17: =Assumptions!$B$149 | E17: =(Assumptions!$B$7/Assumptions!$B$148)/Assumptions!$B$149 | F17: =Assumptions!$B$150 | G17: =Assumptions!$B$150/3 | H17: =Assumptions!$B$151 | I17: =Assumptions!$B$152
A18: =Assumptions!$B$64 | B18: =Assumptions!$B$67 | C18: =Assumptions!$B$153 | D18: =Assumptions!$B$154 | E18: =(Assumptions!$B$7/Assumptions!$B$153)/Assumptions!$B$154 | F18: =Assumptions!$B$155 | G18: =Assumptions!$B$155/3 | H18: =Assumptions!$B$156 | I18: =Assumptions!$B$157

Sheet Return-Solver
A1: RETURN SOLVER — % of post-F our $10M would need (under base case)
A2: Exit | B2: F class proceeds | C2: F class shares | D2: per-share | E2: per-1%-of-T_F | F2: x for 3x ($30M) | G2: x for 4x ($40M) | H2: 3x feasible? | I2: 4x feasible?
A3: =Assumptions!$B$11 | B3: =MAX(Assumptions!$B$3,Assumptions!$B$88*Assumptions!$B$95) | C3: =Assumptions!$B$88 | D3: =B3/C3 | E3: =D3*Assumptions!$B$74 | F3: =(Assumptions!$B$69*Assumptions!$B$7)/E3 | G3: =(Assumptions!$B$70*Assumptions!$B$7)/E3 | H3: =IF(AND(F3>0,F3<=1),"feasible","infeasible") | I3: =IF(AND(G3>0,G3<=1),"feasible","infeasible")
A4: =Assumptions!$B$12 | B4: =MAX(Assumptions!$B$3,Assumptions!$B$88*Assumptions!$B$99) | C4: =Assumptions!$B$88 | D4: =B4/C4 | E4: =D4*Assumptions!$B$74 | F4: =(Assumptions!$B$69*Assumptions!$B$7)/E4 | G4: =(Assumptions!$B$70*Assumptions!$B$7)/E4 | H4: =IF(AND(F4>0,F4<=1),"feasible","infeasible") | I4: =IF(AND(G4>0,G4<=1),"feasible","infeasible")
A5: =Assumptions!$B$13 | B5: =MAX(Assumptions!$B$3,Assumptions!$B$88*Assumptions!$B$103) | C5: =Assumptions!$B$88 | D5: =B5/C5 | E5: =D5*Assumptions!$B$74 | F5: =(Assumptions!$B$69*Assumptions!$B$7)/E5 | G5: =(Assumptions!$B$70*Assumptions!$B$7)/E5 | H5: =IF(AND(F5>0,F5<=1),"feasible","infeasible") | I5: =IF(AND(G5>0,G5<=1),"feasible","infeasible")
A6: =Assumptions!$B$14 | B6: =MAX(Assumptions!$B$3,Assumptions!$B$88*Assumptions!$B$107) | C6: =Assumptions!$B$88 | D6: =B6/C6 | E6: =D6*Assumptions!$B$74 | F6: =(Assumptions!$B$69*Assumptions!$B$7)/E6 | G6: =(Assumptions!$B$70*Assumptions!$B$7)/E6 | H6: =IF(AND(F6>0,F6<=1),"feasible","infeasible") | I6: =IF(AND(G6>0,G6<=1),"feasible","infeasible")
A7: =Assumptions!$B$15 | B7: =MAX(Assumptions!$B$3,Assumptions!$B$88*Assumptions!$B$111) | C7: =Assumptions!$B$88 | D7: =B7/C7 | E7: =D7*Assumptions!$B$74 | F7: =(Assumptions!$B$69*Assumptions!$B$7)/E7 | G7: =(Assumptions!$B$70*Assumptions!$B$7)/E7 | H7: =IF(AND(F7>0,F7<=1),"feasible","infeasible") | I7: =IF(AND(G7>0,G7<=1),"feasible","infeasible")
A9: Note: x = our_shares / T_F such that x · T_F · (F_class_proceeds / F_class_shares) = target
A10: Equivalently: x = (target × 30M) / (post_money × F_class_proceeds)
