Workbook

Sheet Assumptions
A1: Label | B1: Value | C1: Notes
A2: series_f_pre_money_usd | B2: 1400000000 | C2: Series F pre-money
A3: series_f_primary_raise_usd | B3: 30000000 | C3: Series F primary
A4: series_f_secondary_raise_usd | B4: 15000000 | C4: Secondary tender
A5: tender_pps_multiplier | B5: 0.85 | C5: Tender PPS = mult x F_PPS
A6: esop_refresh_target | B6: 0.13 | C6: ESOP target post-F FD
A7: our_fund_check_usd | B7: 10000000 | C7: Our $10M check
A8: f_lead_primary_check_usd | B8: 20000000 | C8: F_LEAD primary
A9: option_strike_usd | B9: 1 | C9: Option strike
A10: pre_f_options_issued | B10: 2500000 | C10: Pre-F issued options
A11: pre_f_options_unissued | B11: 1894667 | C11: Pre-F unissued pool
A12: pre_f_pool_total | B12: 4394667 | C12: Pre-F total pool (issued+unissued)
A13: pre_f_fd_total | B13: 36617961 | C13: Pre-F fully-diluted
... A56: return_4x | B56: 4 | C56: Return 4x

Sheet Pro-Forma
A1: ROUND-LEVEL FIXED POINT
A2: F pre-money | B2: =Assumptions!$B$2
A3: F primary | B3: =Assumptions!$B$3
A4: Pre-F FD total | B4: =Assumptions!$B$13
A5: Pre-F pool total | B5: =Assumptions!$B$12
A6: ESOP target | B6: =Assumptions!$B$6
A7: OCP_E | B7: =Assumptions!$B$25
A8: OCP_D (post-E NCP) | B8: =Assumptions!$B$24
A9: Broad-based basis A | B9: =Assumptions!$B$14
A10: F PPS | B10: =IFERROR('Pro-Forma'!$B$2/'Pro-Forma'!$B$22,'Pro-Forma'!$B$2/'Pro-Forma'!$B$4)
A11: F primary shares | B11: ='Pro-Forma'!$B$3/'Pro-Forma'!$B$10
A12: B_E | B12: ='Pro-Forma'!$B$3/'Pro-Forma'!$B$7
A13: C = primary / F_PPS | B13: ='Pro-Forma'!$B$3/'Pro-Forma'!$B$10
A14: NCP_E | B14: =IF('Pro-Forma'!$B$10<'Pro-Forma'!$B$7,'Pro-Forma'!$B$7*('Pro-Forma'!$B$9+'Pro-Forma'!$B$12)/('Pro-Forma'!$B$9+'Pro-Forma'!$B$13),'Pro-Forma'!$B$7)
A15: E as-conv shares | B15: =Assumptions!$B$47/'Pro-Forma'!$B$14
A16: E AD addtl shares | B16: ='Pro-Forma'!$B$15-Assumptions!$B$41
A17: B_D | B17: ='Pro-Forma'!$B$3/'Pro-Forma'!$B$8
A18: NCP_D | B18: =IF('Pro-Forma'!$B$10<'Pro-Forma'!$B$8,'Pro-Forma'!$B$8*('Pro-Forma'!$B$9+'Pro-Forma'!$B$17)/('Pro-Forma'!$B$9+'Pro-Forma'!$B$13),'Pro-Forma'!$B$8)
A19: D as-conv shares | B19: =Assumptions!$B$46/'Pro-Forma'!$B$18
A20: D AD addtl shares | B20: ='Pro-Forma'!$B$19-Assumptions!$B$40
A21: ESOP top-up | B21: =MAX(0,'Pro-Forma'!$B$6*'Pro-Forma'!$B$23-'Pro-Forma'!$B$5)
A22: T_premoney | B22: ='Pro-Forma'!$B$4+'Pro-Forma'!$B$16+'Pro-Forma'!$B$20+'Pro-Forma'!$B$21+'Pro-Forma'!$B$32+'Pro-Forma'!$B$39
A23: T_F | B23: ='Pro-Forma'!$B$22+'Pro-Forma'!$B$11
A25: NOTES BLOCK
A26: Note A cap-implied PPS | B26: =Assumptions!$B$27/('Pro-Forma'!$B$4+'Pro-Forma'!$B$16+'Pro-Forma'!$B$20+'Pro-Forma'!$B$21+'Pro-Forma'!$B$39)
A27: Note A discount-impl PPS | B27: ='Pro-Forma'!$B$10*(1-Assumptions!$B$28)
A28: Note A conv PPS = min | B28: =MIN('Pro-Forma'!$B$26,'Pro-Forma'!$B$27)
A29: Note A branch | B29: =IF('Pro-Forma'!$B$26<'Pro-Forma'!$B$27,"cap","discount")
A30: Note A shares if cap | B30: =Assumptions!$B$26/'Pro-Forma'!$B$26
A31: Note A shares if discount | B31: =Assumptions!$B$26/'Pro-Forma'!$B$27
A32: Note A shares issued | B32: =IF('Pro-Forma'!$B$26<'Pro-Forma'!$B$27,'Pro-Forma'!$B$30,'Pro-Forma'!$B$31)
A33: Note B cap-implied PPS | B33: =Assumptions!$B$30/('Pro-Forma'!$B$4+'Pro-Forma'!$B$16+'Pro-Forma'!$B$20+'Pro-Forma'!$B$21+'Pro-Forma'!$B$32)
A34: Note B discount-impl PPS | B34: ='Pro-Forma'!$B$10*(1-Assumptions!$B$31)
A35: Note B conv PPS = min | B35: =MIN('Pro-Forma'!$B$33,'Pro-Forma'!$B$34)
A36: Note B branch | B36: =IF('Pro-Forma'!$B$33<'Pro-Forma'!$B$34,"cap","discount")
A37: Note B shares if cap | B37: =Assumptions!$B$29/'Pro-Forma'!$B$33
A38: Note B shares if discount | B38: =Assumptions!$B$29/'Pro-Forma'!$B$34
A39: Note B shares issued | B39: =IF('Pro-Forma'!$B$33<'Pro-Forma'!$B$34,'Pro-Forma'!$B$37,'Pro-Forma'!$B$38)
A41: Tender shares = $15M/(0.85*F_PPS) | B41: =Assumptions!$B$4/(Assumptions!$B$5*'Pro-Forma'!$B$10)
A42: F_LEAD primary preferred shares | B42: =Assumptions!$B$8/'Pro-Forma'!$B$10
...

Sheet Waterfall
A1: WATERFALL — 5 Exit Scenarios
A2: Exit value (USD) | C2: =Assumptions!$B$15 | D2: =Assumptions!$B$16 | E2: =Assumptions!$B$17 | F2: =Assumptions!$B$18 | G2: =Assumptions!$B$19
A4: INPUTS (post-F cap table)
A5: F preferred shares total | B5: ='Pro-Forma'!$B$11
A6: E as-converted shares | B6: ='Pro-Forma'!$B$15
A7: D as-converted shares | B7: ='Pro-Forma'!$B$19
A8: C shares | B8: =Assumptions!$B$39
A9: B shares | B9: =Assumptions!$B$38
A10: A shares | B10: =Assumptions!$B$37
A11: Seed shares | B11: =Assumptions!$B$36
A12: Common + RSAs (founders+RSAs) | B12: =Assumptions!$B$32+Assumptions!$B$33+Assumptions!$B$34+Assumptions!$B$35
A13: Issued options (pre-F) | B13: =Assumptions!$B$10
A14: Notes shares (NA+NB) | B14: ='Pro-Forma'!$B$32+'Pro-Forma'!$B$39
A15: NCPs (post-F per-share):
A16: F NCP = F_PPS | B16: ='Pro-Forma'!$B$10
A17: E NCP (post-F) | B17: ='Pro-Forma'!$B$14
A18: D NCP (post-F) | B18: ='Pro-Forma'!$B$18
A19: C NCP | B19: =Assumptions!$B$23
A20: B NCP | B20: =Assumptions!$B$22
A21: A NCP | B21: =Assumptions!$B$21
A22: Seed NCP | B22: =Assumptions!$B$20
A23: Aggregate preferences ($):
A24: F preference | B24: =Assumptions!$B$3
A25: E preference | B25: =Assumptions!$B$47
A26: D preference | B26: =Assumptions!$B$46
A27: C preference | B27: =Assumptions!$B$45
A28: B preference | B28: =Assumptions!$B$44
A29: A preference | B29: =Assumptions!$B$43
A30: Seed preference | B30: =Assumptions!$B$42
A31: Option strike | B31: =Assumptions!$B$9
A33: PER-EXIT COMPUTATIONS
A35: common PPS (convert pool $) | C35: =IFERROR(C57/C55, 0) | D35: =IFERROR(D57/D55, 0) | E35: =IFERROR(E57/E55, 0) | F35: =IFERROR(F57/F55, 0) | G35: =IFERROR(G57/G55, 0)
A36: Election F | C36: =IF($B$16<C35,"convert","preference") | D36: =IF($B$16<D35,"convert","preference") | E36: =IF($B$16<E35,"convert","preference") | F36: =IF($B$16<F35,"convert","preference") | G36: =IF($B$16<G35,"convert","preference")
A37: Election E | C37: =IF($B$17<C35,"convert","preference") | D37: =IF($B$17<D35,"convert","preference") | E37: =IF($B$17<E35,"convert","preference") | F37: =IF($B$17<F35,"convert","preference") | G37: =IF($B$17<G35,"convert","preference")
A38: Election D | C38: =IF($B$18<C35,"convert","preference") | D38: =IF($B$18<D35,"convert","preference") | E38: =IF($B$18<E35,"convert","preference") | F38: =IF($B$18<F35,"convert","preference") | G38: =IF($B$18<G35,"convert","preference")
A39: Election C | C39: =IF($B$19<C35,"convert","preference") | D39: =IF($B$19<D35,"convert","preference") | E39: =IF($B$19<E35,"convert","preference") | F39: =IF($B$19<F35,"convert","preference") | G39: =IF($B$19<G35,"convert","preference")
A40: Election B | C40: =IF($B$20<C35,"convert","preference") | D40: =IF($B$20<D35,"convert","preference") | E40: =IF($B$20<E35,"convert","preference") | F40: =IF($B$20<F35,"convert","preference") | G40: =IF($B$20<G35,"convert","preference")
A41: Election A | C41: =IF($B$21<C35,"convert","preference") | D41: =IF($B$21<D35,"convert","preference") | E41: =IF($B$21<E35,"convert","preference") | F41: =IF($B$21<F35,"convert","preference") | G41: =IF($B$21<G35,"convert","preference")
A42: Election Seed | C42: =IF($B$22<C35,"convert","preference") | D42: =IF($B$22<D35,"convert","preference") | E42: =IF($B$22<E35,"convert","preference") | F42: =IF($B$22<F35,"convert","preference") | G42: =IF($B$22<G35,"convert","preference")
A44: F convert shares | C44: =IF(C36="convert",$B$5,0) | D44: =IF(D36="convert",$B$5,0) | E44: =IF(E36="convert",$B$5,0) | F44: =IF(F36="convert",$B$5,0) | G44: =IF(G36="convert",$B$5,0)
...

Sheet Sensitivity
A1: SENSITIVITY: ESOP × Pre-money @ $2B exit
A3: Our $10M post-F ownership %
B4: Pre $1.2B | C4: Pre $1.4B | D4: Pre $1.8B
A5: ESOP 11% | B5: =C45 | C5: =D45 | D5: =E45
A6: ESOP 13% | B6: =F45 | C6: =G45 | D6: =H45
A7: ESOP 15% | B7: =I45 | C7: =J45 | D7: =K45
A9: Our $ proceeds @ $2B exit
B10: Pre $1.2B | C10: Pre $1.4B | D10: Pre $1.8B
A11: ESOP 11% | B11: =C79 | C11: =D79 | D11: =E79
A12: ESOP 13% | B12: =F79 | C12: =G79 | D12: =H79
A13: ESOP 15% | B13: =I79 | C13: =J79 | D13: =K79
A20: HELPER BLOCKS (per scenario) | C20: 11%/$1.2B | D20: 11%/$1.4B | E20: 11%/$1.8B | F20: 13%/$1.2B | G20: 13%/$1.4B | H20: 13%/$1.8B | I20: 15%/$1.2B | J20: 15%/$1.4B | K20: 15%/$1.8B
A21: ESOP target | C21: =Assumptions!$B$49 | D21: =Assumptions!$B$49 | E21: =Assumptions!$B$49 | F21: =Assumptions!$B$50 | G21: =Assumptions!$B$50 | H21: =Assumptions!$B$50 | I21: =Assumptions!$B$51 | J21: =Assumptions!$B$51 | K21: =Assumptions!$B$51
A22: Pre-money | C22: =Assumptions!$B$52 | D22: =Assumptions!$B$53 | E22: =Assumptions!$B$54 | F22: =Assumptions!$B$52 | G22: =Assumptions!$B$53 | H22: =Assumptions!$B$54 | I22: =Assumptions!$B$52 | J22: =Assumptions!$B$53 | K22: =Assumptions!$B$54
A23: Primary | C23: =Assumptions!$B$3 | D23: =Assumptions!$B$3 | E23: =Assumptions!$B$3 | F23: =Assumptions!$B$3 | G23: =Assumptions!$B$3 | H23: =Assumptions!$B$3 | I23: =Assumptions!$B$3 | J23: =Assumptions!$B$3 | K23: =Assumptions!$B$3
A24: F_PPS | C24: =IFERROR(C22/C42,C22/Assumptions!$B$13) | D24: =IFERROR(D22/D42,D22/Assumptions!$B$13) | E24: =IFERROR(E22/E42,E22/Assumptions!$B$13) | F24: =IFERROR(F22/F42,F22/Assumptions!$B$13) | G24: =IFERROR(G22/G42,G22/Assumptions!$B$13) | H24: =IFERROR(H22/H42,H22/Assumptions!$B$13) | I24: =IFERROR(I22/I42,I22/Assumptions!$B$13) | J24: =IFERROR(J22/J42,J22/Assumptions!$B$13) | K24: =IFERROR(K22/K42,K22/Assumptions!$B$13)
A25: F primary shares | C25: =C23/C24 | D25: =D23/D24 | E25: =E23/E24 | F25: =F23/F24 | G25: =G23/G24 | H25: =H23/H24 | I25: =I23/I24 | J25: =J23/J24 | K25: =K23/K24
A26: B_E | C26: =C23/Assumptions!$B$25 | D26: =D23/Assumptions!$B$25 | E26: =E23/Assumptions!$B$25 | F26: =F23/Assumptions!$B$25 | G26: =G23/Assumptions!$B$25 | H26: =H23/Assumptions!$B$25 | I26: =I23/Assumptions!$B$25 | J26: =J23/Assumptions!$B$25 | K26: =K23/Assumptions!$B$25
A27: C = primary/F_PPS | C27: =C23/C24 | D27: =D23/D24 | E27: =E23/E24 | F27: =F23/F24 | G27: =G23/G24 | H27: =H23/H24 | I27: =I23/I24 | J27: =J23/J24 | K27: =K23/K24
A28: NCP_E | C28: =IF(C24<Assumptions!$B$25,Assumptions!$B$25*(Assumptions!$B$14+C26)/(Assumptions!$B$14+C27),Assumptions!$B$25) | D28: =IF(D24<Assumptions!$B$25,Assumptions!$B$25*(Assumptions!$B$14+D26)/(Assumptions!$B$14+D27),Assumptions!$B$25) | E28: =IF(E24<Assumptions!$B$25,Assumptions!$B$25*(Assumptions!$B$14+E26)/(Assumptions!$B$14+E27),Assumptions!$B$25) | F28: =IF(F24<Assumptions!$B$25,Assumptions!$B$25*(Assumptions!$B$14+F26)/(Assumptions!$B$14+F27),Assumptions!$B$25) | G28: =IF(G24<Assumptions!$B$25,Assumptions!$B$25*(Assumptions!$B$14+G26)/(Assumptions!$B$14+G27),Assumptions!$B$25) | H28: =IF(H24<Assumptions!$B$25,Assumptions!$B$25*(Assumptions!$B$14+H26)/(Assumptions!$B$14+H27),Assumptions!$B$25) | I28: =IF(I24<Assumptions!$B$25,Assumptions!$B$25*(Assumptions!$B$14+I26)/(Assumptions!$B$14+I27),Assumptions!$B$25) | J28: =IF(J24<Assumptions!$B$25,Assumptions!$B$25*(Assumptions!$B$14+J26)/(Assumptions!$B$14+J27),Assumptions!$B$25) | K28: =IF(K24<Assumptions!$B$25,Assumptions!$B$25*(Assumptions!$B$14+K26)/(Assumptions!$B$14+K27),Assumptions!$B$25)
A29: E total shares | C29: =Assumptions!$B$47/C28 | D29: =Assumptions!$B$47/D28 | E29: =Assumptions!$B$47/E28 | F29: =Assumptions!$B$47/F28 | G29: =Assumptions!$B$47/G28 | H29: =Assumptions!$B$47/H28 | I29: =Assumptions!$B$47/I28 | J29: =Assumptions!$B$47/J28 | K29: =Assumptions!$B$47/K28
A30: E AD add | C30: =C29-Assumptions!$B$41 | D30: =D29-Assumptions!$B$41 | E30: =E29-Assumptions!$B$41 | F30: =F29-Assumptions!$B$41 | G30: =G29-Assumptions!$B$41 | H30: =H29-Assumptions!$B$41 | I30: =I29-Assumptions!$B$41 | J30: =J29-Assumptions!$B$41 | K30: =K29-Assumptions!$B$41
A31: B_D | C31: =C23/Assumptions!$B$24 | D31: =D23/Assumptions!$B$24 | E31: =E23/Assumptions!$B$24 | F31: =F23/Assumptions!$B$24 | G31: =G23/Assumptions!$B$24 | H31: =H23/Assumptions!$B$24 | I31: =I23/Assumptions!$B$24 | J31: =J23/Assumptions!$B$24 | K31: =K23/Assumptions!$B$24
A32: NCP_D | C32: =IF(C24<Assumptions!$B$24,Assumptions!$B$24*(Assumptions!$B$14+C31)/(Assumptions!$B$14+C27),Assumptions!$B$24) | D32: =IF(D24<Assumptions!$B$24,Assumptions!$B$24*(Assumptions!$B$14+D31)/(Assumptions!$B$14+D27),Assumptions!$B$24) | E32: =IF(E24<Assumptions!$B$24,Assumptions!$B$24*(Assumptions!$B$14+E31)/(Assumptions!$B$14+E27),Assumptions!$B$24) | F32: =IF(F24<Assumptions!$B$24,Assumptions!$B$24*(Assumptions!$B$14+F31)/(Assumptions!$B$14+F27),Assumptions!$B$24) | G32: =IF(G24<Assumptions!$B$24,Assumptions!$B$24*(Assumptions!$B$14+G31)/(Assumptions!$B$14+G27),Assumptions!$B$24) | H32: =IF(H24<Assumptions!$B$24,Assumptions!$B$24*(Assumptions!$B$14+H31)/(Assumptions!$B$14+H27),Assumptions!$B$24) | I32: =IF(I24<Assumptions!$B$24,Assumptions!$B$24*(Assumptions!$B$14+I31)/(Assumptions!$B$14+I27),Assumptions!$B$24) | J32: =IF(J24<Assumptions!$B$24,Assumptions!$B$24*(Assumptions!$B$14+J31)/(Assumptions!$B$14+J27),Assumptions!$B$24) | K32: =IF(K24<Assumptions!$B$24,Assumptions!$B$24*(Assumptions!$B$14+K31)/(Assumptions!$B$14+K27),Assumptions!$B$24)
A33: D total shares | C33: =Assumptions!$B$46/C32 | D33: =Assumptions!$B$46/D32 | E33: =Assumptions!$B$46/E32 | F33: =Assumptions!$B$46/F32 | G33: =Assumptions!$B$46/G32 | H33: =Assumptions!$B$46/H32 | I33: =Assumptions!$B$46/I32 | J33: =Assumptions!$B$46/J32 | K33: =Assumptions!$B$46/K32
A34: D AD add | C34: =C33-Assumptions!$B$40 | D34: =D33-Assumptions!$B$40 | E34: =E33-Assumptions!$B$40 | F34: =F33-Assumptions!$B$40 | G34: =G33-Assumptions!$B$40 | H34: =H33-Assumptions!$B$40 | I34: =I33-Assumptions!$B$40 | J34: =J33-Assumptions!$B$40 | K34: =K33-Assumptions!$B$40
A35: ESOP top-up | C35: =MAX(0,C21*C43-Assumptions!$B$12) | D35: =MAX(0,D21*D43-Assumptions!$B$12) | E35: =MAX(0,E21*E43-Assumptions!$B$12) | F35: =MAX(0,F21*F43-Assumptions!$B$12) | G35: =MAX(0,G21*G43-Assumptions!$B$12) | H35: =MAX(0,H21*H43-Assumptions!$B$12) | I35: =MAX(0,I21*I43-Assumptions!$B$12) | J35: =MAX(0,J21*J43-Assumptions!$B$12) | K35: =MAX(0,K21*K43-Assumptions!$B$12)
A36: Note A capPPS | C36: =Assumptions!$B$27/(Assumptions!$B$13+C30+C34+C35+C41) | D36: =Assumptions!$B$27/(Assumptions!$B$13+D30+D34+D35+D41) | E36: =Assumptions!$B$27/(Assumptions!$B$13+E30+E34+E35+E41) | F36: =Assumptions!$B$27/(Assumptions!$B$13+F30+F34+F35+F41) | G36: =Assumptions!$B$27/(Assumptions!$B$13+G30+G34+G35+G41) | H36: =Assumptions!$B$27/(Assumptions!$B$13+H30+H34+H35+H41) | I36: =Assumptions!$B$27/(Assumptions!$B$13+I30+I34+I35+I41) | J36: =Assumptions!$B$27/(Assumptions!$B$13+J30+J34+J35+J41) | K36: =Assumptions!$B$27/(Assumptions!$B$13+K30+K34+K35+K41)
A37: Note A discPPS | C37: =C24*(1-Assumptions!$B$28) | D37: =D24*(1-Assumptions!$B$28) | E37: =E24*(1-Assumptions!$B$28) | F37: =F24*(1-Assumptions!$B$28) | G37: =G24*(1-Assumptions!$B$28) | H37: =H24*(1-Assumptions!$B$28) | I37: =I24*(1-Assumptions!$B$28) | J37: =J24*(1-Assumptions!$B$28) | K37: =K24*(1-Assumptions!$B$28)
A38: NA shares | C38: =Assumptions!$B$26/MIN(C36,C37) | D38: =Assumptions!$B$26/MIN(D36,D37) | E38: =Assumptions!$B$26/MIN(E36,E37) | F38: =Assumptions!$B$26/MIN(F36,F37) | G38: =Assumptions!$B$26/MIN(G36,G37) | H38: =Assumptions!$B$26/MIN(H36,H37) | I38: =Assumptions!$B$26/MIN(I36,I37) | J38: =Assumptions!$B$26/MIN(J36,J37) | K38: =Assumptions!$B$26/MIN(K36,K37)
A39: Note B capPPS | C39: =Assumptions!$B$30/(Assumptions!$B$13+C30+C34+C35+C38) | D39: =Assumptions!$B$30/(Assumptions!$B$13+D30+D34+D35+D38) | E39: =Assumptions!$B$30/(Assumptions!$B$13+E30+E34+E35+E38) | F39: =Assumptions!$B$30/(Assumptions!$B$13+F30+F34+F35+F38) | G39: =Assumptions!$B$30/(Assumptions!$B$13+G30+G34+G35+G38) | H39: =Assumptions!$B$30/(Assumptions!$B$13+H30+H34+H35+H38) | I39: =Assumptions!$B$30/(Assumptions!$B$13+I30+I34+I35+I38) | J39: =Assumptions!$B$30/(Assumptions!$B$13+J30+J34+J35+J38) | K39: =Assumptions!$B$30/(Assumptions!$B$13+K30+K34+K35+K38)
A40: Note B discPPS | C40: =C24*(1-Assumptions!$B$31) | D40: =D24*(1-Assumptions!$B$31) | E40: =E24*(1-Assumptions!$B$31) | F40: =F24*(1-Assumptions!$B$31) | G40: =G24*(1-Assumptions!$B$31) | H40: =H24*(1-Assumptions!$B$31) | I40: =I24*(1-Assumptions!$B$31) | J40: =J24*(1-Assumptions!$B$31) | K40: =K24*(1-Assumptions!$B$31)
A41: NB shares | C41: =Assumptions!$B$29/MIN(C39,C40) | D41: =Assumptions!$B$29/MIN(D39,D40) | E41: =Assumptions!$B$29/MIN(E39,E40) | F41: =Assumptions!$B$29/MIN(F39,F40) | G41: =Assumptions!$B$29/MIN(G39,G40) | H41: =Assumptions!$B$29/MIN(H39,H40) | I41: =Assumptions!$B$29/MIN(I39,I40) | J41: =Assumptions!$B$29/MIN(J39,J40) | K41: =Assumptions!$B$29/MIN(K39,K40)
A42: T_premoney | C42: =Assumptions!$B$13+C30+C34+C35+C38+C41 | D42: =Assumptions!$B$13+D30+D34+D35+D38+D41 | E42: =Assumptions!$B$13+E30+E34+E35+E38+E41 | F42: =Assumptions!$B$13+F30+F34+F35+F38+F41 | G42: =Assumptions!$B$13+G30+G34+G35+G38+G41 | H42: =Assumptions!$B$13+H30+H34+H35+H38+H41 | I42: =Assumptions!$B$13+I30+I34+I35+I38+I41 | J42: =Assumptions!$B$13+J30+J34+J35+J38+J41 | K42: =Assumptions!$B$13+K30+K34+K35+K38+K41
A43: T_F | C43: =C42+C25 | D43: =D42+D25 | E43: =E42+E25 | F43: =F42+F25 | G43: =G42+G25 | H43: =H42+H25 | I43: =I42+I25 | J43: =J42+J25 | K43: =K42+K25
A44: Our shares | C44: =Assumptions!$B$7/C24 | D44: =Assumptions!$B$7/D24 | E44: =Assumptions!$B$7/E24 | F44: =Assumptions!$B$7/F24 | G44: =Assumptions!$B$7/G24 | H44: =Assumptions!$B$7/H24 | I44: =Assumptions!$B$7/I24 | J44: =Assumptions!$B$7/J24 | K44: =Assumptions!$B$7/K24
A45: Our ownership | C45: =C44/C43 | D45: =D44/D43 | E45: =E44/E43 | F45: =F44/F43 | G45: =G44/G43 | H45: =H44/H43 | I45: =I44/I43 | J45: =J44/J43 | K45: =K44/K43
A46: Exit value | C46: =Assumptions!$B$17 | D46: =Assumptions!$B$17 | E46: =Assumptions!$B$17 | F46: =Assumptions!$B$17 | G46: =Assumptions!$B$17 | H46: =Assumptions!$B$17 | I46: =Assumptions!$B$17 | J46: =Assumptions!$B$17 | K46: =Assumptions!$B$17
A47: F_NCP | C47: =C24 | D47: =D24 | E47: =E24 | F47: =F24 | G47: =G24 | H47: =H24 | I47: =I24 | J47: =J24 | K47: =K24
A48: E_NCP | C48: =C28 | D48: =D28 | E48: =E28 | F48: =F28 | G48: =G28 | H48: =H28 | I48: =I28 | J48: =J28 | K48: =K28
...

Sheet Return-Solver
A1: RETURN SOLVER — Series F ownership % needed for 3× / 4× return on $10M
A3: Metric | B3: $700M | C3: $1.2B | D3: $2B | E3: $4B | F3: $8B
A4: Exit value (USD) | B4: =Assumptions!$B$15 | C4: =Assumptions!$B$16 | D4: =Assumptions!$B$17 | E4: =Assumptions!$B$18 | F4: =Assumptions!$B$19
A5: F election (from Waterfall) | B5: =Waterfall!C36 | C5: =Waterfall!D36 | D5: =Waterfall!E36 | E5: =Waterfall!F36 | F5: =Waterfall!G36
A6: F class total proceeds (base case) | B6: =Waterfall!C60 | C6: =Waterfall!D60 | D6: =Waterfall!E60 | E6: =Waterfall!F60 | F6: =Waterfall!G60
A7: Target $ for 3× | B7: =Assumptions!$B$55*Assumptions!$B$7 | C7: =Assumptions!$B$55*Assumptions!$B$7 | D7: =Assumptions!$B$55*Assumptions!$B$7 | E7: =Assumptions!$B$55*Assumptions!$B$7 | F7: =Assumptions!$B$55*Assumptions!$B$7
A8: Target $ for 4× | B8: =Assumptions!$B$56*Assumptions!$B$7 | C8: =Assumptions!$B$56*Assumptions!$B$7 | D8: =Assumptions!$B$56*Assumptions!$B$7 | E8: =Assumptions!$B$56*Assumptions!$B$7 | F8: =Assumptions!$B$56*Assumptions!$B$7
A9: F ownership % needed for 3× | B9: =IFERROR(B7/B6, "infeasible") | C9: =IFERROR(C7/C6, "infeasible") | D9: =IFERROR(D7/D6, "infeasible") | E9: =IFERROR(E7/E6, "infeasible") | F9: =IFERROR(F7/F6, "infeasible")
A10: F ownership % needed for 4× | B10: =IFERROR(B8/B6, "infeasible") | C10: =IFERROR(C8/C6, "infeasible") | D10: =IFERROR(D8/D6, "infeasible") | E10: =IFERROR(E8/E6, "infeasible") | F10: =IFERROR(F8/F6, "infeasible")
A11: Feasibility flag (3×) | B11: =IF(ISNUMBER(B9),IF(AND(B9>0,B9<=1),"feasible","infeasible"),"infeasible") | C11: =IF(ISNUMBER(C9),IF(AND(C9>0,C9<=1),"feasible","infeasible"),"infeasible") | D11: =IF(ISNUMBER(D9),IF(AND(D9>0,D9<=1),"feasible","infeasible"),"infeasible") | E11: =IF(ISNUMBER(E9),IF(AND(E9>0,E9<=1),"feasible","infeasible"),"infeasible") | F11: =IF(ISNUMBER(F9),IF(AND(F9>0,F9<=1),"feasible","infeasible"),"infeasible")
A12: Feasibility flag (4×) | B12: =IF(ISNUMBER(B10),IF(AND(B10>0,B10<=1),"feasible","infeasible"),"infeasible") | C12: =IF(ISNUMBER(C10),IF(AND(C10>0,C10<=1),"feasible","infeasible"),"infeasible") | D12: =IF(ISNUMBER(D10),IF(AND(D10>0,D10<=1),"feasible","infeasible"),"infeasible") | E12: =IF(ISNUMBER(E10),IF(AND(E10>0,E10<=1),"feasible","infeasible"),"infeasible") | F12: =IF(ISNUMBER(F10),IF(AND(F10>0,F10<=1),"feasible","infeasible"),"infeasible")
A14: Method: x × F_total_proceeds = target; x = target / F_total_proceeds. F_total_proceeds reflects F's election (preference vs convert) at each exit per the base-case full waterfall.
