Workbook

Sheet Assumptions
A1: Kelvin Dynamics — Series F Assumptions
A3: ROUND TERMS
A4: Series F pre-money | B4: 1400000000 | C4: USD
A5: Series F primary raise | B5: 30000000 | C5: USD
A6: Series F secondary raise | B6: 15000000 | C6: USD
A7: Tender PPS multiplier (× F_PPS) | B7: 0.85
A8: ESOP refresh target (post-F FD) | B8: 0.13
A9: Our fund check | B9: 10000000 | C9: USD (1/3 of primary)
A10: F_LEAD primary check | B10: 20000000 | C10: USD (2/3 of primary)
A11: Option strike | B11: 1 | C11: USD
A13: EXIT VALUES
A14: Exit 1 | B14: 700000000 | C14: USD
A15: Exit 2 | B15: 1200000000 | C15: USD
A16: Exit 3 | B16: 2000000000 | C16: USD (sensitivity ref)
A17: Exit 4 | B17: 4000000000 | C17: USD
A18: Exit 5 | B18: 8000000000 | C18: USD
A20: PRIOR-ROUND OCPs (for AD)
A21: OCP Seed | B21: 1
A22: OCP Series A | B22: 3
A23: OCP Series B | B23: 10
A24: OCP Series C | B24: 25
A25: OCP Series D (effective post-E NCP) | B25: 58.118347 | C25: compound v3·v4 off $60 original
A26: OCP Series E | B26: 49.158311
A27: OCP Series D (original) | B27: 60
A29: INVESTED $ BY CLASS
A30: Seed invested | B30: 5000000 | C30: USD
A31: Series A invested | B31: 15000000 | C31: USD
A32: Series B invested | B32: 30000000 | C32: USD
A33: Series C invested | B33: 60000000 | C33: USD
A34: Series D invested | B34: 100000000 | C34: USD
A35: Series E invested | B35: 300000000 | C35: USD
A37: PRE-F SHARE COUNTS
A38: Seed shares | B38: 5000000
A39: Series A shares | B39: 5000000
A40: Series B shares | B40: 3000000
A41: Series C shares | B41: 2400000
A42: Series D shares (post-E adj) | B42: 1720627
A43: Series E shares | B43: 6102667
A44: Founder F1 (CEO) common | B44: 4000000
A45: Founder F2 (CTO) common | B45: 2500000
...

Sheet Pro-Forma
A1: Pro-Forma Cap Table — Post-Series F
A3: ROUND MECHANICS (solved fixed point)
A4: F_PPS | B4: ='Pro-Forma'!$B$162
A5: F primary shares | B5: ='Pro-Forma'!$F$162
A6: Pre-money FD (incl AD, ESOP, notes) | B6: ='Pro-Forma'!$I$162
A7: T_F (post-F FD) | B7: ='Pro-Forma'!$J$162
A8: ESOP top-up shares | B8: ='Pro-Forma'!$H$162
A9: AD extra shares total | B9: ='Pro-Forma'!$E$162
A10: Note A converted shares | B10: ='Pro-Forma'!$C$162
A11: Note B converted shares | B11: ='Pro-Forma'!$D$162
A12: Check: F_PPS × pre-money FD | B12: ='Pro-Forma'!$B$162*'Pro-Forma'!$I$162
A14: ANTI-DILUTION (Broad-based WA)
A15: Class | B15: OCP | C15: Trigger? | D15: B = primary/OCP | E15: C = primary/F_PPS | F15: NCP | G15: New ratio | H15: As-converted | I15: AD extra
A16: Seed | B16: =Assumptions!$B$21 | C16: =IF('Pro-Forma'!$B$162<Assumptions!$B$21,"YES","NO") | D16: =Assumptions!$B$5/Assumptions!$B$21 | E16: =Assumptions!$B$5/'Pro-Forma'!$B$162 | F16: =IF('Pro-Forma'!$B$162<Assumptions!$B$21,Assumptions!$B$21*(Assumptions!$B$50+D16)/(Assumptions!$B$50+E16),Assumptions!$B$21) | G16: =Assumptions!$B$21/F16 | H16: =Assumptions!$B$38 | I16: =MAX(0,H16-Assumptions!$B$38)
A17: Series A | B17: =Assumptions!$B$22 | C17: =IF('Pro-Forma'!$B$162<Assumptions!$B$22,"YES","NO") | D17: =Assumptions!$B$5/Assumptions!$B$22 | E17: =Assumptions!$B$5/'Pro-Forma'!$B$162 | F17: =IF('Pro-Forma'!$B$162<Assumptions!$B$22,Assumptions!$B$22*(Assumptions!$B$50+D17)/(Assumptions!$B$50+E17),Assumptions!$B$22) | G17: =Assumptions!$B$22/F17 | H17: =Assumptions!$B$39 | I17: =MAX(0,H17-Assumptions!$B$39)
A18: Series B | B18: =Assumptions!$B$23 | C18: =IF('Pro-Forma'!$B$162<Assumptions!$B$23,"YES","NO") | D18: =Assumptions!$B$5/Assumptions!$B$23 | E18: =Assumptions!$B$5/'Pro-Forma'!$B$162 | F18: =IF('Pro-Forma'!$B$162<Assumptions!$B$23,Assumptions!$B$23*(Assumptions!$B$50+D18)/(Assumptions!$B$50+E18),Assumptions!$B$23) | G18: =Assumptions!$B$23/F18 | H18: =Assumptions!$B$40 | I18: =MAX(0,H18-Assumptions!$B$40)
A19: Series C | B19: =Assumptions!$B$24 | C19: =IF('Pro-Forma'!$B$162<Assumptions!$B$24,"YES","NO") | D19: =Assumptions!$B$5/Assumptions!$B$24 | E19: =Assumptions!$B$5/'Pro-Forma'!$B$162 | F19: =IF('Pro-Forma'!$B$162<Assumptions!$B$24,Assumptions!$B$24*(Assumptions!$B$50+D19)/(Assumptions!$B$50+E19),Assumptions!$B$24) | G19: =Assumptions!$B$24/F19 | H19: =Assumptions!$B$41 | I19: =MAX(0,H19-Assumptions!$B$41)
A20: Series D | B20: =Assumptions!$B$25 | C20: =IF('Pro-Forma'!$B$162<Assumptions!$B$25,"YES","NO") | D20: =Assumptions!$B$5/Assumptions!$B$25 | E20: =Assumptions!$B$5/'Pro-Forma'!$B$162 | F20: =IF('Pro-Forma'!$B$162<Assumptions!$B$25,Assumptions!$B$25*(Assumptions!$B$50+D20)/(Assumptions!$B$50+E20),Assumptions!$B$25) | G20: =Assumptions!$B$27/F20 | H20: =Assumptions!$B$34/F20 | I20: =MAX(0,H20-Assumptions!$B$42)
A21: Series E | B21: =Assumptions!$B$26 | C21: =IF('Pro-Forma'!$B$162<Assumptions!$B$26,"YES","NO") | D21: =Assumptions!$B$5/Assumptions!$B$26 | E21: =Assumptions!$B$5/'Pro-Forma'!$B$162 | F21: =IF('Pro-Forma'!$B$162<Assumptions!$B$26,Assumptions!$B$26*(Assumptions!$B$50+D21)/(Assumptions!$B$50+E21),Assumptions!$B$26) | G21: =Assumptions!$B$26/F21 | H21: =Assumptions!$B$35/F21 | I21: =MAX(0,H21-Assumptions!$B$43)
A24: CONVERTIBLE NOTES (convert at F closing)
A25: Note | C25: Cap-implied PPS | D25: Discount-implied PPS | E25: Conv PPS | F25: Branch | G25: Shares
A26: Note A | C26: ='Pro-Forma'!$M$162 | D26: ='Pro-Forma'!$N$162 | E26: ='Pro-Forma'!$O$162 | F26: =IF(C26<D26,"cap","discount") | G26: ='Pro-Forma'!$C$162
A27: Note B | C27: ='Pro-Forma'!$P$162 | D27: ='Pro-Forma'!$Q$162 | E27: ='Pro-Forma'!$R$162 | F27: =IF(C27<D27,"cap","discount") | G27: ='Pro-Forma'!$D$162
A30: SECONDARY TENDER (F_LEAD buys from founders)
A31: Tender shares | B31: =Assumptions!$B$6/(Assumptions!$B$7*'Pro-Forma'!$B$162)
A32: Tender PPS | B32: =Assumptions!$B$7*'Pro-Forma'!$B$162
A33: F1 shares transferred | B33: =Assumptions!$B$54*'Pro-Forma'!$B$31
A34: F2 shares transferred | B34: =Assumptions!$B$55*'Pro-Forma'!$B$31
A35: F3 shares transferred | B35: =Assumptions!$B$56*'Pro-Forma'!$B$31
A36: F_LEAD secondary holding (common) | B36: ='Pro-Forma'!$B$31
A39: POST-F CAP TABLE BY STAKEHOLDER
A40: Stakeholder | B40: Class | C40: Shares | D40: % of T_F
A41: F1 (CEO) | B41: Common | C41: =Assumptions!$B$44-'Pro-Forma'!$B$33 | D41: =C41/'Pro-Forma'!$J$162
A42: F2 (CTO) | B42: Common | C42: =Assumptions!$B$45-'Pro-Forma'!$B$34 | D42: =C42/'Pro-Forma'!$J$162
A43: F3 (CSci) | B43: Common | C43: =Assumptions!$B$46-'Pro-Forma'!$B$35 | D43: =C43/'Pro-Forma'!$J$162
A44: E1 (RSA) | B44: RSA | C44: =100000 | D44: =C44/'Pro-Forma'!$J$162
A45: E2 (RSA) | B45: RSA | C45: =100000 | D45: =C45/'Pro-Forma'!$J$162
A46: E3 (RSA) | B46: RSA | C46: =100000 | D46: =C46/'Pro-Forma'!$J$162
A47: E4 (RSA) | B47: RSA | C47: =100000 | D47: =C47/'Pro-Forma'!$J$162
A48: E5 (RSA) | B48: RSA | C48: =100000 | D48: =C48/'Pro-Forma'!$J$162
...

Sheet Waterfall
A1: Liquidation Waterfall — 5 Exit Scenarios
A2: Reverse-chronological seniority: F > E > D > C > B > A > Seed
B3: Exit 1: $700M | C3: Exit 2: $1.2B | D3: Exit 3: $2B | E3: Exit 4: $4B | F3: Exit 5: $8B
A4: Exit value (USD) | B4: =Assumptions!$B$14 | C4: =Assumptions!$B$15 | D4: =Assumptions!$B$16 | E4: =Assumptions!$B$17 | F4: =Assumptions!$B$18
A5: Common + RSA total
A6: Founders post-tender common | B6: ='Pro-Forma'!C41+'Pro-Forma'!C42+'Pro-Forma'!C43 | C6: ='Pro-Forma'!C41+'Pro-Forma'!C42+'Pro-Forma'!C43 | D6: ='Pro-Forma'!C41+'Pro-Forma'!C42+'Pro-Forma'!C43 | E6: ='Pro-Forma'!C41+'Pro-Forma'!C42+'Pro-Forma'!C43 | F6: ='Pro-Forma'!C41+'Pro-Forma'!C42+'Pro-Forma'!C43
A7: RSAs (10×100k) | B7: =SUM('Pro-Forma'!C44:C53) | C7: =SUM('Pro-Forma'!C44:C53) | D7: =SUM('Pro-Forma'!C44:C53) | E7: =SUM('Pro-Forma'!C44:C53) | F7: =SUM('Pro-Forma'!C44:C53)
A8: F_LEAD secondary common | B8: ='Pro-Forma'!C72 | C8: ='Pro-Forma'!C72 | D8: ='Pro-Forma'!C72 | E8: ='Pro-Forma'!C72 | F8: ='Pro-Forma'!C72
A9: Notes A+B (combined) | B9: =('Pro-Forma'!C69+'Pro-Forma'!C70) | C9: =('Pro-Forma'!C69+'Pro-Forma'!C70) | D9: =('Pro-Forma'!C69+'Pro-Forma'!C70) | E9: =('Pro-Forma'!C69+'Pro-Forma'!C70) | F9: =('Pro-Forma'!C69+'Pro-Forma'!C70)
A10: Issued options (pre-strike) | B10: =Assumptions!$B$48 | C10: =Assumptions!$B$48 | D10: =Assumptions!$B$48 | E10: =Assumptions!$B$48 | F10: =Assumptions!$B$48
A11: Pool if all convert (no options) | B11: =('Pro-Forma'!C71+'Pro-Forma'!C73)+SUM('Pro-Forma'!C59:C68)+'Pro-Forma'!C58+'Pro-Forma'!C57+'Pro-Forma'!C56+'Pro-Forma'!C55+'Pro-Forma'!C54+'Pro-Forma'!C41+'Pro-Forma'!C42+'Pro-Forma'!C43+SUM('Pro-Forma'!C44:C53)+'Pro-Forma'!C72+('Pro-Forma'!C69+'Pro-Forma'!C70) | C11: =('Pro-Forma'!C71+'Pro-Forma'!C73)+SUM('Pro-Forma'!C59:C68)+'Pro-Forma'!C58+'Pro-Forma'!C57+'Pro-Forma'!C56+'Pro-Forma'!C55+'Pro-Forma'!C54+'Pro-Forma'!C41+'Pro-Forma'!C42+'Pro-Forma'!C43+SUM('Pro-Forma'!C44:C53)+'Pro-Forma'!C72+('Pro-Forma'!C69+'Pro-Forma'!C70) | D11: =('Pro-Forma'!C71+'Pro-Forma'!C73)+SUM('Pro-Forma'!C59:C68)+'Pro-Forma'!C58+'Pro-Forma'!C57+'Pro-Forma'!C56+'Pro-Forma'!C55+'Pro-Forma'!C54+'Pro-Forma'!C41+'Pro-Forma'!C42+'Pro-Forma'!C43+SUM('Pro-Forma'!C44:C53)+'Pro-Forma'!C72+('Pro-Forma'!C69+'Pro-Forma'!C70) | E11: =('Pro-Forma'!C71+'Pro-Forma'!C73)+SUM('Pro-Forma'!C59:C68)+'Pro-Forma'!C58+'Pro-Forma'!C57+'Pro-Forma'!C56+'Pro-Forma'!C55+'Pro-Forma'!C54+'Pro-Forma'!C41+'Pro-Forma'!C42+'Pro-Forma'!C43+SUM('Pro-Forma'!C44:C53)+'Pro-Forma'!C72+('Pro-Forma'!C69+'Pro-Forma'!C70) | F11: =('Pro-Forma'!C71+'Pro-Forma'!C73)+SUM('Pro-Forma'!C59:C68)+'Pro-Forma'!C58+'Pro-Forma'!C57+'Pro-Forma'!C56+'Pro-Forma'!C55+'Pro-Forma'!C54+'Pro-Forma'!C41+'Pro-Forma'!C42+'Pro-Forma'!C43+SUM('Pro-Forma'!C44:C53)+'Pro-Forma'!C72+('Pro-Forma'!C69+'Pro-Forma'!C70)
A12: Pool with options | B12: =B11+Assumptions!$B$48 | C12: =C11+Assumptions!$B$48 | D12: =D11+Assumptions!$B$48 | E12: =E11+Assumptions!$B$48 | F12: =F11+Assumptions!$B$48
A13: Tentative PPS (all convert, options in) | B13: =(B4+Assumptions!$B$11*Assumptions!$B$48)/B12 | C13: =(C4+Assumptions!$B$11*Assumptions!$B$48)/C12 | D13: =(D4+Assumptions!$B$11*Assumptions!$B$48)/D12 | E13: =(E4+Assumptions!$B$11*Assumptions!$B$48)/E12 | F13: =(F4+Assumptions!$B$11*Assumptions!$B$48)/F12
A14: Options ITM? | B14: =IF(B13>Assumptions!$B$11,"YES","NO") | C14: =IF(C13>Assumptions!$B$11,"YES","NO") | D14: =IF(D13>Assumptions!$B$11,"YES","NO") | E14: =IF(E13>Assumptions!$B$11,"YES","NO") | F14: =IF(F13>Assumptions!$B$11,"YES","NO")
A15: Effective pool (ITM-aware) | B15: =IF(B14="YES",B12,B11) | C15: =IF(C14="YES",C12,C11) | D15: =IF(D14="YES",D12,D11) | E15: =IF(E14="YES",E12,E11) | F15: =IF(F14="YES",F12,F11)
A16: Adjusted exit (incl. strike if ITM) | B16: =IF(B14="YES",B4+Assumptions!$B$11*Assumptions!$B$48,B4) | C16: =IF(C14="YES",C4+Assumptions!$B$11*Assumptions!$B$48,C4) | D16: =IF(D14="YES",D4+Assumptions!$B$11*Assumptions!$B$48,D4) | E16: =IF(E14="YES",E4+Assumptions!$B$11*Assumptions!$B$48,E4) | F16: =IF(F14="YES",F4+Assumptions!$B$11*Assumptions!$B$48,F4)
A18: ELECTIONS (seniority F>E>D>C>B>A>Seed)
A20: F: election | B20: =IF(Assumptions!$B$5>(('Pro-Forma'!C71+'Pro-Forma'!C73))*(B16-(0))/(B15-(0)),"preference","convert") | C20: =IF(Assumptions!$B$5>(('Pro-Forma'!C71+'Pro-Forma'!C73))*(C16-(0))/(C15-(0)),"preference","convert") | D20: =IF(Assumptions!$B$5>(('Pro-Forma'!C71+'Pro-Forma'!C73))*(D16-(0))/(D15-(0)),"preference","convert") | E20: =IF(Assumptions!$B$5>(('Pro-Forma'!C71+'Pro-Forma'!C73))*(E16-(0))/(E15-(0)),"preference","convert") | F20: =IF(Assumptions!$B$5>(('Pro-Forma'!C71+'Pro-Forma'!C73))*(F16-(0))/(F15-(0)),"preference","convert")
A21: F: pref taken (USD) | B21: =IF(B20="preference",Assumptions!$B$5,0) | C21: =IF(C20="preference",Assumptions!$B$5,0) | D21: =IF(D20="preference",Assumptions!$B$5,0) | E21: =IF(E20="preference",Assumptions!$B$5,0) | F21: =IF(F20="preference",Assumptions!$B$5,0)
A22: F: pool loss (shares) | B22: =IF(B20="preference",('Pro-Forma'!C71+'Pro-Forma'!C73),0) | C22: =IF(C20="preference",('Pro-Forma'!C71+'Pro-Forma'!C73),0) | D22: =IF(D20="preference",('Pro-Forma'!C71+'Pro-Forma'!C73),0) | E22: =IF(E20="preference",('Pro-Forma'!C71+'Pro-Forma'!C73),0) | F22: =IF(F20="preference",('Pro-Forma'!C71+'Pro-Forma'!C73),0)
A23: E: election | B23: =IF(Assumptions!$B$35>(SUM('Pro-Forma'!C59:C68))*(B16-(B21))/(B15-(B22)),"preference","convert") | C23: =IF(Assumptions!$B$35>(SUM('Pro-Forma'!C59:C68))*(C16-(C21))/(C15-(C22)),"preference","convert") | D23: =IF(Assumptions!$B$35>(SUM('Pro-Forma'!C59:C68))*(D16-(D21))/(D15-(D22)),"preference","convert") | E23: =IF(Assumptions!$B$35>(SUM('Pro-Forma'!C59:C68))*(E16-(E21))/(E15-(E22)),"preference","convert") | F23: =IF(Assumptions!$B$35>(SUM('Pro-Forma'!C59:C68))*(F16-(F21))/(F15-(F22)),"preference","convert")
A24: E: pref taken (USD) | B24: =IF(B23="preference",Assumptions!$B$35,0) | C24: =IF(C23="preference",Assumptions!$B$35,0) | D24: =IF(D23="preference",Assumptions!$B$35,0) | E24: =IF(E23="preference",Assumptions!$B$35,0) | F24: =IF(F23="preference",Assumptions!$B$35,0)
A25: E: pool loss (shares) | B25: =IF(B23="preference",SUM('Pro-Forma'!C59:C68),0) | C25: =IF(C23="preference",SUM('Pro-Forma'!C59:C68),0) | D25: =IF(D23="preference",SUM('Pro-Forma'!C59:C68),0) | E25: =IF(E23="preference",SUM('Pro-Forma'!C59:C68),0) | F25: =IF(F23="preference",SUM('Pro-Forma'!C59:C68),0)
A26: D: election | B26: =IF(Assumptions!$B$34>('Pro-Forma'!C58)*(B16-(B21+B24))/(B15-(B22+B25)),"preference","convert") | C26: =IF(Assumptions!$B$34>('Pro-Forma'!C58)*(C16-(C21+C24))/(C15-(C22+C25)),"preference","convert") | D26: =IF(Assumptions!$B$34>('Pro-Forma'!C58)*(D16-(D21+D24))/(D15-(D22+D25)),"preference","convert") | E26: =IF(Assumptions!$B$34>('Pro-Forma'!C58)*(E16-(E21+E24))/(E15-(E22+E25)),"preference","convert") | F26: =IF(Assumptions!$B$34>('Pro-Forma'!C58)*(F16-(F21+F24))/(F15-(F22+F25)),"preference","convert")
A27: D: pref taken (USD) | B27: =IF(B26="preference",Assumptions!$B$34,0) | C27: =IF(C26="preference",Assumptions!$B$34,0) | D27: =IF(D26="preference",Assumptions!$B$34,0) | E27: =IF(E26="preference",Assumptions!$B$34,0) | F27: =IF(F26="preference",Assumptions!$B$34,0)
A28: D: pool loss (shares) | B28: =IF(B26="preference",'Pro-Forma'!C58,0) | C28: =IF(C26="preference",'Pro-Forma'!C58,0) | D28: =IF(D26="preference",'Pro-Forma'!C58,0) | E28: =IF(E26="preference",'Pro-Forma'!C58,0) | F28: =IF(F26="preference",'Pro-Forma'!C58,0)
A29: C: election | B29: =IF(Assumptions!$B$33>('Pro-Forma'!C57)*(B16-(B21+B24+B27))/(B15-(B22+B25+B28)),"preference","convert") | C29: =IF(Assumptions!$B$33>('Pro-Forma'!C57)*(C16-(C21+C24+C27))/(C15-(C22+C25+C28)),"preference","convert") | D29: =IF(Assumptions!$B$33>('Pro-Forma'!C57)*(D16-(D21+D24+D27))/(D15-(D22+D25+D28)),"preference","convert") | E29: =IF(Assumptions!$B$33>('Pro-Forma'!C57)*(E16-(E21+E24+E27))/(E15-(E22+E25+E28)),"preference","convert") | F29: =IF(Assumptions!$B$33>('Pro-Forma'!C57)*(F16-(F21+F24+F27))/(F15-(F22+F25+F28)),"preference","convert")
A30: C: pref taken (USD) | B30: =IF(B29="preference",Assumptions!$B$33,0) | C30: =IF(C29="preference",Assumptions!$B$33,0) | D30: =IF(D29="preference",Assumptions!$B$33,0) | E30: =IF(E29="preference",Assumptions!$B$33,0) | F30: =IF(F29="preference",Assumptions!$B$33,0)
A31: C: pool loss (shares) | B31: =IF(B29="preference",'Pro-Forma'!C57,0) | C31: =IF(C29="preference",'Pro-Forma'!C57,0) | D31: =IF(D29="preference",'Pro-Forma'!C57,0) | E31: =IF(E29="preference",'Pro-Forma'!C57,0) | F31: =IF(F29="preference",'Pro-Forma'!C57,0)
A32: B: election | B32: =IF(Assumptions!$B$32>('Pro-Forma'!C56)*(B16-(B21+B24+B27+B30))/(B15-(B22+B25+B28+B31)),"preference","convert") | C32: =IF(Assumptions!$B$32>('Pro-Forma'!C56)*(C16-(C21+C24+C27+C30))/(C15-(C22+C25+C28+C31)),"preference","convert") | D32: =IF(Assumptions!$B$32>('Pro-Forma'!C56)*(D16-(D21+D24+D27+D30))/(D15-(D22+D25+D28+D31)),"preference","convert") | E32: =IF(Assumptions!$B$32>('Pro-Forma'!C56)*(E16-(E21+E24+E27+E30))/(E15-(E22+E25+E28+E31)),"preference","convert") | F32: =IF(Assumptions!$B$32>('Pro-Forma'!C56)*(F16-(F21+F24+F27+F30))/(F15-(F22+F25+F28+F31)),"preference","convert")
A33: B: pref taken (USD) | B33: =IF(B32="preference",Assumptions!$B$32,0) | C33: =IF(C32="preference",Assumptions!$B$32,0) | D33: =IF(D32="preference",Assumptions!$B$32,0) | E33: =IF(E32="preference",Assumptions!$B$32,0) | F33: =IF(F32="preference",Assumptions!$B$32,0)
A34: B: pool loss (shares) | B34: =IF(B32="preference",'Pro-Forma'!C56,0) | C34: =IF(C32="preference",'Pro-Forma'!C56,0) | D34: =IF(D32="preference",'Pro-Forma'!C56,0) | E34: =IF(E32="preference",'Pro-Forma'!C56,0) | F34: =IF(F32="preference",'Pro-Forma'!C56,0)
A35: A: election | B35: =IF(Assumptions!$B$31>('Pro-Forma'!C55)*(B16-(B21+B24+B27+B30+B33))/(B15-(B22+B25+B28+B31+B34)),"preference","convert") | C35: =IF(Assumptions!$B$31>('Pro-Forma'!C55)*(C16-(C21+C24+C27+C30+C33))/(C15-(C22+C25+C28+C31+C34)),"preference","convert") | D35: =IF(Assumptions!$B$31>('Pro-Forma'!C55)*(D16-(D21+D24+D27+D30+D33))/(D15-(D22+D25+D28+D31+D34)),"preference","convert") | E35: =IF(Assumptions!$B$31>('Pro-Forma'!C55)*(E16-(E21+E24+E27+E30+E33))/(E15-(E22+E25+E28+E31+E34)),"preference","convert") | F35: =IF(Assumptions!$B$31>('Pro-Forma'!C55)*(F16-(F21+F24+F27+F30+F33))/(F15-(F22+F25+F28+F31+F34)),"preference","convert")
A36: A: pref taken (USD) | B36: =IF(B35="preference",Assumptions!$B$31,0) | C36: =IF(C35="preference",Assumptions!$B$31,0) | D36: =IF(D35="preference",Assumptions!$B$31,0) | E36: =IF(E35="preference",Assumptions!$B$31,0) | F36: =IF(F35="preference",Assumptions!$B$31,0)
A37: A: pool loss (shares) | B37: =IF(B35="preference",'Pro-Forma'!C55,0) | C37: =IF(C35="preference",'Pro-Forma'!C55,0) | D37: =IF(D35="preference",'Pro-Forma'!C55,0) | E37: =IF(E35="preference",'Pro-Forma'!C55,0) | F37: =IF(F35="preference",'Pro-Forma'!C55,0)
A38: Seed: election | B38: =IF(Assumptions!$B$30>('Pro-Forma'!C54)*(B16-(B21+B24+B27+B30+B33+B36))/(B15-(B22+B25+B28+B31+B34+B37)),"preference","convert") | C38: =IF(Assumptions!$B$30>('Pro-Forma'!C54)*(C16-(C21+C24+C27+C30+C33+C36))/(C15-(C22+C25+C28+C31+C34+C37)),"preference","convert") | D38: =IF(Assumptions!$B$30>('Pro-Forma'!C54)*(D16-(D21+D24+D27+D30+D33+D36))/(D15-(D22+D25+D28+D31+D34+D37)),"preference","convert") | E38: =IF(Assumptions!$B$30>('Pro-Forma'!C54)*(E16-(E21+E24+E27+E30+E33+E36))/(E15-(E22+E25+E28+E31+E34+E37)),"preference","convert") | F38: =IF(Assumptions!$B$30>('Pro-Forma'!C54)*(F16-(F21+F24+F27+F30+F33+F36))/(F15-(F22+F25+F28+F31+F34+F37)),"preference","convert")
A39: Seed: pref taken (USD) | B39: =IF(B38="preference",Assumptions!$B$30,0) | C39: =IF(C38="preference",Assumptions!$B$30,0) | D39: =IF(D38="preference",Assumptions!$B$30,0) | E39: =IF(E38="preference",Assumptions!$B$30,0) | F39: =IF(F38="preference",Assumptions!$B$30,0)
A40: Seed: pool loss (shares) | B40: =IF(B38="preference",'Pro-Forma'!C54,0) | C40: =IF(C38="preference",'Pro-Forma'!C54,0) | D40: =IF(D38="preference",'Pro-Forma'!C54,0) | E40: =IF(E38="preference",'Pro-Forma'!C54,0) | F40: =IF(F38="preference",'Pro-Forma'!C54,0)
A41: Total prefs taken (USD) | B41: =B21+B24+B27+B30+B33+B36+B39 | C41: =C21+C24+C27+C30+C33+C36+C39 | D41: =D21+D24+D27+D30+D33+D36+D39 | E41: =E21+E24+E27+E30+E33+E36+E39 | F41: =F21+F24+F27+F30+F33+F36+F39
A42: Total pool losses (shares) | B42: =B22+B25+B28+B31+B34+B37+B40 | C42: =C22+C25+C28+C31+C34+C37+C40 | D42: =D22+D25+D28+D31+D34+D37+D40 | E42: =E22+E25+E28+E31+E34+E37+E40 | F42: =F22+F25+F28+F31+F34+F37+F40
...

Sheet Sensitivity
A1: Sensitivity: Our $10M check at $2B exit
A2: 3×3 grid: ESOP refresh × Series F pre-money
A4: ESOP \ Pre-money | B4: $1.2B | C4: $1.4B | D4: $1.8B | F4: $ Proceeds | G4: $1.2B | H4: $1.4B | I4: $1.8B
A5: ESOP 11% | B5: ='Sensitivity'!B60 | C5: ='Sensitivity'!B160 | D5: ='Sensitivity'!B260 | F5: ESOP 11% | G5: ='Sensitivity'!B88 | H5: ='Sensitivity'!B188 | I5: ='Sensitivity'!B288
A6: ESOP 13% | B6: ='Sensitivity'!B360 | C6: ='Sensitivity'!B460 | D6: ='Sensitivity'!B560 | F6: ESOP 13% | G6: ='Sensitivity'!B388 | H6: ='Sensitivity'!B488 | I6: ='Sensitivity'!B588
A7: ESOP 15% | B7: ='Sensitivity'!B660 | C7: ='Sensitivity'!B760 | D7: ='Sensitivity'!B860 | F7: ESOP 15% | G7: ='Sensitivity'!B688 | H7: ='Sensitivity'!B788 | I7: ='Sensitivity'!B888
A10: --- SCRATCH BLOCKS (per-scenario fixed-point solve at $2B exit) ---
A12: Scenario [esop=11%, pre=$1.2B]
A13: ESOP target | B13: =Assumptions!$B$67
A14: Pre-money | B14: =Assumptions!$B$70
A16: k | B16: F_PPS_k | C16: nA_k | D16: nB_k | E16: AD_x | F16: F_pri | G16: topup_p | H16: topup | I16: pmFD | J16: T_F | K16: pmFD_A | L16: pmFD_B | M16: cap_A | N16: disc_A | O16: conv_A | P16: cap_B | Q16: disc_B | R16: conv_B | S16: F_PPS_n | T16: nA_n | U16: nB_n
A17: 0 | B17: =$B$14/Assumptions!$B$50 | C17: 0 | D17: 0 | E17: =MAX(0,Assumptions!$B$34/IF(B17<Assumptions!$B$25,Assumptions!$B$25*(Assumptions!$B$50+Assumptions!$B$5/Assumptions!$B$25)/(Assumptions!$B$50+Assumptions!$B$5/B17),Assumptions!$B$25)-Assumptions!$B$42)+MAX(0,Assumptions!$B$35/IF(B17<Assumptions!$B$26,Assumptions!$B$26*(Assumptions!$B$50+Assumptions!$B$5/Assumptions!$B$26)/(Assumptions!$B$50+Assumptions!$B$5/B17),Assumptions!$B$26)-Assumptions!$B$43) | F17: =Assumptions!$B$5/B17 | G17: =$B$13*(((Assumptions!$B$50-Assumptions!$B$51+E17+C17+D17)+F17)/(1-$B$13))-Assumptions!$B$51 | H17: =MAX(0,G17) | I17: =Assumptions!$B$50+E17+H17+C17+D17 | J17: =I17+F17 | K17: =Assumptions!$B$50+E17+H17+D17 | L17: =Assumptions!$B$50+E17+H17+C17 | M17: =Assumptions!$B$60/K17 | N17: =B17*(1-Assumptions!$B$61) | O17: =MIN(M17,N17) | P17: =Assumptions!$B$63/L17 | Q17: =B17*(1-Assumptions!$B$64) | R17: =MIN(P17,Q17) | S17: =$B$14/I17 | T17: =Assumptions!$B$59/O17 | U17: =Assumptions!$B$62/R17
A18: 1 | B18: =S17 | C18: =T17 | D18: =U17 | E18: =MAX(0,Assumptions!$B$34/IF(B18<Assumptions!$B$25,Assumptions!$B$25*(Assumptions!$B$50+Assumptions!$B$5/Assumptions!$B$25)/(Assumptions!$B$50+Assumptions!$B$5/B18),Assumptions!$B$25)-Assumptions!$B$42)+MAX(0,Assumptions!$B$35/IF(B18<Assumptions!$B$26,Assumptions!$B$26*(Assumptions!$B$50+Assumptions!$B$5/Assumptions!$B$26)/(Assumptions!$B$50+Assumptions!$B$5/B18),Assumptions!$B$26)-Assumptions!$B$43) | F18: =Assumptions!$B$5/B18 | G18: =$B$13*(((Assumptions!$B$50-Assumptions!$B$51+E18+C18+D18)+F18)/(1-$B$13))-Assumptions!$B$51 | H18: =MAX(0,G18) | I18: =Assumptions!$B$50+E18+H18+C18+D18 | J18: =I18+F18 | K18: =Assumptions!$B$50+E18+H18+D18 | L18: =Assumptions!$B$50+E18+H18+C18 | M18: =Assumptions!$B$60/K18 | N18: =B18*(1-Assumptions!$B$61) | O18: =MIN(M18,N18) | P18: =Assumptions!$B$63/L18 | Q18: =B18*(1-Assumptions!$B$64) | R18: =MIN(P18,Q18) | S18: =$B$14/I18 | T18: =Assumptions!$B$59/O18 | U18: =Assumptions!$B$62/R18
A19: 2 | B19: =S18 | C19: =T18 | D19: =U18 | E19: =MAX(0,Assumptions!$B$34/IF(B19<Assumptions!$B$25,Assumptions!$B$25*(Assumptions!$B$50+Assumptions!$B$5/Assumptions!$B$25)/(Assumptions!$B$50+Assumptions!$B$5/B19),Assumptions!$B$25)-Assumptions!$B$42)+MAX(0,Assumptions!$B$35/IF(B19<Assumptions!$B$26,Assumptions!$B$26*(Assumptions!$B$50+Assumptions!$B$5/Assumptions!$B$26)/(Assumptions!$B$50+Assumptions!$B$5/B19),Assumptions!$B$26)-Assumptions!$B$43) | F19: =Assumptions!$B$5/B19 | G19: =$B$13*(((Assumptions!$B$50-Assumptions!$B$51+E19+C19+D19)+F19)/(1-$B$13))-Assumptions!$B$51 | H19: =MAX(0,G19) | I19: =Assumptions!$B$50+E19+H19+C19+D19 | J19: =I19+F19 | K19: =Assumptions!$B$50+E19+H19+D19 | L19: =Assumptions!$B$50+E19+H19+C19 | M19: =Assumptions!$B$60/K19 | N19: =B19*(1-Assumptions!$B$61) | O19: =MIN(M19,N19) | P19: =Assumptions!$B$63/L19 | Q19: =B19*(1-Assumptions!$B$64) | R19: =MIN(P19,Q19) | S19: =$B$14/I19 | T19: =Assumptions!$B$59/O19 | U19: =Assumptions!$B$62/R19
A20: 3 | B20: =S19 | C20: =T19 | D20: =U19 | E20: =MAX(0,Assumptions!$B$34/IF(B20<Assumptions!$B$25,Assumptions!$B$25*(Assumptions!$B$50+Assumptions!$B$5/Assumptions!$B$25)/(Assumptions!$B$50+Assumptions!$B$5/B20),Assumptions!$B$25)-Assumptions!$B$42)+MAX(0,Assumptions!$B$35/IF(B20<Assumptions!$B$26,Assumptions!$B$26*(Assumptions!$B$50+Assumptions!$B$5/Assumptions!$B$26)/(Assumptions!$B$50+Assumptions!$B$5/B20),Assumptions!$B$26)-Assumptions!$B$43) | F20: =Assumptions!$B$5/B20 | G20: =$B$13*(((Assumptions!$B$50-Assumptions!$B$51+E20+C20+D20)+F20)/(1-$B$13))-Assumptions!$B$51 | H20: =MAX(0,G20) | I20: =Assumptions!$B$50+E20+H20+C20+D20 | J20: =I20+F20 | K20: =Assumptions!$B$50+E20+H20+D20 | L20: =Assumptions!$B$50+E20+H20+C20 | M20: =Assumptions!$B$60/K20 | N20: =B20*(1-Assumptions!$B$61) | O20: =MIN(M20,N20) | P20: =Assumptions!$B$63/L20 | Q20: =B20*(1-Assumptions!$B$64) | R20: =MIN(P20,Q20) | S20: =$B$14/I20 | T20: =Assumptions!$B$59/O20 | U20: =Assumptions!$B$62/R20
A21: 4 | B21: =S20 | C21: =T20 | D21: =U20 | E21: =MAX(0,Assumptions!$B$34/IF(B21<Assumptions!$B$25,Assumptions!$B$25*(Assumptions!$B$50+Assumptions!$B$5/Assumptions!$B$25)/(Assumptions!$B$50+Assumptions!$B$5/B21),Assumptions!$B$25)-Assumptions!$B$42)+MAX(0,Assumptions!$B$35/IF(B21<Assumptions!$B$26,Assumptions!$B$26*(Assumptions!$B$50+Assumptions!$B$5/Assumptions!$B$26)/(Assumptions!$B$50+Assumptions!$B$5/B21),Assumptions!$B$26)-Assumptions!$B$43) | F21: =Assumptions!$B$5/B21 | G21: =$B$13*(((Assumptions!$B$50-Assumptions!$B$51+E21+C21+D21)+F21)/(1-$B$13))-Assumptions!$B$51 | H21: =MAX(0,G21) | I21: =Assumptions!$B$50+E21+H21+C21+D21 | J21: =I21+F21 | K21: =Assumptions!$B$50+E21+H21+D21 | L21: =Assumptions!$B$50+E21+H21+C21 | M21: =Assumptions!$B$60/K21 | N21: =B21*(1-Assumptions!$B$61) | O21: =MIN(M21,N21) | P21: =Assumptions!$B$63/L21 | Q21: =B21*(1-Assumptions!$B$64) | R21: =MIN(P21,Q21) | S21: =$B$14/I21 | T21: =Assumptions!$B$59/O21 | U21: =Assumptions!$B$62/R21
A22: 5 | B22: =S21 | C22: =T21 | D22: =U21 | E22: =MAX(0,Assumptions!$B$34/IF(B22<Assumptions!$B$25,Assumptions!$B$25*(Assumptions!$B$50+Assumptions!$B$5/Assumptions!$B$25)/(Assumptions!$B$50+Assumptions!$B$5/B22),Assumptions!$B$25)-Assumptions!$B$42)+MAX(0,Assumptions!$B$35/IF(B22<Assumptions!$B$26,Assumptions!$B$26*(Assumptions!$B$50+Assumptions!$B$5/Assumptions!$B$26)/(Assumptions!$B$50+Assumptions!$B$5/B22),Assumptions!$B$26)-Assumptions!$B$43) | F22: =Assumptions!$B$5/B22 | G22: =$B$13*(((Assumptions!$B$50-Assumptions!$B$51+E22+C22+D22)+F22)/(1-$B$13))-Assumptions!$B$51 | H22: =MAX(0,G22) | I22: =Assumptions!$B$50+E22+H22+C22+D22 | J22: =I22+F22 | K22: =Assumptions!$B$50+E22+H22+D22 | L22: =Assumptions!$B$50+E22+H22+C22 | M22: =Assumptions!$B$60/K22 | N22: =B22*(1-Assumptions!$B$61) | O22: =MIN(M22,N22) | P22: =Assumptions!$B$63/L22 | Q22: =B22*(1-Assumptions!$B$64) | R22: =MIN(P22,Q22) | S22: =$B$14/I22 | T22: =Assumptions!$B$59/O22 | U22: =Assumptions!$B$62/R22
A23: 6 | B23: =S22 | C23: =T22 | D23: =U22 | E23: =MAX(0,Assumptions!$B$34/IF(B23<Assumptions!$B$25,Assumptions!$B$25*(Assumptions!$B$50+Assumptions!$B$5/Assumptions!$B$25)/(Assumptions!$B$50+Assumptions!$B$5/B23),Assumptions!$B$25)-Assumptions!$B$42)+MAX(0,Assumptions!$B$35/IF(B23<Assumptions!$B$26,Assumptions!$B$26*(Assumptions!$B$50+Assumptions!$B$5/Assumptions!$B$26)/(Assumptions!$B$50+Assumptions!$B$5/B23),Assumptions!$B$26)-Assumptions!$B$43) | F23: =Assumptions!$B$5/B23 | G23: =$B$13*(((Assumptions!$B$50-Assumptions!$B$51+E23+C23+D23)+F23)/(1-$B$13))-Assumptions!$B$51 | H23: =MAX(0,G23) | I23: =Assumptions!$B$50+E23+H23+C23+D23 | J23: =I23+F23 | K23: =Assumptions!$B$50+E23+H23+D23 | L23: =Assumptions!$B$50+E23+H23+C23 | M23: =Assumptions!$B$60/K23 | N23: =B23*(1-Assumptions!$B$61) | O23: =MIN(M23,N23) | P23: =Assumptions!$B$63/L23 | Q23: =B23*(1-Assumptions!$B$64) | R23: =MIN(P23,Q23) | S23: =$B$14/I23 | T23: =Assumptions!$B$59/O23 | U23: =Assumptions!$B$62/R23
A24: 7 | B24: =S23 | C24: =T23 | D24: =U23 | E24: =MAX(0,Assumptions!$B$34/IF(B24<Assumptions!$B$25,Assumptions!$B$25*(Assumptions!$B$50+Assumptions!$B$5/Assumptions!$B$25)/(Assumptions!$B$50+Assumptions!$B$5/B24),Assumptions!$B$25)-Assumptions!$B$42)+MAX(0,Assumptions!$B$35/IF(B24<Assumptions!$B$26,Assumptions!$B$26*(Assumptions!$B$50+Assumptions!$B$5/Assumptions!$B$26)/(Assumptions!$B$50+Assumptions!$B$5/B24),Assumptions!$B$26)-Assumptions!$B$43) | F24: =Assumptions!$B$5/B24 | G24: =$B$13*(((Assumptions!$B$50-Assumptions!$B$51+E24+C24+D24)+F24)/(1-$B$13))-Assumptions!$B$51 | H24: =MAX(0,G24) | I24: =Assumptions!$B$50+E24+H24+C24+D24 | J24: =I24+F24 | K24: =Assumptions!$B$50+E24+H24+D24 | L24: =Assumptions!$B$50+E24+H24+C24 | M24: =Assumptions!$B$60/K24 | N24: =B24*(1-Assumptions!$B$61) | O24: =MIN(M24,N24) | P24: =Assumptions!$B$63/L24 | Q24: =B24*(1-Assumptions!$B$64) | R24: =MIN(P24,Q24) | S24: =$B$14/I24 | T24: =Assumptions!$B$59/O24 | U24: =Assumptions!$B$62/R24
A25: 8 | B25: =S24 | C25: =T24 | D25: =U24 | E25: =MAX(0,Assumptions!$B$34/IF(B25<Assumptions!$B$25,Assumptions!$B$25*(Assumptions!$B$50+Assumptions!$B$5/Assumptions!$B$25)/(Assumptions!$B$50+Assumptions!$B$5/B25),Assumptions!$B$25)-Assumptions!$B$42)+MAX(0,Assumptions!$B$35/IF(B25<Assumptions!$B$26,Assumptions!$B$26*(Assumptions!$B$50+Assumptions!$B$5/Assumptions!$B$26)/(Assumptions!$B$50+Assumptions!$B$5/B25),Assumptions!$B$26)-Assumptions!$B$43) | F25: =Assumptions!$B$5/B25 | G25: =$B$13*(((Assumptions!$B$50-Assumptions!$B$51+E25+C25+D25)+F25)/(1-$B$13))-Assumptions!$B$51 | H25: =MAX(0,G25) | I25: =Assumptions!$B$50+E25+H25+C25+D25 | J25: =I25+F25 | K25: =Assumptions!$B$50+E25+H25+D25 | L25: =Assumptions!$B$50+E25+H25+C25 | M25: =Assumptions!$B$60/K25 | N25: =B25*(1-Assumptions!$B$61) | O25: =MIN(M25,N25) | P25: =Assumptions!$B$63/L25 | Q25: =B25*(1-Assumptions!$B$64) | R25: =MIN(P25,Q25) | S25: =$B$14/I25 | T25: =Assumptions!$B$59/O25 | U25: =Assumptions!$B$62/R25
A26: 9 | B26: =S25 | C26: =T25 | D26: =U25 | E26: =MAX(0,Assumptions!$B$34/IF(B26<Assumptions!$B$25,Assumptions!$B$25*(Assumptions!$B$50+Assumptions!$B$5/Assumptions!$B$25)/(Assumptions!$B$50+Assumptions!$B$5/B26),Assumptions!$B$25)-Assumptions!$B$42)+MAX(0,Assumptions!$B$35/IF(B26<Assumptions!$B$26,Assumptions!$B$26*(Assumptions!$B$50+Assumptions!$B$5/Assumptions!$B$26)/(Assumptions!$B$50+Assumptions!$B$5/B26),Assumptions!$B$26)-Assumptions!$B$43) | F26: =Assumptions!$B$5/B26 | G26: =$B$13*(((Assumptions!$B$50-Assumptions!$B$51+E26+C26+D26)+F26)/(1-$B$13))-Assumptions!$B$51 | H26: =MAX(0,G26) | I26: =Assumptions!$B$50+E26+H26+C26+D26 | J26: =I26+F26 | K26: =Assumptions!$B$50+E26+H26+D26 | L26: =Assumptions!$B$50+E26+H26+C26 | M26: =Assumptions!$B$60/K26 | N26: =B26*(1-Assumptions!$B$61) | O26: =MIN(M26,N26) | P26: =Assumptions!$B$63/L26 | Q26: =B26*(1-Assumptions!$B$64) | R26: =MIN(P26,Q26) | S26: =$B$14/I26 | T26: =Assumptions!$B$59/O26 | U26: =Assumptions!$B$62/R26
A27: 10 | B27: =S26 | C27: =T26 | D27: =U26 | E27: =MAX(0,Assumptions!$B$34/IF(B27<Assumptions!$B$25,Assumptions!$B$25*(Assumptions!$B$50+Assumptions!$B$5/Assumptions!$B$25)/(Assumptions!$B$50+Assumptions!$B$5/B27),Assumptions!$B$25)-Assumptions!$B$42)+MAX(0,Assumptions!$B$35/IF(B27<Assumptions!$B$26,Assumptions!$B$26*(Assumptions!$B$50+Assumptions!$B$5/Assumptions!$B$26)/(Assumptions!$B$50+Assumptions!$B$5/B27),Assumptions!$B$26)-Assumptions!$B$43) | F27: =Assumptions!$B$5/B27 | G27: =$B$13*(((Assumptions!$B$50-Assumptions!$B$51+E27+C27+D27)+F27)/(1-$B$13))-Assumptions!$B$51 | H27: =MAX(0,G27) | I27: =Assumptions!$B$50+E27+H27+C27+D27 | J27: =I27+F27 | K27: =Assumptions!$B$50+E27+H27+D27 | L27: =Assumptions!$B$50+E27+H27+C27 | M27: =Assumptions!$B$60/K27 | N27: =B27*(1-Assumptions!$B$61) | O27: =MIN(M27,N27) | P27: =Assumptions!$B$63/L27 | Q27: =B27*(1-Assumptions!$B$64) | R27: =MIN(P27,Q27) | S27: =$B$14/I27 | T27: =Assumptions!$B$59/O27 | U27: =Assumptions!$B$62/R27
A28: 11 | B28: =S27 | C28: =T27 | D28: =U27 | E28: =MAX(0,Assumptions!$B$34/IF(B28<Assumptions!$B$25,Assumptions!$B$25*(Assumptions!$B$50+Assumptions!$B$5/Assumptions!$B$25)/(Assumptions!$B$50+Assumptions!$B$5/B28),Assumptions!$B$25)-Assumptions!$B$42)+MAX(0,Assumptions!$B$35/IF(B28<Assumptions!$B$26,Assumptions!$B$26*(Assumptions!$B$50+Assumptions!$B$5/Assumptions!$B$26)/(Assumptions!$B$50+Assumptions!$B$5/B28),Assumptions!$B$26)-Assumptions!$B$43) | F28: =Assumptions!$B$5/B28 | G28: =$B$13*(((Assumptions!$B$50-Assumptions!$B$51+E28+C28+D28)+F28)/(1-$B$13))-Assumptions!$B$51 | H28: =MAX(0,G28) | I28: =Assumptions!$B$50+E28+H28+C28+D28 | J28: =I28+F28 | K28: =Assumptions!$B$50+E28+H28+D28 | L28: =Assumptions!$B$50+E28+H28+C28 | M28: =Assumptions!$B$60/K28 | N28: =B28*(1-Assumptions!$B$61) | O28: =MIN(M28,N28) | P28: =Assumptions!$B$63/L28 | Q28: =B28*(1-Assumptions!$B$64) | R28: =MIN(P28,Q28) | S28: =$B$14/I28 | T28: =Assumptions!$B$59/O28 | U28: =Assumptions!$B$62/R28
A29: 12 | B29: =S28 | C29: =T28 | D29: =U28 | E29: =MAX(0,Assumptions!$B$34/IF(B29<Assumptions!$B$25,Assumptions!$B$25*(Assumptions!$B$50+Assumptions!$B$5/Assumptions!$B$25)/(Assumptions!$B$50+Assumptions!$B$5/B29),Assumptions!$B$25)-Assumptions!$B$42)+MAX(0,Assumptions!$B$35/IF(B29<Assumptions!$B$26,Assumptions!$B$26*(Assumptions!$B$50+Assumptions!$B$5/Assumptions!$B$26)/(Assumptions!$B$50+Assumptions!$B$5/B29),Assumptions!$B$26)-Assumptions!$B$43) | F29: =Assumptions!$B$5/B29 | G29: =$B$13*(((Assumptions!$B$50-Assumptions!$B$51+E29+C29+D29)+F29)/(1-$B$13))-Assumptions!$B$51 | H29: =MAX(0,G29) | I29: =Assumptions!$B$50+E29+H29+C29+D29 | J29: =I29+F29 | K29: =Assumptions!$B$50+E29+H29+D29 | L29: =Assumptions!$B$50+E29+H29+C29 | M29: =Assumptions!$B$60/K29 | N29: =B29*(1-Assumptions!$B$61) | O29: =MIN(M29,N29) | P29: =Assumptions!$B$63/L29 | Q29: =B29*(1-Assumptions!$B$64) | R29: =MIN(P29,Q29) | S29: =$B$14/I29 | T29: =Assumptions!$B$59/O29 | U29: =Assumptions!$B$62/R29
... A47: 30 | B47: =S46 | C47: =T46 | D47: =U46 | E47: =MAX(0,Assumptions!$B$34/IF(B47<Assumptions!$B$25,Assumptions!$B$25*(Assumptions!$B$50+Assumptions!$B$5/Assumptions!$B$25)/(Assumptions!$B$50+Assumptions!$B$5/B47),Assumptions!$B$25)-Assumptions!$B$42)+MAX(0,Assumptions!$B$35/IF(B47<Assumptions!$B$26,Assumptions!$B$26*(Assumptions!$B$50+Assumptions!$B$5/Assumptions!$B$26)/(Assumptions!$B$50+Assumptions!$B$5/B47),Assumptions!$B$26)-Assumptions!$B$43) | F47: =Assumptions!$B$5/B47 | G47: =$B$13*(((Assumptions!$B$50-Assumptions!$B$51+E47+C47+D47)+F47)/(1-$B$13))-Assumptions!$B$51 | H47: =MAX(0,G47) | I47: =Assumptions!$B$50+E47+H47+C47+D47 | J47: =I47+F47 | K47: =Assumptions!$B$50+E47+H47+D47 | L47: =Assumptions!$B$50+E47+H47+C47 | M47: =Assumptions!$B$60/K47 | N47: =B47*(1-Assumptions!$B$61) | O47: =MIN(M47,N47) | P47: =Assumptions!$B$63/L47 | Q47: =B47*(1-Assumptions!$B$64) | R47: =MIN(P47,Q47) | S47: =$B$14/I47 | T47: =Assumptions!$B$59/O47 | U47: =Assumptions!$B$62/R47
A49: Solved F_PPS | B49: =B47
A50: Solved pmFD | B50: =I47
A51: Solved T_F | B51: =J47
A52: Solved AD_extra | B52: =E47
A53: Solved topup | B53: =H47
A54: Solved nA | B54: =C47
A55: Solved nB | B55: =D47
A56: Branch A | B56: =IF(M47<N47,"cap","discount")
A57: Branch B | B57: =IF(P47<Q47,"cap","discount")
A59: Fund shares | B59: =Assumptions!$B$9/B47
A60: Fund ownership % | B60: =B59/J47
A61: Tender shares | B61: =Assumptions!$B$6/(Assumptions!$B$7*B47)
A62: ITM test PPS | B62: =(Assumptions!$B$16+Assumptions!$B$11*Assumptions!$B$48)/(F47+(Assumptions!$B$35/IF(B47<Assumptions!$B$26,Assumptions!$B$26*(Assumptions!$B$50+Assumptions!$B$5/Assumptions!$B$26)/(Assumptions!$B$50+Assumptions!$B$5/B47),Assumptions!$B$26))+(Assumptions!$B$34/IF(B47<Assumptions!$B$25,Assumptions!$B$25*(Assumptions!$B$50+Assumptions!$B$5/Assumptions!$B$25)/(Assumptions!$B$50+Assumptions!$B$5/B47),Assumptions!$B$25))+Assumptions!$B$41+Assumptions!$B$40+Assumptions!$B$39+Assumptions!$B$38+(Assumptions!$B$44+Assumptions!$B$45+Assumptions!$B$46-B61)+Assumptions!$B$47+B61+(C47+D47)+Assumptions!$B$48)
A63: ITM? | B63: =IF(B62>Assumptions!$B$11,"YES","NO")
A64: Effective pool | B64: =IF(B63="YES",(F47+(Assumptions!$B$35/IF(B47<Assumptions!$B$26,Assumptions!$B$26*(Assumptions!$B$50+Assumptions!$B$5/Assumptions!$B$26)/(Assumptions!$B$50+Assumptions!$B$5/B47),Assumptions!$B$26))+(Assumptions!$B$34/IF(B47<Assumptions!$B$25,Assumptions!$B$25*(Assumptions!$B$50+Assumptions!$B$5/Assumptions!$B$25)/(Assumptions!$B$50+Assumptions!$B$5/B47),Assumptions!$B$25))+Assumptions!$B$41+Assumptions!$B$40+Assumptions!$B$39+Assumptions!$B$38+(Assumptions!$B$44+Assumptions!$B$45+Assumptions!$B$46-B61)+Assumptions!$B$47+B61+(C47+D47)+Assumptions!$B$48),(F47+(Assumptions!$B$35/IF(B47<Assumptions!$B$26,Assumptions!$B$26*(Assumptions!$B$50+Assumptions!$B$5/Assumptions!$B$26)/(Assumptions!$B$50+Assumptions!$B$5/B47),Assumptions!$B$26))+(Assumptions!$B$34/IF(B47<Assumptions!$B$25,Assumptions!$B$25*(Assumptions!$B$50+Assumptions!$B$5/Assumptions!$B$25)/(Assumptions!$B$50+Assumptions!$B$5/B47),Assumptions!$B$25))+Assumptions!$B$41+Assumptions!$B$40+Assumptions!$B$39+Assumptions!$B$38+(Assumptions!$B$44+Assumptions!$B$45+Assumptions!$B$46-B61)+Assumptions!$B$47+B61+(C47+D47)))
...

Sheet Return-Solver
A1: Return-Solver — F class ownership % needed for 3× / 4×
A2: Solves: x = (target_mult × fund_check) / (T_F × PPS_at_exit) × 3 (since fund holds 1/3 of F)
A3: Base-case ESOP, full waterfall including F's own election
A5: Exit | B5: Exit value | C5: F election (base) | D5: Waterfall PPS | E5: T_F (post-F FD) | F5: T_F × PPS | G5: F% needed for 3× ($30M) | H5: F% needed for 4× ($40M) | I5: 3× feasible? | J5: 4× feasible?
A6: Exit 1 | B6: =Assumptions!$B$14 | C6: =Waterfall!B20 | D6: =Waterfall!B43 | E6: ='Pro-Forma'!$J$162 | F6: =E6*D6 | G6: =IF(C6="preference","INFEASIBLE",3*Assumptions!$B$75*Assumptions!$B$9/F6) | H6: =IF(C6="preference","INFEASIBLE",3*Assumptions!$B$76*Assumptions!$B$9/F6) | I6: =IF(C6="preference","NO (F takes pref → 1× only)",IF(AND(G6>0,G6<=1),"YES","NO (>100%)")) | J6: =IF(C6="preference","NO (F takes pref → 1× only)",IF(AND(H6>0,H6<=1),"YES","NO (>100%)"))
A7: Exit 2 | B7: =Assumptions!$B$15 | C7: =Waterfall!C20 | D7: =Waterfall!C43 | E7: ='Pro-Forma'!$J$162 | F7: =E7*D7 | G7: =IF(C7="preference","INFEASIBLE",3*Assumptions!$B$75*Assumptions!$B$9/F7) | H7: =IF(C7="preference","INFEASIBLE",3*Assumptions!$B$76*Assumptions!$B$9/F7) | I7: =IF(C7="preference","NO (F takes pref → 1× only)",IF(AND(G7>0,G7<=1),"YES","NO (>100%)")) | J7: =IF(C7="preference","NO (F takes pref → 1× only)",IF(AND(H7>0,H7<=1),"YES","NO (>100%)"))
A8: Exit 3 | B8: =Assumptions!$B$16 | C8: =Waterfall!D20 | D8: =Waterfall!D43 | E8: ='Pro-Forma'!$J$162 | F8: =E8*D8 | G8: =IF(C8="preference","INFEASIBLE",3*Assumptions!$B$75*Assumptions!$B$9/F8) | H8: =IF(C8="preference","INFEASIBLE",3*Assumptions!$B$76*Assumptions!$B$9/F8) | I8: =IF(C8="preference","NO (F takes pref → 1× only)",IF(AND(G8>0,G8<=1),"YES","NO (>100%)")) | J8: =IF(C8="preference","NO (F takes pref → 1× only)",IF(AND(H8>0,H8<=1),"YES","NO (>100%)"))
A9: Exit 4 | B9: =Assumptions!$B$17 | C9: =Waterfall!E20 | D9: =Waterfall!E43 | E9: ='Pro-Forma'!$J$162 | F9: =E9*D9 | G9: =IF(C9="preference","INFEASIBLE",3*Assumptions!$B$75*Assumptions!$B$9/F9) | H9: =IF(C9="preference","INFEASIBLE",3*Assumptions!$B$76*Assumptions!$B$9/F9) | I9: =IF(C9="preference","NO (F takes pref → 1× only)",IF(AND(G9>0,G9<=1),"YES","NO (>100%)")) | J9: =IF(C9="preference","NO (F takes pref → 1× only)",IF(AND(H9>0,H9<=1),"YES","NO (>100%)"))
A10: Exit 5 | B10: =Assumptions!$B$18 | C10: =Waterfall!F20 | D10: =Waterfall!F43 | E10: ='Pro-Forma'!$J$162 | F10: =E10*D10 | G10: =IF(C10="preference","INFEASIBLE",3*Assumptions!$B$75*Assumptions!$B$9/F10) | H10: =IF(C10="preference","INFEASIBLE",3*Assumptions!$B$76*Assumptions!$B$9/F10) | I10: =IF(C10="preference","NO (F takes pref → 1× only)",IF(AND(G10>0,G10<=1),"YES","NO (>100%)")) | J10: =IF(C10="preference","NO (F takes pref → 1× only)",IF(AND(H10>0,H10<=1),"YES","NO (>100%)"))
A12: Note: at low exits where F takes preference, fund returns only its 1/3 of $30M pref = $10M (1×). 3× and 4× infeasible without changing round terms.
A13: Note: at high exits all classes (incl. F) converge — fund proceeds = (x/3)·T_F·PPS, scaling linearly in F class ownership x.
