Workbook

Sheet Assumptions
A1: Knob | B1: Value | C1: Notes
A2: series_f_pre_money_usd | B2: 1400000000 | C2: Series F pre-money valuation
A3: series_f_primary_raise_usd | B3: 30000000 | C3: Series F primary capital ($10M us + $20M F_LEAD)
A4: series_f_secondary_raise_usd | B4: 15000000 | C4: Secondary tender from founders
A5: series_f_tender_pps_multiplier | B5: 0.85 | C5: Tender PPS = mult x F_PPS
A6: esop_refresh_target_post_f | B6: 0.13 | C6: Post-F ESOP target as % of post-F FD
A7: our_fund_check_usd | B7: 10000000 | C7: Our $10M Series F primary check
A8: f_lead_primary_check_usd | B8: 20000000 | C8: F_LEAD $20M primary
A9: exit_value_1_usd | B9: 700000000 | C9: Exit 1
A10: exit_value_2_usd | B10: 1200000000 | C10: Exit 2
A11: exit_value_3_usd | B11: 2000000000 | C11: Exit 3 (sensitivity reference)
A12: exit_value_4_usd | B12: 4000000000 | C12: Exit 4
A13: exit_value_5_usd | B13: 8000000000 | C13: Exit 5
... A51: founder_f3_shares | B51: 1500000 | C51: F3 (CSO)
A52: sensitivity_esop_low | B52: 0.11
A53: sensitivity_esop_base | B53: 0.13
A54: sensitivity_esop_high | B54: 0.15
A55: sensitivity_pre_low_usd | B55: 1200000000
A56: sensitivity_pre_base_usd | B56: 1400000000
A57: sensitivity_pre_high_usd | B57: 1800000000
A58: return_multiple_3x | B58: 3
A59: return_multiple_4x | B59: 4

Sheet Pro-Forma
A1: Pro-Forma — Series F Closing
A3: Solver: F PPS fixed point
A4: F_PPS | B4: =Assumptions!$B$2/B11 -> 37.29976
A5: F primary shares | B5: =Assumptions!$B$3/B4 -> 804294.71
A6: D NCP (new) | B6: =Assumptions!$B$18*(Assumptions!$B$31+Assumptions!$B$3/Assumptions!$B$18)/(Assumptions!$B$31+Assumptions!$B$3/B4) -> 57.670905
A7: E NCP (new) | B7: =Assumptions!$B$19*(Assumptions!$B$31+Assumptions!$B$3/Assumptions!$B$19)/(Assumptions!$B$31+Assumptions!$B$3/B4) -> 48.903442
A8: D total shares post-AD (compound) | B8: =Assumptions!$B$21*Assumptions!$B$20/B6 -> 1733976.9
A9: E total shares post-AD | B9: =Assumptions!$B$23*Assumptions!$B$22/B7 -> 6134472.1
A10: ESOP top-up shares | B10: =MAX(0,Assumptions!$B$6*B12-Assumptions!$B$34) -> 589279.24
A11: Pre-money FD (ex F primary) | B11: =Assumptions!$B$31+(B8-Assumptions!$B$35)+(B9-Assumptions!$B$36)+B10+B14+B15 -> 37533753
A12: T_F (post-F FD) | B12: =B11+B5 -> 38338048
A13: FD for Note A cap (ex F primary, ex Note A's own shares) | B13: =Assumptions!$B$31+(B8-Assumptions!$B$35)+(B9-Assumptions!$B$36)+B10+B15 -> 37347018
A14: Note A shares converted | B14: =Assumptions!$B$25/MIN(Assumptions!$B$26/B13,B4*(1-Assumptions!$B$27)) -> 186735.09
A15: Note B shares converted | B15: =Assumptions!$B$28/MIN(Assumptions!$B$29/B16,B4*(1-Assumptions!$B$30)) -> 94622.908
A16: FD for Note B cap (ex F primary, ex Note B's own shares) | B16: =Assumptions!$B$31+(B8-Assumptions!$B$35)+(B9-Assumptions!$B$36)+B10+B14 -> 37439130
A17: D AD net new shares (delta vs pre-F) | B17: =B8-Assumptions!$B$35 -> 13349.943
A18: E AD net new shares (delta vs pre-F) | B18: =B9-Assumptions!$B$36 -> 31805.125
A21: Anti-Dilution Block (broad-based WA)
A22: Class | B22: OCP | C22: Trigger (F<OCP) | D22: New NCP | E22: New ratio | F22: As-converted shares
A23: Seed | B23: =Assumptions!$B$14 -> 1 | C23: =IF('Pro-Forma'!$B$4<Assumptions!$B$14,"YES","NO") -> NO | D23: =IF('Pro-Forma'!$B$4<Assumptions!$B$14,Assumptions!$B$14*(Assumptions!$B$31+Assumptions!$B$3/Assumptions!$B$14)/(Assumptions!$B$31+Assumptions!$B$3/'Pro-Forma'!$B$4),Assumptions!$B$14) -> 1 | E23: =IF('Pro-Forma'!$B$4<Assumptions!$B$14,Assumptions!$B$14/D23,1) -> 1 | F23: =IF('Pro-Forma'!$B$4<Assumptions!$B$14,Assumptions!$B$37*E23,Assumptions!$B$37) -> 5000000
A24: Series A | B24: =Assumptions!$B$15 -> 3 | C24: =IF('Pro-Forma'!$B$4<Assumptions!$B$15,"YES","NO") -> NO | D24: =IF('Pro-Forma'!$B$4<Assumptions!$B$15,Assumptions!$B$15*(Assumptions!$B$31+Assumptions!$B$3/Assumptions!$B$15)/(Assumptions!$B$31+Assumptions!$B$3/'Pro-Forma'!$B$4),Assumptions!$B$15) -> 3 | E24: =IF('Pro-Forma'!$B$4<Assumptions!$B$15,Assumptions!$B$15/D24,1) -> 1 | F24: =IF('Pro-Forma'!$B$4<Assumptions!$B$15,Assumptions!$B$38*E24,Assumptions!$B$38) -> 5000000
A25: Series B | B25: =Assumptions!$B$16 -> 10 | C25: =IF('Pro-Forma'!$B$4<Assumptions!$B$16,"YES","NO") -> NO | D25: =IF('Pro-Forma'!$B$4<Assumptions!$B$16,Assumptions!$B$16*(Assumptions!$B$31+Assumptions!$B$3/Assumptions!$B$16)/(Assumptions!$B$31+Assumptions!$B$3/'Pro-Forma'!$B$4),Assumptions!$B$16) -> 10 | E25: =IF('Pro-Forma'!$B$4<Assumptions!$B$16,Assumptions!$B$16/D25,1) -> 1 | F25: =IF('Pro-Forma'!$B$4<Assumptions!$B$16,Assumptions!$B$39*E25,Assumptions!$B$39) -> 3000000
A26: Series C | B26: =Assumptions!$B$17 -> 25 | C26: =IF('Pro-Forma'!$B$4<Assumptions!$B$17,"YES","NO") -> NO | D26: =IF('Pro-Forma'!$B$4<Assumptions!$B$17,Assumptions!$B$17*(Assumptions!$B$31+Assumptions!$B$3/Assumptions!$B$17)/(Assumptions!$B$31+Assumptions!$B$3/'Pro-Forma'!$B$4),Assumptions!$B$17) -> 25 | E26: =IF('Pro-Forma'!$B$4<Assumptions!$B$17,Assumptions!$B$17/D26,1) -> 1 | F26: =IF('Pro-Forma'!$B$4<Assumptions!$B$17,Assumptions!$B$40*E26,Assumptions!$B$40) -> 2400000
A27: Series D | B27: =Assumptions!$B$18 -> 58.118347 | C27: =IF('Pro-Forma'!$B$4<Assumptions!$B$18,"YES","NO") -> YES | D27: =IF('Pro-Forma'!$B$4<Assumptions!$B$18,Assumptions!$B$18*(Assumptions!$B$31+Assumptions!$B$3/Assumptions!$B$18)/(Assumptions!$B$31+Assumptions!$B$3/'Pro-Forma'!$B$4),Assumptions!$B$18) -> 57.670905 | E27: =Assumptions!$B$20/D27 -> 1.040386 | F27: =Assumptions!$B$21*E27 -> 1733976.9
A28: Series E | B28: =Assumptions!$B$19 -> 49.158311 | C28: =IF('Pro-Forma'!$B$4<Assumptions!$B$19,"YES","NO") -> YES | D28: =IF('Pro-Forma'!$B$4<Assumptions!$B$19,Assumptions!$B$19*(Assumptions!$B$31+Assumptions!$B$3/Assumptions!$B$19)/(Assumptions!$B$31+Assumptions!$B$3/'Pro-Forma'!$B$4),Assumptions!$B$19) -> 48.903442 | E28: =Assumptions!$B$19/D28 -> 1.0052117 | F28: =Assumptions!$B$23*E28 -> 6134472.1
A30: Convertible Notes Block
A31: Note | B31: Principal | C31: Cap-implied PPS | D31: Discount-implied PPS | E31: Conv PPS (min) | F31: Branch | G31: Shares issued
A32: Note A | B32: =Assumptions!$B$25 -> 5000000 | C32: =Assumptions!$B$26/'Pro-Forma'!$B$13 -> 26.775899 | D32: ='Pro-Forma'!$B$4*(1-Assumptions!$B$27) -> 29.839808 | E32: =MIN(C32,D32) -> 26.775899 | F32: =IF(C32<D32,"cap","discount") -> cap | G32: =B32/E32 -> 186735.09
A33: Note B | B33: =Assumptions!$B$28 -> 3000000 | C33: =Assumptions!$B$29/'Pro-Forma'!$B$16 -> 42.736035 | D33: ='Pro-Forma'!$B$4*(1-Assumptions!$B$30) -> 31.704796 | E33: =MIN(C33,D33) -> 31.704796 | F33: =IF(C33<D33,"cap","discount") -> discount | G33: =B33/E33 -> 94622.908
A35: Tender Block (secondary)
A36: Tender PPS | B36: =Assumptions!$B$5*'Pro-Forma'!$B$4 -> 31.704796
A37: Tender shares (transferred) | B37: =Assumptions!$B$4/B36 -> 473114.54
A38: F1 tendered | B38: =B37*(Assumptions!$B$49/Assumptions!$B$47) -> 291147.41
A39: F2 tendered | B39: =B37*(Assumptions!$B$50/Assumptions!$B$47) -> 181967.13
A40: F3 tendered | B40: =B37*(Assumptions!$B$51/Assumptions!$B$47) -> 109180.28
A41: F_LEAD primary shares | B41: =Assumptions!$B$8/'Pro-Forma'!$B$4 -> 536196.48
A42: F_LEAD total holding (primary + tender) | B42: =B41+B37 -> 1009311
A44: Stakeholder Cap Table (post-F FD)
A45: Stakeholder | B45: Common | C45: Preferred Class | D45: Preferred Shares | E45: Total FD | F45: % of T_F
A46: F1 (CEO) | B46: =Assumptions!$B$49-'Pro-Forma'!$B$38 -> 3763442.7 | D46: =0 -> 0 | E46: =B46+D46 -> 3763442.7 | F46: =E46/'Pro-Forma'!$B$12 -> 0.098164693
...

Sheet Waterfall
A1: Waterfall — Five Exits
A2: Item | B2: =Assumptions!$B$9 -> 700000000 | C2: =Assumptions!$B$10 -> 1200000000 | D2: =Assumptions!$B$11 -> 2000000000 | E2: =Assumptions!$B$12 -> 4000000000 | F2: =Assumptions!$B$13 -> 8000000000
A4: Elections
A5: F election | B5: =IF(B14>B23,"preference","convert") -> preference | C5: =IF(C14>C23,"preference","convert") -> preference | D5: =IF(D14>D23,"preference","convert") -> convert | E5: =IF(E14>E23,"preference","convert") -> convert | F5: =IF(F14>F23,"preference","convert") -> convert
A6: E election | B6: =IF(B15>B24,"preference","convert") -> preference | C6: =IF(C15>C24,"preference","convert") -> preference | D6: =IF(D15>D24,"preference","convert") -> convert | E6: =IF(E15>E24,"preference","convert") -> convert | F6: =IF(F15>F24,"preference","convert") -> convert
A7: D election | B7: =IF(B16>B25,"preference","convert") -> preference | C7: =IF(C16>C25,"preference","convert") -> preference | D7: =IF(D16>D25,"preference","convert") -> preference | E7: =IF(E16>E25,"preference","convert") -> convert | F7: =IF(F16>F25,"preference","convert") -> convert
A8: C election | B8: =IF(B17>B26,"preference","convert") -> preference | C8: =IF(C17>C26,"preference","convert") -> convert | D8: =IF(D17>D26,"preference","convert") -> convert | E8: =IF(E17>E26,"preference","convert") -> convert | F8: =IF(F17>F26,"preference","convert") -> convert
A9: B election | B9: =IF(B18>B27,"preference","convert") -> preference | C9: =IF(C18>C27,"preference","convert") -> convert | D9: =IF(D18>D27,"preference","convert") -> convert | E9: =IF(E18>E27,"preference","convert") -> convert | F9: =IF(F18>F27,"preference","convert") -> convert
A10: A election | B10: =IF(B19>B28,"preference","convert") -> convert | C10: =IF(C19>C28,"preference","convert") -> convert | D10: =IF(D19>D28,"preference","convert") -> convert | E10: =IF(E19>E28,"preference","convert") -> convert | F10: =IF(F19>F28,"preference","convert") -> convert
A11: Seed election | B11: =IF(B20>B29,"preference","convert") -> convert | C11: =IF(C20>C29,"preference","convert") -> convert | D11: =IF(D20>D29,"preference","convert") -> convert | E11: =IF(E20>E29,"preference","convert") -> convert | F11: =IF(F20>F29,"preference","convert") -> convert
A13: Pref payouts
A14: F pref $ | B14: =IF(B5="preference",MIN(Assumptions!$B$3,B$2),0) -> 30000000 | C14: =IF(C5="preference",MIN(Assumptions!$B$3,C$2),0) -> 30000000 | D14: =IF(D5="preference",MIN(Assumptions!$B$3,D$2),0) -> 0 | E14: =IF(E5="preference",MIN(Assumptions!$B$3,E$2),0) -> 0 | F14: =IF(F5="preference",MIN(Assumptions!$B$3,F$2),0) -> 0
A15: E pref $ | B15: =IF(B6="preference",MIN(Assumptions!$B$46,B40),0) -> 300000000 | C15: =IF(C6="preference",MIN(Assumptions!$B$46,C40),0) -> 300000000 | D15: =IF(D6="preference",MIN(Assumptions!$B$46,D40),0) -> 0 | E15: =IF(E6="preference",MIN(Assumptions!$B$46,E40),0) -> 0 | F15: =IF(F6="preference",MIN(Assumptions!$B$46,F40),0) -> 0
A16: D pref $ | B16: =IF(B7="preference",MIN(Assumptions!$B$45,B41),0) -> 100000000 | C16: =IF(C7="preference",MIN(Assumptions!$B$45,C41),0) -> 100000000 | D16: =IF(D7="preference",MIN(Assumptions!$B$45,D41),0) -> 100000000 | E16: =IF(E7="preference",MIN(Assumptions!$B$45,E41),0) -> 0 | F16: =IF(F7="preference",MIN(Assumptions!$B$45,F41),0) -> 0
A17: C pref $ | B17: =IF(B8="preference",MIN(Assumptions!$B$44,B42),0) -> 60000000 | C17: =IF(C8="preference",MIN(Assumptions!$B$44,C42),0) -> 0 | D17: =IF(D8="preference",MIN(Assumptions!$B$44,D42),0) -> 0 | E17: =IF(E8="preference",MIN(Assumptions!$B$44,E42),0) -> 0 | F17: =IF(F8="preference",MIN(Assumptions!$B$44,F42),0) -> 0
A18: B pref $ | B18: =IF(B9="preference",MIN(Assumptions!$B$43,B43),0) -> 30000000 | C18: =IF(C9="preference",MIN(Assumptions!$B$43,C43),0) -> 0 | D18: =IF(D9="preference",MIN(Assumptions!$B$43,D43),0) -> 0 | E18: =IF(E9="preference",MIN(Assumptions!$B$43,E43),0) -> 0 | F18: =IF(F9="preference",MIN(Assumptions!$B$43,F43),0) -> 0
A19: A pref $ | B19: =IF(B10="preference",MIN(Assumptions!$B$42,B44),0) -> 0 | C19: =IF(C10="preference",MIN(Assumptions!$B$42,C44),0) -> 0 | D19: =IF(D10="preference",MIN(Assumptions!$B$42,D44),0) -> 0 | E19: =IF(E10="preference",MIN(Assumptions!$B$42,E44),0) -> 0 | F19: =IF(F10="preference",MIN(Assumptions!$B$42,F44),0) -> 0
A20: Seed pref $ | B20: =IF(B11="preference",MIN(Assumptions!$B$41,B45),0) -> 0 | C20: =IF(C11="preference",MIN(Assumptions!$B$41,C45),0) -> 0 | D20: =IF(D11="preference",MIN(Assumptions!$B$41,D45),0) -> 0 | E20: =IF(E11="preference",MIN(Assumptions!$B$41,E45),0) -> 0 | F20: =IF(F11="preference",MIN(Assumptions!$B$41,F45),0) -> 0
A22: Convert payouts
A23: F conv $ | B23: =B50*'Pro-Forma'!$B$5 -> 6738963.9 | C23: =C50*'Pro-Forma'!$B$5 -> 22858228 | D23: =D50*'Pro-Forma'!$B$5 -> 44846574 | E23: =E50*'Pro-Forma'!$B$5 -> 89785811 | F23: =F50*'Pro-Forma'!$B$5 -> 1.7951554e+08
A24: E conv $ | B24: =B50*'Pro-Forma'!$B$9 -> 51399052 | C24: =C50*'Pro-Forma'!$B$9 -> 1.7434301e+08 | D24: =D50*'Pro-Forma'!$B$9 -> 3.420513e+08 | E24: =E50*'Pro-Forma'!$B$9 -> 6.8480937e+08 | F24: =F50*'Pro-Forma'!$B$9 -> 1.369191e+09
A25: D conv $ | B25: =B50*'Pro-Forma'!$B$8 -> 14528515 | C25: =C50*'Pro-Forma'!$B$8 -> 49279995 | D25: =D50*'Pro-Forma'!$B$8 -> 96684615 | E25: =E50*'Pro-Forma'!$B$8 -> 1.93569e+08 | F25: =F50*'Pro-Forma'!$B$8 -> 3.870171e+08
A26: C conv $ | B26: =B50*Assumptions!$B$40 -> 20108939 | C26: =C50*Assumptions!$B$40 -> 68208513 | D26: =D50*Assumptions!$B$40 -> 1.3382132e+08 | E26: =E50*Assumptions!$B$40 -> 2.6791914e+08 | F26: =F50*Assumptions!$B$40 -> 5.3567093e+08
A27: B conv $ | B27: =B50*Assumptions!$B$39 -> 25136174 | C27: =C50*Assumptions!$B$39 -> 85260641 | D27: =D50*Assumptions!$B$39 -> 1.6727664e+08 | E27: =E50*Assumptions!$B$39 -> 3.3489892e+08 | F27: =F50*Assumptions!$B$39 -> 6.6958866e+08
A28: A conv $ | B28: =B50*Assumptions!$B$38 -> 41893623 | C28: =C50*Assumptions!$B$38 -> 1.4210107e+08 | D28: =D50*Assumptions!$B$38 -> 2.7879441e+08 | E28: =E50*Assumptions!$B$38 -> 5.5816487e+08 | F28: =F50*Assumptions!$B$38 -> 1.1159811e+09
A29: Seed conv $ | B29: =B50*Assumptions!$B$37 -> 41893623 | C29: =C50*Assumptions!$B$37 -> 1.4210107e+08 | D29: =D50*Assumptions!$B$37 -> 2.7879441e+08 | E29: =E50*Assumptions!$B$37 -> 5.5816487e+08 | F29: =F50*Assumptions!$B$37 -> 1.1159811e+09
A31: Proceeds
A32: F proceeds | B32: =IF(B5="preference",B14,B23) -> 30000000 | C32: =IF(C5="preference",C14,C23) -> 30000000 | D32: =IF(D5="preference",D14,D23) -> 44846574 | E32: =IF(E5="preference",E14,E23) -> 89785811 | F32: =IF(F5="preference",F14,F23) -> 1.7951554e+08
A33: E proceeds | B33: =IF(B6="preference",B15,B24) -> 300000000 | C33: =IF(C6="preference",C15,C24) -> 300000000 | D33: =IF(D6="preference",D15,D24) -> 3.420513e+08 | E33: =IF(E6="preference",E15,E24) -> 6.8480937e+08 | F33: =IF(F6="preference",F15,F24) -> 1.369191e+09
A34: D proceeds | B34: =IF(B7="preference",B16,B25) -> 100000000 | C34: =IF(C7="preference",C16,C25) -> 100000000 | D34: =IF(D7="preference",D16,D25) -> 100000000 | E34: =IF(E7="preference",E16,E25) -> 1.93569e+08 | F34: =IF(F7="preference",F16,F25) -> 3.870171e+08
A35: C proceeds | B35: =IF(B8="preference",B17,B26) -> 60000000 | C35: =IF(C8="preference",C17,C26) -> 68208513 | D35: =IF(D8="preference",D17,D26) -> 1.3382132e+08 | E35: =IF(E8="preference",E17,E26) -> 2.6791914e+08 | F35: =IF(F8="preference",F17,F26) -> 5.3567093e+08
A36: B proceeds | B36: =IF(B9="preference",B18,B27) -> 30000000 | C36: =IF(C9="preference",C18,C27) -> 85260641 | D36: =IF(D9="preference",D18,D27) -> 1.6727664e+08 | E36: =IF(E9="preference",E18,E27) -> 3.3489892e+08 | F36: =IF(F9="preference",F18,F27) -> 6.6958866e+08
A37: A proceeds | B37: =IF(B10="preference",B19,B28) -> 41893623 | C37: =IF(C10="preference",C19,C28) -> 1.4210107e+08 | D37: =IF(D10="preference",D19,D28) -> 2.7879441e+08 | E37: =IF(E10="preference",E19,E28) -> 5.5816487e+08 | F37: =IF(F10="preference",F19,F28) -> 1.1159811e+09
A38: Seed proceeds | B38: =IF(B11="preference",B20,B29) -> 41893623 | C38: =IF(C11="preference",C20,C29) -> 1.4210107e+08 | D38: =IF(D11="preference",D20,D29) -> 2.7879441e+08 | E38: =IF(E11="preference",E20,E29) -> 5.5816487e+08 | F38: =IF(F11="preference",F20,F29) -> 1.1159811e+09
A40: Residual after F pref | B40: =MAX(0,B$2-IF(B5="preference",MIN(Assumptions!$B$3,B$2),0)) -> 670000000 | C40: =MAX(0,C$2-IF(C5="preference",MIN(Assumptions!$B$3,C$2),0)) -> 1170000000 | D40: =MAX(0,D$2-IF(D5="preference",MIN(Assumptions!$B$3,D$2),0)) -> 2000000000 | E40: =MAX(0,E$2-IF(E5="preference",MIN(Assumptions!$B$3,E$2),0)) -> 4000000000 | F40: =MAX(0,F$2-IF(F5="preference",MIN(Assumptions!$B$3,F$2),0)) -> 8000000000
A41: Residual after E pref | B41: =MAX(0,B40-IF(B6="preference",MIN(Assumptions!$B$46,B40),0)) -> 370000000 | C41: =MAX(0,C40-IF(C6="preference",MIN(Assumptions!$B$46,C40),0)) -> 870000000 | D41: =MAX(0,D40-IF(D6="preference",MIN(Assumptions!$B$46,D40),0)) -> 2000000000 | E41: =MAX(0,E40-IF(E6="preference",MIN(Assumptions!$B$46,E40),0)) -> 4000000000 | F41: =MAX(0,F40-IF(F6="preference",MIN(Assumptions!$B$46,F40),0)) -> 8000000000
A42: Residual after D pref | B42: =MAX(0,B41-IF(B7="preference",MIN(Assumptions!$B$45,B41),0)) -> 270000000 | C42: =MAX(0,C41-IF(C7="preference",MIN(Assumptions!$B$45,C41),0)) -> 770000000 | D42: =MAX(0,D41-IF(D7="preference",MIN(Assumptions!$B$45,D41),0)) -> 1900000000 | E42: =MAX(0,E41-IF(E7="preference",MIN(Assumptions!$B$45,E41),0)) -> 4000000000 | F42: =MAX(0,F41-IF(F7="preference",MIN(Assumptions!$B$45,F41),0)) -> 8000000000
A43: Residual after C pref | B43: =MAX(0,B42-IF(B8="preference",MIN(Assumptions!$B$44,B42),0)) -> 210000000 | C43: =MAX(0,C42-IF(C8="preference",MIN(Assumptions!$B$44,C42),0)) -> 770000000 | D43: =MAX(0,D42-IF(D8="preference",MIN(Assumptions!$B$44,D42),0)) -> 1900000000 | E43: =MAX(0,E42-IF(E8="preference",MIN(Assumptions!$B$44,E42),0)) -> 4000000000 | F43: =MAX(0,F42-IF(F8="preference",MIN(Assumptions!$B$44,F42),0)) -> 8000000000
A44: Residual after B pref | B44: =MAX(0,B43-IF(B9="preference",MIN(Assumptions!$B$43,B43),0)) -> 180000000 | C44: =MAX(0,C43-IF(C9="preference",MIN(Assumptions!$B$43,C43),0)) -> 770000000 | D44: =MAX(0,D43-IF(D9="preference",MIN(Assumptions!$B$43,D43),0)) -> 1900000000 | E44: =MAX(0,E43-IF(E9="preference",MIN(Assumptions!$B$43,E43),0)) -> 4000000000 | F44: =MAX(0,F43-IF(F9="preference",MIN(Assumptions!$B$43,F43),0)) -> 8000000000
A45: Residual after A pref | B45: =MAX(0,B44-IF(B10="preference",MIN(Assumptions!$B$42,B44),0)) -> 180000000 | C45: =MAX(0,C44-IF(C10="preference",MIN(Assumptions!$B$42,C44),0)) -> 770000000 | D45: =MAX(0,D44-IF(D10="preference",MIN(Assumptions!$B$42,D44),0)) -> 1900000000 | E45: =MAX(0,E44-IF(E10="preference",MIN(Assumptions!$B$42,E44),0)) -> 4000000000 | F45: =MAX(0,F44-IF(F10="preference",MIN(Assumptions!$B$42,F44),0)) -> 8000000000
...

Sheet Sensitivity
A1: Sensitivity — 3×3 ESOP × Pre-money @ $2B exit
A2: Each cell re-solves the full Series F fixed point + Nash waterfall at $2B.
A4: Pre-money → | B4: =Assumptions!$B$55 -> 1200000000 | C4: =Assumptions!$B$56 -> 1400000000 | D4: =Assumptions!$B$57 -> 1800000000
A5: ESOP 11% own % | B5: =B35 -> 0.0081300813 | C5: =B57 -> 0.006993007 | D5: =B79 -> 0.0054644809
A6: ESOP 13% own % | B6: =B101 -> 0.0081300813 | C6: =B123 -> 0.006993007 | D6: =B145 -> 0.0054644809
A7: ESOP 15% own % | B7: =B167 -> 0.0081300813 | C7: =B189 -> 0.006993007 | D7: =B211 -> 0.0054644809
A8: ESOP 11% $ proceeds @ $2B | B8: =B34 -> 17107259 | C8: =B56 -> 14719656 | D8: =B78 -> 11507141
A9: ESOP 13% $ proceeds @ $2B | B9: =B100 -> 17384971 | C9: =B122 -> 14948858 | D9: =B144 -> 11676569
A10: ESOP 15% $ proceeds @ $2B | B10: =B166 -> 17795003 | C10: =B188 -> 15301320 | D10: =B210 -> 11951762
A14: --- Block ESOP=0 PRE=0 ---
A15: F_PPS | B15: =Assumptions!$B$55/B22 -> 32.441295
A16: F_prim_sh | B16: =Assumptions!$B$3/B15 -> 924747.3
A17: D NCP | B17: =Assumptions!$B$18*(Assumptions!$B$31+Assumptions!$B$3/Assumptions!$B$18)/(Assumptions!$B$31+Assumptions!$B$3/B15) -> 57.485873
A18: E NCP | B18: =Assumptions!$B$19*(Assumptions!$B$31+Assumptions!$B$3/Assumptions!$B$19)/(Assumptions!$B$31+Assumptions!$B$3/B15) -> 48.74654
A19: D total | B19: =Assumptions!$B$21*Assumptions!$B$20/B17 -> 1739558.2
A20: E total | B20: =Assumptions!$B$23*Assumptions!$B$22/B18 -> 6154217.4
A21: ESOP topup | B21: =MAX(0,Assumptions!$B$52*B23-Assumptions!$B$34) -> 0
A22: Pre-money FD | B22: =Assumptions!$B$31+(B19-Assumptions!$B$35)+(B20-Assumptions!$B$36)+B21+B25+B26 -> 36989892
A23: T_F | B23: =B22+B16 -> 37914639
A24: FD for Note A cap | B24: =Assumptions!$B$31+(B19-Assumptions!$B$35)+(B20-Assumptions!$B$36)+B21+B26 -> 36797236
A25: NA shares | B25: =Assumptions!$B$25/MIN(Assumptions!$B$26/B24,B15*(1-Assumptions!$B$27)) -> 192655.69
A26: NB shares | B26: =Assumptions!$B$28/MIN(Assumptions!$B$29/B27,B15*(1-Assumptions!$B$30)) -> 108793.8
A27: FD for Note B cap | B27: =Assumptions!$B$31+(B19-Assumptions!$B$35)+(B20-Assumptions!$B$36)+B21+B25 -> 36881098
A28: Branch A | B28: =IF(Assumptions!$B$26/B24<B15*(1-Assumptions!$B$27),"cap","discount") -> discount
A29: Branch B | B29: =IF(Assumptions!$B$29/B27<B15*(1-Assumptions!$B$30),"cap","discount") -> discount
A30: Cap-implied PPS A | B30: =Assumptions!$B$26/B24 -> 27.175954
A31: Conv PPS A (min) | B31: =MIN(Assumptions!$B$26/B24,B15*(1-Assumptions!$B$27)) -> 25.953036
A32: Per-share @ $2B (all convert, ITM checked) | B32: =IF((Assumptions!$B$11+Assumptions!$B$32*Assumptions!$B$24)/((B25+B26+Assumptions!$B$47+Assumptions!$B$48+B16+B20+B19+Assumptions!$B$40+Assumptions!$B$39+Assumptions!$B$38+Assumptions!$B$37)+Assumptions!$B$32)>Assumptions!$B$24,(Assumptions!$B$11+Assumptions!$B$32*Assumptions!$B$24)/((B25+B26+Assumptions!$B$47+Assumptions!$B$48+B16+B20+B19+Assumptions!$B$40+Assumptions!$B$39+Assumptions!$B$38+Assumptions!$B$37)+Assumptions!$B$32),Assumptions!$B$11/(B25+B26+Assumptions!$B$47+Assumptions!$B$48+B16+B20+B19+Assumptions!$B$40+Assumptions!$B$39+Assumptions!$B$38+Assumptions!$B$37)) -> 55.498163
A33: Our shares (= $10M / F_PPS) | B33: =Assumptions!$B$7/B15 -> 308249.1
A34: Our $ proceeds @ $2B | B34: =B32*B33 -> 17107259
A35: Own % of T_F | B35: =B33/B23 -> 0.0081300813
A36: --- Block ESOP=0 PRE=1 ---
A37: F_PPS | B37: =Assumptions!$B$56/B44 -> 37.90205
A38: F_prim_sh | B38: =Assumptions!$B$3/B37 -> 791513.91
A39: D NCP | B39: =Assumptions!$B$18*(Assumptions!$B$31+Assumptions!$B$3/Assumptions!$B$18)/(Assumptions!$B$31+Assumptions!$B$3/B37) -> 57.690608
A40: E NCP | B40: =Assumptions!$B$19*(Assumptions!$B$31+Assumptions!$B$3/Assumptions!$B$19)/(Assumptions!$B$31+Assumptions!$B$3/B37) -> 48.92015
A41: D total | B41: =Assumptions!$B$21*Assumptions!$B$20/B39 -> 1733384.7
A42: E total | B42: =Assumptions!$B$23*Assumptions!$B$22/B40 -> 6132377
A43: ESOP topup | B43: =MAX(0,Assumptions!$B$52*B45-Assumptions!$B$34) -> 0
A44: Pre-money FD | B44: =Assumptions!$B$31+(B41-Assumptions!$B$35)+(B42-Assumptions!$B$36)+B43+B47+B48 -> 36937316
...

Sheet Return-Solver
A1: Return-Solver — Series F % needed for 3x and 4x at each exit
A3: Exit | B3: F election (Nash) | C3: Per-F-share value | D3: T_F | E3: % needed (3x) | F3: Flag 3x | G3: % needed (4x) | H3: Flag 4x
A4: =Assumptions!$B$9 -> 700000000 | B4: =Waterfall!B5 -> preference | C4: =IF(B4="preference",'Pro-Forma'!$B$4,Waterfall!B50) -> 37.29976 | D4: ='Pro-Forma'!$B$12 -> 38338048 | E4: =Assumptions!$B$58*Assumptions!$B$7/(C4*D4) -> 0.020979021 | F4: =IF(OR(E4<=0,E4>1),"INFEASIBLE","OK") -> OK | G4: =Assumptions!$B$59*Assumptions!$B$7/(C4*D4) -> 0.027972028 | H4: =IF(OR(G4<=0,G4>1),"INFEASIBLE","OK") -> OK
A5: =Assumptions!$B$10 -> 1200000000 | B5: =Waterfall!C5 -> preference | C5: =IF(B5="preference",'Pro-Forma'!$B$4,Waterfall!C50) -> 37.29976 | D5: ='Pro-Forma'!$B$12 -> 38338048 | E5: =Assumptions!$B$58*Assumptions!$B$7/(C5*D5) -> 0.020979021 | F5: =IF(OR(E5<=0,E5>1),"INFEASIBLE","OK") -> OK | G5: =Assumptions!$B$59*Assumptions!$B$7/(C5*D5) -> 0.027972028 | H5: =IF(OR(G5<=0,G5>1),"INFEASIBLE","OK") -> OK
A6: =Assumptions!$B$11 -> 2000000000 | B6: =Waterfall!D5 -> convert | C6: =IF(B6="preference",'Pro-Forma'!$B$4,Waterfall!D50) -> 55.758882 | D6: ='Pro-Forma'!$B$12 -> 38338048 | E6: =Assumptions!$B$58*Assumptions!$B$7/(C6*D6) -> 0.014033862 | F6: =IF(OR(E6<=0,E6>1),"INFEASIBLE","OK") -> OK | G6: =Assumptions!$B$59*Assumptions!$B$7/(C6*D6) -> 0.018711816 | H6: =IF(OR(G6<=0,G6>1),"INFEASIBLE","OK") -> OK
A7: =Assumptions!$B$12 -> 4000000000 | B7: =Waterfall!E5 -> convert | C7: =IF(B7="preference",'Pro-Forma'!$B$4,Waterfall!E50) -> 111.63297 | D7: ='Pro-Forma'!$B$12 -> 38338048 | E7: =Assumptions!$B$58*Assumptions!$B$7/(C7*D7) -> 0.0070096892 | F7: =IF(OR(E7<=0,E7>1),"INFEASIBLE","OK") -> OK | G7: =Assumptions!$B$59*Assumptions!$B$7/(C7*D7) -> 0.0093462523 | H7: =IF(OR(G7<=0,G7>1),"INFEASIBLE","OK") -> OK
A8: =Assumptions!$B$13 -> 8000000000 | B8: =Waterfall!F5 -> convert | C8: =IF(B8="preference",'Pro-Forma'!$B$4,Waterfall!F50) -> 223.19622 | D8: ='Pro-Forma'!$B$12 -> 38338048 | E8: =Assumptions!$B$58*Assumptions!$B$7/(C8*D8) -> 0.0035059395 | F8: =IF(OR(E8<=0,E8>1),"INFEASIBLE","OK") -> OK | G8: =Assumptions!$B$59*Assumptions!$B$7/(C8*D8) -> 0.004674586 | H8: =IF(OR(G8<=0,G8>1),"INFEASIBLE","OK") -> OK
