Workbook

Sheet Assumptions
A1: LABEL | B1: VALUE | C1: UNITS
A2: Series F pre-money | B2: 1400000000 | C2: USD
A3: Series F primary raise | B3: 30000000 | C3: USD
A4: Series F secondary raise | B4: 15000000 | C4: USD
A5: Tender PPS multiplier | B5: 0.85 | C5: fraction
A6: ESOP refresh target post-F | B6: 0.13 | C6: fraction of post-F FD
A7: Exit value 1 | B7: 700000000 | C7: USD
A8: Exit value 2 | B8: 1200000000 | C8: USD
A9: Exit value 3 | B9: 2000000000 | C9: USD
A10: Exit value 4 | B10: 4000000000 | C10: USD
A11: Exit value 5 | B11: 8000000000 | C11: USD
A12: Our fund check size | B12: 10000000 | C12: USD
A13: F_LEAD primary check size | B13: 20000000 | C13: USD
... A51: Return target multiple 4x | B51: 4 | C51: multiple

Sheet Pro-Forma
A1: PRO-FORMA — Series F closing
A3: ROUND CLOSING (closed-form fixed point)
A4: X_pos (assuming ESOP top-up > 0) | B4: =((Assumptions!$B$28-(Assumptions!$B$32*(Assumptions!$B$3/Assumptions!$B$18)/(Assumptions!$B$28+Assumptions!$B$3/Assumptions!$B$18))-(Assumptions!$B$34*(Assumptions!$B$3/Assumptions!$B$20)/(Assumptions!$B$28+Assumptions!$B$3/Assumptions!$B$20))-Assumptions!$B$29)/(1-(Assumptions!$B$32*Assumptions!$B$3/(Assumptions!$B$2*(Assumptions!$B$28+Assumptions!$B$3/Assumptions!$B$18)))-(Assumptions!$B$34*Assumptions!$B$3/(Assumptions!$B$2*(Assumptions!$B$28+Assumptions!$B$3/Assumptions!$B$20)))-(Assumptions!$B$6*(1+Assumptions!$B$3/Assumptions!$B$2))-IF((Assumptions!$B$23+Assumptions!$B$22)<Assumptions!$B$2*(1-Assumptions!$B$24),Assumptions!$B$22/(Assumptions!$B$23+Assumptions!$B$22),Assumptions!$B$22/(Assumptions!$B$2*(1-Assumptions!$B$24)))-IF((Assumptions!$B$26+Assumptions!$B$25)<Assumptions!$B$2*(1-Assumptions!$B$27),Assumptions!$B$25/(Assumptions!$B$26+Assumptions!$B$25),Assumptions!$B$25/(Assumptions!$B$2*(1-Assumptions!$B$27)))))
A5: X_zero (assuming ESOP top-up = 0) | B5: =((Assumptions!$B$28-(Assumptions!$B$32*(Assumptions!$B$3/Assumptions!$B$18)/(Assumptions!$B$28+Assumptions!$B$3/Assumptions!$B$18))-(Assumptions!$B$34*(Assumptions!$B$3/Assumptions!$B$20)/(Assumptions!$B$28+Assumptions!$B$3/Assumptions!$B$20)))/(1-(Assumptions!$B$32*Assumptions!$B$3/(Assumptions!$B$2*(Assumptions!$B$28+Assumptions!$B$3/Assumptions!$B$18)))-(Assumptions!$B$34*Assumptions!$B$3/(Assumptions!$B$2*(Assumptions!$B$28+Assumptions!$B$3/Assumptions!$B$20)))-IF((Assumptions!$B$23+Assumptions!$B$22)<Assumptions!$B$2*(1-Assumptions!$B$24),Assumptions!$B$22/(Assumptions!$B$23+Assumptions!$B$22),Assumptions!$B$22/(Assumptions!$B$2*(1-Assumptions!$B$24)))-IF((Assumptions!$B$26+Assumptions!$B$25)<Assumptions!$B$2*(1-Assumptions!$B$27),Assumptions!$B$25/(Assumptions!$B$26+Assumptions!$B$25),Assumptions!$B$25/(Assumptions!$B$2*(1-Assumptions!$B$27)))))
A6: gamma (= esop_target * (1+P/M)) | B6: =(Assumptions!$B$6*(1+Assumptions!$B$3/Assumptions!$B$2))
A7: Pre-money FD (X) — chosen | B7: =IF(B6*B4>Assumptions!$B$29,B4,B5)
A8: F PPS | B8: =Assumptions!$B$2/B7
A9: F primary new shares (= P / F_PPS) | B9: =Assumptions!$B$3/B8
A10: Post-F FD (T_F = X + F primary) | B10: =B7+B9
A11: ESOP top-up shares (= MAX(0, esop_target*T_F - pre_pool)) | B11: =MAX(0,Assumptions!$B$6*B10-Assumptions!$B$29)
A12: Series D additional shares (v4 AD) | B12: =(Assumptions!$B$32*Assumptions!$B$3/(Assumptions!$B$2*(Assumptions!$B$28+Assumptions!$B$3/Assumptions!$B$18)))*B7-(Assumptions!$B$32*(Assumptions!$B$3/Assumptions!$B$18)/(Assumptions!$B$28+Assumptions!$B$3/Assumptions!$B$18))
A13: Series E additional shares (v4 AD) | B13: =(Assumptions!$B$34*Assumptions!$B$3/(Assumptions!$B$2*(Assumptions!$B$28+Assumptions!$B$3/Assumptions!$B$20)))*B7-(Assumptions!$B$34*(Assumptions!$B$3/Assumptions!$B$20)/(Assumptions!$B$28+Assumptions!$B$3/Assumptions!$B$20))
A14: D shares post-F (= D_pre + dD) | B14: =Assumptions!$B$32+B12
A15: E shares post-F (= E_pre + dE) | B15: =Assumptions!$B$34+B13
A16: Tender shares (= secondary / (mult * F_PPS)) | B16: =Assumptions!$B$4/(Assumptions!$B$5*B8)
A17: F_LEAD primary shares (= 20M / F_PPS) | B17: =Assumptions!$B$13/B8
A19: ANTI-DILUTION BLOCK (broad-based weighted-average)
A20: Class | B20: OCP | C20: F PPS | D20: Triggered | E20: NCP | F20: New ratio | G20: As-converted shares
A21: Seed | B21: =Assumptions!$B$14 | C21: =$B$8 | D21: =IF($B$8<Assumptions!$B$14,"yes","no") | E21: =IF($B$8<Assumptions!$B$14,Assumptions!$B$14*(Assumptions!$B$28+Assumptions!$B$3/Assumptions!$B$14)/(Assumptions!$B$28+Assumptions!$B$3/$B$8),Assumptions!$B$14) | F21: =IF($B$8<Assumptions!$B$14,Assumptions!$B$14/E21,1) | G21: =Assumptions!$B$35*F21
A22: Series A | B22: =Assumptions!$B$15 | C22: =$B$8 | D22: =IF($B$8<Assumptions!$B$15,"yes","no") | E22: =IF($B$8<Assumptions!$B$15,Assumptions!$B$15*(Assumptions!$B$28+Assumptions!$B$3/Assumptions!$B$15)/(Assumptions!$B$28+Assumptions!$B$3/$B$8),Assumptions!$B$15) | F22: =IF($B$8<Assumptions!$B$15,Assumptions!$B$15/E22,1) | G22: =Assumptions!$B$36*F22
A23: Series B | B23: =Assumptions!$B$16 | C23: =$B$8 | D23: =IF($B$8<Assumptions!$B$16,"yes","no") | E23: =IF($B$8<Assumptions!$B$16,Assumptions!$B$16*(Assumptions!$B$28+Assumptions!$B$3/Assumptions!$B$16)/(Assumptions!$B$28+Assumptions!$B$3/$B$8),Assumptions!$B$16) | F23: =IF($B$8<Assumptions!$B$16,Assumptions!$B$16/E23,1) | G23: =Assumptions!$B$37*F23
A24: Series C | B24: =Assumptions!$B$17 | C24: =$B$8 | D24: =IF($B$8<Assumptions!$B$17,"yes","no") | E24: =IF($B$8<Assumptions!$B$17,Assumptions!$B$17*(Assumptions!$B$28+Assumptions!$B$3/Assumptions!$B$17)/(Assumptions!$B$28+Assumptions!$B$3/$B$8),Assumptions!$B$17) | F24: =IF($B$8<Assumptions!$B$17,Assumptions!$B$17/E24,1) | G24: =Assumptions!$B$38*F24
A25: Series D | B25: =Assumptions!$B$18 | C25: =$B$8 | D25: =IF($B$8<Assumptions!$B$18,"yes","no") | E25: =IF($B$8<Assumptions!$B$18,Assumptions!$B$18*(Assumptions!$B$28+Assumptions!$B$3/Assumptions!$B$18)/(Assumptions!$B$28+Assumptions!$B$3/$B$8),Assumptions!$B$18) | F25: =IF($B$8<Assumptions!$B$18,Assumptions!$B$19/E25,Assumptions!$B$19/Assumptions!$B$18) | G25: =Assumptions!$B$33*F25
A26: Series E | B26: =Assumptions!$B$20 | C26: =$B$8 | D26: =IF($B$8<Assumptions!$B$20,"yes","no") | E26: =IF($B$8<Assumptions!$B$20,Assumptions!$B$20*(Assumptions!$B$28+Assumptions!$B$3/Assumptions!$B$20)/(Assumptions!$B$28+Assumptions!$B$3/$B$8),Assumptions!$B$20) | F26: =IF($B$8<Assumptions!$B$20,Assumptions!$B$20/E26,1) | G26: =Assumptions!$B$34*F26
A29: NOTES BLOCK
A30: Note | B30: Principal | C30: Cap | D30: Discount | E30: Cap-implied PPS | F30: Disc-implied PPS | G30: Conv PPS (min) | H30: Branch | I30: Shares issued
A31: Note A | B31: =Assumptions!$B$22 | C31: =Assumptions!$B$23 | D31: =Assumptions!$B$24 | E31: =Assumptions!$B$23/($B$7-I31) | F31: =$B$8*(1-Assumptions!$B$24) | G31: =MIN(E31,F31) | H31: =IF(E31<F31,"cap","discount") | I31: =$B$7*IF((Assumptions!$B$23+Assumptions!$B$22)<Assumptions!$B$2*(1-Assumptions!$B$24),Assumptions!$B$22/(Assumptions!$B$23+Assumptions!$B$22),Assumptions!$B$22/(Assumptions!$B$2*(1-Assumptions!$B$24)))
A32: Note B | B32: =Assumptions!$B$25 | C32: =Assumptions!$B$26 | D32: =Assumptions!$B$27 | E32: =Assumptions!$B$26/($B$7-I32) | F32: =$B$8*(1-Assumptions!$B$27) | G32: =MIN(E32,F32) | H32: =IF(E32<F32,"cap","discount") | I32: =$B$7*IF((Assumptions!$B$26+Assumptions!$B$25)<Assumptions!$B$2*(1-Assumptions!$B$27),Assumptions!$B$25/(Assumptions!$B$26+Assumptions!$B$25),Assumptions!$B$25/(Assumptions!$B$2*(1-Assumptions!$B$27)))
A34: TENDER BLOCK
A35: Tender shares (= secondary / (mult * F_PPS)) | B35: =Assumptions!$B$4/(Assumptions!$B$5*$B$8)
A36: Founder F1 tender share-out (50%) | B36: =B35*(Assumptions!$B$39/(Assumptions!$B$39+Assumptions!$B$40+Assumptions!$B$41))
A37: Founder F2 tender share-out (31.25%) | B37: =B35*(Assumptions!$B$40/(Assumptions!$B$39+Assumptions!$B$40+Assumptions!$B$41))
A38: Founder F3 tender share-out (18.75%) | B38: =B35*(Assumptions!$B$41/(Assumptions!$B$39+Assumptions!$B$40+Assumptions!$B$41))
A39: F_LEAD secondary common (= tender shares) | B39: =B35
A41: POST-F CAP TABLE BY STAKEHOLDER × SECURITY CLASS
A42: Stakeholder | B42: Common | C42: Seed | D42: A | E42: B | F42: C | G42: D | H42: E | I42: F | J42: Note A | K42: Note B | L42: Total | M42: Ownership %
A43: F1 (CEO) | B43: =Assumptions!$B$39-B36 | C43: 0 | D43: 0 | E43: 0 | F43: 0 | G43: 0 | H43: 0 | I43: 0 | J43: 0 | K43: 0 | L43: =SUM(B43:K43) | M43: =L43/$L$59
A44: F2 (CTO) | B44: =Assumptions!$B$40-B37 | C44: 0 | D44: 0 | E44: 0 | F44: 0 | G44: 0 | H44: 0 | I44: 0 | J44: 0 | K44: 0 | L44: =SUM(B44:K44) | M44: =L44/$L$59
A45: F3 (Chief Sci.) | B45: =Assumptions!$B$41-B38 | C45: 0 | D45: 0 | E45: 0 | F45: 0 | G45: 0 | H45: 0 | I45: 0 | J45: 0 | K45: 0 | L45: =SUM(B45:K45) | M45: =L45/$L$59
A46: Employee RSAs | B46: =Assumptions!$B$42 | C46: 0 | D46: 0 | E46: 0 | F46: 0 | G46: 0 | H46: 0 | I46: 0 | J46: 0 | K46: 0 | L46: =SUM(B46:K46) | M46: =L46/$L$59
...

Sheet Waterfall
A1: WATERFALL — 1× non-participating with conversion election (K-pass Nash)
A3: Exit value | B3: =Assumptions!$B$7 | C3: =Assumptions!$B$8 | D3: =Assumptions!$B$9 | E3: =Assumptions!$B$10 | F3: =Assumptions!$B$11
A5: Class share counts & liquidation preferences
A6: Class | B6: Shares (post-F) | C6: LP ($)
A7: F | B7: ='Pro-Forma'!$B$9 | C7: =Assumptions!$B$3
A8: E | B8: ='Pro-Forma'!$B$15 | C8: =(Assumptions!$B$34*Assumptions!$B$20)
A9: D | B9: ='Pro-Forma'!$B$14 | C9: =(Assumptions!$B$33*Assumptions!$B$19)
A10: C | B10: =Assumptions!$B$38 | C10: =(Assumptions!$B$38*Assumptions!$B$17)
A11: B | B11: =Assumptions!$B$37 | C11: =(Assumptions!$B$37*Assumptions!$B$16)
A12: A | B12: =Assumptions!$B$36 | C12: =(Assumptions!$B$36*Assumptions!$B$15)
A13: Seed | B13: =Assumptions!$B$35 | C13: =(Assumptions!$B$35*Assumptions!$B$14)
A14: Common-equiv pool (founders + RSAs + Note A + Note B shares) | B14: =(Assumptions!$B$39+Assumptions!$B$40+Assumptions!$B$41+Assumptions!$B$42)+'Pro-Forma'!$I$31+'Pro-Forma'!$I$32
A15: Issued options (ITM at all our exits) | B15: =Assumptions!$B$30
A16: Option strike | B16: =Assumptions!$B$21
A19: PASS 1 ELECTIONS (all-others-convert init)
A20: Class | B20: =Assumptions!$B$7 | C20: =Assumptions!$B$8 | D20: =Assumptions!$B$9 | E20: =Assumptions!$B$10 | F20: =Assumptions!$B$11
A21: F | B21: =IF($C$7>(IF((((B$3))+$B$15*$B$16)/((($B$14+$B$7+$B$8+$B$9+$B$10+$B$11+$B$12+$B$13))+$B$15)>$B$16,(((B$3))+$B$15*$B$16)/((($B$14+$B$7+$B$8+$B$9+$B$10+$B$11+$B$12+$B$13))+$B$15),((B$3))/(($B$14+$B$7+$B$8+$B$9+$B$10+$B$11+$B$12+$B$13))))*$B$7,"preference","convert") | C21: =IF($C$7>(IF((((C$3))+$B$15*$B$16)/((($B$14+$B$7+$B$8+$B$9+$B$10+$B$11+$B$12+$B$13))+$B$15)>$B$16,(((C$3))+$B$15*$B$16)/((($B$14+$B$7+$B$8+$B$9+$B$10+$B$11+$B$12+$B$13))+$B$15),((C$3))/(($B$14+$B$7+$B$8+$B$9+$B$10+$B$11+$B$12+$B$13))))*$B$7,"preference","convert") | D21: =IF($C$7>(IF((((D$3))+$B$15*$B$16)/((($B$14+$B$7+$B$8+$B$9+$B$10+$B$11+$B$12+$B$13))+$B$15)>$B$16,(((D$3))+$B$15*$B$16)/((($B$14+$B$7+$B$8+$B$9+$B$10+$B$11+$B$12+$B$13))+$B$15),((D$3))/(($B$14+$B$7+$B$8+$B$9+$B$10+$B$11+$B$12+$B$13))))*$B$7,"preference","convert") | E21: =IF($C$7>(IF((((E$3))+$B$15*$B$16)/((($B$14+$B$7+$B$8+$B$9+$B$10+$B$11+$B$12+$B$13))+$B$15)>$B$16,(((E$3))+$B$15*$B$16)/((($B$14+$B$7+$B$8+$B$9+$B$10+$B$11+$B$12+$B$13))+$B$15),((E$3))/(($B$14+$B$7+$B$8+$B$9+$B$10+$B$11+$B$12+$B$13))))*$B$7,"preference","convert") | F21: =IF($C$7>(IF((((F$3))+$B$15*$B$16)/((($B$14+$B$7+$B$8+$B$9+$B$10+$B$11+$B$12+$B$13))+$B$15)>$B$16,(((F$3))+$B$15*$B$16)/((($B$14+$B$7+$B$8+$B$9+$B$10+$B$11+$B$12+$B$13))+$B$15),((F$3))/(($B$14+$B$7+$B$8+$B$9+$B$10+$B$11+$B$12+$B$13))))*$B$7,"preference","convert")
A22: E | B22: =IF($C$8>(IF((((B$3))+$B$15*$B$16)/((($B$14+$B$8+$B$7+$B$9+$B$10+$B$11+$B$12+$B$13))+$B$15)>$B$16,(((B$3))+$B$15*$B$16)/((($B$14+$B$8+$B$7+$B$9+$B$10+$B$11+$B$12+$B$13))+$B$15),((B$3))/(($B$14+$B$8+$B$7+$B$9+$B$10+$B$11+$B$12+$B$13))))*$B$8,"preference","convert") | C22: =IF($C$8>(IF((((C$3))+$B$15*$B$16)/((($B$14+$B$8+$B$7+$B$9+$B$10+$B$11+$B$12+$B$13))+$B$15)>$B$16,(((C$3))+$B$15*$B$16)/((($B$14+$B$8+$B$7+$B$9+$B$10+$B$11+$B$12+$B$13))+$B$15),((C$3))/(($B$14+$B$8+$B$7+$B$9+$B$10+$B$11+$B$12+$B$13))))*$B$8,"preference","convert") | D22: =IF($C$8>(IF((((D$3))+$B$15*$B$16)/((($B$14+$B$8+$B$7+$B$9+$B$10+$B$11+$B$12+$B$13))+$B$15)>$B$16,(((D$3))+$B$15*$B$16)/((($B$14+$B$8+$B$7+$B$9+$B$10+$B$11+$B$12+$B$13))+$B$15),((D$3))/(($B$14+$B$8+$B$7+$B$9+$B$10+$B$11+$B$12+$B$13))))*$B$8,"preference","convert") | E22: =IF($C$8>(IF((((E$3))+$B$15*$B$16)/((($B$14+$B$8+$B$7+$B$9+$B$10+$B$11+$B$12+$B$13))+$B$15)>$B$16,(((E$3))+$B$15*$B$16)/((($B$14+$B$8+$B$7+$B$9+$B$10+$B$11+$B$12+$B$13))+$B$15),((E$3))/(($B$14+$B$8+$B$7+$B$9+$B$10+$B$11+$B$12+$B$13))))*$B$8,"preference","convert") | F22: =IF($C$8>(IF((((F$3))+$B$15*$B$16)/((($B$14+$B$8+$B$7+$B$9+$B$10+$B$11+$B$12+$B$13))+$B$15)>$B$16,(((F$3))+$B$15*$B$16)/((($B$14+$B$8+$B$7+$B$9+$B$10+$B$11+$B$12+$B$13))+$B$15),((F$3))/(($B$14+$B$8+$B$7+$B$9+$B$10+$B$11+$B$12+$B$13))))*$B$8,"preference","convert")
A23: D | B23: =IF($C$9>(IF((((B$3))+$B$15*$B$16)/((($B$14+$B$9+$B$7+$B$8+$B$10+$B$11+$B$12+$B$13))+$B$15)>$B$16,(((B$3))+$B$15*$B$16)/((($B$14+$B$9+$B$7+$B$8+$B$10+$B$11+$B$12+$B$13))+$B$15),((B$3))/(($B$14+$B$9+$B$7+$B$8+$B$10+$B$11+$B$12+$B$13))))*$B$9,"preference","convert") | C23: =IF($C$9>(IF((((C$3))+$B$15*$B$16)/((($B$14+$B$9+$B$7+$B$8+$B$10+$B$11+$B$12+$B$13))+$B$15)>$B$16,(((C$3))+$B$15*$B$16)/((($B$14+$B$9+$B$7+$B$8+$B$10+$B$11+$B$12+$B$13))+$B$15),((C$3))/(($B$14+$B$9+$B$7+$B$8+$B$10+$B$11+$B$12+$B$13))))*$B$9,"preference","convert") | D23: =IF($C$9>(IF((((D$3))+$B$15*$B$16)/((($B$14+$B$9+$B$7+$B$8+$B$10+$B$11+$B$12+$B$13))+$B$15)>$B$16,(((D$3))+$B$15*$B$16)/((($B$14+$B$9+$B$7+$B$8+$B$10+$B$11+$B$12+$B$13))+$B$15),((D$3))/(($B$14+$B$9+$B$7+$B$8+$B$10+$B$11+$B$12+$B$13))))*$B$9,"preference","convert") | E23: =IF($C$9>(IF((((E$3))+$B$15*$B$16)/((($B$14+$B$9+$B$7+$B$8+$B$10+$B$11+$B$12+$B$13))+$B$15)>$B$16,(((E$3))+$B$15*$B$16)/((($B$14+$B$9+$B$7+$B$8+$B$10+$B$11+$B$12+$B$13))+$B$15),((E$3))/(($B$14+$B$9+$B$7+$B$8+$B$10+$B$11+$B$12+$B$13))))*$B$9,"preference","convert") | F23: =IF($C$9>(IF((((F$3))+$B$15*$B$16)/((($B$14+$B$9+$B$7+$B$8+$B$10+$B$11+$B$12+$B$13))+$B$15)>$B$16,(((F$3))+$B$15*$B$16)/((($B$14+$B$9+$B$7+$B$8+$B$10+$B$11+$B$12+$B$13))+$B$15),((F$3))/(($B$14+$B$9+$B$7+$B$8+$B$10+$B$11+$B$12+$B$13))))*$B$9,"preference","convert")
A24: C | B24: =IF($C$10>(IF((((B$3))+$B$15*$B$16)/((($B$14+$B$10+$B$7+$B$8+$B$9+$B$11+$B$12+$B$13))+$B$15)>$B$16,(((B$3))+$B$15*$B$16)/((($B$14+$B$10+$B$7+$B$8+$B$9+$B$11+$B$12+$B$13))+$B$15),((B$3))/(($B$14+$B$10+$B$7+$B$8+$B$9+$B$11+$B$12+$B$13))))*$B$10,"preference","convert") | C24: =IF($C$10>(IF((((C$3))+$B$15*$B$16)/((($B$14+$B$10+$B$7+$B$8+$B$9+$B$11+$B$12+$B$13))+$B$15)>$B$16,(((C$3))+$B$15*$B$16)/((($B$14+$B$10+$B$7+$B$8+$B$9+$B$11+$B$12+$B$13))+$B$15),((C$3))/(($B$14+$B$10+$B$7+$B$8+$B$9+$B$11+$B$12+$B$13))))*$B$10,"preference","convert") | D24: =IF($C$10>(IF((((D$3))+$B$15*$B$16)/((($B$14+$B$10+$B$7+$B$8+$B$9+$B$11+$B$12+$B$13))+$B$15)>$B$16,(((D$3))+$B$15*$B$16)/((($B$14+$B$10+$B$7+$B$8+$B$9+$B$11+$B$12+$B$13))+$B$15),((D$3))/(($B$14+$B$10+$B$7+$B$8+$B$9+$B$11+$B$12+$B$13))))*$B$10,"preference","convert") | E24: =IF($C$10>(IF((((E$3))+$B$15*$B$16)/((($B$14+$B$10+$B$7+$B$8+$B$9+$B$11+$B$12+$B$13))+$B$15)>$B$16,(((E$3))+$B$15*$B$16)/((($B$14+$B$10+$B$7+$B$8+$B$9+$B$11+$B$12+$B$13))+$B$15),((E$3))/(($B$14+$B$10+$B$7+$B$8+$B$9+$B$11+$B$12+$B$13))))*$B$10,"preference","convert") | F24: =IF($C$10>(IF((((F$3))+$B$15*$B$16)/((($B$14+$B$10+$B$7+$B$8+$B$9+$B$11+$B$12+$B$13))+$B$15)>$B$16,(((F$3))+$B$15*$B$16)/((($B$14+$B$10+$B$7+$B$8+$B$9+$B$11+$B$12+$B$13))+$B$15),((F$3))/(($B$14+$B$10+$B$7+$B$8+$B$9+$B$11+$B$12+$B$13))))*$B$10,"preference","convert")
A25: B | B25: =IF($C$11>(IF((((B$3))+$B$15*$B$16)/((($B$14+$B$11+$B$7+$B$8+$B$9+$B$10+$B$12+$B$13))+$B$15)>$B$16,(((B$3))+$B$15*$B$16)/((($B$14+$B$11+$B$7+$B$8+$B$9+$B$10+$B$12+$B$13))+$B$15),((B$3))/(($B$14+$B$11+$B$7+$B$8+$B$9+$B$10+$B$12+$B$13))))*$B$11,"preference","convert") | C25: =IF($C$11>(IF((((C$3))+$B$15*$B$16)/((($B$14+$B$11+$B$7+$B$8+$B$9+$B$10+$B$12+$B$13))+$B$15)>$B$16,(((C$3))+$B$15*$B$16)/((($B$14+$B$11+$B$7+$B$8+$B$9+$B$10+$B$12+$B$13))+$B$15),((C$3))/(($B$14+$B$11+$B$7+$B$8+$B$9+$B$10+$B$12+$B$13))))*$B$11,"preference","convert") | D25: =IF($C$11>(IF((((D$3))+$B$15*$B$16)/((($B$14+$B$11+$B$7+$B$8+$B$9+$B$10+$B$12+$B$13))+$B$15)>$B$16,(((D$3))+$B$15*$B$16)/((($B$14+$B$11+$B$7+$B$8+$B$9+$B$10+$B$12+$B$13))+$B$15),((D$3))/(($B$14+$B$11+$B$7+$B$8+$B$9+$B$10+$B$12+$B$13))))*$B$11,"preference","convert") | E25: =IF($C$11>(IF((((E$3))+$B$15*$B$16)/((($B$14+$B$11+$B$7+$B$8+$B$9+$B$10+$B$12+$B$13))+$B$15)>$B$16,(((E$3))+$B$15*$B$16)/((($B$14+$B$11+$B$7+$B$8+$B$9+$B$10+$B$12+$B$13))+$B$15),((E$3))/(($B$14+$B$11+$B$7+$B$8+$B$9+$B$10+$B$12+$B$13))))*$B$11,"preference","convert") | F25: =IF($C$11>(IF((((F$3))+$B$15*$B$16)/((($B$14+$B$11+$B$7+$B$8+$B$9+$B$10+$B$12+$B$13))+$B$15)>$B$16,(((F$3))+$B$15*$B$16)/((($B$14+$B$11+$B$7+$B$8+$B$9+$B$10+$B$12+$B$13))+$B$15),((F$3))/(($B$14+$B$11+$B$7+$B$8+$B$9+$B$10+$B$12+$B$13))))*$B$11,"preference","convert")
A26: A | B26: =IF($C$12>(IF((((B$3))+$B$15*$B$16)/((($B$14+$B$12+$B$7+$B$8+$B$9+$B$10+$B$11+$B$13))+$B$15)>$B$16,(((B$3))+$B$15*$B$16)/((($B$14+$B$12+$B$7+$B$8+$B$9+$B$10+$B$11+$B$13))+$B$15),((B$3))/(($B$14+$B$12+$B$7+$B$8+$B$9+$B$10+$B$11+$B$13))))*$B$12,"preference","convert") | C26: =IF($C$12>(IF((((C$3))+$B$15*$B$16)/((($B$14+$B$12+$B$7+$B$8+$B$9+$B$10+$B$11+$B$13))+$B$15)>$B$16,(((C$3))+$B$15*$B$16)/((($B$14+$B$12+$B$7+$B$8+$B$9+$B$10+$B$11+$B$13))+$B$15),((C$3))/(($B$14+$B$12+$B$7+$B$8+$B$9+$B$10+$B$11+$B$13))))*$B$12,"preference","convert") | D26: =IF($C$12>(IF((((D$3))+$B$15*$B$16)/((($B$14+$B$12+$B$7+$B$8+$B$9+$B$10+$B$11+$B$13))+$B$15)>$B$16,(((D$3))+$B$15*$B$16)/((($B$14+$B$12+$B$7+$B$8+$B$9+$B$10+$B$11+$B$13))+$B$15),((D$3))/(($B$14+$B$12+$B$7+$B$8+$B$9+$B$10+$B$11+$B$13))))*$B$12,"preference","convert") | E26: =IF($C$12>(IF((((E$3))+$B$15*$B$16)/((($B$14+$B$12+$B$7+$B$8+$B$9+$B$10+$B$11+$B$13))+$B$15)>$B$16,(((E$3))+$B$15*$B$16)/((($B$14+$B$12+$B$7+$B$8+$B$9+$B$10+$B$11+$B$13))+$B$15),((E$3))/(($B$14+$B$12+$B$7+$B$8+$B$9+$B$10+$B$11+$B$13))))*$B$12,"preference","convert") | F26: =IF($C$12>(IF((((F$3))+$B$15*$B$16)/((($B$14+$B$12+$B$7+$B$8+$B$9+$B$10+$B$11+$B$13))+$B$15)>$B$16,(((F$3))+$B$15*$B$16)/((($B$14+$B$12+$B$7+$B$8+$B$9+$B$10+$B$11+$B$13))+$B$15),((F$3))/(($B$14+$B$12+$B$7+$B$8+$B$9+$B$10+$B$11+$B$13))))*$B$12,"preference","convert")
A27: Seed | B27: =IF($C$13>(IF((((B$3))+$B$15*$B$16)/((($B$14+$B$13+$B$7+$B$8+$B$9+$B$10+$B$11+$B$12))+$B$15)>$B$16,(((B$3))+$B$15*$B$16)/((($B$14+$B$13+$B$7+$B$8+$B$9+$B$10+$B$11+$B$12))+$B$15),((B$3))/(($B$14+$B$13+$B$7+$B$8+$B$9+$B$10+$B$11+$B$12))))*$B$13,"preference","convert") | C27: =IF($C$13>(IF((((C$3))+$B$15*$B$16)/((($B$14+$B$13+$B$7+$B$8+$B$9+$B$10+$B$11+$B$12))+$B$15)>$B$16,(((C$3))+$B$15*$B$16)/((($B$14+$B$13+$B$7+$B$8+$B$9+$B$10+$B$11+$B$12))+$B$15),((C$3))/(($B$14+$B$13+$B$7+$B$8+$B$9+$B$10+$B$11+$B$12))))*$B$13,"preference","convert") | D27: =IF($C$13>(IF((((D$3))+$B$15*$B$16)/((($B$14+$B$13+$B$7+$B$8+$B$9+$B$10+$B$11+$B$12))+$B$15)>$B$16,(((D$3))+$B$15*$B$16)/((($B$14+$B$13+$B$7+$B$8+$B$9+$B$10+$B$11+$B$12))+$B$15),((D$3))/(($B$14+$B$13+$B$7+$B$8+$B$9+$B$10+$B$11+$B$12))))*$B$13,"preference","convert") | E27: =IF($C$13>(IF((((E$3))+$B$15*$B$16)/((($B$14+$B$13+$B$7+$B$8+$B$9+$B$10+$B$11+$B$12))+$B$15)>$B$16,(((E$3))+$B$15*$B$16)/((($B$14+$B$13+$B$7+$B$8+$B$9+$B$10+$B$11+$B$12))+$B$15),((E$3))/(($B$14+$B$13+$B$7+$B$8+$B$9+$B$10+$B$11+$B$12))))*$B$13,"preference","convert") | F27: =IF($C$13>(IF((((F$3))+$B$15*$B$16)/((($B$14+$B$13+$B$7+$B$8+$B$9+$B$10+$B$11+$B$12))+$B$15)>$B$16,(((F$3))+$B$15*$B$16)/((($B$14+$B$13+$B$7+$B$8+$B$9+$B$10+$B$11+$B$12))+$B$15),((F$3))/(($B$14+$B$13+$B$7+$B$8+$B$9+$B$10+$B$11+$B$12))))*$B$13,"preference","convert")
A28: PASS 2 ELECTIONS (best-response to Pass 1)
A29: Class | B29: =Assumptions!$B$7 | C29: =Assumptions!$B$8 | D29: =Assumptions!$B$9 | E29: =Assumptions!$B$10 | F29: =Assumptions!$B$11
A30: F | B30: =IF($C$7>(IF((((B$3-(IF(B22="preference",$C$8,0)+IF(B23="preference",$C$9,0)+IF(B24="preference",$C$10,0)+IF(B25="preference",$C$11,0)+IF(B26="preference",$C$12,0)+IF(B27="preference",$C$13,0))))+$B$15*$B$16)/((($B$14+$B$7+(IF(B22="convert",$B$8,0)+IF(B23="convert",$B$9,0)+IF(B24="convert",$B$10,0)+IF(B25="convert",$B$11,0)+IF(B26="convert",$B$12,0)+IF(B27="convert",$B$13,0))))+$B$15)>$B$16,(((B$3-(IF(B22="preference",$C$8,0)+IF(B23="preference",$C$9,0)+IF(B24="preference",$C$10,0)+IF(B25="preference",$C$11,0)+IF(B26="preference",$C$12,0)+IF(B27="preference",$C$13,0))))+$B$15*$B$16)/((($B$14+$B$7+(IF(B22="convert",$B$8,0)+IF(B23="convert",$B$9,0)+IF(B24="convert",$B$10,0)+IF(B25="convert",$B$11,0)+IF(B26="convert",$B$12,0)+IF(B27="convert",$B$13,0))))+$B$15),((B$3-(IF(B22="preference",$C$8,0)+IF(B23="preference",$C$9,0)+IF(B24="preference",$C$10,0)+IF(B25="preference",$C$11,0)+IF(B26="preference",$C$12,0)+IF(B27="preference",$C$13,0))))/(($B$14+$B$7+(IF(B22="convert",$B$8,0)+IF(B23="convert",$B$9,0)+IF(B24="convert",$B$10,0)+IF(B25="convert",$B$11,0)+IF(B26="convert",$B$12,0)+IF(B27="convert",$B$13,0))))))*$B$7,"preference","convert") | C30: =IF($C$7>(IF((((C$3-(IF(C22="preference",$C$8,0)+IF(C23="preference",$C$9,0)+IF(C24="preference",$C$10,0)+IF(C25="preference",$C$11,0)+IF(C26="preference",$C$12,0)+IF(C27="preference",$C$13,0))))+$B$15*$B$16)/((($B$14+$B$7+(IF(C22="convert",$B$8,0)+IF(C23="convert",$B$9,0)+IF(C24="convert",$B$10,0)+IF(C25="convert",$B$11,0)+IF(C26="convert",$B$12,0)+IF(C27="convert",$B$13,0))))+$B$15)>$B$16,(((C$3-(IF(C22="preference",$C$8,0)+IF(C23="preference",$C$9,0)+IF(C24="preference",$C$10,0)+IF(C25="preference",$C$11,0)+IF(C26="preference",$C$12,0)+IF(C27="preference",$C$13,0))))+$B$15*$B$16)/((($B$14+$B$7+(IF(C22="convert",$B$8,0)+IF(C23="convert",$B$9,0)+IF(C24="convert",$B$10,0)+IF(C25="convert",$B$11,0)+IF(C26="convert",$B$12,0)+IF(C27="convert",$B$13,0))))+$B$15),((C$3-(IF(C22="preference",$C$8,0)+IF(C23="preference",$C$9,0)+IF(C24="preference",$C$10,0)+IF(C25="preference",$C$11,0)+IF(C26="preference",$C$12,0)+IF(C27="preference",$C$13,0))))/(($B$14+$B$7+(IF(C22="convert",$B$8,0)+IF(C23="convert",$B$9,0)+IF(C24="convert",$B$10,0)+IF(C25="convert",$B$11,0)+IF(C26="convert",$B$12,0)+IF(C27="convert",$B$13,0))))))*$B$7,"preference","convert") | D30: =IF($C$7>(IF((((D$3-(IF(D22="preference",$C$8,0)+IF(D23="preference",$C$9,0)+IF(D24="preference",$C$10,0)+IF(D25="preference",$C$11,0)+IF(D26="preference",$C$12,0)+IF(D27="preference",$C$13,0))))+$B$15*$B$16)/((($B$14+$B$7+(IF(D22="convert",$B$8,0)+IF(D23="convert",$B$9,0)+IF(D24="convert",$B$10,0)+IF(D25="convert",$B$11,0)+IF(D26="convert",$B$12,0)+IF(D27="convert",$B$13,0))))+$B$15)>$B$16,(((D$3-(IF(D22="preference",$C$8,0)+IF(D23="preference",$C$9,0)+IF(D24="preference",$C$10,0)+IF(D25="preference",$C$11,0)+IF(D26="preference",$C$12,0)+IF(D27="preference",$C$13,0))))+$B$15*$B$16)/((($B$14+$B$7+(IF(D22="convert",$B$8,0)+IF(D23="convert",$B$9,0)+IF(D24="convert",$B$10,0)+IF(D25="convert",$B$11,0)+IF(D26="convert",$B$12,0)+IF(D27="convert",$B$13,0))))+$B$15),((D$3-(IF(D22="preference",$C$8,0)+IF(D23="preference",$C$9,0)+IF(D24="preference",$C$10,0)+IF(D25="preference",$C$11,0)+IF(D26="preference",$C$12,0)+IF(D27="preference",$C$13,0))))/(($B$14+$B$7+(IF(D22="convert",$B$8,0)+IF(D23="convert",$B$9,0)+IF(D24="convert",$B$10,0)+IF(D25="convert",$B$11,0)+IF(D26="convert",$B$12,0)+IF(D27="convert",$B$13,0))))))*$B$7,"preference","convert") | E30: =IF($C$7>(IF((((E$3-(IF(E22="preference",$C$8,0)+IF(E23="preference",$C$9,0)+IF(E24="preference",$C$10,0)+IF(E25="preference",$C$11,0)+IF(E26="preference",$C$12,0)+IF(E27="preference",$C$13,0))))+$B$15*$B$16)/((($B$14+$B$7+(IF(E22="convert",$B$8,0)+IF(E23="convert",$B$9,0)+IF(E24="convert",$B$10,0)+IF(E25="convert",$B$11,0)+IF(E26="convert",$B$12,0)+IF(E27="convert",$B$13,0))))+$B$15)>$B$16,(((E$3-(IF(E22="preference",$C$8,0)+IF(E23="preference",$C$9,0)+IF(E24="preference",$C$10,0)+IF(E25="preference",$C$11,0)+IF(E26="preference",$C$12,0)+IF(E27="preference",$C$13,0))))+$B$15*$B$16)/((($B$14+$B$7+(IF(E22="convert",$B$8,0)+IF(E23="convert",$B$9,0)+IF(E24="convert",$B$10,0)+IF(E25="convert",$B$11,0)+IF(E26="convert",$B$12,0)+IF(E27="convert",$B$13,0))))+$B$15),((E$3-(IF(E22="preference",$C$8,0)+IF(E23="preference",$C$9,0)+IF(E24="preference",$C$10,0)+IF(E25="preference",$C$11,0)+IF(E26="preference",$C$12,0)+IF(E27="preference",$C$13,0))))/(($B$14+$B$7+(IF(E22="convert",$B$8,0)+IF(E23="convert",$B$9,0)+IF(E24="convert",$B$10,0)+IF(E25="convert",$B$11,0)+IF(E26="convert",$B$12,0)+IF(E27="convert",$B$13,0))))))*$B$7,"preference","convert") | F30: =IF($C$7>(IF((((F$3-(IF(F22="preference",$C$8,0)+IF(F23="preference",$C$9,0)+IF(F24="preference",$C$10,0)+IF(F25="preference",$C$11,0)+IF(F26="preference",$C$12,0)+IF(F27="preference",$C$13,0))))+$B$15*$B$16)/((($B$14+$B$7+(IF(F22="convert",$B$8,0)+IF(F23="convert",$B$9,0)+IF(F24="convert",$B$10,0)+IF(F25="convert",$B$11,0)+IF(F26="convert",$B$12,0)+IF(F27="convert",$B$13,0))))+$B$15)>$B$16,(((F$3-(IF(F22="preference",$C$8,0)+IF(F23="preference",$C$9,0)+IF(F24="preference",$C$10,0)+IF(F25="preference",$C$11,0)+IF(F26="preference",$C$12,0)+IF(F27="preference",$C$13,0))))+$B$15*$B$16)/((($B$14+$B$7+(IF(F22="convert",$B$8,0)+IF(F23="convert",$B$9,0)+IF(F24="convert",$B$10,0)+IF(F25="convert",$B$11,0)+IF(F26="convert",$B$12,0)+IF(F27="convert",$B$13,0))))+$B$15),((F$3-(IF(F22="preference",$C$8,0)+IF(F23="preference",$C$9,0)+IF(F24="preference",$C$10,0)+IF(F25="preference",$C$11,0)+IF(F26="preference",$C$12,0)+IF(F27="preference",$C$13,0))))/(($B$14+$B$7+(IF(F22="convert",$B$8,0)+IF(F23="convert",$B$9,0)+IF(F24="convert",$B$10,0)+IF(F25="convert",$B$11,0)+IF(F26="convert",$B$12,0)+IF(F27="convert",$B$13,0))))))*$B$7,"preference","convert")
A31: E | B31: =IF($C$8>(IF((((B$3-(IF(B21="preference",$C$7,0)+IF(B23="preference",$C$9,0)+IF(B24="preference",$C$10,0)+IF(B25="preference",$C$11,0)+IF(B26="preference",$C$12,0)+IF(B27="preference",$C$13,0))))+$B$15*$B$16)/((($B$14+$B$8+(IF(B21="convert",$B$7,0)+IF(B23="convert",$B$9,0)+IF(B24="convert",$B$10,0)+IF(B25="convert",$B$11,0)+IF(B26="convert",$B$12,0)+IF(B27="convert",$B$13,0))))+$B$15)>$B$16,(((B$3-(IF(B21="preference",$C$7,0)+IF(B23="preference",$C$9,0)+IF(B24="preference",$C$10,0)+IF(B25="preference",$C$11,0)+IF(B26="preference",$C$12,0)+IF(B27="preference",$C$13,0))))+$B$15*$B$16)/((($B$14+$B$8+(IF(B21="convert",$B$7,0)+IF(B23="convert",$B$9,0)+IF(B24="convert",$B$10,0)+IF(B25="convert",$B$11,0)+IF(B26="convert",$B$12,0)+IF(B27="convert",$B$13,0))))+$B$15),((B$3-(IF(B21="preference",$C$7,0)+IF(B23="preference",$C$9,0)+IF(B24="preference",$C$10,0)+IF(B25="preference",$C$11,0)+IF(B26="preference",$C$12,0)+IF(B27="preference",$C$13,0))))/(($B$14+$B$8+(IF(B21="convert",$B$7,0)+IF(B23="convert",$B$9,0)+IF(B24="convert",$B$10,0)+IF(B25="convert",$B$11,0)+IF(B26="convert",$B$12,0)+IF(B27="convert",$B$13,0))))))*$B$8,"preference","convert") | C31: =IF($C$8>(IF((((C$3-(IF(C21="preference",$C$7,0)+IF(C23="preference",$C$9,0)+IF(C24="preference",$C$10,0)+IF(C25="preference",$C$11,0)+IF(C26="preference",$C$12,0)+IF(C27="preference",$C$13,0))))+$B$15*$B$16)/((($B$14+$B$8+(IF(C21="convert",$B$7,0)+IF(C23="convert",$B$9,0)+IF(C24="convert",$B$10,0)+IF(C25="convert",$B$11,0)+IF(C26="convert",$B$12,0)+IF(C27="convert",$B$13,0))))+$B$15)>$B$16,(((C$3-(IF(C21="preference",$C$7,0)+IF(C23="preference",$C$9,0)+IF(C24="preference",$C$10,0)+IF(C25="preference",$C$11,0)+IF(C26="preference",$C$12,0)+IF(C27="preference",$C$13,0))))+$B$15*$B$16)/((($B$14+$B$8+(IF(C21="convert",$B$7,0)+IF(C23="convert",$B$9,0)+IF(C24="convert",$B$10,0)+IF(C25="convert",$B$11,0)+IF(C26="convert",$B$12,0)+IF(C27="convert",$B$13,0))))+$B$15),((C$3-(IF(C21="preference",$C$7,0)+IF(C23="preference",$C$9,0)+IF(C24="preference",$C$10,0)+IF(C25="preference",$C$11,0)+IF(C26="preference",$C$12,0)+IF(C27="preference",$C$13,0))))/(($B$14+$B$8+(IF(C21="convert",$B$7,0)+IF(C23="convert",$B$9,0)+IF(C24="convert",$B$10,0)+IF(C25="convert",$B$11,0)+IF(C26="convert",$B$12,0)+IF(C27="convert",$B$13,0))))))*$B$8,"preference","convert") | D31: =IF($C$8>(IF((((D$3-(IF(D21="preference",$C$7,0)+IF(D23="preference",$C$9,0)+IF(D24="preference",$C$10,0)+IF(D25="preference",$C$11,0)+IF(D26="preference",$C$12,0)+IF(D27="preference",$C$13,0))))+$B$15*$B$16)/((($B$14+$B$8+(IF(D21="convert",$B$7,0)+IF(D23="convert",$B$9,0)+IF(D24="convert",$B$10,0)+IF(D25="convert",$B$11,0)+IF(D26="convert",$B$12,0)+IF(D27="convert",$B$13,0))))+$B$15)>$B$16,(((D$3-(IF(D21="preference",$C$7,0)+IF(D23="preference",$C$9,0)+IF(D24="preference",$C$10,0)+IF(D25="preference",$C$11,0)+IF(D26="preference",$C$12,0)+IF(D27="preference",$C$13,0))))+$B$15*$B$16)/((($B$14+$B$8+(IF(D21="convert",$B$7,0)+IF(D23="convert",$B$9,0)+IF(D24="convert",$B$10,0)+IF(D25="convert",$B$11,0)+IF(D26="convert",$B$12,0)+IF(D27="convert",$B$13,0))))+$B$15),((D$3-(IF(D21="preference",$C$7,0)+IF(D23="preference",$C$9,0)+IF(D24="preference",$C$10,0)+IF(D25="preference",$C$11,0)+IF(D26="preference",$C$12,0)+IF(D27="preference",$C$13,0))))/(($B$14+$B$8+(IF(D21="convert",$B$7,0)+IF(D23="convert",$B$9,0)+IF(D24="convert",$B$10,0)+IF(D25="convert",$B$11,0)+IF(D26="convert",$B$12,0)+IF(D27="convert",$B$13,0))))))*$B$8,"preference","convert") | E31: =IF($C$8>(IF((((E$3-(IF(E21="preference",$C$7,0)+IF(E23="preference",$C$9,0)+IF(E24="preference",$C$10,0)+IF(E25="preference",$C$11,0)+IF(E26="preference",$C$12,0)+IF(E27="preference",$C$13,0))))+$B$15*$B$16)/((($B$14+$B$8+(IF(E21="convert",$B$7,0)+IF(E23="convert",$B$9,0)+IF(E24="convert",$B$10,0)+IF(E25="convert",$B$11,0)+IF(E26="convert",$B$12,0)+IF(E27="convert",$B$13,0))))+$B$15)>$B$16,(((E$3-(IF(E21="preference",$C$7,0)+IF(E23="preference",$C$9,0)+IF(E24="preference",$C$10,0)+IF(E25="preference",$C$11,0)+IF(E26="preference",$C$12,0)+IF(E27="preference",$C$13,0))))+$B$15*$B$16)/((($B$14+$B$8+(IF(E21="convert",$B$7,0)+IF(E23="convert",$B$9,0)+IF(E24="convert",$B$10,0)+IF(E25="convert",$B$11,0)+IF(E26="convert",$B$12,0)+IF(E27="convert",$B$13,0))))+$B$15),((E$3-(IF(E21="preference",$C$7,0)+IF(E23="preference",$C$9,0)+IF(E24="preference",$C$10,0)+IF(E25="preference",$C$11,0)+IF(E26="preference",$C$12,0)+IF(E27="preference",$C$13,0))))/(($B$14+$B$8+(IF(E21="convert",$B$7,0)+IF(E23="convert",$B$9,0)+IF(E24="convert",$B$10,0)+IF(E25="convert",$B$11,0)+IF(E26="convert",$B$12,0)+IF(E27="convert",$B$13,0))))))*$B$8,"preference","convert") | F31: =IF($C$8>(IF((((F$3-(IF(F21="preference",$C$7,0)+IF(F23="preference",$C$9,0)+IF(F24="preference",$C$10,0)+IF(F25="preference",$C$11,0)+IF(F26="preference",$C$12,0)+IF(F27="preference",$C$13,0))))+$B$15*$B$16)/((($B$14+$B$8+(IF(F21="convert",$B$7,0)+IF(F23="convert",$B$9,0)+IF(F24="convert",$B$10,0)+IF(F25="convert",$B$11,0)+IF(F26="convert",$B$12,0)+IF(F27="convert",$B$13,0))))+$B$15)>$B$16,(((F$3-(IF(F21="preference",$C$7,0)+IF(F23="preference",$C$9,0)+IF(F24="preference",$C$10,0)+IF(F25="preference",$C$11,0)+IF(F26="preference",$C$12,0)+IF(F27="preference",$C$13,0))))+$B$15*$B$16)/((($B$14+$B$8+(IF(F21="convert",$B$7,0)+IF(F23="convert",$B$9,0)+IF(F24="convert",$B$10,0)+IF(F25="convert",$B$11,0)+IF(F26="convert",$B$12,0)+IF(F27="convert",$B$13,0))))+$B$15),((F$3-(IF(F21="preference",$C$7,0)+IF(F23="preference",$C$9,0)+IF(F24="preference",$C$10,0)+IF(F25="preference",$C$11,0)+IF(F26="preference",$C$12,0)+IF(F27="preference",$C$13,0))))/(($B$14+$B$8+(IF(F21="convert",$B$7,0)+IF(F23="convert",$B$9,0)+IF(F24="convert",$B$10,0)+IF(F25="convert",$B$11,0)+IF(F26="convert",$B$12,0)+IF(F27="convert",$B$13,0))))))*$B$8,"preference","convert")
A32: D | B32: =IF($C$9>(IF((((B$3-(IF(B21="preference",$C$7,0)+IF(B22="preference",$C$8,0)+IF(B24="preference",$C$10,0)+IF(B25="preference",$C$11,0)+IF(B26="preference",$C$12,0)+IF(B27="preference",$C$13,0))))+$B$15*$B$16)/((($B$14+$B$9+(IF(B21="convert",$B$7,0)+IF(B22="convert",$B$8,0)+IF(B24="convert",$B$10,0)+IF(B25="convert",$B$11,0)+IF(B26="convert",$B$12,0)+IF(B27="convert",$B$13,0))))+$B$15)>$B$16,(((B$3-(IF(B21="preference",$C$7,0)+IF(B22="preference",$C$8,0)+IF(B24="preference",$C$10,0)+IF(B25="preference",$C$11,0)+IF(B26="preference",$C$12,0)+IF(B27="preference",$C$13,0))))+$B$15*$B$16)/((($B$14+$B$9+(IF(B21="convert",$B$7,0)+IF(B22="convert",$B$8,0)+IF(B24="convert",$B$10,0)+IF(B25="convert",$B$11,0)+IF(B26="convert",$B$12,0)+IF(B27="convert",$B$13,0))))+$B$15),((B$3-(IF(B21="preference",$C$7,0)+IF(B22="preference",$C$8,0)+IF(B24="preference",$C$10,0)+IF(B25="preference",$C$11,0)+IF(B26="preference",$C$12,0)+IF(B27="preference",$C$13,0))))/(($B$14+$B$9+(IF(B21="convert",$B$7,0)+IF(B22="convert",$B$8,0)+IF(B24="convert",$B$10,0)+IF(B25="convert",$B$11,0)+IF(B26="convert",$B$12,0)+IF(B27="convert",$B$13,0))))))*$B$9,"preference","convert") | C32: =IF($C$9>(IF((((C$3-(IF(C21="preference",$C$7,0)+IF(C22="preference",$C$8,0)+IF(C24="preference",$C$10,0)+IF(C25="preference",$C$11,0)+IF(C26="preference",$C$12,0)+IF(C27="preference",$C$13,0))))+$B$15*$B$16)/((($B$14+$B$9+(IF(C21="convert",$B$7,0)+IF(C22="convert",$B$8,0)+IF(C24="convert",$B$10,0)+IF(C25="convert",$B$11,0)+IF(C26="convert",$B$12,0)+IF(C27="convert",$B$13,0))))+$B$15)>$B$16,(((C$3-(IF(C21="preference",$C$7,0)+IF(C22="preference",$C$8,0)+IF(C24="preference",$C$10,0)+IF(C25="preference",$C$11,0)+IF(C26="preference",$C$12,0)+IF(C27="preference",$C$13,0))))+$B$15*$B$16)/((($B$14+$B$9+(IF(C21="convert",$B$7,0)+IF(C22="convert",$B$8,0)+IF(C24="convert",$B$10,0)+IF(C25="convert",$B$11,0)+IF(C26="convert",$B$12,0)+IF(C27="convert",$B$13,0))))+$B$15),((C$3-(IF(C21="preference",$C$7,0)+IF(C22="preference",$C$8,0)+IF(C24="preference",$C$10,0)+IF(C25="preference",$C$11,0)+IF(C26="preference",$C$12,0)+IF(C27="preference",$C$13,0))))/(($B$14+$B$9+(IF(C21="convert",$B$7,0)+IF(C22="convert",$B$8,0)+IF(C24="convert",$B$10,0)+IF(C25="convert",$B$11,0)+IF(C26="convert",$B$12,0)+IF(C27="convert",$B$13,0))))))*$B$9,"preference","convert") | D32: =IF($C$9>(IF((((D$3-(IF(D21="preference",$C$7,0)+IF(D22="preference",$C$8,0)+IF(D24="preference",$C$10,0)+IF(D25="preference",$C$11,0)+IF(D26="preference",$C$12,0)+IF(D27="preference",$C$13,0))))+$B$15*$B$16)/((($B$14+$B$9+(IF(D21="convert",$B$7,0)+IF(D22="convert",$B$8,0)+IF(D24="convert",$B$10,0)+IF(D25="convert",$B$11,0)+IF(D26="convert",$B$12,0)+IF(D27="convert",$B$13,0))))+$B$15)>$B$16,(((D$3-(IF(D21="preference",$C$7,0)+IF(D22="preference",$C$8,0)+IF(D24="preference",$C$10,0)+IF(D25="preference",$C$11,0)+IF(D26="preference",$C$12,0)+IF(D27="preference",$C$13,0))))+$B$15*$B$16)/((($B$14+$B$9+(IF(D21="convert",$B$7,0)+IF(D22="convert",$B$8,0)+IF(D24="convert",$B$10,0)+IF(D25="convert",$B$11,0)+IF(D26="convert",$B$12,0)+IF(D27="convert",$B$13,0))))+$B$15),((D$3-(IF(D21="preference",$C$7,0)+IF(D22="preference",$C$8,0)+IF(D24="preference",$C$10,0)+IF(D25="preference",$C$11,0)+IF(D26="preference",$C$12,0)+IF(D27="preference",$C$13,0))))/(($B$14+$B$9+(IF(D21="convert",$B$7,0)+IF(D22="convert",$B$8,0)+IF(D24="convert",$B$10,0)+IF(D25="convert",$B$11,0)+IF(D26="convert",$B$12,0)+IF(D27="convert",$B$13,0))))))*$B$9,"preference","convert") | E32: =IF($C$9>(IF((((E$3-(IF(E21="preference",$C$7,0)+IF(E22="preference",$C$8,0)+IF(E24="preference",$C$10,0)+IF(E25="preference",$C$11,0)+IF(E26="preference",$C$12,0)+IF(E27="preference",$C$13,0))))+$B$15*$B$16)/((($B$14+$B$9+(IF(E21="convert",$B$7,0)+IF(E22="convert",$B$8,0)+IF(E24="convert",$B$10,0)+IF(E25="convert",$B$11,0)+IF(E26="convert",$B$12,0)+IF(E27="convert",$B$13,0))))+$B$15)>$B$16,(((E$3-(IF(E21="preference",$C$7,0)+IF(E22="preference",$C$8,0)+IF(E24="preference",$C$10,0)+IF(E25="preference",$C$11,0)+IF(E26="preference",$C$12,0)+IF(E27="preference",$C$13,0))))+$B$15*$B$16)/((($B$14+$B$9+(IF(E21="convert",$B$7,0)+IF(E22="convert",$B$8,0)+IF(E24="convert",$B$10,0)+IF(E25="convert",$B$11,0)+IF(E26="convert",$B$12,0)+IF(E27="convert",$B$13,0))))+$B$15),((E$3-(IF(E21="preference",$C$7,0)+IF(E22="preference",$C$8,0)+IF(E24="preference",$C$10,0)+IF(E25="preference",$C$11,0)+IF(E26="preference",$C$12,0)+IF(E27="preference",$C$13,0))))/(($B$14+$B$9+(IF(E21="convert",$B$7,0)+IF(E22="convert",$B$8,0)+IF(E24="convert",$B$10,0)+IF(E25="convert",$B$11,0)+IF(E26="convert",$B$12,0)+IF(E27="convert",$B$13,0))))))*$B$9,"preference","convert") | F32: =IF($C$9>(IF((((F$3-(IF(F21="preference",$C$7,0)+IF(F22="preference",$C$8,0)+IF(F24="preference",$C$10,0)+IF(F25="preference",$C$11,0)+IF(F26="preference",$C$12,0)+IF(F27="preference",$C$13,0))))+$B$15*$B$16)/((($B$14+$B$9+(IF(F21="convert",$B$7,0)+IF(F22="convert",$B$8,0)+IF(F24="convert",$B$10,0)+IF(F25="convert",$B$11,0)+IF(F26="convert",$B$12,0)+IF(F27="convert",$B$13,0))))+$B$15)>$B$16,(((F$3-(IF(F21="preference",$C$7,0)+IF(F22="preference",$C$8,0)+IF(F24="preference",$C$10,0)+IF(F25="preference",$C$11,0)+IF(F26="preference",$C$12,0)+IF(F27="preference",$C$13,0))))+$B$15*$B$16)/((($B$14+$B$9+(IF(F21="convert",$B$7,0)+IF(F22="convert",$B$8,0)+IF(F24="convert",$B$10,0)+IF(F25="convert",$B$11,0)+IF(F26="convert",$B$12,0)+IF(F27="convert",$B$13,0))))+$B$15),((F$3-(IF(F21="preference",$C$7,0)+IF(F22="preference",$C$8,0)+IF(F24="preference",$C$10,0)+IF(F25="preference",$C$11,0)+IF(F26="preference",$C$12,0)+IF(F27="preference",$C$13,0))))/(($B$14+$B$9+(IF(F21="convert",$B$7,0)+IF(F22="convert",$B$8,0)+IF(F24="convert",$B$10,0)+IF(F25="convert",$B$11,0)+IF(F26="convert",$B$12,0)+IF(F27="convert",$B$13,0))))))*$B$9,"preference","convert")
A33: C | B33: =IF($C$10>(IF((((B$3-(IF(B21="preference",$C$7,0)+IF(B22="preference",$C$8,0)+IF(B23="preference",$C$9,0)+IF(B25="preference",$C$11,0)+IF(B26="preference",$C$12,0)+IF(B27="preference",$C$13,0))))+$B$15*$B$16)/((($B$14+$B$10+(IF(B21="convert",$B$7,0)+IF(B22="convert",$B$8,0)+IF(B23="convert",$B$9,0)+IF(B25="convert",$B$11,0)+IF(B26="convert",$B$12,0)+IF(B27="convert",$B$13,0))))+$B$15)>$B$16,(((B$3-(IF(B21="preference",$C$7,0)+IF(B22="preference",$C$8,0)+IF(B23="preference",$C$9,0)+IF(B25="preference",$C$11,0)+IF(B26="preference",$C$12,0)+IF(B27="preference",$C$13,0))))+$B$15*$B$16)/((($B$14+$B$10+(IF(B21="convert",$B$7,0)+IF(B22="convert",$B$8,0)+IF(B23="convert",$B$9,0)+IF(B25="convert",$B$11,0)+IF(B26="convert",$B$12,0)+IF(B27="convert",$B$13,0))))+$B$15),((B$3-(IF(B21="preference",$C$7,0)+IF(B22="preference",$C$8,0)+IF(B23="preference",$C$9,0)+IF(B25="preference",$C$11,0)+IF(B26="preference",$C$12,0)+IF(B27="preference",$C$13,0))))/(($B$14+$B$10+(IF(B21="convert",$B$7,0)+IF(B22="convert",$B$8,0)+IF(B23="convert",$B$9,0)+IF(B25="convert",$B$11,0)+IF(B26="convert",$B$12,0)+IF(B27="convert",$B$13,0))))))*$B$10,"preference","convert") | C33: =IF($C$10>(IF((((C$3-(IF(C21="preference",$C$7,0)+IF(C22="preference",$C$8,0)+IF(C23="preference",$C$9,0)+IF(C25="preference",$C$11,0)+IF(C26="preference",$C$12,0)+IF(C27="preference",$C$13,0))))+$B$15*$B$16)/((($B$14+$B$10+(IF(C21="convert",$B$7,0)+IF(C22="convert",$B$8,0)+IF(C23="convert",$B$9,0)+IF(C25="convert",$B$11,0)+IF(C26="convert",$B$12,0)+IF(C27="convert",$B$13,0))))+$B$15)>$B$16,(((C$3-(IF(C21="preference",$C$7,0)+IF(C22="preference",$C$8,0)+IF(C23="preference",$C$9,0)+IF(C25="preference",$C$11,0)+IF(C26="preference",$C$12,0)+IF(C27="preference",$C$13,0))))+$B$15*$B$16)/((($B$14+$B$10+(IF(C21="convert",$B$7,0)+IF(C22="convert",$B$8,0)+IF(C23="convert",$B$9,0)+IF(C25="convert",$B$11,0)+IF(C26="convert",$B$12,0)+IF(C27="convert",$B$13,0))))+$B$15),((C$3-(IF(C21="preference",$C$7,0)+IF(C22="preference",$C$8,0)+IF(C23="preference",$C$9,0)+IF(C25="preference",$C$11,0)+IF(C26="preference",$C$12,0)+IF(C27="preference",$C$13,0))))/(($B$14+$B$10+(IF(C21="convert",$B$7,0)+IF(C22="convert",$B$8,0)+IF(C23="convert",$B$9,0)+IF(C25="convert",$B$11,0)+IF(C26="convert",$B$12,0)+IF(C27="convert",$B$13,0))))))*$B$10,"preference","convert") | D33: =IF($C$10>(IF((((D$3-(IF(D21="preference",$C$7,0)+IF(D22="preference",$C$8,0)+IF(D23="preference",$C$9,0)+IF(D25="preference",$C$11,0)+IF(D26="preference",$C$12,0)+IF(D27="preference",$C$13,0))))+$B$15*$B$16)/((($B$14+$B$10+(IF(D21="convert",$B$7,0)+IF(D22="convert",$B$8,0)+IF(D23="convert",$B$9,0)+IF(D25="convert",$B$11,0)+IF(D26="convert",$B$12,0)+IF(D27="convert",$B$13,0))))+$B$15)>$B$16,(((D$3-(IF(D21="preference",$C$7,0)+IF(D22="preference",$C$8,0)+IF(D23="preference",$C$9,0)+IF(D25="preference",$C$11,0)+IF(D26="preference",$C$12,0)+IF(D27="preference",$C$13,0))))+$B$15*$B$16)/((($B$14+$B$10+(IF(D21="convert",$B$7,0)+IF(D22="convert",$B$8,0)+IF(D23="convert",$B$9,0)+IF(D25="convert",$B$11,0)+IF(D26="convert",$B$12,0)+IF(D27="convert",$B$13,0))))+$B$15),((D$3-(IF(D21="preference",$C$7,0)+IF(D22="preference",$C$8,0)+IF(D23="preference",$C$9,0)+IF(D25="preference",$C$11,0)+IF(D26="preference",$C$12,0)+IF(D27="preference",$C$13,0))))/(($B$14+$B$10+(IF(D21="convert",$B$7,0)+IF(D22="convert",$B$8,0)+IF(D23="convert",$B$9,0)+IF(D25="convert",$B$11,0)+IF(D26="convert",$B$12,0)+IF(D27="convert",$B$13,0))))))*$B$10,"preference","convert") | E33: =IF($C$10>(IF((((E$3-(IF(E21="preference",$C$7,0)+IF(E22="preference",$C$8,0)+IF(E23="preference",$C$9,0)+IF(E25="preference",$C$11,0)+IF(E26="preference",$C$12,0)+IF(E27="preference",$C$13,0))))+$B$15*$B$16)/((($B$14+$B$10+(IF(E21="convert",$B$7,0)+IF(E22="convert",$B$8,0)+IF(E23="convert",$B$9,0)+IF(E25="convert",$B$11,0)+IF(E26="convert",$B$12,0)+IF(E27="convert",$B$13,0))))+$B$15)>$B$16,(((E$3-(IF(E21="preference",$C$7,0)+IF(E22="preference",$C$8,0)+IF(E23="preference",$C$9,0)+IF(E25="preference",$C$11,0)+IF(E26="preference",$C$12,0)+IF(E27="preference",$C$13,0))))+$B$15*$B$16)/((($B$14+$B$10+(IF(E21="convert",$B$7,0)+IF(E22="convert",$B$8,0)+IF(E23="convert",$B$9,0)+IF(E25="convert",$B$11,0)+IF(E26="convert",$B$12,0)+IF(E27="convert",$B$13,0))))+$B$15),((E$3-(IF(E21="preference",$C$7,0)+IF(E22="preference",$C$8,0)+IF(E23="preference",$C$9,0)+IF(E25="preference",$C$11,0)+IF(E26="preference",$C$12,0)+IF(E27="preference",$C$13,0))))/(($B$14+$B$10+(IF(E21="convert",$B$7,0)+IF(E22="convert",$B$8,0)+IF(E23="convert",$B$9,0)+IF(E25="convert",$B$11,0)+IF(E26="convert",$B$12,0)+IF(E27="convert",$B$13,0))))))*$B$10,"preference","convert") | F33: =IF($C$10>(IF((((F$3-(IF(F21="preference",$C$7,0)+IF(F22="preference",$C$8,0)+IF(F23="preference",$C$9,0)+IF(F25="preference",$C$11,0)+IF(F26="preference",$C$12,0)+IF(F27="preference",$C$13,0))))+$B$15*$B$16)/((($B$14+$B$10+(IF(F21="convert",$B$7,0)+IF(F22="convert",$B$8,0)+IF(F23="convert",$B$9,0)+IF(F25="convert",$B$11,0)+IF(F26="convert",$B$12,0)+IF(F27="convert",$B$13,0))))+$B$15)>$B$16,(((F$3-(IF(F21="preference",$C$7,0)+IF(F22="preference",$C$8,0)+IF(F23="preference",$C$9,0)+IF(F25="preference",$C$11,0)+IF(F26="preference",$C$12,0)+IF(F27="preference",$C$13,0))))+$B$15*$B$16)/((($B$14+$B$10+(IF(F21="convert",$B$7,0)+IF(F22="convert",$B$8,0)+IF(F23="convert",$B$9,0)+IF(F25="convert",$B$11,0)+IF(F26="convert",$B$12,0)+IF(F27="convert",$B$13,0))))+$B$15),((F$3-(IF(F21="preference",$C$7,0)+IF(F22="preference",$C$8,0)+IF(F23="preference",$C$9,0)+IF(F25="preference",$C$11,0)+IF(F26="preference",$C$12,0)+IF(F27="preference",$C$13,0))))/(($B$14+$B$10+(IF(F21="convert",$B$7,0)+IF(F22="convert",$B$8,0)+IF(F23="convert",$B$9,0)+IF(F25="convert",$B$11,0)+IF(F26="convert",$B$12,0)+IF(F27="convert",$B$13,0))))))*$B$10,"preference","convert")
A34: B | B34: =IF($C$11>(IF((((B$3-(IF(B21="preference",$C$7,0)+IF(B22="preference",$C$8,0)+IF(B23="preference",$C$9,0)+IF(B24="preference",$C$10,0)+IF(B26="preference",$C$12,0)+IF(B27="preference",$C$13,0))))+$B$15*$B$16)/((($B$14+$B$11+(IF(B21="convert",$B$7,0)+IF(B22="convert",$B$8,0)+IF(B23="convert",$B$9,0)+IF(B24="convert",$B$10,0)+IF(B26="convert",$B$12,0)+IF(B27="convert",$B$13,0))))+$B$15)>$B$16,(((B$3-(IF(B21="preference",$C$7,0)+IF(B22="preference",$C$8,0)+IF(B23="preference",$C$9,0)+IF(B24="preference",$C$10,0)+IF(B26="preference",$C$12,0)+IF(B27="preference",$C$13,0))))+$B$15*$B$16)/((($B$14+$B$11+(IF(B21="convert",$B$7,0)+IF(B22="convert",$B$8,0)+IF(B23="convert",$B$9,0)+IF(B24="convert",$B$10,0)+IF(B26="convert",$B$12,0)+IF(B27="convert",$B$13,0))))+$B$15),((B$3-(IF(B21="preference",$C$7,0)+IF(B22="preference",$C$8,0)+IF(B23="preference",$C$9,0)+IF(B24="preference",$C$10,0)+IF(B26="preference",$C$12,0)+IF(B27="preference",$C$13,0))))/(($B$14+$B$11+(IF(B21="convert",$B$7,0)+IF(B22="convert",$B$8,0)+IF(B23="convert",$B$9,0)+IF(B24="convert",$B$10,0)+IF(B26="convert",$B$12,0)+IF(B27="convert",$B$13,0))))))*$B$11,"preference","convert") | C34: =IF($C$11>(IF((((C$3-(IF(C21="preference",$C$7,0)+IF(C22="preference",$C$8,0)+IF(C23="preference",$C$9,0)+IF(C24="preference",$C$10,0)+IF(C26="preference",$C$12,0)+IF(C27="preference",$C$13,0))))+$B$15*$B$16)/((($B$14+$B$11+(IF(C21="convert",$B$7,0)+IF(C22="convert",$B$8,0)+IF(C23="convert",$B$9,0)+IF(C24="convert",$B$10,0)+IF(C26="convert",$B$12,0)+IF(C27="convert",$B$13,0))))+$B$15)>$B$16,(((C$3-(IF(C21="preference",$C$7,0)+IF(C22="preference",$C$8,0)+IF(C23="preference",$C$9,0)+IF(C24="preference",$C$10,0)+IF(C26="preference",$C$12,0)+IF(C27="preference",$C$13,0))))+$B$15*$B$16)/((($B$14+$B$11+(IF(C21="convert",$B$7,0)+IF(C22="convert",$B$8,0)+IF(C23="convert",$B$9,0)+IF(C24="convert",$B$10,0)+IF(C26="convert",$B$12,0)+IF(C27="convert",$B$13,0))))+$B$15),((C$3-(IF(C21="preference",$C$7,0)+IF(C22="preference",$C$8,0)+IF(C23="preference",$C$9,0)+IF(C24="preference",$C$10,0)+IF(C26="preference",$C$12,0)+IF(C27="preference",$C$13,0))))/(($B$14+$B$11+(IF(C21="convert",$B$7,0)+IF(C22="convert",$B$8,0)+IF(C23="convert",$B$9,0)+IF(C24="convert",$B$10,0)+IF(C26="convert",$B$12,0)+IF(C27="convert",$B$13,0))))))*$B$11,"preference","convert") | D34: =IF($C$11>(IF((((D$3-(IF(D21="preference",$C$7,0)+IF(D22="preference",$C$8,0)+IF(D23="preference",$C$9,0)+IF(D24="preference",$C$10,0)+IF(D26="preference",$C$12,0)+IF(D27="preference",$C$13,0))))+$B$15*$B$16)/((($B$14+$B$11+(IF(D21="convert",$B$7,0)+IF(D22="convert",$B$8,0)+IF(D23="convert",$B$9,0)+IF(D24="convert",$B$10,0)+IF(D26="convert",$B$12,0)+IF(D27="convert",$B$13,0))))+$B$15)>$B$16,(((D$3-(IF(D21="preference",$C$7,0)+IF(D22="preference",$C$8,0)+IF(D23="preference",$C$9,0)+IF(D24="preference",$C$10,0)+IF(D26="preference",$C$12,0)+IF(D27="preference",$C$13,0))))+$B$15*$B$16)/((($B$14+$B$11+(IF(D21="convert",$B$7,0)+IF(D22="convert",$B$8,0)+IF(D23="convert",$B$9,0)+IF(D24="convert",$B$10,0)+IF(D26="convert",$B$12,0)+IF(D27="convert",$B$13,0))))+$B$15),((D$3-(IF(D21="preference",$C$7,0)+IF(D22="preference",$C$8,0)+IF(D23="preference",$C$9,0)+IF(D24="preference",$C$10,0)+IF(D26="preference",$C$12,0)+IF(D27="preference",$C$13,0))))/(($B$14+$B$11+(IF(D21="convert",$B$7,0)+IF(D22="convert",$B$8,0)+IF(D23="convert",$B$9,0)+IF(D24="convert",$B$10,0)+IF(D26="convert",$B$12,0)+IF(D27="convert",$B$13,0))))))*$B$11,"preference","convert") | E34: =IF($C$11>(IF((((E$3-(IF(E21="preference",$C$7,0)+IF(E22="preference",$C$8,0)+IF(E23="preference",$C$9,0)+IF(E24="preference",$C$10,0)+IF(E26="preference",$C$12,0)+IF(E27="preference",$C$13,0))))+$B$15*$B$16)/((($B$14+$B$11+(IF(E21="convert",$B$7,0)+IF(E22="convert",$B$8,0)+IF(E23="convert",$B$9,0)+IF(E24="convert",$B$10,0)+IF(E26="convert",$B$12,0)+IF(E27="convert",$B$13,0))))+$B$15)>$B$16,(((E$3-(IF(E21="preference",$C$7,0)+IF(E22="preference",$C$8,0)+IF(E23="preference",$C$9,0)+IF(E24="preference",$C$10,0)+IF(E26="preference",$C$12,0)+IF(E27="preference",$C$13,0))))+$B$15*$B$16)/((($B$14+$B$11+(IF(E21="convert",$B$7,0)+IF(E22="convert",$B$8,0)+IF(E23="convert",$B$9,0)+IF(E24="convert",$B$10,0)+IF(E26="convert",$B$12,0)+IF(E27="convert",$B$13,0))))+$B$15),((E$3-(IF(E21="preference",$C$7,0)+IF(E22="preference",$C$8,0)+IF(E23="preference",$C$9,0)+IF(E24="preference",$C$10,0)+IF(E26="preference",$C$12,0)+IF(E27="preference",$C$13,0))))/(($B$14+$B$11+(IF(E21="convert",$B$7,0)+IF(E22="convert",$B$8,0)+IF(E23="convert",$B$9,0)+IF(E24="convert",$B$10,0)+IF(E26="convert",$B$12,0)+IF(E27="convert",$B$13,0))))))*$B$11,"preference","convert") | F34: =IF($C$11>(IF((((F$3-(IF(F21="preference",$C$7,0)+IF(F22="preference",$C$8,0)+IF(F23="preference",$C$9,0)+IF(F24="preference",$C$10,0)+IF(F26="preference",$C$12,0)+IF(F27="preference",$C$13,0))))+$B$15*$B$16)/((($B$14+$B$11+(IF(F21="convert",$B$7,0)+IF(F22="convert",$B$8,0)+IF(F23="convert",$B$9,0)+IF(F24="convert",$B$10,0)+IF(F26="convert",$B$12,0)+IF(F27="convert",$B$13,0))))+$B$15)>$B$16,(((F$3-(IF(F21="preference",$C$7,0)+IF(F22="preference",$C$8,0)+IF(F23="preference",$C$9,0)+IF(F24="preference",$C$10,0)+IF(F26="preference",$C$12,0)+IF(F27="preference",$C$13,0))))+$B$15*$B$16)/((($B$14+$B$11+(IF(F21="convert",$B$7,0)+IF(F22="convert",$B$8,0)+IF(F23="convert",$B$9,0)+IF(F24="convert",$B$10,0)+IF(F26="convert",$B$12,0)+IF(F27="convert",$B$13,0))))+$B$15),((F$3-(IF(F21="preference",$C$7,0)+IF(F22="preference",$C$8,0)+IF(F23="preference",$C$9,0)+IF(F24="preference",$C$10,0)+IF(F26="preference",$C$12,0)+IF(F27="preference",$C$13,0))))/(($B$14+$B$11+(IF(F21="convert",$B$7,0)+IF(F22="convert",$B$8,0)+IF(F23="convert",$B$9,0)+IF(F24="convert",$B$10,0)+IF(F26="convert",$B$12,0)+IF(F27="convert",$B$13,0))))))*$B$11,"preference","convert")
A35: A | B35: =IF($C$12>(IF((((B$3-(IF(B21="preference",$C$7,0)+IF(B22="preference",$C$8,0)+IF(B23="preference",$C$9,0)+IF(B24="preference",$C$10,0)+IF(B25="preference",$C$11,0)+IF(B27="preference",$C$13,0))))+$B$15*$B$16)/((($B$14+$B$12+(IF(B21="convert",$B$7,0)+IF(B22="convert",$B$8,0)+IF(B23="convert",$B$9,0)+IF(B24="convert",$B$10,0)+IF(B25="convert",$B$11,0)+IF(B27="convert",$B$13,0))))+$B$15)>$B$16,(((B$3-(IF(B21="preference",$C$7,0)+IF(B22="preference",$C$8,0)+IF(B23="preference",$C$9,0)+IF(B24="preference",$C$10,0)+IF(B25="preference",$C$11,0)+IF(B27="preference",$C$13,0))))+$B$15*$B$16)/((($B$14+$B$12+(IF(B21="convert",$B$7,0)+IF(B22="convert",$B$8,0)+IF(B23="convert",$B$9,0)+IF(B24="convert",$B$10,0)+IF(B25="convert",$B$11,0)+IF(B27="convert",$B$13,0))))+$B$15),((B$3-(IF(B21="preference",$C$7,0)+IF(B22="preference",$C$8,0)+IF(B23="preference",$C$9,0)+IF(B24="preference",$C$10,0)+IF(B25="preference",$C$11,0)+IF(B27="preference",$C$13,0))))/(($B$14+$B$12+(IF(B21="convert",$B$7,0)+IF(B22="convert",$B$8,0)+IF(B23="convert",$B$9,0)+IF(B24="convert",$B$10,0)+IF(B25="convert",$B$11,0)+IF(B27="convert",$B$13,0))))))*$B$12,"preference","convert") | C35: =IF($C$12>(IF((((C$3-(IF(C21="preference",$C$7,0)+IF(C22="preference",$C$8,0)+IF(C23="preference",$C$9,0)+IF(C24="preference",$C$10,0)+IF(C25="preference",$C$11,0)+IF(C27="preference",$C$13,0))))+$B$15*$B$16)/((($B$14+$B$12+(IF(C21="convert",$B$7,0)+IF(C22="convert",$B$8,0)+IF(C23="convert",$B$9,0)+IF(C24="convert",$B$10,0)+IF(C25="convert",$B$11,0)+IF(C27="convert",$B$13,0))))+$B$15)>$B$16,(((C$3-(IF(C21="preference",$C$7,0)+IF(C22="preference",$C$8,0)+IF(C23="preference",$C$9,0)+IF(C24="preference",$C$10,0)+IF(C25="preference",$C$11,0)+IF(C27="preference",$C$13,0))))+$B$15*$B$16)/((($B$14+$B$12+(IF(C21="convert",$B$7,0)+IF(C22="convert",$B$8,0)+IF(C23="convert",$B$9,0)+IF(C24="convert",$B$10,0)+IF(C25="convert",$B$11,0)+IF(C27="convert",$B$13,0))))+$B$15),((C$3-(IF(C21="preference",$C$7,0)+IF(C22="preference",$C$8,0)+IF(C23="preference",$C$9,0)+IF(C24="preference",$C$10,0)+IF(C25="preference",$C$11,0)+IF(C27="preference",$C$13,0))))/(($B$14+$B$12+(IF(C21="convert",$B$7,0)+IF(C22="convert",$B$8,0)+IF(C23="convert",$B$9,0)+IF(C24="convert",$B$10,0)+IF(C25="convert",$B$11,0)+IF(C27="convert",$B$13,0))))))*$B$12,"preference","convert") | D35: =IF($C$12>(IF((((D$3-(IF(D21="preference",$C$7,0)+IF(D22="preference",$C$8,0)+IF(D23="preference",$C$9,0)+IF(D24="preference",$C$10,0)+IF(D25="preference",$C$11,0)+IF(D27="preference",$C$13,0))))+$B$15*$B$16)/((($B$14+$B$12+(IF(D21="convert",$B$7,0)+IF(D22="convert",$B$8,0)+IF(D23="convert",$B$9,0)+IF(D24="convert",$B$10,0)+IF(D25="convert",$B$11,0)+IF(D27="convert",$B$13,0))))+$B$15)>$B$16,(((D$3-(IF(D21="preference",$C$7,0)+IF(D22="preference",$C$8,0)+IF(D23="preference",$C$9,0)+IF(D24="preference",$C$10,0)+IF(D25="preference",$C$11,0)+IF(D27="preference",$C$13,0))))+$B$15*$B$16)/((($B$14+$B$12+(IF(D21="convert",$B$7,0)+IF(D22="convert",$B$8,0)+IF(D23="convert",$B$9,0)+IF(D24="convert",$B$10,0)+IF(D25="convert",$B$11,0)+IF(D27="convert",$B$13,0))))+$B$15),((D$3-(IF(D21="preference",$C$7,0)+IF(D22="preference",$C$8,0)+IF(D23="preference",$C$9,0)+IF(D24="preference",$C$10,0)+IF(D25="preference",$C$11,0)+IF(D27="preference",$C$13,0))))/(($B$14+$B$12+(IF(D21="convert",$B$7,0)+IF(D22="convert",$B$8,0)+IF(D23="convert",$B$9,0)+IF(D24="convert",$B$10,0)+IF(D25="convert",$B$11,0)+IF(D27="convert",$B$13,0))))))*$B$12,"preference","convert") | E35: =IF($C$12>(IF((((E$3-(IF(E21="preference",$C$7,0)+IF(E22="preference",$C$8,0)+IF(E23="preference",$C$9,0)+IF(E24="preference",$C$10,0)+IF(E25="preference",$C$11,0)+IF(E27="preference",$C$13,0))))+$B$15*$B$16)/((($B$14+$B$12+(IF(E21="convert",$B$7,0)+IF(E22="convert",$B$8,0)+IF(E23="convert",$B$9,0)+IF(E24="convert",$B$10,0)+IF(E25="convert",$B$11,0)+IF(E27="convert",$B$13,0))))+$B$15)>$B$16,(((E$3-(IF(E21="preference",$C$7,0)+IF(E22="preference",$C$8,0)+IF(E23="preference",$C$9,0)+IF(E24="preference",$C$10,0)+IF(E25="preference",$C$11,0)+IF(E27="preference",$C$13,0))))+$B$15*$B$16)/((($B$14+$B$12+(IF(E21="convert",$B$7,0)+IF(E22="convert",$B$8,0)+IF(E23="convert",$B$9,0)+IF(E24="convert",$B$10,0)+IF(E25="convert",$B$11,0)+IF(E27="convert",$B$13,0))))+$B$15),((E$3-(IF(E21="preference",$C$7,0)+IF(E22="preference",$C$8,0)+IF(E23="preference",$C$9,0)+IF(E24="preference",$C$10,0)+IF(E25="preference",$C$11,0)+IF(E27="preference",$C$13,0))))/(($B$14+$B$12+(IF(E21="convert",$B$7,0)+IF(E22="convert",$B$8,0)+IF(E23="convert",$B$9,0)+IF(E24="convert",$B$10,0)+IF(E25="convert",$B$11,0)+IF(E27="convert",$B$13,0))))))*$B$12,"preference","convert") | F35: =IF($C$12>(IF((((F$3-(IF(F21="preference",$C$7,0)+IF(F22="preference",$C$8,0)+IF(F23="preference",$C$9,0)+IF(F24="preference",$C$10,0)+IF(F25="preference",$C$11,0)+IF(F27="preference",$C$13,0))))+$B$15*$B$16)/((($B$14+$B$12+(IF(F21="convert",$B$7,0)+IF(F22="convert",$B$8,0)+IF(F23="convert",$B$9,0)+IF(F24="convert",$B$10,0)+IF(F25="convert",$B$11,0)+IF(F27="convert",$B$13,0))))+$B$15)>$B$16,(((F$3-(IF(F21="preference",$C$7,0)+IF(F22="preference",$C$8,0)+IF(F23="preference",$C$9,0)+IF(F24="preference",$C$10,0)+IF(F25="preference",$C$11,0)+IF(F27="preference",$C$13,0))))+$B$15*$B$16)/((($B$14+$B$12+(IF(F21="convert",$B$7,0)+IF(F22="convert",$B$8,0)+IF(F23="convert",$B$9,0)+IF(F24="convert",$B$10,0)+IF(F25="convert",$B$11,0)+IF(F27="convert",$B$13,0))))+$B$15),((F$3-(IF(F21="preference",$C$7,0)+IF(F22="preference",$C$8,0)+IF(F23="preference",$C$9,0)+IF(F24="preference",$C$10,0)+IF(F25="preference",$C$11,0)+IF(F27="preference",$C$13,0))))/(($B$14+$B$12+(IF(F21="convert",$B$7,0)+IF(F22="convert",$B$8,0)+IF(F23="convert",$B$9,0)+IF(F24="convert",$B$10,0)+IF(F25="convert",$B$11,0)+IF(F27="convert",$B$13,0))))))*$B$12,"preference","convert")
