Workbook

Sheet Assumptions
A1: KELVIN DYNAMICS — SERIES F ASSUMPTIONS
A3: Round terms (knobs)
A4: Series F pre-money (USD) | B4: 1400000000 | C4: knob
A5: Series F primary raise (USD) | B5: 30000000 | C5: knob
A6: Series F secondary tender (USD) | B6: 15000000 | C6: knob
A7: Tender PPS multiplier | B7: 0.85 | C7: knob
A8: ESOP refresh target % (post-F FD) | B8: 0.13 | C8: knob
A9: Our fund check (USD) | B9: 10000000 | C9: knob
A10: F_LEAD primary check (USD) | B10: 20000000 | C10: knob
A11: Option strike (USD) | B11: 1 | C11: knob
A13: Exit values (USD)
A14: Exit 1 | B14: 700000000
A15: Exit 2 | B15: 1200000000
A16: Exit 3 (sensitivity ref) | B16: 2000000000
A17: Exit 4 | B17: 4000000000
A18: Exit 5 | B18: 8000000000
A20: Prior-round OCPs (USD per share)
A21: OCP Seed | B21: 1
A22: OCP Series A | B22: 3
A23: OCP Series B | B23: 10
A24: OCP Series C | B24: 25
A25: OCP Series D (post-E NCP) | B25: 58.118347 | C25: D effective OCP after v3 AD
A26: OCP Series D (original at issuance) | B26: 60 | C26: for compound v3·v4 ratio
A27: OCP Series E | B27: 49.158311
A29: Convertible Notes
A30: Note A principal (USD) | B30: 5000000
A31: Note A cap (USD) | B31: 1000000000
A32: Note A discount | B32: 0.2
A33: Note B principal (USD) | B33: 3000000
A34: Note B cap (USD) | B34: 1600000000
A35: Note B discount | B35: 0.15
A37: Broad-based WA AD inputs
A38: Pre-F broad-based FD (A in NCP formula) | B38: 36617961
A39: Pre-F option pool (issued+unissued) | B39: 4394667
A40: Pre-F issued options | B40: 2500000
A41: Pre-F unissued options | B41: 1894667
A43: Pre-F share counts
A44: F1 (CEO) common | B44: 4000000
A45: F2 (CTO) common | B45: 2500000
A46: F3 (Chief Sci) common | B46: 1500000
...

Sheet Pro-Forma
A1: PRO-FORMA POST-F CAP TABLE
A3: AD BLOCK — Broad-based WA (test F_PPS < OCP per class)
A4: Class | B4: OCP | C4: F_PPS | D4: Trigger? | E4: NCP | F4: new_ratio | G4: Original shares | H4: As-converted shares | I4: AD increment
A5: Seed | B5: =Assumptions!$B$21 | C5: =Assumptions!$B$75 | D5: =IF(Assumptions!$B$75<Assumptions!$B$21,"YES","no") | E5: =IF(Assumptions!$B$75<Assumptions!$B$21,Assumptions!$B$21*(Assumptions!$B$38+Assumptions!$B$5/Assumptions!$B$21)/(Assumptions!$B$38+Assumptions!$B$5/Assumptions!$B$75),Assumptions!$B$21) | F5: =Assumptions!$B$21/'Pro-Forma'!$E$5 | G5: =Assumptions!$B$48 | H5: ='Pro-Forma'!$G$5*'Pro-Forma'!$F$5 | I5: =H5-Assumptions!$B$48
A6: Series A | B6: =Assumptions!$B$22 | C6: =Assumptions!$B$75 | D6: =IF(Assumptions!$B$75<Assumptions!$B$22,"YES","no") | E6: =IF(Assumptions!$B$75<Assumptions!$B$22,Assumptions!$B$22*(Assumptions!$B$38+Assumptions!$B$5/Assumptions!$B$22)/(Assumptions!$B$38+Assumptions!$B$5/Assumptions!$B$75),Assumptions!$B$22) | F6: =Assumptions!$B$22/'Pro-Forma'!$E$6 | G6: =Assumptions!$B$49 | H6: ='Pro-Forma'!$G$6*'Pro-Forma'!$F$6 | I6: =H6-Assumptions!$B$49
A7: Series B | B7: =Assumptions!$B$23 | C7: =Assumptions!$B$75 | D7: =IF(Assumptions!$B$75<Assumptions!$B$23,"YES","no") | E7: =IF(Assumptions!$B$75<Assumptions!$B$23,Assumptions!$B$23*(Assumptions!$B$38+Assumptions!$B$5/Assumptions!$B$23)/(Assumptions!$B$38+Assumptions!$B$5/Assumptions!$B$75),Assumptions!$B$23) | F7: =Assumptions!$B$23/'Pro-Forma'!$E$7 | G7: =Assumptions!$B$50 | H7: ='Pro-Forma'!$G$7*'Pro-Forma'!$F$7 | I7: =H7-Assumptions!$B$50
A8: Series C | B8: =Assumptions!$B$24 | C8: =Assumptions!$B$75 | D8: =IF(Assumptions!$B$75<Assumptions!$B$24,"YES","no") | E8: =IF(Assumptions!$B$75<Assumptions!$B$24,Assumptions!$B$24*(Assumptions!$B$38+Assumptions!$B$5/Assumptions!$B$24)/(Assumptions!$B$38+Assumptions!$B$5/Assumptions!$B$75),Assumptions!$B$24) | F8: =Assumptions!$B$24/'Pro-Forma'!$E$8 | G8: =Assumptions!$B$51 | H8: ='Pro-Forma'!$G$8*'Pro-Forma'!$F$8 | I8: =H8-Assumptions!$B$51
A9: Series D | B9: =Assumptions!$B$25 | C9: =Assumptions!$B$75 | D9: =IF(Assumptions!$B$75<Assumptions!$B$25,"YES","no") | E9: =IF(Assumptions!$B$75<Assumptions!$B$25,Assumptions!$B$25*(Assumptions!$B$38+Assumptions!$B$5/Assumptions!$B$25)/(Assumptions!$B$38+Assumptions!$B$5/Assumptions!$B$75),Assumptions!$B$25) | F9: =Assumptions!$B$26/'Pro-Forma'!$E$9 | G9: =Assumptions!$B$53 | H9: ='Pro-Forma'!$G$9*'Pro-Forma'!$F$9 | I9: =H9-Assumptions!$B$52
A10: Series E | B10: =Assumptions!$B$27 | C10: =Assumptions!$B$75 | D10: =IF(Assumptions!$B$75<Assumptions!$B$27,"YES","no") | E10: =IF(Assumptions!$B$75<Assumptions!$B$27,Assumptions!$B$27*(Assumptions!$B$38+Assumptions!$B$5/Assumptions!$B$27)/(Assumptions!$B$38+Assumptions!$B$5/Assumptions!$B$75),Assumptions!$B$27) | F10: =Assumptions!$B$27/'Pro-Forma'!$E$10 | G10: =Assumptions!$B$54 | H10: ='Pro-Forma'!$G$10*'Pro-Forma'!$F$10 | I10: =H10-Assumptions!$B$54
A12: NOTES BLOCK
A13: Note | B13: Principal | C13: Cap | D13: Discount | E13: Cap-impl PPS | F13: Disc-impl PPS | G13: Conv PPS | H13: Branch | I13: Shares
A14: Note A | B14: =Assumptions!$B$30 | C14: =Assumptions!$B$31 | D14: =Assumptions!$B$32 | E14: =Assumptions!$B$82 | F14: =Assumptions!$B$83 | G14: =Assumptions!$B$84 | H14: =IF(Assumptions!$B$82<Assumptions!$B$83,"cap","discount") | I14: =Assumptions!$B$85
A15: Note B | B15: =Assumptions!$B$33 | C15: =Assumptions!$B$34 | D15: =Assumptions!$B$35 | E15: =Assumptions!$B$86 | F15: =Assumptions!$B$87 | G15: =Assumptions!$B$88 | H15: =IF(Assumptions!$B$86<Assumptions!$B$87,"cap","discount") | I15: =Assumptions!$B$89
A17: TENDER BLOCK — Secondary $15M @ 0.85×F_PPS
A18: Item | B18: Value
A19: Tender PPS | B19: =Assumptions!$B$7*Assumptions!$B$75
A20: Tender shares total | B20: =Assumptions!$B$6/'Pro-Forma'!$B$19
A21: F1 tender out | B21: =0.5*'Pro-Forma'!$B$20
A22: F2 tender out | B22: =0.3125*'Pro-Forma'!$B$20
A23: F3 tender out | B23: =0.1875*'Pro-Forma'!$B$20
A24: F_LEAD secondary common | B24: ='Pro-Forma'!$B$20
A25: F_LEAD primary preferred | B25: =Assumptions!$B$10/Assumptions!$B$75
A26: Our fund primary preferred | B26: =Assumptions!$B$9/Assumptions!$B$75
A28: POST-F CAP TABLE BY STAKEHOLDER
A29: Stakeholder | B29: Class | C29: Pre-F shares | D29: Post-F shares | E29: Ownership %
A30: F1 (CEO) | B30: Common | C30: =Assumptions!$B$44 | D30: =Assumptions!$B$44-'Pro-Forma'!$B$21 | E30: =$D$30/Assumptions!$B$76
A31: F2 (CTO) | B31: Common | C31: =Assumptions!$B$45 | D31: =Assumptions!$B$45-'Pro-Forma'!$B$22 | E31: =$D$31/Assumptions!$B$76
A32: F3 (Chief Sci) | B32: Common | C32: =Assumptions!$B$46 | D32: =Assumptions!$B$46-'Pro-Forma'!$B$23 | E32: =$D$32/Assumptions!$B$76
A33: RSA holders (E1-E10) | B33: Common (RSA) | C33: =Assumptions!$B$47 | D33: =Assumptions!$B$47 | E33: =$D$33/Assumptions!$B$76
A34: Issued options (pre-F) | B34: Options-issued | C34: =Assumptions!$B$40 | D34: =Assumptions!$B$40 | E34: =$D$34/Assumptions!$B$76
A35: Unissued ESOP pool (incl topup) | B35: Options-unissued | C35: =Assumptions!$B$41 | D35: =Assumptions!$B$41+Assumptions!$B$77 | E35: =$D$35/Assumptions!$B$76
A36: SEED1 | B36: Seed Preferred | C36: =Assumptions!$B$48 | D36: =Assumptions!$B$48 | E36: =$D$36/Assumptions!$B$76
A37: A1 | B37: Series A | C37: =Assumptions!$B$49 | D37: =Assumptions!$B$49 | E37: =$D$37/Assumptions!$B$76
A38: B1 | B38: Series B | C38: =Assumptions!$B$50 | D38: =Assumptions!$B$50 | E38: =$D$38/Assumptions!$B$76
A39: C1 | B39: Series C | C39: =Assumptions!$B$51 | D39: =Assumptions!$B$51 | E39: =$D$39/Assumptions!$B$76
A40: D1 | B40: Series D | C40: =Assumptions!$B$52 | D40: =Assumptions!$B$52+Assumptions!$B$79 | E40: =$D$40/Assumptions!$B$76
A41: E1_INV | B41: Series E | C41: =610267 | D41: =610267+(Assumptions!$B$81)*(610267/Assumptions!$B$54) | E41: =$D$41/Assumptions!$B$76
A42: E2_INV | B42: Series E | C42: =610267 | D42: =610267+(Assumptions!$B$81)*(610267/Assumptions!$B$54) | E42: =$D$42/Assumptions!$B$76
A43: E3_INV | B43: Series E | C43: =610267 | D43: =610267+(Assumptions!$B$81)*(610267/Assumptions!$B$54) | E43: =$D$43/Assumptions!$B$76
A44: E4_INV | B44: Series E | C44: =610267 | D44: =610267+(Assumptions!$B$81)*(610267/Assumptions!$B$54) | E44: =$D$44/Assumptions!$B$76
...

Sheet Waterfall
A1: WATERFALL — 5 EXITS × 7 PRICED CLASSES (35 elections)
A3: Class | B3: Invested (USD) | C3: As-converted shares | D3: Election @ $700M | E3: Election @ $1.2B | F3: Election @ $2B | G3: Election @ $4B | H3: Election @ $8B | I3: Proceeds @ $700M | J3: Proceeds @ $1.2B | K3: Proceeds @ $2B | L3: Proceeds @ $4B | M3: Proceeds @ $8B
A4: F (Series F) | B4: =Assumptions!$B$5 | C4: ='Pro-Forma'!$B$25+'Pro-Forma'!$B$26 | D4: =IF(B4>C4*Assumptions!$B$96,"preference","convert") | E4: =IF(B4>C4*Assumptions!$B$106,"preference","convert") | F4: =IF(B4>C4*Assumptions!$B$116,"preference","convert") | G4: =IF(B4>C4*Assumptions!$B$126,"preference","convert") | H4: =IF(B4>C4*Assumptions!$B$136,"preference","convert") | I4: =IF(D4="preference",B4,C4*Assumptions!$B$94) | J4: =IF(E4="preference",B4,C4*Assumptions!$B$104) | K4: =IF(F4="preference",B4,C4*Assumptions!$B$114) | L4: =IF(G4="preference",B4,C4*Assumptions!$B$124) | M4: =IF(H4="preference",B4,C4*Assumptions!$B$134)
A5: E (Series E) | B5: =Assumptions!$B$62 | C5: =Assumptions!$B$54+Assumptions!$B$81 | D5: =IF(B5>C5*Assumptions!$B$97,"preference","convert") | E5: =IF(B5>C5*Assumptions!$B$107,"preference","convert") | F5: =IF(B5>C5*Assumptions!$B$117,"preference","convert") | G5: =IF(B5>C5*Assumptions!$B$127,"preference","convert") | H5: =IF(B5>C5*Assumptions!$B$137,"preference","convert") | I5: =IF(D5="preference",B5,C5*Assumptions!$B$94) | J5: =IF(E5="preference",B5,C5*Assumptions!$B$104) | K5: =IF(F5="preference",B5,C5*Assumptions!$B$114) | L5: =IF(G5="preference",B5,C5*Assumptions!$B$124) | M5: =IF(H5="preference",B5,C5*Assumptions!$B$134)
A6: D (Series D) | B6: =Assumptions!$B$61 | C6: =Assumptions!$B$52+Assumptions!$B$79 | D6: =IF(B6>C6*Assumptions!$B$98,"preference","convert") | E6: =IF(B6>C6*Assumptions!$B$108,"preference","convert") | F6: =IF(B6>C6*Assumptions!$B$118,"preference","convert") | G6: =IF(B6>C6*Assumptions!$B$128,"preference","convert") | H6: =IF(B6>C6*Assumptions!$B$138,"preference","convert") | I6: =IF(D6="preference",B6,C6*Assumptions!$B$94) | J6: =IF(E6="preference",B6,C6*Assumptions!$B$104) | K6: =IF(F6="preference",B6,C6*Assumptions!$B$114) | L6: =IF(G6="preference",B6,C6*Assumptions!$B$124) | M6: =IF(H6="preference",B6,C6*Assumptions!$B$134)
A7: C (Series C) | B7: =Assumptions!$B$60 | C7: =Assumptions!$B$51 | D7: =IF(B7>C7*Assumptions!$B$99,"preference","convert") | E7: =IF(B7>C7*Assumptions!$B$109,"preference","convert") | F7: =IF(B7>C7*Assumptions!$B$119,"preference","convert") | G7: =IF(B7>C7*Assumptions!$B$129,"preference","convert") | H7: =IF(B7>C7*Assumptions!$B$139,"preference","convert") | I7: =IF(D7="preference",B7,C7*Assumptions!$B$94) | J7: =IF(E7="preference",B7,C7*Assumptions!$B$104) | K7: =IF(F7="preference",B7,C7*Assumptions!$B$114) | L7: =IF(G7="preference",B7,C7*Assumptions!$B$124) | M7: =IF(H7="preference",B7,C7*Assumptions!$B$134)
A8: B (Series B) | B8: =Assumptions!$B$59 | C8: =Assumptions!$B$50 | D8: =IF(B8>C8*Assumptions!$B$100,"preference","convert") | E8: =IF(B8>C8*Assumptions!$B$110,"preference","convert") | F8: =IF(B8>C8*Assumptions!$B$120,"preference","convert") | G8: =IF(B8>C8*Assumptions!$B$130,"preference","convert") | H8: =IF(B8>C8*Assumptions!$B$140,"preference","convert") | I8: =IF(D8="preference",B8,C8*Assumptions!$B$94) | J8: =IF(E8="preference",B8,C8*Assumptions!$B$104) | K8: =IF(F8="preference",B8,C8*Assumptions!$B$114) | L8: =IF(G8="preference",B8,C8*Assumptions!$B$124) | M8: =IF(H8="preference",B8,C8*Assumptions!$B$134)
A9: A (Series A) | B9: =Assumptions!$B$58 | C9: =Assumptions!$B$49 | D9: =IF(B9>C9*Assumptions!$B$101,"preference","convert") | E9: =IF(B9>C9*Assumptions!$B$111,"preference","convert") | F9: =IF(B9>C9*Assumptions!$B$121,"preference","convert") | G9: =IF(B9>C9*Assumptions!$B$131,"preference","convert") | H9: =IF(B9>C9*Assumptions!$B$141,"preference","convert") | I9: =IF(D9="preference",B9,C9*Assumptions!$B$94) | J9: =IF(E9="preference",B9,C9*Assumptions!$B$104) | K9: =IF(F9="preference",B9,C9*Assumptions!$B$114) | L9: =IF(G9="preference",B9,C9*Assumptions!$B$124) | M9: =IF(H9="preference",B9,C9*Assumptions!$B$134)
A10: Seed | B10: =Assumptions!$B$57 | C10: =Assumptions!$B$48 | D10: =IF(B10>C10*Assumptions!$B$102,"preference","convert") | E10: =IF(B10>C10*Assumptions!$B$112,"preference","convert") | F10: =IF(B10>C10*Assumptions!$B$122,"preference","convert") | G10: =IF(B10>C10*Assumptions!$B$132,"preference","convert") | H10: =IF(B10>C10*Assumptions!$B$142,"preference","convert") | I10: =IF(D10="preference",B10,C10*Assumptions!$B$94) | J10: =IF(E10="preference",B10,C10*Assumptions!$B$104) | K10: =IF(F10="preference",B10,C10*Assumptions!$B$114) | L10: =IF(G10="preference",B10,C10*Assumptions!$B$124) | M10: =IF(H10="preference",B10,C10*Assumptions!$B$134)
A11: Notes A+B (combined, common-equiv) | B11: =Assumptions!$B$30+Assumptions!$B$33 | C11: =Assumptions!$B$85+Assumptions!$B$89 | D11: ="(no election)" | E11: ="(no election)" | F11: ="(no election)" | G11: ="(no election)" | H11: ="(no election)" | I11: =(Assumptions!$B$85+Assumptions!$B$89)*Assumptions!$B$94 | J11: =(Assumptions!$B$85+Assumptions!$B$89)*Assumptions!$B$104 | K11: =(Assumptions!$B$85+Assumptions!$B$89)*Assumptions!$B$114 | L11: =(Assumptions!$B$85+Assumptions!$B$89)*Assumptions!$B$124 | M11: =(Assumptions!$B$85+Assumptions!$B$89)*Assumptions!$B$134
A12: Common + RSAs + Secondary common (F_LEAD) | B12: =0 | C12: =(Assumptions!$B$44-'Pro-Forma'!$B$21)+(Assumptions!$B$45-'Pro-Forma'!$B$22)+(Assumptions!$B$46-'Pro-Forma'!$B$23)+Assumptions!$B$47+'Pro-Forma'!$B$24 | D12: ="(no election)" | E12: ="(no election)" | F12: ="(no election)" | G12: ="(no election)" | H12: ="(no election)" | I12: =((Assumptions!$B$44-'Pro-Forma'!$B$21)+(Assumptions!$B$45-'Pro-Forma'!$B$22)+(Assumptions!$B$46-'Pro-Forma'!$B$23)+Assumptions!$B$47+'Pro-Forma'!$B$24)*Assumptions!$B$94 | J12: =((Assumptions!$B$44-'Pro-Forma'!$B$21)+(Assumptions!$B$45-'Pro-Forma'!$B$22)+(Assumptions!$B$46-'Pro-Forma'!$B$23)+Assumptions!$B$47+'Pro-Forma'!$B$24)*Assumptions!$B$104 | K12: =((Assumptions!$B$44-'Pro-Forma'!$B$21)+(Assumptions!$B$45-'Pro-Forma'!$B$22)+(Assumptions!$B$46-'Pro-Forma'!$B$23)+Assumptions!$B$47+'Pro-Forma'!$B$24)*Assumptions!$B$114 | L12: =((Assumptions!$B$44-'Pro-Forma'!$B$21)+(Assumptions!$B$45-'Pro-Forma'!$B$22)+(Assumptions!$B$46-'Pro-Forma'!$B$23)+Assumptions!$B$47+'Pro-Forma'!$B$24)*Assumptions!$B$124 | M12: =((Assumptions!$B$44-'Pro-Forma'!$B$21)+(Assumptions!$B$45-'Pro-Forma'!$B$22)+(Assumptions!$B$46-'Pro-Forma'!$B$23)+Assumptions!$B$47+'Pro-Forma'!$B$24)*Assumptions!$B$134
A13: Issued options (net of strike if ITM) | B13: =Assumptions!$B$40*Assumptions!$B$11 | C13: =Assumptions!$B$40 | D13: ="(no election)" | E13: ="(no election)" | F13: ="(no election)" | G13: ="(no election)" | H13: ="(no election)" | I13: =IF(Assumptions!$B$94>Assumptions!$B$11,Assumptions!$B$40*(Assumptions!$B$94-Assumptions!$B$11),0) | J13: =IF(Assumptions!$B$104>Assumptions!$B$11,Assumptions!$B$40*(Assumptions!$B$104-Assumptions!$B$11),0) | K13: =IF(Assumptions!$B$114>Assumptions!$B$11,Assumptions!$B$40*(Assumptions!$B$114-Assumptions!$B$11),0) | L13: =IF(Assumptions!$B$124>Assumptions!$B$11,Assumptions!$B$40*(Assumptions!$B$124-Assumptions!$B$11),0) | M13: =IF(Assumptions!$B$134>Assumptions!$B$11,Assumptions!$B$40*(Assumptions!$B$134-Assumptions!$B$11),0)
A14: Unissued options (forfeit) | B14: =0 | C14: =Assumptions!$B$41+Assumptions!$B$77 | D14: ="(forfeit)" | E14: ="(forfeit)" | F14: ="(forfeit)" | G14: ="(forfeit)" | H14: ="(forfeit)" | I14: =0 | J14: =0 | K14: =0 | L14: =0 | M14: =0
A15: TOTAL distributed | I15: =SUM(I4:I14) | J15: =SUM(J4:J14) | K15: =SUM(K4:K14) | L15: =SUM(L4:L14) | M15: =SUM(M4:M14)
A16: Exit value (target) | I16: =Assumptions!$B$14 | J16: =Assumptions!$B$15 | K16: =Assumptions!$B$16 | L16: =Assumptions!$B$17 | M16: =Assumptions!$B$18
A17: Reconciliation Δ (TOTAL − exit) | I17: =I15-I16 | J17: =J15-J16 | K17: =K15-K16 | L17: =L15-L16 | M17: =M15-M16

Sheet Sensitivity
A1: SENSITIVITY — 3×3 grid: ESOP refresh × Series F pre-money
A2: Each cell re-solves round fixed point (F_PPS, ESOP topup, AD on D/E, both notes); proceeds at $2B exit.
A4: Ownership % (our $10M / F_PPS / T_F)
A5: Pre-money \ ESOP | B5: ESOP 11% | C5: ESOP 13% | D5: ESOP 15%
A6: Pre-money $1.2B | B6: =(Assumptions!$B$9/Assumptions!$B$146)/Assumptions!$B$147 | C6: =(Assumptions!$B$9/Assumptions!$B$188)/Assumptions!$B$189 | D6: =(Assumptions!$B$9/Assumptions!$B$230)/Assumptions!$B$231
A7: Pre-money $1.4B | B7: =(Assumptions!$B$9/Assumptions!$B$160)/Assumptions!$B$161 | C7: =(Assumptions!$B$9/Assumptions!$B$202)/Assumptions!$B$203 | D7: =(Assumptions!$B$9/Assumptions!$B$244)/Assumptions!$B$245
A8: Pre-money $1.8B | B8: =(Assumptions!$B$9/Assumptions!$B$174)/Assumptions!$B$175 | C8: =(Assumptions!$B$9/Assumptions!$B$216)/Assumptions!$B$217 | D8: =(Assumptions!$B$9/Assumptions!$B$258)/Assumptions!$B$259
A10: $ proceeds at $2B exit
A11: Pre-money \ ESOP | B11: ESOP 11% | C11: ESOP 13% | D11: ESOP 15%
A12: Pre-money $1.2B | B12: =IF(Assumptions!$B$5>(Assumptions!$B$5/Assumptions!$B$146)*Assumptions!$B$158,Assumptions!$B$9,(Assumptions!$B$9/Assumptions!$B$146)*Assumptions!$B$157) | C12: =IF(Assumptions!$B$5>(Assumptions!$B$5/Assumptions!$B$188)*Assumptions!$B$200,Assumptions!$B$9,(Assumptions!$B$9/Assumptions!$B$188)*Assumptions!$B$199) | D12: =IF(Assumptions!$B$5>(Assumptions!$B$5/Assumptions!$B$230)*Assumptions!$B$242,Assumptions!$B$9,(Assumptions!$B$9/Assumptions!$B$230)*Assumptions!$B$241)
A13: Pre-money $1.4B | B13: =IF(Assumptions!$B$5>(Assumptions!$B$5/Assumptions!$B$160)*Assumptions!$B$172,Assumptions!$B$9,(Assumptions!$B$9/Assumptions!$B$160)*Assumptions!$B$171) | C13: =IF(Assumptions!$B$5>(Assumptions!$B$5/Assumptions!$B$202)*Assumptions!$B$214,Assumptions!$B$9,(Assumptions!$B$9/Assumptions!$B$202)*Assumptions!$B$213) | D13: =IF(Assumptions!$B$5>(Assumptions!$B$5/Assumptions!$B$244)*Assumptions!$B$256,Assumptions!$B$9,(Assumptions!$B$9/Assumptions!$B$244)*Assumptions!$B$255)
A14: Pre-money $1.8B | B14: =IF(Assumptions!$B$5>(Assumptions!$B$5/Assumptions!$B$174)*Assumptions!$B$186,Assumptions!$B$9,(Assumptions!$B$9/Assumptions!$B$174)*Assumptions!$B$185) | C14: =IF(Assumptions!$B$5>(Assumptions!$B$5/Assumptions!$B$216)*Assumptions!$B$228,Assumptions!$B$9,(Assumptions!$B$9/Assumptions!$B$216)*Assumptions!$B$227) | D14: =IF(Assumptions!$B$5>(Assumptions!$B$5/Assumptions!$B$258)*Assumptions!$B$270,Assumptions!$B$9,(Assumptions!$B$9/Assumptions!$B$258)*Assumptions!$B$269)
A16: F_PPS (USD/share)
A17: Pre-money \ ESOP | B17: ESOP 11% | C17: ESOP 13% | D17: ESOP 15%
A18: Pre-money $1.2B | B18: =Assumptions!$B$146 | C18: =Assumptions!$B$188 | D18: =Assumptions!$B$230
A19: Pre-money $1.4B | B19: =Assumptions!$B$160 | C19: =Assumptions!$B$202 | D19: =Assumptions!$B$244
A20: Pre-money $1.8B | B20: =Assumptions!$B$174 | C20: =Assumptions!$B$216 | D20: =Assumptions!$B$258
A22: Note A conversion branch (cap vs discount)
A23: Pre-money \ ESOP | B23: ESOP 11% | C23: ESOP 13% | D23: ESOP 15%
A24: Pre-money $1.2B | B24: =IF(Assumptions!$B$148<Assumptions!$B$149,"cap","discount") | C24: =IF(Assumptions!$B$190<Assumptions!$B$191,"cap","discount") | D24: =IF(Assumptions!$B$232<Assumptions!$B$233,"cap","discount")
A25: Pre-money $1.4B | B25: =IF(Assumptions!$B$162<Assumptions!$B$163,"cap","discount") | C25: =IF(Assumptions!$B$204<Assumptions!$B$205,"cap","discount") | D25: =IF(Assumptions!$B$246<Assumptions!$B$247,"cap","discount")
A26: Pre-money $1.8B | B26: =IF(Assumptions!$B$176<Assumptions!$B$177,"cap","discount") | C26: =IF(Assumptions!$B$218<Assumptions!$B$219,"cap","discount") | D26: =IF(Assumptions!$B$260<Assumptions!$B$261,"cap","discount")
A28: Note B conversion branch (cap vs discount)
A29: Pre-money \ ESOP | B29: ESOP 11% | C29: ESOP 13% | D29: ESOP 15%
A30: Pre-money $1.2B | B30: =IF(Assumptions!$B$150<Assumptions!$B$151,"cap","discount") | C30: =IF(Assumptions!$B$192<Assumptions!$B$193,"cap","discount") | D30: =IF(Assumptions!$B$234<Assumptions!$B$235,"cap","discount")
A31: Pre-money $1.4B | B31: =IF(Assumptions!$B$164<Assumptions!$B$165,"cap","discount") | C31: =IF(Assumptions!$B$206<Assumptions!$B$207,"cap","discount") | D31: =IF(Assumptions!$B$248<Assumptions!$B$249,"cap","discount")
A32: Pre-money $1.8B | B32: =IF(Assumptions!$B$178<Assumptions!$B$179,"cap","discount") | C32: =IF(Assumptions!$B$220<Assumptions!$B$221,"cap","discount") | D32: =IF(Assumptions!$B$262<Assumptions!$B$263,"cap","discount")
A34: F-class election @ $2B (preference vs convert)
A35: Pre-money \ ESOP | B35: ESOP 11% | C35: ESOP 13% | D35: ESOP 15%
A36: Pre-money $1.2B | B36: =IF(Assumptions!$B$5>(Assumptions!$B$5/Assumptions!$B$146)*Assumptions!$B$158,"preference","convert") | C36: =IF(Assumptions!$B$5>(Assumptions!$B$5/Assumptions!$B$188)*Assumptions!$B$200,"preference","convert") | D36: =IF(Assumptions!$B$5>(Assumptions!$B$5/Assumptions!$B$230)*Assumptions!$B$242,"preference","convert")
A37: Pre-money $1.4B | B37: =IF(Assumptions!$B$5>(Assumptions!$B$5/Assumptions!$B$160)*Assumptions!$B$172,"preference","convert") | C37: =IF(Assumptions!$B$5>(Assumptions!$B$5/Assumptions!$B$202)*Assumptions!$B$214,"preference","convert") | D37: =IF(Assumptions!$B$5>(Assumptions!$B$5/Assumptions!$B$244)*Assumptions!$B$256,"preference","convert")
A38: Pre-money $1.8B | B38: =IF(Assumptions!$B$5>(Assumptions!$B$5/Assumptions!$B$174)*Assumptions!$B$186,"preference","convert") | C38: =IF(Assumptions!$B$5>(Assumptions!$B$5/Assumptions!$B$216)*Assumptions!$B$228,"preference","convert") | D38: =IF(Assumptions!$B$5>(Assumptions!$B$5/Assumptions!$B$258)*Assumptions!$B$270,"preference","convert")

Sheet Return-Solver
A1: RETURN-SOLVER — F-class ownership % needed for 3× / 4× on $10M
A2: Base-case ESOP & full waterfall (incl. F's own election). Targets: 3×=$30M, 4×=$40M.
A4: Exit value | B4: F election | C4: F-class total proceeds | D4: Target 3× ($30M) | E4: Target 4× ($40M) | F4: Ownership % for 3× (of F class) | G4: Ownership % for 4× (of F class) | H4: 3× feasible? | I4: 4× feasible?
A5: =Assumptions!$B$14 | B5: =IF(Assumptions!$B$5>(Assumptions!$B$5/Assumptions!$B$75)*Assumptions!$B$96,"preference","convert") | C5: =IF(B5="preference",Assumptions!$B$5,(Assumptions!$B$5/Assumptions!$B$75)*Assumptions!$B$94) | D5: =Assumptions!$B$71*Assumptions!$B$9 | E5: =Assumptions!$B$72*Assumptions!$B$9 | F5: =D5/C5 | G5: =E5/C5 | H5: =IF(AND(F5>0,F5<=1),"feasible","infeasible") | I5: =IF(AND(G5>0,G5<=1),"feasible","infeasible")
A6: =Assumptions!$B$15 | B6: =IF(Assumptions!$B$5>(Assumptions!$B$5/Assumptions!$B$75)*Assumptions!$B$106,"preference","convert") | C6: =IF(B6="preference",Assumptions!$B$5,(Assumptions!$B$5/Assumptions!$B$75)*Assumptions!$B$104) | D6: =Assumptions!$B$71*Assumptions!$B$9 | E6: =Assumptions!$B$72*Assumptions!$B$9 | F6: =D6/C6 | G6: =E6/C6 | H6: =IF(AND(F6>0,F6<=1),"feasible","infeasible") | I6: =IF(AND(G6>0,G6<=1),"feasible","infeasible")
A7: =Assumptions!$B$16 | B7: =IF(Assumptions!$B$5>(Assumptions!$B$5/Assumptions!$B$75)*Assumptions!$B$116,"preference","convert") | C7: =IF(B7="preference",Assumptions!$B$5,(Assumptions!$B$5/Assumptions!$B$75)*Assumptions!$B$114) | D7: =Assumptions!$B$71*Assumptions!$B$9 | E7: =Assumptions!$B$72*Assumptions!$B$9 | F7: =D7/C7 | G7: =E7/C7 | H7: =IF(AND(F7>0,F7<=1),"feasible","infeasible") | I7: =IF(AND(G7>0,G7<=1),"feasible","infeasible")
A8: =Assumptions!$B$17 | B8: =IF(Assumptions!$B$5>(Assumptions!$B$5/Assumptions!$B$75)*Assumptions!$B$126,"preference","convert") | C8: =IF(B8="preference",Assumptions!$B$5,(Assumptions!$B$5/Assumptions!$B$75)*Assumptions!$B$124) | D8: =Assumptions!$B$71*Assumptions!$B$9 | E8: =Assumptions!$B$72*Assumptions!$B$9 | F8: =D8/C8 | G8: =E8/C8 | H8: =IF(AND(F8>0,F8<=1),"feasible","infeasible") | I8: =IF(AND(G8>0,G8<=1),"feasible","infeasible")
A9: =Assumptions!$B$18 | B9: =IF(Assumptions!$B$5>(Assumptions!$B$5/Assumptions!$B$75)*Assumptions!$B$136,"preference","convert") | C9: =IF(B9="preference",Assumptions!$B$5,(Assumptions!$B$5/Assumptions!$B$75)*Assumptions!$B$134) | D9: =Assumptions!$B$71*Assumptions!$B$9 | E9: =Assumptions!$B$72*Assumptions!$B$9 | F9: =D9/C9 | G9: =E9/C9 | H9: =IF(AND(F9>0,F9<=1),"feasible","infeasible") | I9: =IF(AND(G9>0,G9<=1),"feasible","infeasible")
A12: Notes
A13: • 'F-class total proceeds' = primary if F elects preference, else F_class_shares × pps_eq.
A14: • 'Ownership % of F class' = target / F-class proceeds (the share of F class our $10M would need).
A15: • At base case our $10M = 1/3 of F primary (= 33.33% of F class).
A16: • Ownership > 100% or ≤ 0% flagged as infeasible.
