Workbook

Sheet Assumptions
A1: Knob | B1: Value | C1: Notes
A2: series_f_pre_money | B2: 1400000000 | C2: Series F pre-money USD
A3: series_f_primary_raise | B3: 30000000 | C3: New Series F primary capital USD
A4: series_f_secondary_raise | B4: 15000000 | C4: Secondary tender USD
A5: tender_pps_multiplier | B5: 0.85 | C5: Tender PPS = mult x F_PPS
A6: esop_refresh_target | B6: 0.13 | C6: Post-F ESOP as fraction of post-F FD
A7: our_check | B7: 10000000 | C7: Our fund Series F primary
A8: flead_primary_check | B8: 20000000 | C8: F_LEAD Series F primary
A9: exit_1 | B9: 700000000 | C9: Exit scenario 1
A10: exit_2 | B10: 1200000000 | C10: Exit scenario 2
A11: exit_3 | B11: 2000000000 | C11: Exit scenario 3 (sensitivity)
A12: exit_4 | B12: 4000000000 | C12: Exit scenario 4
A13: exit_5 | B13: 8000000000 | C13: Exit scenario 5
... A29: pre_F_options_unissued | B29: 1894667 | C29: Unissued option pool pre-F
A30: pre_F_options_total | B30: 4394667 | C30: =issued + unissued (pre-existing)
A31: d_orig_pps | B31: 60 | C31: Series D original PPS
A32: d_pre_F_shares | B32: 1720627 | C32: Series D shares pre-F (post-E AD)
A33: d_invested | B33: 100000000 | C33: Series D invested USD
A34: e_pre_F_shares | B34: 6102667 | C34: Series E shares pre-F
A35: e_invested | B35: 300000000 | C35: Series E invested USD
A36: c_shares | B36: 2400000 | C36: Series C shares
A37: c_invested | B37: 60000000 | C37: Series C invested USD
A38: b_shares | B38: 3000000 | C38: Series B shares
A39: b_invested | B39: 30000000 | C39: Series B invested USD
A40: a_shares | B40: 5000000 | C40: Series A shares
A41: a_invested | B41: 15000000 | C41: Series A invested USD
A42: seed_shares | B42: 5000000 | C42: Seed shares
... A58: f3_share_of_founders | B58: 0.1875 | C58: F3 pro-rata 1.5M/8M

Sheet Pro-Forma
A1: Pro-Forma Cap Table — Series F Closing
A3: Fixed-point iteration (15 sweeps) | L3: Final converged values
A4: n | B4: F_PPS | C4: ESOP_topup | D4: NCP_D | E4: NCP_E | F4: AD_D_extra | G4: AD_E_extra | H4: NA_sh | I4: NB_sh | J4: pre_money_FD | L4: F_PPS | M4: =B20 -> 37.299685
A5: iter 0 | B5: =Assumptions!$B$2/Assumptions!$B$27 -> 38.232604 | C5: =MAX(0,Assumptions!$B$6*(Assumptions!$B$2+Assumptions!$B$3)/B5-Assumptions!$B$30) -> 467675.11 | D5: =Assumptions!$B$18*(Assumptions!$B$27+Assumptions!$B$3/Assumptions!$B$18)/(Assumptions!$B$27+Assumptions!$B$3/B5) -> 57.701164 | E5: =Assumptions!$B$19*(Assumptions!$B$27+Assumptions!$B$3/Assumptions!$B$19)/(Assumptions!$B$27+Assumptions!$B$3/B5) -> 48.9291 | F5: =Assumptions!$B$33/D5-Assumptions!$B$32 -> 12440.304 | G5: =Assumptions!$B$35/E5-Assumptions!$B$34 -> 28653.58 | H5: =Assumptions!$B$21/MIN(Assumptions!$B$22/(Assumptions!$B$27+C5+F5+G5+0),B5*(1-Assumptions!$B$23)) -> 185633.65 | I5: =Assumptions!$B$24/MIN(Assumptions!$B$25/(Assumptions!$B$27+C5+F5+G5+H5),B5*(1-Assumptions!$B$26)) -> 92314.187 | J5: =Assumptions!$B$27+C5+F5+G5+H5+I5 -> 37404678 | L5: ESOP top-up | M5: =C20 -> 589289.34
A6: iter 1 | B6: =Assumptions!$B$2/J5 -> 37.428474 | C6: =MAX(0,Assumptions!$B$6*(Assumptions!$B$2+Assumptions!$B$3)/B6-Assumptions!$B$30) -> 572139.86 | D6: =Assumptions!$B$18*(Assumptions!$B$27+Assumptions!$B$3/Assumptions!$B$18)/(Assumptions!$B$27+Assumptions!$B$3/B6) -> 57.675168 | E6: =Assumptions!$B$19*(Assumptions!$B$27+Assumptions!$B$3/Assumptions!$B$19)/(Assumptions!$B$27+Assumptions!$B$3/B6) -> 48.907057 | F6: =Assumptions!$B$33/D6-Assumptions!$B$32 -> 13221.437 | G6: =Assumptions!$B$35/E6-Assumptions!$B$34 -> 31417.106 | H6: =Assumptions!$B$21/MIN(Assumptions!$B$22/(Assumptions!$B$27+C6+F6+G6+I5),B6*(1-Assumptions!$B$23)) -> 186635.27 | I6: =Assumptions!$B$24/MIN(Assumptions!$B$25/(Assumptions!$B$27+C6+F6+G6+H6),B6*(1-Assumptions!$B$26)) -> 94297.507 | J6: =Assumptions!$B$27+C6+F6+G6+H6+I6 -> 37515672 | L6: Pre-money FD | M6: =J20 -> 37533829
A7: iter 2 | B7: =Assumptions!$B$2/J6 -> 37.317737 | C7: =MAX(0,Assumptions!$B$6*(Assumptions!$B$2+Assumptions!$B$3)/B7-Assumptions!$B$30) -> 586878.33 | D7: =Assumptions!$B$18*(Assumptions!$B$27+Assumptions!$B$3/Assumptions!$B$18)/(Assumptions!$B$27+Assumptions!$B$3/B7) -> 57.671502 | E7: =Assumptions!$B$19*(Assumptions!$B$27+Assumptions!$B$3/Assumptions!$B$19)/(Assumptions!$B$27+Assumptions!$B$3/B7) -> 48.903948 | F7: =Assumptions!$B$33/D7-Assumptions!$B$32 -> 13331.643 | G7: =Assumptions!$B$35/E7-Assumptions!$B$34 -> 31806.999 | H7: =Assumptions!$B$21/MIN(Assumptions!$B$22/(Assumptions!$B$27+C7+F7+G7+I6),B7*(1-Assumptions!$B$23)) -> 186721.38 | I7: =Assumptions!$B$24/MIN(Assumptions!$B$25/(Assumptions!$B$27+C7+F7+G7+H7),B7*(1-Assumptions!$B$26)) -> 94577.325 | J7: =Assumptions!$B$27+C7+F7+G7+H7+I7 -> 37531277 | L7: Primary F shares | M7: =Assumptions!$B$3/M4 -> 804296.34
A8: iter 3 | B8: =Assumptions!$B$2/J7 -> 37.302222 | C8: =MAX(0,Assumptions!$B$6*(Assumptions!$B$2+Assumptions!$B$3)/B8-Assumptions!$B$30) -> 588950.38 | D8: =Assumptions!$B$18*(Assumptions!$B$27+Assumptions!$B$3/Assumptions!$B$18)/(Assumptions!$B$27+Assumptions!$B$3/B8) -> 57.670987 | E8: =Assumptions!$B$19*(Assumptions!$B$27+Assumptions!$B$3/Assumptions!$B$19)/(Assumptions!$B$27+Assumptions!$B$3/B8) -> 48.903511 | F8: =Assumptions!$B$33/D8-Assumptions!$B$32 -> 13347.137 | G8: =Assumptions!$B$35/E8-Assumptions!$B$34 -> 31861.813 | H8: =Assumptions!$B$21/MIN(Assumptions!$B$22/(Assumptions!$B$27+C8+F8+G8+I7),B8*(1-Assumptions!$B$23)) -> 186733.49 | I8: =Assumptions!$B$24/MIN(Assumptions!$B$25/(Assumptions!$B$27+C8+F8+G8+H8),B8*(1-Assumptions!$B$26)) -> 94616.664 | J8: =Assumptions!$B$27+C8+F8+G8+H8+I8 -> 37533470 | L8: Tender shares | M8: =Assumptions!$B$4/(Assumptions!$B$5*M4) -> 473115.5
A9: iter 4 | B9: =Assumptions!$B$2/J8 -> 37.300041 | C9: =MAX(0,Assumptions!$B$6*(Assumptions!$B$2+Assumptions!$B$3)/B9-Assumptions!$B$30) -> 589241.69 | D9: =Assumptions!$B$18*(Assumptions!$B$27+Assumptions!$B$3/Assumptions!$B$18)/(Assumptions!$B$27+Assumptions!$B$3/B9) -> 57.670915 | E9: =Assumptions!$B$19*(Assumptions!$B$27+Assumptions!$B$3/Assumptions!$B$19)/(Assumptions!$B$27+Assumptions!$B$3/B9) -> 48.90345 | F9: =Assumptions!$B$33/D9-Assumptions!$B$32 -> 13349.315 | G9: =Assumptions!$B$35/E9-Assumptions!$B$34 -> 31869.52 | H9: =Assumptions!$B$21/MIN(Assumptions!$B$22/(Assumptions!$B$27+C9+F9+G9+I8),B9*(1-Assumptions!$B$23)) -> 186735.19 | I9: =Assumptions!$B$24/MIN(Assumptions!$B$25/(Assumptions!$B$27+C9+F9+G9+H9),B9*(1-Assumptions!$B$26)) -> 94622.194 | J9: =Assumptions!$B$27+C9+F9+G9+H9+I9 -> 37533779 | L9: Post-F FD total | M9: =M6+M7 -> 38338126
A10: iter 5 | B10: =Assumptions!$B$2/J9 -> 37.299735 | C10: =MAX(0,Assumptions!$B$6*(Assumptions!$B$2+Assumptions!$B$3)/B10-Assumptions!$B$30) -> 589282.64 | D10: =Assumptions!$B$18*(Assumptions!$B$27+Assumptions!$B$3/Assumptions!$B$18)/(Assumptions!$B$27+Assumptions!$B$3/B10) -> 57.670904 | E10: =Assumptions!$B$19*(Assumptions!$B$27+Assumptions!$B$3/Assumptions!$B$19)/(Assumptions!$B$27+Assumptions!$B$3/B10) -> 48.903441 | F10: =Assumptions!$B$33/D10-Assumptions!$B$32 -> 13349.622 | G10: =Assumptions!$B$35/E10-Assumptions!$B$34 -> 31870.603 | H10: =Assumptions!$B$21/MIN(Assumptions!$B$22/(Assumptions!$B$27+C10+F10+G10+I9),B10*(1-Assumptions!$B$23)) -> 186735.43 | I10: =Assumptions!$B$24/MIN(Assumptions!$B$25/(Assumptions!$B$27+C10+F10+G10+H10),B10*(1-Assumptions!$B$26)) -> 94622.972 | J10: =Assumptions!$B$27+C10+F10+G10+H10+I10 -> 37533822 | L10: Our F primary shares | M10: =Assumptions!$B$7/M4 -> 268098.78
A11: iter 6 | B11: =Assumptions!$B$2/J10 -> 37.299692 | C11: =MAX(0,Assumptions!$B$6*(Assumptions!$B$2+Assumptions!$B$3)/B11-Assumptions!$B$30) -> 589288.4 | D11: =Assumptions!$B$18*(Assumptions!$B$27+Assumptions!$B$3/Assumptions!$B$18)/(Assumptions!$B$27+Assumptions!$B$3/B11) -> 57.670903 | E11: =Assumptions!$B$19*(Assumptions!$B$27+Assumptions!$B$3/Assumptions!$B$19)/(Assumptions!$B$27+Assumptions!$B$3/B11) -> 48.90344 | F11: =Assumptions!$B$33/D11-Assumptions!$B$32 -> 13349.665 | G11: =Assumptions!$B$35/E11-Assumptions!$B$34 -> 31870.755 | H11: =Assumptions!$B$21/MIN(Assumptions!$B$22/(Assumptions!$B$27+C11+F11+G11+I10),B11*(1-Assumptions!$B$23)) -> 186735.46 | I11: =Assumptions!$B$24/MIN(Assumptions!$B$25/(Assumptions!$B$27+C11+F11+G11+H11),B11*(1-Assumptions!$B$26)) -> 94623.081 | J11: =Assumptions!$B$27+C11+F11+G11+H11+I11 -> 37533828 | L11: F_LEAD primary shares | M11: =Assumptions!$B$8/M4 -> 536197.56
A12: iter 7 | B12: =Assumptions!$B$2/J11 -> 37.299686 | C12: =MAX(0,Assumptions!$B$6*(Assumptions!$B$2+Assumptions!$B$3)/B12-Assumptions!$B$30) -> 589289.21 | D12: =Assumptions!$B$18*(Assumptions!$B$27+Assumptions!$B$3/Assumptions!$B$18)/(Assumptions!$B$27+Assumptions!$B$3/B12) -> 57.670903 | E12: =Assumptions!$B$19*(Assumptions!$B$27+Assumptions!$B$3/Assumptions!$B$19)/(Assumptions!$B$27+Assumptions!$B$3/B12) -> 48.90344 | F12: =Assumptions!$B$33/D12-Assumptions!$B$32 -> 13349.671 | G12: =Assumptions!$B$35/E12-Assumptions!$B$34 -> 31870.777 | H12: =Assumptions!$B$21/MIN(Assumptions!$B$22/(Assumptions!$B$27+C12+F12+G12+I11),B12*(1-Assumptions!$B$23)) -> 186735.47 | I12: =Assumptions!$B$24/MIN(Assumptions!$B$25/(Assumptions!$B$27+C12+F12+G12+H12),B12*(1-Assumptions!$B$26)) -> 94623.097 | J12: =Assumptions!$B$27+C12+F12+G12+H12+I12 -> 37533829 | L12: F_LEAD secondary common | M12: =M8 -> 473115.5
A13: iter 8 | B13: =Assumptions!$B$2/J12 -> 37.299685 | C13: =MAX(0,Assumptions!$B$6*(Assumptions!$B$2+Assumptions!$B$3)/B13-Assumptions!$B$30) -> 589289.32 | D13: =Assumptions!$B$18*(Assumptions!$B$27+Assumptions!$B$3/Assumptions!$B$18)/(Assumptions!$B$27+Assumptions!$B$3/B13) -> 57.670903 | E13: =Assumptions!$B$19*(Assumptions!$B$27+Assumptions!$B$3/Assumptions!$B$19)/(Assumptions!$B$27+Assumptions!$B$3/B13) -> 48.90344 | F13: =Assumptions!$B$33/D13-Assumptions!$B$32 -> 13349.672 | G13: =Assumptions!$B$35/E13-Assumptions!$B$34 -> 31870.78 | H13: =Assumptions!$B$21/MIN(Assumptions!$B$22/(Assumptions!$B$27+C13+F13+G13+I12),B13*(1-Assumptions!$B$23)) -> 186735.47 | I13: =Assumptions!$B$24/MIN(Assumptions!$B$25/(Assumptions!$B$27+C13+F13+G13+H13),B13*(1-Assumptions!$B$26)) -> 94623.099 | J13: =Assumptions!$B$27+C13+F13+G13+H13+I13 -> 37533829
A14: iter 9 | B14: =Assumptions!$B$2/J13 -> 37.299685 | C14: =MAX(0,Assumptions!$B$6*(Assumptions!$B$2+Assumptions!$B$3)/B14-Assumptions!$B$30) -> 589289.34 | D14: =Assumptions!$B$18*(Assumptions!$B$27+Assumptions!$B$3/Assumptions!$B$18)/(Assumptions!$B$27+Assumptions!$B$3/B14) -> 57.670903 | E14: =Assumptions!$B$19*(Assumptions!$B$27+Assumptions!$B$3/Assumptions!$B$19)/(Assumptions!$B$27+Assumptions!$B$3/B14) -> 48.90344 | F14: =Assumptions!$B$33/D14-Assumptions!$B$32 -> 13349.672 | G14: =Assumptions!$B$35/E14-Assumptions!$B$34 -> 31870.78 | H14: =Assumptions!$B$21/MIN(Assumptions!$B$22/(Assumptions!$B$27+C14+F14+G14+I13),B14*(1-Assumptions!$B$23)) -> 186735.47 | I14: =Assumptions!$B$24/MIN(Assumptions!$B$25/(Assumptions!$B$27+C14+F14+G14+H14),B14*(1-Assumptions!$B$26)) -> 94623.099 | J14: =Assumptions!$B$27+C14+F14+G14+H14+I14 -> 37533829
A15: iter 10 | B15: =Assumptions!$B$2/J14 -> 37.299685 | C15: =MAX(0,Assumptions!$B$6*(Assumptions!$B$2+Assumptions!$B$3)/B15-Assumptions!$B$30) -> 589289.34 | D15: =Assumptions!$B$18*(Assumptions!$B$27+Assumptions!$B$3/Assumptions!$B$18)/(Assumptions!$B$27+Assumptions!$B$3/B15) -> 57.670903 | E15: =Assumptions!$B$19*(Assumptions!$B$27+Assumptions!$B$3/Assumptions!$B$19)/(Assumptions!$B$27+Assumptions!$B$3/B15) -> 48.90344 | F15: =Assumptions!$B$33/D15-Assumptions!$B$32 -> 13349.672 | G15: =Assumptions!$B$35/E15-Assumptions!$B$34 -> 31870.78 | H15: =Assumptions!$B$21/MIN(Assumptions!$B$22/(Assumptions!$B$27+C15+F15+G15+I14),B15*(1-Assumptions!$B$23)) -> 186735.47 | I15: =Assumptions!$B$24/MIN(Assumptions!$B$25/(Assumptions!$B$27+C15+F15+G15+H15),B15*(1-Assumptions!$B$26)) -> 94623.099 | J15: =Assumptions!$B$27+C15+F15+G15+H15+I15 -> 37533829
A16: iter 11 | B16: =Assumptions!$B$2/J15 -> 37.299685 | C16: =MAX(0,Assumptions!$B$6*(Assumptions!$B$2+Assumptions!$B$3)/B16-Assumptions!$B$30) -> 589289.34 | D16: =Assumptions!$B$18*(Assumptions!$B$27+Assumptions!$B$3/Assumptions!$B$18)/(Assumptions!$B$27+Assumptions!$B$3/B16) -> 57.670903 | E16: =Assumptions!$B$19*(Assumptions!$B$27+Assumptions!$B$3/Assumptions!$B$19)/(Assumptions!$B$27+Assumptions!$B$3/B16) -> 48.90344 | F16: =Assumptions!$B$33/D16-Assumptions!$B$32 -> 13349.672 | G16: =Assumptions!$B$35/E16-Assumptions!$B$34 -> 31870.78 | H16: =Assumptions!$B$21/MIN(Assumptions!$B$22/(Assumptions!$B$27+C16+F16+G16+I15),B16*(1-Assumptions!$B$23)) -> 186735.47 | I16: =Assumptions!$B$24/MIN(Assumptions!$B$25/(Assumptions!$B$27+C16+F16+G16+H16),B16*(1-Assumptions!$B$26)) -> 94623.099 | J16: =Assumptions!$B$27+C16+F16+G16+H16+I16 -> 37533829
A17: iter 12 | B17: =Assumptions!$B$2/J16 -> 37.299685 | C17: =MAX(0,Assumptions!$B$6*(Assumptions!$B$2+Assumptions!$B$3)/B17-Assumptions!$B$30) -> 589289.34 | D17: =Assumptions!$B$18*(Assumptions!$B$27+Assumptions!$B$3/Assumptions!$B$18)/(Assumptions!$B$27+Assumptions!$B$3/B17) -> 57.670903 | E17: =Assumptions!$B$19*(Assumptions!$B$27+Assumptions!$B$3/Assumptions!$B$19)/(Assumptions!$B$27+Assumptions!$B$3/B17) -> 48.90344 | F17: =Assumptions!$B$33/D17-Assumptions!$B$32 -> 13349.672 | G17: =Assumptions!$B$35/E17-Assumptions!$B$34 -> 31870.78 | H17: =Assumptions!$B$21/MIN(Assumptions!$B$22/(Assumptions!$B$27+C17+F17+G17+I16),B17*(1-Assumptions!$B$23)) -> 186735.47 | I17: =Assumptions!$B$24/MIN(Assumptions!$B$25/(Assumptions!$B$27+C17+F17+G17+H17),B17*(1-Assumptions!$B$26)) -> 94623.099 | J17: =Assumptions!$B$27+C17+F17+G17+H17+I17 -> 37533829
A18: iter 13 | B18: =Assumptions!$B$2/J17 -> 37.299685 | C18: =MAX(0,Assumptions!$B$6*(Assumptions!$B$2+Assumptions!$B$3)/B18-Assumptions!$B$30) -> 589289.34 | D18: =Assumptions!$B$18*(Assumptions!$B$27+Assumptions!$B$3/Assumptions!$B$18)/(Assumptions!$B$27+Assumptions!$B$3/B18) -> 57.670903 | E18: =Assumptions!$B$19*(Assumptions!$B$27+Assumptions!$B$3/Assumptions!$B$19)/(Assumptions!$B$27+Assumptions!$B$3/B18) -> 48.90344 | F18: =Assumptions!$B$33/D18-Assumptions!$B$32 -> 13349.672 | G18: =Assumptions!$B$35/E18-Assumptions!$B$34 -> 31870.78 | H18: =Assumptions!$B$21/MIN(Assumptions!$B$22/(Assumptions!$B$27+C18+F18+G18+I17),B18*(1-Assumptions!$B$23)) -> 186735.47 | I18: =Assumptions!$B$24/MIN(Assumptions!$B$25/(Assumptions!$B$27+C18+F18+G18+H18),B18*(1-Assumptions!$B$26)) -> 94623.099 | J18: =Assumptions!$B$27+C18+F18+G18+H18+I18 -> 37533829
A19: iter 14 | B19: =Assumptions!$B$2/J18 -> 37.299685 | C19: =MAX(0,Assumptions!$B$6*(Assumptions!$B$2+Assumptions!$B$3)/B19-Assumptions!$B$30) -> 589289.34 | D19: =Assumptions!$B$18*(Assumptions!$B$27+Assumptions!$B$3/Assumptions!$B$18)/(Assumptions!$B$27+Assumptions!$B$3/B19) -> 57.670903 | E19: =Assumptions!$B$19*(Assumptions!$B$27+Assumptions!$B$3/Assumptions!$B$19)/(Assumptions!$B$27+Assumptions!$B$3/B19) -> 48.90344 | F19: =Assumptions!$B$33/D19-Assumptions!$B$32 -> 13349.672 | G19: =Assumptions!$B$35/E19-Assumptions!$B$34 -> 31870.78 | H19: =Assumptions!$B$21/MIN(Assumptions!$B$22/(Assumptions!$B$27+C19+F19+G19+I18),B19*(1-Assumptions!$B$23)) -> 186735.47 | I19: =Assumptions!$B$24/MIN(Assumptions!$B$25/(Assumptions!$B$27+C19+F19+G19+H19),B19*(1-Assumptions!$B$26)) -> 94623.099 | J19: =Assumptions!$B$27+C19+F19+G19+H19+I19 -> 37533829
A20: iter 15 | B20: =Assumptions!$B$2/J19 -> 37.299685 | C20: =MAX(0,Assumptions!$B$6*(Assumptions!$B$2+Assumptions!$B$3)/B20-Assumptions!$B$30) -> 589289.34 | D20: =Assumptions!$B$18*(Assumptions!$B$27+Assumptions!$B$3/Assumptions!$B$18)/(Assumptions!$B$27+Assumptions!$B$3/B20) -> 57.670903 | E20: =Assumptions!$B$19*(Assumptions!$B$27+Assumptions!$B$3/Assumptions!$B$19)/(Assumptions!$B$27+Assumptions!$B$3/B20) -> 48.90344 | F20: =Assumptions!$B$33/D20-Assumptions!$B$32 -> 13349.672 | G20: =Assumptions!$B$35/E20-Assumptions!$B$34 -> 31870.78 | H20: =Assumptions!$B$21/MIN(Assumptions!$B$22/(Assumptions!$B$27+C20+F20+G20+I19),B20*(1-Assumptions!$B$23)) -> 186735.47 | I20: =Assumptions!$B$24/MIN(Assumptions!$B$25/(Assumptions!$B$27+C20+F20+G20+H20),B20*(1-Assumptions!$B$26)) -> 94623.099 | J20: =Assumptions!$B$27+C20+F20+G20+H20+I20 -> 37533829
A23: Anti-Dilution Block (Broad-Based WA)
A24: Class | B24: OCP | C24: F_PPS | D24: Trigger (F<OCP) | E24: NCP | F24: new_ratio | G24: as-converted shares
A25: Seed | B25: =Assumptions!$B$14 -> 1 | C25: =M4 -> 37.299685 | D25: =IF(C25<B25,TRUE,FALSE) -> FALSE | E25: =IF(D25, B25*(Assumptions!$B$27+Assumptions!$B$3/B25)/(Assumptions!$B$27+Assumptions!$B$3/C25), B25) -> 1 | F25: =B25/E25 -> 1 | G25: =5000000*F25 -> 5000000
A26: Series A | B26: =Assumptions!$B$15 -> 3 | C26: =M4 -> 37.299685 | D26: =IF(C26<B26,TRUE,FALSE) -> FALSE | E26: =IF(D26, B26*(Assumptions!$B$27+Assumptions!$B$3/B26)/(Assumptions!$B$27+Assumptions!$B$3/C26), B26) -> 3 | F26: =B26/E26 -> 1 | G26: =5000000*F26 -> 5000000
A27: Series B | B27: =Assumptions!$B$16 -> 10 | C27: =M4 -> 37.299685 | D27: =IF(C27<B27,TRUE,FALSE) -> FALSE | E27: =IF(D27, B27*(Assumptions!$B$27+Assumptions!$B$3/B27)/(Assumptions!$B$27+Assumptions!$B$3/C27), B27) -> 10 | F27: =B27/E27 -> 1 | G27: =3000000*F27 -> 3000000
A28: Series C | B28: =Assumptions!$B$17 -> 25 | C28: =M4 -> 37.299685 | D28: =IF(C28<B28,TRUE,FALSE) -> FALSE | E28: =IF(D28, B28*(Assumptions!$B$27+Assumptions!$B$3/B28)/(Assumptions!$B$27+Assumptions!$B$3/C28), B28) -> 25 | F28: =B28/E28 -> 1 | G28: =2400000*F28 -> 2400000
A29: Series D (compound v3*v4) | B29: =Assumptions!$B$18 -> 58.118347 | C29: =M4 -> 37.299685 | D29: =IF(C29<B29,TRUE,FALSE) -> TRUE | E29: =IF(D29, B29*(Assumptions!$B$27+Assumptions!$B$3/B29)/(Assumptions!$B$27+Assumptions!$B$3/C29), B29) -> 57.670903 | F29: =Assumptions!$B$31/E29 -> 1.040386 | G29: =Assumptions!$B$33/E29 -> 1733976.7
A30: Series E | B30: =Assumptions!$B$19 -> 49.158311 | C30: =M4 -> 37.299685 | D30: =IF(C30<B30,TRUE,FALSE) -> TRUE | E30: =IF(D30, B30*(Assumptions!$B$27+Assumptions!$B$3/B30)/(Assumptions!$B$27+Assumptions!$B$3/C30), B30) -> 48.90344 | F30: =B30/E30 -> 1.0052117 | G30: =Assumptions!$B$35/E30 -> 6134537.8
A33: Convertible Notes Block
A34: Note | B34: Cap-implied PPS | C34: Disc-implied PPS | D34: Conv PPS | E34: Branch | F34: Shares
A35: Note A | B35: =Assumptions!$B$22/(Assumptions!$B$27+M5+F20+G20+I20) -> 26.775845 | C35: =M4*(1-Assumptions!$B$23) -> 29.839748 | D35: =MIN(B35,C35) -> 26.775845 | E35: =IF(B35<C35,"cap","discount") -> cap | F35: =Assumptions!$B$21/D35 -> 186735.47
A36: Note B | B36: =Assumptions!$B$25/(Assumptions!$B$27+M5+F20+G20+H20) -> 42.735949 | C36: =M4*(1-Assumptions!$B$26) -> 31.704732 | D36: =MIN(B36,C36) -> 31.704732 | E36: =IF(B36<C36,"cap","discount") -> discount | F36: =Assumptions!$B$24/D36 -> 94623.099
A39: Secondary Tender Block
A40: Tender shares (= 15M / (0.85*F_PPS)) | B40: =M8 -> 473115.5
A41: F_LEAD secondary common | B41: =B40 -> 473115.5
A42: F1 reduction (50%) | B42: =Assumptions!$B$56*B40 -> 236557.75
A43: F2 reduction (31.25%) | B43: =Assumptions!$B$57*B40 -> 147848.59
A44: F3 reduction (18.75%) | B44: =Assumptions!$B$58*B40 -> 88709.156
A45: F1 post-F common | B45: =Assumptions!$B$44-B42 -> 3763442.3
A46: F2 post-F common | B46: =Assumptions!$B$45-B43 -> 2352151.4
A47: F3 post-F common | B47: =Assumptions!$B$46-B44 -> 1411290.8
...

Sheet Waterfall
A1: Exit Waterfall — 1x Non-Participating with Conversion Election
A3: Item | B3: =Assumptions!$B$9 -> 700000000 | C3: =Assumptions!$B$10 -> 1200000000 | D3: =Assumptions!$B$11 -> 2000000000 | E3: =Assumptions!$B$12 -> 4000000000 | F3: =Assumptions!$B$13 -> 8000000000
A4: Class | G4: Shares | H4: LP
A5: F | G5: ='Pro-Forma'!M7 -> 804296.34 | H5: =Assumptions!$B$3 -> 30000000
A6: E | G6: ='Pro-Forma'!G30 -> 6134537.8 | H6: =Assumptions!$B$35 -> 300000000
A7: D | G7: ='Pro-Forma'!G29 -> 1733976.7 | H7: =Assumptions!$B$33 -> 100000000
A8: C | G8: =Assumptions!$B$36 -> 2400000 | H8: =Assumptions!$B$37 -> 60000000
A9: B | G9: =Assumptions!$B$38 -> 3000000 | H9: =Assumptions!$B$39 -> 30000000
A10: A | G10: =Assumptions!$B$40 -> 5000000 | H10: =Assumptions!$B$41 -> 15000000
A11: Seed | G11: =Assumptions!$B$42 -> 5000000 | H11: =Assumptions!$B$43 -> 5000000
A13: Common+RSAs base | G13: =Assumptions!$B$44+Assumptions!$B$45+Assumptions!$B$46+Assumptions!$B$47 -> 9000000
A14: Notes shares (combined) | G14: ='Pro-Forma'!F35+'Pro-Forma'!F36 -> 281358.57
A15: Issued options | G15: =Assumptions!$B$28 -> 2500000
A16: Strike | G16: =Assumptions!$B$20 -> 1
A18: Election by Class (convert | preference)
A19: F | B19: =IF(G5*B39>H5,"convert","preference") -> preference | C19: =IF(G5*C39>H5,"convert","preference") -> preference | D19: =IF(G5*D39>H5,"convert","preference") -> convert | E19: =IF(G5*E39>H5,"convert","preference") -> convert | F19: =IF(G5*F39>H5,"convert","preference") -> convert
A20: E | B20: =IF(G6*B39>H6,"convert","preference") -> preference | C20: =IF(G6*C39>H6,"convert","preference") -> preference | D20: =IF(G6*D39>H6,"convert","preference") -> convert | E20: =IF(G6*E39>H6,"convert","preference") -> convert | F20: =IF(G6*F39>H6,"convert","preference") -> convert
A21: D | B21: =IF(G7*B39>H7,"convert","preference") -> preference | C21: =IF(G7*C39>H7,"convert","preference") -> preference | D21: =IF(G7*D39>H7,"convert","preference") -> preference | E21: =IF(G7*E39>H7,"convert","preference") -> convert | F21: =IF(G7*F39>H7,"convert","preference") -> convert
A22: C | B22: =IF(G8*B39>H8,"convert","preference") -> preference | C22: =IF(G8*C39>H8,"convert","preference") -> convert | D22: =IF(G8*D39>H8,"convert","preference") -> convert | E22: =IF(G8*E39>H8,"convert","preference") -> convert | F22: =IF(G8*F39>H8,"convert","preference") -> convert
A23: B | B23: =IF(G9*B39>H9,"convert","preference") -> preference | C23: =IF(G9*C39>H9,"convert","preference") -> convert | D23: =IF(G9*D39>H9,"convert","preference") -> convert | E23: =IF(G9*E39>H9,"convert","preference") -> convert | F23: =IF(G9*F39>H9,"convert","preference") -> convert
A24: A | B24: =IF(G10*B39>H10,"convert","preference") -> convert | C24: =IF(G10*C39>H10,"convert","preference") -> convert | D24: =IF(G10*D39>H10,"convert","preference") -> convert | E24: =IF(G10*E39>H10,"convert","preference") -> convert | F24: =IF(G10*F39>H10,"convert","preference") -> convert
A25: Seed | B25: =IF(G11*B39>H11,"convert","preference") -> convert | C25: =IF(G11*C39>H11,"convert","preference") -> convert | D25: =IF(G11*D39>H11,"convert","preference") -> convert | E25: =IF(G11*E39>H11,"convert","preference") -> convert | F25: =IF(G11*F39>H11,"convert","preference") -> convert
A27: Class Proceeds ($)
A28: F | B28: =IF(B19="convert",G5*B39,H5) -> 30000000 | C28: =IF(C19="convert",G5*C39,H5) -> 30000000 | D28: =IF(D19="convert",G5*D39,H5) -> 44846575 | E28: =IF(E19="convert",G5*E39,H5) -> 89785823 | F28: =IF(F19="convert",G5*F39,H5) -> 1.7951557e+08
A29: E | B29: =IF(B20="convert",G6*B39,H6) -> 300000000 | C29: =IF(C20="convert",G6*C39,H6) -> 300000000 | D29: =IF(D20="convert",G6*D39,H6) -> 3.4205429e+08 | E29: =IF(E20="convert",G6*E39,H6) -> 6.848154e+08 | F29: =IF(F20="convert",G6*F39,H6) -> 1.3692031e+09
A30: D | B30: =IF(B21="convert",G7*B39,H7) -> 100000000 | C30: =IF(C21="convert",G7*C39,H7) -> 100000000 | D30: =IF(D21="convert",G7*D39,H7) -> 100000000 | E30: =IF(E21="convert",G7*E39,H7) -> 1.9356861e+08 | F30: =IF(F21="convert",G7*F39,H7) -> 3.8701631e+08
A31: C | B31: =IF(B22="convert",G8*B39,H8) -> 60000000 | C31: =IF(C22="convert",G8*C39,H8) -> 68208511 | D31: =IF(D22="convert",G8*D39,H8) -> 1.3382105e+08 | E31: =IF(E22="convert",G8*E39,H8) -> 2.6791863e+08 | F31: =IF(F22="convert",G8*F39,H8) -> 5.3566992e+08
A32: B | B32: =IF(B23="convert",G9*B39,H9) -> 30000000 | C32: =IF(C23="convert",G9*C39,H9) -> 85260639 | D32: =IF(D23="convert",G9*D39,H9) -> 1.6727631e+08 | E32: =IF(E23="convert",G9*E39,H9) -> 3.3489829e+08 | F32: =IF(F23="convert",G9*F39,H9) -> 6.695874e+08
A33: A | B33: =IF(B24="convert",G10*B39,H10) -> 41893622 | C33: =IF(C24="convert",G10*C39,H10) -> 1.4210106e+08 | D33: =IF(D24="convert",G10*D39,H10) -> 2.7879385e+08 | E33: =IF(E24="convert",G10*E39,H10) -> 5.5816382e+08 | F33: =IF(F24="convert",G10*F39,H10) -> 1.115979e+09
A34: Seed | B34: =IF(B25="convert",G11*B39,H11) -> 41893622 | C34: =IF(C25="convert",G11*C39,H11) -> 1.4210106e+08 | D34: =IF(D25="convert",G11*D39,H11) -> 2.7879385e+08 | E34: =IF(E25="convert",G11*E39,H11) -> 5.5816382e+08 | F34: =IF(F25="convert",G11*F39,H11) -> 1.115979e+09
A35: Notes combined (NA+NB) | B35: =G14*B39 -> 2357425.9 | C35: =G14*C39 -> 7996270.5 | D35: =G14*D39 -> 15688208 | E35: =G14*E39 -> 31408834 | F35: =G14*F39 -> 62798051
A36: Total LP paid | B36: =IF(B19="preference",H5,0)+IF(B20="preference",H6,0)+IF(B21="preference",H7,0)+IF(B22="preference",H8,0)+IF(B23="preference",H9,0)+IF(B24="preference",H10,0)+IF(B25="preference",H11,0) -> 520000000 | C36: =IF(C19="preference",H5,0)+IF(C20="preference",H6,0)+IF(C21="preference",H7,0)+IF(C22="preference",H8,0)+IF(C23="preference",H9,0)+IF(C24="preference",H10,0)+IF(C25="preference",H11,0) -> 430000000 | D36: =IF(D19="preference",H5,0)+IF(D20="preference",H6,0)+IF(D21="preference",H7,0)+IF(D22="preference",H8,0)+IF(D23="preference",H9,0)+IF(D24="preference",H10,0)+IF(D25="preference",H11,0) -> 100000000 | E36: =IF(E19="preference",H5,0)+IF(E20="preference",H6,0)+IF(E21="preference",H7,0)+IF(E22="preference",H8,0)+IF(E23="preference",H9,0)+IF(E24="preference",H10,0)+IF(E25="preference",H11,0) -> 0 | F36: =IF(F19="preference",H5,0)+IF(F20="preference",H6,0)+IF(F21="preference",H7,0)+IF(F22="preference",H8,0)+IF(F23="preference",H9,0)+IF(F24="preference",H10,0)+IF(F25="preference",H11,0) -> 0
A37: Convert pool | B37: =G13+G14+G15+IF(B19="convert",G5,0)+IF(B20="convert",G6,0)+IF(B21="convert",G7,0)+IF(B22="convert",G8,0)+IF(B23="convert",G9,0)+IF(B24="convert",G10,0)+IF(B25="convert",G11,0) -> 21781359 | C37: =G13+G14+G15+IF(C19="convert",G5,0)+IF(C20="convert",G6,0)+IF(C21="convert",G7,0)+IF(C22="convert",G8,0)+IF(C23="convert",G9,0)+IF(C24="convert",G10,0)+IF(C25="convert",G11,0) -> 27181359 | D37: =G13+G14+G15+IF(D19="convert",G5,0)+IF(D20="convert",G6,0)+IF(D21="convert",G7,0)+IF(D22="convert",G8,0)+IF(D23="convert",G9,0)+IF(D24="convert",G10,0)+IF(D25="convert",G11,0) -> 34120193 | E37: =G13+G14+G15+IF(E19="convert",G5,0)+IF(E20="convert",G6,0)+IF(E21="convert",G7,0)+IF(E22="convert",G8,0)+IF(E23="convert",G9,0)+IF(E24="convert",G10,0)+IF(E25="convert",G11,0) -> 35854169 | F37: =G13+G14+G15+IF(F19="convert",G5,0)+IF(F20="convert",G6,0)+IF(F21="convert",G7,0)+IF(F22="convert",G8,0)+IF(F23="convert",G9,0)+IF(F24="convert",G10,0)+IF(F25="convert",G11,0) -> 35854169
A38: Residual | B38: =B3-B36+G15*G16 -> 182500000 | C38: =C3-C36+G15*G16 -> 772500000 | D38: =D3-D36+G15*G16 -> 1902500000 | E38: =E3-E36+G15*G16 -> 4002500000 | F38: =F3-F36+G15*G16 -> 8002500000
A39: PPS at exit | B39: =B38/B37 -> 8.3787244 | C39: =C38/C37 -> 28.420213 | D39: =D38/D37 -> 55.758771 | E39: =E38/E37 -> 111.63276 | F39: =F38/F37 -> 223.1958
A41: Common + RSAs | B41: =G13*B39 -> 75408519 | C41: =G13*C39 -> 2.5578192e+08 | D41: =G13*D39 -> 5.0182894e+08 | E41: =G13*E39 -> 1.0046949e+09 | F41: =G13*F39 -> 2.0087622e+09
A42: Issued options (net of strike) | B42: =G15*(B39-G16) -> 18446811 | C42: =G15*(C39-G16) -> 68550532 | D42: =G15*(D39-G16) -> 1.3689693e+08 | E42: =G15*(E39-G16) -> 2.7658191e+08 | F42: =G15*(F39-G16) -> 5.554895e+08
A44: TOTAL ($) | B44: =SUM(B28:B34)+B35+B41+B42 -> 700000000 | C44: =SUM(C28:C34)+C35+C41+C42 -> 1200000000 | D44: =SUM(D28:D34)+D35+D41+D42 -> 2000000000 | E44: =SUM(E28:E34)+E35+E41+E42 -> 4000000000 | F44: =SUM(F28:F34)+F35+F41+F42 -> 8000000000
A45: Reconciliation diff | B45: =B44-B3 -> 0 | C45: =C44-C3 -> 0 | D45: =D44-D3 -> 0 | E45: =E44-E3 -> 0 | F45: =F44-F3 -> 0

Sheet Sensitivity
A1: Sensitivity: ESOP × Pre-Money @ $2B exit
A3: ESOP \ Pre-money | B3: =Assumptions!$B$51 -> 1200000000 | C3: =Assumptions!$B$52 -> 1400000000 | D3: =Assumptions!$B$53 -> 1800000000
A4: 11% ESOP — ownership % | B4: =B34 -> 0.0081300813 | C4: =B69 -> 0.006993007 | D4: =B104 -> 0.0054644809
A5: 13% ESOP — ownership % | B5: =B139 -> 0.0081300813 | C5: =B174 -> 0.006993007 | D5: =B209 -> 0.0054644809
A6: 15% ESOP — ownership % | B6: =B244 -> 0.0081300813 | C6: =B279 -> 0.006993007 | D6: =B314 -> 0.0054644809
A8: Proceeds at $2B exit
A9: Pre-money → | B9: =Assumptions!$B$51 -> 1200000000 | C9: =Assumptions!$B$52 -> 1400000000 | D9: =Assumptions!$B$53 -> 1800000000
A10: 11% ESOP — $ proceeds | B10: =B46 -> 17107255 | C10: =B81 -> 14719654 | D10: =B116 -> 11507138
A11: 13% ESOP — $ proceeds | B11: =B151 -> 17384972 | C11: =B186 -> 14948858 | D11: =B221 -> 11676569
A12: 15% ESOP — $ proceeds | B12: =B256 -> 17795003 | C12: =B291 -> 15301321 | D12: =B326 -> 11951762
A20: === Scenario [11% ESOP, $1.2B pre] ===
A21: pre | B21: =Assumptions!$B$51 -> 1200000000
A22: esop_t | B22: =Assumptions!$B$48 -> 0.11
A23: F_PPS | B23: =B21/B31 -> 32.441237
A24: ESOP_topup | B24: =MAX(0,B22*(B21+Assumptions!$B$3)/B23-Assumptions!$B$30) -> 0
A25: NCP_D | B25: =Assumptions!$B$18*(Assumptions!$B$27+Assumptions!$B$3/Assumptions!$B$18)/(Assumptions!$B$27+Assumptions!$B$3/B23) -> 57.485871
A26: NCP_E | B26: =Assumptions!$B$19*(Assumptions!$B$27+Assumptions!$B$3/Assumptions!$B$19)/(Assumptions!$B$27+Assumptions!$B$3/B23) -> 48.746537
A27: AD_D | B27: =Assumptions!$B$33/B25-Assumptions!$B$32 -> 18930.896
A28: AD_E | B28: =Assumptions!$B$35/B26-Assumptions!$B$34 -> 51616.278
A29: NA_sh | B29: =Assumptions!$B$21/MIN(Assumptions!$B$22/(Assumptions!$B$27+B24+B27+B28+B30),B23*(1-Assumptions!$B$23)) -> 192656.03
A30: NB_sh | B30: =Assumptions!$B$24/MIN(Assumptions!$B$25/(Assumptions!$B$27+B24+B27+B28+B29),B23*(1-Assumptions!$B$26)) -> 108793.99
A31: pre_FD | B31: =Assumptions!$B$27+B24+B27+B28+B29+B30 -> 36989958
A32: T_F | B32: =(B21+Assumptions!$B$3)/B23 -> 37914707
A33: our_shares | B33: =Assumptions!$B$7/B23 -> 308249.65
A34: ownership % | B34: =B33/B32 -> 0.0081300813
A35: F_sh | B35: =Assumptions!$B$3/B23 -> 924748.96 | C35: =Assumptions!$B$3 -> 30000000 | D35: =IF(B35*B44>C35,"convert","preference") -> convert
A36: E_sh | B36: =Assumptions!$B$35/B26 -> 6154283.3 | C36: =Assumptions!$B$35 -> 300000000 | D36: =IF(B36*B44>C36,"convert","preference") -> convert
A37: D_sh | B37: =Assumptions!$B$33/B25 -> 1739557.9 | C37: =Assumptions!$B$33 -> 100000000 | D37: =IF(B37*B44>C37,"convert","preference") -> preference
A38: C_sh | B38: =Assumptions!$B$36 -> 2400000 | C38: =Assumptions!$B$37 -> 60000000 | D38: =IF(B38*B44>C38,"convert","preference") -> convert
A39: B_sh | B39: =Assumptions!$B$38 -> 3000000 | C39: =Assumptions!$B$39 -> 30000000 | D39: =IF(B39*B44>C39,"convert","preference") -> convert
A40: A_sh | B40: =Assumptions!$B$40 -> 5000000 | C40: =Assumptions!$B$41 -> 15000000 | D40: =IF(B40*B44>C40,"convert","preference") -> convert
A41: Seed_sh | B41: =Assumptions!$B$42 -> 5000000 | C41: =Assumptions!$B$43 -> 5000000 | D41: =IF(B41*B44>C41,"convert","preference") -> convert
A42: Notes shares | B42: =B29+B30 -> 301450.03
A43: LP_total | B43: =IF(D35="preference",C35,0)+IF(D36="preference",C36,0)+IF(D37="preference",C37,0)+IF(D38="preference",C38,0)+IF(D39="preference",C39,0)+IF(D40="preference",C40,0)+IF(D41="preference",C41,0) -> 100000000
A44: PPS_at_2B | B44: =(Assumptions!$B$11-B43+Assumptions!$B$28*Assumptions!$B$20)/(Assumptions!$B$44+Assumptions!$B$45+Assumptions!$B$46+Assumptions!$B$47+B42+Assumptions!$B$28+IF(D35="convert",B35,0)+IF(D36="convert",B36,0)+IF(D37="convert",B37,0)+IF(D38="convert",B38,0)+IF(D39="convert",B39,0)+IF(D40="convert",B40,0)+IF(D41="convert",B41,0)) -> 55.498052
A45: F_class_proceeds | B45: =IF(D35="convert",B35*B44,C35) -> 51321766
A46: Our $ proceeds (1/3) | B46: =B45/3 -> 17107255
A55: === Scenario [11% ESOP, $1.4B pre] ===
A56: pre | B56: =Assumptions!$B$52 -> 1400000000
A57: esop_t | B57: =Assumptions!$B$48 -> 0.11
...

Sheet Return-Solver
A1: Return Solver — Required Series F Ownership for $30M / $40M
A3: Exit | B3: F class proceeds | C3: x for 3x ($30M) | D3: x for 4x ($40M) | E3: Feasible 3x? | F3: Feasible 4x?
A4: =Assumptions!$B$9 -> 700000000 | B4: =Waterfall!B28 -> 30000000 | C4: =Assumptions!$B$54*Assumptions!$B$7/B4 -> 1 | D4: =Assumptions!$B$55*Assumptions!$B$7/B4 -> 1.3333333 | E4: =IF(AND(C4>0,C4<=1),"feasible","infeasible") -> feasible | F4: =IF(AND(D4>0,D4<=1),"feasible","infeasible") -> infeasible
A5: =Assumptions!$B$10 -> 1200000000 | B5: =Waterfall!C28 -> 30000000 | C5: =Assumptions!$B$54*Assumptions!$B$7/B5 -> 1 | D5: =Assumptions!$B$55*Assumptions!$B$7/B5 -> 1.3333333 | E5: =IF(AND(C5>0,C5<=1),"feasible","infeasible") -> feasible | F5: =IF(AND(D5>0,D5<=1),"feasible","infeasible") -> infeasible
A6: =Assumptions!$B$11 -> 2000000000 | B6: =Waterfall!D28 -> 44846575 | C6: =Assumptions!$B$54*Assumptions!$B$7/B6 -> 0.6689474 | D6: =Assumptions!$B$55*Assumptions!$B$7/B6 -> 0.89192987 | E6: =IF(AND(C6>0,C6<=1),"feasible","infeasible") -> feasible | F6: =IF(AND(D6>0,D6<=1),"feasible","infeasible") -> feasible
A7: =Assumptions!$B$12 -> 4000000000 | B7: =Waterfall!E28 -> 89785823 | C7: =Assumptions!$B$54*Assumptions!$B$7/B7 -> 0.33412847 | D7: =Assumptions!$B$55*Assumptions!$B$7/B7 -> 0.44550463 | E7: =IF(AND(C7>0,C7<=1),"feasible","infeasible") -> feasible | F7: =IF(AND(D7>0,D7<=1),"feasible","infeasible") -> feasible
A8: =Assumptions!$B$13 -> 8000000000 | B8: =Waterfall!F28 -> 1.7951557e+08 | C8: =Assumptions!$B$54*Assumptions!$B$7/B8 -> 0.16711643 | D8: =Assumptions!$B$55*Assumptions!$B$7/B8 -> 0.2228219 | E8: =IF(AND(C8>0,C8<=1),"feasible","infeasible") -> feasible | F8: =IF(AND(D8>0,D8<=1),"feasible","infeasible") -> feasible
