Workbook
Name F_pre: 'Assumptions'!$B$4
Name F_primary: 'Assumptions'!$B$5
Name F_secondary: 'Assumptions'!$B$6
Name tender_mult: 'Assumptions'!$B$7
Name esop_target: 'Assumptions'!$B$8
Name our_check: 'Assumptions'!$B$9
Name fl_primary: 'Assumptions'!$B$10
Name opt_strike: 'Assumptions'!$B$11
Name exit_v1: 'Assumptions'!$B$13
Name exit_v2: 'Assumptions'!$B$14
Name exit_v3: 'Assumptions'!$B$15
Name exit_v4: 'Assumptions'!$B$16
Name exit_v5: 'Assumptions'!$B$17
Name OCP_seed: 'Assumptions'!$B$19
Name OCP_A: 'Assumptions'!$B$20
Name OCP_B: 'Assumptions'!$B$21
Name OCP_C: 'Assumptions'!$B$22
Name OCP_D: 'Assumptions'!$B$23
Name OCP_E: 'Assumptions'!$B$24
Name NA_P: 'Assumptions'!$B$26
Name NA_cap: 'Assumptions'!$B$27
Name NA_disc: 'Assumptions'!$B$28
Name NB_P: 'Assumptions'!$B$29
Name NB_cap: 'Assumptions'!$B$30
Name NB_disc: 'Assumptions'!$B$31
Name preF_FD: 'Assumptions'!$B$33
Name preF_opts_iss: 'Assumptions'!$B$34
Name preF_opts_uni: 'Assumptions'!$B$35
Name preF_opts: 'Assumptions'!$B$36
Name F1_sh: 'Assumptions'!$B$38
Name F2_sh: 'Assumptions'!$B$39
Name F3_sh: 'Assumptions'!$B$40
Name RSA_sh: 'Assumptions'!$B$41
Name seed_sh: 'Assumptions'!$B$43
Name A_sh: 'Assumptions'!$B$44
Name B_sh: 'Assumptions'!$B$45
Name C_sh: 'Assumptions'!$B$46
Name D_sh: 'Assumptions'!$B$47
Name E_sh: 'Assumptions'!$B$48
Name seed_inv: 'Assumptions'!$B$50
Name A_inv: 'Assumptions'!$B$51
Name B_inv: 'Assumptions'!$B$52
Name C_inv: 'Assumptions'!$B$53
Name D_inv: 'Assumptions'!$B$54
Name E_inv: 'Assumptions'!$B$55
Name sens_e_lo: 'Assumptions'!$B$57
Name sens_e_md: 'Assumptions'!$B$58
Name sens_e_hi: 'Assumptions'!$B$59
Name sens_p_lo: 'Assumptions'!$B$60
Name sens_p_md: 'Assumptions'!$B$61
Name sens_p_hi: 'Assumptions'!$B$62
Name sens_exit: 'Assumptions'!$B$63
Name ret_3x: 'Assumptions'!$B$65
Name ret_4x: 'Assumptions'!$B$66
Name F_PPS: 'Pro-Forma'!$B$4
Name T_F: 'Pro-Forma'!$B$5
Name T_pre: 'Pro-Forma'!$B$6
Name F_prim_sh: 'Pro-Forma'!$B$7
Name topup: 'Pro-Forma'!$B$8
Name preFD_nn: 'Pro-Forma'!$B$9

Sheet Assumptions
A1: Kelvin Dynamics — Series F Assumptions
A2: Label | B2: Value | C2: Units | D2: Name
A3: --- Round Terms ---
A4: Series F pre-money (USD) | B4: 1400000000 | C4: USD | D4: F_pre
A5: Series F primary raise (USD) | B5: 30000000 | C5: USD | D5: F_primary
A6: Series F secondary raise (USD) | B6: 15000000 | C6: USD | D6: F_secondary
A7: Tender PPS multiplier | B7: 0.85 | C7: fraction | D7: tender_mult
A8: ESOP refresh target (post-F FD) | B8: 0.13 | C8: fraction | D8: esop_target
A9: Our fund check (USD) | B9: 10000000 | C9: USD | D9: our_check
A10: F_LEAD primary check (USD) | B10: 20000000 | C10: USD | D10: fl_primary
A11: Option strike (USD) | B11: 1 | C11: USD | D11: opt_strike
A12: --- Exit Values ---
A13: Exit value 1 (USD) | B13: 700000000 | C13: USD | D13: exit_v1
A14: Exit value 2 (USD) | B14: 1200000000 | C14: USD | D14: exit_v2
A15: Exit value 3 (USD) | B15: 2000000000 | C15: USD | D15: exit_v3
A16: Exit value 4 (USD) | B16: 4000000000 | C16: USD | D16: exit_v4
A17: Exit value 5 (USD) | B17: 8000000000 | C17: USD | D17: exit_v5
A18: --- Prior Round OCPs (effective for AD) ---
A19: OCP Seed | B19: 1 | C19: USD | D19: OCP_seed
A20: OCP Series A | B20: 3 | C20: USD | D20: OCP_A
A21: OCP Series B | B21: 10 | C21: USD | D21: OCP_B
A22: OCP Series C | B22: 25 | C22: USD | D22: OCP_C
A23: OCP Series D (post-E NCP, compound v3*v4) | B23: 58.118347 | C23: USD | D23: OCP_D
A24: OCP Series E | B24: 49.158311 | C24: USD | D24: OCP_E
A25: --- Convertible Notes ---
A26: Note A principal (USD) | B26: 5000000 | C26: USD | D26: NA_P
A27: Note A cap (USD) | B27: 1000000000 | C27: USD | D27: NA_cap
A28: Note A discount | B28: 0.2 | C28: fraction | D28: NA_disc
A29: Note B principal (USD) | B29: 3000000 | C29: USD | D29: NB_P
A30: Note B cap (USD) | B30: 1600000000 | C30: USD | D30: NB_cap
A31: Note B discount | B31: 0.15 | C31: fraction | D31: NB_disc
A32: --- Pre-F Cap-Table Inputs (broad-based WA) ---
A33: Pre-F broad-based FD (shares) | B33: 36617961 | C33: shares | D33: preF_FD
A34: Pre-F options issued | B34: 2500000 | C34: shares | D34: preF_opts_iss
A35: Pre-F options unissued | B35: 1894667 | C35: shares | D35: preF_opts_uni
A36: Pre-F option pool total | B36: 4394667 | C36: shares | D36: preF_opts
A37: --- Founders & RSAs ---
A38: Founder F1 common shares | B38: 4000000 | C38: shares | D38: F1_sh
A39: Founder F2 common shares | B39: 2500000 | C39: shares | D39: F2_sh
A40: Founder F3 common shares | B40: 1500000 | C40: shares | D40: F3_sh
...

Sheet Pro-Forma
A1: Pro-Forma Cap Table (Post-Series F)
A3: ROUND MECHANICS (converged)
A4: F_PPS | B4: =N134
A5: T_F (post-F FD) | B5: =I134+J134+K134+L134
A6: T_pre (pre-money FD) | B6: =M134
A7: F_primary shares | B7: =L134
A8: ESOP top-up shares | B8: =H134
A9: Pre-money FD ex-notes | B9: =I134
A10: ESOP total post-F | B10: =preF_opts + H134
A11: Iteration converged at row | B11: 134
A13: ANTI-DILUTION BLOCK (broad-based WA)
A14: Class | B14: OCP | C14: Trigger | D14: NCP | E14: New Ratio | F14: Extras | G14: Total post-AD
A15: Seed | B15: =OCP_seed | C15: =IF(F_PPS<OCP_seed,"YES","NO") | D15: =IF(F_PPS<OCP_seed, OCP_seed*(preF_FD + F_primary/OCP_seed)/(preF_FD + F_primary/F_PPS), OCP_seed) | E15: =OCP_seed/D15 | F15: =seed_sh*(E15-1) | G15: =seed_sh*E15
A16: Series A | B16: =OCP_A | C16: =IF(F_PPS<OCP_A,"YES","NO") | D16: =IF(F_PPS<OCP_A, OCP_A*(preF_FD + F_primary/OCP_A)/(preF_FD + F_primary/F_PPS), OCP_A) | E16: =OCP_A/D16 | F16: =A_sh*(E16-1) | G16: =A_sh*E16
A17: Series B | B17: =OCP_B | C17: =IF(F_PPS<OCP_B,"YES","NO") | D17: =IF(F_PPS<OCP_B, OCP_B*(preF_FD + F_primary/OCP_B)/(preF_FD + F_primary/F_PPS), OCP_B) | E17: =OCP_B/D17 | F17: =B_sh*(E17-1) | G17: =B_sh*E17
A18: Series C | B18: =OCP_C | C18: =IF(F_PPS<OCP_C,"YES","NO") | D18: =IF(F_PPS<OCP_C, OCP_C*(preF_FD + F_primary/OCP_C)/(preF_FD + F_primary/F_PPS), OCP_C) | E18: =OCP_C/D18 | F18: =C_sh*(E18-1) | G18: =C_sh*E18
A19: Series D | B19: =OCP_D | C19: =IF(F_PPS<OCP_D,"YES","NO") | D19: =IF(F_PPS<OCP_D, OCP_D*(preF_FD + F_primary/OCP_D)/(preF_FD + F_primary/F_PPS), OCP_D) | E19: =OCP_D/D19 | F19: =D_sh*(E19-1) | G19: =D_sh*E19
A20: Series E | B20: =OCP_E | C20: =IF(F_PPS<OCP_E,"YES","NO") | D20: =IF(F_PPS<OCP_E, OCP_E*(preF_FD + F_primary/OCP_E)/(preF_FD + F_primary/F_PPS), OCP_E) | E20: =OCP_E/D20 | F20: =E_sh*(E20-1) | G20: =E_sh*E20
A22: CONVERTIBLE NOTES BLOCK
A23: Note | B23: Principal | C23: Cap | D23: Discount | E23: Cap-impl PPS | F23: Disc-impl PPS | G23: Conv PPS | H23: Branch | I23: Shares
A24: Note A | B24: =NA_P | C24: =NA_cap | D24: =NA_disc | E24: =NA_cap/(preFD_nn + K134) | F24: =(1-NA_disc)*F_PPS | G24: =MIN(E24,F24) | H24: =IF(E24<F24,"cap","discount") | I24: =NA_P/G24
A25: Note B | B25: =NB_P | C25: =NB_cap | D25: =NB_disc | E25: =NB_cap/(preFD_nn + I24) | F25: =(1-NB_disc)*F_PPS | G25: =MIN(E25,F25) | H25: =IF(E25<F25,"cap","discount") | I25: =NB_P/G25
A27: TENDER BLOCK
A28: Tender PPS | B28: =tender_mult * F_PPS
A29: Tender shares | B29: =F_secondary / B28
A30: F1 founders share-out | B30: =B29 * F1_sh/(F1_sh+F2_sh+F3_sh)
A31: F2 founders share-out | B31: =B29 * F2_sh/(F1_sh+F2_sh+F3_sh)
A32: F3 founders share-out | B32: =B29 * F3_sh/(F1_sh+F2_sh+F3_sh)
A33: F_LEAD secondary common | B33: =B29
A35: STAKEHOLDER OWNERSHIP
A36: Stakeholder | B36: Role | C36: Common | D36: Preferred | E36: Options (issued) | F36: Options (unissued) | G36: Notes-converted | H36: Total | I36: % of T_F
A37: F1 | B37: Founder (CEO) | C37: =F1_sh - F1_tender | D37: =0 | E37: =0 | F37: =0 | G37: =0 | H37: =SUM(C37:G37) | I37: =H37/T_F
A38: F2 | B38: Founder (CTO) | C38: =F2_sh - F2_tender | D38: =0 | E38: =0 | F38: =0 | G38: =0 | H38: =SUM(C38:G38) | I38: =H38/T_F
A39: F3 | B39: Founder (Chief Sci.) | C39: =F3_sh - F3_tender | D39: =0 | E39: =0 | F39: =0 | G39: =0 | H39: =SUM(C39:G39) | I39: =H39/T_F
A40: RSAs (E1-E10) | B40: Employee RSAs (10 holders) | C40: =RSA_sh | D40: =0 | E40: =0 | F40: =0 | G40: =0 | H40: =SUM(C40:G40) | I40: =H40/T_F
A41: ESOP issued | B41: Issued options | C41: =0 | D41: =0 | E41: =preF_opts_iss | F41: =0 | G41: =0 | H41: =SUM(C41:G41) | I41: =H41/T_F
A42: ESOP unissued | B42: Unissued option pool (post-F) | C42: =0 | D42: =0 | E42: =0 | F42: =preF_opts_uni + topup | G42: =0 | H42: =SUM(C42:G42) | I42: =H42/T_F
A43: SEED1 | B43: Seed preferred LP | C43: =0 | D43: =Seed_total | E43: =0 | F43: =0 | G43: =0 | H43: =SUM(C43:G43) | I43: =H43/T_F
A44: A1 | B44: Series A preferred | C44: =0 | D44: =A_total | E44: =0 | F44: =0 | G44: =0 | H44: =SUM(C44:G44) | I44: =H44/T_F
A45: B1 | B45: Series B preferred | C45: =0 | D45: =B_total | E45: =0 | F45: =0 | G45: =0 | H45: =SUM(C45:G45) | I45: =H45/T_F
...

Sheet Waterfall
A1: Waterfall — Per-Class Election Maximization
A3: Exit value (USD) | B3: =exit_v1 | C3: =exit_v2 | D3: =exit_v3 | E3: =exit_v4 | F3: =exit_v5
A5: DISPLAY (converged)
A6: Prefs paid | B6: =B85 | C6: =B122 | D6: =B159 | E6: =B196 | F6: =B233
A7: Residual | B7: =C85 | C7: =C122 | D7: =C159 | E7: =C196 | F7: =C233
A8: Convert shares (incl. common+RSAs+notes) | B8: =D85 | C8: =D122 | D8: =D159 | E8: =D196 | F8: =D233
A9: Exit PPS (used) | B9: =H85 | C9: =H122 | D9: =H159 | E9: =H196 | F9: =H233
A10: F election | B10: =IF(B9 * F_class_shares > F_primary, "convert", "preference") | C10: =IF(C9 * F_class_shares > F_primary, "convert", "preference") | D10: =IF(D9 * F_class_shares > F_primary, "convert", "preference") | E10: =IF(E9 * F_class_shares > F_primary, "convert", "preference") | F10: =IF(F9 * F_class_shares > F_primary, "convert", "preference")
A11: E election | B11: =IF(B9 * E_total > E_inv, "convert", "preference") | C11: =IF(C9 * E_total > E_inv, "convert", "preference") | D11: =IF(D9 * E_total > E_inv, "convert", "preference") | E11: =IF(E9 * E_total > E_inv, "convert", "preference") | F11: =IF(F9 * E_total > E_inv, "convert", "preference")
A12: D election | B12: =IF(B9 * D_total > D_inv, "convert", "preference") | C12: =IF(C9 * D_total > D_inv, "convert", "preference") | D12: =IF(D9 * D_total > D_inv, "convert", "preference") | E12: =IF(E9 * D_total > D_inv, "convert", "preference") | F12: =IF(F9 * D_total > D_inv, "convert", "preference")
A13: C election | B13: =IF(B9 * C_total > C_inv, "convert", "preference") | C13: =IF(C9 * C_total > C_inv, "convert", "preference") | D13: =IF(D9 * C_total > C_inv, "convert", "preference") | E13: =IF(E9 * C_total > C_inv, "convert", "preference") | F13: =IF(F9 * C_total > C_inv, "convert", "preference")
A14: B election | B14: =IF(B9 * B_total > B_inv, "convert", "preference") | C14: =IF(C9 * B_total > B_inv, "convert", "preference") | D14: =IF(D9 * B_total > B_inv, "convert", "preference") | E14: =IF(E9 * B_total > B_inv, "convert", "preference") | F14: =IF(F9 * B_total > B_inv, "convert", "preference")
A15: A election | B15: =IF(B9 * A_total > A_inv, "convert", "preference") | C15: =IF(C9 * A_total > A_inv, "convert", "preference") | D15: =IF(D9 * A_total > A_inv, "convert", "preference") | E15: =IF(E9 * A_total > A_inv, "convert", "preference") | F15: =IF(F9 * A_total > A_inv, "convert", "preference")
A16: Seed election | B16: =IF(B9 * Seed_total > seed_inv, "convert", "preference") | C16: =IF(C9 * Seed_total > seed_inv, "convert", "preference") | D16: =IF(D9 * Seed_total > seed_inv, "convert", "preference") | E16: =IF(E9 * Seed_total > seed_inv, "convert", "preference") | F16: =IF(F9 * Seed_total > seed_inv, "convert", "preference")
A18: F payout | B18: =IF(B10="convert", B9 * F_class_shares, F_primary) | C18: =IF(C10="convert", C9 * F_class_shares, F_primary) | D18: =IF(D10="convert", D9 * F_class_shares, F_primary) | E18: =IF(E10="convert", E9 * F_class_shares, F_primary) | F18: =IF(F10="convert", F9 * F_class_shares, F_primary)
A19: E payout | B19: =IF(B11="convert", B9 * E_total, E_inv) | C19: =IF(C11="convert", C9 * E_total, E_inv) | D19: =IF(D11="convert", D9 * E_total, E_inv) | E19: =IF(E11="convert", E9 * E_total, E_inv) | F19: =IF(F11="convert", F9 * E_total, E_inv)
A20: D payout | B20: =IF(B12="convert", B9 * D_total, D_inv) | C20: =IF(C12="convert", C9 * D_total, D_inv) | D20: =IF(D12="convert", D9 * D_total, D_inv) | E20: =IF(E12="convert", E9 * D_total, D_inv) | F20: =IF(F12="convert", F9 * D_total, D_inv)
A21: C payout | B21: =IF(B13="convert", B9 * C_total, C_inv) | C21: =IF(C13="convert", C9 * C_total, C_inv) | D21: =IF(D13="convert", D9 * C_total, C_inv) | E21: =IF(E13="convert", E9 * C_total, C_inv) | F21: =IF(F13="convert", F9 * C_total, C_inv)
A22: B payout | B22: =IF(B14="convert", B9 * B_total, B_inv) | C22: =IF(C14="convert", C9 * B_total, B_inv) | D22: =IF(D14="convert", D9 * B_total, B_inv) | E22: =IF(E14="convert", E9 * B_total, B_inv) | F22: =IF(F14="convert", F9 * B_total, B_inv)
A23: A payout | B23: =IF(B15="convert", B9 * A_total, A_inv) | C23: =IF(C15="convert", C9 * A_total, A_inv) | D23: =IF(D15="convert", D9 * A_total, A_inv) | E23: =IF(E15="convert", E9 * A_total, A_inv) | F23: =IF(F15="convert", F9 * A_total, A_inv)
A24: Seed payout | B24: =IF(B16="convert", B9 * Seed_total, seed_inv) | C24: =IF(C16="convert", C9 * Seed_total, seed_inv) | D24: =IF(D16="convert", D9 * Seed_total, seed_inv) | E24: =IF(E16="convert", E9 * Seed_total, seed_inv) | F24: =IF(F16="convert", F9 * Seed_total, seed_inv)
A25: Notes payout (A+B) | B25: =B9 * (NA_sh + NB_sh) | C25: =C9 * (NA_sh + NB_sh) | D25: =D9 * (NA_sh + NB_sh) | E25: =E9 * (NA_sh + NB_sh) | F25: =F9 * (NA_sh + NB_sh)
A26: Common+RSAs payout | B26: =B9 * (F1_sh+F2_sh+F3_sh+RSA_sh) | C26: =C9 * (F1_sh+F2_sh+F3_sh+RSA_sh) | D26: =D9 * (F1_sh+F2_sh+F3_sh+RSA_sh) | E26: =E9 * (F1_sh+F2_sh+F3_sh+RSA_sh) | F26: =F9 * (F1_sh+F2_sh+F3_sh+RSA_sh)
A27: Issued options (net of strike) | B27: =IF(G85=1, (B9 - opt_strike)*preF_opts_iss, 0) | C27: =IF(G122=1, (C9 - opt_strike)*preF_opts_iss, 0) | D27: =IF(G159=1, (D9 - opt_strike)*preF_opts_iss, 0) | E27: =IF(G196=1, (E9 - opt_strike)*preF_opts_iss, 0) | F27: =IF(G233=1, (F9 - opt_strike)*preF_opts_iss, 0)
A28: Total | B28: =B18+B19+B20+B21+B22+B23+B24+B25+B26+B27 | C28: =C18+C19+C20+C21+C22+C23+C24+C25+C26+C27 | D28: =D18+D19+D20+D21+D22+D23+D24+D25+D26+D27 | E28: =E18+E19+E20+E21+E22+E23+E24+E25+E26+E27 | F28: =F18+F19+F20+F21+F22+F23+F24+F25+F26+F27
A29: Reconciliation diff (USD) | B29: =B3 - B28 | C29: =C3 - C28 | D29: =D3 - D28 | E29: =E3 - E28 | F29: =F3 - F28
A49: --- Iteration block for exit exit_v1 ---
A50: iter | B50: prefs_paid | C50: residual | D50: cv_shares | E50: PPS_naive | F50: PPS_w_opts | G50: ITM | H50: PPS | I50: ic_F | J50: ic_E | K50: ic_D | L50: ic_C | M50: ic_B | N50: ic_A | O50: ic_Seed
B51: =(1-I51)*F_primary+(1-J51)*E_inv+(1-K51)*D_inv+(1-L51)*C_inv+(1-M51)*B_inv+(1-N51)*A_inv+(1-O51)*seed_inv | C51: =MAX(0, B3 - B51) | D51: =F1_sh+F2_sh+F3_sh+RSA_sh+NA_sh+NB_sh+I51*F_class_shares+J51*E_total+K51*D_total+L51*C_total+M51*B_total+N51*A_total+O51*Seed_total | E51: =IF(D51>0, C51/D51, 0) | F51: =(C51 + preF_opts_iss*opt_strike)/(D51 + preF_opts_iss) | G51: =IF(F51>opt_strike,1,0) | H51: =IF(G51=1, F51, E51) | I51: =IF(0 * F_class_shares > F_primary, 1, 0) | J51: =IF(0 * E_total > E_inv, 1, 0) | K51: =IF(0 * D_total > D_inv, 1, 0) | L51: =IF(0 * C_total > C_inv, 1, 0) | M51: =IF(0 * B_total > B_inv, 1, 0) | N51: =IF(0 * A_total > A_inv, 1, 0) | O51: =IF(0 * Seed_total > seed_inv, 1, 0)
B52: =(1-I52)*F_primary+(1-J52)*E_inv+(1-K52)*D_inv+(1-L52)*C_inv+(1-M52)*B_inv+(1-N52)*A_inv+(1-O52)*seed_inv | C52: =MAX(0, B3 - B52) | D52: =F1_sh+F2_sh+F3_sh+RSA_sh+NA_sh+NB_sh+I52*F_class_shares+J52*E_total+K52*D_total+L52*C_total+M52*B_total+N52*A_total+O52*Seed_total | E52: =IF(D52>0, C52/D52, 0) | F52: =(C52 + preF_opts_iss*opt_strike)/(D52 + preF_opts_iss) | G52: =IF(F52>opt_strike,1,0) | H52: =IF(G52=1, F52, E52) | I52: =IF(H51 * F_class_shares > F_primary, 1, 0) | J52: =IF(H51 * E_total > E_inv, 1, 0) | K52: =IF(H51 * D_total > D_inv, 1, 0) | L52: =IF(H51 * C_total > C_inv, 1, 0) | M52: =IF(H51 * B_total > B_inv, 1, 0) | N52: =IF(H51 * A_total > A_inv, 1, 0) | O52: =IF(H51 * Seed_total > seed_inv, 1, 0)
B53: =(1-I53)*F_primary+(1-J53)*E_inv+(1-K53)*D_inv+(1-L53)*C_inv+(1-M53)*B_inv+(1-N53)*A_inv+(1-O53)*seed_inv | C53: =MAX(0, B3 - B53) | D53: =F1_sh+F2_sh+F3_sh+RSA_sh+NA_sh+NB_sh+I53*F_class_shares+J53*E_total+K53*D_total+L53*C_total+M53*B_total+N53*A_total+O53*Seed_total | E53: =IF(D53>0, C53/D53, 0) | F53: =(C53 + preF_opts_iss*opt_strike)/(D53 + preF_opts_iss) | G53: =IF(F53>opt_strike,1,0) | H53: =IF(G53=1, F53, E53) | I53: =IF(H52 * F_class_shares > F_primary, 1, 0) | J53: =IF(H52 * E_total > E_inv, 1, 0) | K53: =IF(H52 * D_total > D_inv, 1, 0) | L53: =IF(H52 * C_total > C_inv, 1, 0) | M53: =IF(H52 * B_total > B_inv, 1, 0) | N53: =IF(H52 * A_total > A_inv, 1, 0) | O53: =IF(H52 * Seed_total > seed_inv, 1, 0)
B54: =(1-I54)*F_primary+(1-J54)*E_inv+(1-K54)*D_inv+(1-L54)*C_inv+(1-M54)*B_inv+(1-N54)*A_inv+(1-O54)*seed_inv | C54: =MAX(0, B3 - B54) | D54: =F1_sh+F2_sh+F3_sh+RSA_sh+NA_sh+NB_sh+I54*F_class_shares+J54*E_total+K54*D_total+L54*C_total+M54*B_total+N54*A_total+O54*Seed_total | E54: =IF(D54>0, C54/D54, 0) | F54: =(C54 + preF_opts_iss*opt_strike)/(D54 + preF_opts_iss) | G54: =IF(F54>opt_strike,1,0) | H54: =IF(G54=1, F54, E54) | I54: =IF(H53 * F_class_shares > F_primary, 1, 0) | J54: =IF(H53 * E_total > E_inv, 1, 0) | K54: =IF(H53 * D_total > D_inv, 1, 0) | L54: =IF(H53 * C_total > C_inv, 1, 0) | M54: =IF(H53 * B_total > B_inv, 1, 0) | N54: =IF(H53 * A_total > A_inv, 1, 0) | O54: =IF(H53 * Seed_total > seed_inv, 1, 0)
B55: =(1-I55)*F_primary+(1-J55)*E_inv+(1-K55)*D_inv+(1-L55)*C_inv+(1-M55)*B_inv+(1-N55)*A_inv+(1-O55)*seed_inv | C55: =MAX(0, B3 - B55) | D55: =F1_sh+F2_sh+F3_sh+RSA_sh+NA_sh+NB_sh+I55*F_class_shares+J55*E_total+K55*D_total+L55*C_total+M55*B_total+N55*A_total+O55*Seed_total | E55: =IF(D55>0, C55/D55, 0) | F55: =(C55 + preF_opts_iss*opt_strike)/(D55 + preF_opts_iss) | G55: =IF(F55>opt_strike,1,0) | H55: =IF(G55=1, F55, E55) | I55: =IF(H54 * F_class_shares > F_primary, 1, 0) | J55: =IF(H54 * E_total > E_inv, 1, 0) | K55: =IF(H54 * D_total > D_inv, 1, 0) | L55: =IF(H54 * C_total > C_inv, 1, 0) | M55: =IF(H54 * B_total > B_inv, 1, 0) | N55: =IF(H54 * A_total > A_inv, 1, 0) | O55: =IF(H54 * Seed_total > seed_inv, 1, 0)
B56: =(1-I56)*F_primary+(1-J56)*E_inv+(1-K56)*D_inv+(1-L56)*C_inv+(1-M56)*B_inv+(1-N56)*A_inv+(1-O56)*seed_inv | C56: =MAX(0, B3 - B56) | D56: =F1_sh+F2_sh+F3_sh+RSA_sh+NA_sh+NB_sh+I56*F_class_shares+J56*E_total+K56*D_total+L56*C_total+M56*B_total+N56*A_total+O56*Seed_total | E56: =IF(D56>0, C56/D56, 0) | F56: =(C56 + preF_opts_iss*opt_strike)/(D56 + preF_opts_iss) | G56: =IF(F56>opt_strike,1,0) | H56: =IF(G56=1, F56, E56) | I56: =IF(H55 * F_class_shares > F_primary, 1, 0) | J56: =IF(H55 * E_total > E_inv, 1, 0) | K56: =IF(H55 * D_total > D_inv, 1, 0) | L56: =IF(H55 * C_total > C_inv, 1, 0) | M56: =IF(H55 * B_total > B_inv, 1, 0) | N56: =IF(H55 * A_total > A_inv, 1, 0) | O56: =IF(H55 * Seed_total > seed_inv, 1, 0)
B57: =(1-I57)*F_primary+(1-J57)*E_inv+(1-K57)*D_inv+(1-L57)*C_inv+(1-M57)*B_inv+(1-N57)*A_inv+(1-O57)*seed_inv | C57: =MAX(0, B3 - B57) | D57: =F1_sh+F2_sh+F3_sh+RSA_sh+NA_sh+NB_sh+I57*F_class_shares+J57*E_total+K57*D_total+L57*C_total+M57*B_total+N57*A_total+O57*Seed_total | E57: =IF(D57>0, C57/D57, 0) | F57: =(C57 + preF_opts_iss*opt_strike)/(D57 + preF_opts_iss) | G57: =IF(F57>opt_strike,1,0) | H57: =IF(G57=1, F57, E57) | I57: =IF(H56 * F_class_shares > F_primary, 1, 0) | J57: =IF(H56 * E_total > E_inv, 1, 0) | K57: =IF(H56 * D_total > D_inv, 1, 0) | L57: =IF(H56 * C_total > C_inv, 1, 0) | M57: =IF(H56 * B_total > B_inv, 1, 0) | N57: =IF(H56 * A_total > A_inv, 1, 0) | O57: =IF(H56 * Seed_total > seed_inv, 1, 0)
B58: =(1-I58)*F_primary+(1-J58)*E_inv+(1-K58)*D_inv+(1-L58)*C_inv+(1-M58)*B_inv+(1-N58)*A_inv+(1-O58)*seed_inv | C58: =MAX(0, B3 - B58) | D58: =F1_sh+F2_sh+F3_sh+RSA_sh+NA_sh+NB_sh+I58*F_class_shares+J58*E_total+K58*D_total+L58*C_total+M58*B_total+N58*A_total+O58*Seed_total | E58: =IF(D58>0, C58/D58, 0) | F58: =(C58 + preF_opts_iss*opt_strike)/(D58 + preF_opts_iss) | G58: =IF(F58>opt_strike,1,0) | H58: =IF(G58=1, F58, E58) | I58: =IF(H57 * F_class_shares > F_primary, 1, 0) | J58: =IF(H57 * E_total > E_inv, 1, 0) | K58: =IF(H57 * D_total > D_inv, 1, 0) | L58: =IF(H57 * C_total > C_inv, 1, 0) | M58: =IF(H57 * B_total > B_inv, 1, 0) | N58: =IF(H57 * A_total > A_inv, 1, 0) | O58: =IF(H57 * Seed_total > seed_inv, 1, 0)
B59: =(1-I59)*F_primary+(1-J59)*E_inv+(1-K59)*D_inv+(1-L59)*C_inv+(1-M59)*B_inv+(1-N59)*A_inv+(1-O59)*seed_inv | C59: =MAX(0, B3 - B59) | D59: =F1_sh+F2_sh+F3_sh+RSA_sh+NA_sh+NB_sh+I59*F_class_shares+J59*E_total+K59*D_total+L59*C_total+M59*B_total+N59*A_total+O59*Seed_total | E59: =IF(D59>0, C59/D59, 0) | F59: =(C59 + preF_opts_iss*opt_strike)/(D59 + preF_opts_iss) | G59: =IF(F59>opt_strike,1,0) | H59: =IF(G59=1, F59, E59) | I59: =IF(H58 * F_class_shares > F_primary, 1, 0) | J59: =IF(H58 * E_total > E_inv, 1, 0) | K59: =IF(H58 * D_total > D_inv, 1, 0) | L59: =IF(H58 * C_total > C_inv, 1, 0) | M59: =IF(H58 * B_total > B_inv, 1, 0) | N59: =IF(H58 * A_total > A_inv, 1, 0) | O59: =IF(H58 * Seed_total > seed_inv, 1, 0)
B60: =(1-I60)*F_primary+(1-J60)*E_inv+(1-K60)*D_inv+(1-L60)*C_inv+(1-M60)*B_inv+(1-N60)*A_inv+(1-O60)*seed_inv | C60: =MAX(0, B3 - B60) | D60: =F1_sh+F2_sh+F3_sh+RSA_sh+NA_sh+NB_sh+I60*F_class_shares+J60*E_total+K60*D_total+L60*C_total+M60*B_total+N60*A_total+O60*Seed_total | E60: =IF(D60>0, C60/D60, 0) | F60: =(C60 + preF_opts_iss*opt_strike)/(D60 + preF_opts_iss) | G60: =IF(F60>opt_strike,1,0) | H60: =IF(G60=1, F60, E60) | I60: =IF(H59 * F_class_shares > F_primary, 1, 0) | J60: =IF(H59 * E_total > E_inv, 1, 0) | K60: =IF(H59 * D_total > D_inv, 1, 0) | L60: =IF(H59 * C_total > C_inv, 1, 0) | M60: =IF(H59 * B_total > B_inv, 1, 0) | N60: =IF(H59 * A_total > A_inv, 1, 0) | O60: =IF(H59 * Seed_total > seed_inv, 1, 0)
B61: =(1-I61)*F_primary+(1-J61)*E_inv+(1-K61)*D_inv+(1-L61)*C_inv+(1-M61)*B_inv+(1-N61)*A_inv+(1-O61)*seed_inv | C61: =MAX(0, B3 - B61) | D61: =F1_sh+F2_sh+F3_sh+RSA_sh+NA_sh+NB_sh+I61*F_class_shares+J61*E_total+K61*D_total+L61*C_total+M61*B_total+N61*A_total+O61*Seed_total | E61: =IF(D61>0, C61/D61, 0) | F61: =(C61 + preF_opts_iss*opt_strike)/(D61 + preF_opts_iss) | G61: =IF(F61>opt_strike,1,0) | H61: =IF(G61=1, F61, E61) | I61: =IF(H60 * F_class_shares > F_primary, 1, 0) | J61: =IF(H60 * E_total > E_inv, 1, 0) | K61: =IF(H60 * D_total > D_inv, 1, 0) | L61: =IF(H60 * C_total > C_inv, 1, 0) | M61: =IF(H60 * B_total > B_inv, 1, 0) | N61: =IF(H60 * A_total > A_inv, 1, 0) | O61: =IF(H60 * Seed_total > seed_inv, 1, 0)
B62: =(1-I62)*F_primary+(1-J62)*E_inv+(1-K62)*D_inv+(1-L62)*C_inv+(1-M62)*B_inv+(1-N62)*A_inv+(1-O62)*seed_inv | C62: =MAX(0, B3 - B62) | D62: =F1_sh+F2_sh+F3_sh+RSA_sh+NA_sh+NB_sh+I62*F_class_shares+J62*E_total+K62*D_total+L62*C_total+M62*B_total+N62*A_total+O62*Seed_total | E62: =IF(D62>0, C62/D62, 0) | F62: =(C62 + preF_opts_iss*opt_strike)/(D62 + preF_opts_iss) | G62: =IF(F62>opt_strike,1,0) | H62: =IF(G62=1, F62, E62) | I62: =IF(H61 * F_class_shares > F_primary, 1, 0) | J62: =IF(H61 * E_total > E_inv, 1, 0) | K62: =IF(H61 * D_total > D_inv, 1, 0) | L62: =IF(H61 * C_total > C_inv, 1, 0) | M62: =IF(H61 * B_total > B_inv, 1, 0) | N62: =IF(H61 * A_total > A_inv, 1, 0) | O62: =IF(H61 * Seed_total > seed_inv, 1, 0)
...

Sheet Sensitivity
A1: Sensitivity — ESOP × Pre-money @ $2B exit
A3: Each cell shows our $10M check's post-F ownership % and $ proceeds at $2B exit.
A4: Each cell re-solves the full fixed point (F_PPS, ESOP, AD on D&E, both note branches) from scratch.
A6: ESOP ↓ / Pre-money → | B6: =sens_p_lo | C6: =sens_p_md | D6: =sens_p_hi
A7: =sens_e_lo | B7: =TEXT(D31,"0.0000%")&" / "&TEXT(H31*our_check/F_primary,"$#,##0") | C7: =TEXT(D71,"0.0000%")&" / "&TEXT(H71*our_check/F_primary,"$#,##0") | D7: =TEXT(D111,"0.0000%")&" / "&TEXT(H111*our_check/F_primary,"$#,##0")
A8: =sens_e_md | B8: =TEXT(D151,"0.0000%")&" / "&TEXT(H151*our_check/F_primary,"$#,##0") | C8: =TEXT(D191,"0.0000%")&" / "&TEXT(H191*our_check/F_primary,"$#,##0") | D8: =TEXT(D231,"0.0000%")&" / "&TEXT(H231*our_check/F_primary,"$#,##0")
A9: =sens_e_hi | B9: =TEXT(D271,"0.0000%")&" / "&TEXT(H271*our_check/F_primary,"$#,##0") | C9: =TEXT(D311,"0.0000%")&" / "&TEXT(H311*our_check/F_primary,"$#,##0") | D9: =TEXT(D351,"0.0000%")&" / "&TEXT(H351*our_check/F_primary,"$#,##0")
A29: --- Scenario 1: ESOP=sens_e_lo, Pre-money=sens_p_lo ---
A30: ESOP | B30: =sens_e_lo | C30: Pre-money | D30: =sens_p_lo | E30: F_PPS | F30: =N68 | G30: T_F | H30: =I68+J68+K68+L68 | I30: NA_sh | J30: =J68 | K30: NB_sh | L30: =K68 | M30: NA_branch | N30: =IF(NA_cap/(I68+K68) < (1-NA_disc)*N68, "cap", "discount") | O30: NB_branch | P30: =IF(NB_cap/(I68+J68) < (1-NB_disc)*N68, "cap", "discount")
A31: our_sh | B31: =our_check/F30 | C31: own% | D31: =B31/H30 | E31: F_election | F31: =IF(Y68*L68 > F_primary, "convert", "preference") | G31: F_payout | H31: =IF(F31="convert", Y68*L68, F_primary) | I31: our_$ | J31: =H31*our_check/F_primary
A33: iter | B33: F_PPS_in | C33: NCP_D | D33: NCP_E | E33: extras_D | F33: extras_E | G33: T_F | H33: topup | I33: preFD_nn | J33: NA_sh | K33: NB_sh | L33: F_prim_sh | M33: T_pre | N33: F_PPS_out | O33: ic_F | P33: ic_E | Q33: ic_D | R33: ic_C | S33: ic_B | T33: ic_A | U33: ic_Seed | V33: prefs_paid | W33: residual | X33: cv_shares | Y33: PPS_2B
B34: =D30/preF_FD | C34: =OCP_D*(preF_FD + F_primary/OCP_D)/(preF_FD + F_primary/B34) | D34: =OCP_E*(preF_FD + F_primary/OCP_E)/(preF_FD + F_primary/B34) | E34: =D_sh*(OCP_D/C34 - 1) | F34: =E_sh*(OCP_E/D34 - 1) | G34: =(preF_FD + E34 + F34 - preF_opts + 0 + 0 + F_primary/B34)/(1-B30) | H34: =MAX(0, B30*G34 - preF_opts) | I34: =preF_FD + E34 + F34 + H34 | J34: =NA_P/MIN(NA_cap/(I34+0), (1-NA_disc)*B34) | K34: =NB_P/MIN(NB_cap/(I34+J34), (1-NB_disc)*B34) | L34: =F_primary/B34 | M34: =I34+J34+K34 | N34: =D30/M34 | O34: =IF(0*L34 > F_primary, 1, 0) | P34: =IF(0*(E_sh + F34) > E_inv, 1, 0) | Q34: =IF(0*(D_sh + E34) > D_inv, 1, 0) | R34: =IF(0*C_sh > C_inv, 1, 0) | S34: =IF(0*B_sh > B_inv, 1, 0) | T34: =IF(0*A_sh > A_inv, 1, 0) | U34: =IF(0*seed_sh > seed_inv, 1, 0) | V34: =(1-O34)*F_primary+(1-P34)*E_inv+(1-Q34)*D_inv+(1-R34)*C_inv+(1-S34)*B_inv+(1-T34)*A_inv+(1-U34)*seed_inv | W34: =MAX(0, sens_exit - V34) | X34: =F1_sh+F2_sh+F3_sh+RSA_sh+J34+K34+O34*L34+P34*(E_sh + F34)+Q34*(D_sh + E34)+R34*C_sh+S34*B_sh+T34*A_sh+U34*seed_sh | Y34: =(W34 + preF_opts_iss*opt_strike)/(X34 + preF_opts_iss)
B35: =N34 | C35: =OCP_D*(preF_FD + F_primary/OCP_D)/(preF_FD + F_primary/B35) | D35: =OCP_E*(preF_FD + F_primary/OCP_E)/(preF_FD + F_primary/B35) | E35: =D_sh*(OCP_D/C35 - 1) | F35: =E_sh*(OCP_E/D35 - 1) | G35: =(preF_FD + E35 + F35 - preF_opts + J34 + K34 + F_primary/B35)/(1-B30) | H35: =MAX(0, B30*G35 - preF_opts) | I35: =preF_FD + E35 + F35 + H35 | J35: =NA_P/MIN(NA_cap/(I35+K34), (1-NA_disc)*B35) | K35: =NB_P/MIN(NB_cap/(I35+J35), (1-NB_disc)*B35) | L35: =F_primary/B35 | M35: =I35+J35+K35 | N35: =D30/M35 | O35: =IF(Y34*L35 > F_primary, 1, 0) | P35: =IF(Y34*(E_sh + F35) > E_inv, 1, 0) | Q35: =IF(Y34*(D_sh + E35) > D_inv, 1, 0) | R35: =IF(Y34*C_sh > C_inv, 1, 0) | S35: =IF(Y34*B_sh > B_inv, 1, 0) | T35: =IF(Y34*A_sh > A_inv, 1, 0) | U35: =IF(Y34*seed_sh > seed_inv, 1, 0) | V35: =(1-O35)*F_primary+(1-P35)*E_inv+(1-Q35)*D_inv+(1-R35)*C_inv+(1-S35)*B_inv+(1-T35)*A_inv+(1-U35)*seed_inv | W35: =MAX(0, sens_exit - V35) | X35: =F1_sh+F2_sh+F3_sh+RSA_sh+J35+K35+O35*L35+P35*(E_sh + F35)+Q35*(D_sh + E35)+R35*C_sh+S35*B_sh+T35*A_sh+U35*seed_sh | Y35: =(W35 + preF_opts_iss*opt_strike)/(X35 + preF_opts_iss)
B36: =N35 | C36: =OCP_D*(preF_FD + F_primary/OCP_D)/(preF_FD + F_primary/B36) | D36: =OCP_E*(preF_FD + F_primary/OCP_E)/(preF_FD + F_primary/B36) | E36: =D_sh*(OCP_D/C36 - 1) | F36: =E_sh*(OCP_E/D36 - 1) | G36: =(preF_FD + E36 + F36 - preF_opts + J35 + K35 + F_primary/B36)/(1-B30) | H36: =MAX(0, B30*G36 - preF_opts) | I36: =preF_FD + E36 + F36 + H36 | J36: =NA_P/MIN(NA_cap/(I36+K35), (1-NA_disc)*B36) | K36: =NB_P/MIN(NB_cap/(I36+J36), (1-NB_disc)*B36) | L36: =F_primary/B36 | M36: =I36+J36+K36 | N36: =D30/M36 | O36: =IF(Y35*L36 > F_primary, 1, 0) | P36: =IF(Y35*(E_sh + F36) > E_inv, 1, 0) | Q36: =IF(Y35*(D_sh + E36) > D_inv, 1, 0) | R36: =IF(Y35*C_sh > C_inv, 1, 0) | S36: =IF(Y35*B_sh > B_inv, 1, 0) | T36: =IF(Y35*A_sh > A_inv, 1, 0) | U36: =IF(Y35*seed_sh > seed_inv, 1, 0) | V36: =(1-O36)*F_primary+(1-P36)*E_inv+(1-Q36)*D_inv+(1-R36)*C_inv+(1-S36)*B_inv+(1-T36)*A_inv+(1-U36)*seed_inv | W36: =MAX(0, sens_exit - V36) | X36: =F1_sh+F2_sh+F3_sh+RSA_sh+J36+K36+O36*L36+P36*(E_sh + F36)+Q36*(D_sh + E36)+R36*C_sh+S36*B_sh+T36*A_sh+U36*seed_sh | Y36: =(W36 + preF_opts_iss*opt_strike)/(X36 + preF_opts_iss)
B37: =N36 | C37: =OCP_D*(preF_FD + F_primary/OCP_D)/(preF_FD + F_primary/B37) | D37: =OCP_E*(preF_FD + F_primary/OCP_E)/(preF_FD + F_primary/B37) | E37: =D_sh*(OCP_D/C37 - 1) | F37: =E_sh*(OCP_E/D37 - 1) | G37: =(preF_FD + E37 + F37 - preF_opts + J36 + K36 + F_primary/B37)/(1-B30) | H37: =MAX(0, B30*G37 - preF_opts) | I37: =preF_FD + E37 + F37 + H37 | J37: =NA_P/MIN(NA_cap/(I37+K36), (1-NA_disc)*B37) | K37: =NB_P/MIN(NB_cap/(I37+J37), (1-NB_disc)*B37) | L37: =F_primary/B37 | M37: =I37+J37+K37 | N37: =D30/M37 | O37: =IF(Y36*L37 > F_primary, 1, 0) | P37: =IF(Y36*(E_sh + F37) > E_inv, 1, 0) | Q37: =IF(Y36*(D_sh + E37) > D_inv, 1, 0) | R37: =IF(Y36*C_sh > C_inv, 1, 0) | S37: =IF(Y36*B_sh > B_inv, 1, 0) | T37: =IF(Y36*A_sh > A_inv, 1, 0) | U37: =IF(Y36*seed_sh > seed_inv, 1, 0) | V37: =(1-O37)*F_primary+(1-P37)*E_inv+(1-Q37)*D_inv+(1-R37)*C_inv+(1-S37)*B_inv+(1-T37)*A_inv+(1-U37)*seed_inv | W37: =MAX(0, sens_exit - V37) | X37: =F1_sh+F2_sh+F3_sh+RSA_sh+J37+K37+O37*L37+P37*(E_sh + F37)+Q37*(D_sh + E37)+R37*C_sh+S37*B_sh+T37*A_sh+U37*seed_sh | Y37: =(W37 + preF_opts_iss*opt_strike)/(X37 + preF_opts_iss)
B38: =N37 | C38: =OCP_D*(preF_FD + F_primary/OCP_D)/(preF_FD + F_primary/B38) | D38: =OCP_E*(preF_FD + F_primary/OCP_E)/(preF_FD + F_primary/B38) | E38: =D_sh*(OCP_D/C38 - 1) | F38: =E_sh*(OCP_E/D38 - 1) | G38: =(preF_FD + E38 + F38 - preF_opts + J37 + K37 + F_primary/B38)/(1-B30) | H38: =MAX(0, B30*G38 - preF_opts) | I38: =preF_FD + E38 + F38 + H38 | J38: =NA_P/MIN(NA_cap/(I38+K37), (1-NA_disc)*B38) | K38: =NB_P/MIN(NB_cap/(I38+J38), (1-NB_disc)*B38) | L38: =F_primary/B38 | M38: =I38+J38+K38 | N38: =D30/M38 | O38: =IF(Y37*L38 > F_primary, 1, 0) | P38: =IF(Y37*(E_sh + F38) > E_inv, 1, 0) | Q38: =IF(Y37*(D_sh + E38) > D_inv, 1, 0) | R38: =IF(Y37*C_sh > C_inv, 1, 0) | S38: =IF(Y37*B_sh > B_inv, 1, 0) | T38: =IF(Y37*A_sh > A_inv, 1, 0) | U38: =IF(Y37*seed_sh > seed_inv, 1, 0) | V38: =(1-O38)*F_primary+(1-P38)*E_inv+(1-Q38)*D_inv+(1-R38)*C_inv+(1-S38)*B_inv+(1-T38)*A_inv+(1-U38)*seed_inv | W38: =MAX(0, sens_exit - V38) | X38: =F1_sh+F2_sh+F3_sh+RSA_sh+J38+K38+O38*L38+P38*(E_sh + F38)+Q38*(D_sh + E38)+R38*C_sh+S38*B_sh+T38*A_sh+U38*seed_sh | Y38: =(W38 + preF_opts_iss*opt_strike)/(X38 + preF_opts_iss)
B39: =N38 | C39: =OCP_D*(preF_FD + F_primary/OCP_D)/(preF_FD + F_primary/B39) | D39: =OCP_E*(preF_FD + F_primary/OCP_E)/(preF_FD + F_primary/B39) | E39: =D_sh*(OCP_D/C39 - 1) | F39: =E_sh*(OCP_E/D39 - 1) | G39: =(preF_FD + E39 + F39 - preF_opts + J38 + K38 + F_primary/B39)/(1-B30) | H39: =MAX(0, B30*G39 - preF_opts) | I39: =preF_FD + E39 + F39 + H39 | J39: =NA_P/MIN(NA_cap/(I39+K38), (1-NA_disc)*B39) | K39: =NB_P/MIN(NB_cap/(I39+J39), (1-NB_disc)*B39) | L39: =F_primary/B39 | M39: =I39+J39+K39 | N39: =D30/M39 | O39: =IF(Y38*L39 > F_primary, 1, 0) | P39: =IF(Y38*(E_sh + F39) > E_inv, 1, 0) | Q39: =IF(Y38*(D_sh + E39) > D_inv, 1, 0) | R39: =IF(Y38*C_sh > C_inv, 1, 0) | S39: =IF(Y38*B_sh > B_inv, 1, 0) | T39: =IF(Y38*A_sh > A_inv, 1, 0) | U39: =IF(Y38*seed_sh > seed_inv, 1, 0) | V39: =(1-O39)*F_primary+(1-P39)*E_inv+(1-Q39)*D_inv+(1-R39)*C_inv+(1-S39)*B_inv+(1-T39)*A_inv+(1-U39)*seed_inv | W39: =MAX(0, sens_exit - V39) | X39: =F1_sh+F2_sh+F3_sh+RSA_sh+J39+K39+O39*L39+P39*(E_sh + F39)+Q39*(D_sh + E39)+R39*C_sh+S39*B_sh+T39*A_sh+U39*seed_sh | Y39: =(W39 + preF_opts_iss*opt_strike)/(X39 + preF_opts_iss)
B40: =N39 | C40: =OCP_D*(preF_FD + F_primary/OCP_D)/(preF_FD + F_primary/B40) | D40: =OCP_E*(preF_FD + F_primary/OCP_E)/(preF_FD + F_primary/B40) | E40: =D_sh*(OCP_D/C40 - 1) | F40: =E_sh*(OCP_E/D40 - 1) | G40: =(preF_FD + E40 + F40 - preF_opts + J39 + K39 + F_primary/B40)/(1-B30) | H40: =MAX(0, B30*G40 - preF_opts) | I40: =preF_FD + E40 + F40 + H40 | J40: =NA_P/MIN(NA_cap/(I40+K39), (1-NA_disc)*B40) | K40: =NB_P/MIN(NB_cap/(I40+J40), (1-NB_disc)*B40) | L40: =F_primary/B40 | M40: =I40+J40+K40 | N40: =D30/M40 | O40: =IF(Y39*L40 > F_primary, 1, 0) | P40: =IF(Y39*(E_sh + F40) > E_inv, 1, 0) | Q40: =IF(Y39*(D_sh + E40) > D_inv, 1, 0) | R40: =IF(Y39*C_sh > C_inv, 1, 0) | S40: =IF(Y39*B_sh > B_inv, 1, 0) | T40: =IF(Y39*A_sh > A_inv, 1, 0) | U40: =IF(Y39*seed_sh > seed_inv, 1, 0) | V40: =(1-O40)*F_primary+(1-P40)*E_inv+(1-Q40)*D_inv+(1-R40)*C_inv+(1-S40)*B_inv+(1-T40)*A_inv+(1-U40)*seed_inv | W40: =MAX(0, sens_exit - V40) | X40: =F1_sh+F2_sh+F3_sh+RSA_sh+J40+K40+O40*L40+P40*(E_sh + F40)+Q40*(D_sh + E40)+R40*C_sh+S40*B_sh+T40*A_sh+U40*seed_sh | Y40: =(W40 + preF_opts_iss*opt_strike)/(X40 + preF_opts_iss)
B41: =N40 | C41: =OCP_D*(preF_FD + F_primary/OCP_D)/(preF_FD + F_primary/B41) | D41: =OCP_E*(preF_FD + F_primary/OCP_E)/(preF_FD + F_primary/B41) | E41: =D_sh*(OCP_D/C41 - 1) | F41: =E_sh*(OCP_E/D41 - 1) | G41: =(preF_FD + E41 + F41 - preF_opts + J40 + K40 + F_primary/B41)/(1-B30) | H41: =MAX(0, B30*G41 - preF_opts) | I41: =preF_FD + E41 + F41 + H41 | J41: =NA_P/MIN(NA_cap/(I41+K40), (1-NA_disc)*B41) | K41: =NB_P/MIN(NB_cap/(I41+J41), (1-NB_disc)*B41) | L41: =F_primary/B41 | M41: =I41+J41+K41 | N41: =D30/M41 | O41: =IF(Y40*L41 > F_primary, 1, 0) | P41: =IF(Y40*(E_sh + F41) > E_inv, 1, 0) | Q41: =IF(Y40*(D_sh + E41) > D_inv, 1, 0) | R41: =IF(Y40*C_sh > C_inv, 1, 0) | S41: =IF(Y40*B_sh > B_inv, 1, 0) | T41: =IF(Y40*A_sh > A_inv, 1, 0) | U41: =IF(Y40*seed_sh > seed_inv, 1, 0) | V41: =(1-O41)*F_primary+(1-P41)*E_inv+(1-Q41)*D_inv+(1-R41)*C_inv+(1-S41)*B_inv+(1-T41)*A_inv+(1-U41)*seed_inv | W41: =MAX(0, sens_exit - V41) | X41: =F1_sh+F2_sh+F3_sh+RSA_sh+J41+K41+O41*L41+P41*(E_sh + F41)+Q41*(D_sh + E41)+R41*C_sh+S41*B_sh+T41*A_sh+U41*seed_sh | Y41: =(W41 + preF_opts_iss*opt_strike)/(X41 + preF_opts_iss)
B42: =N41 | C42: =OCP_D*(preF_FD + F_primary/OCP_D)/(preF_FD + F_primary/B42) | D42: =OCP_E*(preF_FD + F_primary/OCP_E)/(preF_FD + F_primary/B42) | E42: =D_sh*(OCP_D/C42 - 1) | F42: =E_sh*(OCP_E/D42 - 1) | G42: =(preF_FD + E42 + F42 - preF_opts + J41 + K41 + F_primary/B42)/(1-B30) | H42: =MAX(0, B30*G42 - preF_opts) | I42: =preF_FD + E42 + F42 + H42 | J42: =NA_P/MIN(NA_cap/(I42+K41), (1-NA_disc)*B42) | K42: =NB_P/MIN(NB_cap/(I42+J42), (1-NB_disc)*B42) | L42: =F_primary/B42 | M42: =I42+J42+K42 | N42: =D30/M42 | O42: =IF(Y41*L42 > F_primary, 1, 0) | P42: =IF(Y41*(E_sh + F42) > E_inv, 1, 0) | Q42: =IF(Y41*(D_sh + E42) > D_inv, 1, 0) | R42: =IF(Y41*C_sh > C_inv, 1, 0) | S42: =IF(Y41*B_sh > B_inv, 1, 0) | T42: =IF(Y41*A_sh > A_inv, 1, 0) | U42: =IF(Y41*seed_sh > seed_inv, 1, 0) | V42: =(1-O42)*F_primary+(1-P42)*E_inv+(1-Q42)*D_inv+(1-R42)*C_inv+(1-S42)*B_inv+(1-T42)*A_inv+(1-U42)*seed_inv | W42: =MAX(0, sens_exit - V42) | X42: =F1_sh+F2_sh+F3_sh+RSA_sh+J42+K42+O42*L42+P42*(E_sh + F42)+Q42*(D_sh + E42)+R42*C_sh+S42*B_sh+T42*A_sh+U42*seed_sh | Y42: =(W42 + preF_opts_iss*opt_strike)/(X42 + preF_opts_iss)
B43: =N42 | C43: =OCP_D*(preF_FD + F_primary/OCP_D)/(preF_FD + F_primary/B43) | D43: =OCP_E*(preF_FD + F_primary/OCP_E)/(preF_FD + F_primary/B43) | E43: =D_sh*(OCP_D/C43 - 1) | F43: =E_sh*(OCP_E/D43 - 1) | G43: =(preF_FD + E43 + F43 - preF_opts + J42 + K42 + F_primary/B43)/(1-B30) | H43: =MAX(0, B30*G43 - preF_opts) | I43: =preF_FD + E43 + F43 + H43 | J43: =NA_P/MIN(NA_cap/(I43+K42), (1-NA_disc)*B43) | K43: =NB_P/MIN(NB_cap/(I43+J43), (1-NB_disc)*B43) | L43: =F_primary/B43 | M43: =I43+J43+K43 | N43: =D30/M43 | O43: =IF(Y42*L43 > F_primary, 1, 0) | P43: =IF(Y42*(E_sh + F43) > E_inv, 1, 0) | Q43: =IF(Y42*(D_sh + E43) > D_inv, 1, 0) | R43: =IF(Y42*C_sh > C_inv, 1, 0) | S43: =IF(Y42*B_sh > B_inv, 1, 0) | T43: =IF(Y42*A_sh > A_inv, 1, 0) | U43: =IF(Y42*seed_sh > seed_inv, 1, 0) | V43: =(1-O43)*F_primary+(1-P43)*E_inv+(1-Q43)*D_inv+(1-R43)*C_inv+(1-S43)*B_inv+(1-T43)*A_inv+(1-U43)*seed_inv | W43: =MAX(0, sens_exit - V43) | X43: =F1_sh+F2_sh+F3_sh+RSA_sh+J43+K43+O43*L43+P43*(E_sh + F43)+Q43*(D_sh + E43)+R43*C_sh+S43*B_sh+T43*A_sh+U43*seed_sh | Y43: =(W43 + preF_opts_iss*opt_strike)/(X43 + preF_opts_iss)
B44: =N43 | C44: =OCP_D*(preF_FD + F_primary/OCP_D)/(preF_FD + F_primary/B44) | D44: =OCP_E*(preF_FD + F_primary/OCP_E)/(preF_FD + F_primary/B44) | E44: =D_sh*(OCP_D/C44 - 1) | F44: =E_sh*(OCP_E/D44 - 1) | G44: =(preF_FD + E44 + F44 - preF_opts + J43 + K43 + F_primary/B44)/(1-B30) | H44: =MAX(0, B30*G44 - preF_opts) | I44: =preF_FD + E44 + F44 + H44 | J44: =NA_P/MIN(NA_cap/(I44+K43), (1-NA_disc)*B44) | K44: =NB_P/MIN(NB_cap/(I44+J44), (1-NB_disc)*B44) | L44: =F_primary/B44 | M44: =I44+J44+K44 | N44: =D30/M44 | O44: =IF(Y43*L44 > F_primary, 1, 0) | P44: =IF(Y43*(E_sh + F44) > E_inv, 1, 0) | Q44: =IF(Y43*(D_sh + E44) > D_inv, 1, 0) | R44: =IF(Y43*C_sh > C_inv, 1, 0) | S44: =IF(Y43*B_sh > B_inv, 1, 0) | T44: =IF(Y43*A_sh > A_inv, 1, 0) | U44: =IF(Y43*seed_sh > seed_inv, 1, 0) | V44: =(1-O44)*F_primary+(1-P44)*E_inv+(1-Q44)*D_inv+(1-R44)*C_inv+(1-S44)*B_inv+(1-T44)*A_inv+(1-U44)*seed_inv | W44: =MAX(0, sens_exit - V44) | X44: =F1_sh+F2_sh+F3_sh+RSA_sh+J44+K44+O44*L44+P44*(E_sh + F44)+Q44*(D_sh + E44)+R44*C_sh+S44*B_sh+T44*A_sh+U44*seed_sh | Y44: =(W44 + preF_opts_iss*opt_strike)/(X44 + preF_opts_iss)
B45: =N44 | C45: =OCP_D*(preF_FD + F_primary/OCP_D)/(preF_FD + F_primary/B45) | D45: =OCP_E*(preF_FD + F_primary/OCP_E)/(preF_FD + F_primary/B45) | E45: =D_sh*(OCP_D/C45 - 1) | F45: =E_sh*(OCP_E/D45 - 1) | G45: =(preF_FD + E45 + F45 - preF_opts + J44 + K44 + F_primary/B45)/(1-B30) | H45: =MAX(0, B30*G45 - preF_opts) | I45: =preF_FD + E45 + F45 + H45 | J45: =NA_P/MIN(NA_cap/(I45+K44), (1-NA_disc)*B45) | K45: =NB_P/MIN(NB_cap/(I45+J45), (1-NB_disc)*B45) | L45: =F_primary/B45 | M45: =I45+J45+K45 | N45: =D30/M45 | O45: =IF(Y44*L45 > F_primary, 1, 0) | P45: =IF(Y44*(E_sh + F45) > E_inv, 1, 0) | Q45: =IF(Y44*(D_sh + E45) > D_inv, 1, 0) | R45: =IF(Y44*C_sh > C_inv, 1, 0) | S45: =IF(Y44*B_sh > B_inv, 1, 0) | T45: =IF(Y44*A_sh > A_inv, 1, 0) | U45: =IF(Y44*seed_sh > seed_inv, 1, 0) | V45: =(1-O45)*F_primary+(1-P45)*E_inv+(1-Q45)*D_inv+(1-R45)*C_inv+(1-S45)*B_inv+(1-T45)*A_inv+(1-U45)*seed_inv | W45: =MAX(0, sens_exit - V45) | X45: =F1_sh+F2_sh+F3_sh+RSA_sh+J45+K45+O45*L45+P45*(E_sh + F45)+Q45*(D_sh + E45)+R45*C_sh+S45*B_sh+T45*A_sh+U45*seed_sh | Y45: =(W45 + preF_opts_iss*opt_strike)/(X45 + preF_opts_iss)
B46: =N45 | C46: =OCP_D*(preF_FD + F_primary/OCP_D)/(preF_FD + F_primary/B46) | D46: =OCP_E*(preF_FD + F_primary/OCP_E)/(preF_FD + F_primary/B46) | E46: =D_sh*(OCP_D/C46 - 1) | F46: =E_sh*(OCP_E/D46 - 1) | G46: =(preF_FD + E46 + F46 - preF_opts + J45 + K45 + F_primary/B46)/(1-B30) | H46: =MAX(0, B30*G46 - preF_opts) | I46: =preF_FD + E46 + F46 + H46 | J46: =NA_P/MIN(NA_cap/(I46+K45), (1-NA_disc)*B46) | K46: =NB_P/MIN(NB_cap/(I46+J46), (1-NB_disc)*B46) | L46: =F_primary/B46 | M46: =I46+J46+K46 | N46: =D30/M46 | O46: =IF(Y45*L46 > F_primary, 1, 0) | P46: =IF(Y45*(E_sh + F46) > E_inv, 1, 0) | Q46: =IF(Y45*(D_sh + E46) > D_inv, 1, 0) | R46: =IF(Y45*C_sh > C_inv, 1, 0) | S46: =IF(Y45*B_sh > B_inv, 1, 0) | T46: =IF(Y45*A_sh > A_inv, 1, 0) | U46: =IF(Y45*seed_sh > seed_inv, 1, 0) | V46: =(1-O46)*F_primary+(1-P46)*E_inv+(1-Q46)*D_inv+(1-R46)*C_inv+(1-S46)*B_inv+(1-T46)*A_inv+(1-U46)*seed_inv | W46: =MAX(0, sens_exit - V46) | X46: =F1_sh+F2_sh+F3_sh+RSA_sh+J46+K46+O46*L46+P46*(E_sh + F46)+Q46*(D_sh + E46)+R46*C_sh+S46*B_sh+T46*A_sh+U46*seed_sh | Y46: =(W46 + preF_opts_iss*opt_strike)/(X46 + preF_opts_iss)
B47: =N46 | C47: =OCP_D*(preF_FD + F_primary/OCP_D)/(preF_FD + F_primary/B47) | D47: =OCP_E*(preF_FD + F_primary/OCP_E)/(preF_FD + F_primary/B47) | E47: =D_sh*(OCP_D/C47 - 1) | F47: =E_sh*(OCP_E/D47 - 1) | G47: =(preF_FD + E47 + F47 - preF_opts + J46 + K46 + F_primary/B47)/(1-B30) | H47: =MAX(0, B30*G47 - preF_opts) | I47: =preF_FD + E47 + F47 + H47 | J47: =NA_P/MIN(NA_cap/(I47+K46), (1-NA_disc)*B47) | K47: =NB_P/MIN(NB_cap/(I47+J47), (1-NB_disc)*B47) | L47: =F_primary/B47 | M47: =I47+J47+K47 | N47: =D30/M47 | O47: =IF(Y46*L47 > F_primary, 1, 0) | P47: =IF(Y46*(E_sh + F47) > E_inv, 1, 0) | Q47: =IF(Y46*(D_sh + E47) > D_inv, 1, 0) | R47: =IF(Y46*C_sh > C_inv, 1, 0) | S47: =IF(Y46*B_sh > B_inv, 1, 0) | T47: =IF(Y46*A_sh > A_inv, 1, 0) | U47: =IF(Y46*seed_sh > seed_inv, 1, 0) | V47: =(1-O47)*F_primary+(1-P47)*E_inv+(1-Q47)*D_inv+(1-R47)*C_inv+(1-S47)*B_inv+(1-T47)*A_inv+(1-U47)*seed_inv | W47: =MAX(0, sens_exit - V47) | X47: =F1_sh+F2_sh+F3_sh+RSA_sh+J47+K47+O47*L47+P47*(E_sh + F47)+Q47*(D_sh + E47)+R47*C_sh+S47*B_sh+T47*A_sh+U47*seed_sh | Y47: =(W47 + preF_opts_iss*opt_strike)/(X47 + preF_opts_iss)
B48: =N47 | C48: =OCP_D*(preF_FD + F_primary/OCP_D)/(preF_FD + F_primary/B48) | D48: =OCP_E*(preF_FD + F_primary/OCP_E)/(preF_FD + F_primary/B48) | E48: =D_sh*(OCP_D/C48 - 1) | F48: =E_sh*(OCP_E/D48 - 1) | G48: =(preF_FD + E48 + F48 - preF_opts + J47 + K47 + F_primary/B48)/(1-B30) | H48: =MAX(0, B30*G48 - preF_opts) | I48: =preF_FD + E48 + F48 + H48 | J48: =NA_P/MIN(NA_cap/(I48+K47), (1-NA_disc)*B48) | K48: =NB_P/MIN(NB_cap/(I48+J48), (1-NB_disc)*B48) | L48: =F_primary/B48 | M48: =I48+J48+K48 | N48: =D30/M48 | O48: =IF(Y47*L48 > F_primary, 1, 0) | P48: =IF(Y47*(E_sh + F48) > E_inv, 1, 0) | Q48: =IF(Y47*(D_sh + E48) > D_inv, 1, 0) | R48: =IF(Y47*C_sh > C_inv, 1, 0) | S48: =IF(Y47*B_sh > B_inv, 1, 0) | T48: =IF(Y47*A_sh > A_inv, 1, 0) | U48: =IF(Y47*seed_sh > seed_inv, 1, 0) | V48: =(1-O48)*F_primary+(1-P48)*E_inv+(1-Q48)*D_inv+(1-R48)*C_inv+(1-S48)*B_inv+(1-T48)*A_inv+(1-U48)*seed_inv | W48: =MAX(0, sens_exit - V48) | X48: =F1_sh+F2_sh+F3_sh+RSA_sh+J48+K48+O48*L48+P48*(E_sh + F48)+Q48*(D_sh + E48)+R48*C_sh+S48*B_sh+T48*A_sh+U48*seed_sh | Y48: =(W48 + preF_opts_iss*opt_strike)/(X48 + preF_opts_iss)
B49: =N48 | C49: =OCP_D*(preF_FD + F_primary/OCP_D)/(preF_FD + F_primary/B49) | D49: =OCP_E*(preF_FD + F_primary/OCP_E)/(preF_FD + F_primary/B49) | E49: =D_sh*(OCP_D/C49 - 1) | F49: =E_sh*(OCP_E/D49 - 1) | G49: =(preF_FD + E49 + F49 - preF_opts + J48 + K48 + F_primary/B49)/(1-B30) | H49: =MAX(0, B30*G49 - preF_opts) | I49: =preF_FD + E49 + F49 + H49 | J49: =NA_P/MIN(NA_cap/(I49+K48), (1-NA_disc)*B49) | K49: =NB_P/MIN(NB_cap/(I49+J49), (1-NB_disc)*B49) | L49: =F_primary/B49 | M49: =I49+J49+K49 | N49: =D30/M49 | O49: =IF(Y48*L49 > F_primary, 1, 0) | P49: =IF(Y48*(E_sh + F49) > E_inv, 1, 0) | Q49: =IF(Y48*(D_sh + E49) > D_inv, 1, 0) | R49: =IF(Y48*C_sh > C_inv, 1, 0) | S49: =IF(Y48*B_sh > B_inv, 1, 0) | T49: =IF(Y48*A_sh > A_inv, 1, 0) | U49: =IF(Y48*seed_sh > seed_inv, 1, 0) | V49: =(1-O49)*F_primary+(1-P49)*E_inv+(1-Q49)*D_inv+(1-R49)*C_inv+(1-S49)*B_inv+(1-T49)*A_inv+(1-U49)*seed_inv | W49: =MAX(0, sens_exit - V49) | X49: =F1_sh+F2_sh+F3_sh+RSA_sh+J49+K49+O49*L49+P49*(E_sh + F49)+Q49*(D_sh + E49)+R49*C_sh+S49*B_sh+T49*A_sh+U49*seed_sh | Y49: =(W49 + preF_opts_iss*opt_strike)/(X49 + preF_opts_iss)
B50: =N49 | C50: =OCP_D*(preF_FD + F_primary/OCP_D)/(preF_FD + F_primary/B50) | D50: =OCP_E*(preF_FD + F_primary/OCP_E)/(preF_FD + F_primary/B50) | E50: =D_sh*(OCP_D/C50 - 1) | F50: =E_sh*(OCP_E/D50 - 1) | G50: =(preF_FD + E50 + F50 - preF_opts + J49 + K49 + F_primary/B50)/(1-B30) | H50: =MAX(0, B30*G50 - preF_opts) | I50: =preF_FD + E50 + F50 + H50 | J50: =NA_P/MIN(NA_cap/(I50+K49), (1-NA_disc)*B50) | K50: =NB_P/MIN(NB_cap/(I50+J50), (1-NB_disc)*B50) | L50: =F_primary/B50 | M50: =I50+J50+K50 | N50: =D30/M50 | O50: =IF(Y49*L50 > F_primary, 1, 0) | P50: =IF(Y49*(E_sh + F50) > E_inv, 1, 0) | Q50: =IF(Y49*(D_sh + E50) > D_inv, 1, 0) | R50: =IF(Y49*C_sh > C_inv, 1, 0) | S50: =IF(Y49*B_sh > B_inv, 1, 0) | T50: =IF(Y49*A_sh > A_inv, 1, 0) | U50: =IF(Y49*seed_sh > seed_inv, 1, 0) | V50: =(1-O50)*F_primary+(1-P50)*E_inv+(1-Q50)*D_inv+(1-R50)*C_inv+(1-S50)*B_inv+(1-T50)*A_inv+(1-U50)*seed_inv | W50: =MAX(0, sens_exit - V50) | X50: =F1_sh+F2_sh+F3_sh+RSA_sh+J50+K50+O50*L50+P50*(E_sh + F50)+Q50*(D_sh + E50)+R50*C_sh+S50*B_sh+T50*A_sh+U50*seed_sh | Y50: =(W50 + preF_opts_iss*opt_strike)/(X50 + preF_opts_iss)
B51: =N50 | C51: =OCP_D*(preF_FD + F_primary/OCP_D)/(preF_FD + F_primary/B51) | D51: =OCP_E*(preF_FD + F_primary/OCP_E)/(preF_FD + F_primary/B51) | E51: =D_sh*(OCP_D/C51 - 1) | F51: =E_sh*(OCP_E/D51 - 1) | G51: =(preF_FD + E51 + F51 - preF_opts + J50 + K50 + F_primary/B51)/(1-B30) | H51: =MAX(0, B30*G51 - preF_opts) | I51: =preF_FD + E51 + F51 + H51 | J51: =NA_P/MIN(NA_cap/(I51+K50), (1-NA_disc)*B51) | K51: =NB_P/MIN(NB_cap/(I51+J51), (1-NB_disc)*B51) | L51: =F_primary/B51 | M51: =I51+J51+K51 | N51: =D30/M51 | O51: =IF(Y50*L51 > F_primary, 1, 0) | P51: =IF(Y50*(E_sh + F51) > E_inv, 1, 0) | Q51: =IF(Y50*(D_sh + E51) > D_inv, 1, 0) | R51: =IF(Y50*C_sh > C_inv, 1, 0) | S51: =IF(Y50*B_sh > B_inv, 1, 0) | T51: =IF(Y50*A_sh > A_inv, 1, 0) | U51: =IF(Y50*seed_sh > seed_inv, 1, 0) | V51: =(1-O51)*F_primary+(1-P51)*E_inv+(1-Q51)*D_inv+(1-R51)*C_inv+(1-S51)*B_inv+(1-T51)*A_inv+(1-U51)*seed_inv | W51: =MAX(0, sens_exit - V51) | X51: =F1_sh+F2_sh+F3_sh+RSA_sh+J51+K51+O51*L51+P51*(E_sh + F51)+Q51*(D_sh + E51)+R51*C_sh+S51*B_sh+T51*A_sh+U51*seed_sh | Y51: =(W51 + preF_opts_iss*opt_strike)/(X51 + preF_opts_iss)
B52: =N51 | C52: =OCP_D*(preF_FD + F_primary/OCP_D)/(preF_FD + F_primary/B52) | D52: =OCP_E*(preF_FD + F_primary/OCP_E)/(preF_FD + F_primary/B52) | E52: =D_sh*(OCP_D/C52 - 1) | F52: =E_sh*(OCP_E/D52 - 1) | G52: =(preF_FD + E52 + F52 - preF_opts + J51 + K51 + F_primary/B52)/(1-B30) | H52: =MAX(0, B30*G52 - preF_opts) | I52: =preF_FD + E52 + F52 + H52 | J52: =NA_P/MIN(NA_cap/(I52+K51), (1-NA_disc)*B52) | K52: =NB_P/MIN(NB_cap/(I52+J52), (1-NB_disc)*B52) | L52: =F_primary/B52 | M52: =I52+J52+K52 | N52: =D30/M52 | O52: =IF(Y51*L52 > F_primary, 1, 0) | P52: =IF(Y51*(E_sh + F52) > E_inv, 1, 0) | Q52: =IF(Y51*(D_sh + E52) > D_inv, 1, 0) | R52: =IF(Y51*C_sh > C_inv, 1, 0) | S52: =IF(Y51*B_sh > B_inv, 1, 0) | T52: =IF(Y51*A_sh > A_inv, 1, 0) | U52: =IF(Y51*seed_sh > seed_inv, 1, 0) | V52: =(1-O52)*F_primary+(1-P52)*E_inv+(1-Q52)*D_inv+(1-R52)*C_inv+(1-S52)*B_inv+(1-T52)*A_inv+(1-U52)*seed_inv | W52: =MAX(0, sens_exit - V52) | X52: =F1_sh+F2_sh+F3_sh+RSA_sh+J52+K52+O52*L52+P52*(E_sh + F52)+Q52*(D_sh + E52)+R52*C_sh+S52*B_sh+T52*A_sh+U52*seed_sh | Y52: =(W52 + preF_opts_iss*opt_strike)/(X52 + preF_opts_iss)
B53: =N52 | C53: =OCP_D*(preF_FD + F_primary/OCP_D)/(preF_FD + F_primary/B53) | D53: =OCP_E*(preF_FD + F_primary/OCP_E)/(preF_FD + F_primary/B53) | E53: =D_sh*(OCP_D/C53 - 1) | F53: =E_sh*(OCP_E/D53 - 1) | G53: =(preF_FD + E53 + F53 - preF_opts + J52 + K52 + F_primary/B53)/(1-B30) | H53: =MAX(0, B30*G53 - preF_opts) | I53: =preF_FD + E53 + F53 + H53 | J53: =NA_P/MIN(NA_cap/(I53+K52), (1-NA_disc)*B53) | K53: =NB_P/MIN(NB_cap/(I53+J53), (1-NB_disc)*B53) | L53: =F_primary/B53 | M53: =I53+J53+K53 | N53: =D30/M53 | O53: =IF(Y52*L53 > F_primary, 1, 0) | P53: =IF(Y52*(E_sh + F53) > E_inv, 1, 0) | Q53: =IF(Y52*(D_sh + E53) > D_inv, 1, 0) | R53: =IF(Y52*C_sh > C_inv, 1, 0) | S53: =IF(Y52*B_sh > B_inv, 1, 0) | T53: =IF(Y52*A_sh > A_inv, 1, 0) | U53: =IF(Y52*seed_sh > seed_inv, 1, 0) | V53: =(1-O53)*F_primary+(1-P53)*E_inv+(1-Q53)*D_inv+(1-R53)*C_inv+(1-S53)*B_inv+(1-T53)*A_inv+(1-U53)*seed_inv | W53: =MAX(0, sens_exit - V53) | X53: =F1_sh+F2_sh+F3_sh+RSA_sh+J53+K53+O53*L53+P53*(E_sh + F53)+Q53*(D_sh + E53)+R53*C_sh+S53*B_sh+T53*A_sh+U53*seed_sh | Y53: =(W53 + preF_opts_iss*opt_strike)/(X53 + preF_opts_iss)
B54: =N53 | C54: =OCP_D*(preF_FD + F_primary/OCP_D)/(preF_FD + F_primary/B54) | D54: =OCP_E*(preF_FD + F_primary/OCP_E)/(preF_FD + F_primary/B54) | E54: =D_sh*(OCP_D/C54 - 1) | F54: =E_sh*(OCP_E/D54 - 1) | G54: =(preF_FD + E54 + F54 - preF_opts + J53 + K53 + F_primary/B54)/(1-B30) | H54: =MAX(0, B30*G54 - preF_opts) | I54: =preF_FD + E54 + F54 + H54 | J54: =NA_P/MIN(NA_cap/(I54+K53), (1-NA_disc)*B54) | K54: =NB_P/MIN(NB_cap/(I54+J54), (1-NB_disc)*B54) | L54: =F_primary/B54 | M54: =I54+J54+K54 | N54: =D30/M54 | O54: =IF(Y53*L54 > F_primary, 1, 0) | P54: =IF(Y53*(E_sh + F54) > E_inv, 1, 0) | Q54: =IF(Y53*(D_sh + E54) > D_inv, 1, 0) | R54: =IF(Y53*C_sh > C_inv, 1, 0) | S54: =IF(Y53*B_sh > B_inv, 1, 0) | T54: =IF(Y53*A_sh > A_inv, 1, 0) | U54: =IF(Y53*seed_sh > seed_inv, 1, 0) | V54: =(1-O54)*F_primary+(1-P54)*E_inv+(1-Q54)*D_inv+(1-R54)*C_inv+(1-S54)*B_inv+(1-T54)*A_inv+(1-U54)*seed_inv | W54: =MAX(0, sens_exit - V54) | X54: =F1_sh+F2_sh+F3_sh+RSA_sh+J54+K54+O54*L54+P54*(E_sh + F54)+Q54*(D_sh + E54)+R54*C_sh+S54*B_sh+T54*A_sh+U54*seed_sh | Y54: =(W54 + preF_opts_iss*opt_strike)/(X54 + preF_opts_iss)
B55: =N54 | C55: =OCP_D*(preF_FD + F_primary/OCP_D)/(preF_FD + F_primary/B55) | D55: =OCP_E*(preF_FD + F_primary/OCP_E)/(preF_FD + F_primary/B55) | E55: =D_sh*(OCP_D/C55 - 1) | F55: =E_sh*(OCP_E/D55 - 1) | G55: =(preF_FD + E55 + F55 - preF_opts + J54 + K54 + F_primary/B55)/(1-B30) | H55: =MAX(0, B30*G55 - preF_opts) | I55: =preF_FD + E55 + F55 + H55 | J55: =NA_P/MIN(NA_cap/(I55+K54), (1-NA_disc)*B55) | K55: =NB_P/MIN(NB_cap/(I55+J55), (1-NB_disc)*B55) | L55: =F_primary/B55 | M55: =I55+J55+K55 | N55: =D30/M55 | O55: =IF(Y54*L55 > F_primary, 1, 0) | P55: =IF(Y54*(E_sh + F55) > E_inv, 1, 0) | Q55: =IF(Y54*(D_sh + E55) > D_inv, 1, 0) | R55: =IF(Y54*C_sh > C_inv, 1, 0) | S55: =IF(Y54*B_sh > B_inv, 1, 0) | T55: =IF(Y54*A_sh > A_inv, 1, 0) | U55: =IF(Y54*seed_sh > seed_inv, 1, 0) | V55: =(1-O55)*F_primary+(1-P55)*E_inv+(1-Q55)*D_inv+(1-R55)*C_inv+(1-S55)*B_inv+(1-T55)*A_inv+(1-U55)*seed_inv | W55: =MAX(0, sens_exit - V55) | X55: =F1_sh+F2_sh+F3_sh+RSA_sh+J55+K55+O55*L55+P55*(E_sh + F55)+Q55*(D_sh + E55)+R55*C_sh+S55*B_sh+T55*A_sh+U55*seed_sh | Y55: =(W55 + preF_opts_iss*opt_strike)/(X55 + preF_opts_iss)
B56: =N55 | C56: =OCP_D*(preF_FD + F_primary/OCP_D)/(preF_FD + F_primary/B56) | D56: =OCP_E*(preF_FD + F_primary/OCP_E)/(preF_FD + F_primary/B56) | E56: =D_sh*(OCP_D/C56 - 1) | F56: =E_sh*(OCP_E/D56 - 1) | G56: =(preF_FD + E56 + F56 - preF_opts + J55 + K55 + F_primary/B56)/(1-B30) | H56: =MAX(0, B30*G56 - preF_opts) | I56: =preF_FD + E56 + F56 + H56 | J56: =NA_P/MIN(NA_cap/(I56+K55), (1-NA_disc)*B56) | K56: =NB_P/MIN(NB_cap/(I56+J56), (1-NB_disc)*B56) | L56: =F_primary/B56 | M56: =I56+J56+K56 | N56: =D30/M56 | O56: =IF(Y55*L56 > F_primary, 1, 0) | P56: =IF(Y55*(E_sh + F56) > E_inv, 1, 0) | Q56: =IF(Y55*(D_sh + E56) > D_inv, 1, 0) | R56: =IF(Y55*C_sh > C_inv, 1, 0) | S56: =IF(Y55*B_sh > B_inv, 1, 0) | T56: =IF(Y55*A_sh > A_inv, 1, 0) | U56: =IF(Y55*seed_sh > seed_inv, 1, 0) | V56: =(1-O56)*F_primary+(1-P56)*E_inv+(1-Q56)*D_inv+(1-R56)*C_inv+(1-S56)*B_inv+(1-T56)*A_inv+(1-U56)*seed_inv | W56: =MAX(0, sens_exit - V56) | X56: =F1_sh+F2_sh+F3_sh+RSA_sh+J56+K56+O56*L56+P56*(E_sh + F56)+Q56*(D_sh + E56)+R56*C_sh+S56*B_sh+T56*A_sh+U56*seed_sh | Y56: =(W56 + preF_opts_iss*opt_strike)/(X56 + preF_opts_iss)
B57: =N56 | C57: =OCP_D*(preF_FD + F_primary/OCP_D)/(preF_FD + F_primary/B57) | D57: =OCP_E*(preF_FD + F_primary/OCP_E)/(preF_FD + F_primary/B57) | E57: =D_sh*(OCP_D/C57 - 1) | F57: =E_sh*(OCP_E/D57 - 1) | G57: =(preF_FD + E57 + F57 - preF_opts + J56 + K56 + F_primary/B57)/(1-B30) | H57: =MAX(0, B30*G57 - preF_opts) | I57: =preF_FD + E57 + F57 + H57 | J57: =NA_P/MIN(NA_cap/(I57+K56), (1-NA_disc)*B57) | K57: =NB_P/MIN(NB_cap/(I57+J57), (1-NB_disc)*B57) | L57: =F_primary/B57 | M57: =I57+J57+K57 | N57: =D30/M57 | O57: =IF(Y56*L57 > F_primary, 1, 0) | P57: =IF(Y56*(E_sh + F57) > E_inv, 1, 0) | Q57: =IF(Y56*(D_sh + E57) > D_inv, 1, 0) | R57: =IF(Y56*C_sh > C_inv, 1, 0) | S57: =IF(Y56*B_sh > B_inv, 1, 0) | T57: =IF(Y56*A_sh > A_inv, 1, 0) | U57: =IF(Y56*seed_sh > seed_inv, 1, 0) | V57: =(1-O57)*F_primary+(1-P57)*E_inv+(1-Q57)*D_inv+(1-R57)*C_inv+(1-S57)*B_inv+(1-T57)*A_inv+(1-U57)*seed_inv | W57: =MAX(0, sens_exit - V57) | X57: =F1_sh+F2_sh+F3_sh+RSA_sh+J57+K57+O57*L57+P57*(E_sh + F57)+Q57*(D_sh + E57)+R57*C_sh+S57*B_sh+T57*A_sh+U57*seed_sh | Y57: =(W57 + preF_opts_iss*opt_strike)/(X57 + preF_opts_iss)
B58: =N57 | C58: =OCP_D*(preF_FD + F_primary/OCP_D)/(preF_FD + F_primary/B58) | D58: =OCP_E*(preF_FD + F_primary/OCP_E)/(preF_FD + F_primary/B58) | E58: =D_sh*(OCP_D/C58 - 1) | F58: =E_sh*(OCP_E/D58 - 1) | G58: =(preF_FD + E58 + F58 - preF_opts + J57 + K57 + F_primary/B58)/(1-B30) | H58: =MAX(0, B30*G58 - preF_opts) | I58: =preF_FD + E58 + F58 + H58 | J58: =NA_P/MIN(NA_cap/(I58+K57), (1-NA_disc)*B58) | K58: =NB_P/MIN(NB_cap/(I58+J58), (1-NB_disc)*B58) | L58: =F_primary/B58 | M58: =I58+J58+K58 | N58: =D30/M58 | O58: =IF(Y57*L58 > F_primary, 1, 0) | P58: =IF(Y57*(E_sh + F58) > E_inv, 1, 0) | Q58: =IF(Y57*(D_sh + E58) > D_inv, 1, 0) | R58: =IF(Y57*C_sh > C_inv, 1, 0) | S58: =IF(Y57*B_sh > B_inv, 1, 0) | T58: =IF(Y57*A_sh > A_inv, 1, 0) | U58: =IF(Y57*seed_sh > seed_inv, 1, 0) | V58: =(1-O58)*F_primary+(1-P58)*E_inv+(1-Q58)*D_inv+(1-R58)*C_inv+(1-S58)*B_inv+(1-T58)*A_inv+(1-U58)*seed_inv | W58: =MAX(0, sens_exit - V58) | X58: =F1_sh+F2_sh+F3_sh+RSA_sh+J58+K58+O58*L58+P58*(E_sh + F58)+Q58*(D_sh + E58)+R58*C_sh+S58*B_sh+T58*A_sh+U58*seed_sh | Y58: =(W58 + preF_opts_iss*opt_strike)/(X58 + preF_opts_iss)
B59: =N58 | C59: =OCP_D*(preF_FD + F_primary/OCP_D)/(preF_FD + F_primary/B59) | D59: =OCP_E*(preF_FD + F_primary/OCP_E)/(preF_FD + F_primary/B59) | E59: =D_sh*(OCP_D/C59 - 1) | F59: =E_sh*(OCP_E/D59 - 1) | G59: =(preF_FD + E59 + F59 - preF_opts + J58 + K58 + F_primary/B59)/(1-B30) | H59: =MAX(0, B30*G59 - preF_opts) | I59: =preF_FD + E59 + F59 + H59 | J59: =NA_P/MIN(NA_cap/(I59+K58), (1-NA_disc)*B59) | K59: =NB_P/MIN(NB_cap/(I59+J59), (1-NB_disc)*B59) | L59: =F_primary/B59 | M59: =I59+J59+K59 | N59: =D30/M59 | O59: =IF(Y58*L59 > F_primary, 1, 0) | P59: =IF(Y58*(E_sh + F59) > E_inv, 1, 0) | Q59: =IF(Y58*(D_sh + E59) > D_inv, 1, 0) | R59: =IF(Y58*C_sh > C_inv, 1, 0) | S59: =IF(Y58*B_sh > B_inv, 1, 0) | T59: =IF(Y58*A_sh > A_inv, 1, 0) | U59: =IF(Y58*seed_sh > seed_inv, 1, 0) | V59: =(1-O59)*F_primary+(1-P59)*E_inv+(1-Q59)*D_inv+(1-R59)*C_inv+(1-S59)*B_inv+(1-T59)*A_inv+(1-U59)*seed_inv | W59: =MAX(0, sens_exit - V59) | X59: =F1_sh+F2_sh+F3_sh+RSA_sh+J59+K59+O59*L59+P59*(E_sh + F59)+Q59*(D_sh + E59)+R59*C_sh+S59*B_sh+T59*A_sh+U59*seed_sh | Y59: =(W59 + preF_opts_iss*opt_strike)/(X59 + preF_opts_iss)
B60: =N59 | C60: =OCP_D*(preF_FD + F_primary/OCP_D)/(preF_FD + F_primary/B60) | D60: =OCP_E*(preF_FD + F_primary/OCP_E)/(preF_FD + F_primary/B60) | E60: =D_sh*(OCP_D/C60 - 1) | F60: =E_sh*(OCP_E/D60 - 1) | G60: =(preF_FD + E60 + F60 - preF_opts + J59 + K59 + F_primary/B60)/(1-B30) | H60: =MAX(0, B30*G60 - preF_opts) | I60: =preF_FD + E60 + F60 + H60 | J60: =NA_P/MIN(NA_cap/(I60+K59), (1-NA_disc)*B60) | K60: =NB_P/MIN(NB_cap/(I60+J60), (1-NB_disc)*B60) | L60: =F_primary/B60 | M60: =I60+J60+K60 | N60: =D30/M60 | O60: =IF(Y59*L60 > F_primary, 1, 0) | P60: =IF(Y59*(E_sh + F60) > E_inv, 1, 0) | Q60: =IF(Y59*(D_sh + E60) > D_inv, 1, 0) | R60: =IF(Y59*C_sh > C_inv, 1, 0) | S60: =IF(Y59*B_sh > B_inv, 1, 0) | T60: =IF(Y59*A_sh > A_inv, 1, 0) | U60: =IF(Y59*seed_sh > seed_inv, 1, 0) | V60: =(1-O60)*F_primary+(1-P60)*E_inv+(1-Q60)*D_inv+(1-R60)*C_inv+(1-S60)*B_inv+(1-T60)*A_inv+(1-U60)*seed_inv | W60: =MAX(0, sens_exit - V60) | X60: =F1_sh+F2_sh+F3_sh+RSA_sh+J60+K60+O60*L60+P60*(E_sh + F60)+Q60*(D_sh + E60)+R60*C_sh+S60*B_sh+T60*A_sh+U60*seed_sh | Y60: =(W60 + preF_opts_iss*opt_strike)/(X60 + preF_opts_iss)
B61: =N60 | C61: =OCP_D*(preF_FD + F_primary/OCP_D)/(preF_FD + F_primary/B61) | D61: =OCP_E*(preF_FD + F_primary/OCP_E)/(preF_FD + F_primary/B61) | E61: =D_sh*(OCP_D/C61 - 1) | F61: =E_sh*(OCP_E/D61 - 1) | G61: =(preF_FD + E61 + F61 - preF_opts + J60 + K60 + F_primary/B61)/(1-B30) | H61: =MAX(0, B30*G61 - preF_opts) | I61: =preF_FD + E61 + F61 + H61 | J61: =NA_P/MIN(NA_cap/(I61+K60), (1-NA_disc)*B61) | K61: =NB_P/MIN(NB_cap/(I61+J61), (1-NB_disc)*B61) | L61: =F_primary/B61 | M61: =I61+J61+K61 | N61: =D30/M61 | O61: =IF(Y60*L61 > F_primary, 1, 0) | P61: =IF(Y60*(E_sh + F61) > E_inv, 1, 0) | Q61: =IF(Y60*(D_sh + E61) > D_inv, 1, 0) | R61: =IF(Y60*C_sh > C_inv, 1, 0) | S61: =IF(Y60*B_sh > B_inv, 1, 0) | T61: =IF(Y60*A_sh > A_inv, 1, 0) | U61: =IF(Y60*seed_sh > seed_inv, 1, 0) | V61: =(1-O61)*F_primary+(1-P61)*E_inv+(1-Q61)*D_inv+(1-R61)*C_inv+(1-S61)*B_inv+(1-T61)*A_inv+(1-U61)*seed_inv | W61: =MAX(0, sens_exit - V61) | X61: =F1_sh+F2_sh+F3_sh+RSA_sh+J61+K61+O61*L61+P61*(E_sh + F61)+Q61*(D_sh + E61)+R61*C_sh+S61*B_sh+T61*A_sh+U61*seed_sh | Y61: =(W61 + preF_opts_iss*opt_strike)/(X61 + preF_opts_iss)
B62: =N61 | C62: =OCP_D*(preF_FD + F_primary/OCP_D)/(preF_FD + F_primary/B62) | D62: =OCP_E*(preF_FD + F_primary/OCP_E)/(preF_FD + F_primary/B62) | E62: =D_sh*(OCP_D/C62 - 1) | F62: =E_sh*(OCP_E/D62 - 1) | G62: =(preF_FD + E62 + F62 - preF_opts + J61 + K61 + F_primary/B62)/(1-B30) | H62: =MAX(0, B30*G62 - preF_opts) | I62: =preF_FD + E62 + F62 + H62 | J62: =NA_P/MIN(NA_cap/(I62+K61), (1-NA_disc)*B62) | K62: =NB_P/MIN(NB_cap/(I62+J62), (1-NB_disc)*B62) | L62: =F_primary/B62 | M62: =I62+J62+K62 | N62: =D30/M62 | O62: =IF(Y61*L62 > F_primary, 1, 0) | P62: =IF(Y61*(E_sh + F62) > E_inv, 1, 0) | Q62: =IF(Y61*(D_sh + E62) > D_inv, 1, 0) | R62: =IF(Y61*C_sh > C_inv, 1, 0) | S62: =IF(Y61*B_sh > B_inv, 1, 0) | T62: =IF(Y61*A_sh > A_inv, 1, 0) | U62: =IF(Y61*seed_sh > seed_inv, 1, 0) | V62: =(1-O62)*F_primary+(1-P62)*E_inv+(1-Q62)*D_inv+(1-R62)*C_inv+(1-S62)*B_inv+(1-T62)*A_inv+(1-U62)*seed_inv | W62: =MAX(0, sens_exit - V62) | X62: =F1_sh+F2_sh+F3_sh+RSA_sh+J62+K62+O62*L62+P62*(E_sh + F62)+Q62*(D_sh + E62)+R62*C_sh+S62*B_sh+T62*A_sh+U62*seed_sh | Y62: =(W62 + preF_opts_iss*opt_strike)/(X62 + preF_opts_iss)
...

Sheet Return-Solver
A1: Return-Solver — Series F Ownership % Required
A3: For each exit, what % of post-F FD must our $10M check own to return 3× ($30M) and 4× ($40M)?
A4: Under base-case ESOP (13%) and full waterfall (incl. F's own election).
A5: Flagged INFEASIBLE if required ownership ≤ 0% or > 100%.
A7: Exit | B7: F election | C7: F class total payout | D7: Per-share to our shares | E7: Required own% for 3× | F7: 3× flag | G7: Required own% for 4× | H7: 4× flag
A8: =exit_v1 | B8: =Waterfall!B10 | C8: =Waterfall!B18 | D8: =C8 / F_prim_sh | E8: =ret_3x*our_check/(T_F * D8) | F8: =IF(OR(E8<=0, E8>1), "INFEASIBLE", "feasible") | G8: =ret_4x*our_check/(T_F * D8) | H8: =IF(OR(G8<=0, G8>1), "INFEASIBLE", "feasible")
A9: =exit_v2 | B9: =Waterfall!C10 | C9: =Waterfall!C18 | D9: =C9 / F_prim_sh | E9: =ret_3x*our_check/(T_F * D9) | F9: =IF(OR(E9<=0, E9>1), "INFEASIBLE", "feasible") | G9: =ret_4x*our_check/(T_F * D9) | H9: =IF(OR(G9<=0, G9>1), "INFEASIBLE", "feasible")
A10: =exit_v3 | B10: =Waterfall!D10 | C10: =Waterfall!D18 | D10: =C10 / F_prim_sh | E10: =ret_3x*our_check/(T_F * D10) | F10: =IF(OR(E10<=0, E10>1), "INFEASIBLE", "feasible") | G10: =ret_4x*our_check/(T_F * D10) | H10: =IF(OR(G10<=0, G10>1), "INFEASIBLE", "feasible")
A11: =exit_v4 | B11: =Waterfall!E10 | C11: =Waterfall!E18 | D11: =C11 / F_prim_sh | E11: =ret_3x*our_check/(T_F * D11) | F11: =IF(OR(E11<=0, E11>1), "INFEASIBLE", "feasible") | G11: =ret_4x*our_check/(T_F * D11) | H11: =IF(OR(G11<=0, G11>1), "INFEASIBLE", "feasible")
A12: =exit_v5 | B12: =Waterfall!F10 | C12: =Waterfall!F18 | D12: =C12 / F_prim_sh | E12: =ret_3x*our_check/(T_F * D12) | F12: =IF(OR(E12<=0, E12>1), "INFEASIBLE", "feasible") | G12: =ret_4x*our_check/(T_F * D12) | H12: =IF(OR(G12<=0, G12>1), "INFEASIBLE", "feasible")
