Workbook

Sheet Assumptions
A1: Series F Analysis — Assumptions
A2: Knob | B2: Value | C2: Notes
A3: series_f_pre_money_usd | B3: 1400000000 | C3: Series F pre-money valuation
A4: series_f_primary_raise_usd | B4: 30000000 | C4: New Series F primary capital
A5: series_f_secondary_raise_usd | B5: 15000000 | C5: Secondary tender from founders
A6: series_f_tender_pps_multiplier | B6: 0.85 | C6: Tender PPS = mult x F_PPS
A7: esop_refresh_target_post_f | B7: 0.13 | C7: Post-F ESOP as fraction of post-F FD
A8: our_fund_check_usd | B8: 10000000 | C8: Our fund check (1/3 of primary)
A9: f_lead_primary_check_usd | B9: 20000000 | C9: F_LEAD primary check (2/3 of primary)
A10: option_strike_usd | B10: 1 | C10: Strike for issued options
A11: exit_value_1_usd | B11: 700000000 | C11: Exit 1
A12: exit_value_2_usd | B12: 1200000000 | C12: Exit 2
A13: exit_value_3_usd | B13: 2000000000 | C13: Exit 3 (sensitivity)
A14: exit_value_4_usd | B14: 4000000000 | C14: Exit 4
... A57: return_multiple_4x | B57: 4 | C57: Return target 4x

Sheet Solver
A1: Solver — Round Fixed-Point Iteration Ladder
A3: Step | B3: F_PPS | C3: D_NCP | D3: E_NCP | E3: ΔD | F3: ΔE | G3: ESOP | H3: N_A | I3: N_B | J3: pre_money_FD | K3: T_F_post | L3: F_PPS check
A4: Base seed | B4: =Assumptions!$B$3/Assumptions!$B$29 | C4: =Assumptions!$B$20 | D4: =Assumptions!$B$21 | E4: 0 | F4: 0 | G4: 0 | H4: 0 | I4: 0 | J4: =Assumptions!$B$29 | K4: =J4+Assumptions!$B$4/B4 | L4: =B4
A5: Base iter 1 | B5: =Assumptions!$B$3/J4 | C5: =IF(B5<Assumptions!$B$20,Assumptions!$B$20*(Assumptions!$B$29+Assumptions!$B$4/Assumptions!$B$20)/(Assumptions!$B$29+Assumptions!$B$4/B5),Assumptions!$B$20) | D5: =IF(B5<Assumptions!$B$21,Assumptions!$B$21*(Assumptions!$B$29+Assumptions!$B$4/Assumptions!$B$21)/(Assumptions!$B$29+Assumptions!$B$4/B5),Assumptions!$B$21) | E5: =Assumptions!$B$37*Assumptions!$B$22/C5-Assumptions!$B$38 | F5: =Assumptions!$B$39*Assumptions!$B$21/D5-Assumptions!$B$39 | G5: =MAX(0,Assumptions!$B$7*(Assumptions!$B$29+E5+F5+G4+H4+I4+Assumptions!$B$4/B5)-Assumptions!$B$30) | H5: =Assumptions!$B$23/MIN(Assumptions!$B$24/(Assumptions!$B$29+E5+F5+G5+I4),B5*(1-Assumptions!$B$25)) | I5: =Assumptions!$B$26/MIN(Assumptions!$B$27/(Assumptions!$B$29+E5+F5+G5+H5),B5*(1-Assumptions!$B$28)) | J5: =Assumptions!$B$29+E5+F5+G5+H5+I5 | K5: =J5+Assumptions!$B$4/B5 | L5: =B5
A6: Base iter 2 | B6: =Assumptions!$B$3/J5 | C6: =IF(B6<Assumptions!$B$20,Assumptions!$B$20*(Assumptions!$B$29+Assumptions!$B$4/Assumptions!$B$20)/(Assumptions!$B$29+Assumptions!$B$4/B6),Assumptions!$B$20) | D6: =IF(B6<Assumptions!$B$21,Assumptions!$B$21*(Assumptions!$B$29+Assumptions!$B$4/Assumptions!$B$21)/(Assumptions!$B$29+Assumptions!$B$4/B6),Assumptions!$B$21) | E6: =Assumptions!$B$37*Assumptions!$B$22/C6-Assumptions!$B$38 | F6: =Assumptions!$B$39*Assumptions!$B$21/D6-Assumptions!$B$39 | G6: =MAX(0,Assumptions!$B$7*(Assumptions!$B$29+E6+F6+G5+H5+I5+Assumptions!$B$4/B6)-Assumptions!$B$30) | H6: =Assumptions!$B$23/MIN(Assumptions!$B$24/(Assumptions!$B$29+E6+F6+G6+I5),B6*(1-Assumptions!$B$25)) | I6: =Assumptions!$B$26/MIN(Assumptions!$B$27/(Assumptions!$B$29+E6+F6+G6+H6),B6*(1-Assumptions!$B$28)) | J6: =Assumptions!$B$29+E6+F6+G6+H6+I6 | K6: =J6+Assumptions!$B$4/B6 | L6: =B6
A7: Base iter 3 | B7: =Assumptions!$B$3/J6 | C7: =IF(B7<Assumptions!$B$20,Assumptions!$B$20*(Assumptions!$B$29+Assumptions!$B$4/Assumptions!$B$20)/(Assumptions!$B$29+Assumptions!$B$4/B7),Assumptions!$B$20) | D7: =IF(B7<Assumptions!$B$21,Assumptions!$B$21*(Assumptions!$B$29+Assumptions!$B$4/Assumptions!$B$21)/(Assumptions!$B$29+Assumptions!$B$4/B7),Assumptions!$B$21) | E7: =Assumptions!$B$37*Assumptions!$B$22/C7-Assumptions!$B$38 | F7: =Assumptions!$B$39*Assumptions!$B$21/D7-Assumptions!$B$39 | G7: =MAX(0,Assumptions!$B$7*(Assumptions!$B$29+E7+F7+G6+H6+I6+Assumptions!$B$4/B7)-Assumptions!$B$30) | H7: =Assumptions!$B$23/MIN(Assumptions!$B$24/(Assumptions!$B$29+E7+F7+G7+I6),B7*(1-Assumptions!$B$25)) | I7: =Assumptions!$B$26/MIN(Assumptions!$B$27/(Assumptions!$B$29+E7+F7+G7+H7),B7*(1-Assumptions!$B$28)) | J7: =Assumptions!$B$29+E7+F7+G7+H7+I7 | K7: =J7+Assumptions!$B$4/B7 | L7: =B7
A8: Base iter 4 | B8: =Assumptions!$B$3/J7 | C8: =IF(B8<Assumptions!$B$20,Assumptions!$B$20*(Assumptions!$B$29+Assumptions!$B$4/Assumptions!$B$20)/(Assumptions!$B$29+Assumptions!$B$4/B8),Assumptions!$B$20) | D8: =IF(B8<Assumptions!$B$21,Assumptions!$B$21*(Assumptions!$B$29+Assumptions!$B$4/Assumptions!$B$21)/(Assumptions!$B$29+Assumptions!$B$4/B8),Assumptions!$B$21) | E8: =Assumptions!$B$37*Assumptions!$B$22/C8-Assumptions!$B$38 | F8: =Assumptions!$B$39*Assumptions!$B$21/D8-Assumptions!$B$39 | G8: =MAX(0,Assumptions!$B$7*(Assumptions!$B$29+E8+F8+G7+H7+I7+Assumptions!$B$4/B8)-Assumptions!$B$30) | H8: =Assumptions!$B$23/MIN(Assumptions!$B$24/(Assumptions!$B$29+E8+F8+G8+I7),B8*(1-Assumptions!$B$25)) | I8: =Assumptions!$B$26/MIN(Assumptions!$B$27/(Assumptions!$B$29+E8+F8+G8+H8),B8*(1-Assumptions!$B$28)) | J8: =Assumptions!$B$29+E8+F8+G8+H8+I8 | K8: =J8+Assumptions!$B$4/B8 | L8: =B8
A9: Base iter 5 | B9: =Assumptions!$B$3/J8 | C9: =IF(B9<Assumptions!$B$20,Assumptions!$B$20*(Assumptions!$B$29+Assumptions!$B$4/Assumptions!$B$20)/(Assumptions!$B$29+Assumptions!$B$4/B9),Assumptions!$B$20) | D9: =IF(B9<Assumptions!$B$21,Assumptions!$B$21*(Assumptions!$B$29+Assumptions!$B$4/Assumptions!$B$21)/(Assumptions!$B$29+Assumptions!$B$4/B9),Assumptions!$B$21) | E9: =Assumptions!$B$37*Assumptions!$B$22/C9-Assumptions!$B$38 | F9: =Assumptions!$B$39*Assumptions!$B$21/D9-Assumptions!$B$39 | G9: =MAX(0,Assumptions!$B$7*(Assumptions!$B$29+E9+F9+G8+H8+I8+Assumptions!$B$4/B9)-Assumptions!$B$30) | H9: =Assumptions!$B$23/MIN(Assumptions!$B$24/(Assumptions!$B$29+E9+F9+G9+I8),B9*(1-Assumptions!$B$25)) | I9: =Assumptions!$B$26/MIN(Assumptions!$B$27/(Assumptions!$B$29+E9+F9+G9+H9),B9*(1-Assumptions!$B$28)) | J9: =Assumptions!$B$29+E9+F9+G9+H9+I9 | K9: =J9+Assumptions!$B$4/B9 | L9: =B9
A10: Base iter 6 | B10: =Assumptions!$B$3/J9 | C10: =IF(B10<Assumptions!$B$20,Assumptions!$B$20*(Assumptions!$B$29+Assumptions!$B$4/Assumptions!$B$20)/(Assumptions!$B$29+Assumptions!$B$4/B10),Assumptions!$B$20) | D10: =IF(B10<Assumptions!$B$21,Assumptions!$B$21*(Assumptions!$B$29+Assumptions!$B$4/Assumptions!$B$21)/(Assumptions!$B$29+Assumptions!$B$4/B10),Assumptions!$B$21) | E10: =Assumptions!$B$37*Assumptions!$B$22/C10-Assumptions!$B$38 | F10: =Assumptions!$B$39*Assumptions!$B$21/D10-Assumptions!$B$39 | G10: =MAX(0,Assumptions!$B$7*(Assumptions!$B$29+E10+F10+G9+H9+I9+Assumptions!$B$4/B10)-Assumptions!$B$30) | H10: =Assumptions!$B$23/MIN(Assumptions!$B$24/(Assumptions!$B$29+E10+F10+G10+I9),B10*(1-Assumptions!$B$25)) | I10: =Assumptions!$B$26/MIN(Assumptions!$B$27/(Assumptions!$B$29+E10+F10+G10+H10),B10*(1-Assumptions!$B$28)) | J10: =Assumptions!$B$29+E10+F10+G10+H10+I10 | K10: =J10+Assumptions!$B$4/B10 | L10: =B10
A11: Base iter 7 | B11: =Assumptions!$B$3/J10 | C11: =IF(B11<Assumptions!$B$20,Assumptions!$B$20*(Assumptions!$B$29+Assumptions!$B$4/Assumptions!$B$20)/(Assumptions!$B$29+Assumptions!$B$4/B11),Assumptions!$B$20) | D11: =IF(B11<Assumptions!$B$21,Assumptions!$B$21*(Assumptions!$B$29+Assumptions!$B$4/Assumptions!$B$21)/(Assumptions!$B$29+Assumptions!$B$4/B11),Assumptions!$B$21) | E11: =Assumptions!$B$37*Assumptions!$B$22/C11-Assumptions!$B$38 | F11: =Assumptions!$B$39*Assumptions!$B$21/D11-Assumptions!$B$39 | G11: =MAX(0,Assumptions!$B$7*(Assumptions!$B$29+E11+F11+G10+H10+I10+Assumptions!$B$4/B11)-Assumptions!$B$30) | H11: =Assumptions!$B$23/MIN(Assumptions!$B$24/(Assumptions!$B$29+E11+F11+G11+I10),B11*(1-Assumptions!$B$25)) | I11: =Assumptions!$B$26/MIN(Assumptions!$B$27/(Assumptions!$B$29+E11+F11+G11+H11),B11*(1-Assumptions!$B$28)) | J11: =Assumptions!$B$29+E11+F11+G11+H11+I11 | K11: =J11+Assumptions!$B$4/B11 | L11: =B11
A12: Base iter 8 | B12: =Assumptions!$B$3/J11 | C12: =IF(B12<Assumptions!$B$20,Assumptions!$B$20*(Assumptions!$B$29+Assumptions!$B$4/Assumptions!$B$20)/(Assumptions!$B$29+Assumptions!$B$4/B12),Assumptions!$B$20) | D12: =IF(B12<Assumptions!$B$21,Assumptions!$B$21*(Assumptions!$B$29+Assumptions!$B$4/Assumptions!$B$21)/(Assumptions!$B$29+Assumptions!$B$4/B12),Assumptions!$B$21) | E12: =Assumptions!$B$37*Assumptions!$B$22/C12-Assumptions!$B$38 | F12: =Assumptions!$B$39*Assumptions!$B$21/D12-Assumptions!$B$39 | G12: =MAX(0,Assumptions!$B$7*(Assumptions!$B$29+E12+F12+G11+H11+I11+Assumptions!$B$4/B12)-Assumptions!$B$30) | H12: =Assumptions!$B$23/MIN(Assumptions!$B$24/(Assumptions!$B$29+E12+F12+G12+I11),B12*(1-Assumptions!$B$25)) | I12: =Assumptions!$B$26/MIN(Assumptions!$B$27/(Assumptions!$B$29+E12+F12+G12+H12),B12*(1-Assumptions!$B$28)) | J12: =Assumptions!$B$29+E12+F12+G12+H12+I12 | K12: =J12+Assumptions!$B$4/B12 | L12: =B12
A13: Base iter 9 | B13: =Assumptions!$B$3/J12 | C13: =IF(B13<Assumptions!$B$20,Assumptions!$B$20*(Assumptions!$B$29+Assumptions!$B$4/Assumptions!$B$20)/(Assumptions!$B$29+Assumptions!$B$4/B13),Assumptions!$B$20) | D13: =IF(B13<Assumptions!$B$21,Assumptions!$B$21*(Assumptions!$B$29+Assumptions!$B$4/Assumptions!$B$21)/(Assumptions!$B$29+Assumptions!$B$4/B13),Assumptions!$B$21) | E13: =Assumptions!$B$37*Assumptions!$B$22/C13-Assumptions!$B$38 | F13: =Assumptions!$B$39*Assumptions!$B$21/D13-Assumptions!$B$39 | G13: =MAX(0,Assumptions!$B$7*(Assumptions!$B$29+E13+F13+G12+H12+I12+Assumptions!$B$4/B13)-Assumptions!$B$30) | H13: =Assumptions!$B$23/MIN(Assumptions!$B$24/(Assumptions!$B$29+E13+F13+G13+I12),B13*(1-Assumptions!$B$25)) | I13: =Assumptions!$B$26/MIN(Assumptions!$B$27/(Assumptions!$B$29+E13+F13+G13+H13),B13*(1-Assumptions!$B$28)) | J13: =Assumptions!$B$29+E13+F13+G13+H13+I13 | K13: =J13+Assumptions!$B$4/B13 | L13: =B13
A14: Base iter 10 | B14: =Assumptions!$B$3/J13 | C14: =IF(B14<Assumptions!$B$20,Assumptions!$B$20*(Assumptions!$B$29+Assumptions!$B$4/Assumptions!$B$20)/(Assumptions!$B$29+Assumptions!$B$4/B14),Assumptions!$B$20) | D14: =IF(B14<Assumptions!$B$21,Assumptions!$B$21*(Assumptions!$B$29+Assumptions!$B$4/Assumptions!$B$21)/(Assumptions!$B$29+Assumptions!$B$4/B14),Assumptions!$B$21) | E14: =Assumptions!$B$37*Assumptions!$B$22/C14-Assumptions!$B$38 | F14: =Assumptions!$B$39*Assumptions!$B$21/D14-Assumptions!$B$39 | G14: =MAX(0,Assumptions!$B$7*(Assumptions!$B$29+E14+F14+G13+H13+I13+Assumptions!$B$4/B14)-Assumptions!$B$30) | H14: =Assumptions!$B$23/MIN(Assumptions!$B$24/(Assumptions!$B$29+E14+F14+G14+I13),B14*(1-Assumptions!$B$25)) | I14: =Assumptions!$B$26/MIN(Assumptions!$B$27/(Assumptions!$B$29+E14+F14+G14+H14),B14*(1-Assumptions!$B$28)) | J14: =Assumptions!$B$29+E14+F14+G14+H14+I14 | K14: =J14+Assumptions!$B$4/B14 | L14: =B14
A15: Base iter 11 | B15: =Assumptions!$B$3/J14 | C15: =IF(B15<Assumptions!$B$20,Assumptions!$B$20*(Assumptions!$B$29+Assumptions!$B$4/Assumptions!$B$20)/(Assumptions!$B$29+Assumptions!$B$4/B15),Assumptions!$B$20) | D15: =IF(B15<Assumptions!$B$21,Assumptions!$B$21*(Assumptions!$B$29+Assumptions!$B$4/Assumptions!$B$21)/(Assumptions!$B$29+Assumptions!$B$4/B15),Assumptions!$B$21) | E15: =Assumptions!$B$37*Assumptions!$B$22/C15-Assumptions!$B$38 | F15: =Assumptions!$B$39*Assumptions!$B$21/D15-Assumptions!$B$39 | G15: =MAX(0,Assumptions!$B$7*(Assumptions!$B$29+E15+F15+G14+H14+I14+Assumptions!$B$4/B15)-Assumptions!$B$30) | H15: =Assumptions!$B$23/MIN(Assumptions!$B$24/(Assumptions!$B$29+E15+F15+G15+I14),B15*(1-Assumptions!$B$25)) | I15: =Assumptions!$B$26/MIN(Assumptions!$B$27/(Assumptions!$B$29+E15+F15+G15+H15),B15*(1-Assumptions!$B$28)) | J15: =Assumptions!$B$29+E15+F15+G15+H15+I15 | K15: =J15+Assumptions!$B$4/B15 | L15: =B15
A16: Base iter 12 | B16: =Assumptions!$B$3/J15 | C16: =IF(B16<Assumptions!$B$20,Assumptions!$B$20*(Assumptions!$B$29+Assumptions!$B$4/Assumptions!$B$20)/(Assumptions!$B$29+Assumptions!$B$4/B16),Assumptions!$B$20) | D16: =IF(B16<Assumptions!$B$21,Assumptions!$B$21*(Assumptions!$B$29+Assumptions!$B$4/Assumptions!$B$21)/(Assumptions!$B$29+Assumptions!$B$4/B16),Assumptions!$B$21) | E16: =Assumptions!$B$37*Assumptions!$B$22/C16-Assumptions!$B$38 | F16: =Assumptions!$B$39*Assumptions!$B$21/D16-Assumptions!$B$39 | G16: =MAX(0,Assumptions!$B$7*(Assumptions!$B$29+E16+F16+G15+H15+I15+Assumptions!$B$4/B16)-Assumptions!$B$30) | H16: =Assumptions!$B$23/MIN(Assumptions!$B$24/(Assumptions!$B$29+E16+F16+G16+I15),B16*(1-Assumptions!$B$25)) | I16: =Assumptions!$B$26/MIN(Assumptions!$B$27/(Assumptions!$B$29+E16+F16+G16+H16),B16*(1-Assumptions!$B$28)) | J16: =Assumptions!$B$29+E16+F16+G16+H16+I16 | K16: =J16+Assumptions!$B$4/B16 | L16: =B16
... A84: Base iter 80 | B84: =Assumptions!$B$3/J83 | C84: =IF(B84<Assumptions!$B$20,Assumptions!$B$20*(Assumptions!$B$29+Assumptions!$B$4/Assumptions!$B$20)/(Assumptions!$B$29+Assumptions!$B$4/B84),Assumptions!$B$20) | D84: =IF(B84<Assumptions!$B$21,Assumptions!$B$21*(Assumptions!$B$29+Assumptions!$B$4/Assumptions!$B$21)/(Assumptions!$B$29+Assumptions!$B$4/B84),Assumptions!$B$21) | E84: =Assumptions!$B$37*Assumptions!$B$22/C84-Assumptions!$B$38 | F84: =Assumptions!$B$39*Assumptions!$B$21/D84-Assumptions!$B$39 | G84: =MAX(0,Assumptions!$B$7*(Assumptions!$B$29+E84+F84+G83+H83+I83+Assumptions!$B$4/B84)-Assumptions!$B$30) | H84: =Assumptions!$B$23/MIN(Assumptions!$B$24/(Assumptions!$B$29+E84+F84+G84+I83),B84*(1-Assumptions!$B$25)) | I84: =Assumptions!$B$26/MIN(Assumptions!$B$27/(Assumptions!$B$29+E84+F84+G84+H84),B84*(1-Assumptions!$B$28)) | J84: =Assumptions!$B$29+E84+F84+G84+H84+I84 | K84: =J84+Assumptions!$B$4/B84 | L84: =B84

Sheet Pro-Forma
A1: Pro-Forma Post-F Cap Table
A3: Round Mechanics (from Solver)
A4: F PPS (USD) | B4: =Solver!B84
A5: D new conversion price (NCP) | B5: =Solver!C84
A6: E new conversion price (NCP) | B6: =Solver!D84
A7: ΔD shares (AD bump) | B7: =Solver!E84
A8: ΔE shares (AD bump) | B8: =Solver!F84
A9: ESOP top-up shares | B9: =Solver!G84
A10: Note A converted shares | B10: =M21
A11: Note B converted shares | B11: =M22
A12: New F primary shares ($30M / F_PPS) | B12: =Assumptions!$B$4/B4
A13: Pre-money FD | B13: =Solver!J84
A14: Post-F FD (T_F) | B14: =Solver!K84
A15: Tender shares | B15: =Assumptions!$B$5/(Assumptions!$B$6*B4)
A17: Anti-Dilution Block (Broad-Based WA) | H17: Convertible Notes Block
A18: Class | B18: OCP | C18: F_PPS<OCP? | D18: New CP | E18: New ratio (compound) | F18: As-converted shares | H18: Note | I18: Cap-implied PPS | J18: Discount-implied PPS | K18: Conversion PPS (min) | L18: Branch | M18: Shares
A19: Seed | B19: =Assumptions!$B$16 | C19: =IF(B4<B19,"trigger","dormant") | D19: =B19 | E19: =B19/D19 | F19: =Assumptions!$B$33*E19
A20: Series A | B20: =Assumptions!$B$17 | C20: =IF(B4<B20,"trigger","dormant") | D20: =B20 | E20: =B20/D20 | F20: =Assumptions!$B$34*E20
A21: Series B | B21: =Assumptions!$B$18 | C21: =IF(B4<B21,"trigger","dormant") | D21: =B21 | E21: =B21/D21 | F21: =Assumptions!$B$35*E21 | H21: Note A | I21: =Assumptions!$B$24/(Assumptions!$B$29+B7+B8+B9+Solver!I84) | J21: =B4*(1-Assumptions!$B$25) | K21: =MIN(I21,J21) | L21: =IF(I21<J21,"cap","discount") | M21: =Assumptions!$B$23/K21
A22: Series C | B22: =Assumptions!$B$19 | C22: =IF(B4<B22,"trigger","dormant") | D22: =B22 | E22: =B22/D22 | F22: =Assumptions!$B$36*E22 | H22: Note B | I22: =Assumptions!$B$27/(Assumptions!$B$29+B7+B8+B9+Solver!H84) | J22: =B4*(1-Assumptions!$B$28) | K22: =MIN(I22,J22) | L22: =IF(I22<J22,"cap","discount") | M22: =Assumptions!$B$26/K22
A23: Series D | B23: =Assumptions!$B$20 | C23: =IF(B4<B23,"trigger","dormant") | D23: =B5 | E23: =Assumptions!$B$22/D23 | F23: =Assumptions!$B$37*E23
A24: Series E | B24: =Assumptions!$B$21 | C24: =IF(B4<B24,"trigger","dormant") | D24: =B6 | E24: =Assumptions!$B$21/D24 | F24: =Assumptions!$B$39*E24
A27: Tender Block (Secondary)
A28: Tender shares | B28: =B15
A29: F1 share-out (50%) | B29: =B28*0.5
A30: F2 share-out (31.25%) | B30: =B28*0.3125
A31: F3 share-out (18.75%) | B31: =B28*0.1875
A32: F_LEAD secondary common | B32: =B28
A35: Stakeholder Breakdown (Post-F)
A36: Stakeholder | B36: Common | C36: Pref Class | D36: Pref Shares | E36: Total FD Shares | F36: Ownership %
A37: F1 | B37: =Assumptions!$B$46-B29 | D37: =0 | E37: =B37+D37 | F37: =E37/$B$14
A38: F2 | B38: =Assumptions!$B$47-B30 | D38: =0 | E38: =B38+D38 | F38: =E38/$B$14
A39: F3 | B39: =Assumptions!$B$48-B31 | D39: =0 | E39: =B39+D39 | F39: =E39/$B$14
A40: RSA holders (E1-E10) | B40: =Assumptions!$B$49 | D40: =0 | E40: =B40+D40 | F40: =E40/$B$14
A41: SEED1 | B41: =0 | C41: Seed | D41: =Assumptions!$B$33 | E41: =B41+D41 | F41: =E41/$B$14
A42: A1 | B42: =0 | C42: Series A | D42: =Assumptions!$B$34 | E42: =B42+D42 | F42: =E42/$B$14
A43: B1 | B43: =0 | C43: Series B | D43: =Assumptions!$B$35 | E43: =B43+D43 | F43: =E43/$B$14
A44: C1 | B44: =0 | C44: Series C | D44: =Assumptions!$B$36 | E44: =B44+D44 | F44: =E44/$B$14
A45: D1 | B45: =0 | C45: Series D | D45: =F23 | E45: =B45+D45 | F45: =E45/$B$14
A46: Series E LPs (10) | B46: =0 | C46: Series E | D46: =F24 | E46: =B46+D46 | F46: =E46/$B$14
...

Sheet Waterfall
A1: Waterfall by Exit Value
A3: Class | B3: LP ($) | C3: Post-F shares
A4: F | B4: =Assumptions!$B$4 | C4: =Assumptions!$B$4/'Pro-Forma'!$B$4
A5: E | B5: =Assumptions!$B$45 | C5: ='Pro-Forma'!$F$24
A6: D | B6: =Assumptions!$B$44 | C6: ='Pro-Forma'!$F$23
A7: C | B7: =Assumptions!$B$43 | C7: =Assumptions!$B$36
A8: B | B8: =Assumptions!$B$42 | C8: =Assumptions!$B$35
A9: A | B9: =Assumptions!$B$41 | C9: =Assumptions!$B$34
A10: Seed | B10: =Assumptions!$B$40 | C10: =Assumptions!$B$33
A12: Exit Value (USD) | B12: =Assumptions!$B$11 | C12: =Assumptions!$B$12 | D12: =Assumptions!$B$13 | E12: =Assumptions!$B$14 | F12: =Assumptions!$B$15
A14: 35 Election Cells (formula-driven IF)
A16: Exit 1 iteration ladder
A17: Step | B17: F_el | C17: E_el | D17: D_el | E17: C_el | F17: B_el | G17: A_el | H17: Seed_el | I17: prefs | J17: conv_sh | K17: cpool | L17: ITM_PPS | M17: ITM? | N17: common_PPS | O17: opt_proc
A18: seed (all convert) | B18: ="convert" | C18: ="convert" | D18: ="convert" | E18: ="convert" | F18: ="convert" | G18: ="convert" | H18: ="convert" | I18: =IF(B18="preference",$B$4,0)+IF(C18="preference",$B$5,0)+IF(D18="preference",$B$6,0)+IF(E18="preference",$B$7,0)+IF(F18="preference",$B$8,0)+IF(G18="preference",$B$9,0)+IF(H18="preference",$B$10,0) | J18: =IF(B18="convert",$C$4,0)+IF(C18="convert",$C$5,0)+IF(D18="convert",$C$6,0)+IF(E18="convert",$C$7,0)+IF(F18="convert",$C$8,0)+IF(G18="convert",$C$9,0)+IF(H18="convert",$C$10,0) | K18: =(Assumptions!$B$46+Assumptions!$B$47+Assumptions!$B$48)+Assumptions!$B$49+('Pro-Forma'!$M$21+'Pro-Forma'!$M$22)+J18 | L18: =(B12-I18+Assumptions!$B$31*Assumptions!$B$10)/(K18+Assumptions!$B$31) | M18: =IF(L18>Assumptions!$B$10,"yes","no") | N18: =IF(M18="yes",L18,MAX(0,(B12-I18)/K18)) | O18: =IF(M18="yes",Assumptions!$B$31*(N18-Assumptions!$B$10),0)
A19: iter 1 | B19: =IF($B$4>$C$4*N18,"preference","convert") | C19: =IF($B$5>$C$5*N18,"preference","convert") | D19: =IF($B$6>$C$6*N18,"preference","convert") | E19: =IF($B$7>$C$7*N18,"preference","convert") | F19: =IF($B$8>$C$8*N18,"preference","convert") | G19: =IF($B$9>$C$9*N18,"preference","convert") | H19: =IF($B$10>$C$10*N18,"preference","convert") | I19: =IF(B19="preference",$B$4,0)+IF(C19="preference",$B$5,0)+IF(D19="preference",$B$6,0)+IF(E19="preference",$B$7,0)+IF(F19="preference",$B$8,0)+IF(G19="preference",$B$9,0)+IF(H19="preference",$B$10,0) | J19: =IF(B19="convert",$C$4,0)+IF(C19="convert",$C$5,0)+IF(D19="convert",$C$6,0)+IF(E19="convert",$C$7,0)+IF(F19="convert",$C$8,0)+IF(G19="convert",$C$9,0)+IF(H19="convert",$C$10,0) | K19: =(Assumptions!$B$46+Assumptions!$B$47+Assumptions!$B$48)+Assumptions!$B$49+('Pro-Forma'!$M$21+'Pro-Forma'!$M$22)+J19 | L19: =(B12-I19+Assumptions!$B$31*Assumptions!$B$10)/(K19+Assumptions!$B$31) | M19: =IF(L19>Assumptions!$B$10,"yes","no") | N19: =IF(M19="yes",L19,MAX(0,(B12-I19)/K19)) | O19: =IF(M19="yes",Assumptions!$B$31*(N19-Assumptions!$B$10),0)
A20: iter 2 | B20: =IF($B$4>$C$4*N19,"preference","convert") | C20: =IF($B$5>$C$5*N19,"preference","convert") | D20: =IF($B$6>$C$6*N19,"preference","convert") | E20: =IF($B$7>$C$7*N19,"preference","convert") | F20: =IF($B$8>$C$8*N19,"preference","convert") | G20: =IF($B$9>$C$9*N19,"preference","convert") | H20: =IF($B$10>$C$10*N19,"preference","convert") | I20: =IF(B20="preference",$B$4,0)+IF(C20="preference",$B$5,0)+IF(D20="preference",$B$6,0)+IF(E20="preference",$B$7,0)+IF(F20="preference",$B$8,0)+IF(G20="preference",$B$9,0)+IF(H20="preference",$B$10,0) | J20: =IF(B20="convert",$C$4,0)+IF(C20="convert",$C$5,0)+IF(D20="convert",$C$6,0)+IF(E20="convert",$C$7,0)+IF(F20="convert",$C$8,0)+IF(G20="convert",$C$9,0)+IF(H20="convert",$C$10,0) | K20: =(Assumptions!$B$46+Assumptions!$B$47+Assumptions!$B$48)+Assumptions!$B$49+('Pro-Forma'!$M$21+'Pro-Forma'!$M$22)+J20 | L20: =(B12-I20+Assumptions!$B$31*Assumptions!$B$10)/(K20+Assumptions!$B$31) | M20: =IF(L20>Assumptions!$B$10,"yes","no") | N20: =IF(M20="yes",L20,MAX(0,(B12-I20)/K20)) | O20: =IF(M20="yes",Assumptions!$B$31*(N20-Assumptions!$B$10),0)
A21: iter 3 | B21: =IF($B$4>$C$4*N20,"preference","convert") | C21: =IF($B$5>$C$5*N20,"preference","convert") | D21: =IF($B$6>$C$6*N20,"preference","convert") | E21: =IF($B$7>$C$7*N20,"preference","convert") | F21: =IF($B$8>$C$8*N20,"preference","convert") | G21: =IF($B$9>$C$9*N20,"preference","convert") | H21: =IF($B$10>$C$10*N20,"preference","convert") | I21: =IF(B21="preference",$B$4,0)+IF(C21="preference",$B$5,0)+IF(D21="preference",$B$6,0)+IF(E21="preference",$B$7,0)+IF(F21="preference",$B$8,0)+IF(G21="preference",$B$9,0)+IF(H21="preference",$B$10,0) | J21: =IF(B21="convert",$C$4,0)+IF(C21="convert",$C$5,0)+IF(D21="convert",$C$6,0)+IF(E21="convert",$C$7,0)+IF(F21="convert",$C$8,0)+IF(G21="convert",$C$9,0)+IF(H21="convert",$C$10,0) | K21: =(Assumptions!$B$46+Assumptions!$B$47+Assumptions!$B$48)+Assumptions!$B$49+('Pro-Forma'!$M$21+'Pro-Forma'!$M$22)+J21 | L21: =(B12-I21+Assumptions!$B$31*Assumptions!$B$10)/(K21+Assumptions!$B$31) | M21: =IF(L21>Assumptions!$B$10,"yes","no") | N21: =IF(M21="yes",L21,MAX(0,(B12-I21)/K21)) | O21: =IF(M21="yes",Assumptions!$B$31*(N21-Assumptions!$B$10),0)
A22: iter 4 | B22: =IF($B$4>$C$4*N21,"preference","convert") | C22: =IF($B$5>$C$5*N21,"preference","convert") | D22: =IF($B$6>$C$6*N21,"preference","convert") | E22: =IF($B$7>$C$7*N21,"preference","convert") | F22: =IF($B$8>$C$8*N21,"preference","convert") | G22: =IF($B$9>$C$9*N21,"preference","convert") | H22: =IF($B$10>$C$10*N21,"preference","convert") | I22: =IF(B22="preference",$B$4,0)+IF(C22="preference",$B$5,0)+IF(D22="preference",$B$6,0)+IF(E22="preference",$B$7,0)+IF(F22="preference",$B$8,0)+IF(G22="preference",$B$9,0)+IF(H22="preference",$B$10,0) | J22: =IF(B22="convert",$C$4,0)+IF(C22="convert",$C$5,0)+IF(D22="convert",$C$6,0)+IF(E22="convert",$C$7,0)+IF(F22="convert",$C$8,0)+IF(G22="convert",$C$9,0)+IF(H22="convert",$C$10,0) | K22: =(Assumptions!$B$46+Assumptions!$B$47+Assumptions!$B$48)+Assumptions!$B$49+('Pro-Forma'!$M$21+'Pro-Forma'!$M$22)+J22 | L22: =(B12-I22+Assumptions!$B$31*Assumptions!$B$10)/(K22+Assumptions!$B$31) | M22: =IF(L22>Assumptions!$B$10,"yes","no") | N22: =IF(M22="yes",L22,MAX(0,(B12-I22)/K22)) | O22: =IF(M22="yes",Assumptions!$B$31*(N22-Assumptions!$B$10),0)
A23: iter 5 | B23: =IF($B$4>$C$4*N22,"preference","convert") | C23: =IF($B$5>$C$5*N22,"preference","convert") | D23: =IF($B$6>$C$6*N22,"preference","convert") | E23: =IF($B$7>$C$7*N22,"preference","convert") | F23: =IF($B$8>$C$8*N22,"preference","convert") | G23: =IF($B$9>$C$9*N22,"preference","convert") | H23: =IF($B$10>$C$10*N22,"preference","convert") | I23: =IF(B23="preference",$B$4,0)+IF(C23="preference",$B$5,0)+IF(D23="preference",$B$6,0)+IF(E23="preference",$B$7,0)+IF(F23="preference",$B$8,0)+IF(G23="preference",$B$9,0)+IF(H23="preference",$B$10,0) | J23: =IF(B23="convert",$C$4,0)+IF(C23="convert",$C$5,0)+IF(D23="convert",$C$6,0)+IF(E23="convert",$C$7,0)+IF(F23="convert",$C$8,0)+IF(G23="convert",$C$9,0)+IF(H23="convert",$C$10,0) | K23: =(Assumptions!$B$46+Assumptions!$B$47+Assumptions!$B$48)+Assumptions!$B$49+('Pro-Forma'!$M$21+'Pro-Forma'!$M$22)+J23 | L23: =(B12-I23+Assumptions!$B$31*Assumptions!$B$10)/(K23+Assumptions!$B$31) | M23: =IF(L23>Assumptions!$B$10,"yes","no") | N23: =IF(M23="yes",L23,MAX(0,(B12-I23)/K23)) | O23: =IF(M23="yes",Assumptions!$B$31*(N23-Assumptions!$B$10),0)
A24: iter 6 | B24: =IF($B$4>$C$4*N23,"preference","convert") | C24: =IF($B$5>$C$5*N23,"preference","convert") | D24: =IF($B$6>$C$6*N23,"preference","convert") | E24: =IF($B$7>$C$7*N23,"preference","convert") | F24: =IF($B$8>$C$8*N23,"preference","convert") | G24: =IF($B$9>$C$9*N23,"preference","convert") | H24: =IF($B$10>$C$10*N23,"preference","convert") | I24: =IF(B24="preference",$B$4,0)+IF(C24="preference",$B$5,0)+IF(D24="preference",$B$6,0)+IF(E24="preference",$B$7,0)+IF(F24="preference",$B$8,0)+IF(G24="preference",$B$9,0)+IF(H24="preference",$B$10,0) | J24: =IF(B24="convert",$C$4,0)+IF(C24="convert",$C$5,0)+IF(D24="convert",$C$6,0)+IF(E24="convert",$C$7,0)+IF(F24="convert",$C$8,0)+IF(G24="convert",$C$9,0)+IF(H24="convert",$C$10,0) | K24: =(Assumptions!$B$46+Assumptions!$B$47+Assumptions!$B$48)+Assumptions!$B$49+('Pro-Forma'!$M$21+'Pro-Forma'!$M$22)+J24 | L24: =(B12-I24+Assumptions!$B$31*Assumptions!$B$10)/(K24+Assumptions!$B$31) | M24: =IF(L24>Assumptions!$B$10,"yes","no") | N24: =IF(M24="yes",L24,MAX(0,(B12-I24)/K24)) | O24: =IF(M24="yes",Assumptions!$B$31*(N24-Assumptions!$B$10),0)
A25: iter 7 | B25: =IF($B$4>$C$4*N24,"preference","convert") | C25: =IF($B$5>$C$5*N24,"preference","convert") | D25: =IF($B$6>$C$6*N24,"preference","convert") | E25: =IF($B$7>$C$7*N24,"preference","convert") | F25: =IF($B$8>$C$8*N24,"preference","convert") | G25: =IF($B$9>$C$9*N24,"preference","convert") | H25: =IF($B$10>$C$10*N24,"preference","convert") | I25: =IF(B25="preference",$B$4,0)+IF(C25="preference",$B$5,0)+IF(D25="preference",$B$6,0)+IF(E25="preference",$B$7,0)+IF(F25="preference",$B$8,0)+IF(G25="preference",$B$9,0)+IF(H25="preference",$B$10,0) | J25: =IF(B25="convert",$C$4,0)+IF(C25="convert",$C$5,0)+IF(D25="convert",$C$6,0)+IF(E25="convert",$C$7,0)+IF(F25="convert",$C$8,0)+IF(G25="convert",$C$9,0)+IF(H25="convert",$C$10,0) | K25: =(Assumptions!$B$46+Assumptions!$B$47+Assumptions!$B$48)+Assumptions!$B$49+('Pro-Forma'!$M$21+'Pro-Forma'!$M$22)+J25 | L25: =(B12-I25+Assumptions!$B$31*Assumptions!$B$10)/(K25+Assumptions!$B$31) | M25: =IF(L25>Assumptions!$B$10,"yes","no") | N25: =IF(M25="yes",L25,MAX(0,(B12-I25)/K25)) | O25: =IF(M25="yes",Assumptions!$B$31*(N25-Assumptions!$B$10),0)
A26: iter 8 | B26: =IF($B$4>$C$4*N25,"preference","convert") | C26: =IF($B$5>$C$5*N25,"preference","convert") | D26: =IF($B$6>$C$6*N25,"preference","convert") | E26: =IF($B$7>$C$7*N25,"preference","convert") | F26: =IF($B$8>$C$8*N25,"preference","convert") | G26: =IF($B$9>$C$9*N25,"preference","convert") | H26: =IF($B$10>$C$10*N25,"preference","convert") | I26: =IF(B26="preference",$B$4,0)+IF(C26="preference",$B$5,0)+IF(D26="preference",$B$6,0)+IF(E26="preference",$B$7,0)+IF(F26="preference",$B$8,0)+IF(G26="preference",$B$9,0)+IF(H26="preference",$B$10,0) | J26: =IF(B26="convert",$C$4,0)+IF(C26="convert",$C$5,0)+IF(D26="convert",$C$6,0)+IF(E26="convert",$C$7,0)+IF(F26="convert",$C$8,0)+IF(G26="convert",$C$9,0)+IF(H26="convert",$C$10,0) | K26: =(Assumptions!$B$46+Assumptions!$B$47+Assumptions!$B$48)+Assumptions!$B$49+('Pro-Forma'!$M$21+'Pro-Forma'!$M$22)+J26 | L26: =(B12-I26+Assumptions!$B$31*Assumptions!$B$10)/(K26+Assumptions!$B$31) | M26: =IF(L26>Assumptions!$B$10,"yes","no") | N26: =IF(M26="yes",L26,MAX(0,(B12-I26)/K26)) | O26: =IF(M26="yes",Assumptions!$B$31*(N26-Assumptions!$B$10),0)
A27: iter 9 | B27: =IF($B$4>$C$4*N26,"preference","convert") | C27: =IF($B$5>$C$5*N26,"preference","convert") | D27: =IF($B$6>$C$6*N26,"preference","convert") | E27: =IF($B$7>$C$7*N26,"preference","convert") | F27: =IF($B$8>$C$8*N26,"preference","convert") | G27: =IF($B$9>$C$9*N26,"preference","convert") | H27: =IF($B$10>$C$10*N26,"preference","convert") | I27: =IF(B27="preference",$B$4,0)+IF(C27="preference",$B$5,0)+IF(D27="preference",$B$6,0)+IF(E27="preference",$B$7,0)+IF(F27="preference",$B$8,0)+IF(G27="preference",$B$9,0)+IF(H27="preference",$B$10,0) | J27: =IF(B27="convert",$C$4,0)+IF(C27="convert",$C$5,0)+IF(D27="convert",$C$6,0)+IF(E27="convert",$C$7,0)+IF(F27="convert",$C$8,0)+IF(G27="convert",$C$9,0)+IF(H27="convert",$C$10,0) | K27: =(Assumptions!$B$46+Assumptions!$B$47+Assumptions!$B$48)+Assumptions!$B$49+('Pro-Forma'!$M$21+'Pro-Forma'!$M$22)+J27 | L27: =(B12-I27+Assumptions!$B$31*Assumptions!$B$10)/(K27+Assumptions!$B$31) | M27: =IF(L27>Assumptions!$B$10,"yes","no") | N27: =IF(M27="yes",L27,MAX(0,(B12-I27)/K27)) | O27: =IF(M27="yes",Assumptions!$B$31*(N27-Assumptions!$B$10),0)
A28: iter 10 | B28: =IF($B$4>$C$4*N27,"preference","convert") | C28: =IF($B$5>$C$5*N27,"preference","convert") | D28: =IF($B$6>$C$6*N27,"preference","convert") | E28: =IF($B$7>$C$7*N27,"preference","convert") | F28: =IF($B$8>$C$8*N27,"preference","convert") | G28: =IF($B$9>$C$9*N27,"preference","convert") | H28: =IF($B$10>$C$10*N27,"preference","convert") | I28: =IF(B28="preference",$B$4,0)+IF(C28="preference",$B$5,0)+IF(D28="preference",$B$6,0)+IF(E28="preference",$B$7,0)+IF(F28="preference",$B$8,0)+IF(G28="preference",$B$9,0)+IF(H28="preference",$B$10,0) | J28: =IF(B28="convert",$C$4,0)+IF(C28="convert",$C$5,0)+IF(D28="convert",$C$6,0)+IF(E28="convert",$C$7,0)+IF(F28="convert",$C$8,0)+IF(G28="convert",$C$9,0)+IF(H28="convert",$C$10,0) | K28: =(Assumptions!$B$46+Assumptions!$B$47+Assumptions!$B$48)+Assumptions!$B$49+('Pro-Forma'!$M$21+'Pro-Forma'!$M$22)+J28 | L28: =(B12-I28+Assumptions!$B$31*Assumptions!$B$10)/(K28+Assumptions!$B$31) | M28: =IF(L28>Assumptions!$B$10,"yes","no") | N28: =IF(M28="yes",L28,MAX(0,(B12-I28)/K28)) | O28: =IF(M28="yes",Assumptions!$B$31*(N28-Assumptions!$B$10),0)
A29: iter 11 | B29: =IF($B$4>$C$4*N28,"preference","convert") | C29: =IF($B$5>$C$5*N28,"preference","convert") | D29: =IF($B$6>$C$6*N28,"preference","convert") | E29: =IF($B$7>$C$7*N28,"preference","convert") | F29: =IF($B$8>$C$8*N28,"preference","convert") | G29: =IF($B$9>$C$9*N28,"preference","convert") | H29: =IF($B$10>$C$10*N28,"preference","convert") | I29: =IF(B29="preference",$B$4,0)+IF(C29="preference",$B$5,0)+IF(D29="preference",$B$6,0)+IF(E29="preference",$B$7,0)+IF(F29="preference",$B$8,0)+IF(G29="preference",$B$9,0)+IF(H29="preference",$B$10,0) | J29: =IF(B29="convert",$C$4,0)+IF(C29="convert",$C$5,0)+IF(D29="convert",$C$6,0)+IF(E29="convert",$C$7,0)+IF(F29="convert",$C$8,0)+IF(G29="convert",$C$9,0)+IF(H29="convert",$C$10,0) | K29: =(Assumptions!$B$46+Assumptions!$B$47+Assumptions!$B$48)+Assumptions!$B$49+('Pro-Forma'!$M$21+'Pro-Forma'!$M$22)+J29 | L29: =(B12-I29+Assumptions!$B$31*Assumptions!$B$10)/(K29+Assumptions!$B$31) | M29: =IF(L29>Assumptions!$B$10,"yes","no") | N29: =IF(M29="yes",L29,MAX(0,(B12-I29)/K29)) | O29: =IF(M29="yes",Assumptions!$B$31*(N29-Assumptions!$B$10),0)
A30: iter 12 | B30: =IF($B$4>$C$4*N29,"preference","convert") | C30: =IF($B$5>$C$5*N29,"preference","convert") | D30: =IF($B$6>$C$6*N29,"preference","convert") | E30: =IF($B$7>$C$7*N29,"preference","convert") | F30: =IF($B$8>$C$8*N29,"preference","convert") | G30: =IF($B$9>$C$9*N29,"preference","convert") | H30: =IF($B$10>$C$10*N29,"preference","convert") | I30: =IF(B30="preference",$B$4,0)+IF(C30="preference",$B$5,0)+IF(D30="preference",$B$6,0)+IF(E30="preference",$B$7,0)+IF(F30="preference",$B$8,0)+IF(G30="preference",$B$9,0)+IF(H30="preference",$B$10,0) | J30: =IF(B30="convert",$C$4,0)+IF(C30="convert",$C$5,0)+IF(D30="convert",$C$6,0)+IF(E30="convert",$C$7,0)+IF(F30="convert",$C$8,0)+IF(G30="convert",$C$9,0)+IF(H30="convert",$C$10,0) | K30: =(Assumptions!$B$46+Assumptions!$B$47+Assumptions!$B$48)+Assumptions!$B$49+('Pro-Forma'!$M$21+'Pro-Forma'!$M$22)+J30 | L30: =(B12-I30+Assumptions!$B$31*Assumptions!$B$10)/(K30+Assumptions!$B$31) | M30: =IF(L30>Assumptions!$B$10,"yes","no") | N30: =IF(M30="yes",L30,MAX(0,(B12-I30)/K30)) | O30: =IF(M30="yes",Assumptions!$B$31*(N30-Assumptions!$B$10),0)
A31: iter 13 | B31: =IF($B$4>$C$4*N30,"preference","convert") | C31: =IF($B$5>$C$5*N30,"preference","convert") | D31: =IF($B$6>$C$6*N30,"preference","convert") | E31: =IF($B$7>$C$7*N30,"preference","convert") | F31: =IF($B$8>$C$8*N30,"preference","convert") | G31: =IF($B$9>$C$9*N30,"preference","convert") | H31: =IF($B$10>$C$10*N30,"preference","convert") | I31: =IF(B31="preference",$B$4,0)+IF(C31="preference",$B$5,0)+IF(D31="preference",$B$6,0)+IF(E31="preference",$B$7,0)+IF(F31="preference",$B$8,0)+IF(G31="preference",$B$9,0)+IF(H31="preference",$B$10,0) | J31: =IF(B31="convert",$C$4,0)+IF(C31="convert",$C$5,0)+IF(D31="convert",$C$6,0)+IF(E31="convert",$C$7,0)+IF(F31="convert",$C$8,0)+IF(G31="convert",$C$9,0)+IF(H31="convert",$C$10,0) | K31: =(Assumptions!$B$46+Assumptions!$B$47+Assumptions!$B$48)+Assumptions!$B$49+('Pro-Forma'!$M$21+'Pro-Forma'!$M$22)+J31 | L31: =(B12-I31+Assumptions!$B$31*Assumptions!$B$10)/(K31+Assumptions!$B$31) | M31: =IF(L31>Assumptions!$B$10,"yes","no") | N31: =IF(M31="yes",L31,MAX(0,(B12-I31)/K31)) | O31: =IF(M31="yes",Assumptions!$B$31*(N31-Assumptions!$B$10),0)
A32: iter 14 | B32: =IF($B$4>$C$4*N31,"preference","convert") | C32: =IF($B$5>$C$5*N31,"preference","convert") | D32: =IF($B$6>$C$6*N31,"preference","convert") | E32: =IF($B$7>$C$7*N31,"preference","convert") | F32: =IF($B$8>$C$8*N31,"preference","convert") | G32: =IF($B$9>$C$9*N31,"preference","convert") | H32: =IF($B$10>$C$10*N31,"preference","convert") | I32: =IF(B32="preference",$B$4,0)+IF(C32="preference",$B$5,0)+IF(D32="preference",$B$6,0)+IF(E32="preference",$B$7,0)+IF(F32="preference",$B$8,0)+IF(G32="preference",$B$9,0)+IF(H32="preference",$B$10,0) | J32: =IF(B32="convert",$C$4,0)+IF(C32="convert",$C$5,0)+IF(D32="convert",$C$6,0)+IF(E32="convert",$C$7,0)+IF(F32="convert",$C$8,0)+IF(G32="convert",$C$9,0)+IF(H32="convert",$C$10,0) | K32: =(Assumptions!$B$46+Assumptions!$B$47+Assumptions!$B$48)+Assumptions!$B$49+('Pro-Forma'!$M$21+'Pro-Forma'!$M$22)+J32 | L32: =(B12-I32+Assumptions!$B$31*Assumptions!$B$10)/(K32+Assumptions!$B$31) | M32: =IF(L32>Assumptions!$B$10,"yes","no") | N32: =IF(M32="yes",L32,MAX(0,(B12-I32)/K32)) | O32: =IF(M32="yes",Assumptions!$B$31*(N32-Assumptions!$B$10),0)
A33: iter 15 | B33: =IF($B$4>$C$4*N32,"preference","convert") | C33: =IF($B$5>$C$5*N32,"preference","convert") | D33: =IF($B$6>$C$6*N32,"preference","convert") | E33: =IF($B$7>$C$7*N32,"preference","convert") | F33: =IF($B$8>$C$8*N32,"preference","convert") | G33: =IF($B$9>$C$9*N32,"preference","convert") | H33: =IF($B$10>$C$10*N32,"preference","convert") | I33: =IF(B33="preference",$B$4,0)+IF(C33="preference",$B$5,0)+IF(D33="preference",$B$6,0)+IF(E33="preference",$B$7,0)+IF(F33="preference",$B$8,0)+IF(G33="preference",$B$9,0)+IF(H33="preference",$B$10,0) | J33: =IF(B33="convert",$C$4,0)+IF(C33="convert",$C$5,0)+IF(D33="convert",$C$6,0)+IF(E33="convert",$C$7,0)+IF(F33="convert",$C$8,0)+IF(G33="convert",$C$9,0)+IF(H33="convert",$C$10,0) | K33: =(Assumptions!$B$46+Assumptions!$B$47+Assumptions!$B$48)+Assumptions!$B$49+('Pro-Forma'!$M$21+'Pro-Forma'!$M$22)+J33 | L33: =(B12-I33+Assumptions!$B$31*Assumptions!$B$10)/(K33+Assumptions!$B$31) | M33: =IF(L33>Assumptions!$B$10,"yes","no") | N33: =IF(M33="yes",L33,MAX(0,(B12-I33)/K33)) | O33: =IF(M33="yes",Assumptions!$B$31*(N33-Assumptions!$B$10),0)
A34: iter 16 | B34: =IF($B$4>$C$4*N33,"preference","convert") | C34: =IF($B$5>$C$5*N33,"preference","convert") | D34: =IF($B$6>$C$6*N33,"preference","convert") | E34: =IF($B$7>$C$7*N33,"preference","convert") | F34: =IF($B$8>$C$8*N33,"preference","convert") | G34: =IF($B$9>$C$9*N33,"preference","convert") | H34: =IF($B$10>$C$10*N33,"preference","convert") | I34: =IF(B34="preference",$B$4,0)+IF(C34="preference",$B$5,0)+IF(D34="preference",$B$6,0)+IF(E34="preference",$B$7,0)+IF(F34="preference",$B$8,0)+IF(G34="preference",$B$9,0)+IF(H34="preference",$B$10,0) | J34: =IF(B34="convert",$C$4,0)+IF(C34="convert",$C$5,0)+IF(D34="convert",$C$6,0)+IF(E34="convert",$C$7,0)+IF(F34="convert",$C$8,0)+IF(G34="convert",$C$9,0)+IF(H34="convert",$C$10,0) | K34: =(Assumptions!$B$46+Assumptions!$B$47+Assumptions!$B$48)+Assumptions!$B$49+('Pro-Forma'!$M$21+'Pro-Forma'!$M$22)+J34 | L34: =(B12-I34+Assumptions!$B$31*Assumptions!$B$10)/(K34+Assumptions!$B$31) | M34: =IF(L34>Assumptions!$B$10,"yes","no") | N34: =IF(M34="yes",L34,MAX(0,(B12-I34)/K34)) | O34: =IF(M34="yes",Assumptions!$B$31*(N34-Assumptions!$B$10),0)
A35: iter 17 | B35: =IF($B$4>$C$4*N34,"preference","convert") | C35: =IF($B$5>$C$5*N34,"preference","convert") | D35: =IF($B$6>$C$6*N34,"preference","convert") | E35: =IF($B$7>$C$7*N34,"preference","convert") | F35: =IF($B$8>$C$8*N34,"preference","convert") | G35: =IF($B$9>$C$9*N34,"preference","convert") | H35: =IF($B$10>$C$10*N34,"preference","convert") | I35: =IF(B35="preference",$B$4,0)+IF(C35="preference",$B$5,0)+IF(D35="preference",$B$6,0)+IF(E35="preference",$B$7,0)+IF(F35="preference",$B$8,0)+IF(G35="preference",$B$9,0)+IF(H35="preference",$B$10,0) | J35: =IF(B35="convert",$C$4,0)+IF(C35="convert",$C$5,0)+IF(D35="convert",$C$6,0)+IF(E35="convert",$C$7,0)+IF(F35="convert",$C$8,0)+IF(G35="convert",$C$9,0)+IF(H35="convert",$C$10,0) | K35: =(Assumptions!$B$46+Assumptions!$B$47+Assumptions!$B$48)+Assumptions!$B$49+('Pro-Forma'!$M$21+'Pro-Forma'!$M$22)+J35 | L35: =(B12-I35+Assumptions!$B$31*Assumptions!$B$10)/(K35+Assumptions!$B$31) | M35: =IF(L35>Assumptions!$B$10,"yes","no") | N35: =IF(M35="yes",L35,MAX(0,(B12-I35)/K35)) | O35: =IF(M35="yes",Assumptions!$B$31*(N35-Assumptions!$B$10),0)
A36: iter 18 | B36: =IF($B$4>$C$4*N35,"preference","convert") | C36: =IF($B$5>$C$5*N35,"preference","convert") | D36: =IF($B$6>$C$6*N35,"preference","convert") | E36: =IF($B$7>$C$7*N35,"preference","convert") | F36: =IF($B$8>$C$8*N35,"preference","convert") | G36: =IF($B$9>$C$9*N35,"preference","convert") | H36: =IF($B$10>$C$10*N35,"preference","convert") | I36: =IF(B36="preference",$B$4,0)+IF(C36="preference",$B$5,0)+IF(D36="preference",$B$6,0)+IF(E36="preference",$B$7,0)+IF(F36="preference",$B$8,0)+IF(G36="preference",$B$9,0)+IF(H36="preference",$B$10,0) | J36: =IF(B36="convert",$C$4,0)+IF(C36="convert",$C$5,0)+IF(D36="convert",$C$6,0)+IF(E36="convert",$C$7,0)+IF(F36="convert",$C$8,0)+IF(G36="convert",$C$9,0)+IF(H36="convert",$C$10,0) | K36: =(Assumptions!$B$46+Assumptions!$B$47+Assumptions!$B$48)+Assumptions!$B$49+('Pro-Forma'!$M$21+'Pro-Forma'!$M$22)+J36 | L36: =(B12-I36+Assumptions!$B$31*Assumptions!$B$10)/(K36+Assumptions!$B$31) | M36: =IF(L36>Assumptions!$B$10,"yes","no") | N36: =IF(M36="yes",L36,MAX(0,(B12-I36)/K36)) | O36: =IF(M36="yes",Assumptions!$B$31*(N36-Assumptions!$B$10),0)
A37: iter 19 | B37: =IF($B$4>$C$4*N36,"preference","convert") | C37: =IF($B$5>$C$5*N36,"preference","convert") | D37: =IF($B$6>$C$6*N36,"preference","convert") | E37: =IF($B$7>$C$7*N36,"preference","convert") | F37: =IF($B$8>$C$8*N36,"preference","convert") | G37: =IF($B$9>$C$9*N36,"preference","convert") | H37: =IF($B$10>$C$10*N36,"preference","convert") | I37: =IF(B37="preference",$B$4,0)+IF(C37="preference",$B$5,0)+IF(D37="preference",$B$6,0)+IF(E37="preference",$B$7,0)+IF(F37="preference",$B$8,0)+IF(G37="preference",$B$9,0)+IF(H37="preference",$B$10,0) | J37: =IF(B37="convert",$C$4,0)+IF(C37="convert",$C$5,0)+IF(D37="convert",$C$6,0)+IF(E37="convert",$C$7,0)+IF(F37="convert",$C$8,0)+IF(G37="convert",$C$9,0)+IF(H37="convert",$C$10,0) | K37: =(Assumptions!$B$46+Assumptions!$B$47+Assumptions!$B$48)+Assumptions!$B$49+('Pro-Forma'!$M$21+'Pro-Forma'!$M$22)+J37 | L37: =(B12-I37+Assumptions!$B$31*Assumptions!$B$10)/(K37+Assumptions!$B$31) | M37: =IF(L37>Assumptions!$B$10,"yes","no") | N37: =IF(M37="yes",L37,MAX(0,(B12-I37)/K37)) | O37: =IF(M37="yes",Assumptions!$B$31*(N37-Assumptions!$B$10),0)
A38: iter 20 | B38: =IF($B$4>$C$4*N37,"preference","convert") | C38: =IF($B$5>$C$5*N37,"preference","convert") | D38: =IF($B$6>$C$6*N37,"preference","convert") | E38: =IF($B$7>$C$7*N37,"preference","convert") | F38: =IF($B$8>$C$8*N37,"preference","convert") | G38: =IF($B$9>$C$9*N37,"preference","convert") | H38: =IF($B$10>$C$10*N37,"preference","convert") | I38: =IF(B38="preference",$B$4,0)+IF(C38="preference",$B$5,0)+IF(D38="preference",$B$6,0)+IF(E38="preference",$B$7,0)+IF(F38="preference",$B$8,0)+IF(G38="preference",$B$9,0)+IF(H38="preference",$B$10,0) | J38: =IF(B38="convert",$C$4,0)+IF(C38="convert",$C$5,0)+IF(D38="convert",$C$6,0)+IF(E38="convert",$C$7,0)+IF(F38="convert",$C$8,0)+IF(G38="convert",$C$9,0)+IF(H38="convert",$C$10,0) | K38: =(Assumptions!$B$46+Assumptions!$B$47+Assumptions!$B$48)+Assumptions!$B$49+('Pro-Forma'!$M$21+'Pro-Forma'!$M$22)+J38 | L38: =(B12-I38+Assumptions!$B$31*Assumptions!$B$10)/(K38+Assumptions!$B$31) | M38: =IF(L38>Assumptions!$B$10,"yes","no") | N38: =IF(M38="yes",L38,MAX(0,(B12-I38)/K38)) | O38: =IF(M38="yes",Assumptions!$B$31*(N38-Assumptions!$B$10),0)
A39: iter 21 | B39: =IF($B$4>$C$4*N38,"preference","convert") | C39: =IF($B$5>$C$5*N38,"preference","convert") | D39: =IF($B$6>$C$6*N38,"preference","convert") | E39: =IF($B$7>$C$7*N38,"preference","convert") | F39: =IF($B$8>$C$8*N38,"preference","convert") | G39: =IF($B$9>$C$9*N38,"preference","convert") | H39: =IF($B$10>$C$10*N38,"preference","convert") | I39: =IF(B39="preference",$B$4,0)+IF(C39="preference",$B$5,0)+IF(D39="preference",$B$6,0)+IF(E39="preference",$B$7,0)+IF(F39="preference",$B$8,0)+IF(G39="preference",$B$9,0)+IF(H39="preference",$B$10,0) | J39: =IF(B39="convert",$C$4,0)+IF(C39="convert",$C$5,0)+IF(D39="convert",$C$6,0)+IF(E39="convert",$C$7,0)+IF(F39="convert",$C$8,0)+IF(G39="convert",$C$9,0)+IF(H39="convert",$C$10,0) | K39: =(Assumptions!$B$46+Assumptions!$B$47+Assumptions!$B$48)+Assumptions!$B$49+('Pro-Forma'!$M$21+'Pro-Forma'!$M$22)+J39 | L39: =(B12-I39+Assumptions!$B$31*Assumptions!$B$10)/(K39+Assumptions!$B$31) | M39: =IF(L39>Assumptions!$B$10,"yes","no") | N39: =IF(M39="yes",L39,MAX(0,(B12-I39)/K39)) | O39: =IF(M39="yes",Assumptions!$B$31*(N39-Assumptions!$B$10),0)
A40: iter 22 | B40: =IF($B$4>$C$4*N39,"preference","convert") | C40: =IF($B$5>$C$5*N39,"preference","convert") | D40: =IF($B$6>$C$6*N39,"preference","convert") | E40: =IF($B$7>$C$7*N39,"preference","convert") | F40: =IF($B$8>$C$8*N39,"preference","convert") | G40: =IF($B$9>$C$9*N39,"preference","convert") | H40: =IF($B$10>$C$10*N39,"preference","convert") | I40: =IF(B40="preference",$B$4,0)+IF(C40="preference",$B$5,0)+IF(D40="preference",$B$6,0)+IF(E40="preference",$B$7,0)+IF(F40="preference",$B$8,0)+IF(G40="preference",$B$9,0)+IF(H40="preference",$B$10,0) | J40: =IF(B40="convert",$C$4,0)+IF(C40="convert",$C$5,0)+IF(D40="convert",$C$6,0)+IF(E40="convert",$C$7,0)+IF(F40="convert",$C$8,0)+IF(G40="convert",$C$9,0)+IF(H40="convert",$C$10,0) | K40: =(Assumptions!$B$46+Assumptions!$B$47+Assumptions!$B$48)+Assumptions!$B$49+('Pro-Forma'!$M$21+'Pro-Forma'!$M$22)+J40 | L40: =(B12-I40+Assumptions!$B$31*Assumptions!$B$10)/(K40+Assumptions!$B$31) | M40: =IF(L40>Assumptions!$B$10,"yes","no") | N40: =IF(M40="yes",L40,MAX(0,(B12-I40)/K40)) | O40: =IF(M40="yes",Assumptions!$B$31*(N40-Assumptions!$B$10),0)
A41: iter 23 | B41: =IF($B$4>$C$4*N40,"preference","convert") | C41: =IF($B$5>$C$5*N40,"preference","convert") | D41: =IF($B$6>$C$6*N40,"preference","convert") | E41: =IF($B$7>$C$7*N40,"preference","convert") | F41: =IF($B$8>$C$8*N40,"preference","convert") | G41: =IF($B$9>$C$9*N40,"preference","convert") | H41: =IF($B$10>$C$10*N40,"preference","convert") | I41: =IF(B41="preference",$B$4,0)+IF(C41="preference",$B$5,0)+IF(D41="preference",$B$6,0)+IF(E41="preference",$B$7,0)+IF(F41="preference",$B$8,0)+IF(G41="preference",$B$9,0)+IF(H41="preference",$B$10,0) | J41: =IF(B41="convert",$C$4,0)+IF(C41="convert",$C$5,0)+IF(D41="convert",$C$6,0)+IF(E41="convert",$C$7,0)+IF(F41="convert",$C$8,0)+IF(G41="convert",$C$9,0)+IF(H41="convert",$C$10,0) | K41: =(Assumptions!$B$46+Assumptions!$B$47+Assumptions!$B$48)+Assumptions!$B$49+('Pro-Forma'!$M$21+'Pro-Forma'!$M$22)+J41 | L41: =(B12-I41+Assumptions!$B$31*Assumptions!$B$10)/(K41+Assumptions!$B$31) | M41: =IF(L41>Assumptions!$B$10,"yes","no") | N41: =IF(M41="yes",L41,MAX(0,(B12-I41)/K41)) | O41: =IF(M41="yes",Assumptions!$B$31*(N41-Assumptions!$B$10),0)
A42: iter 24 | B42: =IF($B$4>$C$4*N41,"preference","convert") | C42: =IF($B$5>$C$5*N41,"preference","convert") | D42: =IF($B$6>$C$6*N41,"preference","convert") | E42: =IF($B$7>$C$7*N41,"preference","convert") | F42: =IF($B$8>$C$8*N41,"preference","convert") | G42: =IF($B$9>$C$9*N41,"preference","convert") | H42: =IF($B$10>$C$10*N41,"preference","convert") | I42: =IF(B42="preference",$B$4,0)+IF(C42="preference",$B$5,0)+IF(D42="preference",$B$6,0)+IF(E42="preference",$B$7,0)+IF(F42="preference",$B$8,0)+IF(G42="preference",$B$9,0)+IF(H42="preference",$B$10,0) | J42: =IF(B42="convert",$C$4,0)+IF(C42="convert",$C$5,0)+IF(D42="convert",$C$6,0)+IF(E42="convert",$C$7,0)+IF(F42="convert",$C$8,0)+IF(G42="convert",$C$9,0)+IF(H42="convert",$C$10,0) | K42: =(Assumptions!$B$46+Assumptions!$B$47+Assumptions!$B$48)+Assumptions!$B$49+('Pro-Forma'!$M$21+'Pro-Forma'!$M$22)+J42 | L42: =(B12-I42+Assumptions!$B$31*Assumptions!$B$10)/(K42+Assumptions!$B$31) | M42: =IF(L42>Assumptions!$B$10,"yes","no") | N42: =IF(M42="yes",L42,MAX(0,(B12-I42)/K42)) | O42: =IF(M42="yes",Assumptions!$B$31*(N42-Assumptions!$B$10),0)
A43: iter 25 | B43: =IF($B$4>$C$4*N42,"preference","convert") | C43: =IF($B$5>$C$5*N42,"preference","convert") | D43: =IF($B$6>$C$6*N42,"preference","convert") | E43: =IF($B$7>$C$7*N42,"preference","convert") | F43: =IF($B$8>$C$8*N42,"preference","convert") | G43: =IF($B$9>$C$9*N42,"preference","convert") | H43: =IF($B$10>$C$10*N42,"preference","convert") | I43: =IF(B43="preference",$B$4,0)+IF(C43="preference",$B$5,0)+IF(D43="preference",$B$6,0)+IF(E43="preference",$B$7,0)+IF(F43="preference",$B$8,0)+IF(G43="preference",$B$9,0)+IF(H43="preference",$B$10,0) | J43: =IF(B43="convert",$C$4,0)+IF(C43="convert",$C$5,0)+IF(D43="convert",$C$6,0)+IF(E43="convert",$C$7,0)+IF(F43="convert",$C$8,0)+IF(G43="convert",$C$9,0)+IF(H43="convert",$C$10,0) | K43: =(Assumptions!$B$46+Assumptions!$B$47+Assumptions!$B$48)+Assumptions!$B$49+('Pro-Forma'!$M$21+'Pro-Forma'!$M$22)+J43 | L43: =(B12-I43+Assumptions!$B$31*Assumptions!$B$10)/(K43+Assumptions!$B$31) | M43: =IF(L43>Assumptions!$B$10,"yes","no") | N43: =IF(M43="yes",L43,MAX(0,(B12-I43)/K43)) | O43: =IF(M43="yes",Assumptions!$B$31*(N43-Assumptions!$B$10),0)
A44: iter 26 | B44: =IF($B$4>$C$4*N43,"preference","convert") | C44: =IF($B$5>$C$5*N43,"preference","convert") | D44: =IF($B$6>$C$6*N43,"preference","convert") | E44: =IF($B$7>$C$7*N43,"preference","convert") | F44: =IF($B$8>$C$8*N43,"preference","convert") | G44: =IF($B$9>$C$9*N43,"preference","convert") | H44: =IF($B$10>$C$10*N43,"preference","convert") | I44: =IF(B44="preference",$B$4,0)+IF(C44="preference",$B$5,0)+IF(D44="preference",$B$6,0)+IF(E44="preference",$B$7,0)+IF(F44="preference",$B$8,0)+IF(G44="preference",$B$9,0)+IF(H44="preference",$B$10,0) | J44: =IF(B44="convert",$C$4,0)+IF(C44="convert",$C$5,0)+IF(D44="convert",$C$6,0)+IF(E44="convert",$C$7,0)+IF(F44="convert",$C$8,0)+IF(G44="convert",$C$9,0)+IF(H44="convert",$C$10,0) | K44: =(Assumptions!$B$46+Assumptions!$B$47+Assumptions!$B$48)+Assumptions!$B$49+('Pro-Forma'!$M$21+'Pro-Forma'!$M$22)+J44 | L44: =(B12-I44+Assumptions!$B$31*Assumptions!$B$10)/(K44+Assumptions!$B$31) | M44: =IF(L44>Assumptions!$B$10,"yes","no") | N44: =IF(M44="yes",L44,MAX(0,(B12-I44)/K44)) | O44: =IF(M44="yes",Assumptions!$B$31*(N44-Assumptions!$B$10),0)
...

Sheet Sensitivity
A1: Sensitivity Grid — Our $10M check, post-F ownership % and $ proceeds at $2B exit
A3: Each cell re-solves full round + waterfall fixed point at the cell's (ESOP, pre-money).
A6: ESOP \ Pre-money | B6: =Assumptions!$B$53 | C6: =Assumptions!$B$54 | D6: =Assumptions!$B$55
A7: =Assumptions!$B$50 | B7: =TEXT(B133*100,"0.0000")&"% / $"&TEXT(B134,"#,##0") | C7: =TEXT(B257*100,"0.0000")&"% / $"&TEXT(B258,"#,##0") | D7: =TEXT(B381*100,"0.0000")&"% / $"&TEXT(B382,"#,##0")
A8: =Assumptions!$B$51 | B8: =TEXT(B505*100,"0.0000")&"% / $"&TEXT(B506,"#,##0") | C8: =TEXT(B629*100,"0.0000")&"% / $"&TEXT(B630,"#,##0") | D8: =TEXT(B753*100,"0.0000")&"% / $"&TEXT(B754,"#,##0")
A9: =Assumptions!$B$52 | B9: =TEXT(B877*100,"0.0000")&"% / $"&TEXT(B878,"#,##0") | C9: =TEXT(B1001*100,"0.0000")&"% / $"&TEXT(B1002,"#,##0") | D9: =TEXT(B1125*100,"0.0000")&"% / $"&TEXT(B1126,"#,##0")
A13: Cell (0,0) — ESOP=low, Pre=low
A14: Step | B14: F_PPS | C14: D_NCP | D14: E_NCP | E14: ΔD | F14: ΔE | G14: ESOP | H14: N_A | I14: N_B | J14: preFD | K14: T_F | L14: F_PPS chk
A15: cell(0,0) seed | B15: =Assumptions!$B$53/Assumptions!$B$29 | C15: =Assumptions!$B$20 | D15: =Assumptions!$B$21 | E15: 0 | F15: 0 | G15: 0 | H15: 0 | I15: 0 | J15: =Assumptions!$B$29 | K15: =J15+Assumptions!$B$4/B15 | L15: =B15
A16: cell(0,0) iter 1 | B16: =Assumptions!$B$53/J15 | C16: =IF(B16<Assumptions!$B$20,Assumptions!$B$20*(Assumptions!$B$29+Assumptions!$B$4/Assumptions!$B$20)/(Assumptions!$B$29+Assumptions!$B$4/B16),Assumptions!$B$20) | D16: =IF(B16<Assumptions!$B$21,Assumptions!$B$21*(Assumptions!$B$29+Assumptions!$B$4/Assumptions!$B$21)/(Assumptions!$B$29+Assumptions!$B$4/B16),Assumptions!$B$21) | E16: =Assumptions!$B$37*Assumptions!$B$22/C16-Assumptions!$B$38 | F16: =Assumptions!$B$39*Assumptions!$B$21/D16-Assumptions!$B$39 | G16: =MAX(0,Assumptions!$B$50*(Assumptions!$B$29+E16+F16+G15+H15+I15+Assumptions!$B$4/B16)-Assumptions!$B$30) | H16: =Assumptions!$B$23/MIN(Assumptions!$B$24/(Assumptions!$B$29+E16+F16+G16+I15),B16*(1-Assumptions!$B$25)) | I16: =Assumptions!$B$26/MIN(Assumptions!$B$27/(Assumptions!$B$29+E16+F16+G16+H16),B16*(1-Assumptions!$B$28)) | J16: =Assumptions!$B$29+E16+F16+G16+H16+I16 | K16: =J16+Assumptions!$B$4/B16 | L16: =B16
A17: cell(0,0) iter 2 | B17: =Assumptions!$B$53/J16 | C17: =IF(B17<Assumptions!$B$20,Assumptions!$B$20*(Assumptions!$B$29+Assumptions!$B$4/Assumptions!$B$20)/(Assumptions!$B$29+Assumptions!$B$4/B17),Assumptions!$B$20) | D17: =IF(B17<Assumptions!$B$21,Assumptions!$B$21*(Assumptions!$B$29+Assumptions!$B$4/Assumptions!$B$21)/(Assumptions!$B$29+Assumptions!$B$4/B17),Assumptions!$B$21) | E17: =Assumptions!$B$37*Assumptions!$B$22/C17-Assumptions!$B$38 | F17: =Assumptions!$B$39*Assumptions!$B$21/D17-Assumptions!$B$39 | G17: =MAX(0,Assumptions!$B$50*(Assumptions!$B$29+E17+F17+G16+H16+I16+Assumptions!$B$4/B17)-Assumptions!$B$30) | H17: =Assumptions!$B$23/MIN(Assumptions!$B$24/(Assumptions!$B$29+E17+F17+G17+I16),B17*(1-Assumptions!$B$25)) | I17: =Assumptions!$B$26/MIN(Assumptions!$B$27/(Assumptions!$B$29+E17+F17+G17+H17),B17*(1-Assumptions!$B$28)) | J17: =Assumptions!$B$29+E17+F17+G17+H17+I17 | K17: =J17+Assumptions!$B$4/B17 | L17: =B17
A18: cell(0,0) iter 3 | B18: =Assumptions!$B$53/J17 | C18: =IF(B18<Assumptions!$B$20,Assumptions!$B$20*(Assumptions!$B$29+Assumptions!$B$4/Assumptions!$B$20)/(Assumptions!$B$29+Assumptions!$B$4/B18),Assumptions!$B$20) | D18: =IF(B18<Assumptions!$B$21,Assumptions!$B$21*(Assumptions!$B$29+Assumptions!$B$4/Assumptions!$B$21)/(Assumptions!$B$29+Assumptions!$B$4/B18),Assumptions!$B$21) | E18: =Assumptions!$B$37*Assumptions!$B$22/C18-Assumptions!$B$38 | F18: =Assumptions!$B$39*Assumptions!$B$21/D18-Assumptions!$B$39 | G18: =MAX(0,Assumptions!$B$50*(Assumptions!$B$29+E18+F18+G17+H17+I17+Assumptions!$B$4/B18)-Assumptions!$B$30) | H18: =Assumptions!$B$23/MIN(Assumptions!$B$24/(Assumptions!$B$29+E18+F18+G18+I17),B18*(1-Assumptions!$B$25)) | I18: =Assumptions!$B$26/MIN(Assumptions!$B$27/(Assumptions!$B$29+E18+F18+G18+H18),B18*(1-Assumptions!$B$28)) | J18: =Assumptions!$B$29+E18+F18+G18+H18+I18 | K18: =J18+Assumptions!$B$4/B18 | L18: =B18
A19: cell(0,0) iter 4 | B19: =Assumptions!$B$53/J18 | C19: =IF(B19<Assumptions!$B$20,Assumptions!$B$20*(Assumptions!$B$29+Assumptions!$B$4/Assumptions!$B$20)/(Assumptions!$B$29+Assumptions!$B$4/B19),Assumptions!$B$20) | D19: =IF(B19<Assumptions!$B$21,Assumptions!$B$21*(Assumptions!$B$29+Assumptions!$B$4/Assumptions!$B$21)/(Assumptions!$B$29+Assumptions!$B$4/B19),Assumptions!$B$21) | E19: =Assumptions!$B$37*Assumptions!$B$22/C19-Assumptions!$B$38 | F19: =Assumptions!$B$39*Assumptions!$B$21/D19-Assumptions!$B$39 | G19: =MAX(0,Assumptions!$B$50*(Assumptions!$B$29+E19+F19+G18+H18+I18+Assumptions!$B$4/B19)-Assumptions!$B$30) | H19: =Assumptions!$B$23/MIN(Assumptions!$B$24/(Assumptions!$B$29+E19+F19+G19+I18),B19*(1-Assumptions!$B$25)) | I19: =Assumptions!$B$26/MIN(Assumptions!$B$27/(Assumptions!$B$29+E19+F19+G19+H19),B19*(1-Assumptions!$B$28)) | J19: =Assumptions!$B$29+E19+F19+G19+H19+I19 | K19: =J19+Assumptions!$B$4/B19 | L19: =B19
A20: cell(0,0) iter 5 | B20: =Assumptions!$B$53/J19 | C20: =IF(B20<Assumptions!$B$20,Assumptions!$B$20*(Assumptions!$B$29+Assumptions!$B$4/Assumptions!$B$20)/(Assumptions!$B$29+Assumptions!$B$4/B20),Assumptions!$B$20) | D20: =IF(B20<Assumptions!$B$21,Assumptions!$B$21*(Assumptions!$B$29+Assumptions!$B$4/Assumptions!$B$21)/(Assumptions!$B$29+Assumptions!$B$4/B20),Assumptions!$B$21) | E20: =Assumptions!$B$37*Assumptions!$B$22/C20-Assumptions!$B$38 | F20: =Assumptions!$B$39*Assumptions!$B$21/D20-Assumptions!$B$39 | G20: =MAX(0,Assumptions!$B$50*(Assumptions!$B$29+E20+F20+G19+H19+I19+Assumptions!$B$4/B20)-Assumptions!$B$30) | H20: =Assumptions!$B$23/MIN(Assumptions!$B$24/(Assumptions!$B$29+E20+F20+G20+I19),B20*(1-Assumptions!$B$25)) | I20: =Assumptions!$B$26/MIN(Assumptions!$B$27/(Assumptions!$B$29+E20+F20+G20+H20),B20*(1-Assumptions!$B$28)) | J20: =Assumptions!$B$29+E20+F20+G20+H20+I20 | K20: =J20+Assumptions!$B$4/B20 | L20: =B20
A21: cell(0,0) iter 6 | B21: =Assumptions!$B$53/J20 | C21: =IF(B21<Assumptions!$B$20,Assumptions!$B$20*(Assumptions!$B$29+Assumptions!$B$4/Assumptions!$B$20)/(Assumptions!$B$29+Assumptions!$B$4/B21),Assumptions!$B$20) | D21: =IF(B21<Assumptions!$B$21,Assumptions!$B$21*(Assumptions!$B$29+Assumptions!$B$4/Assumptions!$B$21)/(Assumptions!$B$29+Assumptions!$B$4/B21),Assumptions!$B$21) | E21: =Assumptions!$B$37*Assumptions!$B$22/C21-Assumptions!$B$38 | F21: =Assumptions!$B$39*Assumptions!$B$21/D21-Assumptions!$B$39 | G21: =MAX(0,Assumptions!$B$50*(Assumptions!$B$29+E21+F21+G20+H20+I20+Assumptions!$B$4/B21)-Assumptions!$B$30) | H21: =Assumptions!$B$23/MIN(Assumptions!$B$24/(Assumptions!$B$29+E21+F21+G21+I20),B21*(1-Assumptions!$B$25)) | I21: =Assumptions!$B$26/MIN(Assumptions!$B$27/(Assumptions!$B$29+E21+F21+G21+H21),B21*(1-Assumptions!$B$28)) | J21: =Assumptions!$B$29+E21+F21+G21+H21+I21 | K21: =J21+Assumptions!$B$4/B21 | L21: =B21
A22: cell(0,0) iter 7 | B22: =Assumptions!$B$53/J21 | C22: =IF(B22<Assumptions!$B$20,Assumptions!$B$20*(Assumptions!$B$29+Assumptions!$B$4/Assumptions!$B$20)/(Assumptions!$B$29+Assumptions!$B$4/B22),Assumptions!$B$20) | D22: =IF(B22<Assumptions!$B$21,Assumptions!$B$21*(Assumptions!$B$29+Assumptions!$B$4/Assumptions!$B$21)/(Assumptions!$B$29+Assumptions!$B$4/B22),Assumptions!$B$21) | E22: =Assumptions!$B$37*Assumptions!$B$22/C22-Assumptions!$B$38 | F22: =Assumptions!$B$39*Assumptions!$B$21/D22-Assumptions!$B$39 | G22: =MAX(0,Assumptions!$B$50*(Assumptions!$B$29+E22+F22+G21+H21+I21+Assumptions!$B$4/B22)-Assumptions!$B$30) | H22: =Assumptions!$B$23/MIN(Assumptions!$B$24/(Assumptions!$B$29+E22+F22+G22+I21),B22*(1-Assumptions!$B$25)) | I22: =Assumptions!$B$26/MIN(Assumptions!$B$27/(Assumptions!$B$29+E22+F22+G22+H22),B22*(1-Assumptions!$B$28)) | J22: =Assumptions!$B$29+E22+F22+G22+H22+I22 | K22: =J22+Assumptions!$B$4/B22 | L22: =B22
A23: cell(0,0) iter 8 | B23: =Assumptions!$B$53/J22 | C23: =IF(B23<Assumptions!$B$20,Assumptions!$B$20*(Assumptions!$B$29+Assumptions!$B$4/Assumptions!$B$20)/(Assumptions!$B$29+Assumptions!$B$4/B23),Assumptions!$B$20) | D23: =IF(B23<Assumptions!$B$21,Assumptions!$B$21*(Assumptions!$B$29+Assumptions!$B$4/Assumptions!$B$21)/(Assumptions!$B$29+Assumptions!$B$4/B23),Assumptions!$B$21) | E23: =Assumptions!$B$37*Assumptions!$B$22/C23-Assumptions!$B$38 | F23: =Assumptions!$B$39*Assumptions!$B$21/D23-Assumptions!$B$39 | G23: =MAX(0,Assumptions!$B$50*(Assumptions!$B$29+E23+F23+G22+H22+I22+Assumptions!$B$4/B23)-Assumptions!$B$30) | H23: =Assumptions!$B$23/MIN(Assumptions!$B$24/(Assumptions!$B$29+E23+F23+G23+I22),B23*(1-Assumptions!$B$25)) | I23: =Assumptions!$B$26/MIN(Assumptions!$B$27/(Assumptions!$B$29+E23+F23+G23+H23),B23*(1-Assumptions!$B$28)) | J23: =Assumptions!$B$29+E23+F23+G23+H23+I23 | K23: =J23+Assumptions!$B$4/B23 | L23: =B23
A24: cell(0,0) iter 9 | B24: =Assumptions!$B$53/J23 | C24: =IF(B24<Assumptions!$B$20,Assumptions!$B$20*(Assumptions!$B$29+Assumptions!$B$4/Assumptions!$B$20)/(Assumptions!$B$29+Assumptions!$B$4/B24),Assumptions!$B$20) | D24: =IF(B24<Assumptions!$B$21,Assumptions!$B$21*(Assumptions!$B$29+Assumptions!$B$4/Assumptions!$B$21)/(Assumptions!$B$29+Assumptions!$B$4/B24),Assumptions!$B$21) | E24: =Assumptions!$B$37*Assumptions!$B$22/C24-Assumptions!$B$38 | F24: =Assumptions!$B$39*Assumptions!$B$21/D24-Assumptions!$B$39 | G24: =MAX(0,Assumptions!$B$50*(Assumptions!$B$29+E24+F24+G23+H23+I23+Assumptions!$B$4/B24)-Assumptions!$B$30) | H24: =Assumptions!$B$23/MIN(Assumptions!$B$24/(Assumptions!$B$29+E24+F24+G24+I23),B24*(1-Assumptions!$B$25)) | I24: =Assumptions!$B$26/MIN(Assumptions!$B$27/(Assumptions!$B$29+E24+F24+G24+H24),B24*(1-Assumptions!$B$28)) | J24: =Assumptions!$B$29+E24+F24+G24+H24+I24 | K24: =J24+Assumptions!$B$4/B24 | L24: =B24
A25: cell(0,0) iter 10 | B25: =Assumptions!$B$53/J24 | C25: =IF(B25<Assumptions!$B$20,Assumptions!$B$20*(Assumptions!$B$29+Assumptions!$B$4/Assumptions!$B$20)/(Assumptions!$B$29+Assumptions!$B$4/B25),Assumptions!$B$20) | D25: =IF(B25<Assumptions!$B$21,Assumptions!$B$21*(Assumptions!$B$29+Assumptions!$B$4/Assumptions!$B$21)/(Assumptions!$B$29+Assumptions!$B$4/B25),Assumptions!$B$21) | E25: =Assumptions!$B$37*Assumptions!$B$22/C25-Assumptions!$B$38 | F25: =Assumptions!$B$39*Assumptions!$B$21/D25-Assumptions!$B$39 | G25: =MAX(0,Assumptions!$B$50*(Assumptions!$B$29+E25+F25+G24+H24+I24+Assumptions!$B$4/B25)-Assumptions!$B$30) | H25: =Assumptions!$B$23/MIN(Assumptions!$B$24/(Assumptions!$B$29+E25+F25+G25+I24),B25*(1-Assumptions!$B$25)) | I25: =Assumptions!$B$26/MIN(Assumptions!$B$27/(Assumptions!$B$29+E25+F25+G25+H25),B25*(1-Assumptions!$B$28)) | J25: =Assumptions!$B$29+E25+F25+G25+H25+I25 | K25: =J25+Assumptions!$B$4/B25 | L25: =B25
A26: cell(0,0) iter 11 | B26: =Assumptions!$B$53/J25 | C26: =IF(B26<Assumptions!$B$20,Assumptions!$B$20*(Assumptions!$B$29+Assumptions!$B$4/Assumptions!$B$20)/(Assumptions!$B$29+Assumptions!$B$4/B26),Assumptions!$B$20) | D26: =IF(B26<Assumptions!$B$21,Assumptions!$B$21*(Assumptions!$B$29+Assumptions!$B$4/Assumptions!$B$21)/(Assumptions!$B$29+Assumptions!$B$4/B26),Assumptions!$B$21) | E26: =Assumptions!$B$37*Assumptions!$B$22/C26-Assumptions!$B$38 | F26: =Assumptions!$B$39*Assumptions!$B$21/D26-Assumptions!$B$39 | G26: =MAX(0,Assumptions!$B$50*(Assumptions!$B$29+E26+F26+G25+H25+I25+Assumptions!$B$4/B26)-Assumptions!$B$30) | H26: =Assumptions!$B$23/MIN(Assumptions!$B$24/(Assumptions!$B$29+E26+F26+G26+I25),B26*(1-Assumptions!$B$25)) | I26: =Assumptions!$B$26/MIN(Assumptions!$B$27/(Assumptions!$B$29+E26+F26+G26+H26),B26*(1-Assumptions!$B$28)) | J26: =Assumptions!$B$29+E26+F26+G26+H26+I26 | K26: =J26+Assumptions!$B$4/B26 | L26: =B26
