Workbook

Sheet Assumptions
A1: Kelvin Dynamics — Series F Analysis Assumptions
A3: ROUND TERMS
A4: Series F pre-money (USD) | B4: 1400000000 | C4: Knob
A5: Series F primary raise (USD) | B5: 30000000
A6: Series F secondary raise (USD) | B6: 15000000 | C6: Tender
A7: Tender PPS multiplier | B7: 0.85 | C7: Tender PPS = mult × F_PPS
A8: ESOP refresh target (post-F FD) | B8: 0.13
A9: Our fund check (USD) | B9: 10000000 | C9: 1/3 of primary
A10: F_LEAD primary check (USD) | B10: 20000000 | C10: 2/3 of primary
A11: Option strike (USD) | B11: 1
A13: EXIT SCENARIOS
A14: Exit 1 (USD) | B14: 700000000
A15: Exit 2 (USD) | B15: 1200000000
A16: Exit 3 (USD) | B16: 2000000000 | C16: Sensitivity ref
A17: Exit 4 (USD) | B17: 4000000000
A18: Exit 5 (USD) | B18: 8000000000
A20: PRIOR-ROUND OCPs
A21: Seed OCP | B21: 1
A22: Series A OCP | B22: 3
A23: Series B OCP | B23: 10
A24: Series C OCP | B24: 25
A25: Series D OCP (post-E NCP) | B25: 58.118347 | C25: AD-effective
A26: Series D original OCP | B26: 60
A27: Series E OCP | B27: 49.158311
A29: PRE-F SHARE COUNTS
A30: Founder F1 common | B30: 4000000 | C30: CEO 50%
A31: Founder F2 common | B31: 2500000 | C31: CTO 31.25%
A32: Founder F3 common | B32: 1500000 | C32: CSO 18.75%
A33: Employee RSAs total | B33: 1000000 | C33: 10×100K
A34: Seed preferred shares | B34: 5000000
A35: Series A preferred shares | B35: 5000000
A36: Series B preferred shares | B36: 3000000
A37: Series C preferred shares | B37: 2400000
A38: Series D preferred shares (orig) | B38: 1666667 | C38: Issued at $60
A39: Series D preferred shares (post-E) | B39: 1720627 | C39: After E AD
A40: Series E preferred shares | B40: 6102667
A41: Pre-F issued options | B41: 2500000
A42: Pre-F unissued options | B42: 1894667
A43: Pre-F total options pool | B43: 4394667
A44: Pre-F broad-based FD total | B44: 36617961 | C44: AD denominator A
...

Sheet Pro-Forma
A1: Pro-Forma Cap Table — Post Series F Closing
A3: Pro-Forma Solver — Base Case
A4: Iter | B4: F_PPS | C4: F_prim_shares | D4: NCP_E | E4: new_E_shares | F4: AD_inc_E | G4: NCP_D | H4: new_D_shares | I4: AD_inc_D | J4: ESOP_topup | K4: cap_FD_A | L4: cap_pps_A | M4: disc_pps_A | N4: conv_pps_A | O4: N_A | P4: cap_FD_B | Q4: cap_pps_B | R4: disc_pps_B | S4: conv_pps_B | T4: N_B | U4: pre_money_FD | V4: T_F
A5: 0 | B5: ='Assumptions'!$B$4/'Assumptions'!$B$44 | C5: ='Assumptions'!$B$5/$B$5 | D5: ='Assumptions'!$B$27*('Assumptions'!$B$44+'Assumptions'!$B$5/'Assumptions'!$B$27)/('Assumptions'!$B$44+'Assumptions'!$B$5/$B$5) | E5: ='Assumptions'!$B$40*'Assumptions'!$B$27/$D$5 | F5: =$E$5-'Assumptions'!$B$40 | G5: ='Assumptions'!$B$25*('Assumptions'!$B$44+'Assumptions'!$B$5/'Assumptions'!$B$25)/('Assumptions'!$B$44+'Assumptions'!$B$5/$B$5) | H5: ='Assumptions'!$B$38*'Assumptions'!$B$26/$G$5 | I5: =$H$5-'Assumptions'!$B$39 | J5: =MAX(0,'Assumptions'!$B$8*('Assumptions'!$B$44+$F$5+$I$5+$C$5)/(1-'Assumptions'!$B$8)-'Assumptions'!$B$43) | K5: ='Assumptions'!$B$44+$J$5+$F$5+$I$5+0 | L5: ='Assumptions'!$B$57/$K$5 | M5: =$B$5*(1-'Assumptions'!$B$58) | N5: =MIN($L$5,$M$5) | O5: ='Assumptions'!$B$56/$N$5 | P5: ='Assumptions'!$B$44+$J$5+$F$5+$I$5+$O$5 | Q5: ='Assumptions'!$B$60/$P$5 | R5: =$B$5*(1-'Assumptions'!$B$61) | S5: =MIN($Q$5,$R$5) | T5: ='Assumptions'!$B$59/$S$5 | U5: ='Assumptions'!$B$44+$J$5+$F$5+$I$5+$O$5+$T$5 | V5: =$U$5+$C$5
A6: 1 | B6: ='Assumptions'!$B$4/$U$5 | C6: ='Assumptions'!$B$5/$B$6 | D6: ='Assumptions'!$B$27*('Assumptions'!$B$44+'Assumptions'!$B$5/'Assumptions'!$B$27)/('Assumptions'!$B$44+'Assumptions'!$B$5/$B$6) | E6: ='Assumptions'!$B$40*'Assumptions'!$B$27/$D$6 | F6: =$E$6-'Assumptions'!$B$40 | G6: ='Assumptions'!$B$25*('Assumptions'!$B$44+'Assumptions'!$B$5/'Assumptions'!$B$25)/('Assumptions'!$B$44+'Assumptions'!$B$5/$B$6) | H6: ='Assumptions'!$B$38*'Assumptions'!$B$26/$G$6 | I6: =$H$6-'Assumptions'!$B$39 | J6: =MAX(0,'Assumptions'!$B$8*$V$5-'Assumptions'!$B$43) | K6: ='Assumptions'!$B$44+$J$6+$F$6+$I$6+$T$5 | L6: ='Assumptions'!$B$57/$K$6 | M6: =$B$6*(1-'Assumptions'!$B$58) | N6: =MIN($L$6,$M$6) | O6: ='Assumptions'!$B$56/$N$6 | P6: ='Assumptions'!$B$44+$J$6+$F$6+$I$6+$O$6 | Q6: ='Assumptions'!$B$60/$P$6 | R6: =$B$6*(1-'Assumptions'!$B$61) | S6: =MIN($Q$6,$R$6) | T6: ='Assumptions'!$B$59/$S$6 | U6: ='Assumptions'!$B$44+$J$6+$F$6+$I$6+$O$6+$T$6 | V6: =$U$6+$C$6
A7: 2 | B7: ='Assumptions'!$B$4/$U$6 | C7: ='Assumptions'!$B$5/$B$7 | D7: ='Assumptions'!$B$27*('Assumptions'!$B$44+'Assumptions'!$B$5/'Assumptions'!$B$27)/('Assumptions'!$B$44+'Assumptions'!$B$5/$B$7) | E7: ='Assumptions'!$B$40*'Assumptions'!$B$27/$D$7 | F7: =$E$7-'Assumptions'!$B$40 | G7: ='Assumptions'!$B$25*('Assumptions'!$B$44+'Assumptions'!$B$5/'Assumptions'!$B$25)/('Assumptions'!$B$44+'Assumptions'!$B$5/$B$7) | H7: ='Assumptions'!$B$38*'Assumptions'!$B$26/$G$7 | I7: =$H$7-'Assumptions'!$B$39 | J7: =MAX(0,'Assumptions'!$B$8*$V$6-'Assumptions'!$B$43) | K7: ='Assumptions'!$B$44+$J$7+$F$7+$I$7+$T$6 | L7: ='Assumptions'!$B$57/$K$7 | M7: =$B$7*(1-'Assumptions'!$B$58) | N7: =MIN($L$7,$M$7) | O7: ='Assumptions'!$B$56/$N$7 | P7: ='Assumptions'!$B$44+$J$7+$F$7+$I$7+$O$7 | Q7: ='Assumptions'!$B$60/$P$7 | R7: =$B$7*(1-'Assumptions'!$B$61) | S7: =MIN($Q$7,$R$7) | T7: ='Assumptions'!$B$59/$S$7 | U7: ='Assumptions'!$B$44+$J$7+$F$7+$I$7+$O$7+$T$7 | V7: =$U$7+$C$7
A8: 3 | B8: ='Assumptions'!$B$4/$U$7 | C8: ='Assumptions'!$B$5/$B$8 | D8: ='Assumptions'!$B$27*('Assumptions'!$B$44+'Assumptions'!$B$5/'Assumptions'!$B$27)/('Assumptions'!$B$44+'Assumptions'!$B$5/$B$8) | E8: ='Assumptions'!$B$40*'Assumptions'!$B$27/$D$8 | F8: =$E$8-'Assumptions'!$B$40 | G8: ='Assumptions'!$B$25*('Assumptions'!$B$44+'Assumptions'!$B$5/'Assumptions'!$B$25)/('Assumptions'!$B$44+'Assumptions'!$B$5/$B$8) | H8: ='Assumptions'!$B$38*'Assumptions'!$B$26/$G$8 | I8: =$H$8-'Assumptions'!$B$39 | J8: =MAX(0,'Assumptions'!$B$8*$V$7-'Assumptions'!$B$43) | K8: ='Assumptions'!$B$44+$J$8+$F$8+$I$8+$T$7 | L8: ='Assumptions'!$B$57/$K$8 | M8: =$B$8*(1-'Assumptions'!$B$58) | N8: =MIN($L$8,$M$8) | O8: ='Assumptions'!$B$56/$N$8 | P8: ='Assumptions'!$B$44+$J$8+$F$8+$I$8+$O$8 | Q8: ='Assumptions'!$B$60/$P$8 | R8: =$B$8*(1-'Assumptions'!$B$61) | S8: =MIN($Q$8,$R$8) | T8: ='Assumptions'!$B$59/$S$8 | U8: ='Assumptions'!$B$44+$J$8+$F$8+$I$8+$O$8+$T$8 | V8: =$U$8+$C$8
A9: 4 | B9: ='Assumptions'!$B$4/$U$8 | C9: ='Assumptions'!$B$5/$B$9 | D9: ='Assumptions'!$B$27*('Assumptions'!$B$44+'Assumptions'!$B$5/'Assumptions'!$B$27)/('Assumptions'!$B$44+'Assumptions'!$B$5/$B$9) | E9: ='Assumptions'!$B$40*'Assumptions'!$B$27/$D$9 | F9: =$E$9-'Assumptions'!$B$40 | G9: ='Assumptions'!$B$25*('Assumptions'!$B$44+'Assumptions'!$B$5/'Assumptions'!$B$25)/('Assumptions'!$B$44+'Assumptions'!$B$5/$B$9) | H9: ='Assumptions'!$B$38*'Assumptions'!$B$26/$G$9 | I9: =$H$9-'Assumptions'!$B$39 | J9: =MAX(0,'Assumptions'!$B$8*$V$8-'Assumptions'!$B$43) | K9: ='Assumptions'!$B$44+$J$9+$F$9+$I$9+$T$8 | L9: ='Assumptions'!$B$57/$K$9 | M9: =$B$9*(1-'Assumptions'!$B$58) | N9: =MIN($L$9,$M$9) | O9: ='Assumptions'!$B$56/$N$9 | P9: ='Assumptions'!$B$44+$J$9+$F$9+$I$9+$O$9 | Q9: ='Assumptions'!$B$60/$P$9 | R9: =$B$9*(1-'Assumptions'!$B$61) | S9: =MIN($Q$9,$R$9) | T9: ='Assumptions'!$B$59/$S$9 | U9: ='Assumptions'!$B$44+$J$9+$F$9+$I$9+$O$9+$T$9 | V9: =$U$9+$C$9
A10: 5 | B10: ='Assumptions'!$B$4/$U$9 | C10: ='Assumptions'!$B$5/$B$10 | D10: ='Assumptions'!$B$27*('Assumptions'!$B$44+'Assumptions'!$B$5/'Assumptions'!$B$27)/('Assumptions'!$B$44+'Assumptions'!$B$5/$B$10) | E10: ='Assumptions'!$B$40*'Assumptions'!$B$27/$D$10 | F10: =$E$10-'Assumptions'!$B$40 | G10: ='Assumptions'!$B$25*('Assumptions'!$B$44+'Assumptions'!$B$5/'Assumptions'!$B$25)/('Assumptions'!$B$44+'Assumptions'!$B$5/$B$10) | H10: ='Assumptions'!$B$38*'Assumptions'!$B$26/$G$10 | I10: =$H$10-'Assumptions'!$B$39 | J10: =MAX(0,'Assumptions'!$B$8*$V$9-'Assumptions'!$B$43) | K10: ='Assumptions'!$B$44+$J$10+$F$10+$I$10+$T$9 | L10: ='Assumptions'!$B$57/$K$10 | M10: =$B$10*(1-'Assumptions'!$B$58) | N10: =MIN($L$10,$M$10) | O10: ='Assumptions'!$B$56/$N$10 | P10: ='Assumptions'!$B$44+$J$10+$F$10+$I$10+$O$10 | Q10: ='Assumptions'!$B$60/$P$10 | R10: =$B$10*(1-'Assumptions'!$B$61) | S10: =MIN($Q$10,$R$10) | T10: ='Assumptions'!$B$59/$S$10 | U10: ='Assumptions'!$B$44+$J$10+$F$10+$I$10+$O$10+$T$10 | V10: =$U$10+$C$10
A11: 6 | B11: ='Assumptions'!$B$4/$U$10 | C11: ='Assumptions'!$B$5/$B$11 | D11: ='Assumptions'!$B$27*('Assumptions'!$B$44+'Assumptions'!$B$5/'Assumptions'!$B$27)/('Assumptions'!$B$44+'Assumptions'!$B$5/$B$11) | E11: ='Assumptions'!$B$40*'Assumptions'!$B$27/$D$11 | F11: =$E$11-'Assumptions'!$B$40 | G11: ='Assumptions'!$B$25*('Assumptions'!$B$44+'Assumptions'!$B$5/'Assumptions'!$B$25)/('Assumptions'!$B$44+'Assumptions'!$B$5/$B$11) | H11: ='Assumptions'!$B$38*'Assumptions'!$B$26/$G$11 | I11: =$H$11-'Assumptions'!$B$39 | J11: =MAX(0,'Assumptions'!$B$8*$V$10-'Assumptions'!$B$43) | K11: ='Assumptions'!$B$44+$J$11+$F$11+$I$11+$T$10 | L11: ='Assumptions'!$B$57/$K$11 | M11: =$B$11*(1-'Assumptions'!$B$58) | N11: =MIN($L$11,$M$11) | O11: ='Assumptions'!$B$56/$N$11 | P11: ='Assumptions'!$B$44+$J$11+$F$11+$I$11+$O$11 | Q11: ='Assumptions'!$B$60/$P$11 | R11: =$B$11*(1-'Assumptions'!$B$61) | S11: =MIN($Q$11,$R$11) | T11: ='Assumptions'!$B$59/$S$11 | U11: ='Assumptions'!$B$44+$J$11+$F$11+$I$11+$O$11+$T$11 | V11: =$U$11+$C$11
A12: 7 | B12: ='Assumptions'!$B$4/$U$11 | C12: ='Assumptions'!$B$5/$B$12 | D12: ='Assumptions'!$B$27*('Assumptions'!$B$44+'Assumptions'!$B$5/'Assumptions'!$B$27)/('Assumptions'!$B$44+'Assumptions'!$B$5/$B$12) | E12: ='Assumptions'!$B$40*'Assumptions'!$B$27/$D$12 | F12: =$E$12-'Assumptions'!$B$40 | G12: ='Assumptions'!$B$25*('Assumptions'!$B$44+'Assumptions'!$B$5/'Assumptions'!$B$25)/('Assumptions'!$B$44+'Assumptions'!$B$5/$B$12) | H12: ='Assumptions'!$B$38*'Assumptions'!$B$26/$G$12 | I12: =$H$12-'Assumptions'!$B$39 | J12: =MAX(0,'Assumptions'!$B$8*$V$11-'Assumptions'!$B$43) | K12: ='Assumptions'!$B$44+$J$12+$F$12+$I$12+$T$11 | L12: ='Assumptions'!$B$57/$K$12 | M12: =$B$12*(1-'Assumptions'!$B$58) | N12: =MIN($L$12,$M$12) | O12: ='Assumptions'!$B$56/$N$12 | P12: ='Assumptions'!$B$44+$J$12+$F$12+$I$12+$O$12 | Q12: ='Assumptions'!$B$60/$P$12 | R12: =$B$12*(1-'Assumptions'!$B$61) | S12: =MIN($Q$12,$R$12) | T12: ='Assumptions'!$B$59/$S$12 | U12: ='Assumptions'!$B$44+$J$12+$F$12+$I$12+$O$12+$T$12 | V12: =$U$12+$C$12
A13: 8 | B13: ='Assumptions'!$B$4/$U$12 | C13: ='Assumptions'!$B$5/$B$13 | D13: ='Assumptions'!$B$27*('Assumptions'!$B$44+'Assumptions'!$B$5/'Assumptions'!$B$27)/('Assumptions'!$B$44+'Assumptions'!$B$5/$B$13) | E13: ='Assumptions'!$B$40*'Assumptions'!$B$27/$D$13 | F13: =$E$13-'Assumptions'!$B$40 | G13: ='Assumptions'!$B$25*('Assumptions'!$B$44+'Assumptions'!$B$5/'Assumptions'!$B$25)/('Assumptions'!$B$44+'Assumptions'!$B$5/$B$13) | H13: ='Assumptions'!$B$38*'Assumptions'!$B$26/$G$13 | I13: =$H$13-'Assumptions'!$B$39 | J13: =MAX(0,'Assumptions'!$B$8*$V$12-'Assumptions'!$B$43) | K13: ='Assumptions'!$B$44+$J$13+$F$13+$I$13+$T$12 | L13: ='Assumptions'!$B$57/$K$13 | M13: =$B$13*(1-'Assumptions'!$B$58) | N13: =MIN($L$13,$M$13) | O13: ='Assumptions'!$B$56/$N$13 | P13: ='Assumptions'!$B$44+$J$13+$F$13+$I$13+$O$13 | Q13: ='Assumptions'!$B$60/$P$13 | R13: =$B$13*(1-'Assumptions'!$B$61) | S13: =MIN($Q$13,$R$13) | T13: ='Assumptions'!$B$59/$S$13 | U13: ='Assumptions'!$B$44+$J$13+$F$13+$I$13+$O$13+$T$13 | V13: =$U$13+$C$13
A14: 9 | B14: ='Assumptions'!$B$4/$U$13 | C14: ='Assumptions'!$B$5/$B$14 | D14: ='Assumptions'!$B$27*('Assumptions'!$B$44+'Assumptions'!$B$5/'Assumptions'!$B$27)/('Assumptions'!$B$44+'Assumptions'!$B$5/$B$14) | E14: ='Assumptions'!$B$40*'Assumptions'!$B$27/$D$14 | F14: =$E$14-'Assumptions'!$B$40 | G14: ='Assumptions'!$B$25*('Assumptions'!$B$44+'Assumptions'!$B$5/'Assumptions'!$B$25)/('Assumptions'!$B$44+'Assumptions'!$B$5/$B$14) | H14: ='Assumptions'!$B$38*'Assumptions'!$B$26/$G$14 | I14: =$H$14-'Assumptions'!$B$39 | J14: =MAX(0,'Assumptions'!$B$8*$V$13-'Assumptions'!$B$43) | K14: ='Assumptions'!$B$44+$J$14+$F$14+$I$14+$T$13 | L14: ='Assumptions'!$B$57/$K$14 | M14: =$B$14*(1-'Assumptions'!$B$58) | N14: =MIN($L$14,$M$14) | O14: ='Assumptions'!$B$56/$N$14 | P14: ='Assumptions'!$B$44+$J$14+$F$14+$I$14+$O$14 | Q14: ='Assumptions'!$B$60/$P$14 | R14: =$B$14*(1-'Assumptions'!$B$61) | S14: =MIN($Q$14,$R$14) | T14: ='Assumptions'!$B$59/$S$14 | U14: ='Assumptions'!$B$44+$J$14+$F$14+$I$14+$O$14+$T$14 | V14: =$U$14+$C$14
A15: 10 | B15: ='Assumptions'!$B$4/$U$14 | C15: ='Assumptions'!$B$5/$B$15 | D15: ='Assumptions'!$B$27*('Assumptions'!$B$44+'Assumptions'!$B$5/'Assumptions'!$B$27)/('Assumptions'!$B$44+'Assumptions'!$B$5/$B$15) | E15: ='Assumptions'!$B$40*'Assumptions'!$B$27/$D$15 | F15: =$E$15-'Assumptions'!$B$40 | G15: ='Assumptions'!$B$25*('Assumptions'!$B$44+'Assumptions'!$B$5/'Assumptions'!$B$25)/('Assumptions'!$B$44+'Assumptions'!$B$5/$B$15) | H15: ='Assumptions'!$B$38*'Assumptions'!$B$26/$G$15 | I15: =$H$15-'Assumptions'!$B$39 | J15: =MAX(0,'Assumptions'!$B$8*$V$14-'Assumptions'!$B$43) | K15: ='Assumptions'!$B$44+$J$15+$F$15+$I$15+$T$14 | L15: ='Assumptions'!$B$57/$K$15 | M15: =$B$15*(1-'Assumptions'!$B$58) | N15: =MIN($L$15,$M$15) | O15: ='Assumptions'!$B$56/$N$15 | P15: ='Assumptions'!$B$44+$J$15+$F$15+$I$15+$O$15 | Q15: ='Assumptions'!$B$60/$P$15 | R15: =$B$15*(1-'Assumptions'!$B$61) | S15: =MIN($Q$15,$R$15) | T15: ='Assumptions'!$B$59/$S$15 | U15: ='Assumptions'!$B$44+$J$15+$F$15+$I$15+$O$15+$T$15 | V15: =$U$15+$C$15
A16: 11 | B16: ='Assumptions'!$B$4/$U$15 | C16: ='Assumptions'!$B$5/$B$16 | D16: ='Assumptions'!$B$27*('Assumptions'!$B$44+'Assumptions'!$B$5/'Assumptions'!$B$27)/('Assumptions'!$B$44+'Assumptions'!$B$5/$B$16) | E16: ='Assumptions'!$B$40*'Assumptions'!$B$27/$D$16 | F16: =$E$16-'Assumptions'!$B$40 | G16: ='Assumptions'!$B$25*('Assumptions'!$B$44+'Assumptions'!$B$5/'Assumptions'!$B$25)/('Assumptions'!$B$44+'Assumptions'!$B$5/$B$16) | H16: ='Assumptions'!$B$38*'Assumptions'!$B$26/$G$16 | I16: =$H$16-'Assumptions'!$B$39 | J16: =MAX(0,'Assumptions'!$B$8*$V$15-'Assumptions'!$B$43) | K16: ='Assumptions'!$B$44+$J$16+$F$16+$I$16+$T$15 | L16: ='Assumptions'!$B$57/$K$16 | M16: =$B$16*(1-'Assumptions'!$B$58) | N16: =MIN($L$16,$M$16) | O16: ='Assumptions'!$B$56/$N$16 | P16: ='Assumptions'!$B$44+$J$16+$F$16+$I$16+$O$16 | Q16: ='Assumptions'!$B$60/$P$16 | R16: =$B$16*(1-'Assumptions'!$B$61) | S16: =MIN($Q$16,$R$16) | T16: ='Assumptions'!$B$59/$S$16 | U16: ='Assumptions'!$B$44+$J$16+$F$16+$I$16+$O$16+$T$16 | V16: =$U$16+$C$16
A17: 12 | B17: ='Assumptions'!$B$4/$U$16 | C17: ='Assumptions'!$B$5/$B$17 | D17: ='Assumptions'!$B$27*('Assumptions'!$B$44+'Assumptions'!$B$5/'Assumptions'!$B$27)/('Assumptions'!$B$44+'Assumptions'!$B$5/$B$17) | E17: ='Assumptions'!$B$40*'Assumptions'!$B$27/$D$17 | F17: =$E$17-'Assumptions'!$B$40 | G17: ='Assumptions'!$B$25*('Assumptions'!$B$44+'Assumptions'!$B$5/'Assumptions'!$B$25)/('Assumptions'!$B$44+'Assumptions'!$B$5/$B$17) | H17: ='Assumptions'!$B$38*'Assumptions'!$B$26/$G$17 | I17: =$H$17-'Assumptions'!$B$39 | J17: =MAX(0,'Assumptions'!$B$8*$V$16-'Assumptions'!$B$43) | K17: ='Assumptions'!$B$44+$J$17+$F$17+$I$17+$T$16 | L17: ='Assumptions'!$B$57/$K$17 | M17: =$B$17*(1-'Assumptions'!$B$58) | N17: =MIN($L$17,$M$17) | O17: ='Assumptions'!$B$56/$N$17 | P17: ='Assumptions'!$B$44+$J$17+$F$17+$I$17+$O$17 | Q17: ='Assumptions'!$B$60/$P$17 | R17: =$B$17*(1-'Assumptions'!$B$61) | S17: =MIN($Q$17,$R$17) | T17: ='Assumptions'!$B$59/$S$17 | U17: ='Assumptions'!$B$44+$J$17+$F$17+$I$17+$O$17+$T$17 | V17: =$U$17+$C$17
A18: 13 | B18: ='Assumptions'!$B$4/$U$17 | C18: ='Assumptions'!$B$5/$B$18 | D18: ='Assumptions'!$B$27*('Assumptions'!$B$44+'Assumptions'!$B$5/'Assumptions'!$B$27)/('Assumptions'!$B$44+'Assumptions'!$B$5/$B$18) | E18: ='Assumptions'!$B$40*'Assumptions'!$B$27/$D$18 | F18: =$E$18-'Assumptions'!$B$40 | G18: ='Assumptions'!$B$25*('Assumptions'!$B$44+'Assumptions'!$B$5/'Assumptions'!$B$25)/('Assumptions'!$B$44+'Assumptions'!$B$5/$B$18) | H18: ='Assumptions'!$B$38*'Assumptions'!$B$26/$G$18 | I18: =$H$18-'Assumptions'!$B$39 | J18: =MAX(0,'Assumptions'!$B$8*$V$17-'Assumptions'!$B$43) | K18: ='Assumptions'!$B$44+$J$18+$F$18+$I$18+$T$17 | L18: ='Assumptions'!$B$57/$K$18 | M18: =$B$18*(1-'Assumptions'!$B$58) | N18: =MIN($L$18,$M$18) | O18: ='Assumptions'!$B$56/$N$18 | P18: ='Assumptions'!$B$44+$J$18+$F$18+$I$18+$O$18 | Q18: ='Assumptions'!$B$60/$P$18 | R18: =$B$18*(1-'Assumptions'!$B$61) | S18: =MIN($Q$18,$R$18) | T18: ='Assumptions'!$B$59/$S$18 | U18: ='Assumptions'!$B$44+$J$18+$F$18+$I$18+$O$18+$T$18 | V18: =$U$18+$C$18
A19: 14 | B19: ='Assumptions'!$B$4/$U$18 | C19: ='Assumptions'!$B$5/$B$19 | D19: ='Assumptions'!$B$27*('Assumptions'!$B$44+'Assumptions'!$B$5/'Assumptions'!$B$27)/('Assumptions'!$B$44+'Assumptions'!$B$5/$B$19) | E19: ='Assumptions'!$B$40*'Assumptions'!$B$27/$D$19 | F19: =$E$19-'Assumptions'!$B$40 | G19: ='Assumptions'!$B$25*('Assumptions'!$B$44+'Assumptions'!$B$5/'Assumptions'!$B$25)/('Assumptions'!$B$44+'Assumptions'!$B$5/$B$19) | H19: ='Assumptions'!$B$38*'Assumptions'!$B$26/$G$19 | I19: =$H$19-'Assumptions'!$B$39 | J19: =MAX(0,'Assumptions'!$B$8*$V$18-'Assumptions'!$B$43) | K19: ='Assumptions'!$B$44+$J$19+$F$19+$I$19+$T$18 | L19: ='Assumptions'!$B$57/$K$19 | M19: =$B$19*(1-'Assumptions'!$B$58) | N19: =MIN($L$19,$M$19) | O19: ='Assumptions'!$B$56/$N$19 | P19: ='Assumptions'!$B$44+$J$19+$F$19+$I$19+$O$19 | Q19: ='Assumptions'!$B$60/$P$19 | R19: =$B$19*(1-'Assumptions'!$B$61) | S19: =MIN($Q$19,$R$19) | T19: ='Assumptions'!$B$59/$S$19 | U19: ='Assumptions'!$B$44+$J$19+$F$19+$I$19+$O$19+$T$19 | V19: =$U$19+$C$19 | W19: branch_A | X19: branch_B | Y19: post_F_options | Z19: unissued_opts | AA19: issued_opts
A20: 15 | B20: ='Assumptions'!$B$4/$U$19 | C20: ='Assumptions'!$B$5/$B$20 | D20: ='Assumptions'!$B$27*('Assumptions'!$B$44+'Assumptions'!$B$5/'Assumptions'!$B$27)/('Assumptions'!$B$44+'Assumptions'!$B$5/$B$20) | E20: ='Assumptions'!$B$40*'Assumptions'!$B$27/$D$20 | F20: =$E$20-'Assumptions'!$B$40 | G20: ='Assumptions'!$B$25*('Assumptions'!$B$44+'Assumptions'!$B$5/'Assumptions'!$B$25)/('Assumptions'!$B$44+'Assumptions'!$B$5/$B$20) | H20: ='Assumptions'!$B$38*'Assumptions'!$B$26/$G$20 | I20: =$H$20-'Assumptions'!$B$39 | J20: =MAX(0,'Assumptions'!$B$8*$V$19-'Assumptions'!$B$43) | K20: ='Assumptions'!$B$44+$J$20+$F$20+$I$20+$T$19 | L20: ='Assumptions'!$B$57/$K$20 | M20: =$B$20*(1-'Assumptions'!$B$58) | N20: =MIN($L$20,$M$20) | O20: ='Assumptions'!$B$56/$N$20 | P20: ='Assumptions'!$B$44+$J$20+$F$20+$I$20+$O$20 | Q20: ='Assumptions'!$B$60/$P$20 | R20: =$B$20*(1-'Assumptions'!$B$61) | S20: =MIN($Q$20,$R$20) | T20: ='Assumptions'!$B$59/$S$20 | U20: ='Assumptions'!$B$44+$J$20+$F$20+$I$20+$O$20+$T$20 | V20: =$U$20+$C$20 | W20: =IF('Pro-Forma'!$L$20<'Pro-Forma'!$M$20,"cap","discount") | X20: =IF('Pro-Forma'!$Q$20<'Pro-Forma'!$R$20,"cap","discount") | Y20: ='Assumptions'!$B$43+'Pro-Forma'!$J$20 | Z20: ='Assumptions'!$B$42+'Pro-Forma'!$J$20 | AA20: ='Assumptions'!$B$41
A23: ANTI-DILUTION BLOCK
A24: Class | B24: OCP-for-AD | C24: Trigger (F_PPS<OCP) | D24: New NCP | E24: New ratio | F24: Original shares | G24: As-converted shares
A25: Series Seed | B25: ='Assumptions'!$B$21 | C25: =IF('Pro-Forma'!$B$20<'Assumptions'!$B$21,"trigger","dormant") | D25: ='Assumptions'!$B$21 | E25: =1 | F25: ='Assumptions'!$B$34 | G25: ='Assumptions'!$B$34
A26: Series A | B26: ='Assumptions'!$B$22 | C26: =IF('Pro-Forma'!$B$20<'Assumptions'!$B$22,"trigger","dormant") | D26: ='Assumptions'!$B$22 | E26: =1 | F26: ='Assumptions'!$B$35 | G26: ='Assumptions'!$B$35
A27: Series B | B27: ='Assumptions'!$B$23 | C27: =IF('Pro-Forma'!$B$20<'Assumptions'!$B$23,"trigger","dormant") | D27: ='Assumptions'!$B$23 | E27: =1 | F27: ='Assumptions'!$B$36 | G27: ='Assumptions'!$B$36
A28: Series C | B28: ='Assumptions'!$B$24 | C28: =IF('Pro-Forma'!$B$20<'Assumptions'!$B$24,"trigger","dormant") | D28: ='Assumptions'!$B$24 | E28: =1 | F28: ='Assumptions'!$B$37 | G28: ='Assumptions'!$B$37
A29: Series D | B29: ='Assumptions'!$B$25 | C29: =IF('Pro-Forma'!$B$20<'Assumptions'!$B$25,"trigger","dormant") | D29: ='Pro-Forma'!$G$20 | E29: ='Assumptions'!$B$26/'Pro-Forma'!$G$20 | F29: ='Assumptions'!$B$38 | G29: ='Pro-Forma'!$H$20
A30: Series E | B30: ='Assumptions'!$B$27 | C30: =IF('Pro-Forma'!$B$20<'Assumptions'!$B$27,"trigger","dormant") | D30: ='Pro-Forma'!$D$20 | E30: ='Assumptions'!$B$27/'Pro-Forma'!$D$20 | F30: ='Assumptions'!$B$40 | G30: ='Pro-Forma'!$E$20
A32: NOTES BLOCK
A33: Note | B33: Cap-implied PPS | C33: Discount-implied PPS | D33: Conversion PPS (MIN) | E33: Branch (IF) | F33: Shares issued
A34: Note A | B34: ='Pro-Forma'!$L$20 | C34: ='Pro-Forma'!$M$20 | D34: ='Pro-Forma'!$N$20 | E34: ='Pro-Forma'!$W$20 | F34: ='Pro-Forma'!$O$20
A35: Note B | B35: ='Pro-Forma'!$Q$20 | C35: ='Pro-Forma'!$R$20 | D35: ='Pro-Forma'!$S$20 | E35: ='Pro-Forma'!$X$20 | F35: ='Pro-Forma'!$T$20
A37: TENDER BLOCK
A38: Tender PPS (= mult × F_PPS) | B38: ='Assumptions'!$B$7*'Pro-Forma'!$B$20
A39: Tender shares (= secondary / tender PPS) | B39: ='Assumptions'!$B$6/'Pro-Forma'!$B$38
A40: F1 tender share-out (50%) | B40: ='Pro-Forma'!$B$39*0.50
A41: F2 tender share-out (31.25%) | B41: ='Pro-Forma'!$B$39*0.3125
A42: F3 tender share-out (18.75%) | B42: ='Pro-Forma'!$B$39*0.1875
A43: F_LEAD secondary common holding | B43: ='Pro-Forma'!$B$39
A44: F_LEAD primary F shares | B44: ='Assumptions'!$B$10/'Pro-Forma'!$B$20
A45: Our fund F shares | B45: ='Assumptions'!$B$9/'Pro-Forma'!$B$20
...

Sheet Waterfall
A1: Waterfall — 1× Non-Participating with Conversion Election
A3: Exit value (USD) | B3: ='Assumptions'!$B$14 | C3: ='Assumptions'!$B$15 | D3: ='Assumptions'!$B$16 | E3: ='Assumptions'!$B$17 | F3: ='Assumptions'!$B$18
A5: STATIC POOL COMPONENTS
A6: Common+RSAs shares (founders post-tender + RSAs + tender to F_LEAD) | B6: ='Assumptions'!$B$30+'Assumptions'!$B$31+'Assumptions'!$B$32+'Assumptions'!$B$33
A7: Notes converted (N_A + N_B) | B7: ='Pro-Forma'!$O$20+'Pro-Forma'!$T$20
A8: Issued options (always assume ITM at these exits) | B8: ='Pro-Forma'!$AA$20
A10: PER-CLASS AS-CONVERTED SHARES
A11: F shares | B11: ='Pro-Forma'!$C$20
A12: E shares | B12: ='Pro-Forma'!$E$20
A13: D shares | B13: ='Pro-Forma'!$H$20
A14: C shares | B14: ='Assumptions'!$B$37
A15: B shares | B15: ='Assumptions'!$B$36
A16: A shares | B16: ='Assumptions'!$B$35
A17: Seed shares | B17: ='Assumptions'!$B$34
A19: PER-CLASS PREFERENCE (USD)
A20: F pref | B20: ='Assumptions'!$B$53
A21: E pref | B21: ='Assumptions'!$B$52
A22: D pref | B22: ='Assumptions'!$B$51
A23: C pref | B23: ='Assumptions'!$B$50
A24: B pref | B24: ='Assumptions'!$B$49
A25: A pref | B25: ='Assumptions'!$B$48
A26: Seed pref | B26: ='Assumptions'!$B$47
A28: --- F class ---
A29: Senior pref total (paid above F) | B29: =0 | C29: =0 | D29: =0 | E29: =0 | F29: =0
A30: Senior convert pool shares | B30: =0 | C30: =0 | D30: =0 | E30: =0 | F30: =0
A31: Junior pool shares (assume convert) | B31: =$B$12+$B$13+$B$14+$B$15+$B$16+$B$17 | C31: =$B$12+$B$13+$B$14+$B$15+$B$16+$B$17 | D31: =$B$12+$B$13+$B$14+$B$15+$B$16+$B$17 | E31: =$B$12+$B$13+$B$14+$B$15+$B$16+$B$17 | F31: =$B$12+$B$13+$B$14+$B$15+$B$16+$B$17
A32: Convert pool size (incl. F) | B32: =$B$11+B30+B31+$B$6+$B$7+$B$8 | C32: =$B$11+C30+C31+$B$6+$B$7+$B$8 | D32: =$B$11+D30+D31+$B$6+$B$7+$B$8 | E32: =$B$11+E30+E31+$B$6+$B$7+$B$8 | F32: =$B$11+F30+F31+$B$6+$B$7+$B$8
A33: Residual cash (exit + opts strike − senior pref) | B33: =$B$3+'Assumptions'!$B$11*$B$8-B29 | C33: =$C$3+'Assumptions'!$B$11*$B$8-C29 | D33: =$D$3+'Assumptions'!$B$11*$B$8-D29 | E33: =$E$3+'Assumptions'!$B$11*$B$8-E29 | F33: =$F$3+'Assumptions'!$B$11*$B$8-F29
A34: Per-share (residual / pool) | B34: =B33/B32 | C34: =C33/C32 | D34: =D33/D32 | E34: =E33/E32 | F34: =F33/F32
A35: F convert payoff | B35: =$B$11*B34 | C35: =$B$11*C34 | D35: =$B$11*D34 | E35: =$B$11*E34 | F35: =$B$11*F34
A36: F preference payoff | B36: =$B$20 | C36: =$B$20 | D36: =$B$20 | E36: =$B$20 | F36: =$B$20
A37: F ELECTION (IF formula) | B37: =IF(B35>B36,"convert","preference") | C37: =IF(C35>C36,"convert","preference") | D37: =IF(D35>D36,"convert","preference") | E37: =IF(E35>E36,"convert","preference") | F37: =IF(F35>F36,"convert","preference")
A38: F realized payoff | B38: =IF(B37="convert",B35,B36) | C38: =IF(C37="convert",C35,C36) | D38: =IF(D37="convert",D35,D36) | E38: =IF(E37="convert",E35,E36) | F38: =IF(F37="convert",F35,F36)
A40: --- E class ---
A41: Senior pref total (paid above E) | B41: =IF(B37="preference",$B$20,0) | C41: =IF(C37="preference",$B$20,0) | D41: =IF(D37="preference",$B$20,0) | E41: =IF(E37="preference",$B$20,0) | F41: =IF(F37="preference",$B$20,0)
A42: Senior convert pool shares | B42: =IF(B37="convert",$B$11,0) | C42: =IF(C37="convert",$B$11,0) | D42: =IF(D37="convert",$B$11,0) | E42: =IF(E37="convert",$B$11,0) | F42: =IF(F37="convert",$B$11,0)
A43: Junior pool shares (assume convert) | B43: =$B$13+$B$14+$B$15+$B$16+$B$17 | C43: =$B$13+$B$14+$B$15+$B$16+$B$17 | D43: =$B$13+$B$14+$B$15+$B$16+$B$17 | E43: =$B$13+$B$14+$B$15+$B$16+$B$17 | F43: =$B$13+$B$14+$B$15+$B$16+$B$17
A44: Convert pool size (incl. E) | B44: =$B$12+B42+B43+$B$6+$B$7+$B$8 | C44: =$B$12+C42+C43+$B$6+$B$7+$B$8 | D44: =$B$12+D42+D43+$B$6+$B$7+$B$8 | E44: =$B$12+E42+E43+$B$6+$B$7+$B$8 | F44: =$B$12+F42+F43+$B$6+$B$7+$B$8
A45: Residual cash (exit + opts strike − senior pref) | B45: =$B$3+'Assumptions'!$B$11*$B$8-B41 | C45: =$C$3+'Assumptions'!$B$11*$B$8-C41 | D45: =$D$3+'Assumptions'!$B$11*$B$8-D41 | E45: =$E$3+'Assumptions'!$B$11*$B$8-E41 | F45: =$F$3+'Assumptions'!$B$11*$B$8-F41
A46: Per-share (residual / pool) | B46: =B45/B44 | C46: =C45/C44 | D46: =D45/D44 | E46: =E45/E44 | F46: =F45/F44
...

Sheet Sensitivity
A1: Sensitivity Grid — 3×3 (ESOP × Pre-money) at $2B Exit
A3: OWNERSHIP % (our $10M check's post-F FD share)
B4: Pre $1.2B | C4: Pre $1.4B | D4: Pre $1.8B
A5: ESOP 11% | B5: =(('Assumptions'!$B$9/'Sensitivity'!$B$52)/'Sensitivity'!$V$52) | C5: =(('Assumptions'!$B$9/'Sensitivity'!$B$72)/'Sensitivity'!$V$72) | D5: =(('Assumptions'!$B$9/'Sensitivity'!$B$92)/'Sensitivity'!$V$92)
A6: ESOP 13% | B6: =(('Assumptions'!$B$9/'Sensitivity'!$B$112)/'Sensitivity'!$V$112) | C6: =(('Assumptions'!$B$9/'Sensitivity'!$B$132)/'Sensitivity'!$V$132) | D6: =(('Assumptions'!$B$9/'Sensitivity'!$B$152)/'Sensitivity'!$V$152)
A7: ESOP 15% | B7: =(('Assumptions'!$B$9/'Sensitivity'!$B$172)/'Sensitivity'!$V$172) | C7: =(('Assumptions'!$B$9/'Sensitivity'!$B$192)/'Sensitivity'!$V$192) | D7: =(('Assumptions'!$B$9/'Sensitivity'!$B$212)/'Sensitivity'!$V$212)
A9: PROCEEDS at $2B exit (our $10M check)
B10: Pre $1.2B | C10: Pre $1.4B | D10: Pre $1.8B
A11: ESOP 11% | B11: =(('Assumptions'!$B$9/'Sensitivity'!$B$52)*(('Assumptions'!$B$16+'Assumptions'!$B$11*'Assumptions'!$B$41-'Assumptions'!$B$51)/(('Assumptions'!$B$30+'Assumptions'!$B$31+'Assumptions'!$B$32+'Assumptions'!$B$33)+'Assumptions'!$B$34+'Assumptions'!$B$35+'Assumptions'!$B$36+'Assumptions'!$B$37+'Sensitivity'!$E$52+'Sensitivity'!$O$52+'Sensitivity'!$T$52+'Assumptions'!$B$41+'Assumptions'!$B$5/'Sensitivity'!$B$52))) | C11: =(('Assumptions'!$B$9/'Sensitivity'!$B$72)*(('Assumptions'!$B$16+'Assumptions'!$B$11*'Assumptions'!$B$41-'Assumptions'!$B$51)/(('Assumptions'!$B$30+'Assumptions'!$B$31+'Assumptions'!$B$32+'Assumptions'!$B$33)+'Assumptions'!$B$34+'Assumptions'!$B$35+'Assumptions'!$B$36+'Assumptions'!$B$37+'Sensitivity'!$E$72+'Sensitivity'!$O$72+'Sensitivity'!$T$72+'Assumptions'!$B$41+'Assumptions'!$B$5/'Sensitivity'!$B$72))) | D11: =(('Assumptions'!$B$9/'Sensitivity'!$B$92)*(('Assumptions'!$B$16+'Assumptions'!$B$11*'Assumptions'!$B$41-'Assumptions'!$B$51)/(('Assumptions'!$B$30+'Assumptions'!$B$31+'Assumptions'!$B$32+'Assumptions'!$B$33)+'Assumptions'!$B$34+'Assumptions'!$B$35+'Assumptions'!$B$36+'Assumptions'!$B$37+'Sensitivity'!$E$92+'Sensitivity'!$O$92+'Sensitivity'!$T$92+'Assumptions'!$B$41+'Assumptions'!$B$5/'Sensitivity'!$B$92)))
A12: ESOP 13% | B12: =(('Assumptions'!$B$9/'Sensitivity'!$B$112)*(('Assumptions'!$B$16+'Assumptions'!$B$11*'Assumptions'!$B$41-'Assumptions'!$B$51)/(('Assumptions'!$B$30+'Assumptions'!$B$31+'Assumptions'!$B$32+'Assumptions'!$B$33)+'Assumptions'!$B$34+'Assumptions'!$B$35+'Assumptions'!$B$36+'Assumptions'!$B$37+'Sensitivity'!$E$112+'Sensitivity'!$O$112+'Sensitivity'!$T$112+'Assumptions'!$B$41+'Assumptions'!$B$5/'Sensitivity'!$B$112))) | C12: =(('Assumptions'!$B$9/'Sensitivity'!$B$132)*(('Assumptions'!$B$16+'Assumptions'!$B$11*'Assumptions'!$B$41-'Assumptions'!$B$51)/(('Assumptions'!$B$30+'Assumptions'!$B$31+'Assumptions'!$B$32+'Assumptions'!$B$33)+'Assumptions'!$B$34+'Assumptions'!$B$35+'Assumptions'!$B$36+'Assumptions'!$B$37+'Sensitivity'!$E$132+'Sensitivity'!$O$132+'Sensitivity'!$T$132+'Assumptions'!$B$41+'Assumptions'!$B$5/'Sensitivity'!$B$132))) | D12: =(('Assumptions'!$B$9/'Sensitivity'!$B$152)*(('Assumptions'!$B$16+'Assumptions'!$B$11*'Assumptions'!$B$41-'Assumptions'!$B$51)/(('Assumptions'!$B$30+'Assumptions'!$B$31+'Assumptions'!$B$32+'Assumptions'!$B$33)+'Assumptions'!$B$34+'Assumptions'!$B$35+'Assumptions'!$B$36+'Assumptions'!$B$37+'Sensitivity'!$E$152+'Sensitivity'!$O$152+'Sensitivity'!$T$152+'Assumptions'!$B$41+'Assumptions'!$B$5/'Sensitivity'!$B$152)))
A13: ESOP 15% | B13: =(('Assumptions'!$B$9/'Sensitivity'!$B$172)*(('Assumptions'!$B$16+'Assumptions'!$B$11*'Assumptions'!$B$41-'Assumptions'!$B$51)/(('Assumptions'!$B$30+'Assumptions'!$B$31+'Assumptions'!$B$32+'Assumptions'!$B$33)+'Assumptions'!$B$34+'Assumptions'!$B$35+'Assumptions'!$B$36+'Assumptions'!$B$37+'Sensitivity'!$E$172+'Sensitivity'!$O$172+'Sensitivity'!$T$172+'Assumptions'!$B$41+'Assumptions'!$B$5/'Sensitivity'!$B$172))) | C13: =(('Assumptions'!$B$9/'Sensitivity'!$B$192)*(('Assumptions'!$B$16+'Assumptions'!$B$11*'Assumptions'!$B$41-'Assumptions'!$B$51)/(('Assumptions'!$B$30+'Assumptions'!$B$31+'Assumptions'!$B$32+'Assumptions'!$B$33)+'Assumptions'!$B$34+'Assumptions'!$B$35+'Assumptions'!$B$36+'Assumptions'!$B$37+'Sensitivity'!$E$192+'Sensitivity'!$O$192+'Sensitivity'!$T$192+'Assumptions'!$B$41+'Assumptions'!$B$5/'Sensitivity'!$B$192))) | D13: =(('Assumptions'!$B$9/'Sensitivity'!$B$212)*(('Assumptions'!$B$16+'Assumptions'!$B$11*'Assumptions'!$B$41-'Assumptions'!$B$51)/(('Assumptions'!$B$30+'Assumptions'!$B$31+'Assumptions'!$B$32+'Assumptions'!$B$33)+'Assumptions'!$B$34+'Assumptions'!$B$35+'Assumptions'!$B$36+'Assumptions'!$B$37+'Sensitivity'!$E$212+'Sensitivity'!$O$212+'Sensitivity'!$T$212+'Assumptions'!$B$41+'Assumptions'!$B$5/'Sensitivity'!$B$212)))
A15: MULTIPLE on $10M (proceeds / 10M)
B16: Pre $1.2B | C16: Pre $1.4B | D16: Pre $1.8B
A17: ESOP 11% | B17: =(('Assumptions'!$B$9/'Sensitivity'!$B$52)*(('Assumptions'!$B$16+'Assumptions'!$B$11*'Assumptions'!$B$41-'Assumptions'!$B$51)/(('Assumptions'!$B$30+'Assumptions'!$B$31+'Assumptions'!$B$32+'Assumptions'!$B$33)+'Assumptions'!$B$34+'Assumptions'!$B$35+'Assumptions'!$B$36+'Assumptions'!$B$37+'Sensitivity'!$E$52+'Sensitivity'!$O$52+'Sensitivity'!$T$52+'Assumptions'!$B$41+'Assumptions'!$B$5/'Sensitivity'!$B$52)))/'Assumptions'!$B$9 | C17: =(('Assumptions'!$B$9/'Sensitivity'!$B$72)*(('Assumptions'!$B$16+'Assumptions'!$B$11*'Assumptions'!$B$41-'Assumptions'!$B$51)/(('Assumptions'!$B$30+'Assumptions'!$B$31+'Assumptions'!$B$32+'Assumptions'!$B$33)+'Assumptions'!$B$34+'Assumptions'!$B$35+'Assumptions'!$B$36+'Assumptions'!$B$37+'Sensitivity'!$E$72+'Sensitivity'!$O$72+'Sensitivity'!$T$72+'Assumptions'!$B$41+'Assumptions'!$B$5/'Sensitivity'!$B$72)))/'Assumptions'!$B$9 | D17: =(('Assumptions'!$B$9/'Sensitivity'!$B$92)*(('Assumptions'!$B$16+'Assumptions'!$B$11*'Assumptions'!$B$41-'Assumptions'!$B$51)/(('Assumptions'!$B$30+'Assumptions'!$B$31+'Assumptions'!$B$32+'Assumptions'!$B$33)+'Assumptions'!$B$34+'Assumptions'!$B$35+'Assumptions'!$B$36+'Assumptions'!$B$37+'Sensitivity'!$E$92+'Sensitivity'!$O$92+'Sensitivity'!$T$92+'Assumptions'!$B$41+'Assumptions'!$B$5/'Sensitivity'!$B$92)))/'Assumptions'!$B$9
A18: ESOP 13% | B18: =(('Assumptions'!$B$9/'Sensitivity'!$B$112)*(('Assumptions'!$B$16+'Assumptions'!$B$11*'Assumptions'!$B$41-'Assumptions'!$B$51)/(('Assumptions'!$B$30+'Assumptions'!$B$31+'Assumptions'!$B$32+'Assumptions'!$B$33)+'Assumptions'!$B$34+'Assumptions'!$B$35+'Assumptions'!$B$36+'Assumptions'!$B$37+'Sensitivity'!$E$112+'Sensitivity'!$O$112+'Sensitivity'!$T$112+'Assumptions'!$B$41+'Assumptions'!$B$5/'Sensitivity'!$B$112)))/'Assumptions'!$B$9 | C18: =(('Assumptions'!$B$9/'Sensitivity'!$B$132)*(('Assumptions'!$B$16+'Assumptions'!$B$11*'Assumptions'!$B$41-'Assumptions'!$B$51)/(('Assumptions'!$B$30+'Assumptions'!$B$31+'Assumptions'!$B$32+'Assumptions'!$B$33)+'Assumptions'!$B$34+'Assumptions'!$B$35+'Assumptions'!$B$36+'Assumptions'!$B$37+'Sensitivity'!$E$132+'Sensitivity'!$O$132+'Sensitivity'!$T$132+'Assumptions'!$B$41+'Assumptions'!$B$5/'Sensitivity'!$B$132)))/'Assumptions'!$B$9 | D18: =(('Assumptions'!$B$9/'Sensitivity'!$B$152)*(('Assumptions'!$B$16+'Assumptions'!$B$11*'Assumptions'!$B$41-'Assumptions'!$B$51)/(('Assumptions'!$B$30+'Assumptions'!$B$31+'Assumptions'!$B$32+'Assumptions'!$B$33)+'Assumptions'!$B$34+'Assumptions'!$B$35+'Assumptions'!$B$36+'Assumptions'!$B$37+'Sensitivity'!$E$152+'Sensitivity'!$O$152+'Sensitivity'!$T$152+'Assumptions'!$B$41+'Assumptions'!$B$5/'Sensitivity'!$B$152)))/'Assumptions'!$B$9
A19: ESOP 15% | B19: =(('Assumptions'!$B$9/'Sensitivity'!$B$172)*(('Assumptions'!$B$16+'Assumptions'!$B$11*'Assumptions'!$B$41-'Assumptions'!$B$51)/(('Assumptions'!$B$30+'Assumptions'!$B$31+'Assumptions'!$B$32+'Assumptions'!$B$33)+'Assumptions'!$B$34+'Assumptions'!$B$35+'Assumptions'!$B$36+'Assumptions'!$B$37+'Sensitivity'!$E$172+'Sensitivity'!$O$172+'Sensitivity'!$T$172+'Assumptions'!$B$41+'Assumptions'!$B$5/'Sensitivity'!$B$172)))/'Assumptions'!$B$9 | C19: =(('Assumptions'!$B$9/'Sensitivity'!$B$192)*(('Assumptions'!$B$16+'Assumptions'!$B$11*'Assumptions'!$B$41-'Assumptions'!$B$51)/(('Assumptions'!$B$30+'Assumptions'!$B$31+'Assumptions'!$B$32+'Assumptions'!$B$33)+'Assumptions'!$B$34+'Assumptions'!$B$35+'Assumptions'!$B$36+'Assumptions'!$B$37+'Sensitivity'!$E$192+'Sensitivity'!$O$192+'Sensitivity'!$T$192+'Assumptions'!$B$41+'Assumptions'!$B$5/'Sensitivity'!$B$192)))/'Assumptions'!$B$9 | D19: =(('Assumptions'!$B$9/'Sensitivity'!$B$212)*(('Assumptions'!$B$16+'Assumptions'!$B$11*'Assumptions'!$B$41-'Assumptions'!$B$51)/(('Assumptions'!$B$30+'Assumptions'!$B$31+'Assumptions'!$B$32+'Assumptions'!$B$33)+'Assumptions'!$B$34+'Assumptions'!$B$35+'Assumptions'!$B$36+'Assumptions'!$B$37+'Sensitivity'!$E$212+'Sensitivity'!$O$212+'Sensitivity'!$T$212+'Assumptions'!$B$41+'Assumptions'!$B$5/'Sensitivity'!$B$212)))/'Assumptions'!$B$9
A21: NOTE A BRANCH per cell
B22: Pre $1.2B | C22: Pre $1.4B | D22: Pre $1.8B
A23: ESOP 11% | B23: ='Sensitivity'!$W$52 | C23: ='Sensitivity'!$W$72 | D23: ='Sensitivity'!$W$92
A24: ESOP 13% | B24: ='Sensitivity'!$W$112 | C24: ='Sensitivity'!$W$132 | D24: ='Sensitivity'!$W$152
A25: ESOP 15% | B25: ='Sensitivity'!$W$172 | C25: ='Sensitivity'!$W$192 | D25: ='Sensitivity'!$W$212
A27: NOTE B BRANCH per cell
B28: Pre $1.2B | C28: Pre $1.4B | D28: Pre $1.8B
A29: ESOP 11% | B29: ='Sensitivity'!$X$52 | C29: ='Sensitivity'!$X$72 | D29: ='Sensitivity'!$X$92
A30: ESOP 13% | B30: ='Sensitivity'!$X$112 | C30: ='Sensitivity'!$X$132 | D30: ='Sensitivity'!$X$152
A31: ESOP 15% | B31: ='Sensitivity'!$X$172 | C31: ='Sensitivity'!$X$192 | D31: ='Sensitivity'!$X$212
A35: Cell (11%, $1.2B)
A36: Iter | B36: F_PPS | C36: F_prim_shares | D36: NCP_E | E36: new_E_shares | F36: AD_inc_E | G36: NCP_D | H36: new_D_shares | I36: AD_inc_D | J36: ESOP_topup | K36: cap_FD_A | L36: cap_pps_A | M36: disc_pps_A | N36: conv_pps_A | O36: N_A | P36: cap_FD_B | Q36: cap_pps_B | R36: disc_pps_B | S36: conv_pps_B | T36: N_B | U36: pre_money_FD | V36: T_F
A37: 0 | B37: ='Assumptions'!$B$67/'Assumptions'!$B$44 | C37: ='Assumptions'!$B$5/$B$37 | D37: ='Assumptions'!$B$27*('Assumptions'!$B$44+'Assumptions'!$B$5/'Assumptions'!$B$27)/('Assumptions'!$B$44+'Assumptions'!$B$5/$B$37) | E37: ='Assumptions'!$B$40*'Assumptions'!$B$27/$D$37 | F37: =$E$37-'Assumptions'!$B$40 | G37: ='Assumptions'!$B$25*('Assumptions'!$B$44+'Assumptions'!$B$5/'Assumptions'!$B$25)/('Assumptions'!$B$44+'Assumptions'!$B$5/$B$37) | H37: ='Assumptions'!$B$38*'Assumptions'!$B$26/$G$37 | I37: =$H$37-'Assumptions'!$B$39 | J37: =MAX(0,'Assumptions'!$B$64*('Assumptions'!$B$44+$F$37+$I$37+$C$37)/(1-'Assumptions'!$B$64)-'Assumptions'!$B$43) | K37: ='Assumptions'!$B$44+$J$37+$F$37+$I$37+0 | L37: ='Assumptions'!$B$57/$K$37 | M37: =$B$37*(1-'Assumptions'!$B$58) | N37: =MIN($L$37,$M$37) | O37: ='Assumptions'!$B$56/$N$37 | P37: ='Assumptions'!$B$44+$J$37+$F$37+$I$37+$O$37 | Q37: ='Assumptions'!$B$60/$P$37 | R37: =$B$37*(1-'Assumptions'!$B$61) | S37: =MIN($Q$37,$R$37) | T37: ='Assumptions'!$B$59/$S$37 | U37: ='Assumptions'!$B$44+$J$37+$F$37+$I$37+$O$37+$T$37 | V37: =$U$37+$C$37
A38: 1 | B38: ='Assumptions'!$B$67/$U$37 | C38: ='Assumptions'!$B$5/$B$38 | D38: ='Assumptions'!$B$27*('Assumptions'!$B$44+'Assumptions'!$B$5/'Assumptions'!$B$27)/('Assumptions'!$B$44+'Assumptions'!$B$5/$B$38) | E38: ='Assumptions'!$B$40*'Assumptions'!$B$27/$D$38 | F38: =$E$38-'Assumptions'!$B$40 | G38: ='Assumptions'!$B$25*('Assumptions'!$B$44+'Assumptions'!$B$5/'Assumptions'!$B$25)/('Assumptions'!$B$44+'Assumptions'!$B$5/$B$38) | H38: ='Assumptions'!$B$38*'Assumptions'!$B$26/$G$38 | I38: =$H$38-'Assumptions'!$B$39 | J38: =MAX(0,'Assumptions'!$B$64*$V$37-'Assumptions'!$B$43) | K38: ='Assumptions'!$B$44+$J$38+$F$38+$I$38+$T$37 | L38: ='Assumptions'!$B$57/$K$38 | M38: =$B$38*(1-'Assumptions'!$B$58) | N38: =MIN($L$38,$M$38) | O38: ='Assumptions'!$B$56/$N$38 | P38: ='Assumptions'!$B$44+$J$38+$F$38+$I$38+$O$38 | Q38: ='Assumptions'!$B$60/$P$38 | R38: =$B$38*(1-'Assumptions'!$B$61) | S38: =MIN($Q$38,$R$38) | T38: ='Assumptions'!$B$59/$S$38 | U38: ='Assumptions'!$B$44+$J$38+$F$38+$I$38+$O$38+$T$38 | V38: =$U$38+$C$38
A39: 2 | B39: ='Assumptions'!$B$67/$U$38 | C39: ='Assumptions'!$B$5/$B$39 | D39: ='Assumptions'!$B$27*('Assumptions'!$B$44+'Assumptions'!$B$5/'Assumptions'!$B$27)/('Assumptions'!$B$44+'Assumptions'!$B$5/$B$39) | E39: ='Assumptions'!$B$40*'Assumptions'!$B$27/$D$39 | F39: =$E$39-'Assumptions'!$B$40 | G39: ='Assumptions'!$B$25*('Assumptions'!$B$44+'Assumptions'!$B$5/'Assumptions'!$B$25)/('Assumptions'!$B$44+'Assumptions'!$B$5/$B$39) | H39: ='Assumptions'!$B$38*'Assumptions'!$B$26/$G$39 | I39: =$H$39-'Assumptions'!$B$39 | J39: =MAX(0,'Assumptions'!$B$64*$V$38-'Assumptions'!$B$43) | K39: ='Assumptions'!$B$44+$J$39+$F$39+$I$39+$T$38 | L39: ='Assumptions'!$B$57/$K$39 | M39: =$B$39*(1-'Assumptions'!$B$58) | N39: =MIN($L$39,$M$39) | O39: ='Assumptions'!$B$56/$N$39 | P39: ='Assumptions'!$B$44+$J$39+$F$39+$I$39+$O$39 | Q39: ='Assumptions'!$B$60/$P$39 | R39: =$B$39*(1-'Assumptions'!$B$61) | S39: =MIN($Q$39,$R$39) | T39: ='Assumptions'!$B$59/$S$39 | U39: ='Assumptions'!$B$44+$J$39+$F$39+$I$39+$O$39+$T$39 | V39: =$U$39+$C$39
A40: 3 | B40: ='Assumptions'!$B$67/$U$39 | C40: ='Assumptions'!$B$5/$B$40 | D40: ='Assumptions'!$B$27*('Assumptions'!$B$44+'Assumptions'!$B$5/'Assumptions'!$B$27)/('Assumptions'!$B$44+'Assumptions'!$B$5/$B$40) | E40: ='Assumptions'!$B$40*'Assumptions'!$B$27/$D$40 | F40: =$E$40-'Assumptions'!$B$40 | G40: ='Assumptions'!$B$25*('Assumptions'!$B$44+'Assumptions'!$B$5/'Assumptions'!$B$25)/('Assumptions'!$B$44+'Assumptions'!$B$5/$B$40) | H40: ='Assumptions'!$B$38*'Assumptions'!$B$26/$G$40 | I40: =$H$40-'Assumptions'!$B$39 | J40: =MAX(0,'Assumptions'!$B$64*$V$39-'Assumptions'!$B$43) | K40: ='Assumptions'!$B$44+$J$40+$F$40+$I$40+$T$39 | L40: ='Assumptions'!$B$57/$K$40 | M40: =$B$40*(1-'Assumptions'!$B$58) | N40: =MIN($L$40,$M$40) | O40: ='Assumptions'!$B$56/$N$40 | P40: ='Assumptions'!$B$44+$J$40+$F$40+$I$40+$O$40 | Q40: ='Assumptions'!$B$60/$P$40 | R40: =$B$40*(1-'Assumptions'!$B$61) | S40: =MIN($Q$40,$R$40) | T40: ='Assumptions'!$B$59/$S$40 | U40: ='Assumptions'!$B$44+$J$40+$F$40+$I$40+$O$40+$T$40 | V40: =$U$40+$C$40
A41: 4 | B41: ='Assumptions'!$B$67/$U$40 | C41: ='Assumptions'!$B$5/$B$41 | D41: ='Assumptions'!$B$27*('Assumptions'!$B$44+'Assumptions'!$B$5/'Assumptions'!$B$27)/('Assumptions'!$B$44+'Assumptions'!$B$5/$B$41) | E41: ='Assumptions'!$B$40*'Assumptions'!$B$27/$D$41 | F41: =$E$41-'Assumptions'!$B$40 | G41: ='Assumptions'!$B$25*('Assumptions'!$B$44+'Assumptions'!$B$5/'Assumptions'!$B$25)/('Assumptions'!$B$44+'Assumptions'!$B$5/$B$41) | H41: ='Assumptions'!$B$38*'Assumptions'!$B$26/$G$41 | I41: =$H$41-'Assumptions'!$B$39 | J41: =MAX(0,'Assumptions'!$B$64*$V$40-'Assumptions'!$B$43) | K41: ='Assumptions'!$B$44+$J$41+$F$41+$I$41+$T$40 | L41: ='Assumptions'!$B$57/$K$41 | M41: =$B$41*(1-'Assumptions'!$B$58) | N41: =MIN($L$41,$M$41) | O41: ='Assumptions'!$B$56/$N$41 | P41: ='Assumptions'!$B$44+$J$41+$F$41+$I$41+$O$41 | Q41: ='Assumptions'!$B$60/$P$41 | R41: =$B$41*(1-'Assumptions'!$B$61) | S41: =MIN($Q$41,$R$41) | T41: ='Assumptions'!$B$59/$S$41 | U41: ='Assumptions'!$B$44+$J$41+$F$41+$I$41+$O$41+$T$41 | V41: =$U$41+$C$41
A42: 5 | B42: ='Assumptions'!$B$67/$U$41 | C42: ='Assumptions'!$B$5/$B$42 | D42: ='Assumptions'!$B$27*('Assumptions'!$B$44+'Assumptions'!$B$5/'Assumptions'!$B$27)/('Assumptions'!$B$44+'Assumptions'!$B$5/$B$42) | E42: ='Assumptions'!$B$40*'Assumptions'!$B$27/$D$42 | F42: =$E$42-'Assumptions'!$B$40 | G42: ='Assumptions'!$B$25*('Assumptions'!$B$44+'Assumptions'!$B$5/'Assumptions'!$B$25)/('Assumptions'!$B$44+'Assumptions'!$B$5/$B$42) | H42: ='Assumptions'!$B$38*'Assumptions'!$B$26/$G$42 | I42: =$H$42-'Assumptions'!$B$39 | J42: =MAX(0,'Assumptions'!$B$64*$V$41-'Assumptions'!$B$43) | K42: ='Assumptions'!$B$44+$J$42+$F$42+$I$42+$T$41 | L42: ='Assumptions'!$B$57/$K$42 | M42: =$B$42*(1-'Assumptions'!$B$58) | N42: =MIN($L$42,$M$42) | O42: ='Assumptions'!$B$56/$N$42 | P42: ='Assumptions'!$B$44+$J$42+$F$42+$I$42+$O$42 | Q42: ='Assumptions'!$B$60/$P$42 | R42: =$B$42*(1-'Assumptions'!$B$61) | S42: =MIN($Q$42,$R$42) | T42: ='Assumptions'!$B$59/$S$42 | U42: ='Assumptions'!$B$44+$J$42+$F$42+$I$42+$O$42+$T$42 | V42: =$U$42+$C$42
A43: 6 | B43: ='Assumptions'!$B$67/$U$42 | C43: ='Assumptions'!$B$5/$B$43 | D43: ='Assumptions'!$B$27*('Assumptions'!$B$44+'Assumptions'!$B$5/'Assumptions'!$B$27)/('Assumptions'!$B$44+'Assumptions'!$B$5/$B$43) | E43: ='Assumptions'!$B$40*'Assumptions'!$B$27/$D$43 | F43: =$E$43-'Assumptions'!$B$40 | G43: ='Assumptions'!$B$25*('Assumptions'!$B$44+'Assumptions'!$B$5/'Assumptions'!$B$25)/('Assumptions'!$B$44+'Assumptions'!$B$5/$B$43) | H43: ='Assumptions'!$B$38*'Assumptions'!$B$26/$G$43 | I43: =$H$43-'Assumptions'!$B$39 | J43: =MAX(0,'Assumptions'!$B$64*$V$42-'Assumptions'!$B$43) | K43: ='Assumptions'!$B$44+$J$43+$F$43+$I$43+$T$42 | L43: ='Assumptions'!$B$57/$K$43 | M43: =$B$43*(1-'Assumptions'!$B$58) | N43: =MIN($L$43,$M$43) | O43: ='Assumptions'!$B$56/$N$43 | P43: ='Assumptions'!$B$44+$J$43+$F$43+$I$43+$O$43 | Q43: ='Assumptions'!$B$60/$P$43 | R43: =$B$43*(1-'Assumptions'!$B$61) | S43: =MIN($Q$43,$R$43) | T43: ='Assumptions'!$B$59/$S$43 | U43: ='Assumptions'!$B$44+$J$43+$F$43+$I$43+$O$43+$T$43 | V43: =$U$43+$C$43
A44: 7 | B44: ='Assumptions'!$B$67/$U$43 | C44: ='Assumptions'!$B$5/$B$44 | D44: ='Assumptions'!$B$27*('Assumptions'!$B$44+'Assumptions'!$B$5/'Assumptions'!$B$27)/('Assumptions'!$B$44+'Assumptions'!$B$5/$B$44) | E44: ='Assumptions'!$B$40*'Assumptions'!$B$27/$D$44 | F44: =$E$44-'Assumptions'!$B$40 | G44: ='Assumptions'!$B$25*('Assumptions'!$B$44+'Assumptions'!$B$5/'Assumptions'!$B$25)/('Assumptions'!$B$44+'Assumptions'!$B$5/$B$44) | H44: ='Assumptions'!$B$38*'Assumptions'!$B$26/$G$44 | I44: =$H$44-'Assumptions'!$B$39 | J44: =MAX(0,'Assumptions'!$B$64*$V$43-'Assumptions'!$B$43) | K44: ='Assumptions'!$B$44+$J$44+$F$44+$I$44+$T$43 | L44: ='Assumptions'!$B$57/$K$44 | M44: =$B$44*(1-'Assumptions'!$B$58) | N44: =MIN($L$44,$M$44) | O44: ='Assumptions'!$B$56/$N$44 | P44: ='Assumptions'!$B$44+$J$44+$F$44+$I$44+$O$44 | Q44: ='Assumptions'!$B$60/$P$44 | R44: =$B$44*(1-'Assumptions'!$B$61) | S44: =MIN($Q$44,$R$44) | T44: ='Assumptions'!$B$59/$S$44 | U44: ='Assumptions'!$B$44+$J$44+$F$44+$I$44+$O$44+$T$44 | V44: =$U$44+$C$44
A45: 8 | B45: ='Assumptions'!$B$67/$U$44 | C45: ='Assumptions'!$B$5/$B$45 | D45: ='Assumptions'!$B$27*('Assumptions'!$B$44+'Assumptions'!$B$5/'Assumptions'!$B$27)/('Assumptions'!$B$44+'Assumptions'!$B$5/$B$45) | E45: ='Assumptions'!$B$40*'Assumptions'!$B$27/$D$45 | F45: =$E$45-'Assumptions'!$B$40 | G45: ='Assumptions'!$B$25*('Assumptions'!$B$44+'Assumptions'!$B$5/'Assumptions'!$B$25)/('Assumptions'!$B$44+'Assumptions'!$B$5/$B$45) | H45: ='Assumptions'!$B$38*'Assumptions'!$B$26/$G$45 | I45: =$H$45-'Assumptions'!$B$39 | J45: =MAX(0,'Assumptions'!$B$64*$V$44-'Assumptions'!$B$43) | K45: ='Assumptions'!$B$44+$J$45+$F$45+$I$45+$T$44 | L45: ='Assumptions'!$B$57/$K$45 | M45: =$B$45*(1-'Assumptions'!$B$58) | N45: =MIN($L$45,$M$45) | O45: ='Assumptions'!$B$56/$N$45 | P45: ='Assumptions'!$B$44+$J$45+$F$45+$I$45+$O$45 | Q45: ='Assumptions'!$B$60/$P$45 | R45: =$B$45*(1-'Assumptions'!$B$61) | S45: =MIN($Q$45,$R$45) | T45: ='Assumptions'!$B$59/$S$45 | U45: ='Assumptions'!$B$44+$J$45+$F$45+$I$45+$O$45+$T$45 | V45: =$U$45+$C$45
A46: 9 | B46: ='Assumptions'!$B$67/$U$45 | C46: ='Assumptions'!$B$5/$B$46 | D46: ='Assumptions'!$B$27*('Assumptions'!$B$44+'Assumptions'!$B$5/'Assumptions'!$B$27)/('Assumptions'!$B$44+'Assumptions'!$B$5/$B$46) | E46: ='Assumptions'!$B$40*'Assumptions'!$B$27/$D$46 | F46: =$E$46-'Assumptions'!$B$40 | G46: ='Assumptions'!$B$25*('Assumptions'!$B$44+'Assumptions'!$B$5/'Assumptions'!$B$25)/('Assumptions'!$B$44+'Assumptions'!$B$5/$B$46) | H46: ='Assumptions'!$B$38*'Assumptions'!$B$26/$G$46 | I46: =$H$46-'Assumptions'!$B$39 | J46: =MAX(0,'Assumptions'!$B$64*$V$45-'Assumptions'!$B$43) | K46: ='Assumptions'!$B$44+$J$46+$F$46+$I$46+$T$45 | L46: ='Assumptions'!$B$57/$K$46 | M46: =$B$46*(1-'Assumptions'!$B$58) | N46: =MIN($L$46,$M$46) | O46: ='Assumptions'!$B$56/$N$46 | P46: ='Assumptions'!$B$44+$J$46+$F$46+$I$46+$O$46 | Q46: ='Assumptions'!$B$60/$P$46 | R46: =$B$46*(1-'Assumptions'!$B$61) | S46: =MIN($Q$46,$R$46) | T46: ='Assumptions'!$B$59/$S$46 | U46: ='Assumptions'!$B$44+$J$46+$F$46+$I$46+$O$46+$T$46 | V46: =$U$46+$C$46
A47: 10 | B47: ='Assumptions'!$B$67/$U$46 | C47: ='Assumptions'!$B$5/$B$47 | D47: ='Assumptions'!$B$27*('Assumptions'!$B$44+'Assumptions'!$B$5/'Assumptions'!$B$27)/('Assumptions'!$B$44+'Assumptions'!$B$5/$B$47) | E47: ='Assumptions'!$B$40*'Assumptions'!$B$27/$D$47 | F47: =$E$47-'Assumptions'!$B$40 | G47: ='Assumptions'!$B$25*('Assumptions'!$B$44+'Assumptions'!$B$5/'Assumptions'!$B$25)/('Assumptions'!$B$44+'Assumptions'!$B$5/$B$47) | H47: ='Assumptions'!$B$38*'Assumptions'!$B$26/$G$47 | I47: =$H$47-'Assumptions'!$B$39 | J47: =MAX(0,'Assumptions'!$B$64*$V$46-'Assumptions'!$B$43) | K47: ='Assumptions'!$B$44+$J$47+$F$47+$I$47+$T$46 | L47: ='Assumptions'!$B$57/$K$47 | M47: =$B$47*(1-'Assumptions'!$B$58) | N47: =MIN($L$47,$M$47) | O47: ='Assumptions'!$B$56/$N$47 | P47: ='Assumptions'!$B$44+$J$47+$F$47+$I$47+$O$47 | Q47: ='Assumptions'!$B$60/$P$47 | R47: =$B$47*(1-'Assumptions'!$B$61) | S47: =MIN($Q$47,$R$47) | T47: ='Assumptions'!$B$59/$S$47 | U47: ='Assumptions'!$B$44+$J$47+$F$47+$I$47+$O$47+$T$47 | V47: =$U$47+$C$47
A48: 11 | B48: ='Assumptions'!$B$67/$U$47 | C48: ='Assumptions'!$B$5/$B$48 | D48: ='Assumptions'!$B$27*('Assumptions'!$B$44+'Assumptions'!$B$5/'Assumptions'!$B$27)/('Assumptions'!$B$44+'Assumptions'!$B$5/$B$48) | E48: ='Assumptions'!$B$40*'Assumptions'!$B$27/$D$48 | F48: =$E$48-'Assumptions'!$B$40 | G48: ='Assumptions'!$B$25*('Assumptions'!$B$44+'Assumptions'!$B$5/'Assumptions'!$B$25)/('Assumptions'!$B$44+'Assumptions'!$B$5/$B$48) | H48: ='Assumptions'!$B$38*'Assumptions'!$B$26/$G$48 | I48: =$H$48-'Assumptions'!$B$39 | J48: =MAX(0,'Assumptions'!$B$64*$V$47-'Assumptions'!$B$43) | K48: ='Assumptions'!$B$44+$J$48+$F$48+$I$48+$T$47 | L48: ='Assumptions'!$B$57/$K$48 | M48: =$B$48*(1-'Assumptions'!$B$58) | N48: =MIN($L$48,$M$48) | O48: ='Assumptions'!$B$56/$N$48 | P48: ='Assumptions'!$B$44+$J$48+$F$48+$I$48+$O$48 | Q48: ='Assumptions'!$B$60/$P$48 | R48: =$B$48*(1-'Assumptions'!$B$61) | S48: =MIN($Q$48,$R$48) | T48: ='Assumptions'!$B$59/$S$48 | U48: ='Assumptions'!$B$44+$J$48+$F$48+$I$48+$O$48+$T$48 | V48: =$U$48+$C$48
...

Sheet Return-Solver
A1: Return-Solver — F ownership % needed for 3× and 4× on $10M
A2: Approach: assume F converts; OTHER classes' elections from base-case Waterfall hold; solve closed form.
B3: Exit 1 ($700M) | C3: Exit 2 ($1.2B) | D3: Exit 3 ($2B) | E3: Exit 4 ($4B) | F3: Exit 5 ($8B)
A4: Exit value | B4: ='Assumptions'!$B$14 | C4: ='Assumptions'!$B$15 | D4: ='Assumptions'!$B$16 | E4: ='Assumptions'!$B$17 | F4: ='Assumptions'!$B$18
A5: Others' pref total (sum of pref electors) | B5: =IF('Waterfall'!B49="preference",'Waterfall'!$B$21,0)+IF('Waterfall'!B61="preference",'Waterfall'!$B$22,0)+IF('Waterfall'!B73="preference",'Waterfall'!$B$23,0)+IF('Waterfall'!B85="preference",'Waterfall'!$B$24,0)+IF('Waterfall'!B97="preference",'Waterfall'!$B$25,0)+IF('Waterfall'!B109="preference",'Waterfall'!$B$26,0) | C5: =IF('Waterfall'!C49="preference",'Waterfall'!$B$21,0)+IF('Waterfall'!C61="preference",'Waterfall'!$B$22,0)+IF('Waterfall'!C73="preference",'Waterfall'!$B$23,0)+IF('Waterfall'!C85="preference",'Waterfall'!$B$24,0)+IF('Waterfall'!C97="preference",'Waterfall'!$B$25,0)+IF('Waterfall'!C109="preference",'Waterfall'!$B$26,0) | D5: =IF('Waterfall'!D49="preference",'Waterfall'!$B$21,0)+IF('Waterfall'!D61="preference",'Waterfall'!$B$22,0)+IF('Waterfall'!D73="preference",'Waterfall'!$B$23,0)+IF('Waterfall'!D85="preference",'Waterfall'!$B$24,0)+IF('Waterfall'!D97="preference",'Waterfall'!$B$25,0)+IF('Waterfall'!D109="preference",'Waterfall'!$B$26,0) | E5: =IF('Waterfall'!E49="preference",'Waterfall'!$B$21,0)+IF('Waterfall'!E61="preference",'Waterfall'!$B$22,0)+IF('Waterfall'!E73="preference",'Waterfall'!$B$23,0)+IF('Waterfall'!E85="preference",'Waterfall'!$B$24,0)+IF('Waterfall'!E97="preference",'Waterfall'!$B$25,0)+IF('Waterfall'!E109="preference",'Waterfall'!$B$26,0) | F5: =IF('Waterfall'!F49="preference",'Waterfall'!$B$21,0)+IF('Waterfall'!F61="preference",'Waterfall'!$B$22,0)+IF('Waterfall'!F73="preference",'Waterfall'!$B$23,0)+IF('Waterfall'!F85="preference",'Waterfall'!$B$24,0)+IF('Waterfall'!F97="preference",'Waterfall'!$B$25,0)+IF('Waterfall'!F109="preference",'Waterfall'!$B$26,0)
A6: Others' convert pool (sum of conv shares + common + notes + issued opts) | B6: =IF('Waterfall'!B49="convert",'Waterfall'!$B$12,0)+IF('Waterfall'!B61="convert",'Waterfall'!$B$13,0)+IF('Waterfall'!B73="convert",'Waterfall'!$B$14,0)+IF('Waterfall'!B85="convert",'Waterfall'!$B$15,0)+IF('Waterfall'!B97="convert",'Waterfall'!$B$16,0)+IF('Waterfall'!B109="convert",'Waterfall'!$B$17,0)+'Waterfall'!$B$6+'Waterfall'!$B$7+'Waterfall'!$B$8 | C6: =IF('Waterfall'!C49="convert",'Waterfall'!$B$12,0)+IF('Waterfall'!C61="convert",'Waterfall'!$B$13,0)+IF('Waterfall'!C73="convert",'Waterfall'!$B$14,0)+IF('Waterfall'!C85="convert",'Waterfall'!$B$15,0)+IF('Waterfall'!C97="convert",'Waterfall'!$B$16,0)+IF('Waterfall'!C109="convert",'Waterfall'!$B$17,0)+'Waterfall'!$B$6+'Waterfall'!$B$7+'Waterfall'!$B$8 | D6: =IF('Waterfall'!D49="convert",'Waterfall'!$B$12,0)+IF('Waterfall'!D61="convert",'Waterfall'!$B$13,0)+IF('Waterfall'!D73="convert",'Waterfall'!$B$14,0)+IF('Waterfall'!D85="convert",'Waterfall'!$B$15,0)+IF('Waterfall'!D97="convert",'Waterfall'!$B$16,0)+IF('Waterfall'!D109="convert",'Waterfall'!$B$17,0)+'Waterfall'!$B$6+'Waterfall'!$B$7+'Waterfall'!$B$8 | E6: =IF('Waterfall'!E49="convert",'Waterfall'!$B$12,0)+IF('Waterfall'!E61="convert",'Waterfall'!$B$13,0)+IF('Waterfall'!E73="convert",'Waterfall'!$B$14,0)+IF('Waterfall'!E85="convert",'Waterfall'!$B$15,0)+IF('Waterfall'!E97="convert",'Waterfall'!$B$16,0)+IF('Waterfall'!E109="convert",'Waterfall'!$B$17,0)+'Waterfall'!$B$6+'Waterfall'!$B$7+'Waterfall'!$B$8 | F6: =IF('Waterfall'!F49="convert",'Waterfall'!$B$12,0)+IF('Waterfall'!F61="convert",'Waterfall'!$B$13,0)+IF('Waterfall'!F73="convert",'Waterfall'!$B$14,0)+IF('Waterfall'!F85="convert",'Waterfall'!$B$15,0)+IF('Waterfall'!F97="convert",'Waterfall'!$B$16,0)+IF('Waterfall'!F109="convert",'Waterfall'!$B$17,0)+'Waterfall'!$B$6+'Waterfall'!$B$7+'Waterfall'!$B$8
A7: Residual R = exit + strike*opts − others' pref total | B7: ='Assumptions'!$B$14+'Assumptions'!$B$11*'Waterfall'!$B$8-B5 | C7: ='Assumptions'!$B$15+'Assumptions'!$B$11*'Waterfall'!$B$8-C5 | D7: ='Assumptions'!$B$16+'Assumptions'!$B$11*'Waterfall'!$B$8-D5 | E7: ='Assumptions'!$B$17+'Assumptions'!$B$11*'Waterfall'!$B$8-E5 | F7: ='Assumptions'!$B$18+'Assumptions'!$B$11*'Waterfall'!$B$8-F5
A8: Pre-F portion of FD (base-case pre_money_FD) | B8: ='Pro-Forma'!$U$20 | C8: ='Pro-Forma'!$U$20 | D8: ='Pro-Forma'!$U$20 | E8: ='Pro-Forma'!$U$20 | F8: ='Pro-Forma'!$U$20
A10: TARGET 3× ($30M to us → F class needs $90M)
A11: Required F class payoff (3× × 3 = 9× × $10M) | B11: ='Assumptions'!$B$72*3*'Assumptions'!$B$9 | C11: ='Assumptions'!$B$72*3*'Assumptions'!$B$9 | D11: ='Assumptions'!$B$72*3*'Assumptions'!$B$9 | E11: ='Assumptions'!$B$72*3*'Assumptions'!$B$9 | F11: ='Assumptions'!$B$72*3*'Assumptions'!$B$9
A12: F_shares needed (closed form) | B12: =IFERROR(B11*B6/(B7-B11),NA()) | C12: =IFERROR(C11*C6/(C7-C11),NA()) | D12: =IFERROR(D11*D6/(D7-D11),NA()) | E12: =IFERROR(E11*E6/(E7-E11),NA()) | F12: =IFERROR(F11*F6/(F7-F11),NA())
A13: F ownership % (= F_shares / (F_shares + pre_F_other)) | B13: =IF(OR(B7<=B11,B12<=0),"INFEASIBLE",IF(B12/(B12+B8)>1,"INFEASIBLE",B12/(B12+B8))) | C13: =IF(OR(C7<=C11,C12<=0),"INFEASIBLE",IF(C12/(C12+C8)>1,"INFEASIBLE",C12/(C12+C8))) | D13: =IF(OR(D7<=D11,D12<=0),"INFEASIBLE",IF(D12/(D12+D8)>1,"INFEASIBLE",D12/(D12+D8))) | E13: =IF(OR(E7<=E11,E12<=0),"INFEASIBLE",IF(E12/(E12+E8)>1,"INFEASIBLE",E12/(E12+E8))) | F13: =IF(OR(F7<=F11,F12<=0),"INFEASIBLE",IF(F12/(F12+F8)>1,"INFEASIBLE",F12/(F12+F8)))
A14: Sanity: implied our payoff @ that F_pct | B14: =IF(ISNUMBER(B13),(B12/(B12+B6))*B7/3,"—") | C14: =IF(ISNUMBER(C13),(C12/(C12+C6))*C7/3,"—") | D14: =IF(ISNUMBER(D13),(D12/(D12+D6))*D7/3,"—") | E14: =IF(ISNUMBER(E13),(E12/(E12+E6))*E7/3,"—") | F14: =IF(ISNUMBER(F13),(F12/(F12+F6))*F7/3,"—")
A16: TARGET 4× ($40M to us → F class needs $120M)
A17: Required F class payoff (4× × 3 = 12× × $10M) | B17: ='Assumptions'!$B$73*3*'Assumptions'!$B$9 | C17: ='Assumptions'!$B$73*3*'Assumptions'!$B$9 | D17: ='Assumptions'!$B$73*3*'Assumptions'!$B$9 | E17: ='Assumptions'!$B$73*3*'Assumptions'!$B$9 | F17: ='Assumptions'!$B$73*3*'Assumptions'!$B$9
A18: F_shares needed | B18: =IFERROR(B17*B6/(B7-B17),NA()) | C18: =IFERROR(C17*C6/(C7-C17),NA()) | D18: =IFERROR(D17*D6/(D7-D17),NA()) | E18: =IFERROR(E17*E6/(E7-E17),NA()) | F18: =IFERROR(F17*F6/(F7-F17),NA())
A19: F ownership % (4×) | B19: =IF(OR(B7<=B17,B18<=0),"INFEASIBLE",IF(B18/(B18+B8)>1,"INFEASIBLE",B18/(B18+B8))) | C19: =IF(OR(C7<=C17,C18<=0),"INFEASIBLE",IF(C18/(C18+C8)>1,"INFEASIBLE",C18/(C18+C8))) | D19: =IF(OR(D7<=D17,D18<=0),"INFEASIBLE",IF(D18/(D18+D8)>1,"INFEASIBLE",D18/(D18+D8))) | E19: =IF(OR(E7<=E17,E18<=0),"INFEASIBLE",IF(E18/(E18+E8)>1,"INFEASIBLE",E18/(E18+E8))) | F19: =IF(OR(F7<=F17,F18<=0),"INFEASIBLE",IF(F18/(F18+F8)>1,"INFEASIBLE",F18/(F18+F8)))
A20: Sanity: implied our payoff @ that F_pct (4×) | B20: =IF(ISNUMBER(B19),(B18/(B18+B6))*B7/3,"—") | C20: =IF(ISNUMBER(C19),(C18/(C18+C6))*C7/3,"—") | D20: =IF(ISNUMBER(D19),(D18/(D18+D6))*D7/3,"—") | E20: =IF(ISNUMBER(E19),(E18/(E18+E6))*E7/3,"—") | F20: =IF(ISNUMBER(F19),(F18/(F18+F6))*F7/3,"—")
A22: Note: At low exits ($700M), F's preference alone returns $10M = 1×; therefore F MUST convert to reach 3× or 4×.
A23: INFEASIBLE flagged when residual ≤ required F class payoff or implied ownership > 100%.
