Workbook

Sheet Assumptions
B2: Kelvin Dynamics — Series F Assumptions & Solver
B3: All inputs in USD or shares unless noted
B5: Series F Round Terms
B6: Series F pre-money valuation ($) | C6: 1400000000
B7: Series F primary raise ($) | C7: 30000000
B8: Series F secondary raise ($) | C8: 15000000
B9: Tender PPS multiplier (× F PPS) | C9: 0.85
B10: ESOP refresh target (% of post-F FD) | C10: 0.13
B11: Our fund check ($) | C11: 10000000
B12: F_LEAD primary check ($) | C12: 20000000
B13: Option strike ($) | C13: 1
B15: Prior Round OCPs (for AD)
B16: Seed OCP | C16: 1
B17: Series A OCP | C17: 3
B18: Series B OCP | C18: 10
B19: Series C OCP | C19: 25
B20: Series D OCP (post-E NCP, compound base) | C20: 58.118347
B21: Series D original OCP (issued at) | C21: 60
B22: Series E OCP | C22: 49.158311
B24: Invested Capital by Series
B25: Seed invested ($) | C25: 5000000
B26: Series A invested ($) | C26: 15000000
B27: Series B invested ($) | C27: 30000000
B28: Series C invested ($) | C28: 60000000
B29: Series D invested ($) | C29: 100000000
B30: Series E invested ($) | C30: 300000000
B32: Convertible Notes
B33: Note A principal ($) | C33: 5000000
B34: Note A valuation cap ($) | C34: 1000000000
B35: Note A discount | C35: 0.2
B36: Note B principal ($) | C36: 3000000
B37: Note B valuation cap ($) | C37: 1600000000
B38: Note B discount | C38: 0.15
B40: Pre-F Share Counts (broad-based AD inputs)
B41: Founders common (F1+F2+F3) | C41: =E41+F41+G41 -> 8000000 | D41: (F1 / F2 / F3 →) | E41: 4000000 | F41: 2500000 | G41: 1500000
B42: Employee RSAs (10 × 100,000) | C42: 1000000
B43: Seed preferred shares | C43: 5000000
B44: Series A preferred shares | C44: 5000000
B45: Series B preferred shares | C45: 3000000
B46: Series C preferred shares | C46: 2400000
...

Sheet Pro-Forma
B2: Kelvin Dynamics — Pro-Forma Cap Table (Post-Series F)
B3: Shares and ownership % after F closing, AD adjustments, note conversions, and tender
B5: Anti-Dilution Block (Broad-Based WA)
B6: Class | C6: OCP-for-AD | D6: F PPS | E6: Trigger? | F6: NCP (post-F) | G6: New Ratio | H6: As-Converted Shares
B7: Seed | C7: =Assumptions!C16 -> 1 | D7: =Assumptions!C88 -> 37.345247 | E7: =IF(D7<C7,"Yes","No") -> No | F7: =IF(E7="Yes",C7*(Assumptions!C52+Assumptions!C7/C7)/(Assumptions!C52+Assumptions!C7/D7),C7) -> 1 | G7: =C7/F7 -> 1 | H7: =Assumptions!C25/F7 -> 5000000
B8: Series A | C8: =Assumptions!C17 -> 3 | D8: =Assumptions!C88 -> 37.345247 | E8: =IF(D8<C8,"Yes","No") -> No | F8: =IF(E8="Yes",C8*(Assumptions!C52+Assumptions!C7/C8)/(Assumptions!C52+Assumptions!C7/D8),C8) -> 3 | G8: =C8/F8 -> 1 | H8: =Assumptions!C26/F8 -> 5000000
B9: Series B | C9: =Assumptions!C18 -> 10 | D9: =Assumptions!C88 -> 37.345247 | E9: =IF(D9<C9,"Yes","No") -> No | F9: =IF(E9="Yes",C9*(Assumptions!C52+Assumptions!C7/C9)/(Assumptions!C52+Assumptions!C7/D9),C9) -> 10 | G9: =C9/F9 -> 1 | H9: =Assumptions!C27/F9 -> 3000000
B10: Series C | C10: =Assumptions!C19 -> 25 | D10: =Assumptions!C88 -> 37.345247 | E10: =IF(D10<C10,"Yes","No") -> No | F10: =IF(E10="Yes",C10*(Assumptions!C52+Assumptions!C7/C10)/(Assumptions!C52+Assumptions!C7/D10),C10) -> 25 | G10: =C10/F10 -> 1 | H10: =Assumptions!C28/F10 -> 2400000
B11: Series D | C11: =Assumptions!C20 -> 58.118347 | D11: =Assumptions!C88 -> 37.345247 | E11: =IF(D11<C11,"Yes","No") -> Yes | F11: =IF(E11="Yes",C11*(Assumptions!C52+Assumptions!C7/C11)/(Assumptions!C52+Assumptions!C7/D11),C11) -> 57.672415 | G11: =Assumptions!C21/F11 -> 1.0403587 | H11: =Assumptions!C29/F11 -> 1733931.2
B12: Series E | C12: =Assumptions!C22 -> 49.158311 | D12: =Assumptions!C88 -> 37.345247 | E12: =IF(D12<C12,"Yes","No") -> Yes | F12: =IF(E12="Yes",C12*(Assumptions!C52+Assumptions!C7/C12)/(Assumptions!C52+Assumptions!C7/D12),C12) -> 48.904722 | G12: =C12/F12 -> 1.0051854 | H12: =Assumptions!C30/F12 -> 6134376.9
B13: Total AD top-up shares | H13: =SUM(H7:H12)-({A}C43+{A}C44+{A}C45+{A}C46+{A}C47+{A}C48) -> #VALUE!
B15: Convertible Notes Conversion
B16: Note | C16: Principal | D16: Cap-Implied PPS | E16: Discount-Implied PPS | F16: Conversion PPS | G16: Branch | H16: Shares Issued
B17: Note A | C17: =Assumptions!C33 -> 5000000 | D17: =Assumptions!C34/(Assumptions!C52+Assumptions!C90+Assumptions!C96) -> 26.808552 | E17: =Assumptions!C88*(1-Assumptions!C35) -> 29.876198 | F17: =MIN(D17,E17) -> 26.808552 | G17: =IF(D17<=E17,"cap","discount") -> cap | H17: =C17/F17 -> 186507.65
B18: Note B | C18: =Assumptions!C36 -> 3000000 | D18: =Assumptions!C37/(Assumptions!C52+Assumptions!C90+Assumptions!C94) -> 42.788152 | E18: =Assumptions!C88*(1-Assumptions!C38) -> 31.74346 | F18: =MIN(D18,E18) -> 31.74346 | G18: =IF(D18<=E18,"cap","discount") -> discount | H18: =C18/F18 -> 94507.656
B19: Total notes shares | H19: =SUM(H17:H18) -> 281015.3
B21: Secondary Tender (founder share-out → F_LEAD)
B22: Tender PPS (= 0.85 × F_PPS) | C22: =Assumptions!C97 -> 31.74346
B23: Tender size ($) | C23: =Assumptions!C8 -> 15000000
B24: Total tender shares (transferred) | C24: =C23/C22 -> 472538.28
B26: Founder | C26: Pre-F Common | D26: Pro-Rata Share | E26: Tendered to F_LEAD | F26: Post-F Common
B27: F1 (CEO) | C27: =Assumptions!E41 -> 4000000 | D27: =C27/Assumptions!C41 -> 0.5 | E27: =$C$24*D27 -> 236269.14 | F27: =C27-E27 -> 3763730.9
B28: F2 (CTO) | C28: =Assumptions!F41 -> 2500000 | D28: =C28/Assumptions!C41 -> 0.3125 | E28: =$C$24*D28 -> 147668.21 | F28: =C28-E28 -> 2352331.8
B29: F3 (Chief Sci.) | C29: =Assumptions!G41 -> 1500000 | D29: =C29/Assumptions!C41 -> 0.1875 | E29: =$C$24*D29 -> 88600.928 | F29: =C29-E29 -> 1411399.1
B30: Total founders | C30: =SUM(C27:C29) -> 8000000 | D30: =SUM(D27:D29) -> 1 | E30: =SUM(E27:E29) -> 472538.28 | F30: =SUM(F27:F29) -> 7527461.7
B32: F_LEAD secondary common (from tender) | C32: =C24 -> 472538.28
B34: Post-F Cap Table by Stakeholder
B35: Stakeholder | C35: Role / Class | D35: Common (incl. RSAs) | E35: Preferred (as-conv.) | F35: Note-Conv. | G35: F Primary | H35: F Secondary | I35: Total Shares | J35: Ownership %
B36: F1 | C36: Founder (CEO) | D36: =F27 -> 3763730.9 | E36: 0 | F36: 0 | G36: 0 | H36: 0 | I36: =D36+E36+F36+G36+H36 -> 3763730.9 | J36: =I36/I$70 -> 0.098176516
B37: F2 | C37: Founder (CTO) | D37: =F28 -> 2352331.8 | E37: 0 | F37: 0 | G37: 0 | H37: 0 | I37: =D37+E37+F37+G37+H37 -> 2352331.8 | J37: =I37/I$70 -> 0.061360323
B38: F3 | C38: Founder (Chief Sci.) | D38: =F29 -> 1411399.1 | E38: 0 | F38: 0 | G38: 0 | H38: 0 | I38: =D38+E38+F38+G38+H38 -> 1411399.1 | J38: =I38/I$70 -> 0.036816194
B39: E1 | C39: Employee RSA | D39: =Assumptions!C42/10 -> 100000 | E39: 0 | F39: 0 | G39: 0 | H39: 0 | I39: =D39+E39+F39+G39+H39 -> 100000 | J39: =I39/I$70 -> 0.0026084893
B40: E2 | C40: Employee RSA | D40: =Assumptions!C42/10 -> 100000 | E40: 0 | F40: 0 | G40: 0 | H40: 0 | I40: =D40+E40+F40+G40+H40 -> 100000 | J40: =I40/I$70 -> 0.0026084893
B41: E3 | C41: Employee RSA | D41: =Assumptions!C42/10 -> 100000 | E41: 0 | F41: 0 | G41: 0 | H41: 0 | I41: =D41+E41+F41+G41+H41 -> 100000 | J41: =I41/I$70 -> 0.0026084893
B42: E4 | C42: Employee RSA | D42: =Assumptions!C42/10 -> 100000 | E42: 0 | F42: 0 | G42: 0 | H42: 0 | I42: =D42+E42+F42+G42+H42 -> 100000 | J42: =I42/I$70 -> 0.0026084893
B43: E5 | C43: Employee RSA | D43: =Assumptions!C42/10 -> 100000 | E43: 0 | F43: 0 | G43: 0 | H43: 0 | I43: =D43+E43+F43+G43+H43 -> 100000 | J43: =I43/I$70 -> 0.0026084893
B44: E6 | C44: Employee RSA | D44: =Assumptions!C42/10 -> 100000 | E44: 0 | F44: 0 | G44: 0 | H44: 0 | I44: =D44+E44+F44+G44+H44 -> 100000 | J44: =I44/I$70 -> 0.0026084893
B45: E7 | C45: Employee RSA | D45: =Assumptions!C42/10 -> 100000 | E45: 0 | F45: 0 | G45: 0 | H45: 0 | I45: =D45+E45+F45+G45+H45 -> 100000 | J45: =I45/I$70 -> 0.0026084893
B46: E8 | C46: Employee RSA | D46: =Assumptions!C42/10 -> 100000 | E46: 0 | F46: 0 | G46: 0 | H46: 0 | I46: =D46+E46+F46+G46+H46 -> 100000 | J46: =I46/I$70 -> 0.0026084893
B47: E9 | C47: Employee RSA | D47: =Assumptions!C42/10 -> 100000 | E47: 0 | F47: 0 | G47: 0 | H47: 0 | I47: =D47+E47+F47+G47+H47 -> 100000 | J47: =I47/I$70 -> 0.0026084893
...

Sheet Return-Solver
B2: Kelvin Dynamics — Return Solver
B3: Required Series F class ownership % to return 3× / 4× our $10M check, by exit
B5: Inputs (base case)
B6: Our check ($) | C6: =Assumptions!C11 -> 10000000
B7: 3× target ($) | C7: =Assumptions!C64*C6 -> 30000000
B8: 4× target ($) | C8: =Assumptions!D64*C6 -> 40000000
B9: F primary new shares (base) | C9: =Assumptions!C89 -> 803315.08
B10: Post-F FD T_F (base) | C10: =Assumptions!C101 -> 38336366
B12: Required F-Class Ownership % per Exit (incl. F's equilibrium election)
B13: Exit Value | C13: F Class Total $ (waterfall) | D13: F Election (waterfall) | E13: Req. F-Class % for 3× | F13: Req. F-Class % for 4× | G13: Req. Company % for 3× | H13: Req. Company % for 4× | I13: Feasibility
B14: Exit 1: $700M | C14: =Waterfall!C34 -> 30000000 | D14: =Waterfall!C24 -> preference | E14: =$C$7/C14 -> 1 | F14: =$C$8/C14 -> 1.3333333 | G14: =E14*$C$9/$C$10 -> 0.020954388 | H14: =F14*$C$9/$C$10 -> 0.027939184 | I14: =IF(F14>1,"4× infeasible",IF(E14>1,"3× infeasible","Both feasible")) -> 4× infeasible
B15: Exit 2: $1.2B | C15: =Waterfall!D34 -> 30000000 | D15: =Waterfall!D24 -> preference | E15: =$C$7/C15 -> 1 | F15: =$C$8/C15 -> 1.3333333 | G15: =E15*$C$9/$C$10 -> 0.020954388 | H15: =F15*$C$9/$C$10 -> 0.027939184 | I15: =IF(F15>1,"4× infeasible",IF(E15>1,"3× infeasible","Both feasible")) -> 4× infeasible
B16: Exit 3: $2B | C16: =Waterfall!E34 -> 44793811 | D16: =Waterfall!E24 -> convert | E16: =$C$7/C16 -> 0.66973538 | F16: =$C$8/C16 -> 0.8929805 | G16: =E16*$C$9/$C$10 -> 0.014033895 | H16: =F16*$C$9/$C$10 -> 0.01871186 | I16: =IF(F16>1,"4× infeasible",IF(E16>1,"3× infeasible","Both feasible")) -> Both feasible
B17: Exit 4: $4B | C17: =Waterfall!F34 -> 89680111 | D17: =Waterfall!F24 -> convert | E17: =$C$7/C17 -> 0.33452233 | F17: =$C$8/C17 -> 0.44602978 | G17: =E17*$C$9/$C$10 -> 0.0070097107 | H17: =F17*$C$9/$C$10 -> 0.0093462809 | I17: =IF(F17>1,"4× infeasible",IF(E17>1,"3× infeasible","Both feasible")) -> Both feasible
B18: Exit 5: $8B | C18: =Waterfall!G34 -> 1.7930421e+08 | D18: =Waterfall!G24 -> convert | E18: =$C$7/C18 -> 0.16731342 | F18: =$C$8/C18 -> 0.22308456 | G18: =E18*$C$9/$C$10 -> 0.0035059503 | H18: =F18*$C$9/$C$10 -> 0.0046746003 | I18: =IF(F18>1,"4× infeasible",IF(E18>1,"3× infeasible","Both feasible")) -> Both feasible
B20: Reference: at base-case (1/3 of F class) our return = | C20: =Waterfall!C22 -> 700000000 | D20: =Waterfall!D22 -> 1200000000 | E20: =Waterfall!E22 -> 2000000000 | F20: =Waterfall!F22 -> 4000000000 | G20: =Waterfall!G22 -> 8000000000
B21: Our $ proceeds at base-case ownership | C21: =Waterfall!C34*(Assumptions!C11/Assumptions!C7) -> 10000000 | D21: =Waterfall!D34*(Assumptions!C11/Assumptions!C7) -> 10000000 | E21: =Waterfall!E34*(Assumptions!C11/Assumptions!C7) -> 14931270 | F21: =Waterfall!F34*(Assumptions!C11/Assumptions!C7) -> 29893370 | G21: =Waterfall!G34*(Assumptions!C11/Assumptions!C7) -> 59768069
B22: Our MOIC at base-case ownership | C22: =C21/Assumptions!C11 -> 1 | D22: =D21/Assumptions!C11 -> 1 | E22: =E21/Assumptions!C11 -> 1.493127 | F22: =F21/Assumptions!C11 -> 2.989337 | G22: =G21/Assumptions!C11 -> 5.9768069
B24: Notes
B25: F-Class % is share of Series F class (vs F_LEAD's 2/3 + our 1/3 = 100%).
B26: Company % = Required F-Class % × F_class_shares / T_F (post-F FD).
B27: Infeasibility triggered when target exceeds the entire F-class proceeds at that exit.

Sheet Sensitivity
B2: Kelvin Dynamics — Sensitivity (ESOP × Pre-Money @ $2B Exit)
B3: Per-cell fixed-point solve (F PPS, ESOP top-up, AD on D and E, both notes branches)
B5: Our $10M Check — Post-F Ownership %
B6: ESOP refresh ↓ / Pre-money → | C6: =Assumptions!C63 -> 1200000000 | D6: =Assumptions!D63 -> 1400000000 | E6: =Assumptions!E63 -> 1800000000
B7: =Assumptions!C62 -> 0.11 | C7: =M61 -> 0.0081150329 | D7: =M111 -> 0.006985159 | E7: =M161 -> 0.0054637046
B8: =Assumptions!D62 -> 0.13 | C8: =M211 -> 0.0081145933 | D8: =M261 -> 0.0069847959 | E8: =M311 -> 0.0054634358
B9: =Assumptions!E62 -> 0.15 | C9: =M361 -> 0.008113969 | D9: =M411 -> 0.0069842585 | E9: =M461 -> 0.0054630155
B11: Our $10M Check — $ Proceeds at $2B Exit
B12: ESOP refresh ↓ / Pre-money → | C12: =Assumptions!C63 -> 1200000000 | D12: =Assumptions!D63 -> 1400000000 | E12: =Assumptions!E63 -> 1800000000
B13: =Assumptions!C62 -> 0.11 | C13: =M62 -> 17075680 | D13: =M112 -> 14703175 | E13: =M162 -> 11505507
B14: =Assumptions!D62 -> 0.13 | C14: =M212 -> 17351776 | D14: =M262 -> 14931270 | E14: =M312 -> 11674332
B15: =Assumptions!E62 -> 0.15 | C15: =M362 -> 17759653 | D15: =M412 -> 15282139 | E15: =M462 -> 11948552
B17: Our $10M Check — Multiple of Invested Capital (MOIC)
B18: ESOP refresh ↓ / Pre-money → | C18: =Assumptions!C63 -> 1200000000 | D18: =Assumptions!D63 -> 1400000000 | E18: =Assumptions!E63 -> 1800000000
B19: =Assumptions!C62 -> 0.11 | C19: =M62/Assumptions!C11 -> 1.707568 | D19: =M112/Assumptions!C11 -> 1.4703175 | E19: =M162/Assumptions!C11 -> 1.1505507
B20: =Assumptions!D62 -> 0.13 | C20: =M212/Assumptions!C11 -> 1.7351776 | D20: =M262/Assumptions!C11 -> 1.493127 | E20: =M312/Assumptions!C11 -> 1.1674332
B21: =Assumptions!E62 -> 0.15 | C21: =M362/Assumptions!C11 -> 1.7759653 | D21: =M412/Assumptions!C11 -> 1.5282139 | E21: =M462/Assumptions!C11 -> 1.1948552
B30: Scenario 1: ESOP=11%, Pre=$1.2B
B31: Iter → | C31: 0 | D31: 1 | E31: 2 | F31: 3 | G31: 4 | H31: 5
B32: F PPS | C32: =Assumptions!C63/Assumptions!C52 -> 32.770803 | D32: =Assumptions!C63/(Assumptions!C52+C38+C42+C46) -> 32.770803 | E32: =Assumptions!C63/(Assumptions!C52+D38+D42+D46) -> 32.505896 | F32: =Assumptions!C63/(Assumptions!C52+E38+E42+E46) -> 32.503755 | G32: =Assumptions!C63/(Assumptions!C52+F38+F42+F46) -> 32.503738 | H32: =Assumptions!C63/(Assumptions!C52+G38+G42+G46) -> 32.503737
B33: F primary shares | C33: =Assumptions!C7/C32 -> 915449.03 | D33: =Assumptions!C7/D32 -> 915449.03 | E33: =Assumptions!C7/E32 -> 922909.49 | F33: =Assumptions!C7/F32 -> 922970.28 | G33: =Assumptions!C7/G32 -> 922970.78 | H33: =Assumptions!C7/H32 -> 922970.78
B34: NCP_D | C34: =Assumptions!C20*(Assumptions!C52+Assumptions!C7/Assumptions!C20)/(Assumptions!C52+Assumptions!C7/C32) -> 57.500114 | D34: =Assumptions!C20*(Assumptions!C52+Assumptions!C7/Assumptions!C20)/(Assumptions!C52+Assumptions!C7/D32) -> 57.500114 | E34: =Assumptions!C20*(Assumptions!C52+Assumptions!C7/Assumptions!C20)/(Assumptions!C52+Assumptions!C7/E32) -> 57.488687 | F34: =Assumptions!C20*(Assumptions!C52+Assumptions!C7/Assumptions!C20)/(Assumptions!C52+Assumptions!C7/F32) -> 57.488594 | G34: =Assumptions!C20*(Assumptions!C52+Assumptions!C7/Assumptions!C20)/(Assumptions!C52+Assumptions!C7/G32) -> 57.488593 | H34: =Assumptions!C20*(Assumptions!C52+Assumptions!C7/Assumptions!C20)/(Assumptions!C52+Assumptions!C7/H32) -> 57.488593
B35: AD_D shares | C35: =MAX(0,IF(C32<Assumptions!C20,Assumptions!C29/C34-Assumptions!C47,0)) -> 18499.98 | D35: =MAX(0,IF(D32<Assumptions!C20,Assumptions!C29/D34-Assumptions!C47,0)) -> 18499.98 | E35: =MAX(0,IF(E32<Assumptions!C20,Assumptions!C29/E34-Assumptions!C47,0)) -> 18845.664 | F35: =MAX(0,IF(F32<Assumptions!C20,Assumptions!C29/F34-Assumptions!C47,0)) -> 18848.481 | G35: =MAX(0,IF(G32<Assumptions!C20,Assumptions!C29/G34-Assumptions!C47,0)) -> 18848.504 | H35: =MAX(0,IF(H32<Assumptions!C20,Assumptions!C29/H34-Assumptions!C47,0)) -> 18848.504
B36: NCP_E | C36: =Assumptions!C22*(Assumptions!C52+Assumptions!C7/Assumptions!C22)/(Assumptions!C52+Assumptions!C7/C32) -> 48.758616 | D36: =Assumptions!C22*(Assumptions!C52+Assumptions!C7/Assumptions!C22)/(Assumptions!C52+Assumptions!C7/D32) -> 48.758616 | E36: =Assumptions!C22*(Assumptions!C52+Assumptions!C7/Assumptions!C22)/(Assumptions!C52+Assumptions!C7/E32) -> 48.748926 | F36: =Assumptions!C22*(Assumptions!C52+Assumptions!C7/Assumptions!C22)/(Assumptions!C52+Assumptions!C7/F32) -> 48.748847 | G36: =Assumptions!C22*(Assumptions!C52+Assumptions!C7/Assumptions!C22)/(Assumptions!C52+Assumptions!C7/G32) -> 48.748846 | H36: =Assumptions!C22*(Assumptions!C52+Assumptions!C7/Assumptions!C22)/(Assumptions!C52+Assumptions!C7/H32) -> 48.748846
B37: AD_E shares | C37: =MAX(0,IF(C32<Assumptions!C22,Assumptions!C30/C36-Assumptions!C48,0)) -> 50091.764 | D37: =MAX(0,IF(D32<Assumptions!C22,Assumptions!C30/D36-Assumptions!C48,0)) -> 50091.764 | E37: =MAX(0,IF(E32<Assumptions!C22,Assumptions!C30/E36-Assumptions!C48,0)) -> 51314.738 | F37: =MAX(0,IF(F32<Assumptions!C22,Assumptions!C30/F36-Assumptions!C48,0)) -> 51324.705 | G37: =MAX(0,IF(G32<Assumptions!C22,Assumptions!C30/G36-Assumptions!C48,0)) -> 51324.786 | H37: =MAX(0,IF(H32<Assumptions!C22,Assumptions!C30/H36-Assumptions!C48,0)) -> 51324.787
B38: ESOP top-up | C38: =MAX(0,(Assumptions!C62*(Assumptions!C52+C35+C37+C33+C42+C46)-Assumptions!C51)/(1-Assumptions!C62)) -> 0 | D38: =MAX(0,(Assumptions!C62*(Assumptions!C52+D35+D37+D33+D42+D46)-Assumptions!C51)/(1-Assumptions!C62)) -> 0 | E38: =MAX(0,(Assumptions!C62*(Assumptions!C52+E35+E37+E33+E42+E46)-Assumptions!C51)/(1-Assumptions!C62)) -> 0 | F38: =MAX(0,(Assumptions!C62*(Assumptions!C52+F35+F37+F33+F42+F46)-Assumptions!C51)/(1-Assumptions!C62)) -> 0 | G38: =MAX(0,(Assumptions!C62*(Assumptions!C52+G35+G37+G33+G42+G46)-Assumptions!C51)/(1-Assumptions!C62)) -> 0 | H38: =MAX(0,(Assumptions!C62*(Assumptions!C52+H35+H37+H33+H42+H46)-Assumptions!C51)/(1-Assumptions!C62)) -> 0
B39: N_A cap PPS | C39: =Assumptions!C34/(Assumptions!C52+C38+C46) -> 27.309003 | D39: =Assumptions!C34/(Assumptions!C52+C38+C46) -> 27.309003 | E39: =Assumptions!C34/(Assumptions!C52+D38+D46) -> 27.228918 | F39: =Assumptions!C34/(Assumptions!C52+E38+E46) -> 27.228267 | G39: =Assumptions!C34/(Assumptions!C52+F38+F46) -> 27.228262 | H39: =Assumptions!C34/(Assumptions!C52+G38+G46) -> 27.228262
B40: N_A disc PPS | C40: =C32*(1-Assumptions!C35) -> 26.216643 | D40: =D32*(1-Assumptions!C35) -> 26.216643 | E40: =E32*(1-Assumptions!C35) -> 26.004717 | F40: =F32*(1-Assumptions!C35) -> 26.003004 | G40: =G32*(1-Assumptions!C35) -> 26.00299 | H40: =H32*(1-Assumptions!C35) -> 26.00299
B41: N_A conv PPS | C41: =MIN(C39,C40) -> 26.216643 | D41: =MIN(D39,D40) -> 26.216643 | E41: =MIN(E39,E40) -> 26.004717 | F41: =MIN(F39,F40) -> 26.003004 | G41: =MIN(G39,G40) -> 26.00299 | H41: =MIN(H39,H40) -> 26.00299
B42: N_A shares | C42: 0 | D42: =Assumptions!C33/D41 -> 190718.55 | E42: =Assumptions!C33/E41 -> 192272.81 | F42: =Assumptions!C33/F41 -> 192285.48 | G42: =Assumptions!C33/G41 -> 192285.58 | H42: =Assumptions!C33/H41 -> 192285.58
B43: N_B cap PPS | C43: =Assumptions!C37/(Assumptions!C52+C38+C42) -> 43.694405 | D43: =Assumptions!C37/(Assumptions!C52+C38+C42) -> 43.694405 | E43: =Assumptions!C37/(Assumptions!C52+D38+D42) -> 43.468009 | F43: =Assumptions!C37/(Assumptions!C52+E38+E42) -> 43.466173 | G43: =Assumptions!C37/(Assumptions!C52+F38+F42) -> 43.466158 | H43: =Assumptions!C37/(Assumptions!C52+G38+G42) -> 43.466158
B44: N_B disc PPS | C44: =C32*(1-Assumptions!C38) -> 27.855183 | D44: =D32*(1-Assumptions!C38) -> 27.855183 | E44: =E32*(1-Assumptions!C38) -> 27.630012 | F44: =F32*(1-Assumptions!C38) -> 27.628192 | G44: =G32*(1-Assumptions!C38) -> 27.628177 | H44: =H32*(1-Assumptions!C38) -> 27.628177
B45: N_B conv PPS | C45: =MIN(C43,C44) -> 27.855183 | D45: =MIN(D43,D44) -> 27.855183 | E45: =MIN(E43,E44) -> 27.630012 | F45: =MIN(F43,F44) -> 27.628192 | G45: =MIN(G43,G44) -> 27.628177 | H45: =MIN(H43,H44) -> 27.628177
B46: N_B shares | C46: 0 | D46: =Assumptions!C36/D45 -> 107699.89 | E46: =Assumptions!C36/E45 -> 108577.59 | F46: =Assumptions!C36/F45 -> 108584.74 | G46: =Assumptions!C36/G45 -> 108584.8 | H46: =Assumptions!C36/H45 -> 108584.8
B47: Post-F FD (T_F) | H47: =Assumptions!C52+H38+H35+H37+H42+H46+H33 -> 37911975
B49: Mini-waterfall @ $2B exit
B50: Class | C50: Shares | D50: Pref ($) | E50: Iter1 | F50: Iter2 | G50: Iter3 | H50: Iter4 | I50: Convert@final | J50: Final $
B51: Series F | C51: =H33 -> 922970.78 | D51: =Assumptions!C7 -> 30000000 | E51: =IF(D51>((Assumptions!C57+IF(D62=1,C61*C60,0))*C51/(SUM($C$51:$C$57)+C58+C59+IF(D62=1,C60,0))),1,0) -> 0 | F51: =IF(D51>((Assumptions!C57+IF(D62=1,C61*C60,0)-(SUMPRODUCT($D$51:$D$57,$E$51:$E$57)-D51*E51))*C51/((((SUM($C$51:$C$57)-SUMPRODUCT($C$51:$C$57,$E$51:$E$57))-C51*(1-E51))+C58+C59+IF(D62=1,C60,0))+C51)),1,0) -> 0 | G51: =IF(D51>((Assumptions!C57+IF(D62=1,C61*C60,0)-(SUMPRODUCT($D$51:$D$57,$F$51:$F$57)-D51*F51))*C51/((((SUM($C$51:$C$57)-SUMPRODUCT($C$51:$C$57,$F$51:$F$57))-C51*(1-F51))+C58+C59+IF(D62=1,C60,0))+C51)),1,0) -> 0 | H51: =IF(D51>((Assumptions!C57+IF(D62=1,C61*C60,0)-(SUMPRODUCT($D$51:$D$57,$G$51:$G$57)-D51*G51))*C51/((((SUM($C$51:$C$57)-SUMPRODUCT($C$51:$C$57,$G$51:$G$57))-C51*(1-G51))+C58+C59+IF(D62=1,C60,0))+C51)),1,0) -> 0 | I51: =((Assumptions!C57+IF(D62=1,C61*C60,0)-(SUMPRODUCT($D$51:$D$57,$H$51:$H$57)-D51*H51))*C51/((((SUM($C$51:$C$57)-SUMPRODUCT($C$51:$C$57,$H$51:$H$57))-C51*(1-H51))+C58+C59+IF(D62=1,C60,0))+C51)) -> 51227040 | J51: =IF(H51=1,D51,I51) -> 51227040
B52: Series E | C52: =Assumptions!C48+H37 -> 6153991.8 | D52: =Assumptions!C30 -> 300000000 | E52: =IF(D52>((Assumptions!C57+IF(D62=1,C61*C60,0))*C52/(SUM($C$51:$C$57)+C58+C59+IF(D62=1,C60,0))),1,0) -> 0 | F52: =IF(D52>((Assumptions!C57+IF(D62=1,C61*C60,0)-(SUMPRODUCT($D$51:$D$57,$E$51:$E$57)-D52*E52))*C52/((((SUM($C$51:$C$57)-SUMPRODUCT($C$51:$C$57,$E$51:$E$57))-C52*(1-E52))+C58+C59+IF(D62=1,C60,0))+C52)),1,0) -> 0 | G52: =IF(D52>((Assumptions!C57+IF(D62=1,C61*C60,0)-(SUMPRODUCT($D$51:$D$57,$F$51:$F$57)-D52*F52))*C52/((((SUM($C$51:$C$57)-SUMPRODUCT($C$51:$C$57,$F$51:$F$57))-C52*(1-F52))+C58+C59+IF(D62=1,C60,0))+C52)),1,0) -> 0 | H52: =IF(D52>((Assumptions!C57+IF(D62=1,C61*C60,0)-(SUMPRODUCT($D$51:$D$57,$G$51:$G$57)-D52*G52))*C52/((((SUM($C$51:$C$57)-SUMPRODUCT($C$51:$C$57,$G$51:$G$57))-C52*(1-G52))+C58+C59+IF(D62=1,C60,0))+C52)),1,0) -> 0 | I52: =((Assumptions!C57+IF(D62=1,C61*C60,0)-(SUMPRODUCT($D$51:$D$57,$H$51:$H$57)-D52*H52))*C52/((((SUM($C$51:$C$57)-SUMPRODUCT($C$51:$C$57,$H$51:$H$57))-C52*(1-H52))+C58+C59+IF(D62=1,C60,0))+C52)) -> 3.4156096e+08 | J52: =IF(H52=1,D52,I52) -> 3.4156096e+08
B53: Series D | C53: =Assumptions!C47+H35 -> 1739475.5 | D53: =Assumptions!C29 -> 100000000 | E53: =IF(D53>((Assumptions!C57+IF(D62=1,C61*C60,0))*C53/(SUM($C$51:$C$57)+C58+C59+IF(D62=1,C60,0))),1,0) -> 1 | F53: =IF(D53>((Assumptions!C57+IF(D62=1,C61*C60,0)-(SUMPRODUCT($D$51:$D$57,$E$51:$E$57)-D53*E53))*C53/((((SUM($C$51:$C$57)-SUMPRODUCT($C$51:$C$57,$E$51:$E$57))-C53*(1-E53))+C58+C59+IF(D62=1,C60,0))+C53)),1,0) -> 1 | G53: =IF(D53>((Assumptions!C57+IF(D62=1,C61*C60,0)-(SUMPRODUCT($D$51:$D$57,$F$51:$F$57)-D53*F53))*C53/((((SUM($C$51:$C$57)-SUMPRODUCT($C$51:$C$57,$F$51:$F$57))-C53*(1-F53))+C58+C59+IF(D62=1,C60,0))+C53)),1,0) -> 1 | H53: =IF(D53>((Assumptions!C57+IF(D62=1,C61*C60,0)-(SUMPRODUCT($D$51:$D$57,$G$51:$G$57)-D53*G53))*C53/((((SUM($C$51:$C$57)-SUMPRODUCT($C$51:$C$57,$G$51:$G$57))-C53*(1-G53))+C58+C59+IF(D62=1,C60,0))+C53)),1,0) -> 1 | I53: =((Assumptions!C57+IF(D62=1,C61*C60,0)-(SUMPRODUCT($D$51:$D$57,$H$51:$H$57)-D53*H53))*C53/((((SUM($C$51:$C$57)-SUMPRODUCT($C$51:$C$57,$H$51:$H$57))-C53*(1-H53))+C58+C59+IF(D62=1,C60,0))+C53)) -> 96711827 | J53: =IF(H53=1,D53,I53) -> 100000000
...

Sheet Waterfall
B2: Kelvin Dynamics — Exit Waterfall (5 Scenarios × 7 Election Cells)
B3: 1× non-participating preferred with conversion election; notes ride convert pool
B5: Class Reference Schedule
B6: Class | C6: Shares (post-F) | D6: Liquidation Pref ($)
B7: Series F | C7: =Assumptions!C89 -> 803315.08 | D7: =Assumptions!C7 -> 30000000
B8: Series E | C8: ='Pro-Forma'!H12 -> 6134376.9 | D8: =Assumptions!C30 -> 300000000
B9: Series D | C9: ='Pro-Forma'!H11 -> 1733931.2 | D9: =Assumptions!C29 -> 100000000
B10: Series C | C10: ='Pro-Forma'!H10 -> 2400000 | D10: =Assumptions!C28 -> 60000000
B11: Series B | C11: ='Pro-Forma'!H9 -> 3000000 | D11: =Assumptions!C27 -> 30000000
B12: Series A | C12: ='Pro-Forma'!H8 -> 5000000 | D12: =Assumptions!C26 -> 15000000
B13: Seed | C13: ='Pro-Forma'!H7 -> 5000000 | D13: =Assumptions!C25 -> 5000000
B14: Notes A+B (combined) | C14: ='Pro-Forma'!H17+'Pro-Forma'!H18 -> 281015.3 | D14: 0
B15: Common + RSAs + F_LEAD secondary | C15: =Assumptions!C41+Assumptions!C42 -> 9000000 | D15: 0
B16: Issued options (vested, ITM only) | C16: =Assumptions!C49 -> 2500000 | D16: 0
B17: Option strike ($) | C17: =Assumptions!C13 -> 1
B18: Total pref ($, max if all take pref) | D18: =SUM(D7:D13) -> 540000000
B19: Total convert pool (priced + common + notes + ITM opts) | C19: =SUM(C7:C16) -> 35852639
B21: Exit Scenarios — Final Elections and Proceeds
B22: Exit Value ($) | C22: =Assumptions!C55 -> 700000000 | D22: =Assumptions!C56 -> 1200000000 | E22: =Assumptions!C57 -> 2000000000 | F22: =Assumptions!C58 -> 4000000000 | G22: =Assumptions!C59 -> 8000000000
B23: Class
B24: Series F | C24: =IF(H52=1,"preference","convert") -> preference | D24: =IF(H67=1,"preference","convert") -> preference | E24: =IF(H82=1,"preference","convert") -> convert | F24: =IF(H97=1,"preference","convert") -> convert | G24: =IF(H112=1,"preference","convert") -> convert
B25: Series E | C25: =IF(H53=1,"preference","convert") -> preference | D25: =IF(H68=1,"preference","convert") -> preference | E25: =IF(H83=1,"preference","convert") -> convert | F25: =IF(H98=1,"preference","convert") -> convert | G25: =IF(H113=1,"preference","convert") -> convert
B26: Series D | C26: =IF(H54=1,"preference","convert") -> preference | D26: =IF(H69=1,"preference","convert") -> preference | E26: =IF(H84=1,"preference","convert") -> preference | F26: =IF(H99=1,"preference","convert") -> convert | G26: =IF(H114=1,"preference","convert") -> convert
B27: Series C | C27: =IF(H55=1,"preference","convert") -> preference | D27: =IF(H70=1,"preference","convert") -> convert | E27: =IF(H85=1,"preference","convert") -> convert | F27: =IF(H100=1,"preference","convert") -> convert | G27: =IF(H115=1,"preference","convert") -> convert
B28: Series B | C28: =IF(H56=1,"preference","convert") -> preference | D28: =IF(H71=1,"preference","convert") -> convert | E28: =IF(H86=1,"preference","convert") -> convert | F28: =IF(H101=1,"preference","convert") -> convert | G28: =IF(H116=1,"preference","convert") -> convert
B29: Series A | C29: =IF(H57=1,"preference","convert") -> convert | D29: =IF(H72=1,"preference","convert") -> convert | E29: =IF(H87=1,"preference","convert") -> convert | F29: =IF(H102=1,"preference","convert") -> convert | G29: =IF(H117=1,"preference","convert") -> convert
B30: Seed | C30: =IF(H58=1,"preference","convert") -> convert | D30: =IF(H73=1,"preference","convert") -> convert | E30: =IF(H88=1,"preference","convert") -> convert | F30: =IF(H103=1,"preference","convert") -> convert | G30: =IF(H118=1,"preference","convert") -> convert
B32: Proceeds Matrix ($)
B33: Class | C33: $700M | D33: $1.2B | E33: $2B | F33: $4B | G33: $8B
B34: Series F | C34: =J52 -> 30000000 | D34: =J67 -> 30000000 | E34: =J82 -> 44793811 | F34: =J97 -> 89680111 | G34: =J112 -> 1.7930421e+08
B35: Series E | C35: =J53 -> 300000000 | D35: =J68 -> 300000000 | E35: =J83 -> 3.4206021e+08 | F35: =J98 -> 6.8482669e+08 | G35: =J113 -> 1.3692256e+09
B36: Series D | C36: =J54 -> 100000000 | D36: =J69 -> 100000000 | E36: =J84 -> 100000000 | F36: =J99 -> 1.935718e+08 | G36: =J114 -> 3.8702269e+08
B37: Series C | C37: =J55 -> 60000000 | D37: =J70 -> 68209373 | E37: =J85 -> 1.3382688e+08 | F37: =J100 -> 2.6793007e+08 | G37: =J115 -> 5.3569279e+08
B38: Series B | C38: =J56 -> 30000000 | D38: =J71 -> 85261716 | E38: =J86 -> 1.6728359e+08 | F38: =J101 -> 3.3491259e+08 | G38: =J116 -> 6.6961599e+08
B39: Series A | C39: =J57 -> 41894282 | D39: =J72 -> 1.4210286e+08 | E39: =J87 -> 2.7880599e+08 | F39: =J102 -> 5.5818765e+08 | G39: =J117 -> 1.1160266e+09
B40: Seed | C40: =J58 -> 41894282 | D40: =J73 -> 1.4210286e+08 | E40: =J88 -> 2.7880599e+08 | F40: =J103 -> 5.5818765e+08 | G40: =J118 -> 1.1160266e+09
B41: Notes A+B | C41: =J60 -> 2354586.9 | D41: =J75 -> 7986615.6 | E41: =J90 -> 15669750 | F41: =J105 -> 31371854 | G41: =J120 -> 62724113
B42: Common + RSAs + F_LEAD sec. | C42: =J61 -> 75409708 | D42: =J76 -> 2.5578515e+08 | E42: =J91 -> 5.0185078e+08 | F42: =J106 -> 1.0047378e+09 | G42: =J121 -> 2.008848e+09
B43: Issued options (net of strike) | C43: =J62 -> 18447141 | D43: =J77 -> 68551430 | E43: =J92 -> 1.36903e+08 | F43: =J107 -> 2.7659382e+08 | G43: =J122 -> 5.5551332e+08
B44: Total | C44: =SUM(C34:C43) -> 700000000 | D44: =SUM(D34:D43) -> 1200000000 | E44: =SUM(E34:E43) -> 2e+09 | F44: =SUM(F34:F43) -> 4e+09 | G44: =SUM(G34:G43) -> 8e+09
...
