Workbook

Sheet Assumptions
B2: Kelvin Dynamics — Series F Assumptions
B3: Sole source of inputs. All output tabs reference this sheet.
B5: Series F Round Terms
B6: Pre-money valuation ($) | C6: 1400000000
B7: Primary raise ($) | C7: 30000000
B8: Secondary tender ($) | C8: 15000000
B9: Tender PPS multiplier | C9: 0.85
B10: ESOP refresh target (% post-F FD) | C10: 0.13
B11: Our fund check ($) | C11: 10000000
B12: F_LEAD primary check ($) | C12: 20000000
B14: Exit Scenarios
B15: Exit 1 ($) | C15: 700000000
B16: Exit 2 ($) | C16: 1200000000
B17: Exit 3 ($, sensitivity ref) | C17: 2000000000
B18: Exit 4 ($) | C18: 4000000000
B19: Exit 5 ($) | C19: 8000000000
B21: Prior Round OCPs (for AD)
B22: Seed OCP ($/share) | C22: 1
B23: Series A OCP ($/share) | C23: 3
B24: Series B OCP ($/share) | C24: 10
B25: Series C OCP ($/share) | C25: 25
B26: Series D OCP (post-E NCP, $/share) | C26: 58.118347
B27: Series D original OCP ($/share) | C27: 60
B28: Series E OCP ($/share) | C28: 49.158311
B30: Pre-F Share Counts
B31: Founder F1 (CEO) common | C31: 4000000
B32: Founder F2 (CTO) common | C32: 2500000
B33: Founder F3 (CSci) common | C33: 1500000
B34: Employee RSAs (10 × 100k) | C34: 1000000
B35: Seed shares | C35: 5000000
B36: Series A shares | C36: 5000000
B37: Series B shares | C37: 3000000
B38: Series C shares | C38: 2400000
B39: Series D shares (post-E AD) | C39: 1720627
B40: Series D original shares (= $100M / $60) | C40: 1666667
B41: Series E shares | C41: 6102667
B42: Pre-F issued options | C42: 2500000
B43: Pre-F unissued option pool | C43: 1894667
B44: Pre-F FD total (sum) | C44: =SUM(C31:C43)-C40 -> 36617961
B46: Convertible Notes
...

Sheet Pro-Forma
B2: Kelvin Dynamics — Series F Pro-Forma
B3: Post-F cap table, AD adjustments, note conversions, tender. ($, shares)
B5: F PPS Solver — Iterative Fixed Point
B6: Iteration | C6: Iter 0 | D6: Iter 1 | E6: Iter 2 | F6: Iter 3 | G6: Iter 4 | H6: Iter 5 | I6: Iter 6 | J6: Iter 7 | K6: Iter 8 | L6: Iter 9
B7: F_PPS (input) | C7: 45 | D7: =C25 -> 37.375973 | E7: =D25 -> 37.300872 | F7: =E25 -> 37.299776 | G7: =F25 -> 37.29976 | H7: =G25 -> 37.29976 | I7: =H25 -> 37.29976 | J7: =I25 -> 37.29976 | K7: =J25 -> 37.29976 | L7: =K25 -> 37.29976
B8: NCP_D (post-F WA) | C8: =IF(C7<Assumptions!$C$26,Assumptions!$C$26*(Assumptions!$C$44+Assumptions!$C$7/Assumptions!$C$26)/(Assumptions!$C$44+Assumptions!$C$7/C7),Assumptions!$C$26) -> 57.883785 | D8: =IF(D7<Assumptions!$C$26,Assumptions!$C$26*(Assumptions!$C$44+Assumptions!$C$7/Assumptions!$C$26)/(Assumptions!$C$44+Assumptions!$C$7/D7),Assumptions!$C$26) -> 57.673433 | E8: =IF(E7<Assumptions!$C$26,Assumptions!$C$26*(Assumptions!$C$44+Assumptions!$C$7/Assumptions!$C$26)/(Assumptions!$C$44+Assumptions!$C$7/E7),Assumptions!$C$26) -> 57.670942 | F8: =IF(F7<Assumptions!$C$26,Assumptions!$C$26*(Assumptions!$C$44+Assumptions!$C$7/Assumptions!$C$26)/(Assumptions!$C$44+Assumptions!$C$7/F7),Assumptions!$C$26) -> 57.670906 | G8: =IF(G7<Assumptions!$C$26,Assumptions!$C$26*(Assumptions!$C$44+Assumptions!$C$7/Assumptions!$C$26)/(Assumptions!$C$44+Assumptions!$C$7/G7),Assumptions!$C$26) -> 57.670905 | H8: =IF(H7<Assumptions!$C$26,Assumptions!$C$26*(Assumptions!$C$44+Assumptions!$C$7/Assumptions!$C$26)/(Assumptions!$C$44+Assumptions!$C$7/H7),Assumptions!$C$26) -> 57.670905 | I8: =IF(I7<Assumptions!$C$26,Assumptions!$C$26*(Assumptions!$C$44+Assumptions!$C$7/Assumptions!$C$26)/(Assumptions!$C$44+Assumptions!$C$7/I7),Assumptions!$C$26) -> 57.670905 | J8: =IF(J7<Assumptions!$C$26,Assumptions!$C$26*(Assumptions!$C$44+Assumptions!$C$7/Assumptions!$C$26)/(Assumptions!$C$44+Assumptions!$C$7/J7),Assumptions!$C$26) -> 57.670905 | ... L8: =IF(L7<Assumptions!$C$26,Assumptions!$C$26*(Assumptions!$C$44+Assumptions!$C$7/Assumptions!$C$26)/(Assumptions!$C$44+Assumptions!$C$7/L7),Assumptions!$C$26) -> 57.670905
B9: Δ Series D shares | C9: =Assumptions!$C$40*Assumptions!$C$27/C8-Assumptions!$C$39 -> 6972.8859 | D9: =Assumptions!$C$40*Assumptions!$C$27/D8-Assumptions!$C$39 -> 13273.951 | E9: =Assumptions!$C$40*Assumptions!$C$27/E8-Assumptions!$C$39 -> 13348.833 | F9: =Assumptions!$C$40*Assumptions!$C$27/F8-Assumptions!$C$39 -> 13349.927 | G9: =Assumptions!$C$40*Assumptions!$C$27/G8-Assumptions!$C$39 -> 13349.943 | H9: =Assumptions!$C$40*Assumptions!$C$27/H8-Assumptions!$C$39 -> 13349.943 | I9: =Assumptions!$C$40*Assumptions!$C$27/I8-Assumptions!$C$39 -> 13349.943 | J9: =Assumptions!$C$40*Assumptions!$C$27/J8-Assumptions!$C$39 -> 13349.943 | ... L9: =Assumptions!$C$40*Assumptions!$C$27/L8-Assumptions!$C$39 -> 13349.943
B10: NCP_E (post-F WA) | C10: =IF(C7<Assumptions!$C$28,Assumptions!$C$28*(Assumptions!$C$44+Assumptions!$C$7/Assumptions!$C$28)/(Assumptions!$C$44+Assumptions!$C$7/C7),Assumptions!$C$28) -> 49.083958 | D10: =IF(D7<Assumptions!$C$28,Assumptions!$C$28*(Assumptions!$C$44+Assumptions!$C$7/Assumptions!$C$28)/(Assumptions!$C$44+Assumptions!$C$7/D7),Assumptions!$C$28) -> 48.905585 | E10: =IF(E7<Assumptions!$C$28,Assumptions!$C$28*(Assumptions!$C$44+Assumptions!$C$7/Assumptions!$C$28)/(Assumptions!$C$44+Assumptions!$C$7/E7),Assumptions!$C$28) -> 48.903473 | F10: =IF(F7<Assumptions!$C$28,Assumptions!$C$28*(Assumptions!$C$44+Assumptions!$C$7/Assumptions!$C$28)/(Assumptions!$C$44+Assumptions!$C$7/F7),Assumptions!$C$28) -> 48.903443 | G10: =IF(G7<Assumptions!$C$28,Assumptions!$C$28*(Assumptions!$C$44+Assumptions!$C$7/Assumptions!$C$28)/(Assumptions!$C$44+Assumptions!$C$7/G7),Assumptions!$C$28) -> 48.903442 | H10: =IF(H7<Assumptions!$C$28,Assumptions!$C$28*(Assumptions!$C$44+Assumptions!$C$7/Assumptions!$C$28)/(Assumptions!$C$44+Assumptions!$C$7/H7),Assumptions!$C$28) -> 48.903442 | I10: =IF(I7<Assumptions!$C$28,Assumptions!$C$28*(Assumptions!$C$44+Assumptions!$C$7/Assumptions!$C$28)/(Assumptions!$C$44+Assumptions!$C$7/I7),Assumptions!$C$28) -> 48.903442 | J10: =IF(J7<Assumptions!$C$28,Assumptions!$C$28*(Assumptions!$C$44+Assumptions!$C$7/Assumptions!$C$28)/(Assumptions!$C$44+Assumptions!$C$7/J7),Assumptions!$C$28) -> 48.903442 | ... L10: =IF(L7<Assumptions!$C$28,Assumptions!$C$28*(Assumptions!$C$44+Assumptions!$C$7/Assumptions!$C$28)/(Assumptions!$C$44+Assumptions!$C$7/L7),Assumptions!$C$28) -> 48.903442
B11: Δ Series E shares | C11: =Assumptions!$C$41*Assumptions!$C$28/C10-Assumptions!$C$41 -> 9244.3417 | D11: =Assumptions!$C$41*Assumptions!$C$28/D10-Assumptions!$C$41 -> 31536.282 | E11: =Assumptions!$C$41*Assumptions!$C$28/E10-Assumptions!$C$41 -> 31801.197 | F11: =Assumptions!$C$41*Assumptions!$C$28/F10-Assumptions!$C$41 -> 31805.07 | G11: =Assumptions!$C$41*Assumptions!$C$28/G10-Assumptions!$C$41 -> 31805.125 | H11: =Assumptions!$C$41*Assumptions!$C$28/H10-Assumptions!$C$41 -> 31805.125 | I11: =Assumptions!$C$41*Assumptions!$C$28/I10-Assumptions!$C$41 -> 31805.125 | J11: =Assumptions!$C$41*Assumptions!$C$28/J10-Assumptions!$C$41 -> 31805.125 | ... L11: =Assumptions!$C$41*Assumptions!$C$28/L10-Assumptions!$C$41 -> 31805.125
B12: Base FD (preF + ΔD + ΔE) | C12: =Assumptions!$C$44+C9+C11 -> 36634178 | D12: =Assumptions!$C$44+D9+D11 -> 36662771 | E12: =Assumptions!$C$44+E9+E11 -> 36663111 | F12: =Assumptions!$C$44+F9+F11 -> 36663116 | G12: =Assumptions!$C$44+G9+G11 -> 36663116 | H12: =Assumptions!$C$44+H9+H11 -> 36663116 | I12: =Assumptions!$C$44+I9+I11 -> 36663116 | J12: =Assumptions!$C$44+J9+J11 -> 36663116 | ... L12: =Assumptions!$C$44+L9+L11 -> 36663116
B13: F_S (new F primary shares) | C13: =Assumptions!$C$7/C7 -> 666666.67 | D13: =Assumptions!$C$7/D7 -> 802654.68 | E13: =Assumptions!$C$7/E7 -> 804270.75 | F13: =Assumptions!$C$7/F7 -> 804294.37 | G13: =Assumptions!$C$7/G7 -> 804294.71 | H13: =Assumptions!$C$7/H7 -> 804294.71 | I13: =Assumptions!$C$7/I7 -> 804294.71 | J13: =Assumptions!$C$7/J7 -> 804294.71 | ... L13: =Assumptions!$C$7/L7 -> 804294.71
B14: Note A — cap PPS | C14: =Assumptions!$C$48/(C12+0+0) -> 27.296914 | D14: =Assumptions!$C$48/(D12+C22+C21) -> 26.807754 | E14: =Assumptions!$C$48/(E12+D22+D21) -> 26.776298 | F14: =Assumptions!$C$48/(F12+E22+E21) -> 26.775905 | G14: =Assumptions!$C$48/(G12+F22+F21) -> 26.775899 | H14: =Assumptions!$C$48/(H12+G22+G21) -> 26.775899 | I14: =Assumptions!$C$48/(I12+H22+H21) -> 26.775899 | J14: =Assumptions!$C$48/(J12+I22+I21) -> 26.775899 | K14: =Assumptions!$C$48/(K12+J22+J21) -> 26.775899 | L14: =Assumptions!$C$48/(L12+K22+K21) -> 26.775899
B15: Note A — discount PPS | C15: =C7*(1-Assumptions!$C$49) -> 36 | D15: =D7*(1-Assumptions!$C$49) -> 29.900779 | E15: =E7*(1-Assumptions!$C$49) -> 29.840697 | F15: =F7*(1-Assumptions!$C$49) -> 29.839821 | G15: =G7*(1-Assumptions!$C$49) -> 29.839808 | H15: =H7*(1-Assumptions!$C$49) -> 29.839808 | I15: =I7*(1-Assumptions!$C$49) -> 29.839808 | J15: =J7*(1-Assumptions!$C$49) -> 29.839808 | ... L15: =L7*(1-Assumptions!$C$49) -> 29.839808
B16: Note A — conv PPS (min) | C16: =MIN(C14,C15) -> 27.296914 | D16: =MIN(D14,D15) -> 26.807754 | E16: =MIN(E14,E15) -> 26.776298 | F16: =MIN(F14,F15) -> 26.775905 | G16: =MIN(G14,G15) -> 26.775899 | H16: =MIN(H14,H15) -> 26.775899 | I16: =MIN(I14,I15) -> 26.775899 | J16: =MIN(J14,J15) -> 26.775899 | ... L16: =MIN(L14,L15) -> 26.775899
B17: Note A — shares issued | C17: =Assumptions!$C$47/C16 -> 183170.89 | D17: =Assumptions!$C$47/D16 -> 186513.2 | E17: =Assumptions!$C$47/E16 -> 186732.31 | F17: =Assumptions!$C$47/F16 -> 186735.05 | G17: =Assumptions!$C$47/G16 -> 186735.09 | H17: =Assumptions!$C$47/H16 -> 186735.09 | I17: =Assumptions!$C$47/I16 -> 186735.09 | J17: =Assumptions!$C$47/J16 -> 186735.09 | ... L17: =Assumptions!$C$47/L16 -> 186735.09
B18: Note B — cap PPS | C18: =Assumptions!$C$51/(C12+0+0) -> 43.675062 | D18: =Assumptions!$C$51/(D12+C22+C17) -> 42.772308 | E18: =Assumptions!$C$51/(E12+D22+D17) -> 42.736704 | F18: =Assumptions!$C$51/(F12+E22+E17) -> 42.736045 | G18: =Assumptions!$C$51/(G12+F22+F17) -> 42.736035 | H18: =Assumptions!$C$51/(H12+G22+G17) -> 42.736035 | I18: =Assumptions!$C$51/(I12+H22+H17) -> 42.736035 | J18: =Assumptions!$C$51/(J12+I22+I17) -> 42.736035 | K18: =Assumptions!$C$51/(K12+J22+J17) -> 42.736035 | L18: =Assumptions!$C$51/(L12+K22+K17) -> 42.736035
B19: Note B — discount PPS | C19: =C7*(1-Assumptions!$C$52) -> 38.25 | D19: =D7*(1-Assumptions!$C$52) -> 31.769577 | E19: =E7*(1-Assumptions!$C$52) -> 31.705741 | F19: =F7*(1-Assumptions!$C$52) -> 31.70481 | G19: =G7*(1-Assumptions!$C$52) -> 31.704796 | H19: =H7*(1-Assumptions!$C$52) -> 31.704796 | I19: =I7*(1-Assumptions!$C$52) -> 31.704796 | J19: =J7*(1-Assumptions!$C$52) -> 31.704796 | ... L19: =L7*(1-Assumptions!$C$52) -> 31.704796
B20: Note B — conv PPS (min) | C20: =MIN(C18,C19) -> 38.25 | D20: =MIN(D18,D19) -> 31.769577 | E20: =MIN(E18,E19) -> 31.705741 | F20: =MIN(F18,F19) -> 31.70481 | G20: =MIN(G18,G19) -> 31.704796 | H20: =MIN(H18,H19) -> 31.704796 | I20: =MIN(I18,I19) -> 31.704796 | J20: =MIN(J18,J19) -> 31.704796 | ... L20: =MIN(L18,L19) -> 31.704796
B21: Note B — shares issued | C21: =Assumptions!$C$50/C20 -> 78431.373 | D21: =Assumptions!$C$50/D20 -> 94429.963 | E21: =Assumptions!$C$50/E20 -> 94620.088 | F21: =Assumptions!$C$50/F20 -> 94622.868 | G21: =Assumptions!$C$50/G20 -> 94622.907 | H21: =Assumptions!$C$50/H20 -> 94622.907 | I21: =Assumptions!$C$50/I20 -> 94622.908 | J21: =Assumptions!$C$50/J20 -> 94622.908 | ... L21: =Assumptions!$C$50/L20 -> 94622.908
B22: ESOP top-up | C22: =MAX(0,(Assumptions!$C$10*(C12+C17+C21+C13)-Assumptions!$C$56)/(1-Assumptions!$C$10)) -> 561438.08 | D22: =MAX(0,(Assumptions!$C$10*(D12+D17+D21+D13)-Assumptions!$C$56)/(1-Assumptions!$C$10)) -> 588920.67 | E22: =MAX(0,(Assumptions!$C$10*(E12+E17+E21+E13)-Assumptions!$C$56)/(1-Assumptions!$C$10)) -> 589274.07 | F22: =MAX(0,(Assumptions!$C$10*(F12+F17+F21+F13)-Assumptions!$C$56)/(1-Assumptions!$C$10)) -> 589279.17 | G22: =MAX(0,(Assumptions!$C$10*(G12+G17+G21+G13)-Assumptions!$C$56)/(1-Assumptions!$C$10)) -> 589279.24 | H22: =MAX(0,(Assumptions!$C$10*(H12+H17+H21+H13)-Assumptions!$C$56)/(1-Assumptions!$C$10)) -> 589279.24 | I22: =MAX(0,(Assumptions!$C$10*(I12+I17+I21+I13)-Assumptions!$C$56)/(1-Assumptions!$C$10)) -> 589279.24 | J22: =MAX(0,(Assumptions!$C$10*(J12+J17+J21+J13)-Assumptions!$C$56)/(1-Assumptions!$C$10)) -> 589279.24 | ... L22: =MAX(0,(Assumptions!$C$10*(L12+L17+L21+L13)-Assumptions!$C$56)/(1-Assumptions!$C$10)) -> 589279.24
B23: T_F (post-F FD shares) | C23: =C12+C22+C17+C21+C13 -> 38123885 | D23: =D12+D22+D17+D21+D13 -> 38335290 | E23: =E12+E22+E17+E21+E13 -> 38338008 | F23: =F12+F22+F17+F21+F13 -> 38338047 | G23: =G12+G22+G17+G21+G13 -> 38338048 | H23: =H12+H22+H17+H21+H13 -> 38338048 | I23: =I12+I22+I17+I21+I13 -> 38338048 | J23: =J12+J22+J17+J21+J13 -> 38338048 | ... L23: =L12+L22+L17+L21+L13 -> 38338048
B24: Pre-money FD shares | C24: =C23-C13 -> 37457219 | D24: =D23-D13 -> 37532635 | E24: =E23-E13 -> 37533737 | F24: =F23-F13 -> 37533753 | G24: =G23-G13 -> 37533753 | H24: =H23-H13 -> 37533753 | I24: =I23-I13 -> 37533753 | J24: =J23-J13 -> 37533753 | ... L24: =L23-L13 -> 37533753
B25: F_PPS_new | C25: =Assumptions!$C$6/C24 -> 37.375973 | D25: =Assumptions!$C$6/D24 -> 37.300872 | E25: =Assumptions!$C$6/E24 -> 37.299776 | F25: =Assumptions!$C$6/F24 -> 37.29976 | G25: =Assumptions!$C$6/G24 -> 37.29976 | H25: =Assumptions!$C$6/H24 -> 37.29976 | I25: =Assumptions!$C$6/I24 -> 37.29976 | J25: =Assumptions!$C$6/J24 -> 37.29976 | ... L25: =Assumptions!$C$6/L24 -> 37.29976
B27: Converged Round Mechanics
B28: Series F PPS ($) | C28: =L25 -> 37.29976
B29: Series F new primary shares | C29: =L13 -> 804294.71
B30: Pre-money FD shares | C30: =L24 -> 37533753
B31: Post-F FD shares (T_F) | C31: =L23 -> 38338048
B32: ESOP top-up | C32: =L22 -> 589279.24
B33: Total post-F option pool | C33: =Assumptions!$C$56+L22 -> 4983946.2
B34: Implied post-money valuation ($) | C34: =C28*C31 -> 1430000000
B35: Tender PPS ($) | C35: =Assumptions!$C$9*C28 -> 31.704796
B36: Tender shares (founders → F_LEAD) | C36: =Assumptions!$C$8/C35 -> 473114.54
B38: Anti-Dilution Block (Broad-Based WA)
B39: Class | C39: Original OCP | D39: Trigger? | E39: New conv. price (NCP) | F39: New ratio (compound) | G39: As-converted shares | H39: Δ vs. pre-F
B40: Seed | C40: =Assumptions!$C$22 -> 1 | D40: =IF(C28<Assumptions!$C$22,"YES","no") -> no | E40: =IF(C28<Assumptions!$C$22,Assumptions!$C$22*(Assumptions!$C$44+Assumptions!$C$7/Assumptions!$C$22)/(Assumptions!$C$44+Assumptions!$C$7/C28),Assumptions!$C$22) -> 1 | F40: =Assumptions!$C$22/E40 -> 1 | G40: =Assumptions!$C$35*F40 -> 5000000 | H40: =G40-Assumptions!$C$35 -> 0
B41: Series A | C41: =Assumptions!$C$23 -> 3 | D41: =IF(C28<Assumptions!$C$23,"YES","no") -> no | E41: =IF(C28<Assumptions!$C$23,Assumptions!$C$23*(Assumptions!$C$44+Assumptions!$C$7/Assumptions!$C$23)/(Assumptions!$C$44+Assumptions!$C$7/C28),Assumptions!$C$23) -> 3 | F41: =Assumptions!$C$23/E41 -> 1 | G41: =Assumptions!$C$36*F41 -> 5000000 | H41: =G41-Assumptions!$C$36 -> 0
B42: Series B | C42: =Assumptions!$C$24 -> 10 | D42: =IF(C28<Assumptions!$C$24,"YES","no") -> no | E42: =IF(C28<Assumptions!$C$24,Assumptions!$C$24*(Assumptions!$C$44+Assumptions!$C$7/Assumptions!$C$24)/(Assumptions!$C$44+Assumptions!$C$7/C28),Assumptions!$C$24) -> 10 | F42: =Assumptions!$C$24/E42 -> 1 | G42: =Assumptions!$C$37*F42 -> 3000000 | H42: =G42-Assumptions!$C$37 -> 0
B43: Series C | C43: =Assumptions!$C$25 -> 25 | D43: =IF(C28<Assumptions!$C$25,"YES","no") -> no | E43: =IF(C28<Assumptions!$C$25,Assumptions!$C$25*(Assumptions!$C$44+Assumptions!$C$7/Assumptions!$C$25)/(Assumptions!$C$44+Assumptions!$C$7/C28),Assumptions!$C$25) -> 25 | F43: =Assumptions!$C$25/E43 -> 1 | G43: =Assumptions!$C$38*F43 -> 2400000 | H43: =G43-Assumptions!$C$38 -> 0
B44: Series D | C44: =Assumptions!$C$27 -> 60 | D44: =IF(C28<Assumptions!$C$26,"YES","no") -> YES | E44: =L8 -> 57.670905 | F44: =Assumptions!$C$27/E44 -> 1.040386 | G44: =Assumptions!$C$40*F44 -> 1733976.9 | H44: =G44-Assumptions!$C$39 -> 13349.943
...

Sheet Waterfall
B2: Kelvin Dynamics — Waterfall
B3: 1× non-participating with conversion election. Notes ride convert. Game-theoretic Nash equilibrium per exit.
B5: Exit Scenarios ($M)
B6: Exit value ($) | C6: =Assumptions!$C$15 -> 700000000 | D6: =Assumptions!$C$16 -> 1200000000 | E6: =Assumptions!$C$17 -> 2000000000 | F6: =Assumptions!$C$18 -> 4000000000 | G6: =Assumptions!$C$19 -> 8000000000
B7: + Issued option strike cash | C7: ='Pro-Forma'!$D$76*Assumptions!$C$55 -> 2500000 | D7: ='Pro-Forma'!$D$76*Assumptions!$C$55 -> 2500000 | E7: ='Pro-Forma'!$D$76*Assumptions!$C$55 -> 2500000 | F7: ='Pro-Forma'!$D$76*Assumptions!$C$55 -> 2500000 | G7: ='Pro-Forma'!$D$76*Assumptions!$C$55 -> 2500000
B8: Distributable to equity ($) | C8: =C6+C7 -> 702500000 | D8: =D6+D7 -> 1202500000 | E8: =E6+E7 -> 2002500000 | F8: =F6+F7 -> 4002500000 | G8: =G6+G7 -> 8002500000
B10: Per-Class Election (Nash equilibrium)
B11: Series F | C11: =IF(H43,"preference","convert") -> preference | D11: =IF(H65,"preference","convert") -> preference | E11: =IF(H87,"preference","convert") -> convert | F11: =IF(H109,"preference","convert") -> convert | G11: =IF(H131,"preference","convert") -> convert
B12: Series E | C12: =IF(H44,"preference","convert") -> preference | D12: =IF(H66,"preference","convert") -> preference | E12: =IF(H88,"preference","convert") -> convert | F12: =IF(H110,"preference","convert") -> convert | G12: =IF(H132,"preference","convert") -> convert
B13: Series D | C13: =IF(H45,"preference","convert") -> preference | D13: =IF(H67,"preference","convert") -> preference | E13: =IF(H89,"preference","convert") -> preference | F13: =IF(H111,"preference","convert") -> convert | G13: =IF(H133,"preference","convert") -> convert
B14: Series C | C14: =IF(H46,"preference","convert") -> preference | D14: =IF(H68,"preference","convert") -> convert | E14: =IF(H90,"preference","convert") -> convert | F14: =IF(H112,"preference","convert") -> convert | G14: =IF(H134,"preference","convert") -> convert
B15: Series B | C15: =IF(H47,"preference","convert") -> preference | D15: =IF(H69,"preference","convert") -> convert | E15: =IF(H91,"preference","convert") -> convert | F15: =IF(H113,"preference","convert") -> convert | G15: =IF(H135,"preference","convert") -> convert
B16: Series A | C16: =IF(H48,"preference","convert") -> convert | D16: =IF(H70,"preference","convert") -> convert | E16: =IF(H92,"preference","convert") -> convert | F16: =IF(H114,"preference","convert") -> convert | G16: =IF(H136,"preference","convert") -> convert
B17: Seed | C17: =IF(H49,"preference","convert") -> convert | D17: =IF(H71,"preference","convert") -> convert | E17: =IF(H93,"preference","convert") -> convert | F17: =IF(H115,"preference","convert") -> convert | G17: =IF(H137,"preference","convert") -> convert
B19: Per-Class Proceeds ($)
B20: Series F | C20: =IF(H43,Assumptions!$C$7,'Pro-Forma'!$C$29*H53) -> 30000000 | D20: =IF(H65,Assumptions!$C$7,'Pro-Forma'!$C$29*H75) -> 30000000 | E20: =IF(H87,Assumptions!$C$7,'Pro-Forma'!$C$29*H97) -> 44846573 | F20: =IF(H109,Assumptions!$C$7,'Pro-Forma'!$C$29*H119) -> 89785811 | G20: =IF(H131,Assumptions!$C$7,'Pro-Forma'!$C$29*H141) -> 1.7951554e+08
B21: Series E | C21: =IF(H44,Assumptions!$C$41*Assumptions!$C$28,'Pro-Forma'!$G$45*H53) -> 2.999968e+08 | D21: =IF(H66,Assumptions!$C$41*Assumptions!$C$28,'Pro-Forma'!$G$45*H75) -> 2.999968e+08 | E21: =IF(H88,Assumptions!$C$41*Assumptions!$C$28,'Pro-Forma'!$G$45*H97) -> 3.420513e+08 | F21: =IF(H110,Assumptions!$C$41*Assumptions!$C$28,'Pro-Forma'!$G$45*H119) -> 6.8480937e+08 | G21: =IF(H132,Assumptions!$C$41*Assumptions!$C$28,'Pro-Forma'!$G$45*H141) -> 1.369191e+09
B22: Series D | C22: =IF(H45,Assumptions!$C$40*Assumptions!$C$27,'Pro-Forma'!$G$44*H53) -> 100000020 | D22: =IF(H67,Assumptions!$C$40*Assumptions!$C$27,'Pro-Forma'!$G$44*H75) -> 100000020 | E22: =IF(H89,Assumptions!$C$40*Assumptions!$C$27,'Pro-Forma'!$G$44*H97) -> 100000020 | F22: =IF(H111,Assumptions!$C$40*Assumptions!$C$27,'Pro-Forma'!$G$44*H119) -> 1.93569e+08 | G22: =IF(H133,Assumptions!$C$40*Assumptions!$C$27,'Pro-Forma'!$G$44*H141) -> 3.870171e+08
B23: Series C | C23: =IF(H46,Assumptions!$C$38*Assumptions!$C$25,'Pro-Forma'!$G$43*H53) -> 60000000 | D23: =IF(H68,Assumptions!$C$38*Assumptions!$C$25,'Pro-Forma'!$G$43*H75) -> 68208793 | E23: =IF(H90,Assumptions!$C$38*Assumptions!$C$25,'Pro-Forma'!$G$43*H97) -> 1.3382131e+08 | F23: =IF(H112,Assumptions!$C$38*Assumptions!$C$25,'Pro-Forma'!$G$43*H119) -> 2.6791914e+08 | G23: =IF(H134,Assumptions!$C$38*Assumptions!$C$25,'Pro-Forma'!$G$43*H141) -> 5.3567093e+08
B24: Series B | C24: =IF(H47,Assumptions!$C$37*Assumptions!$C$24,'Pro-Forma'!$G$42*H53) -> 30000000 | D24: =IF(H69,Assumptions!$C$37*Assumptions!$C$24,'Pro-Forma'!$G$42*H75) -> 85260991 | E24: =IF(H91,Assumptions!$C$37*Assumptions!$C$24,'Pro-Forma'!$G$42*H97) -> 1.6727664e+08 | F24: =IF(H113,Assumptions!$C$37*Assumptions!$C$24,'Pro-Forma'!$G$42*H119) -> 3.3489892e+08 | G24: =IF(H135,Assumptions!$C$37*Assumptions!$C$24,'Pro-Forma'!$G$42*H141) -> 6.6958866e+08
B25: Series A | C25: =IF(H48,Assumptions!$C$36*Assumptions!$C$23,'Pro-Forma'!$G$41*H53) -> 41894352 | D25: =IF(H70,Assumptions!$C$36*Assumptions!$C$23,'Pro-Forma'!$G$41*H75) -> 1.4210165e+08 | E25: =IF(H92,Assumptions!$C$36*Assumptions!$C$23,'Pro-Forma'!$G$41*H97) -> 2.787944e+08 | F25: =IF(H114,Assumptions!$C$36*Assumptions!$C$23,'Pro-Forma'!$G$41*H119) -> 5.5816487e+08 | G25: =IF(H136,Assumptions!$C$36*Assumptions!$C$23,'Pro-Forma'!$G$41*H141) -> 1.1159811e+09
B26: Seed | C26: =IF(H49,Assumptions!$C$35*Assumptions!$C$22,'Pro-Forma'!$G$40*H53) -> 41894352 | D26: =IF(H71,Assumptions!$C$35*Assumptions!$C$22,'Pro-Forma'!$G$40*H75) -> 1.4210165e+08 | E26: =IF(H93,Assumptions!$C$35*Assumptions!$C$22,'Pro-Forma'!$G$40*H97) -> 2.787944e+08 | F26: =IF(H115,Assumptions!$C$35*Assumptions!$C$22,'Pro-Forma'!$G$40*H119) -> 5.5816487e+08 | G26: =IF(H137,Assumptions!$C$35*Assumptions!$C$22,'Pro-Forma'!$G$40*H141) -> 1.1159811e+09
B27: Notes (combined A+B) | C27: =('Pro-Forma'!$G$49+'Pro-Forma'!$G$50)*H53 -> 2357462.2 | D27: =('Pro-Forma'!$G$49+'Pro-Forma'!$G$50)*H75 -> 7996287.3 | E27: =('Pro-Forma'!$G$49+'Pro-Forma'!$G$50)*H97 -> 15688207 | F27: =('Pro-Forma'!$G$49+'Pro-Forma'!$G$50)*H119 -> 31408830 | G27: =('Pro-Forma'!$G$49+'Pro-Forma'!$G$50)*H141 -> 62798042
B28: Common + RSAs (founders, employees, F_LEAD secondary) | C28: =('Pro-Forma'!$D$62+'Pro-Forma'!$D$63+'Pro-Forma'!$D$64+'Pro-Forma'!$D$65+'Pro-Forma'!$D$74)*H53 -> 75409834 | D28: =('Pro-Forma'!$D$62+'Pro-Forma'!$D$63+'Pro-Forma'!$D$64+'Pro-Forma'!$D$65+'Pro-Forma'!$D$74)*H75 -> 2.5578297e+08 | E28: =('Pro-Forma'!$D$62+'Pro-Forma'!$D$63+'Pro-Forma'!$D$64+'Pro-Forma'!$D$65+'Pro-Forma'!$D$74)*H97 -> 5.0182993e+08 | F28: =('Pro-Forma'!$D$62+'Pro-Forma'!$D$63+'Pro-Forma'!$D$64+'Pro-Forma'!$D$65+'Pro-Forma'!$D$74)*H119 -> 1.0046968e+09 | G28: =('Pro-Forma'!$D$62+'Pro-Forma'!$D$63+'Pro-Forma'!$D$64+'Pro-Forma'!$D$65+'Pro-Forma'!$D$74)*H141 -> 2.008766e+09
B29: Issued options (net of strike, ITM) | C29: =IF(H53>Assumptions!$C$55,'Pro-Forma'!$D$76*(H53-Assumptions!$C$55),0) -> 18447176 | D29: =IF(H75>Assumptions!$C$55,'Pro-Forma'!$D$76*(H75-Assumptions!$C$55),0) -> 68550826 | E29: =IF(H97>Assumptions!$C$55,'Pro-Forma'!$D$76*(H97-Assumptions!$C$55),0) -> 1.368972e+08 | F29: =IF(H119>Assumptions!$C$55,'Pro-Forma'!$D$76*(H119-Assumptions!$C$55),0) -> 2.7658243e+08 | G29: =IF(H141>Assumptions!$C$55,'Pro-Forma'!$D$76*(H141-Assumptions!$C$55),0) -> 5.5549055e+08
B30: Total to all stakeholders | C30: =SUM(C20:C29) -> 700000000 | D30: =SUM(D20:D29) -> 1200000000 | E30: =SUM(E20:E29) -> 2e+09 | F30: =SUM(F20:F29) -> 4000000000 | G30: =SUM(G20:G29) -> 8e+09
B31: Check (vs. exit value) | C31: =ROUND(C30-C6,0) -> 0 | D31: =ROUND(D30-D6,0) -> 0 | E31: =ROUND(E30-E6,0) -> 0 | F31: =ROUND(F30-F6,0) -> 0 | G31: =ROUND(G30-G6,0) -> 0
B40: Exit 1 Nash Solver — iterative best response
B41: Iteration | C41: Iter 0 | D41: Iter 1 | E41: Iter 2 | F41: Iter 3 | G41: Iter 4 | H41: Iter 5
B42: Distributable ($) | C42: =C$8 -> 702500000 | D42: =C$8 -> 702500000 | E42: =C$8 -> 702500000 | F42: =C$8 -> 702500000 | G42: =C$8 -> 702500000 | H42: =C$8 -> 702500000
B43: F_takes_pref | C43: FALSE | D43: =Assumptions!$C$7>C54 -> 1 | E43: =Assumptions!$C$7>D54 -> 1 | F43: =Assumptions!$C$7>E54 -> 1 | G43: =Assumptions!$C$7>F54 -> 1 | H43: =Assumptions!$C$7>G54 -> 1
B44: E_takes_pref | C44: FALSE | D44: =Assumptions!$C$41*Assumptions!$C$28>C55 -> 1 | E44: =Assumptions!$C$41*Assumptions!$C$28>D55 -> 1 | F44: =Assumptions!$C$41*Assumptions!$C$28>E55 -> 1 | G44: =Assumptions!$C$41*Assumptions!$C$28>F55 -> 1 | H44: =Assumptions!$C$41*Assumptions!$C$28>G55 -> 1
B45: D_takes_pref | C45: FALSE | D45: =Assumptions!$C$40*Assumptions!$C$27>C56 -> 1 | E45: =Assumptions!$C$40*Assumptions!$C$27>D56 -> 1 | F45: =Assumptions!$C$40*Assumptions!$C$27>E56 -> 1 | G45: =Assumptions!$C$40*Assumptions!$C$27>F56 -> 1 | H45: =Assumptions!$C$40*Assumptions!$C$27>G56 -> 1
B46: C_takes_pref | C46: FALSE | D46: =Assumptions!$C$38*Assumptions!$C$25>C57 -> 1 | E46: =Assumptions!$C$38*Assumptions!$C$25>D57 -> 1 | F46: =Assumptions!$C$38*Assumptions!$C$25>E57 -> 1 | G46: =Assumptions!$C$38*Assumptions!$C$25>F57 -> 1 | H46: =Assumptions!$C$38*Assumptions!$C$25>G57 -> 1
B47: B_takes_pref | C47: FALSE | D47: =Assumptions!$C$37*Assumptions!$C$24>C58 -> 0 | E47: =Assumptions!$C$37*Assumptions!$C$24>D58 -> 1 | F47: =Assumptions!$C$37*Assumptions!$C$24>E58 -> 1 | G47: =Assumptions!$C$37*Assumptions!$C$24>F58 -> 1 | H47: =Assumptions!$C$37*Assumptions!$C$24>G58 -> 1
B48: A_takes_pref | C48: FALSE | D48: =Assumptions!$C$36*Assumptions!$C$23>C59 -> 0 | E48: =Assumptions!$C$36*Assumptions!$C$23>D59 -> 0 | F48: =Assumptions!$C$36*Assumptions!$C$23>E59 -> 0 | G48: =Assumptions!$C$36*Assumptions!$C$23>F59 -> 0 | H48: =Assumptions!$C$36*Assumptions!$C$23>G59 -> 0
B49: Seed_takes_pref | C49: FALSE | D49: =Assumptions!$C$35*Assumptions!$C$22>C60 -> 0 | E49: =Assumptions!$C$35*Assumptions!$C$22>D60 -> 0 | F49: =Assumptions!$C$35*Assumptions!$C$22>E60 -> 0 | G49: =Assumptions!$C$35*Assumptions!$C$22>F60 -> 0 | H49: =Assumptions!$C$35*Assumptions!$C$22>G60 -> 0
B50: Sum prefs taken | C50: =IF(C43,Assumptions!$C$7,0)+IF(C44,Assumptions!$C$41*Assumptions!$C$28,0)+IF(C45,Assumptions!$C$40*Assumptions!$C$27,0)+IF(C46,Assumptions!$C$38*Assumptions!$C$25,0)+IF(C47,Assumptions!$C$37*Assumptions!$C$24,0)+IF(C48,Assumptions!$C$36*Assumptions!$C$23,0)+IF(C49,Assumptions!$C$35*Assumptions!$C$22,0) -> 0 | D50: =IF(D43,Assumptions!$C$7,0)+IF(D44,Assumptions!$C$41*Assumptions!$C$28,0)+IF(D45,Assumptions!$C$40*Assumptions!$C$27,0)+IF(D46,Assumptions!$C$38*Assumptions!$C$25,0)+IF(D47,Assumptions!$C$37*Assumptions!$C$24,0)+IF(D48,Assumptions!$C$36*Assumptions!$C$23,0)+IF(D49,Assumptions!$C$35*Assumptions!$C$22,0) -> 4.8999682e+08 | E50: =IF(E43,Assumptions!$C$7,0)+IF(E44,Assumptions!$C$41*Assumptions!$C$28,0)+IF(E45,Assumptions!$C$40*Assumptions!$C$27,0)+IF(E46,Assumptions!$C$38*Assumptions!$C$25,0)+IF(E47,Assumptions!$C$37*Assumptions!$C$24,0)+IF(E48,Assumptions!$C$36*Assumptions!$C$23,0)+IF(E49,Assumptions!$C$35*Assumptions!$C$22,0) -> 5.1999682e+08 | F50: =IF(F43,Assumptions!$C$7,0)+IF(F44,Assumptions!$C$41*Assumptions!$C$28,0)+IF(F45,Assumptions!$C$40*Assumptions!$C$27,0)+IF(F46,Assumptions!$C$38*Assumptions!$C$25,0)+IF(F47,Assumptions!$C$37*Assumptions!$C$24,0)+IF(F48,Assumptions!$C$36*Assumptions!$C$23,0)+IF(F49,Assumptions!$C$35*Assumptions!$C$22,0) -> 5.1999682e+08 | G50: =IF(G43,Assumptions!$C$7,0)+IF(G44,Assumptions!$C$41*Assumptions!$C$28,0)+IF(G45,Assumptions!$C$40*Assumptions!$C$27,0)+IF(G46,Assumptions!$C$38*Assumptions!$C$25,0)+IF(G47,Assumptions!$C$37*Assumptions!$C$24,0)+IF(G48,Assumptions!$C$36*Assumptions!$C$23,0)+IF(G49,Assumptions!$C$35*Assumptions!$C$22,0) -> 5.1999682e+08 | H50: =IF(H43,Assumptions!$C$7,0)+IF(H44,Assumptions!$C$41*Assumptions!$C$28,0)+IF(H45,Assumptions!$C$40*Assumptions!$C$27,0)+IF(H46,Assumptions!$C$38*Assumptions!$C$25,0)+IF(H47,Assumptions!$C$37*Assumptions!$C$24,0)+IF(H48,Assumptions!$C$36*Assumptions!$C$23,0)+IF(H49,Assumptions!$C$35*Assumptions!$C$22,0) -> 5.1999682e+08
B51: Convert pool (shares) | C51: =IF(C43,0,'Pro-Forma'!$C$29)+IF(C44,0,'Pro-Forma'!$G$45)+IF(C45,0,'Pro-Forma'!$G$44)+IF(C46,0,'Pro-Forma'!$G$43)+IF(C47,0,'Pro-Forma'!$G$42)+IF(C48,0,'Pro-Forma'!$G$41)+IF(C49,0,'Pro-Forma'!$G$40)+('Pro-Forma'!$D$62+'Pro-Forma'!$D$63+'Pro-Forma'!$D$64+'Pro-Forma'!$D$65+'Pro-Forma'!$D$74+'Pro-Forma'!$G$49+'Pro-Forma'!$G$50+'Pro-Forma'!$D$76) -> 35854102 | D51: =IF(D43,0,'Pro-Forma'!$C$29)+IF(D44,0,'Pro-Forma'!$G$45)+IF(D45,0,'Pro-Forma'!$G$44)+IF(D46,0,'Pro-Forma'!$G$43)+IF(D47,0,'Pro-Forma'!$G$42)+IF(D48,0,'Pro-Forma'!$G$41)+IF(D49,0,'Pro-Forma'!$G$40)+('Pro-Forma'!$D$62+'Pro-Forma'!$D$63+'Pro-Forma'!$D$64+'Pro-Forma'!$D$65+'Pro-Forma'!$D$74+'Pro-Forma'!$G$49+'Pro-Forma'!$G$50+'Pro-Forma'!$D$76) -> 24781358 | E51: =IF(E43,0,'Pro-Forma'!$C$29)+IF(E44,0,'Pro-Forma'!$G$45)+IF(E45,0,'Pro-Forma'!$G$44)+IF(E46,0,'Pro-Forma'!$G$43)+IF(E47,0,'Pro-Forma'!$G$42)+IF(E48,0,'Pro-Forma'!$G$41)+IF(E49,0,'Pro-Forma'!$G$40)+('Pro-Forma'!$D$62+'Pro-Forma'!$D$63+'Pro-Forma'!$D$64+'Pro-Forma'!$D$65+'Pro-Forma'!$D$74+'Pro-Forma'!$G$49+'Pro-Forma'!$G$50+'Pro-Forma'!$D$76) -> 21781358 | F51: =IF(F43,0,'Pro-Forma'!$C$29)+IF(F44,0,'Pro-Forma'!$G$45)+IF(F45,0,'Pro-Forma'!$G$44)+IF(F46,0,'Pro-Forma'!$G$43)+IF(F47,0,'Pro-Forma'!$G$42)+IF(F48,0,'Pro-Forma'!$G$41)+IF(F49,0,'Pro-Forma'!$G$40)+('Pro-Forma'!$D$62+'Pro-Forma'!$D$63+'Pro-Forma'!$D$64+'Pro-Forma'!$D$65+'Pro-Forma'!$D$74+'Pro-Forma'!$G$49+'Pro-Forma'!$G$50+'Pro-Forma'!$D$76) -> 21781358 | G51: =IF(G43,0,'Pro-Forma'!$C$29)+IF(G44,0,'Pro-Forma'!$G$45)+IF(G45,0,'Pro-Forma'!$G$44)+IF(G46,0,'Pro-Forma'!$G$43)+IF(G47,0,'Pro-Forma'!$G$42)+IF(G48,0,'Pro-Forma'!$G$41)+IF(G49,0,'Pro-Forma'!$G$40)+('Pro-Forma'!$D$62+'Pro-Forma'!$D$63+'Pro-Forma'!$D$64+'Pro-Forma'!$D$65+'Pro-Forma'!$D$74+'Pro-Forma'!$G$49+'Pro-Forma'!$G$50+'Pro-Forma'!$D$76) -> 21781358 | H51: =IF(H43,0,'Pro-Forma'!$C$29)+IF(H44,0,'Pro-Forma'!$G$45)+IF(H45,0,'Pro-Forma'!$G$44)+IF(H46,0,'Pro-Forma'!$G$43)+IF(H47,0,'Pro-Forma'!$G$42)+IF(H48,0,'Pro-Forma'!$G$41)+IF(H49,0,'Pro-Forma'!$G$40)+('Pro-Forma'!$D$62+'Pro-Forma'!$D$63+'Pro-Forma'!$D$64+'Pro-Forma'!$D$65+'Pro-Forma'!$D$74+'Pro-Forma'!$G$49+'Pro-Forma'!$G$50+'Pro-Forma'!$D$76) -> 21781358
B52: Residual ($) | C52: =C42-C50 -> 702500000 | D52: =D42-D50 -> 2.1250318e+08 | E52: =E42-E50 -> 1.8250318e+08 | F52: =F42-F50 -> 1.8250318e+08 | G52: =G42-G50 -> 1.8250318e+08 | H52: =H42-H50 -> 1.8250318e+08
...

Sheet Sensitivity
B2: Kelvin Dynamics — Sensitivity
B3: Our $10M check — ownership % and $ proceeds at $2,000M exit. Each cell re-solves the full round.
B5: Sensitivity — Our $10M Check at $2,000M Exit
B7: Our Ownership % (post-F)
B8: Pre-Money ↓ / ESOP → | C8: ESOP 11% | D8: ESOP 13% | E8: ESOP 15%
B9: $1,200M | C9: =(Assumptions!$C$11/M57)/M55 -> 0.0081300813 | D9: =(Assumptions!$C$11/M102)/M100 -> 0.0081300813 | E9: =(Assumptions!$C$11/M147)/M145 -> 0.0081300813
B10: $1,400M (base) | C10: =(Assumptions!$C$11/M192)/M190 -> 0.006993007 | D10: =(Assumptions!$C$11/M237)/M235 -> 0.006993007 | E10: =(Assumptions!$C$11/M282)/M280 -> 0.006993007
B11: $1,800M | C11: =(Assumptions!$C$11/M327)/M325 -> 0.0054644809 | D11: =(Assumptions!$C$11/M372)/M370 -> 0.0054644809 | E11: =(Assumptions!$C$11/M417)/M415 -> 0.0054644809
B13: Our $ Proceeds at $2B Exit
B14: Pre-Money ↓ / ESOP → | C14: ESOP 11% | D14: ESOP 13% | E14: ESOP 15%
B15: $1,200M | C15: =(Assumptions!$C$11/Assumptions!$C$7)*IF(H60,Assumptions!$C$7,M45*H70) -> 17107259 | D15: =(Assumptions!$C$11/Assumptions!$C$7)*IF(H105,Assumptions!$C$7,M90*H115) -> 17384971 | E15: =(Assumptions!$C$11/Assumptions!$C$7)*IF(H150,Assumptions!$C$7,M135*H160) -> 17795002
B16: $1,400M (base) | C16: =(Assumptions!$C$11/Assumptions!$C$7)*IF(H195,Assumptions!$C$7,M180*H205) -> 14719656 | D16: =(Assumptions!$C$11/Assumptions!$C$7)*IF(H240,Assumptions!$C$7,M225*H250) -> 14948858 | E16: =(Assumptions!$C$11/Assumptions!$C$7)*IF(H285,Assumptions!$C$7,M270*H295) -> 15301320
B17: $1,800M | C17: =(Assumptions!$C$11/Assumptions!$C$7)*IF(H330,Assumptions!$C$7,M315*H340) -> 11507141 | D17: =(Assumptions!$C$11/Assumptions!$C$7)*IF(H375,Assumptions!$C$7,M360*H385) -> 11676568 | E17: =(Assumptions!$C$11/Assumptions!$C$7)*IF(H420,Assumptions!$C$7,M405*H430) -> 11951762
B35: Solver: ESOP=11%, Pre=$1,200M
B36: pre_money ($) | C36: =Assumptions!$C$62 -> 1200000000
B37: esop_target | C37: =Assumptions!$C$59 -> 0.11
B38: Iteration | D38: Iter 0 | E38: Iter 1 | F38: Iter 2 | G38: Iter 3 | H38: Iter 4 | I38: Iter 5 | J38: Iter 6 | K38: Iter 7 | L38: Iter 8 | M38: Iter 9
B39: F_PPS (input) | D39: 45 | E39: =D57 -> 32.524044 | F39: =E57 -> 32.442402 | G39: =F57 -> 32.44131 | H39: =G57 -> 32.441295 | I39: =H57 -> 32.441295 | J39: =I57 -> 32.441295 | K39: =J57 -> 32.441295 | L39: =K57 -> 32.441295 | M39: =L57 -> 32.441295
B40: NCP_D | D40: =IF(D39<Assumptions!$C$26,Assumptions!$C$26*(Assumptions!$C$44+Assumptions!$C$7/Assumptions!$C$26)/(Assumptions!$C$44+Assumptions!$C$7/D39),Assumptions!$C$26) -> 57.883785 | E40: =IF(E39<Assumptions!$C$26,Assumptions!$C$26*(Assumptions!$C$44+Assumptions!$C$7/Assumptions!$C$26)/(Assumptions!$C$44+Assumptions!$C$7/E39),Assumptions!$C$26) -> 57.489476 | F40: =IF(F39<Assumptions!$C$26,Assumptions!$C$26*(Assumptions!$C$44+Assumptions!$C$7/Assumptions!$C$26)/(Assumptions!$C$44+Assumptions!$C$7/F39),Assumptions!$C$26) -> 57.485921 | G40: =IF(G39<Assumptions!$C$26,Assumptions!$C$26*(Assumptions!$C$44+Assumptions!$C$7/Assumptions!$C$26)/(Assumptions!$C$44+Assumptions!$C$7/G39),Assumptions!$C$26) -> 57.485874 | H40: =IF(H39<Assumptions!$C$26,Assumptions!$C$26*(Assumptions!$C$44+Assumptions!$C$7/Assumptions!$C$26)/(Assumptions!$C$44+Assumptions!$C$7/H39),Assumptions!$C$26) -> 57.485873 | I40: =IF(I39<Assumptions!$C$26,Assumptions!$C$26*(Assumptions!$C$44+Assumptions!$C$7/Assumptions!$C$26)/(Assumptions!$C$44+Assumptions!$C$7/I39),Assumptions!$C$26) -> 57.485873 | J40: =IF(J39<Assumptions!$C$26,Assumptions!$C$26*(Assumptions!$C$44+Assumptions!$C$7/Assumptions!$C$26)/(Assumptions!$C$44+Assumptions!$C$7/J39),Assumptions!$C$26) -> 57.485873 | K40: =IF(K39<Assumptions!$C$26,Assumptions!$C$26*(Assumptions!$C$44+Assumptions!$C$7/Assumptions!$C$26)/(Assumptions!$C$44+Assumptions!$C$7/K39),Assumptions!$C$26) -> 57.485873 | ... M40: =IF(M39<Assumptions!$C$26,Assumptions!$C$26*(Assumptions!$C$44+Assumptions!$C$7/Assumptions!$C$26)/(Assumptions!$C$44+Assumptions!$C$7/M39),Assumptions!$C$26) -> 57.485873
B41: Δ D shares | D41: =Assumptions!$C$40*Assumptions!$C$27/D40-Assumptions!$C$39 -> 6972.8859 | E41: =Assumptions!$C$40*Assumptions!$C$27/E40-Assumptions!$C$39 -> 18822.15 | F41: =Assumptions!$C$40*Assumptions!$C$27/F40-Assumptions!$C$39 -> 18929.706 | G41: =Assumptions!$C$40*Assumptions!$C$27/G40-Assumptions!$C$39 -> 18931.148 | H41: =Assumptions!$C$40*Assumptions!$C$27/H40-Assumptions!$C$39 -> 18931.167 | I41: =Assumptions!$C$40*Assumptions!$C$27/I40-Assumptions!$C$39 -> 18931.167 | J41: =Assumptions!$C$40*Assumptions!$C$27/J40-Assumptions!$C$39 -> 18931.167 | K41: =Assumptions!$C$40*Assumptions!$C$27/K40-Assumptions!$C$39 -> 18931.167 | ... M41: =Assumptions!$C$40*Assumptions!$C$27/M40-Assumptions!$C$39 -> 18931.167
B42: NCP_E | D42: =IF(D39<Assumptions!$C$28,Assumptions!$C$28*(Assumptions!$C$44+Assumptions!$C$7/Assumptions!$C$28)/(Assumptions!$C$44+Assumptions!$C$7/D39),Assumptions!$C$28) -> 49.083958 | E42: =IF(E39<Assumptions!$C$28,Assumptions!$C$28*(Assumptions!$C$44+Assumptions!$C$7/Assumptions!$C$28)/(Assumptions!$C$44+Assumptions!$C$7/E39),Assumptions!$C$28) -> 48.749595 | F42: =IF(F39<Assumptions!$C$28,Assumptions!$C$28*(Assumptions!$C$44+Assumptions!$C$7/Assumptions!$C$28)/(Assumptions!$C$44+Assumptions!$C$7/F39),Assumptions!$C$28) -> 48.746581 | G42: =IF(G39<Assumptions!$C$28,Assumptions!$C$28*(Assumptions!$C$44+Assumptions!$C$7/Assumptions!$C$28)/(Assumptions!$C$44+Assumptions!$C$7/G39),Assumptions!$C$28) -> 48.74654 | H42: =IF(H39<Assumptions!$C$28,Assumptions!$C$28*(Assumptions!$C$44+Assumptions!$C$7/Assumptions!$C$28)/(Assumptions!$C$44+Assumptions!$C$7/H39),Assumptions!$C$28) -> 48.74654 | I42: =IF(I39<Assumptions!$C$28,Assumptions!$C$28*(Assumptions!$C$44+Assumptions!$C$7/Assumptions!$C$28)/(Assumptions!$C$44+Assumptions!$C$7/I39),Assumptions!$C$28) -> 48.74654 | J42: =IF(J39<Assumptions!$C$28,Assumptions!$C$28*(Assumptions!$C$44+Assumptions!$C$7/Assumptions!$C$28)/(Assumptions!$C$44+Assumptions!$C$7/J39),Assumptions!$C$28) -> 48.74654 | K42: =IF(K39<Assumptions!$C$28,Assumptions!$C$28*(Assumptions!$C$44+Assumptions!$C$7/Assumptions!$C$28)/(Assumptions!$C$44+Assumptions!$C$7/K39),Assumptions!$C$28) -> 48.74654 | ... M42: =IF(M39<Assumptions!$C$28,Assumptions!$C$28*(Assumptions!$C$44+Assumptions!$C$7/Assumptions!$C$28)/(Assumptions!$C$44+Assumptions!$C$7/M39),Assumptions!$C$28) -> 48.74654
B43: Δ E shares | D43: =Assumptions!$C$41*Assumptions!$C$28/D42-Assumptions!$C$41 -> 9244.3417 | E43: =Assumptions!$C$41*Assumptions!$C$28/E42-Assumptions!$C$41 -> 51164.726 | F43: =Assumptions!$C$41*Assumptions!$C$28/F42-Assumptions!$C$41 -> 51545.238 | G43: =Assumptions!$C$41*Assumptions!$C$28/G42-Assumptions!$C$41 -> 51550.339 | H43: =Assumptions!$C$41*Assumptions!$C$28/H42-Assumptions!$C$41 -> 51550.408 | I43: =Assumptions!$C$41*Assumptions!$C$28/I42-Assumptions!$C$41 -> 51550.409 | J43: =Assumptions!$C$41*Assumptions!$C$28/J42-Assumptions!$C$41 -> 51550.409 | K43: =Assumptions!$C$41*Assumptions!$C$28/K42-Assumptions!$C$41 -> 51550.409 | ... M43: =Assumptions!$C$41*Assumptions!$C$28/M42-Assumptions!$C$41 -> 51550.409
B44: Base FD | D44: =Assumptions!$C$44+D41+D43 -> 36634178 | E44: =Assumptions!$C$44+E41+E43 -> 36687948 | F44: =Assumptions!$C$44+F41+F43 -> 36688436 | G44: =Assumptions!$C$44+G41+G43 -> 36688442 | H44: =Assumptions!$C$44+H41+H43 -> 36688443 | I44: =Assumptions!$C$44+I41+I43 -> 36688443 | J44: =Assumptions!$C$44+J41+J43 -> 36688443 | K44: =Assumptions!$C$44+K41+K43 -> 36688443 | ... M44: =Assumptions!$C$44+M41+M43 -> 36688443
B45: F_S | D45: =Assumptions!$C$7/D39 -> 666666.67 | E45: =Assumptions!$C$7/E39 -> 922394.51 | F45: =Assumptions!$C$7/F39 -> 924715.76 | G45: =Assumptions!$C$7/G39 -> 924746.88 | H45: =Assumptions!$C$7/H39 -> 924747.3 | I45: =Assumptions!$C$7/I39 -> 924747.3 | J45: =Assumptions!$C$7/J39 -> 924747.3 | K45: =Assumptions!$C$7/K39 -> 924747.3 | ... M45: =Assumptions!$C$7/M39 -> 924747.3
B46: Note A cap PPS | D46: =Assumptions!$C$48/(D44+0+0) -> 27.296914 | E46: =Assumptions!$C$48/(E44+D54+D53) -> 27.198762 | F46: =Assumptions!$C$48/(F44+E54+E53) -> 27.176163 | G46: =Assumptions!$C$48/(G44+F54+F53) -> 27.175957 | H46: =Assumptions!$C$48/(H44+G54+G53) -> 27.175954 | I46: =Assumptions!$C$48/(I44+H54+H53) -> 27.175954 | J46: =Assumptions!$C$48/(J44+I54+I53) -> 27.175954 | K46: =Assumptions!$C$48/(K44+J54+J53) -> 27.175954 | L46: =Assumptions!$C$48/(L44+K54+K53) -> 27.175954 | M46: =Assumptions!$C$48/(M44+L54+L53) -> 27.175954
B47: Note A disc PPS | D47: =D39*(1-Assumptions!$C$49) -> 36 | E47: =E39*(1-Assumptions!$C$49) -> 26.019235 | F47: =F39*(1-Assumptions!$C$49) -> 25.953921 | G47: =G39*(1-Assumptions!$C$49) -> 25.953048 | H47: =H39*(1-Assumptions!$C$49) -> 25.953036 | I47: =I39*(1-Assumptions!$C$49) -> 25.953036 | J47: =J39*(1-Assumptions!$C$49) -> 25.953036 | K47: =K39*(1-Assumptions!$C$49) -> 25.953036 | ... M47: =M39*(1-Assumptions!$C$49) -> 25.953036
B48: Note A conv PPS | D48: =MIN(D46,D47) -> 27.296914 | E48: =MIN(E46,E47) -> 26.019235 | F48: =MIN(F46,F47) -> 25.953921 | G48: =MIN(G46,G47) -> 25.953048 | H48: =MIN(H46,H47) -> 25.953036 | I48: =MIN(I46,I47) -> 25.953036 | J48: =MIN(J46,J47) -> 25.953036 | K48: =MIN(K46,K47) -> 25.953036 | ... M48: =MIN(M46,M47) -> 25.953036
B49: Note A shares | D49: =Assumptions!$C$47/D48 -> 183170.89 | E49: =Assumptions!$C$47/E48 -> 192165.52 | F49: =Assumptions!$C$47/F48 -> 192649.12 | G49: =Assumptions!$C$47/G48 -> 192655.6 | H49: =Assumptions!$C$47/H48 -> 192655.69 | I49: =Assumptions!$C$47/I48 -> 192655.69 | J49: =Assumptions!$C$47/J48 -> 192655.69 | K49: =Assumptions!$C$47/K48 -> 192655.69 | ... M49: =Assumptions!$C$47/M48 -> 192655.69
B50: Note B cap PPS | D50: =Assumptions!$C$51/(D44+0+0) -> 43.675062 | E50: =Assumptions!$C$51/(E44+D54+D49) -> 43.394398 | F50: =Assumptions!$C$51/(F44+E54+E49) -> 43.38324 | G50: =Assumptions!$C$51/(G44+F54+F49) -> 43.382664 | H50: =Assumptions!$C$51/(H44+G54+G49) -> 43.382656 | I50: =Assumptions!$C$51/(I44+H54+H49) -> 43.382656 | J50: =Assumptions!$C$51/(J44+I54+I49) -> 43.382656 | K50: =Assumptions!$C$51/(K44+J54+J49) -> 43.382656 | L50: =Assumptions!$C$51/(L44+K54+K49) -> 43.382656 | M50: =Assumptions!$C$51/(M44+L54+L49) -> 43.382656
B51: Note B disc PPS | D51: =D39*(1-Assumptions!$C$52) -> 38.25 | E51: =E39*(1-Assumptions!$C$52) -> 27.645438 | F51: =F39*(1-Assumptions!$C$52) -> 27.576041 | G51: =G39*(1-Assumptions!$C$52) -> 27.575113 | H51: =H39*(1-Assumptions!$C$52) -> 27.575101 | I51: =I39*(1-Assumptions!$C$52) -> 27.575101 | J51: =J39*(1-Assumptions!$C$52) -> 27.575101 | K51: =K39*(1-Assumptions!$C$52) -> 27.575101 | ... M51: =M39*(1-Assumptions!$C$52) -> 27.575101
B52: Note B conv PPS | D52: =MIN(D50,D51) -> 38.25 | E52: =MIN(E50,E51) -> 27.645438 | F52: =MIN(F50,F51) -> 27.576041 | G52: =MIN(G50,G51) -> 27.575113 | H52: =MIN(H50,H51) -> 27.575101 | I52: =MIN(I50,I51) -> 27.575101 | J52: =MIN(J50,J51) -> 27.575101 | K52: =MIN(K50,K51) -> 27.575101 | ... M52: =MIN(M50,M51) -> 27.575101
B53: Note B shares | D53: =Assumptions!$C$50/D52 -> 78431.373 | E53: =Assumptions!$C$50/E52 -> 108517 | F53: =Assumptions!$C$50/F52 -> 108790.09 | G53: =Assumptions!$C$50/G52 -> 108793.75 | H53: =Assumptions!$C$50/H52 -> 108793.8 | I53: =Assumptions!$C$50/I52 -> 108793.8 | J53: =Assumptions!$C$50/J52 -> 108793.8 | K53: =Assumptions!$C$50/K52 -> 108793.8 | ... M53: =Assumptions!$C$50/M52 -> 108793.8
B54: ESOP top-up | D54: =MAX(0,(Assumptions!$C$59*(D44+D49+D53+D45)-Assumptions!$C$56)/(1-Assumptions!$C$59)) -> 0 | E54: =MAX(0,(Assumptions!$C$59*(E44+E49+E53+E45)-Assumptions!$C$56)/(1-Assumptions!$C$59)) -> 0 | F54: =MAX(0,(Assumptions!$C$59*(F44+F49+F53+F45)-Assumptions!$C$56)/(1-Assumptions!$C$59)) -> 0 | G54: =MAX(0,(Assumptions!$C$59*(G44+G49+G53+G45)-Assumptions!$C$56)/(1-Assumptions!$C$59)) -> 0 | H54: =MAX(0,(Assumptions!$C$59*(H44+H49+H53+H45)-Assumptions!$C$56)/(1-Assumptions!$C$59)) -> 0 | I54: =MAX(0,(Assumptions!$C$59*(I44+I49+I53+I45)-Assumptions!$C$56)/(1-Assumptions!$C$59)) -> 0 | J54: =MAX(0,(Assumptions!$C$59*(J44+J49+J53+J45)-Assumptions!$C$56)/(1-Assumptions!$C$59)) -> 0 | K54: =MAX(0,(Assumptions!$C$59*(K44+K49+K53+K45)-Assumptions!$C$56)/(1-Assumptions!$C$59)) -> 0 | ... M54: =MAX(0,(Assumptions!$C$59*(M44+M49+M53+M45)-Assumptions!$C$56)/(1-Assumptions!$C$59)) -> 0
B55: T_F | D55: =D44+D54+D49+D53+D45 -> 37562447 | E55: =E44+E54+E49+E53+E45 -> 37911025 | F55: =F44+F54+F49+F53+F45 -> 37914591 | G55: =G44+G54+G49+G53+G45 -> 37914639 | H55: =H44+H54+H49+H53+H45 -> 37914639 | I55: =I44+I54+I49+I53+I45 -> 37914639 | J55: =J44+J54+J49+J53+J45 -> 37914639 | K55: =K44+K54+K49+K53+K45 -> 37914639 | ... M55: =M44+M54+M49+M53+M45 -> 37914639
B56: Pre-money FD | D56: =D55-D45 -> 36895780 | E56: =E55-E45 -> 36988630 | F56: =F55-F45 -> 36989875 | G56: =G55-G45 -> 36989892 | H56: =H55-H45 -> 36989892 | I56: =I55-I45 -> 36989892 | J56: =J55-J45 -> 36989892 | K56: =K55-K45 -> 36989892 | ... M56: =M55-M45 -> 36989892
B57: F_PPS_new | D57: =Assumptions!$C$62/D56 -> 32.524044 | E57: =Assumptions!$C$62/E56 -> 32.442402 | F57: =Assumptions!$C$62/F56 -> 32.44131 | G57: =Assumptions!$C$62/G56 -> 32.441295 | H57: =Assumptions!$C$62/H56 -> 32.441295 | I57: =Assumptions!$C$62/I56 -> 32.441295 | J57: =Assumptions!$C$62/J56 -> 32.441295 | K57: =Assumptions!$C$62/K56 -> 32.441295 | ... M57: =Assumptions!$C$62/M56 -> 32.441295
B59: Distributable_$2B | D59: =Assumptions!$C$17+Assumptions!$C$42*Assumptions!$C$55 -> 2002500000 | E59: =Assumptions!$C$17+Assumptions!$C$42*Assumptions!$C$55 -> 2002500000 | F59: =Assumptions!$C$17+Assumptions!$C$42*Assumptions!$C$55 -> 2002500000 | G59: =Assumptions!$C$17+Assumptions!$C$42*Assumptions!$C$55 -> 2002500000 | H59: =Assumptions!$C$17+Assumptions!$C$42*Assumptions!$C$55 -> 2002500000
B60: F pref? | D60: FALSE | E60: =Assumptions!$C$7>D71 -> 0 | F60: =Assumptions!$C$7>E71 -> 0 | G60: =Assumptions!$C$7>F71 -> 0 | H60: =Assumptions!$C$7>G71 -> 0
B61: E pref? | D61: FALSE | E61: =Assumptions!$C$41*Assumptions!$C$28>D72 -> 0 | F61: =Assumptions!$C$41*Assumptions!$C$28>E72 -> 0 | G61: =Assumptions!$C$41*Assumptions!$C$28>F72 -> 0 | H61: =Assumptions!$C$41*Assumptions!$C$28>G72 -> 0
B62: D pref? | D62: FALSE | E62: =Assumptions!$C$40*Assumptions!$C$27>D73 -> 1 | F62: =Assumptions!$C$40*Assumptions!$C$27>E73 -> 1 | G62: =Assumptions!$C$40*Assumptions!$C$27>F73 -> 1 | H62: =Assumptions!$C$40*Assumptions!$C$27>G73 -> 1
...

Sheet Return-Solver
B2: Kelvin Dynamics — Return Solver
B3: Required Series F ownership % to achieve 3x / 4x on our $10M check.
B5: Per-Exit Data (from Waterfall)
B6: Exit value ($) | C6: =Waterfall!C6 -> 700000000 | D6: =Waterfall!D6 -> 1200000000 | E6: =Waterfall!E6 -> 2000000000 | F6: =Waterfall!F6 -> 4000000000 | G6: =Waterfall!G6 -> 8000000000
B7: F class total proceeds ($) | C7: =Waterfall!C20 -> 30000000 | D7: =Waterfall!D20 -> 30000000 | E7: =Waterfall!E20 -> 44846573 | F7: =Waterfall!F20 -> 89785811 | G7: =Waterfall!G20 -> 1.7951554e+08
B8: F election | C8: =Waterfall!C11 -> preference | D8: =Waterfall!D11 -> preference | E8: =Waterfall!E11 -> convert | F8: =Waterfall!F11 -> convert | G8: =Waterfall!G11 -> convert
B9: $ per F share at exit | C9: =C7/'Pro-Forma'!$C$29 -> 37.29976 | D9: =D7/'Pro-Forma'!$C$29 -> 37.29976 | E9: =E7/'Pro-Forma'!$C$29 -> 55.758881 | F9: =F7/'Pro-Forma'!$C$29 -> 111.63297 | G9: =G7/'Pro-Forma'!$C$29 -> 223.19622
B10: $ per 1% of T_F (in F class) | C10: ='Pro-Forma'!$C$31*C9*0.01 -> 14300000 | D10: ='Pro-Forma'!$C$31*D9*0.01 -> 14300000 | E10: ='Pro-Forma'!$C$31*E9*0.01 -> 21376867 | F10: ='Pro-Forma'!$C$31*F9*0.01 -> 42797903 | G10: ='Pro-Forma'!$C$31*G9*0.01 -> 85569074
B12: Required Series F Ownership % (of post-F FD)
B13: Target 3x ($) | C13: =Assumptions!$C$67 -> 30000000 | D13: =Assumptions!$C$67 -> 30000000 | E13: =Assumptions!$C$67 -> 30000000 | F13: =Assumptions!$C$67 -> 30000000 | G13: =Assumptions!$C$67 -> 30000000
B14: Req. ownership % (3x) | C14: =Assumptions!$C$67*'Pro-Forma'!$C$29/('Pro-Forma'!$C$31*C7) -> 0.020979021 | D14: =Assumptions!$C$67*'Pro-Forma'!$C$29/('Pro-Forma'!$C$31*D7) -> 0.020979021 | E14: =Assumptions!$C$67*'Pro-Forma'!$C$29/('Pro-Forma'!$C$31*E7) -> 0.014033862 | F14: =Assumptions!$C$67*'Pro-Forma'!$C$29/('Pro-Forma'!$C$31*F7) -> 0.0070096892 | G14: =Assumptions!$C$67*'Pro-Forma'!$C$29/('Pro-Forma'!$C$31*G7) -> 0.0035059395
B15: Feasible? (3x) | C15: =IF(OR(C14<=0,C14>1),"INFEASIBLE","feasible") -> feasible | D15: =IF(OR(D14<=0,D14>1),"INFEASIBLE","feasible") -> feasible | E15: =IF(OR(E14<=0,E14>1),"INFEASIBLE","feasible") -> feasible | F15: =IF(OR(F14<=0,F14>1),"INFEASIBLE","feasible") -> feasible | G15: =IF(OR(G14<=0,G14>1),"INFEASIBLE","feasible") -> feasible
B16: Target 4x ($) | C16: =Assumptions!$C$68 -> 40000000 | D16: =Assumptions!$C$68 -> 40000000 | E16: =Assumptions!$C$68 -> 40000000 | F16: =Assumptions!$C$68 -> 40000000 | G16: =Assumptions!$C$68 -> 40000000
B17: Req. ownership % (4x) | C17: =Assumptions!$C$68*'Pro-Forma'!$C$29/('Pro-Forma'!$C$31*C7) -> 0.027972028 | D17: =Assumptions!$C$68*'Pro-Forma'!$C$29/('Pro-Forma'!$C$31*D7) -> 0.027972028 | E17: =Assumptions!$C$68*'Pro-Forma'!$C$29/('Pro-Forma'!$C$31*E7) -> 0.018711816 | F17: =Assumptions!$C$68*'Pro-Forma'!$C$29/('Pro-Forma'!$C$31*F7) -> 0.0093462523 | G17: =Assumptions!$C$68*'Pro-Forma'!$C$29/('Pro-Forma'!$C$31*G7) -> 0.004674586
B18: Feasible? (4x) | C18: =IF(OR(C17<=0,C17>1),"INFEASIBLE","feasible") -> feasible | D18: =IF(OR(D17<=0,D17>1),"INFEASIBLE","feasible") -> feasible | E18: =IF(OR(E17<=0,E17>1),"INFEASIBLE","feasible") -> feasible | F18: =IF(OR(F17<=0,F17>1),"INFEASIBLE","feasible") -> feasible | G18: =IF(OR(G17<=0,G17>1),"INFEASIBLE","feasible") -> feasible
B20: Reference
B21: T_F (post-F FD shares) | C21: ='Pro-Forma'!$C$31 -> 38338048
B22: F_S (Series F primary shares) | C22: ='Pro-Forma'!$C$29 -> 804294.71
B23: Our base ownership % of T_F | C23: =(Assumptions!$C$11/'Pro-Forma'!$C$28)/'Pro-Forma'!$C$31 -> 0.006993007
B24: Our base $ at $2B exit | C24: =C23*'Pro-Forma'!$C$31*E9 -> 14948858
