Workbook

Sheet Assumptions
B2: Kelvin Dynamics — Series F Assumptions
B3: $ in actual dollars; shares in actual count
B5: Round Terms
B6: Series F pre-money (USD) | C6: 1400000000
B7: Series F primary raise (USD) | C7: 30000000
B8: Series F secondary raise (USD) | C8: 15000000
B9: Tender PPS multiplier | C9: 0.85
B10: ESOP refresh target (% post-F FD) | C10: 0.13
B11: Our fund check (USD) | C11: 10000000
B12: F_LEAD primary check (USD) | C12: 20000000
B13: Option strike (USD) | C13: 1
B15: Pre-F Cap Table (shares)
B16: Founder F1 (CEO) common | C16: 4000000
B17: Founder F2 (CTO) common | C17: 2500000
B18: Founder F3 (Chief Sci) common | C18: 1500000
B19: Employee RSAs (10 holders) | C19: 1000000
B20: Seed preferred shares | C20: 5000000
B21: Series A preferred shares | C21: 5000000
B22: Series B preferred shares | C22: 3000000
B23: Series C preferred shares | C23: 2400000
B24: Series D preferred shares (post-AD v3) | C24: 1720627
B25: Series E preferred shares | C25: 6102667
B26: Pre-F options issued | C26: 2500000
B27: Pre-F options unissued | C27: 1894667
B28: Pre-F FD total | C28: =SUM(C16:C27) -> 36617961
B30: Original Conversion Prices (OCP)
B31: Seed OCP | C31: 1
B32: Series A OCP | C32: 3
B33: Series B OCP | C33: 10
B34: Series C OCP | C34: 25
B35: Series D OCP (post-E NCP, compound v3·v4) | C35: 58.118347
B36: Series E OCP | C36: 49.158311
B38: Liquidation Preferences (1x)
B39: Seed invested USD | C39: 5000000
B40: Series A invested USD | C40: 15000000
B41: Series B invested USD | C41: 30000000
B42: Series C invested USD | C42: 60000000
B43: Series D invested USD | C43: 100000000
B44: Series E invested USD | C44: 300000000
B45: Series F invested USD (= primary raise) | C45: =C7 -> 30000000
...

Sheet Pro-Forma
B2: Pro-Forma Series F Cap Table
B3: Solves F PPS, AD, notes, ESOP simultaneously via fixed-point iteration
B5: Solved Round Mechanics
B6: Series F PPS (USD) | C6: =Solver!R28 -> 37.299761
B7: AD-adjusted NCP, Series D | C7: =Solver!I28 -> 57.670905
B8: AD-adjusted NCP, Series E | C8: =Solver!J28 -> 48.903442
B9: AD trigger test (Seed) | C9: =IF(C6<Assumptions!C31,"trigger","dormant") -> dormant
B10: AD trigger test (Series A) | C10: =IF(C6<Assumptions!C32,"trigger","dormant") -> dormant
B11: AD trigger test (Series B) | C11: =IF(C6<Assumptions!C33,"trigger","dormant") -> dormant
B12: AD trigger test (Series C) | C12: =IF(C6<Assumptions!C34,"trigger","dormant") -> dormant
B13: AD trigger test (Series D) | C13: =IF(C6<Assumptions!C35,"trigger","dormant") -> trigger
B14: AD trigger test (Series E) | C14: =IF(C6<Assumptions!C36,"trigger","dormant") -> trigger
B15: AD ratio (Series D, new/old) | C15: =Assumptions!C35/Solver!I28 -> 1.0077585
B16: AD ratio (Series E, new/old) | C16: =Assumptions!C36/Solver!J28 -> 1.0052117
B17: AD extra shares — Series D | C17: =Solver!K28 -> 13349.544
B18: AD extra shares — Series E | C18: =Solver!L28 -> 31805.124
B19: ESOP top-up shares | C19: =Solver!O28 -> 589279.18
B20: Note A shares converted | C20: =Solver!M28 -> 186735.09
B21: Note B shares converted | C21: =Solver!N28 -> 94622.906
B22: F primary shares | C22: =Assumptions!C7/C6 -> 804294.7
B23: Tender shares (founders → F_LEAD) | C23: =Assumptions!C8/(Assumptions!C9*C6) -> 473114.53
B24: Pre-money FD (denominator for F_PPS) | C24: =Solver!P28 -> 37533753
B25: Total post-F FD (T_F) | C25: =Solver!Q28 -> 38338048
B27: Note Conversion Branches
B28: Note A: cap-implied PPS | C28: =Assumptions!C49/(Assumptions!C28+Solver!O28+Solver!K28+Solver!L28+Solver!N28) -> 26.7759
B29: Note A: discount-implied PPS | C29: =C6*(1-Assumptions!C50) -> 29.839809
B30: Note A: branch (cap | discount) | C30: =IF(C28<C29,"cap","discount") -> cap
B31: Note A: conversion PPS | C31: =MIN(C28,C29) -> 26.7759
B32: Note A: shares | C32: =Assumptions!C48/C31 -> 186735.09
B33: Note B: cap-implied PPS | C33: =Assumptions!C52/(Assumptions!C28+Solver!O28+Solver!K28+Solver!L28+Solver!M28) -> 42.736036
B34: Note B: discount-implied PPS | C34: =C6*(1-Assumptions!C53) -> 31.704797
B35: Note B: branch | C35: =IF(C33<C34,"cap","discount") -> discount
B36: Note B: conversion PPS | C36: =MIN(C33,C34) -> 31.704797
B37: Note B: shares | C37: =Assumptions!C51/C36 -> 94622.906
B39: Anti-Dilution Block (broad-based WA)
B40: Class | C40: OCP | D40: Trigger | E40: New CP | F40: Ratio (new/old)
B41: Seed | C41: =Assumptions!C31 -> 1 | D41: =IF(C6<Assumptions!C31,"trigger","dormant") -> dormant | E41: =IF(D41="dormant",C41,Assumptions!C31*(Assumptions!C28+Assumptions!C7/Assumptions!C31)/(Assumptions!C28+Assumptions!C7/C6)) -> 1 | F41: =C41/E41 -> 1
B42: Series A | C42: =Assumptions!C32 -> 3 | D42: =IF(C6<Assumptions!C32,"trigger","dormant") -> dormant | E42: =IF(D42="dormant",C42,Assumptions!C32*(Assumptions!C28+Assumptions!C7/Assumptions!C32)/(Assumptions!C28+Assumptions!C7/C6)) -> 3 | F42: =C42/E42 -> 1
B43: Series B | C43: =Assumptions!C33 -> 10 | D43: =IF(C6<Assumptions!C33,"trigger","dormant") -> dormant | E43: =IF(D43="dormant",C43,Assumptions!C33*(Assumptions!C28+Assumptions!C7/Assumptions!C33)/(Assumptions!C28+Assumptions!C7/C6)) -> 10 | F43: =C43/E43 -> 1
B44: Series C | C44: =Assumptions!C34 -> 25 | D44: =IF(C6<Assumptions!C34,"trigger","dormant") -> dormant | E44: =IF(D44="dormant",C44,Assumptions!C34*(Assumptions!C28+Assumptions!C7/Assumptions!C34)/(Assumptions!C28+Assumptions!C7/C6)) -> 25 | F44: =C44/E44 -> 1
...

Sheet Return-Solver
B2: Return-Solver — Required F Ownership for 3x and 4x
B3: Per exit, solve for company % needed by our $10M check to hit target multiples
B5: Reference Mechanics (base case)
B6: F PPS | C6: ='Pro-Forma'!C6 -> 37.299761
B7: Total post-F FD (T_F) | C7: ='Pro-Forma'!C25 -> 38338048
B8: F primary shares | C8: ='Pro-Forma'!C22 -> 804294.7
B9: F preference (1x) | C9: =Assumptions!C45 -> 30000000
B10: Our check | C10: =Assumptions!C11 -> 10000000
B12: Exit Scenarios
B13: Exit value | C13: ='Waterfall'!C24 -> 700000000 | D13: ='Waterfall'!D24 -> 1200000000 | E13: ='Waterfall'!E24 -> 2000000000 | F13: ='Waterfall'!F24 -> 4000000000 | G13: ='Waterfall'!G24 -> 8000000000
B14: F election | C14: =IF('Waterfall'!C59,"convert","preference") -> preference | D14: =IF('Waterfall'!D59,"convert","preference") -> preference | E14: =IF('Waterfall'!E59,"convert","preference") -> convert | F14: =IF('Waterfall'!F59,"convert","preference") -> convert | G14: =IF('Waterfall'!G59,"convert","preference") -> convert
B15: Common per-share value at exit | C15: ='Waterfall'!C85 -> 8.3787246 | D15: ='Waterfall'!D85 -> 28.420214 | E15: ='Waterfall'!E85 -> 55.758882 | F15: ='Waterfall'!F85 -> 111.63297 | G15: ='Waterfall'!G85 -> 223.19622
B16: Per-F-share proceeds (pref vs convert) | C16: =IF('Waterfall'!C59,C15,$C$6) -> 37.299761 | D16: =IF('Waterfall'!D59,D15,$C$6) -> 37.299761 | E16: =IF('Waterfall'!E59,E15,$C$6) -> 55.758882 | F16: =IF('Waterfall'!F59,F15,$C$6) -> 111.63297 | G16: =IF('Waterfall'!G59,G15,$C$6) -> 223.19622
B17: F class total proceeds | C17: =$C$8*C16 -> 30000000 | D17: =$C$8*D16 -> 30000000 | E17: =$C$8*E16 -> 44846573 | F17: =$C$8*F16 -> 89785811 | G17: =$C$8*G16 -> 1.7951554e+08
B19: Required Company Ownership % to hit target
B20: Target 3x ($30M) | C20: =IF(OR(($C$10*Assumptions!C73)>C17,(($C$10*Assumptions!C73)/($C$7*C16))>1),NA(),(($C$10*Assumptions!C73)/($C$7*C16))) -> 0.020979021 | D20: =IF(OR(($C$10*Assumptions!C73)>D17,(($C$10*Assumptions!C73)/($C$7*D16))>1),NA(),(($C$10*Assumptions!C73)/($C$7*D16))) -> 0.020979021 | E20: =IF(OR(($C$10*Assumptions!C73)>E17,(($C$10*Assumptions!C73)/($C$7*E16))>1),NA(),(($C$10*Assumptions!C73)/($C$7*E16))) -> 0.014033862 | F20: =IF(OR(($C$10*Assumptions!C73)>F17,(($C$10*Assumptions!C73)/($C$7*F16))>1),NA(),(($C$10*Assumptions!C73)/($C$7*F16))) -> 0.0070096892 | G20: =IF(OR(($C$10*Assumptions!C73)>G17,(($C$10*Assumptions!C73)/($C$7*G16))>1),NA(),(($C$10*Assumptions!C73)/($C$7*G16))) -> 0.0035059395
B21: Status (3x) | C21: =IF(OR(($C$10*Assumptions!C73)>C17,(($C$10*Assumptions!C73)/($C$7*C16))>1),"infeasible","feasible") -> feasible | D21: =IF(OR(($C$10*Assumptions!C73)>D17,(($C$10*Assumptions!C73)/($C$7*D16))>1),"infeasible","feasible") -> feasible | E21: =IF(OR(($C$10*Assumptions!C73)>E17,(($C$10*Assumptions!C73)/($C$7*E16))>1),"infeasible","feasible") -> feasible | F21: =IF(OR(($C$10*Assumptions!C73)>F17,(($C$10*Assumptions!C73)/($C$7*F16))>1),"infeasible","feasible") -> feasible | G21: =IF(OR(($C$10*Assumptions!C73)>G17,(($C$10*Assumptions!C73)/($C$7*G16))>1),"infeasible","feasible") -> feasible
B23: Target 4x ($40M) | C23: =IF(OR(($C$10*Assumptions!C74)>C17,(($C$10*Assumptions!C74)/($C$7*C16))>1),NA(),(($C$10*Assumptions!C74)/($C$7*C16))) -> #N/A | D23: =IF(OR(($C$10*Assumptions!C74)>D17,(($C$10*Assumptions!C74)/($C$7*D16))>1),NA(),(($C$10*Assumptions!C74)/($C$7*D16))) -> #N/A | E23: =IF(OR(($C$10*Assumptions!C74)>E17,(($C$10*Assumptions!C74)/($C$7*E16))>1),NA(),(($C$10*Assumptions!C74)/($C$7*E16))) -> 0.018711816 | F23: =IF(OR(($C$10*Assumptions!C74)>F17,(($C$10*Assumptions!C74)/($C$7*F16))>1),NA(),(($C$10*Assumptions!C74)/($C$7*F16))) -> 0.0093462523 | G23: =IF(OR(($C$10*Assumptions!C74)>G17,(($C$10*Assumptions!C74)/($C$7*G16))>1),NA(),(($C$10*Assumptions!C74)/($C$7*G16))) -> 0.0046745861
B24: Status (4x) | C24: =IF(OR(($C$10*Assumptions!C74)>C17,(($C$10*Assumptions!C74)/($C$7*C16))>1),"infeasible","feasible") -> infeasible | D24: =IF(OR(($C$10*Assumptions!C74)>D17,(($C$10*Assumptions!C74)/($C$7*D16))>1),"infeasible","feasible") -> infeasible | E24: =IF(OR(($C$10*Assumptions!C74)>E17,(($C$10*Assumptions!C74)/($C$7*E16))>1),"infeasible","feasible") -> feasible | F24: =IF(OR(($C$10*Assumptions!C74)>F17,(($C$10*Assumptions!C74)/($C$7*F16))>1),"infeasible","feasible") -> feasible | G24: =IF(OR(($C$10*Assumptions!C74)>G17,(($C$10*Assumptions!C74)/($C$7*G16))>1),"infeasible","feasible") -> feasible
B26: Implied Required $ Check
B27: Required check for 3x ($) | C27: =IF(($C$10*Assumptions!C73)>C17,NA(),($C$10*Assumptions!C73)*$C$6/C16) -> 30000000 | D27: =IF(($C$10*Assumptions!C73)>D17,NA(),($C$10*Assumptions!C73)*$C$6/D16) -> 30000000 | E27: =IF(($C$10*Assumptions!C73)>E17,NA(),($C$10*Assumptions!C73)*$C$6/E16) -> 20068423 | F27: =IF(($C$10*Assumptions!C73)>F17,NA(),($C$10*Assumptions!C73)*$C$6/F16) -> 10023856 | G27: =IF(($C$10*Assumptions!C73)>G17,NA(),($C$10*Assumptions!C73)*$C$6/G16) -> 5013493.5
B28: Required check for 4x ($) | C28: =IF(($C$10*Assumptions!C74)>C17,NA(),($C$10*Assumptions!C74)*$C$6/C16) -> #N/A | D28: =IF(($C$10*Assumptions!C74)>D17,NA(),($C$10*Assumptions!C74)*$C$6/D16) -> #N/A | E28: =IF(($C$10*Assumptions!C74)>E17,NA(),($C$10*Assumptions!C74)*$C$6/E16) -> 26757897 | F28: =IF(($C$10*Assumptions!C74)>F17,NA(),($C$10*Assumptions!C74)*$C$6/F16) -> 13365141 | G28: =IF(($C$10*Assumptions!C74)>G17,NA(),($C$10*Assumptions!C74)*$C$6/G16) -> 6684658.1
B30: Methodology: Required ownership % = target proceeds ÷ (T_F × per-F-share proceeds at exit).
B31: F-converts case: per-F-share = common per-share value (Waterfall row 85). F-prefers case: per-F-share = F PPS (1x preference).
B32: Infeasible if target exceeds F class total proceeds or required ownership > 100%.

Sheet Sens-Helper
B2: Sensitivity Helpers — 9 Scenario Solvers
B3: Each solver re-solves F PPS, AD, notes, ESOP for one (pre, esop) cell
B5: Scenario 1: ESOP=11%, Pre=$1.2B
B6: ESOP target | C6: =Assumptions!C65 -> 0.11 | D6: Pre-money | E6: =Assumptions!C68 -> 1200000000
C8: iter | D8: F_PPS | E8: NCP_D | F8: NCP_E | G8: AD_D | H8: AD_E | I8: n_A | J8: n_B | K8: ESOP_top | L8: FD_pre | M8: T_F | N8: F_PPS_new
C9: 0 | D9: =$E$6/Assumptions!C28 -> 32.770803 | E9: =IF(D9<Assumptions!C35,Assumptions!C35*(Assumptions!C28+Assumptions!C7/Assumptions!C35)/(Assumptions!C28+Assumptions!C7/D9),Assumptions!C35) -> 57.500114 | F9: =IF(D9<Assumptions!C36,Assumptions!C36*(Assumptions!C28+Assumptions!C7/Assumptions!C36)/(Assumptions!C28+Assumptions!C7/D9),Assumptions!C36) -> 48.758616 | G9: =Assumptions!C24*(Assumptions!C35/E9-1) -> 18499.928 | H9: =Assumptions!C25*(Assumptions!C36/F9-1) -> 50026.182 | I9: =Assumptions!C48/MIN((Assumptions!C49/(Assumptions!C28+0+G9+H9+0)),(D9*(1-Assumptions!C50))) -> 190718.55 | J9: =Assumptions!C51/MIN((Assumptions!C52/(Assumptions!C28+0+G9+H9+I9)),(D9*(1-Assumptions!C53))) -> 107699.89 | K9: =MAX(0,($C$6*(Assumptions!C28+G9+H9+I9+J9+Assumptions!C7/D9)-Assumptions!C55)/(1-$C$6)) -> 0 | L9: =Assumptions!C28+K9+G9+H9+I9+J9 -> 36984906 | M9: =L9+Assumptions!C7/D9 -> 37900355 | N9: =$E$6/L9 -> 32.445669
C10: 1 | D10: =N9 -> 32.445669 | E10: =IF(D10<Assumptions!C35,Assumptions!C35*(Assumptions!C28+Assumptions!C7/Assumptions!C35)/(Assumptions!C28+Assumptions!C7/D10),Assumptions!C35) -> 57.486064 | F10: =IF(D10<Assumptions!C36,Assumptions!C36*(Assumptions!C28+Assumptions!C7/Assumptions!C36)/(Assumptions!C28+Assumptions!C7/D10),Assumptions!C36) -> 48.746701 | G10: =Assumptions!C24*(Assumptions!C35/E10-1) -> 18924.992 | H10: =Assumptions!C25*(Assumptions!C36/F10-1) -> 51529.973 | I10: =Assumptions!C48/MIN((Assumptions!C49/(Assumptions!C28+K9+G10+H10+J9)),(D10*(1-Assumptions!C50))) -> 192629.72 | J10: =Assumptions!C51/MIN((Assumptions!C52/(Assumptions!C28+K9+G10+H10+I10)),(D10*(1-Assumptions!C53))) -> 108779.13 | K10: =MAX(0,($C$6*(Assumptions!C28+G10+H10+I10+J10+Assumptions!C7/D10)-Assumptions!C55)/(1-$C$6)) -> 0 | L10: =Assumptions!C28+K10+G10+H10+I10+J10 -> 36989825 | M10: =L10+Assumptions!C7/D10 -> 37914447 | N10: =$E$6/L10 -> 32.441354
C11: 2 | D11: =N10 -> 32.441354 | E11: =IF(D11<Assumptions!C35,Assumptions!C35*(Assumptions!C28+Assumptions!C7/Assumptions!C35)/(Assumptions!C28+Assumptions!C7/D11),Assumptions!C35) -> 57.485876 | F11: =IF(D11<Assumptions!C36,Assumptions!C36*(Assumptions!C28+Assumptions!C7/Assumptions!C36)/(Assumptions!C28+Assumptions!C7/D11),Assumptions!C36) -> 48.746542 | G11: =Assumptions!C24*(Assumptions!C35/E11-1) -> 18930.69 | H11: =Assumptions!C25*(Assumptions!C36/F11-1) -> 51550.133 | I11: =Assumptions!C48/MIN((Assumptions!C49/(Assumptions!C28+K10+G11+H11+J10)),(D11*(1-Assumptions!C50))) -> 192655.34 | J11: =Assumptions!C51/MIN((Assumptions!C52/(Assumptions!C28+K10+G11+H11+I11)),(D11*(1-Assumptions!C53))) -> 108793.6 | K11: =MAX(0,($C$6*(Assumptions!C28+G11+H11+I11+J11+Assumptions!C7/D11)-Assumptions!C55)/(1-$C$6)) -> 0 | L11: =Assumptions!C28+K11+G11+H11+I11+J11 -> 36989891 | M11: =L11+Assumptions!C7/D11 -> 37914636 | N11: =$E$6/L11 -> 32.441296
C12: 3 | D12: =N11 -> 32.441296 | E12: =IF(D12<Assumptions!C35,Assumptions!C35*(Assumptions!C28+Assumptions!C7/Assumptions!C35)/(Assumptions!C28+Assumptions!C7/D12),Assumptions!C35) -> 57.485873 | F12: =IF(D12<Assumptions!C36,Assumptions!C36*(Assumptions!C28+Assumptions!C7/Assumptions!C36)/(Assumptions!C28+Assumptions!C7/D12),Assumptions!C36) -> 48.74654 | G12: =Assumptions!C24*(Assumptions!C35/E12-1) -> 18930.767 | H12: =Assumptions!C25*(Assumptions!C36/F12-1) -> 51550.403 | I12: =Assumptions!C48/MIN((Assumptions!C49/(Assumptions!C28+K11+G12+H12+J11)),(D12*(1-Assumptions!C50))) -> 192655.68 | J12: =Assumptions!C51/MIN((Assumptions!C52/(Assumptions!C28+K11+G12+H12+I12)),(D12*(1-Assumptions!C53))) -> 108793.8 | K12: =MAX(0,($C$6*(Assumptions!C28+G12+H12+I12+J12+Assumptions!C7/D12)-Assumptions!C55)/(1-$C$6)) -> 0 | L12: =Assumptions!C28+K12+G12+H12+I12+J12 -> 36989892 | M12: =L12+Assumptions!C7/D12 -> 37914639 | N12: =$E$6/L12 -> 32.441295
C13: 4 | D13: =N12 -> 32.441295 | E13: =IF(D13<Assumptions!C35,Assumptions!C35*(Assumptions!C28+Assumptions!C7/Assumptions!C35)/(Assumptions!C28+Assumptions!C7/D13),Assumptions!C35) -> 57.485873 | F13: =IF(D13<Assumptions!C36,Assumptions!C36*(Assumptions!C28+Assumptions!C7/Assumptions!C36)/(Assumptions!C28+Assumptions!C7/D13),Assumptions!C36) -> 48.74654 | G13: =Assumptions!C24*(Assumptions!C35/E13-1) -> 18930.768 | H13: =Assumptions!C25*(Assumptions!C36/F13-1) -> 51550.407 | I13: =Assumptions!C48/MIN((Assumptions!C49/(Assumptions!C28+K12+G13+H13+J12)),(D13*(1-Assumptions!C50))) -> 192655.69 | J13: =Assumptions!C51/MIN((Assumptions!C52/(Assumptions!C28+K12+G13+H13+I13)),(D13*(1-Assumptions!C53))) -> 108793.8 | K13: =MAX(0,($C$6*(Assumptions!C28+G13+H13+I13+J13+Assumptions!C7/D13)-Assumptions!C55)/(1-$C$6)) -> 0 | L13: =Assumptions!C28+K13+G13+H13+I13+J13 -> 36989892 | M13: =L13+Assumptions!C7/D13 -> 37914639 | N13: =$E$6/L13 -> 32.441295
C14: 5 | D14: =N13 -> 32.441295 | E14: =IF(D14<Assumptions!C35,Assumptions!C35*(Assumptions!C28+Assumptions!C7/Assumptions!C35)/(Assumptions!C28+Assumptions!C7/D14),Assumptions!C35) -> 57.485873 | F14: =IF(D14<Assumptions!C36,Assumptions!C36*(Assumptions!C28+Assumptions!C7/Assumptions!C36)/(Assumptions!C28+Assumptions!C7/D14),Assumptions!C36) -> 48.74654 | G14: =Assumptions!C24*(Assumptions!C35/E14-1) -> 18930.768 | H14: =Assumptions!C25*(Assumptions!C36/F14-1) -> 51550.407 | I14: =Assumptions!C48/MIN((Assumptions!C49/(Assumptions!C28+K13+G14+H14+J13)),(D14*(1-Assumptions!C50))) -> 192655.69 | J14: =Assumptions!C51/MIN((Assumptions!C52/(Assumptions!C28+K13+G14+H14+I14)),(D14*(1-Assumptions!C53))) -> 108793.8 | K14: =MAX(0,($C$6*(Assumptions!C28+G14+H14+I14+J14+Assumptions!C7/D14)-Assumptions!C55)/(1-$C$6)) -> 0 | L14: =Assumptions!C28+K14+G14+H14+I14+J14 -> 36989892 | M14: =L14+Assumptions!C7/D14 -> 37914639 | N14: =$E$6/L14 -> 32.441295
C15: 6 | D15: =N14 -> 32.441295 | E15: =IF(D15<Assumptions!C35,Assumptions!C35*(Assumptions!C28+Assumptions!C7/Assumptions!C35)/(Assumptions!C28+Assumptions!C7/D15),Assumptions!C35) -> 57.485873 | F15: =IF(D15<Assumptions!C36,Assumptions!C36*(Assumptions!C28+Assumptions!C7/Assumptions!C36)/(Assumptions!C28+Assumptions!C7/D15),Assumptions!C36) -> 48.74654 | G15: =Assumptions!C24*(Assumptions!C35/E15-1) -> 18930.768 | H15: =Assumptions!C25*(Assumptions!C36/F15-1) -> 51550.407 | I15: =Assumptions!C48/MIN((Assumptions!C49/(Assumptions!C28+K14+G15+H15+J14)),(D15*(1-Assumptions!C50))) -> 192655.69 | J15: =Assumptions!C51/MIN((Assumptions!C52/(Assumptions!C28+K14+G15+H15+I15)),(D15*(1-Assumptions!C53))) -> 108793.8 | K15: =MAX(0,($C$6*(Assumptions!C28+G15+H15+I15+J15+Assumptions!C7/D15)-Assumptions!C55)/(1-$C$6)) -> 0 | L15: =Assumptions!C28+K15+G15+H15+I15+J15 -> 36989892 | M15: =L15+Assumptions!C7/D15 -> 37914639 | N15: =$E$6/L15 -> 32.441295
C16: 7 | D16: =N15 -> 32.441295 | E16: =IF(D16<Assumptions!C35,Assumptions!C35*(Assumptions!C28+Assumptions!C7/Assumptions!C35)/(Assumptions!C28+Assumptions!C7/D16),Assumptions!C35) -> 57.485873 | F16: =IF(D16<Assumptions!C36,Assumptions!C36*(Assumptions!C28+Assumptions!C7/Assumptions!C36)/(Assumptions!C28+Assumptions!C7/D16),Assumptions!C36) -> 48.74654 | G16: =Assumptions!C24*(Assumptions!C35/E16-1) -> 18930.768 | H16: =Assumptions!C25*(Assumptions!C36/F16-1) -> 51550.407 | I16: =Assumptions!C48/MIN((Assumptions!C49/(Assumptions!C28+K15+G16+H16+J15)),(D16*(1-Assumptions!C50))) -> 192655.69 | J16: =Assumptions!C51/MIN((Assumptions!C52/(Assumptions!C28+K15+G16+H16+I16)),(D16*(1-Assumptions!C53))) -> 108793.8 | K16: =MAX(0,($C$6*(Assumptions!C28+G16+H16+I16+J16+Assumptions!C7/D16)-Assumptions!C55)/(1-$C$6)) -> 0 | L16: =Assumptions!C28+K16+G16+H16+I16+J16 -> 36989892 | M16: =L16+Assumptions!C7/D16 -> 37914639 | N16: =$E$6/L16 -> 32.441295
C17: 8 | D17: =N16 -> 32.441295 | E17: =IF(D17<Assumptions!C35,Assumptions!C35*(Assumptions!C28+Assumptions!C7/Assumptions!C35)/(Assumptions!C28+Assumptions!C7/D17),Assumptions!C35) -> 57.485873 | F17: =IF(D17<Assumptions!C36,Assumptions!C36*(Assumptions!C28+Assumptions!C7/Assumptions!C36)/(Assumptions!C28+Assumptions!C7/D17),Assumptions!C36) -> 48.74654 | G17: =Assumptions!C24*(Assumptions!C35/E17-1) -> 18930.768 | H17: =Assumptions!C25*(Assumptions!C36/F17-1) -> 51550.407 | I17: =Assumptions!C48/MIN((Assumptions!C49/(Assumptions!C28+K16+G17+H17+J16)),(D17*(1-Assumptions!C50))) -> 192655.69 | J17: =Assumptions!C51/MIN((Assumptions!C52/(Assumptions!C28+K16+G17+H17+I17)),(D17*(1-Assumptions!C53))) -> 108793.8 | K17: =MAX(0,($C$6*(Assumptions!C28+G17+H17+I17+J17+Assumptions!C7/D17)-Assumptions!C55)/(1-$C$6)) -> 0 | L17: =Assumptions!C28+K17+G17+H17+I17+J17 -> 36989892 | M17: =L17+Assumptions!C7/D17 -> 37914639 | N17: =$E$6/L17 -> 32.441295
C18: 9 | D18: =N17 -> 32.441295 | E18: =IF(D18<Assumptions!C35,Assumptions!C35*(Assumptions!C28+Assumptions!C7/Assumptions!C35)/(Assumptions!C28+Assumptions!C7/D18),Assumptions!C35) -> 57.485873 | F18: =IF(D18<Assumptions!C36,Assumptions!C36*(Assumptions!C28+Assumptions!C7/Assumptions!C36)/(Assumptions!C28+Assumptions!C7/D18),Assumptions!C36) -> 48.74654 | G18: =Assumptions!C24*(Assumptions!C35/E18-1) -> 18930.768 | H18: =Assumptions!C25*(Assumptions!C36/F18-1) -> 51550.407 | I18: =Assumptions!C48/MIN((Assumptions!C49/(Assumptions!C28+K17+G18+H18+J17)),(D18*(1-Assumptions!C50))) -> 192655.69 | J18: =Assumptions!C51/MIN((Assumptions!C52/(Assumptions!C28+K17+G18+H18+I18)),(D18*(1-Assumptions!C53))) -> 108793.8 | K18: =MAX(0,($C$6*(Assumptions!C28+G18+H18+I18+J18+Assumptions!C7/D18)-Assumptions!C55)/(1-$C$6)) -> 0 | L18: =Assumptions!C28+K18+G18+H18+I18+J18 -> 36989892 | M18: =L18+Assumptions!C7/D18 -> 37914639 | N18: =$E$6/L18 -> 32.441295
C19: 10 | D19: =N18 -> 32.441295 | E19: =IF(D19<Assumptions!C35,Assumptions!C35*(Assumptions!C28+Assumptions!C7/Assumptions!C35)/(Assumptions!C28+Assumptions!C7/D19),Assumptions!C35) -> 57.485873 | F19: =IF(D19<Assumptions!C36,Assumptions!C36*(Assumptions!C28+Assumptions!C7/Assumptions!C36)/(Assumptions!C28+Assumptions!C7/D19),Assumptions!C36) -> 48.74654 | G19: =Assumptions!C24*(Assumptions!C35/E19-1) -> 18930.768 | H19: =Assumptions!C25*(Assumptions!C36/F19-1) -> 51550.407 | I19: =Assumptions!C48/MIN((Assumptions!C49/(Assumptions!C28+K18+G19+H19+J18)),(D19*(1-Assumptions!C50))) -> 192655.69 | J19: =Assumptions!C51/MIN((Assumptions!C52/(Assumptions!C28+K18+G19+H19+I19)),(D19*(1-Assumptions!C53))) -> 108793.8 | K19: =MAX(0,($C$6*(Assumptions!C28+G19+H19+I19+J19+Assumptions!C7/D19)-Assumptions!C55)/(1-$C$6)) -> 0 | L19: =Assumptions!C28+K19+G19+H19+I19+J19 -> 36989892 | M19: =L19+Assumptions!C7/D19 -> 37914639 | N19: =$E$6/L19 -> 32.441295
C20: 11 | D20: =N19 -> 32.441295 | E20: =IF(D20<Assumptions!C35,Assumptions!C35*(Assumptions!C28+Assumptions!C7/Assumptions!C35)/(Assumptions!C28+Assumptions!C7/D20),Assumptions!C35) -> 57.485873 | F20: =IF(D20<Assumptions!C36,Assumptions!C36*(Assumptions!C28+Assumptions!C7/Assumptions!C36)/(Assumptions!C28+Assumptions!C7/D20),Assumptions!C36) -> 48.74654 | G20: =Assumptions!C24*(Assumptions!C35/E20-1) -> 18930.768 | H20: =Assumptions!C25*(Assumptions!C36/F20-1) -> 51550.407 | I20: =Assumptions!C48/MIN((Assumptions!C49/(Assumptions!C28+K19+G20+H20+J19)),(D20*(1-Assumptions!C50))) -> 192655.69 | J20: =Assumptions!C51/MIN((Assumptions!C52/(Assumptions!C28+K19+G20+H20+I20)),(D20*(1-Assumptions!C53))) -> 108793.8 | K20: =MAX(0,($C$6*(Assumptions!C28+G20+H20+I20+J20+Assumptions!C7/D20)-Assumptions!C55)/(1-$C$6)) -> 0 | L20: =Assumptions!C28+K20+G20+H20+I20+J20 -> 36989892 | M20: =L20+Assumptions!C7/D20 -> 37914639 | N20: =$E$6/L20 -> 32.441295
C21: 12 | D21: =N20 -> 32.441295 | E21: =IF(D21<Assumptions!C35,Assumptions!C35*(Assumptions!C28+Assumptions!C7/Assumptions!C35)/(Assumptions!C28+Assumptions!C7/D21),Assumptions!C35) -> 57.485873 | F21: =IF(D21<Assumptions!C36,Assumptions!C36*(Assumptions!C28+Assumptions!C7/Assumptions!C36)/(Assumptions!C28+Assumptions!C7/D21),Assumptions!C36) -> 48.74654 | G21: =Assumptions!C24*(Assumptions!C35/E21-1) -> 18930.768 | H21: =Assumptions!C25*(Assumptions!C36/F21-1) -> 51550.407 | I21: =Assumptions!C48/MIN((Assumptions!C49/(Assumptions!C28+K20+G21+H21+J20)),(D21*(1-Assumptions!C50))) -> 192655.69 | J21: =Assumptions!C51/MIN((Assumptions!C52/(Assumptions!C28+K20+G21+H21+I21)),(D21*(1-Assumptions!C53))) -> 108793.8 | K21: =MAX(0,($C$6*(Assumptions!C28+G21+H21+I21+J21+Assumptions!C7/D21)-Assumptions!C55)/(1-$C$6)) -> 0 | L21: =Assumptions!C28+K21+G21+H21+I21+J21 -> 36989892 | M21: =L21+Assumptions!C7/D21 -> 37914639 | N21: =$E$6/L21 -> 32.441295
C22: 13 | D22: =N21 -> 32.441295 | E22: =IF(D22<Assumptions!C35,Assumptions!C35*(Assumptions!C28+Assumptions!C7/Assumptions!C35)/(Assumptions!C28+Assumptions!C7/D22),Assumptions!C35) -> 57.485873 | F22: =IF(D22<Assumptions!C36,Assumptions!C36*(Assumptions!C28+Assumptions!C7/Assumptions!C36)/(Assumptions!C28+Assumptions!C7/D22),Assumptions!C36) -> 48.74654 | G22: =Assumptions!C24*(Assumptions!C35/E22-1) -> 18930.768 | H22: =Assumptions!C25*(Assumptions!C36/F22-1) -> 51550.407 | I22: =Assumptions!C48/MIN((Assumptions!C49/(Assumptions!C28+K21+G22+H22+J21)),(D22*(1-Assumptions!C50))) -> 192655.69 | J22: =Assumptions!C51/MIN((Assumptions!C52/(Assumptions!C28+K21+G22+H22+I22)),(D22*(1-Assumptions!C53))) -> 108793.8 | K22: =MAX(0,($C$6*(Assumptions!C28+G22+H22+I22+J22+Assumptions!C7/D22)-Assumptions!C55)/(1-$C$6)) -> 0 | L22: =Assumptions!C28+K22+G22+H22+I22+J22 -> 36989892 | M22: =L22+Assumptions!C7/D22 -> 37914639 | N22: =$E$6/L22 -> 32.441295
C23: 14 | D23: =N22 -> 32.441295 | E23: =IF(D23<Assumptions!C35,Assumptions!C35*(Assumptions!C28+Assumptions!C7/Assumptions!C35)/(Assumptions!C28+Assumptions!C7/D23),Assumptions!C35) -> 57.485873 | F23: =IF(D23<Assumptions!C36,Assumptions!C36*(Assumptions!C28+Assumptions!C7/Assumptions!C36)/(Assumptions!C28+Assumptions!C7/D23),Assumptions!C36) -> 48.74654 | G23: =Assumptions!C24*(Assumptions!C35/E23-1) -> 18930.768 | H23: =Assumptions!C25*(Assumptions!C36/F23-1) -> 51550.407 | I23: =Assumptions!C48/MIN((Assumptions!C49/(Assumptions!C28+K22+G23+H23+J22)),(D23*(1-Assumptions!C50))) -> 192655.69 | J23: =Assumptions!C51/MIN((Assumptions!C52/(Assumptions!C28+K22+G23+H23+I23)),(D23*(1-Assumptions!C53))) -> 108793.8 | K23: =MAX(0,($C$6*(Assumptions!C28+G23+H23+I23+J23+Assumptions!C7/D23)-Assumptions!C55)/(1-$C$6)) -> 0 | L23: =Assumptions!C28+K23+G23+H23+I23+J23 -> 36989892 | M23: =L23+Assumptions!C7/D23 -> 37914639 | N23: =$E$6/L23 -> 32.441295
B24: F PPS | C24: =N23 -> 32.441295 | D24: T_F | E24: =M23 -> 37914639 | F24: Note A branch | G24: =IF((Assumptions!C49/(Assumptions!C28+K23+G23+H23+J23))<(N23*(1-Assumptions!C50)),"cap","discount") -> discount | H24: Note B branch | I24: =IF((Assumptions!C52/(Assumptions!C28+K23+G23+H23+I23))<(N23*(1-Assumptions!C53)),"cap","discount") -> discount
B25: Scenario 2: ESOP=11%, Pre=$1.4B
B26: ESOP target | C26: =Assumptions!C65 -> 0.11 | D26: Pre-money | E26: =Assumptions!C69 -> 1400000000
C28: iter | D28: F_PPS | E28: NCP_D | F28: NCP_E | G28: AD_D | H28: AD_E | I28: n_A | J28: n_B | K28: ESOP_top | L28: FD_pre | M28: T_F | N28: F_PPS_new
C29: 0 | D29: =$E$26/Assumptions!C28 -> 38.232604 | E29: =IF(D29<Assumptions!C35,Assumptions!C35*(Assumptions!C28+Assumptions!C7/Assumptions!C35)/(Assumptions!C28+Assumptions!C7/D29),Assumptions!C35) -> 57.701164 | F29: =IF(D29<Assumptions!C36,Assumptions!C36*(Assumptions!C28+Assumptions!C7/Assumptions!C36)/(Assumptions!C28+Assumptions!C7/D29),Assumptions!C36) -> 48.9291 | G29: =Assumptions!C24*(Assumptions!C35/E29-1) -> 12440.253 | H29: =Assumptions!C25*(Assumptions!C36/F29-1) -> 28588.226 | I29: =Assumptions!C48/MIN((Assumptions!C49/(Assumptions!C28+0+G29+H29+0)),(D29*(1-Assumptions!C50))) -> 183294.95 | J29: =Assumptions!C51/MIN((Assumptions!C52/(Assumptions!C28+0+G29+H29+I29)),(D29*(1-Assumptions!C53))) -> 92314.187 | K29: =MAX(0,($C$26*(Assumptions!C28+G29+H29+I29+J29+Assumptions!C7/D29)-Assumptions!C55)/(1-$C$26)) -> 0 | L29: =Assumptions!C28+K29+G29+H29+I29+J29 -> 36934599 | M29: =L29+Assumptions!C7/D29 -> 37719269 | N29: =$E$26/L29 -> 37.904839
C30: 1 | D30: =N29 -> 37.904839 | E30: =IF(D30<Assumptions!C35,Assumptions!C35*(Assumptions!C28+Assumptions!C7/Assumptions!C35)/(Assumptions!C28+Assumptions!C7/D30),Assumptions!C35) -> 57.690698 | F30: =IF(D30<Assumptions!C36,Assumptions!C36*(Assumptions!C28+Assumptions!C7/Assumptions!C36)/(Assumptions!C28+Assumptions!C7/D30),Assumptions!C36) -> 48.920226 | G30: =Assumptions!C24*(Assumptions!C35/E30-1) -> 12754.643 | H30: =Assumptions!C25*(Assumptions!C36/F30-1) -> 29700.478 | I30: =Assumptions!C48/MIN((Assumptions!C49/(Assumptions!C28+K29+G30+H30+J29)),(D30*(1-Assumptions!C50))) -> 183763.65 | J30: =Assumptions!C51/MIN((Assumptions!C52/(Assumptions!C28+K29+G30+H30+I30)),(D30*(1-Assumptions!C53))) -> 93112.433 | K30: =MAX(0,($C$26*(Assumptions!C28+G30+H30+I30+J30+Assumptions!C7/D30)-Assumptions!C55)/(1-$C$26)) -> 0 | L30: =Assumptions!C28+K30+G30+H30+I30+J30 -> 36937292 | M30: =L30+Assumptions!C7/D30 -> 37728748 | N30: =$E$26/L30 -> 37.902074
C31: 2 | D31: =N30 -> 37.902074 | E31: =IF(D31<Assumptions!C35,Assumptions!C35*(Assumptions!C28+Assumptions!C7/Assumptions!C35)/(Assumptions!C28+Assumptions!C7/D31),Assumptions!C35) -> 57.690609 | F31: =IF(D31<Assumptions!C36,Assumptions!C36*(Assumptions!C28+Assumptions!C7/Assumptions!C36)/(Assumptions!C28+Assumptions!C7/D31),Assumptions!C36) -> 48.92015 | G31: =Assumptions!C24*(Assumptions!C35/E31-1) -> 12757.317 | H31: =Assumptions!C25*(Assumptions!C36/F31-1) -> 29709.939 | I31: =Assumptions!C48/MIN((Assumptions!C49/(Assumptions!C28+K30+G31+H31+J30)),(D31*(1-Assumptions!C50))) -> 183767.7 | J31: =Assumptions!C51/MIN((Assumptions!C52/(Assumptions!C28+K30+G31+H31+I31)),(D31*(1-Assumptions!C53))) -> 93119.224 | K31: =MAX(0,($C$26*(Assumptions!C28+G31+H31+I31+J31+Assumptions!C7/D31)-Assumptions!C55)/(1-$C$26)) -> 0 | L31: =Assumptions!C28+K31+G31+H31+I31+J31 -> 36937315 | M31: =L31+Assumptions!C7/D31 -> 37728829 | N31: =$E$26/L31 -> 37.902051
C32: 3 | D32: =N31 -> 37.902051 | E32: =IF(D32<Assumptions!C35,Assumptions!C35*(Assumptions!C28+Assumptions!C7/Assumptions!C35)/(Assumptions!C28+Assumptions!C7/D32),Assumptions!C35) -> 57.690608 | F32: =IF(D32<Assumptions!C36,Assumptions!C36*(Assumptions!C28+Assumptions!C7/Assumptions!C36)/(Assumptions!C28+Assumptions!C7/D32),Assumptions!C36) -> 48.92015 | G32: =Assumptions!C24*(Assumptions!C35/E32-1) -> 12757.34 | H32: =Assumptions!C25*(Assumptions!C36/F32-1) -> 29710.02 | I32: =Assumptions!C48/MIN((Assumptions!C49/(Assumptions!C28+K31+G32+H32+J31)),(D32*(1-Assumptions!C50))) -> 183767.74 | J32: =Assumptions!C51/MIN((Assumptions!C52/(Assumptions!C28+K31+G32+H32+I32)),(D32*(1-Assumptions!C53))) -> 93119.282 | K32: =MAX(0,($C$26*(Assumptions!C28+G32+H32+I32+J32+Assumptions!C7/D32)-Assumptions!C55)/(1-$C$26)) -> 0 | L32: =Assumptions!C28+K32+G32+H32+I32+J32 -> 36937315 | M32: =L32+Assumptions!C7/D32 -> 37728829 | N32: =$E$26/L32 -> 37.902051
C33: 4 | D33: =N32 -> 37.902051 | E33: =IF(D33<Assumptions!C35,Assumptions!C35*(Assumptions!C28+Assumptions!C7/Assumptions!C35)/(Assumptions!C28+Assumptions!C7/D33),Assumptions!C35) -> 57.690608 | F33: =IF(D33<Assumptions!C36,Assumptions!C36*(Assumptions!C28+Assumptions!C7/Assumptions!C36)/(Assumptions!C28+Assumptions!C7/D33),Assumptions!C36) -> 48.92015 | G33: =Assumptions!C24*(Assumptions!C35/E33-1) -> 12757.34 | H33: =Assumptions!C25*(Assumptions!C36/F33-1) -> 29710.021 | I33: =Assumptions!C48/MIN((Assumptions!C49/(Assumptions!C28+K32+G33+H33+J32)),(D33*(1-Assumptions!C50))) -> 183767.74 | J33: =Assumptions!C51/MIN((Assumptions!C52/(Assumptions!C28+K32+G33+H33+I33)),(D33*(1-Assumptions!C53))) -> 93119.282 | K33: =MAX(0,($C$26*(Assumptions!C28+G33+H33+I33+J33+Assumptions!C7/D33)-Assumptions!C55)/(1-$C$26)) -> 0 | L33: =Assumptions!C28+K33+G33+H33+I33+J33 -> 36937315 | M33: =L33+Assumptions!C7/D33 -> 37728829 | N33: =$E$26/L33 -> 37.902051
C34: 5 | D34: =N33 -> 37.902051 | E34: =IF(D34<Assumptions!C35,Assumptions!C35*(Assumptions!C28+Assumptions!C7/Assumptions!C35)/(Assumptions!C28+Assumptions!C7/D34),Assumptions!C35) -> 57.690608 | F34: =IF(D34<Assumptions!C36,Assumptions!C36*(Assumptions!C28+Assumptions!C7/Assumptions!C36)/(Assumptions!C28+Assumptions!C7/D34),Assumptions!C36) -> 48.92015 | G34: =Assumptions!C24*(Assumptions!C35/E34-1) -> 12757.34 | H34: =Assumptions!C25*(Assumptions!C36/F34-1) -> 29710.021 | I34: =Assumptions!C48/MIN((Assumptions!C49/(Assumptions!C28+K33+G34+H34+J33)),(D34*(1-Assumptions!C50))) -> 183767.74 | J34: =Assumptions!C51/MIN((Assumptions!C52/(Assumptions!C28+K33+G34+H34+I34)),(D34*(1-Assumptions!C53))) -> 93119.282 | K34: =MAX(0,($C$26*(Assumptions!C28+G34+H34+I34+J34+Assumptions!C7/D34)-Assumptions!C55)/(1-$C$26)) -> 0 | L34: =Assumptions!C28+K34+G34+H34+I34+J34 -> 36937315 | M34: =L34+Assumptions!C7/D34 -> 37728829 | N34: =$E$26/L34 -> 37.902051
C35: 6 | D35: =N34 -> 37.902051 | E35: =IF(D35<Assumptions!C35,Assumptions!C35*(Assumptions!C28+Assumptions!C7/Assumptions!C35)/(Assumptions!C28+Assumptions!C7/D35),Assumptions!C35) -> 57.690608 | F35: =IF(D35<Assumptions!C36,Assumptions!C36*(Assumptions!C28+Assumptions!C7/Assumptions!C36)/(Assumptions!C28+Assumptions!C7/D35),Assumptions!C36) -> 48.92015 | G35: =Assumptions!C24*(Assumptions!C35/E35-1) -> 12757.34 | H35: =Assumptions!C25*(Assumptions!C36/F35-1) -> 29710.021 | I35: =Assumptions!C48/MIN((Assumptions!C49/(Assumptions!C28+K34+G35+H35+J34)),(D35*(1-Assumptions!C50))) -> 183767.74 | J35: =Assumptions!C51/MIN((Assumptions!C52/(Assumptions!C28+K34+G35+H35+I35)),(D35*(1-Assumptions!C53))) -> 93119.282 | K35: =MAX(0,($C$26*(Assumptions!C28+G35+H35+I35+J35+Assumptions!C7/D35)-Assumptions!C55)/(1-$C$26)) -> 0 | L35: =Assumptions!C28+K35+G35+H35+I35+J35 -> 36937315 | M35: =L35+Assumptions!C7/D35 -> 37728829 | N35: =$E$26/L35 -> 37.902051
C36: 7 | D36: =N35 -> 37.902051 | E36: =IF(D36<Assumptions!C35,Assumptions!C35*(Assumptions!C28+Assumptions!C7/Assumptions!C35)/(Assumptions!C28+Assumptions!C7/D36),Assumptions!C35) -> 57.690608 | F36: =IF(D36<Assumptions!C36,Assumptions!C36*(Assumptions!C28+Assumptions!C7/Assumptions!C36)/(Assumptions!C28+Assumptions!C7/D36),Assumptions!C36) -> 48.92015 | G36: =Assumptions!C24*(Assumptions!C35/E36-1) -> 12757.34 | H36: =Assumptions!C25*(Assumptions!C36/F36-1) -> 29710.021 | I36: =Assumptions!C48/MIN((Assumptions!C49/(Assumptions!C28+K35+G36+H36+J35)),(D36*(1-Assumptions!C50))) -> 183767.74 | J36: =Assumptions!C51/MIN((Assumptions!C52/(Assumptions!C28+K35+G36+H36+I36)),(D36*(1-Assumptions!C53))) -> 93119.282 | K36: =MAX(0,($C$26*(Assumptions!C28+G36+H36+I36+J36+Assumptions!C7/D36)-Assumptions!C55)/(1-$C$26)) -> 0 | L36: =Assumptions!C28+K36+G36+H36+I36+J36 -> 36937315 | M36: =L36+Assumptions!C7/D36 -> 37728829 | N36: =$E$26/L36 -> 37.902051
C37: 8 | D37: =N36 -> 37.902051 | E37: =IF(D37<Assumptions!C35,Assumptions!C35*(Assumptions!C28+Assumptions!C7/Assumptions!C35)/(Assumptions!C28+Assumptions!C7/D37),Assumptions!C35) -> 57.690608 | F37: =IF(D37<Assumptions!C36,Assumptions!C36*(Assumptions!C28+Assumptions!C7/Assumptions!C36)/(Assumptions!C28+Assumptions!C7/D37),Assumptions!C36) -> 48.92015 | G37: =Assumptions!C24*(Assumptions!C35/E37-1) -> 12757.34 | H37: =Assumptions!C25*(Assumptions!C36/F37-1) -> 29710.021 | I37: =Assumptions!C48/MIN((Assumptions!C49/(Assumptions!C28+K36+G37+H37+J36)),(D37*(1-Assumptions!C50))) -> 183767.74 | J37: =Assumptions!C51/MIN((Assumptions!C52/(Assumptions!C28+K36+G37+H37+I37)),(D37*(1-Assumptions!C53))) -> 93119.282 | K37: =MAX(0,($C$26*(Assumptions!C28+G37+H37+I37+J37+Assumptions!C7/D37)-Assumptions!C55)/(1-$C$26)) -> 0 | L37: =Assumptions!C28+K37+G37+H37+I37+J37 -> 36937315 | M37: =L37+Assumptions!C7/D37 -> 37728829 | N37: =$E$26/L37 -> 37.902051
C38: 9 | D38: =N37 -> 37.902051 | E38: =IF(D38<Assumptions!C35,Assumptions!C35*(Assumptions!C28+Assumptions!C7/Assumptions!C35)/(Assumptions!C28+Assumptions!C7/D38),Assumptions!C35) -> 57.690608 | F38: =IF(D38<Assumptions!C36,Assumptions!C36*(Assumptions!C28+Assumptions!C7/Assumptions!C36)/(Assumptions!C28+Assumptions!C7/D38),Assumptions!C36) -> 48.92015 | G38: =Assumptions!C24*(Assumptions!C35/E38-1) -> 12757.34 | H38: =Assumptions!C25*(Assumptions!C36/F38-1) -> 29710.021 | I38: =Assumptions!C48/MIN((Assumptions!C49/(Assumptions!C28+K37+G38+H38+J37)),(D38*(1-Assumptions!C50))) -> 183767.74 | J38: =Assumptions!C51/MIN((Assumptions!C52/(Assumptions!C28+K37+G38+H38+I38)),(D38*(1-Assumptions!C53))) -> 93119.282 | K38: =MAX(0,($C$26*(Assumptions!C28+G38+H38+I38+J38+Assumptions!C7/D38)-Assumptions!C55)/(1-$C$26)) -> 0 | L38: =Assumptions!C28+K38+G38+H38+I38+J38 -> 36937315 | M38: =L38+Assumptions!C7/D38 -> 37728829 | N38: =$E$26/L38 -> 37.902051
C39: 10 | D39: =N38 -> 37.902051 | E39: =IF(D39<Assumptions!C35,Assumptions!C35*(Assumptions!C28+Assumptions!C7/Assumptions!C35)/(Assumptions!C28+Assumptions!C7/D39),Assumptions!C35) -> 57.690608 | F39: =IF(D39<Assumptions!C36,Assumptions!C36*(Assumptions!C28+Assumptions!C7/Assumptions!C36)/(Assumptions!C28+Assumptions!C7/D39),Assumptions!C36) -> 48.92015 | G39: =Assumptions!C24*(Assumptions!C35/E39-1) -> 12757.34 | H39: =Assumptions!C25*(Assumptions!C36/F39-1) -> 29710.021 | I39: =Assumptions!C48/MIN((Assumptions!C49/(Assumptions!C28+K38+G39+H39+J38)),(D39*(1-Assumptions!C50))) -> 183767.74 | J39: =Assumptions!C51/MIN((Assumptions!C52/(Assumptions!C28+K38+G39+H39+I39)),(D39*(1-Assumptions!C53))) -> 93119.282 | K39: =MAX(0,($C$26*(Assumptions!C28+G39+H39+I39+J39+Assumptions!C7/D39)-Assumptions!C55)/(1-$C$26)) -> 0 | L39: =Assumptions!C28+K39+G39+H39+I39+J39 -> 36937315 | M39: =L39+Assumptions!C7/D39 -> 37728829 | N39: =$E$26/L39 -> 37.902051
C40: 11 | D40: =N39 -> 37.902051 | E40: =IF(D40<Assumptions!C35,Assumptions!C35*(Assumptions!C28+Assumptions!C7/Assumptions!C35)/(Assumptions!C28+Assumptions!C7/D40),Assumptions!C35) -> 57.690608 | F40: =IF(D40<Assumptions!C36,Assumptions!C36*(Assumptions!C28+Assumptions!C7/Assumptions!C36)/(Assumptions!C28+Assumptions!C7/D40),Assumptions!C36) -> 48.92015 | G40: =Assumptions!C24*(Assumptions!C35/E40-1) -> 12757.34 | H40: =Assumptions!C25*(Assumptions!C36/F40-1) -> 29710.021 | I40: =Assumptions!C48/MIN((Assumptions!C49/(Assumptions!C28+K39+G40+H40+J39)),(D40*(1-Assumptions!C50))) -> 183767.74 | J40: =Assumptions!C51/MIN((Assumptions!C52/(Assumptions!C28+K39+G40+H40+I40)),(D40*(1-Assumptions!C53))) -> 93119.282 | K40: =MAX(0,($C$26*(Assumptions!C28+G40+H40+I40+J40+Assumptions!C7/D40)-Assumptions!C55)/(1-$C$26)) -> 0 | L40: =Assumptions!C28+K40+G40+H40+I40+J40 -> 36937315 | M40: =L40+Assumptions!C7/D40 -> 37728829 | N40: =$E$26/L40 -> 37.902051
C41: 12 | D41: =N40 -> 37.902051 | E41: =IF(D41<Assumptions!C35,Assumptions!C35*(Assumptions!C28+Assumptions!C7/Assumptions!C35)/(Assumptions!C28+Assumptions!C7/D41),Assumptions!C35) -> 57.690608 | F41: =IF(D41<Assumptions!C36,Assumptions!C36*(Assumptions!C28+Assumptions!C7/Assumptions!C36)/(Assumptions!C28+Assumptions!C7/D41),Assumptions!C36) -> 48.92015 | G41: =Assumptions!C24*(Assumptions!C35/E41-1) -> 12757.34 | H41: =Assumptions!C25*(Assumptions!C36/F41-1) -> 29710.021 | I41: =Assumptions!C48/MIN((Assumptions!C49/(Assumptions!C28+K40+G41+H41+J40)),(D41*(1-Assumptions!C50))) -> 183767.74 | J41: =Assumptions!C51/MIN((Assumptions!C52/(Assumptions!C28+K40+G41+H41+I41)),(D41*(1-Assumptions!C53))) -> 93119.282 | K41: =MAX(0,($C$26*(Assumptions!C28+G41+H41+I41+J41+Assumptions!C7/D41)-Assumptions!C55)/(1-$C$26)) -> 0 | L41: =Assumptions!C28+K41+G41+H41+I41+J41 -> 36937315 | M41: =L41+Assumptions!C7/D41 -> 37728829 | N41: =$E$26/L41 -> 37.902051
C42: 13 | D42: =N41 -> 37.902051 | E42: =IF(D42<Assumptions!C35,Assumptions!C35*(Assumptions!C28+Assumptions!C7/Assumptions!C35)/(Assumptions!C28+Assumptions!C7/D42),Assumptions!C35) -> 57.690608 | F42: =IF(D42<Assumptions!C36,Assumptions!C36*(Assumptions!C28+Assumptions!C7/Assumptions!C36)/(Assumptions!C28+Assumptions!C7/D42),Assumptions!C36) -> 48.92015 | G42: =Assumptions!C24*(Assumptions!C35/E42-1) -> 12757.34 | H42: =Assumptions!C25*(Assumptions!C36/F42-1) -> 29710.021 | I42: =Assumptions!C48/MIN((Assumptions!C49/(Assumptions!C28+K41+G42+H42+J41)),(D42*(1-Assumptions!C50))) -> 183767.74 | J42: =Assumptions!C51/MIN((Assumptions!C52/(Assumptions!C28+K41+G42+H42+I42)),(D42*(1-Assumptions!C53))) -> 93119.282 | K42: =MAX(0,($C$26*(Assumptions!C28+G42+H42+I42+J42+Assumptions!C7/D42)-Assumptions!C55)/(1-$C$26)) -> 0 | L42: =Assumptions!C28+K42+G42+H42+I42+J42 -> 36937315 | M42: =L42+Assumptions!C7/D42 -> 37728829 | N42: =$E$26/L42 -> 37.902051
C43: 14 | D43: =N42 -> 37.902051 | E43: =IF(D43<Assumptions!C35,Assumptions!C35*(Assumptions!C28+Assumptions!C7/Assumptions!C35)/(Assumptions!C28+Assumptions!C7/D43),Assumptions!C35) -> 57.690608 | F43: =IF(D43<Assumptions!C36,Assumptions!C36*(Assumptions!C28+Assumptions!C7/Assumptions!C36)/(Assumptions!C28+Assumptions!C7/D43),Assumptions!C36) -> 48.92015 | G43: =Assumptions!C24*(Assumptions!C35/E43-1) -> 12757.34 | H43: =Assumptions!C25*(Assumptions!C36/F43-1) -> 29710.021 | I43: =Assumptions!C48/MIN((Assumptions!C49/(Assumptions!C28+K42+G43+H43+J42)),(D43*(1-Assumptions!C50))) -> 183767.74 | J43: =Assumptions!C51/MIN((Assumptions!C52/(Assumptions!C28+K42+G43+H43+I43)),(D43*(1-Assumptions!C53))) -> 93119.282 | K43: =MAX(0,($C$26*(Assumptions!C28+G43+H43+I43+J43+Assumptions!C7/D43)-Assumptions!C55)/(1-$C$26)) -> 0 | L43: =Assumptions!C28+K43+G43+H43+I43+J43 -> 36937315 | M43: =L43+Assumptions!C7/D43 -> 37728829 | N43: =$E$26/L43 -> 37.902051
B44: F PPS | C44: =N43 -> 37.902051 | D44: T_F | E44: =M43 -> 37728829 | F44: Note A branch | G44: =IF((Assumptions!C49/(Assumptions!C28+K43+G43+H43+J43))<(N43*(1-Assumptions!C50)),"cap","discount") -> cap | H44: Note B branch | I44: =IF((Assumptions!C52/(Assumptions!C28+K43+G43+H43+I43))<(N43*(1-Assumptions!C53)),"cap","discount") -> discount
...

Sheet Sensitivity
B2: Sensitivity — $10M Check at $2B Exit
B3: 3x3 grid: ESOP refresh × Series F pre-money | per-cell full re-solve
B5: Reference: Exit value | C5: =Assumptions!C60 -> 2000000000
B6: Reference: Our check | C6: =Assumptions!C11 -> 10000000
B9: Our $10M Post-F Ownership %
C11: Pre-money → | D11: =Assumptions!C68 -> 1200000000 | E11: =Assumptions!C69 -> 1400000000 | F11: =Assumptions!C70 -> 1800000000
B12: ESOP ↓
B13: =Assumptions!C65 -> 0.11 | D13: =(Assumptions!C11/'Sens-Helper'!N23)/'Sens-Helper'!M23 -> 0.0081300813 | E13: =(Assumptions!C11/'Sens-Helper'!N43)/'Sens-Helper'!M43 -> 0.006993007 | F13: =(Assumptions!C11/'Sens-Helper'!N63)/'Sens-Helper'!M63 -> 0.0054644809
B14: =Assumptions!C66 -> 0.13 | D14: =(Assumptions!C11/'Sens-Helper'!N83)/'Sens-Helper'!M83 -> 0.0081300813 | E14: =(Assumptions!C11/'Sens-Helper'!N103)/'Sens-Helper'!M103 -> 0.006993007 | F14: =(Assumptions!C11/'Sens-Helper'!N123)/'Sens-Helper'!M123 -> 0.0054644809
B15: =Assumptions!C67 -> 0.15 | D15: =(Assumptions!C11/'Sens-Helper'!N143)/'Sens-Helper'!M143 -> 0.0081300813 | E15: =(Assumptions!C11/'Sens-Helper'!N163)/'Sens-Helper'!M163 -> 0.006993007 | F15: =(Assumptions!C11/'Sens-Helper'!N183)/'Sens-Helper'!M183 -> 0.0054644809
B18: Our $10M Proceeds at $2B Exit ($M)
C20: Pre-money → | D20: =Assumptions!C68 -> 1200000000 | E20: =Assumptions!C69 -> 1400000000 | F20: =Assumptions!C70 -> 1800000000
B21: ESOP ↓
B22: =Assumptions!C65 -> 0.11 | D22: =(Assumptions!C11/'Sens-Helper'!N23)*IF(((Assumptions!C60-Assumptions!C43)/(((Assumptions!C16+Assumptions!C17+Assumptions!C18+Assumptions!C19)+'Sens-Helper'!I23+'Sens-Helper'!J23)+((Assumptions!C7/'Sens-Helper'!N23)+(Assumptions!C25+'Sens-Helper'!H23)+Assumptions!C23+Assumptions!C22+Assumptions!C21+Assumptions!C20)))>Assumptions!C13,((Assumptions!C60-Assumptions!C43)+Assumptions!C26*Assumptions!C13)/((((Assumptions!C16+Assumptions!C17+Assumptions!C18+Assumptions!C19)+'Sens-Helper'!I23+'Sens-Helper'!J23)+((Assumptions!C7/'Sens-Helper'!N23)+(Assumptions!C25+'Sens-Helper'!H23)+Assumptions!C23+Assumptions!C22+Assumptions!C21+Assumptions!C20))+Assumptions!C26),((Assumptions!C60-Assumptions!C43)/(((Assumptions!C16+Assumptions!C17+Assumptions!C18+Assumptions!C19)+'Sens-Helper'!I23+'Sens-Helper'!J23)+((Assumptions!C7/'Sens-Helper'!N23)+(Assumptions!C25+'Sens-Helper'!H23)+Assumptions!C23+Assumptions!C22+Assumptions!C21+Assumptions!C20)))) -> 17107259 | E22: =(Assumptions!C11/'Sens-Helper'!N43)*IF(((Assumptions!C60-Assumptions!C43)/(((Assumptions!C16+Assumptions!C17+Assumptions!C18+Assumptions!C19)+'Sens-Helper'!I43+'Sens-Helper'!J43)+((Assumptions!C7/'Sens-Helper'!N43)+(Assumptions!C25+'Sens-Helper'!H43)+Assumptions!C23+Assumptions!C22+Assumptions!C21+Assumptions!C20)))>Assumptions!C13,((Assumptions!C60-Assumptions!C43)+Assumptions!C26*Assumptions!C13)/((((Assumptions!C16+Assumptions!C17+Assumptions!C18+Assumptions!C19)+'Sens-Helper'!I43+'Sens-Helper'!J43)+((Assumptions!C7/'Sens-Helper'!N43)+(Assumptions!C25+'Sens-Helper'!H43)+Assumptions!C23+Assumptions!C22+Assumptions!C21+Assumptions!C20))+Assumptions!C26),((Assumptions!C60-Assumptions!C43)/(((Assumptions!C16+Assumptions!C17+Assumptions!C18+Assumptions!C19)+'Sens-Helper'!I43+'Sens-Helper'!J43)+((Assumptions!C7/'Sens-Helper'!N43)+(Assumptions!C25+'Sens-Helper'!H43)+Assumptions!C23+Assumptions!C22+Assumptions!C21+Assumptions!C20)))) -> 14719656 | F22: =(Assumptions!C11/'Sens-Helper'!N63)*IF(((Assumptions!C60-Assumptions!C43)/(((Assumptions!C16+Assumptions!C17+Assumptions!C18+Assumptions!C19)+'Sens-Helper'!I63+'Sens-Helper'!J63)+((Assumptions!C7/'Sens-Helper'!N63)+(Assumptions!C25+'Sens-Helper'!H63)+Assumptions!C23+Assumptions!C22+Assumptions!C21+Assumptions!C20)))>Assumptions!C13,((Assumptions!C60-Assumptions!C43)+Assumptions!C26*Assumptions!C13)/((((Assumptions!C16+Assumptions!C17+Assumptions!C18+Assumptions!C19)+'Sens-Helper'!I63+'Sens-Helper'!J63)+((Assumptions!C7/'Sens-Helper'!N63)+(Assumptions!C25+'Sens-Helper'!H63)+Assumptions!C23+Assumptions!C22+Assumptions!C21+Assumptions!C20))+Assumptions!C26),((Assumptions!C60-Assumptions!C43)/(((Assumptions!C16+Assumptions!C17+Assumptions!C18+Assumptions!C19)+'Sens-Helper'!I63+'Sens-Helper'!J63)+((Assumptions!C7/'Sens-Helper'!N63)+(Assumptions!C25+'Sens-Helper'!H63)+Assumptions!C23+Assumptions!C22+Assumptions!C21+Assumptions!C20)))) -> 11507141
B23: =Assumptions!C66 -> 0.13 | D23: =(Assumptions!C11/'Sens-Helper'!N83)*IF(((Assumptions!C60-Assumptions!C43)/(((Assumptions!C16+Assumptions!C17+Assumptions!C18+Assumptions!C19)+'Sens-Helper'!I83+'Sens-Helper'!J83)+((Assumptions!C7/'Sens-Helper'!N83)+(Assumptions!C25+'Sens-Helper'!H83)+Assumptions!C23+Assumptions!C22+Assumptions!C21+Assumptions!C20)))>Assumptions!C13,((Assumptions!C60-Assumptions!C43)+Assumptions!C26*Assumptions!C13)/((((Assumptions!C16+Assumptions!C17+Assumptions!C18+Assumptions!C19)+'Sens-Helper'!I83+'Sens-Helper'!J83)+((Assumptions!C7/'Sens-Helper'!N83)+(Assumptions!C25+'Sens-Helper'!H83)+Assumptions!C23+Assumptions!C22+Assumptions!C21+Assumptions!C20))+Assumptions!C26),((Assumptions!C60-Assumptions!C43)/(((Assumptions!C16+Assumptions!C17+Assumptions!C18+Assumptions!C19)+'Sens-Helper'!I83+'Sens-Helper'!J83)+((Assumptions!C7/'Sens-Helper'!N83)+(Assumptions!C25+'Sens-Helper'!H83)+Assumptions!C23+Assumptions!C22+Assumptions!C21+Assumptions!C20)))) -> 17384971 | E23: =(Assumptions!C11/'Sens-Helper'!N103)*IF(((Assumptions!C60-Assumptions!C43)/(((Assumptions!C16+Assumptions!C17+Assumptions!C18+Assumptions!C19)+'Sens-Helper'!I103+'Sens-Helper'!J103)+((Assumptions!C7/'Sens-Helper'!N103)+(Assumptions!C25+'Sens-Helper'!H103)+Assumptions!C23+Assumptions!C22+Assumptions!C21+Assumptions!C20)))>Assumptions!C13,((Assumptions!C60-Assumptions!C43)+Assumptions!C26*Assumptions!C13)/((((Assumptions!C16+Assumptions!C17+Assumptions!C18+Assumptions!C19)+'Sens-Helper'!I103+'Sens-Helper'!J103)+((Assumptions!C7/'Sens-Helper'!N103)+(Assumptions!C25+'Sens-Helper'!H103)+Assumptions!C23+Assumptions!C22+Assumptions!C21+Assumptions!C20))+Assumptions!C26),((Assumptions!C60-Assumptions!C43)/(((Assumptions!C16+Assumptions!C17+Assumptions!C18+Assumptions!C19)+'Sens-Helper'!I103+'Sens-Helper'!J103)+((Assumptions!C7/'Sens-Helper'!N103)+(Assumptions!C25+'Sens-Helper'!H103)+Assumptions!C23+Assumptions!C22+Assumptions!C21+Assumptions!C20)))) -> 14948858 | F23: =(Assumptions!C11/'Sens-Helper'!N123)*IF(((Assumptions!C60-Assumptions!C43)/(((Assumptions!C16+Assumptions!C17+Assumptions!C18+Assumptions!C19)+'Sens-Helper'!I123+'Sens-Helper'!J123)+((Assumptions!C7/'Sens-Helper'!N123)+(Assumptions!C25+'Sens-Helper'!H123)+Assumptions!C23+Assumptions!C22+Assumptions!C21+Assumptions!C20)))>Assumptions!C13,((Assumptions!C60-Assumptions!C43)+Assumptions!C26*Assumptions!C13)/((((Assumptions!C16+Assumptions!C17+Assumptions!C18+Assumptions!C19)+'Sens-Helper'!I123+'Sens-Helper'!J123)+((Assumptions!C7/'Sens-Helper'!N123)+(Assumptions!C25+'Sens-Helper'!H123)+Assumptions!C23+Assumptions!C22+Assumptions!C21+Assumptions!C20))+Assumptions!C26),((Assumptions!C60-Assumptions!C43)/(((Assumptions!C16+Assumptions!C17+Assumptions!C18+Assumptions!C19)+'Sens-Helper'!I123+'Sens-Helper'!J123)+((Assumptions!C7/'Sens-Helper'!N123)+(Assumptions!C25+'Sens-Helper'!H123)+Assumptions!C23+Assumptions!C22+Assumptions!C21+Assumptions!C20)))) -> 11676568
B24: =Assumptions!C67 -> 0.15 | D24: =(Assumptions!C11/'Sens-Helper'!N143)*IF(((Assumptions!C60-Assumptions!C43)/(((Assumptions!C16+Assumptions!C17+Assumptions!C18+Assumptions!C19)+'Sens-Helper'!I143+'Sens-Helper'!J143)+((Assumptions!C7/'Sens-Helper'!N143)+(Assumptions!C25+'Sens-Helper'!H143)+Assumptions!C23+Assumptions!C22+Assumptions!C21+Assumptions!C20)))>Assumptions!C13,((Assumptions!C60-Assumptions!C43)+Assumptions!C26*Assumptions!C13)/((((Assumptions!C16+Assumptions!C17+Assumptions!C18+Assumptions!C19)+'Sens-Helper'!I143+'Sens-Helper'!J143)+((Assumptions!C7/'Sens-Helper'!N143)+(Assumptions!C25+'Sens-Helper'!H143)+Assumptions!C23+Assumptions!C22+Assumptions!C21+Assumptions!C20))+Assumptions!C26),((Assumptions!C60-Assumptions!C43)/(((Assumptions!C16+Assumptions!C17+Assumptions!C18+Assumptions!C19)+'Sens-Helper'!I143+'Sens-Helper'!J143)+((Assumptions!C7/'Sens-Helper'!N143)+(Assumptions!C25+'Sens-Helper'!H143)+Assumptions!C23+Assumptions!C22+Assumptions!C21+Assumptions!C20)))) -> 17795002 | E24: =(Assumptions!C11/'Sens-Helper'!N163)*IF(((Assumptions!C60-Assumptions!C43)/(((Assumptions!C16+Assumptions!C17+Assumptions!C18+Assumptions!C19)+'Sens-Helper'!I163+'Sens-Helper'!J163)+((Assumptions!C7/'Sens-Helper'!N163)+(Assumptions!C25+'Sens-Helper'!H163)+Assumptions!C23+Assumptions!C22+Assumptions!C21+Assumptions!C20)))>Assumptions!C13,((Assumptions!C60-Assumptions!C43)+Assumptions!C26*Assumptions!C13)/((((Assumptions!C16+Assumptions!C17+Assumptions!C18+Assumptions!C19)+'Sens-Helper'!I163+'Sens-Helper'!J163)+((Assumptions!C7/'Sens-Helper'!N163)+(Assumptions!C25+'Sens-Helper'!H163)+Assumptions!C23+Assumptions!C22+Assumptions!C21+Assumptions!C20))+Assumptions!C26),((Assumptions!C60-Assumptions!C43)/(((Assumptions!C16+Assumptions!C17+Assumptions!C18+Assumptions!C19)+'Sens-Helper'!I163+'Sens-Helper'!J163)+((Assumptions!C7/'Sens-Helper'!N163)+(Assumptions!C25+'Sens-Helper'!H163)+Assumptions!C23+Assumptions!C22+Assumptions!C21+Assumptions!C20)))) -> 15301320 | F24: =(Assumptions!C11/'Sens-Helper'!N183)*IF(((Assumptions!C60-Assumptions!C43)/(((Assumptions!C16+Assumptions!C17+Assumptions!C18+Assumptions!C19)+'Sens-Helper'!I183+'Sens-Helper'!J183)+((Assumptions!C7/'Sens-Helper'!N183)+(Assumptions!C25+'Sens-Helper'!H183)+Assumptions!C23+Assumptions!C22+Assumptions!C21+Assumptions!C20)))>Assumptions!C13,((Assumptions!C60-Assumptions!C43)+Assumptions!C26*Assumptions!C13)/((((Assumptions!C16+Assumptions!C17+Assumptions!C18+Assumptions!C19)+'Sens-Helper'!I183+'Sens-Helper'!J183)+((Assumptions!C7/'Sens-Helper'!N183)+(Assumptions!C25+'Sens-Helper'!H183)+Assumptions!C23+Assumptions!C22+Assumptions!C21+Assumptions!C20))+Assumptions!C26),((Assumptions!C60-Assumptions!C43)/(((Assumptions!C16+Assumptions!C17+Assumptions!C18+Assumptions!C19)+'Sens-Helper'!I183+'Sens-Helper'!J183)+((Assumptions!C7/'Sens-Helper'!N183)+(Assumptions!C25+'Sens-Helper'!H183)+Assumptions!C23+Assumptions!C22+Assumptions!C21+Assumptions!C20)))) -> 11951762
B27: Each cell uses Sens-Helper scenarios 1-9 for F PPS, AD, notes, ESOP fixed point.
B28: At $2B exit: F=convert, E=convert, D=preference, C=convert, B=convert, A=convert, Seed=convert.

Sheet Solver
B2: Fixed-Point Solver — Base Case | G2: Fixed-Point Solver (F_PPS)
B3: Iterative refinement of F PPS, AD, notes, ESOP | G3: iter | H3: F_PPS | I3: NCP_D | J3: NCP_E | K3: AD_D | L3: AD_E | M3: n_A | N3: n_B | O3: ESOP_top | P3: FD_pre | Q3: T_F | R3: F_PPS_new
G4: 0 | H4: =Assumptions!C6/Assumptions!C28 -> 38.232604 | I4: =IF(H4<Assumptions!C35,Assumptions!C35*(Assumptions!C28+Assumptions!C7/Assumptions!C35)/(Assumptions!C28+Assumptions!C7/H4),Assumptions!C35) -> 57.701164 | J4: =IF(H4<Assumptions!C36,Assumptions!C36*(Assumptions!C28+Assumptions!C7/Assumptions!C36)/(Assumptions!C28+Assumptions!C7/H4),Assumptions!C36) -> 48.9291 | K4: =Assumptions!C24*(Assumptions!C35/I4-1) -> 12440.253 | L4: =Assumptions!C25*(Assumptions!C36/J4-1) -> 28588.226 | M4: =Assumptions!C48/MIN((Assumptions!C49/(Assumptions!C28+0+K4+L4+0)),(H4*(1-Assumptions!C50))) -> 183294.95 | N4: =Assumptions!C51/MIN((Assumptions!C52/(Assumptions!C28+0+K4+L4+M4)),(H4*(1-Assumptions!C53))) -> 92314.187 | O4: =MAX(0,(Assumptions!C10*(Assumptions!C28+K4+L4+M4+N4+Assumptions!C7/H4)-Assumptions!C55)/(1-Assumptions!C10)) -> 584871.26 | P4: =Assumptions!C28+O4+K4+L4+M4+N4 -> 37519470 | Q4: =P4+Assumptions!C7/H4 -> 38304140 | R4: =Assumptions!C6/P4 -> 37.31396
G5: 1 | H5: =R4 -> 37.31396 | I5: =IF(H5<Assumptions!C35,Assumptions!C35*(Assumptions!C28+Assumptions!C7/Assumptions!C35)/(Assumptions!C28+Assumptions!C7/H5),Assumptions!C35) -> 57.671377 | J5: =IF(H5<Assumptions!C36,Assumptions!C36*(Assumptions!C28+Assumptions!C7/Assumptions!C36)/(Assumptions!C28+Assumptions!C7/H5),Assumptions!C36) -> 48.903842 | K5: =Assumptions!C24*(Assumptions!C35/I5-1) -> 13335.363 | L5: =Assumptions!C25*(Assumptions!C36/J5-1) -> 31754.952 | M5: =Assumptions!C48/MIN((Assumptions!C49/(Assumptions!C28+O4+K5+L5+N4)),(H5*(1-Assumptions!C50))) -> 186701.18 | N5: =Assumptions!C51/MIN((Assumptions!C52/(Assumptions!C28+O4+K5+L5+M5)),(H5*(1-Assumptions!C53))) -> 94586.899 | O5: =MAX(0,(Assumptions!C10*(Assumptions!C28+K5+L5+M5+N5+Assumptions!C7/H5)-Assumptions!C55)/(1-Assumptions!C10)) -> 589213.38 | P5: =Assumptions!C28+O5+K5+L5+M5+N5 -> 37533553 | Q5: =P5+Assumptions!C7/H5 -> 38337541 | R5: =Assumptions!C6/P5 -> 37.29996
G6: 2 | H6: =R5 -> 37.29996 | I6: =IF(H6<Assumptions!C35,Assumptions!C35*(Assumptions!C28+Assumptions!C7/Assumptions!C35)/(Assumptions!C28+Assumptions!C7/H6),Assumptions!C35) -> 57.670912 | J6: =IF(H6<Assumptions!C36,Assumptions!C36*(Assumptions!C28+Assumptions!C7/Assumptions!C36)/(Assumptions!C28+Assumptions!C7/H6),Assumptions!C36) -> 48.903448 | K6: =Assumptions!C24*(Assumptions!C35/I6-1) -> 13349.346 | L6: =Assumptions!C25*(Assumptions!C36/J6-1) -> 31804.421 | M6: =Assumptions!C48/MIN((Assumptions!C49/(Assumptions!C28+O5+K6+L6+N5)),(H6*(1-Assumptions!C50))) -> 186734.58 | N6: =Assumptions!C51/MIN((Assumptions!C52/(Assumptions!C28+O5+K6+L6+M6)),(H6*(1-Assumptions!C53))) -> 94622.402 | O6: =MAX(0,(Assumptions!C10*(Assumptions!C28+K6+L6+M6+N6+Assumptions!C7/H6)-Assumptions!C55)/(1-Assumptions!C10)) -> 589278.25 | P6: =Assumptions!C28+O6+K6+L6+M6+N6 -> 37533750 | Q6: =P6+Assumptions!C7/H6 -> 38338040 | R6: =Assumptions!C6/P6 -> 37.299764
G7: 3 | H7: =R6 -> 37.299764 | I7: =IF(H7<Assumptions!C35,Assumptions!C35*(Assumptions!C28+Assumptions!C7/Assumptions!C35)/(Assumptions!C28+Assumptions!C7/H7),Assumptions!C35) -> 57.670905 | J7: =IF(H7<Assumptions!C36,Assumptions!C36*(Assumptions!C28+Assumptions!C7/Assumptions!C36)/(Assumptions!C28+Assumptions!C7/H7),Assumptions!C36) -> 48.903442 | K7: =Assumptions!C24*(Assumptions!C35/I7-1) -> 13349.542 | L7: =Assumptions!C25*(Assumptions!C36/J7-1) -> 31805.114 | M7: =Assumptions!C48/MIN((Assumptions!C49/(Assumptions!C28+O6+K7+L7+N6)),(H7*(1-Assumptions!C50))) -> 186735.08 | N7: =Assumptions!C51/MIN((Assumptions!C52/(Assumptions!C28+O6+K7+L7+M7)),(H7*(1-Assumptions!C53))) -> 94622.899 | O7: =MAX(0,(Assumptions!C10*(Assumptions!C28+K7+L7+M7+N7+Assumptions!C7/H7)-Assumptions!C55)/(1-Assumptions!C10)) -> 589279.17 | P7: =Assumptions!C28+O7+K7+L7+M7+N7 -> 37533753 | Q7: =P7+Assumptions!C7/H7 -> 38338047 | R7: =Assumptions!C6/P7 -> 37.299761
G8: 4 | H8: =R7 -> 37.299761 | I8: =IF(H8<Assumptions!C35,Assumptions!C35*(Assumptions!C28+Assumptions!C7/Assumptions!C35)/(Assumptions!C28+Assumptions!C7/H8),Assumptions!C35) -> 57.670905 | J8: =IF(H8<Assumptions!C36,Assumptions!C36*(Assumptions!C28+Assumptions!C7/Assumptions!C36)/(Assumptions!C28+Assumptions!C7/H8),Assumptions!C36) -> 48.903442 | K8: =Assumptions!C24*(Assumptions!C35/I8-1) -> 13349.544 | L8: =Assumptions!C25*(Assumptions!C36/J8-1) -> 31805.124 | M8: =Assumptions!C48/MIN((Assumptions!C49/(Assumptions!C28+O7+K8+L8+N7)),(H8*(1-Assumptions!C50))) -> 186735.09 | N8: =Assumptions!C51/MIN((Assumptions!C52/(Assumptions!C28+O7+K8+L8+M8)),(H8*(1-Assumptions!C53))) -> 94622.906 | O8: =MAX(0,(Assumptions!C10*(Assumptions!C28+K8+L8+M8+N8+Assumptions!C7/H8)-Assumptions!C55)/(1-Assumptions!C10)) -> 589279.18 | P8: =Assumptions!C28+O8+K8+L8+M8+N8 -> 37533753 | Q8: =P8+Assumptions!C7/H8 -> 38338048 | R8: =Assumptions!C6/P8 -> 37.299761
G9: 5 | H9: =R8 -> 37.299761 | I9: =IF(H9<Assumptions!C35,Assumptions!C35*(Assumptions!C28+Assumptions!C7/Assumptions!C35)/(Assumptions!C28+Assumptions!C7/H9),Assumptions!C35) -> 57.670905 | J9: =IF(H9<Assumptions!C36,Assumptions!C36*(Assumptions!C28+Assumptions!C7/Assumptions!C36)/(Assumptions!C28+Assumptions!C7/H9),Assumptions!C36) -> 48.903442 | K9: =Assumptions!C24*(Assumptions!C35/I9-1) -> 13349.544 | L9: =Assumptions!C25*(Assumptions!C36/J9-1) -> 31805.124 | M9: =Assumptions!C48/MIN((Assumptions!C49/(Assumptions!C28+O8+K9+L9+N8)),(H9*(1-Assumptions!C50))) -> 186735.09 | N9: =Assumptions!C51/MIN((Assumptions!C52/(Assumptions!C28+O8+K9+L9+M9)),(H9*(1-Assumptions!C53))) -> 94622.906 | O9: =MAX(0,(Assumptions!C10*(Assumptions!C28+K9+L9+M9+N9+Assumptions!C7/H9)-Assumptions!C55)/(1-Assumptions!C10)) -> 589279.18 | P9: =Assumptions!C28+O9+K9+L9+M9+N9 -> 37533753 | Q9: =P9+Assumptions!C7/H9 -> 38338048 | R9: =Assumptions!C6/P9 -> 37.299761
G10: 6 | H10: =R9 -> 37.299761 | I10: =IF(H10<Assumptions!C35,Assumptions!C35*(Assumptions!C28+Assumptions!C7/Assumptions!C35)/(Assumptions!C28+Assumptions!C7/H10),Assumptions!C35) -> 57.670905 | J10: =IF(H10<Assumptions!C36,Assumptions!C36*(Assumptions!C28+Assumptions!C7/Assumptions!C36)/(Assumptions!C28+Assumptions!C7/H10),Assumptions!C36) -> 48.903442 | K10: =Assumptions!C24*(Assumptions!C35/I10-1) -> 13349.544 | L10: =Assumptions!C25*(Assumptions!C36/J10-1) -> 31805.124 | M10: =Assumptions!C48/MIN((Assumptions!C49/(Assumptions!C28+O9+K10+L10+N9)),(H10*(1-Assumptions!C50))) -> 186735.09 | N10: =Assumptions!C51/MIN((Assumptions!C52/(Assumptions!C28+O9+K10+L10+M10)),(H10*(1-Assumptions!C53))) -> 94622.906 | O10: =MAX(0,(Assumptions!C10*(Assumptions!C28+K10+L10+M10+N10+Assumptions!C7/H10)-Assumptions!C55)/(1-Assumptions!C10)) -> 589279.18 | P10: =Assumptions!C28+O10+K10+L10+M10+N10 -> 37533753 | Q10: =P10+Assumptions!C7/H10 -> 38338048 | R10: =Assumptions!C6/P10 -> 37.299761
G11: 7 | H11: =R10 -> 37.299761 | I11: =IF(H11<Assumptions!C35,Assumptions!C35*(Assumptions!C28+Assumptions!C7/Assumptions!C35)/(Assumptions!C28+Assumptions!C7/H11),Assumptions!C35) -> 57.670905 | J11: =IF(H11<Assumptions!C36,Assumptions!C36*(Assumptions!C28+Assumptions!C7/Assumptions!C36)/(Assumptions!C28+Assumptions!C7/H11),Assumptions!C36) -> 48.903442 | K11: =Assumptions!C24*(Assumptions!C35/I11-1) -> 13349.544 | L11: =Assumptions!C25*(Assumptions!C36/J11-1) -> 31805.124 | M11: =Assumptions!C48/MIN((Assumptions!C49/(Assumptions!C28+O10+K11+L11+N10)),(H11*(1-Assumptions!C50))) -> 186735.09 | N11: =Assumptions!C51/MIN((Assumptions!C52/(Assumptions!C28+O10+K11+L11+M11)),(H11*(1-Assumptions!C53))) -> 94622.906 | O11: =MAX(0,(Assumptions!C10*(Assumptions!C28+K11+L11+M11+N11+Assumptions!C7/H11)-Assumptions!C55)/(1-Assumptions!C10)) -> 589279.18 | P11: =Assumptions!C28+O11+K11+L11+M11+N11 -> 37533753 | Q11: =P11+Assumptions!C7/H11 -> 38338048 | R11: =Assumptions!C6/P11 -> 37.299761
