Workbook

Sheet Assumptions
B2: Kelvin Dynamics — Assumptions
B3: Series F Round Modeling — All Inputs
B5: Series F Round Terms
B6: Pre-money valuation ($) | C6: 1400000000
B7: Primary raise ($) | C7: 30000000
B8: Secondary raise ($) | C8: 15000000
B9: Tender PPS multiplier | C9: 0.85
B10: ESOP refresh target (% post-F FD) | C10: 0.13
B11: Our fund check ($) | C11: 10000000
B12: F_LEAD primary check ($) | C12: 20000000
B14: Prior Round OCPs (for AD)
B15: Seed OCP ($/sh) | C15: 1
B16: Series A OCP ($/sh) | C16: 3
B17: Series B OCP ($/sh) | C17: 10
B18: Series C OCP ($/sh) | C18: 25
B19: Series D OCP — post-E NCP ($/sh) | C19: 58.118347
B20: Series E OCP ($/sh) | C20: 49.158311
B21: Series D original PPS (informational) | C21: 60
B23: Existing Cap Table (Pre-F)
B24: F1 founder common | C24: 4000000
B25: F2 founder common | C25: 2500000
B26: F3 founder common | C26: 1500000
B27: Employee RSAs (10 holders × 100K) | C27: 1000000
B28: Pre-F options issued | C28: 2500000
B29: Pre-F options unissued | C29: 1894667
B30: Pre-F option pool total | C30: =C28+C29
B31: Seed shares issued | C31: 5000000
B32: Series A shares issued | C32: 5000000
B33: Series B shares issued | C33: 3000000
B34: Series C shares issued | C34: 2400000
B35: Series D shares issued (original) | C35: 1666667
B36: Series E shares issued | C36: 6102667
B37: Pre-F broad-based FD (post-E AD on D) | C37: 36617961
B39: Cumulative Invested by Class
B40: Seed invested ($) | C40: 5000000
B41: Series A invested ($) | C41: 15000000
B42: Series B invested ($) | C42: 30000000
B43: Series C invested ($) | C43: 60000000
B44: Series D invested ($) | C44: 100000000
B45: Series E invested ($) | C45: 300000000
...

Sheet Pro-Forma
B2: Kelvin Dynamics — Pro-Forma Cap Table (Post-F)
B3: F PPS fixed-point solve · AD · Notes · Tender · Ownership
B5: Pre-F Constants
B6: Founders + RSAs common (sh) | C6: =SUM(Assumptions!C24:C27)
B7: Seed+A+B+C issued shares (sh) | C7: =SUM(Assumptions!C31:C34)
B8: Pre-F option pool (sh) | C8: =Assumptions!C30
B9: Pre-F broad-based FD — constant A (sh) | C9: =Assumptions!C37
B10: Notional B for E (30M / E_OCP) (sh) | C10: =Assumptions!C7/Assumptions!C20
B11: Notional B for D (30M / D_OCP) (sh) | C11: =Assumptions!C7/Assumptions!C19
B12: Constant subtotal (founders + early pref + options) (sh) | C12: =C6+C7+C8
B14: F PPS Fixed-Point Solver (4 iterations)
B15: Iter | C15: F_PPS | D15: NCP_E | E15: NCP_D | F15: D_AD sh | G15: E_AD sh | H15: pre_F w/AD | I15: ESOP topup | J15: cap_PPS_A | K15: disc_PPS_A | L15: branch_A | M15: conv_PPS_A | N15: N_A sh | O15: cap_PPS_B | P15: disc_PPS_B | Q15: branch_B | R15: conv_PPS_B | S15: N_B sh | T15: T_F | U15: new pre_FD
B16: Iter 0 | C16: =Assumptions!C6/C9 | D16: =Assumptions!C20*(C9+C10)/(C9+Assumptions!C7/C16) | E16: =Assumptions!C19*(C9+C11)/(C9+Assumptions!C7/C16) | F16: =Assumptions!C44/E16 | G16: =Assumptions!C45/D16 | H16: =C12+F16+G16 | I16: =MAX(0,(0.13*(H16+Assumptions!C7/C16)-Assumptions!C30)/0.87) | J16: =Assumptions!C49/(H16+I16) | K16: =C16*(1-Assumptions!C50) | L16: =IF(J16<K16,"cap","discount") | M16: =MIN(J16,K16) | N16: =Assumptions!C48/M16 | O16: =Assumptions!C52/(H16+I16+N16) | P16: =C16*(1-Assumptions!C53) | Q16: =IF(O16<P16,"cap","discount") | R16: =MIN(O16,P16) | S16: =Assumptions!C51/R16 | T16: =H16+I16+N16+S16+Assumptions!C7/C16 | U16: =H16+I16+N16+S16
B17: Iter 1 | C17: =Assumptions!C6/U16 | D17: =Assumptions!C20*(C9+C10)/(C9+Assumptions!C7/C17) | E17: =Assumptions!C19*(C9+C11)/(C9+Assumptions!C7/C17) | F17: =Assumptions!C44/E17 | G17: =Assumptions!C45/D17 | H17: =C12+F17+G17 | I17: =MAX(0,(0.13*(H17+N16+S16+Assumptions!C7/C17)-Assumptions!C30)/0.87) | J17: =Assumptions!C49/(H17+I17+S16) | K17: =C17*(1-Assumptions!C50) | L17: =IF(J17<K17,"cap","discount") | M17: =MIN(J17,K17) | N17: =Assumptions!C48/M17 | O17: =Assumptions!C52/(H17+I17+N17) | P17: =C17*(1-Assumptions!C53) | Q17: =IF(O17<P17,"cap","discount") | R17: =MIN(O17,P17) | S17: =Assumptions!C51/R17 | T17: =H17+I17+N17+S17+Assumptions!C7/C17 | U17: =H17+I17+N17+S17
B18: Iter 2 | C18: =Assumptions!C6/U17 | D18: =Assumptions!C20*(C9+C10)/(C9+Assumptions!C7/C18) | E18: =Assumptions!C19*(C9+C11)/(C9+Assumptions!C7/C18) | F18: =Assumptions!C44/E18 | G18: =Assumptions!C45/D18 | H18: =C12+F18+G18 | I18: =MAX(0,(0.13*(H18+N17+S17+Assumptions!C7/C18)-Assumptions!C30)/0.87) | J18: =Assumptions!C49/(H18+I18+S17) | K18: =C18*(1-Assumptions!C50) | L18: =IF(J18<K18,"cap","discount") | M18: =MIN(J18,K18) | N18: =Assumptions!C48/M18 | O18: =Assumptions!C52/(H18+I18+N18) | P18: =C18*(1-Assumptions!C53) | Q18: =IF(O18<P18,"cap","discount") | R18: =MIN(O18,P18) | S18: =Assumptions!C51/R18 | T18: =H18+I18+N18+S18+Assumptions!C7/C18 | U18: =H18+I18+N18+S18
B19: Iter 3 | C19: =Assumptions!C6/U18 | D19: =Assumptions!C20*(C9+C10)/(C9+Assumptions!C7/C19) | E19: =Assumptions!C19*(C9+C11)/(C9+Assumptions!C7/C19) | F19: =Assumptions!C44/E19 | G19: =Assumptions!C45/D19 | H19: =C12+F19+G19 | I19: =MAX(0,(0.13*(H19+N18+S18+Assumptions!C7/C19)-Assumptions!C30)/0.87) | J19: =Assumptions!C49/(H19+I19+S18) | K19: =C19*(1-Assumptions!C50) | L19: =IF(J19<K19,"cap","discount") | M19: =MIN(J19,K19) | N19: =Assumptions!C48/M19 | O19: =Assumptions!C52/(H19+I19+N19) | P19: =C19*(1-Assumptions!C53) | Q19: =IF(O19<P19,"cap","discount") | R19: =MIN(O19,P19) | S19: =Assumptions!C51/R19 | T19: =H19+I19+N19+S19+Assumptions!C7/C19 | U19: =H19+I19+N19+S19
B21: Final Round Results (= Iter 3)
B22: F PPS ($/sh) | C22: =C19
B23: New F primary shares | C23: =Assumptions!C7/C22
B24: Pre-money FD (sh) | C24: =U19
B25: Post-F FD T_F (sh) | C25: =T19
B26: ESOP top-up (sh) | C26: =I19
B27: Post-F option pool (sh) | C27: =Assumptions!C30+C26
B28: Post-F option pool % of T_F | C28: =C27/C25
B30: Anti-Dilution Block (Broad-Based WA)
B31: Class | C31: OCP | D31: F_PPS<OCP? | E31: NCP | F31: New ratio | G31: Invested | H31: As-conv shares
B32: Seed | C32: =Assumptions!C15 | D32: =IF(C22<C32,"YES","no") | E32: =C32*(C9+Assumptions!C7/C32)/(C9+Assumptions!C7/C22) | F32: =C32/E32 | G32: =Assumptions!C40 | H32: =IF(D32="YES",G32/E32,Assumptions!C31)
B33: Series A | C33: =Assumptions!C16 | D33: =IF(C22<C33,"YES","no") | E33: =C33*(C9+Assumptions!C7/C33)/(C9+Assumptions!C7/C22) | F33: =C33/E33 | G33: =Assumptions!C41 | H33: =IF(D33="YES",G33/E33,Assumptions!C32)
B34: Series B | C34: =Assumptions!C17 | D34: =IF(C22<C34,"YES","no") | E34: =C34*(C9+Assumptions!C7/C34)/(C9+Assumptions!C7/C22) | F34: =C34/E34 | G34: =Assumptions!C42 | H34: =IF(D34="YES",G34/E34,Assumptions!C33)
B35: Series C | C35: =Assumptions!C18 | D35: =IF(C22<C35,"YES","no") | E35: =C35*(C9+Assumptions!C7/C35)/(C9+Assumptions!C7/C22) | F35: =C35/E35 | G35: =Assumptions!C43 | H35: =IF(D35="YES",G35/E35,Assumptions!C34)
B36: Series D | C36: =Assumptions!C19 | D36: =IF(C22<C36,"YES","no") | E36: =C36*(C9+Assumptions!C7/C36)/(C9+Assumptions!C7/C22) | F36: =C36/E36 | G36: =Assumptions!C44 | H36: =IF(D36="YES",G36/E36,Assumptions!C35)
B37: Series E | C37: =Assumptions!C20 | D37: =IF(C22<C37,"YES","no") | E37: =C37*(C9+Assumptions!C7/C37)/(C9+Assumptions!C7/C22) | F37: =C37/E37 | G37: =Assumptions!C45 | H37: =IF(D37="YES",G37/E37,Assumptions!C36)
B38: Total preferred (Seed–E) as-conv | H38: =SUM(H32:H37)
B40: Convertible Notes Conversion Block
B41: Note | C41: Principal | D41: Cap | E41: Discount | F41: cap-PPS | G41: disc-PPS | H41: branch | I41: conv-PPS | J41: Shares
B42: Note A | C42: =Assumptions!C48 | D42: =Assumptions!C49 | E42: =Assumptions!C50 | F42: =J19 | G42: =K19 | H42: =L19 | I42: =M19 | J42: =N19
B43: Note B | C43: =Assumptions!C51 | D43: =Assumptions!C52 | E43: =Assumptions!C53 | F43: =O19 | G43: =P19 | H43: =Q19 | I43: =R19 | J43: =S19
B44: Total notes shares | J44: =J42+J43
B46: Secondary Tender Block
B47: Tender PPS ($/sh) | C47: =Assumptions!C9*C22
...

Sheet Return-Solver
B2: Kelvin Dynamics — Return Solver
B3: Required Series F ownership % for our $10M check at 3× / 4× returns
B5: Per-Exit Inputs (from Waterfall)
B6: Metric | C6: Exit 1 | D6: Exit 2 | E6: Exit 3 | F6: Exit 4 | G6: Exit 5
B7: Exit value ($) | C7: =Assumptions!C59 | D7: =Assumptions!C60 | E7: =Assumptions!C61 | F7: =Assumptions!C62 | G7: =Assumptions!C63
B8: V_final ($/sh) | C8: =Waterfall!F35 | D8: =Waterfall!G35 | E8: =Waterfall!H35 | F8: =Waterfall!I35 | G8: =Waterfall!J35
B9: F class election | C9: =Waterfall!F41 | D9: =Waterfall!G41 | E9: =Waterfall!H41 | F9: =Waterfall!I41 | G9: =Waterfall!J41
B10: T_F (post-F FD, sh) | C10: ='Pro-Forma'!C25 | D10: ='Pro-Forma'!C25 | E10: ='Pro-Forma'!C25 | F10: ='Pro-Forma'!C25 | G10: ='Pro-Forma'!C25
B11: F class OCP (= F_PPS) | C11: ='Pro-Forma'!C22 | D11: ='Pro-Forma'!C22 | E11: ='Pro-Forma'!C22 | F11: ='Pro-Forma'!C22 | G11: ='Pro-Forma'!C22
B13: 3× Target — Need $30M from $10M Check
B14: Target $ proceeds | C14: =Assumptions!C75*Assumptions!C11 | D14: =Assumptions!C75*Assumptions!C11 | E14: =Assumptions!C75*Assumptions!C11 | F14: =Assumptions!C75*Assumptions!C11 | G14: =Assumptions!C75*Assumptions!C11
B15: Required our ownership % | C15: =IF(C9="convert",C14/(C10*C8),"infeasible — F preference caps at $10M") | D15: =IF(D9="convert",D14/(D10*D8),"infeasible — F preference caps at $10M") | E15: =IF(E9="convert",E14/(E10*E8),"infeasible — F preference caps at $10M") | F15: =IF(F9="convert",F14/(F10*F8),"infeasible — F preference caps at $10M") | G15: =IF(G9="convert",G14/(G10*G8),"infeasible — F preference caps at $10M")
B16: Feasible? | C16: =IF(C9="preference","infeasible (F pref)",IF(OR(C15<=0,C15>1),"infeasible (out of bounds)","feasible")) | D16: =IF(D9="preference","infeasible (F pref)",IF(OR(D15<=0,D15>1),"infeasible (out of bounds)","feasible")) | E16: =IF(E9="preference","infeasible (F pref)",IF(OR(E15<=0,E15>1),"infeasible (out of bounds)","feasible")) | F16: =IF(F9="preference","infeasible (F pref)",IF(OR(F15<=0,F15>1),"infeasible (out of bounds)","feasible")) | G16: =IF(G9="preference","infeasible (F pref)",IF(OR(G15<=0,G15>1),"infeasible (out of bounds)","feasible"))
B18: 4× Target — Need $40M from $10M Check
B19: Target $ proceeds | C19: =Assumptions!C76*Assumptions!C11 | D19: =Assumptions!C76*Assumptions!C11 | E19: =Assumptions!C76*Assumptions!C11 | F19: =Assumptions!C76*Assumptions!C11 | G19: =Assumptions!C76*Assumptions!C11
B20: Required our ownership % | C20: =IF(C9="convert",C19/(C10*C8),"infeasible — F preference caps at $10M") | D20: =IF(D9="convert",D19/(D10*D8),"infeasible — F preference caps at $10M") | E20: =IF(E9="convert",E19/(E10*E8),"infeasible — F preference caps at $10M") | F20: =IF(F9="convert",F19/(F10*F8),"infeasible — F preference caps at $10M") | G20: =IF(G9="convert",G19/(G10*G8),"infeasible — F preference caps at $10M")
B21: Feasible? | C21: =IF(C9="preference","infeasible (F pref)",IF(OR(C20<=0,C20>1),"infeasible (out of bounds)","feasible")) | D21: =IF(D9="preference","infeasible (F pref)",IF(OR(D20<=0,D20>1),"infeasible (out of bounds)","feasible")) | E21: =IF(E9="preference","infeasible (F pref)",IF(OR(E20<=0,E20>1),"infeasible (out of bounds)","feasible")) | F21: =IF(F9="preference","infeasible (F pref)",IF(OR(F20<=0,F20>1),"infeasible (out of bounds)","feasible")) | G21: =IF(G9="preference","infeasible (F pref)",IF(OR(G20<=0,G20>1),"infeasible (out of bounds)","feasible"))
B23: For Reference — Base Case
B24: Our base-case ownership % | C24: =Assumptions!C11/'Pro-Forma'!C22/'Pro-Forma'!C25 | D24: (constant; round-fixed)
B25: Our base-case $ proceeds @ exit | C25: =IF(C9="preference",Assumptions!C11,Assumptions!C11/C11*C8) | D25: =IF(D9="preference",Assumptions!C11,Assumptions!C11/D11*D8) | E25: =IF(E9="preference",Assumptions!C11,Assumptions!C11/E11*E8) | F25: =IF(F9="preference",Assumptions!C11,Assumptions!C11/F11*F8) | G25: =IF(G9="preference",Assumptions!C11,Assumptions!C11/G11*G8)
B26: Base-case multiple | C26: =C25/Assumptions!C11 | D26: =D25/Assumptions!C11 | E26: =E25/Assumptions!C11 | F26: =F25/Assumptions!C11 | G26: =G25/Assumptions!C11
B28: Note: "Required our ownership %" assumes round structure (T_F, F_PPS) is held at base case; only our slice is varied. F class = our + F_LEAD primary. Our check is 1/3 of F primary. F preference always returns exactly our check ($10M = 1× MOIC), so 3×/4× impossible at exits where F elects preference.

Sheet Sensitivity
B2: Kelvin Dynamics — Sensitivity
B3: Our $10M check at $2B exit · ESOP {11/13/15%} × Pre-money {$1.2B/$1.4B/$1.8B}
B5: 3×3 Sensitivity — Our $10M Check
B6: Our $ Proceeds @ $2B Exit
B7: ESOP \ Pre | D7: $1.2B | E7: $1.4B | F7: $1.8B
C8: 11% | D8: =C76 | E8: =D76 | F8: =E76
C9: 13% | D9: =F76 | E9: =G76 | F9: =H76
C10: 15% | D10: =I76 | E10: =J76 | F10: =K76
B12: Our Post-F Ownership %
B13: ESOP \ Pre | D13: $1.2B | E13: $1.4B | F13: $1.8B
C14: 11% | D14: =C77 | E14: =D77 | F14: =E77
C15: 13% | D15: =F77 | E15: =G77 | F15: =H77
C16: 15% | D16: =I77 | E16: =J77 | F16: =K77
B18: Per-Scenario Detailed Solves (3 iterations each)
B19: Scenario (ESOP / Pre) | C19: 11% / $1.2B | D19: 11% / $1.4B | E19: 11% / $1.8B | F19: 13% / $1.2B | G19: 13% / $1.4B | H19: 13% / $1.8B | I19: 15% / $1.2B | J19: 15% / $1.4B | K19: 15% / $1.8B
B21: ESOP target | C21: =Assumptions!C66 | D21: =Assumptions!C66 | E21: =Assumptions!C66 | F21: =Assumptions!C67 | G21: =Assumptions!C67 | H21: =Assumptions!C67 | I21: =Assumptions!C68 | J21: =Assumptions!C68 | K21: =Assumptions!C68
B22: Pre-money ($) | C22: =Assumptions!C69 | D22: =Assumptions!C70 | E22: =Assumptions!C71 | F22: =Assumptions!C69 | G22: =Assumptions!C70 | H22: =Assumptions!C71 | I22: =Assumptions!C69 | J22: =Assumptions!C70 | K22: =Assumptions!C71
B24: — Iteration 0 (initial guess) —
B25: I0: F_PPS | C25: =C22/Assumptions!C37 | D25: =D22/Assumptions!C37 | E25: =E22/Assumptions!C37 | F25: =F22/Assumptions!C37 | G25: =G22/Assumptions!C37 | H25: =H22/Assumptions!C37 | I25: =I22/Assumptions!C37 | J25: =J22/Assumptions!C37 | K25: =K22/Assumptions!C37
B26: I0: NCP_E | C26: =Assumptions!C20*(Assumptions!C37+Assumptions!C7/Assumptions!C20)/(Assumptions!C37+Assumptions!C7/C25) | D26: =Assumptions!C20*(Assumptions!C37+Assumptions!C7/Assumptions!C20)/(Assumptions!C37+Assumptions!C7/D25) | E26: =Assumptions!C20*(Assumptions!C37+Assumptions!C7/Assumptions!C20)/(Assumptions!C37+Assumptions!C7/E25) | F26: =Assumptions!C20*(Assumptions!C37+Assumptions!C7/Assumptions!C20)/(Assumptions!C37+Assumptions!C7/F25) | G26: =Assumptions!C20*(Assumptions!C37+Assumptions!C7/Assumptions!C20)/(Assumptions!C37+Assumptions!C7/G25) | H26: =Assumptions!C20*(Assumptions!C37+Assumptions!C7/Assumptions!C20)/(Assumptions!C37+Assumptions!C7/H25) | I26: =Assumptions!C20*(Assumptions!C37+Assumptions!C7/Assumptions!C20)/(Assumptions!C37+Assumptions!C7/I25) | J26: =Assumptions!C20*(Assumptions!C37+Assumptions!C7/Assumptions!C20)/(Assumptions!C37+Assumptions!C7/J25) | K26: =Assumptions!C20*(Assumptions!C37+Assumptions!C7/Assumptions!C20)/(Assumptions!C37+Assumptions!C7/K25)
B27: I0: NCP_D | C27: =Assumptions!C19*(Assumptions!C37+Assumptions!C7/Assumptions!C19)/(Assumptions!C37+Assumptions!C7/C25) | D27: =Assumptions!C19*(Assumptions!C37+Assumptions!C7/Assumptions!C19)/(Assumptions!C37+Assumptions!C7/D25) | E27: =Assumptions!C19*(Assumptions!C37+Assumptions!C7/Assumptions!C19)/(Assumptions!C37+Assumptions!C7/E25) | F27: =Assumptions!C19*(Assumptions!C37+Assumptions!C7/Assumptions!C19)/(Assumptions!C37+Assumptions!C7/F25) | G27: =Assumptions!C19*(Assumptions!C37+Assumptions!C7/Assumptions!C19)/(Assumptions!C37+Assumptions!C7/G25) | H27: =Assumptions!C19*(Assumptions!C37+Assumptions!C7/Assumptions!C19)/(Assumptions!C37+Assumptions!C7/H25) | I27: =Assumptions!C19*(Assumptions!C37+Assumptions!C7/Assumptions!C19)/(Assumptions!C37+Assumptions!C7/I25) | J27: =Assumptions!C19*(Assumptions!C37+Assumptions!C7/Assumptions!C19)/(Assumptions!C37+Assumptions!C7/J25) | K27: =Assumptions!C19*(Assumptions!C37+Assumptions!C7/Assumptions!C19)/(Assumptions!C37+Assumptions!C7/K25)
B28: I0: D_AD sh | C28: =Assumptions!C44/C27 | D28: =Assumptions!C44/D27 | E28: =Assumptions!C44/E27 | F28: =Assumptions!C44/F27 | G28: =Assumptions!C44/G27 | H28: =Assumptions!C44/H27 | I28: =Assumptions!C44/I27 | J28: =Assumptions!C44/J27 | K28: =Assumptions!C44/K27
B29: I0: E_AD sh | C29: =Assumptions!C45/C26 | D29: =Assumptions!C45/D26 | E29: =Assumptions!C45/E26 | F29: =Assumptions!C45/F26 | G29: =Assumptions!C45/G26 | H29: =Assumptions!C45/H26 | I29: =Assumptions!C45/I26 | J29: =Assumptions!C45/J26 | K29: =Assumptions!C45/K26
B30: I0: pre_F_AD | C30: ='Pro-Forma'!C12+C28+C29 | D30: ='Pro-Forma'!C12+D28+D29 | E30: ='Pro-Forma'!C12+E28+E29 | F30: ='Pro-Forma'!C12+F28+F29 | G30: ='Pro-Forma'!C12+G28+G29 | H30: ='Pro-Forma'!C12+H28+H29 | I30: ='Pro-Forma'!C12+I28+I29 | J30: ='Pro-Forma'!C12+J28+J29 | K30: ='Pro-Forma'!C12+K28+K29
B31: I0: topup | C31: =MAX(0,(C21*(C30+Assumptions!C7/C25)-Assumptions!C30)/(1-C21)) | D31: =MAX(0,(D21*(D30+Assumptions!C7/D25)-Assumptions!C30)/(1-D21)) | E31: =MAX(0,(E21*(E30+Assumptions!C7/E25)-Assumptions!C30)/(1-E21)) | F31: =MAX(0,(F21*(F30+Assumptions!C7/F25)-Assumptions!C30)/(1-F21)) | G31: =MAX(0,(G21*(G30+Assumptions!C7/G25)-Assumptions!C30)/(1-G21)) | H31: =MAX(0,(H21*(H30+Assumptions!C7/H25)-Assumptions!C30)/(1-H21)) | I31: =MAX(0,(I21*(I30+Assumptions!C7/I25)-Assumptions!C30)/(1-I21)) | J31: =MAX(0,(J21*(J30+Assumptions!C7/J25)-Assumptions!C30)/(1-J21)) | K31: =MAX(0,(K21*(K30+Assumptions!C7/K25)-Assumptions!C30)/(1-K21))
B32: I0: cap_A | C32: =Assumptions!C49/(C30+C31+0) | D32: =Assumptions!C49/(D30+D31+0) | E32: =Assumptions!C49/(E30+E31+0) | F32: =Assumptions!C49/(F30+F31+0) | G32: =Assumptions!C49/(G30+G31+0) | H32: =Assumptions!C49/(H30+H31+0) | I32: =Assumptions!C49/(I30+I31+0) | J32: =Assumptions!C49/(J30+J31+0) | K32: =Assumptions!C49/(K30+K31+0)
B33: I0: disc_A | C33: =C25*(1-Assumptions!C50) | D33: =D25*(1-Assumptions!C50) | E33: =E25*(1-Assumptions!C50) | F33: =F25*(1-Assumptions!C50) | G33: =G25*(1-Assumptions!C50) | H33: =H25*(1-Assumptions!C50) | I33: =I25*(1-Assumptions!C50) | J33: =J25*(1-Assumptions!C50) | K33: =K25*(1-Assumptions!C50)
B34: I0: branch_A | C34: =IF(C32<C33,"cap","discount") | D34: =IF(D32<D33,"cap","discount") | E34: =IF(E32<E33,"cap","discount") | F34: =IF(F32<F33,"cap","discount") | G34: =IF(G32<G33,"cap","discount") | H34: =IF(H32<H33,"cap","discount") | I34: =IF(I32<I33,"cap","discount") | J34: =IF(J32<J33,"cap","discount") | K34: =IF(K32<K33,"cap","discount")
B35: I0: N_A sh | C35: =Assumptions!C48/MIN(C32,C33) | D35: =Assumptions!C48/MIN(D32,D33) | E35: =Assumptions!C48/MIN(E32,E33) | F35: =Assumptions!C48/MIN(F32,F33) | G35: =Assumptions!C48/MIN(G32,G33) | H35: =Assumptions!C48/MIN(H32,H33) | I35: =Assumptions!C48/MIN(I32,I33) | J35: =Assumptions!C48/MIN(J32,J33) | K35: =Assumptions!C48/MIN(K32,K33)
B36: I0: cap_B | C36: =Assumptions!C52/(C30+C31+C35) | D36: =Assumptions!C52/(D30+D31+D35) | E36: =Assumptions!C52/(E30+E31+E35) | F36: =Assumptions!C52/(F30+F31+F35) | G36: =Assumptions!C52/(G30+G31+G35) | H36: =Assumptions!C52/(H30+H31+H35) | I36: =Assumptions!C52/(I30+I31+I35) | J36: =Assumptions!C52/(J30+J31+J35) | K36: =Assumptions!C52/(K30+K31+K35)
B37: I0: disc_B | C37: =C25*(1-Assumptions!C53) | D37: =D25*(1-Assumptions!C53) | E37: =E25*(1-Assumptions!C53) | F37: =F25*(1-Assumptions!C53) | G37: =G25*(1-Assumptions!C53) | H37: =H25*(1-Assumptions!C53) | I37: =I25*(1-Assumptions!C53) | J37: =J25*(1-Assumptions!C53) | K37: =K25*(1-Assumptions!C53)
B38: I0: branch_B | C38: =IF(C36<C37,"cap","discount") | D38: =IF(D36<D37,"cap","discount") | E38: =IF(E36<E37,"cap","discount") | F38: =IF(F36<F37,"cap","discount") | G38: =IF(G36<G37,"cap","discount") | H38: =IF(H36<H37,"cap","discount") | I38: =IF(I36<I37,"cap","discount") | J38: =IF(J36<J37,"cap","discount") | K38: =IF(K36<K37,"cap","discount")
B39: I0: N_B sh | C39: =Assumptions!C51/MIN(C36,C37) | D39: =Assumptions!C51/MIN(D36,D37) | E39: =Assumptions!C51/MIN(E36,E37) | F39: =Assumptions!C51/MIN(F36,F37) | G39: =Assumptions!C51/MIN(G36,G37) | H39: =Assumptions!C51/MIN(H36,H37) | I39: =Assumptions!C51/MIN(I36,I37) | J39: =Assumptions!C51/MIN(J36,J37) | K39: =Assumptions!C51/MIN(K36,K37)
B40: I0: new_pre_FD | C40: =C30+C31+C35+C39 | D40: =D30+D31+D35+D39 | E40: =E30+E31+E35+E39 | F40: =F30+F31+F35+F39 | G40: =G30+G31+G35+G39 | H40: =H30+H31+H35+H39 | I40: =I30+I31+I35+I39 | J40: =J30+J31+J35+J39 | K40: =K30+K31+K35+K39
B41: I1: F_PPS | C41: =C22/C40 | D41: =D22/D40 | E41: =E22/E40 | F41: =F22/F40 | G41: =G22/G40 | H41: =H22/H40 | I41: =I22/I40 | J41: =J22/J40 | K41: =K22/K40
B42: I1: NCP_E | C42: =Assumptions!C20*(Assumptions!C37+Assumptions!C7/Assumptions!C20)/(Assumptions!C37+Assumptions!C7/C41) | D42: =Assumptions!C20*(Assumptions!C37+Assumptions!C7/Assumptions!C20)/(Assumptions!C37+Assumptions!C7/D41) | E42: =Assumptions!C20*(Assumptions!C37+Assumptions!C7/Assumptions!C20)/(Assumptions!C37+Assumptions!C7/E41) | F42: =Assumptions!C20*(Assumptions!C37+Assumptions!C7/Assumptions!C20)/(Assumptions!C37+Assumptions!C7/F41) | G42: =Assumptions!C20*(Assumptions!C37+Assumptions!C7/Assumptions!C20)/(Assumptions!C37+Assumptions!C7/G41) | H42: =Assumptions!C20*(Assumptions!C37+Assumptions!C7/Assumptions!C20)/(Assumptions!C37+Assumptions!C7/H41) | I42: =Assumptions!C20*(Assumptions!C37+Assumptions!C7/Assumptions!C20)/(Assumptions!C37+Assumptions!C7/I41) | J42: =Assumptions!C20*(Assumptions!C37+Assumptions!C7/Assumptions!C20)/(Assumptions!C37+Assumptions!C7/J41) | K42: =Assumptions!C20*(Assumptions!C37+Assumptions!C7/Assumptions!C20)/(Assumptions!C37+Assumptions!C7/K41)
B43: I1: NCP_D | C43: =Assumptions!C19*(Assumptions!C37+Assumptions!C7/Assumptions!C19)/(Assumptions!C37+Assumptions!C7/C41) | D43: =Assumptions!C19*(Assumptions!C37+Assumptions!C7/Assumptions!C19)/(Assumptions!C37+Assumptions!C7/D41) | E43: =Assumptions!C19*(Assumptions!C37+Assumptions!C7/Assumptions!C19)/(Assumptions!C37+Assumptions!C7/E41) | F43: =Assumptions!C19*(Assumptions!C37+Assumptions!C7/Assumptions!C19)/(Assumptions!C37+Assumptions!C7/F41) | G43: =Assumptions!C19*(Assumptions!C37+Assumptions!C7/Assumptions!C19)/(Assumptions!C37+Assumptions!C7/G41) | H43: =Assumptions!C19*(Assumptions!C37+Assumptions!C7/Assumptions!C19)/(Assumptions!C37+Assumptions!C7/H41) | I43: =Assumptions!C19*(Assumptions!C37+Assumptions!C7/Assumptions!C19)/(Assumptions!C37+Assumptions!C7/I41) | J43: =Assumptions!C19*(Assumptions!C37+Assumptions!C7/Assumptions!C19)/(Assumptions!C37+Assumptions!C7/J41) | K43: =Assumptions!C19*(Assumptions!C37+Assumptions!C7/Assumptions!C19)/(Assumptions!C37+Assumptions!C7/K41)
B44: I1: D_AD sh | C44: =Assumptions!C44/C43 | D44: =Assumptions!C44/D43 | E44: =Assumptions!C44/E43 | F44: =Assumptions!C44/F43 | G44: =Assumptions!C44/G43 | H44: =Assumptions!C44/H43 | I44: =Assumptions!C44/I43 | J44: =Assumptions!C44/J43 | K44: =Assumptions!C44/K43
B45: I1: E_AD sh | C45: =Assumptions!C45/C42 | D45: =Assumptions!C45/D42 | E45: =Assumptions!C45/E42 | F45: =Assumptions!C45/F42 | G45: =Assumptions!C45/G42 | H45: =Assumptions!C45/H42 | I45: =Assumptions!C45/I42 | J45: =Assumptions!C45/J42 | K45: =Assumptions!C45/K42
B46: I1: pre_F_AD | C46: ='Pro-Forma'!C12+C44+C45 | D46: ='Pro-Forma'!C12+D44+D45 | E46: ='Pro-Forma'!C12+E44+E45 | F46: ='Pro-Forma'!C12+F44+F45 | G46: ='Pro-Forma'!C12+G44+G45 | H46: ='Pro-Forma'!C12+H44+H45 | I46: ='Pro-Forma'!C12+I44+I45 | J46: ='Pro-Forma'!C12+J44+J45 | K46: ='Pro-Forma'!C12+K44+K45
...

Sheet Waterfall
B2: Kelvin Dynamics — Exit Waterfall
B3: 5 exits · 7-class election Nash via MIN(V_k) · reconciles to exit
B5: Priced Classes — Sorted by Effective OCP (Descending)
B6: Class | C6: OCP-eff ($) | D6: Shares | E6: LP ($)
B7: D Pref | C7: ='Pro-Forma'!E36 | D7: ='Pro-Forma'!H36 | E7: =Assumptions!C44
B8: E Pref | C8: ='Pro-Forma'!E37 | D8: ='Pro-Forma'!H37 | E8: =Assumptions!C45
B9: F Pref | C9: ='Pro-Forma'!C22 | D9: ='Pro-Forma'!C23 | E9: =Assumptions!C7
B10: C Pref | C10: =Assumptions!C18 | D10: ='Pro-Forma'!H35 | E10: =Assumptions!C43
B11: B Pref | C11: =Assumptions!C17 | D11: ='Pro-Forma'!H34 | E11: =Assumptions!C42
B12: A Pref | C12: =Assumptions!C16 | D12: ='Pro-Forma'!H33 | E12: =Assumptions!C41
B13: Seed Pref | C13: =Assumptions!C15 | D13: ='Pro-Forma'!H32 | E13: =Assumptions!C40
B15: Always-Convert Constituents
B16: Common + RSAs | D16: ='Pro-Forma'!C6
B17: Notes (A + B combined) | D17: ='Pro-Forma'!J42+'Pro-Forma'!J43
B18: Issued options | C18: =Assumptions!C56 | D18: =Assumptions!C28
B19: Total priced shares (Seed–F) | D19: =SUM(D7:D13)
B20: Constant convert pool (common+notes+options) | D20: =D16+D17+D18
B22: V_k Per Exit (k = top-k OCP classes take preference)
B23: k | C23: cum LP top-k | D23: cum sh top-k | E23: Convert denom | F23: Exit 1 V_k | G23: Exit 2 V_k | H23: Exit 3 V_k | I23: Exit 4 V_k | J23: Exit 5 V_k
B24: k = 0 | C24: 0 | D24: 0 | E24: =D20+D19-D24 | F24: =(Assumptions!C59-C24+D18*C18)/E24 | G24: =(Assumptions!C60-C24+D18*C18)/E24 | H24: =(Assumptions!C61-C24+D18*C18)/E24 | I24: =(Assumptions!C62-C24+D18*C18)/E24 | J24: =(Assumptions!C63-C24+D18*C18)/E24
B25: k = 1 | C25: =C24+E7 | D25: =D24+D7 | E25: =D20+D19-D25 | F25: =(Assumptions!C59-C25+D18*C18)/E25 | G25: =(Assumptions!C60-C25+D18*C18)/E25 | H25: =(Assumptions!C61-C25+D18*C18)/E25 | I25: =(Assumptions!C62-C25+D18*C18)/E25 | J25: =(Assumptions!C63-C25+D18*C18)/E25
B26: k = 2 | C26: =C25+E8 | D26: =D25+D8 | E26: =D20+D19-D26 | F26: =(Assumptions!C59-C26+D18*C18)/E26 | G26: =(Assumptions!C60-C26+D18*C18)/E26 | H26: =(Assumptions!C61-C26+D18*C18)/E26 | I26: =(Assumptions!C62-C26+D18*C18)/E26 | J26: =(Assumptions!C63-C26+D18*C18)/E26
B27: k = 3 | C27: =C26+E9 | D27: =D26+D9 | E27: =D20+D19-D27 | F27: =(Assumptions!C59-C27+D18*C18)/E27 | G27: =(Assumptions!C60-C27+D18*C18)/E27 | H27: =(Assumptions!C61-C27+D18*C18)/E27 | I27: =(Assumptions!C62-C27+D18*C18)/E27 | J27: =(Assumptions!C63-C27+D18*C18)/E27
B28: k = 4 | C28: =C27+E10 | D28: =D27+D10 | E28: =D20+D19-D28 | F28: =(Assumptions!C59-C28+D18*C18)/E28 | G28: =(Assumptions!C60-C28+D18*C18)/E28 | H28: =(Assumptions!C61-C28+D18*C18)/E28 | I28: =(Assumptions!C62-C28+D18*C18)/E28 | J28: =(Assumptions!C63-C28+D18*C18)/E28
B29: k = 5 | C29: =C28+E11 | D29: =D28+D11 | E29: =D20+D19-D29 | F29: =(Assumptions!C59-C29+D18*C18)/E29 | G29: =(Assumptions!C60-C29+D18*C18)/E29 | H29: =(Assumptions!C61-C29+D18*C18)/E29 | I29: =(Assumptions!C62-C29+D18*C18)/E29 | J29: =(Assumptions!C63-C29+D18*C18)/E29
B30: k = 6 | C30: =C29+E12 | D30: =D29+D12 | E30: =D20+D19-D30 | F30: =(Assumptions!C59-C30+D18*C18)/E30 | G30: =(Assumptions!C60-C30+D18*C18)/E30 | H30: =(Assumptions!C61-C30+D18*C18)/E30 | I30: =(Assumptions!C62-C30+D18*C18)/E30 | J30: =(Assumptions!C63-C30+D18*C18)/E30
B31: k = 7 | C31: =C30+E13 | D31: =D30+D13 | E31: =D20+D19-D31 | F31: =(Assumptions!C59-C31+D18*C18)/E31 | G31: =(Assumptions!C60-C31+D18*C18)/E31 | H31: =(Assumptions!C61-C31+D18*C18)/E31 | I31: =(Assumptions!C62-C31+D18*C18)/E31 | J31: =(Assumptions!C63-C31+D18*C18)/E31
B33: Equilibrium V (per common-equiv share) — MIN(V_k)
B34: Exit value | F34: =Assumptions!C59 | G34: =Assumptions!C60 | H34: =Assumptions!C61 | I34: =Assumptions!C62 | J34: =Assumptions!C63
B35: V_final ($/sh) | F35: =MIN(F24:F31) | G35: =MIN(G24:G31) | H35: =MIN(H24:H31) | I35: =MIN(I24:I31) | J35: =MIN(J24:J31)
B37: Elections — IF(OCP_class > V_final, "preference", "convert")
B38: Class | C38: OCP-eff | F38: Exit 1 | G38: Exit 2 | H38: Exit 3 | I38: Exit 4 | J38: Exit 5
B39: D Pref | C39: =C7 | F39: =IF(C39>F$35,"preference","convert") | G39: =IF(C39>G$35,"preference","convert") | H39: =IF(C39>H$35,"preference","convert") | I39: =IF(C39>I$35,"preference","convert") | J39: =IF(C39>J$35,"preference","convert")
B40: E Pref | C40: =C8 | F40: =IF(C40>F$35,"preference","convert") | G40: =IF(C40>G$35,"preference","convert") | H40: =IF(C40>H$35,"preference","convert") | I40: =IF(C40>I$35,"preference","convert") | J40: =IF(C40>J$35,"preference","convert")
B41: F Pref | C41: =C9 | F41: =IF(C41>F$35,"preference","convert") | G41: =IF(C41>G$35,"preference","convert") | H41: =IF(C41>H$35,"preference","convert") | I41: =IF(C41>I$35,"preference","convert") | J41: =IF(C41>J$35,"preference","convert")
B42: C Pref | C42: =C10 | F42: =IF(C42>F$35,"preference","convert") | G42: =IF(C42>G$35,"preference","convert") | H42: =IF(C42>H$35,"preference","convert") | I42: =IF(C42>I$35,"preference","convert") | J42: =IF(C42>J$35,"preference","convert")
B43: B Pref | C43: =C11 | F43: =IF(C43>F$35,"preference","convert") | G43: =IF(C43>G$35,"preference","convert") | H43: =IF(C43>H$35,"preference","convert") | I43: =IF(C43>I$35,"preference","convert") | J43: =IF(C43>J$35,"preference","convert")
B44: A Pref | C44: =C12 | F44: =IF(C44>F$35,"preference","convert") | G44: =IF(C44>G$35,"preference","convert") | H44: =IF(C44>H$35,"preference","convert") | I44: =IF(C44>I$35,"preference","convert") | J44: =IF(C44>J$35,"preference","convert")
B45: Seed Pref | C45: =C13 | F45: =IF(C45>F$35,"preference","convert") | G45: =IF(C45>G$35,"preference","convert") | H45: =IF(C45>H$35,"preference","convert") | I45: =IF(C45>I$35,"preference","convert") | J45: =IF(C45>J$35,"preference","convert")
B47: Proceeds by Class × Exit ($)
...
