Workbook

Sheet Assumptions
B2: Assumptions
B3: Kelvin Dynamics — Series F Round Inputs
B5: Round Terms
B6: Series F pre-money valuation | C6: 1400000000 | D6: USD
B7: Series F primary raise | C7: 30000000 | D7: USD
B8: Series F post-money | C8: =C6+C7 -> 1430000000 | D8: USD
B9: Series F secondary raise (tender) | C9: 15000000 | D9: USD
B10: Tender PPS multiplier | C10: 0.85 | D10: × F PPS
B11: ESOP refresh target (post-F FD) | C11: 0.13 | D11: of T_F
B12: Our fund check size | C12: 10000000 | D12: USD
B13: F_LEAD primary check | C13: 20000000 | D13: USD
B14: Option strike (issued options) | C14: 1 | D14: USD/share
B16: Pre-F Capitalization (carryover from Series E)
B17: Pre-F broad-based FD (A in WA AD formula) | C17: 36617961 | D17: shares
B18: Pre-F options issued | C18: 2500000 | D18: shares
B19: Pre-F options unissued (existing pool) | C19: 1894667 | D19: shares
B20: Pre-F existing option pool (issued + unissued) | C20: =C18+C19 -> 4394667 | D20: shares
B22: Common Stock Holdings
B23: Founder F1 (CEO) common | C23: 4000000 | D23: shares
B24: Founder F2 (CTO) common | C24: 2500000 | D24: shares
B25: Founder F3 (Chief Sci) common | C25: 1500000 | D25: shares
B26: Founders subtotal | C26: =SUM(C23:C25) -> 8000000 | D26: shares
B27: Employee RSAs (E1-E10, 100k each) | C27: 1000000 | D27: shares
B28: Total common + RSAs | C28: =C26+C27 -> 9000000 | D28: shares
B30: Prior Round OCPs (for Anti-Dilution)
B31: Seed OCP | C31: 1 | D31: USD/sh
B32: Series A OCP | C32: 3 | D32: USD/sh
B33: Series B OCP | C33: 10 | D33: USD/sh
B34: Series C OCP | C34: 25 | D34: USD/sh
B35: Series D OCP (compound v3·v4 = post-E NCP) | C35: 58.118347 | D35: USD/sh
B36: Series D original PPS (issued at) | C36: 60 | D36: USD/sh
B37: Series E OCP / PPS | C37: 49.158311 | D37: USD/sh
B39: Prior Round Shares Outstanding
B40: Seed shares | C40: 5000000 | D40: shares
B41: Series A shares | C41: 5000000 | D41: shares
B42: Series B shares | C42: 3000000 | D42: shares
B43: Series C shares | C43: 2400000 | D43: shares
B44: Series D shares (originally issued at $60) | C44: 1666667 | D44: shares
B45: Series E shares | C45: 6102667 | D45: shares
B47: Invested USD per Class
...

Sheet Pro-Forma
B2: Pro-Forma Cap Table
B3: Series F closing — fully-diluted ownership
B5: Round Solve (Fixed Point)
B6: Series F pre-money | C6: =Assumptions!C6 -> 1400000000
B7: Series F primary raise | C7: =Assumptions!C7 -> 30000000
B8: Series F post-money | C8: =C6+C7 -> 1430000000
B9: ESOP target % of post-F FD | C9: =Assumptions!C11 -> 0.13
B10: Pre-F broad-based FD (A in WA AD) | C10: =Assumptions!C17 -> 36617961
B11: Existing option pool (issued + unissued) | C11: =Assumptions!C20 -> 4394667
B12: Common + RSAs | C12: =Assumptions!C28 -> 9000000
B14: Series E AD Coefficients
B15: OCP_E | C15: =Assumptions!C37 -> 49.158311
B16: α_E (E shares constant) | C16: =Assumptions!C45*C15*C10/(C15*C10+C7) -> 6002627.5
B17: β_E (E shares × p) | C17: =Assumptions!C45*C15*C7/(C15*C10+C7) -> 4917773.1
B19: Series D AD Coefficients
B20: OCP_D (compound v3·v4 = post-E NCP) | C20: =Assumptions!C35 -> 58.118347
B21: Original D PPS | C21: =Assumptions!C36 -> 60
B22: α_D | C22: =Assumptions!C44*C21*C10/(C20*C10+C7) -> 1696709.6
B23: β_D | C23: =Assumptions!C44*C21*C7/(C20*C10+C7) -> 1390063.4
B25: Note A Branch Determination
B26: Note A principal | C26: =Assumptions!C56 -> 5000000
B27: Note A cap | C27: =Assumptions!C57 -> 1000000000
B28: Note A discount | C28: =Assumptions!C58 -> 0.2
B29: Cap branch wins iff pre > threshold | C29: =(C27+C26)/(1-C28) -> 1256250000
B30: Note A branch | C30: =IF(C6>C29,"cap","discount") -> cap
B31: β_NA (NA shares × p) | C31: =IF(C30="cap",C26*C6/(C27+C26),C26/(1-C28)) -> 6965174.1
B33: Note B Branch Determination
B34: Note B principal | C34: =Assumptions!C59 -> 3000000
B35: Note B cap | C35: =Assumptions!C60 -> 1600000000
B36: Note B discount | C36: =Assumptions!C61 -> 0.15
B37: Cap branch wins iff pre > threshold | C37: =(C35+C34)/(1-C36) -> 1.8858824e+09
B38: Note B branch | C38: =IF(C6>C37,"cap","discount") -> discount
B39: β_NB | C39: =IF(C38="cap",C34*C6/(C35+C34),C34/(1-C36)) -> 3529411.8
B41: Closed-Form Solve
B42: Pre-F constant shares (Common+Seed+A+B+C) | C42: =C12+Assumptions!C40+Assumptions!C41+Assumptions!C42+Assumptions!C43 -> 24400000
B43: M = constants + α_E + α_D | C43: =C42+C16+C22 -> 32099337
B44: K = (1-esop)·post − raise − β_E − β_D − β_NA − β_NB | C44: =(1-C9)*C8-C7-C17-C23-C31-C39 -> 1.1972976e+09
B45: F_PPS = K / M (top-up triggered branch) | C45: =C44/C43 -> 37.29976
B46: T_F = post / F_PPS | C46: =C8/C45 -> 38338048
B47: ESOP top-up triggered? (0.13·T_F > 4.39M) | C47: =IF(C9*C46>C11,"Yes","No") -> Yes
...

Sheet Return-Solver
B2: Return Solver
B3: Required Series F ownership for 3× / 4× return on our $10M check
B5: Inputs (Base Case)
B6: Our fund check | C6: =Assumptions!C12 -> 10000000
B7: Series F primary raise (total) | C7: =Assumptions!C7 -> 30000000
B8: Target multiple 3× | C8: =Assumptions!C75 -> 3
B9: Target multiple 4× | C9: =Assumptions!C76 -> 4
B10: 3× target proceeds | C10: =C6*C8 -> 30000000
B11: 4× target proceeds | C11: =C6*C9 -> 40000000
B12: Post-F T_F (base case) | C12: ='Pro-Forma'!C50 -> 38338048
B13: Post-money (base) | C13: ='Pro-Forma'!C8 -> 1430000000
B14: Per-Exit Required Ownership
B15: Exit Scenario | C15: Exit Value | D15: F Election (base) | E15: PPS at Exit | F15: Req % for 3× ($30M) | G15: Req % for 4× ($40M) | H15: Feasibility Flag
B16: Exit 1 | C16: =Assumptions!C64 -> 700000000 | D16: ='Waterfall'!D43 -> preference | E16: ='Waterfall'!C44 -> 8.3787246 | F16: =IF(D16="convert",$C$10/(E16*$C$12),$C$10/$C$13) -> 0.020979021 | G16: =IF(D16="convert",$C$11/(E16*$C$12),$C$11/$C$13) -> 0.027972028 | H16: =IF(OR(F16<=0,F16>1,G16<=0,G16>1),"INFEASIBLE","feasible") -> feasible
B17: Exit 2 | C17: =Assumptions!C65 -> 1200000000 | D17: ='Waterfall'!D58 -> preference | E17: ='Waterfall'!C59 -> 28.420214 | F17: =IF(D17="convert",$C$10/(E17*$C$12),$C$10/$C$13) -> 0.020979021 | G17: =IF(D17="convert",$C$11/(E17*$C$12),$C$11/$C$13) -> 0.027972028 | H17: =IF(OR(F17<=0,F17>1,G17<=0,G17>1),"INFEASIBLE","feasible") -> feasible
B18: Exit 3 | C18: =Assumptions!C66 -> 2000000000 | D18: ='Waterfall'!D73 -> convert | E18: ='Waterfall'!C74 -> 55.758882 | F18: =IF(D18="convert",$C$10/(E18*$C$12),$C$10/$C$13) -> 0.014033862 | G18: =IF(D18="convert",$C$11/(E18*$C$12),$C$11/$C$13) -> 0.018711816 | H18: =IF(OR(F18<=0,F18>1,G18<=0,G18>1),"INFEASIBLE","feasible") -> feasible
B19: Exit 4 | C19: =Assumptions!C67 -> 4000000000 | D19: ='Waterfall'!D88 -> convert | E19: ='Waterfall'!C89 -> 111.63297 | F19: =IF(D19="convert",$C$10/(E19*$C$12),$C$10/$C$13) -> 0.0070096892 | G19: =IF(D19="convert",$C$11/(E19*$C$12),$C$11/$C$13) -> 0.0093462523 | H19: =IF(OR(F19<=0,F19>1,G19<=0,G19>1),"INFEASIBLE","feasible") -> feasible
B20: Exit 5 | C20: =Assumptions!C68 -> 8000000000 | D20: ='Waterfall'!D103 -> convert | E20: ='Waterfall'!C104 -> 223.19622 | F20: =IF(D20="convert",$C$10/(E20*$C$12),$C$10/$C$13) -> 0.0035059395 | G20: =IF(D20="convert",$C$11/(E20*$C$12),$C$11/$C$13) -> 0.004674586 | H20: =IF(OR(F20<=0,F20>1,G20<=0,G20>1),"INFEASIBLE","feasible") -> feasible
B22: Notes
B23: If F takes preference at an exit, max F-class proceeds = $30M total
B24: regardless of ownership %; 4× target requires $40M, infeasible by definition
B25: When F converts, required ownership scales as target / (PPS × T_F)

Sheet Sensitivity
B2: Sensitivity Analysis
B3: Our $10M check — ownership % and $ proceeds at $2B exit
B5: Global Constants (independent of cell)
B6: Pre-F broad-based FD (A in WA AD) | C6: =Assumptions!C17 -> 36617961
B7: Series F primary raise | C7: =Assumptions!C7 -> 30000000
B8: OCP_E | C8: =Assumptions!C37 -> 49.158311
B9: OCP_D | C9: =Assumptions!C35 -> 58.118347
B10: Original D PPS | C10: =Assumptions!C36 -> 60
B11: α_E (constant) | C11: =Assumptions!C45*C8*C6/(C8*C6+C7) -> 6002627.5
B12: β_E (constant) | C12: =Assumptions!C45*C8*C7/(C8*C6+C7) -> 4917773.1
B13: α_D (constant) | C13: =Assumptions!C44*C10*C6/(C9*C6+C7) -> 1696709.6
B14: β_D (constant) | C14: =Assumptions!C44*C10*C7/(C9*C6+C7) -> 1390063.4
B15: M (constant pre-F shares) | C15: =Assumptions!C28+Assumptions!C40+Assumptions!C41+Assumptions!C42+Assumptions!C43+C11+C13 -> 32099337
B16: Common (9M + RSAs) | C16: =Assumptions!C28 -> 9000000
B17: Options issued | C17: =Assumptions!C18 -> 2500000
B18: Option strike | C18: =Assumptions!C14 -> 1
B19: Existing option pool | C19: =Assumptions!C20 -> 4394667
B20: Note A principal / cap / disc | C20: =Assumptions!C56 -> 5000000 | D20: =Assumptions!C57 -> 1000000000 | E20: =Assumptions!C58 -> 0.2
B21: Note B principal / cap / disc | C21: =Assumptions!C59 -> 3000000 | D21: =Assumptions!C60 -> 1600000000 | E21: =Assumptions!C61 -> 0.15
B22: Cap branch threshold (NA, NB) | C22: =(D20+C20)/(1-E20) -> 1256250000 | D22: =(D21+C21)/(1-E21) -> 1.8858824e+09
B23: $2B exit target | C23: =Assumptions!C66 -> 2000000000
B24: Our fund check | C24: =Assumptions!C12 -> 10000000
B28: Cell (11%, $1.2B)
B29: Pre-money | C29: =Assumptions!C72 -> 1200000000
B30: ESOP refresh | C30: =Assumptions!C71 -> 0.11
B31: Post-money | C31: =C29+$C$7 -> 1230000000
B32: Note A branch / β_NA | C32: =IF(C29>$C$22,"cap","discount") -> discount | D32: =IF(C32="cap",$C$20*C29/($D$20+$C$20),$C$20/(1-$E$20)) -> 6250000
B33: Note B branch / β_NB | C33: =IF(C29>$D$22,"cap","discount") -> discount | D33: =IF(C33="cap",$C$21*C29/($D$21+$C$21),$C$21/(1-$E$21)) -> 3529411.8
B34: K | C34: =(1-C30)*C31-$C$7-$C$12-$C$14-D32-D33 -> 1.0486128e+09
B35: F_PPS | C35: =C34/$C$15 -> 32.667739
B36: T_F | C36: =C31/C35 -> 37651826
B37: F_pri shares | C37: =$C$7/C35 -> 918337.21
B38: E_sh (with AD) | C38: =$C$11+$C$12/C35 -> 6153166.6
B39: D_sh (with AD) | C39: =$C$13+$C$14/C35 -> 1739261.2
B40: NA_sh / NB_sh | C40: =D32/C35 -> 191320.25 | D40: =D33/C35 -> 108039.67
B41: Opts (max) | C41: =MAX($C$19,C30*C36) -> 4394667
B42: Common-eq base (common+opts+notes) | C42: =$C$16+$C$17+C40+D40 -> 11799360
B43: $2B Waterfall — Iteration
B44: Class → | D44: F | E44: E | F44: D | G44: C | H44: B | I44: A | J44: Seed | K44: ΣPref | L44: ΣConvN
B45: S (pref $) | D45: =$C$7 | E45: =Assumptions!C53 -> 300000000 | F45: =Assumptions!C52 -> 100000000 | G45: =Assumptions!C51 -> 60000000 | H45: =Assumptions!C50 -> 30000000 | I45: =Assumptions!C49 -> 15000000 | J45: =Assumptions!C48 -> 5000000
...

Sheet Waterfall
B2: Waterfall Analysis
B3: Per-class elections (Nash equilibrium) and payoffs at five exits
B5: Class Constants
B6: Class | C6: Pref ($) | D6: As-Conv Shares
B7: Series F | C7: ='Pro-Forma'!C7 -> 30000000 | D7: ='Pro-Forma'!C7/'Pro-Forma'!C49 -> 804294.71
B8: Series E | C8: =Assumptions!C53 -> 300000000 | D8: ='Pro-Forma'!G59 -> 6134472.1
B9: Series D | C9: =Assumptions!C52 -> 100000000 | D9: ='Pro-Forma'!G58 -> 1733976.9
B10: Series C | C10: =Assumptions!C51 -> 60000000 | D10: ='Pro-Forma'!G57 -> 2400000
B11: Series B | C11: =Assumptions!C50 -> 30000000 | D11: ='Pro-Forma'!G56 -> 3000000
B12: Series A | C12: =Assumptions!C49 -> 15000000 | D12: ='Pro-Forma'!G55 -> 5000000
B13: Seed | C13: =Assumptions!C48 -> 5000000 | D13: ='Pro-Forma'!G54 -> 5000000
B15: Common + RSAs | D15: =Assumptions!C28 -> 9000000
B16: Notes (A + B common-eq post-conv) | D16: ='Pro-Forma'!G63+'Pro-Forma'!G64 -> 281358
B17: Options issued (ITM at exit) | D17: =Assumptions!C18 -> 2500000
B18: Option strike | C18: =Assumptions!C14 -> 1
B19: Common-equivalent base (always in pool) | D19: =D15+D16+D17 -> 11781358
B21: Exit Scenarios ($)
B22: Exit value | D22: =Assumptions!C64 -> 700000000 | E22: =Assumptions!C65 -> 1200000000 | F22: =Assumptions!C66 -> 2000000000 | G22: =Assumptions!C67 -> 4000000000 | H22: =Assumptions!C68 -> 8000000000
B23: Effective exit (+ options strike cash) | D23: =D22+$D$17*$C$18 -> 702500000 | E23: =E22+$D$17*$C$18 -> 1202500000 | F23: =F22+$D$17*$C$18 -> 2002500000 | G23: =G22+$D$17*$C$18 -> 4002500000 | H23: =H22+$D$17*$C$18 -> 8002500000
B25: Election Decisions (Nash Equilibrium) — 35 cells
B26: Class | D26: $700M | E26: $1.2B | F26: $2.0B | G26: $4.0B | H26: $8.0B
B27: Series F | D27: =D43 -> preference | E27: =D58 -> preference | F27: =D73 -> convert | G27: =D88 -> convert | H27: =D103 -> convert
B28: Series E | D28: =E43 -> preference | E28: =E58 -> preference | F28: =E73 -> convert | G28: =E88 -> convert | H28: =E103 -> convert
B29: Series D | D29: =F43 -> preference | E29: =F58 -> preference | F29: =F73 -> preference | G29: =F88 -> convert | H29: =F103 -> convert
B30: Series C | D30: =G43 -> preference | E30: =G58 -> convert | F30: =G73 -> convert | G30: =G88 -> convert | H30: =G103 -> convert
B31: Series B | D31: =H43 -> preference | E31: =H58 -> convert | F31: =H73 -> convert | G31: =H88 -> convert | H31: =H103 -> convert
B32: Series A | D32: =I43 -> convert | E32: =I58 -> convert | F32: =I73 -> convert | G32: =I88 -> convert | H32: =I103 -> convert
B33: Seed | D33: =J43 -> convert | E33: =J58 -> convert | F33: =J73 -> convert | G33: =J88 -> convert | H33: =J103 -> convert
B36: Exit 1: $700M — Iteration & Payoffs
B37: Iter / Class | D37: F | E37: E | F37: D | G37: C | H37: B | I37: A | J37: Seed | K37: ΣPref | L37: ΣConvN
B38: Iter 0 (init) | D38: convert | E38: convert | F38: convert | G38: convert | H38: convert | I38: convert | J38: convert | K38: =IF(D38="preference",$C$7,0)+IF(E38="preference",$C$8,0)+IF(F38="preference",$C$9,0)+IF(G38="preference",$C$10,0)+IF(H38="preference",$C$11,0)+IF(I38="preference",$C$12,0)+IF(J38="preference",$C$13,0) -> 0 | L38: =IF(D38="convert",$D$7,0)+IF(E38="convert",$D$8,0)+IF(F38="convert",$D$9,0)+IF(G38="convert",$D$10,0)+IF(H38="convert",$D$11,0)+IF(I38="convert",$D$12,0)+IF(J38="convert",$D$13,0) -> 24072744
B39: Iter 1 | D39: =IF($C$7>((D$23-(K38-IF(D38="preference",$C$7,0)))/($D$19+(L38-IF(D38="convert",$D$7,0))+$D$7)*$D$7),"preference","convert") -> preference | E39: =IF($C$8>((D$23-(K38-IF(E38="preference",$C$8,0)))/($D$19+(L38-IF(E38="convert",$D$8,0))+$D$8)*$D$8),"preference","convert") -> preference | F39: =IF($C$9>((D$23-(K38-IF(F38="preference",$C$9,0)))/($D$19+(L38-IF(F38="convert",$D$9,0))+$D$9)*$D$9),"preference","convert") -> preference | G39: =IF($C$10>((D$23-(K38-IF(G38="preference",$C$10,0)))/($D$19+(L38-IF(G38="convert",$D$10,0))+$D$10)*$D$10),"preference","convert") -> preference | H39: =IF($C$11>((D$23-(K38-IF(H38="preference",$C$11,0)))/($D$19+(L38-IF(H38="convert",$D$11,0))+$D$11)*$D$11),"preference","convert") -> convert | I39: =IF($C$12>((D$23-(K38-IF(I38="preference",$C$12,0)))/($D$19+(L38-IF(I38="convert",$D$12,0))+$D$12)*$D$12),"preference","convert") -> convert | J39: =IF($C$13>((D$23-(K38-IF(J38="preference",$C$13,0)))/($D$19+(L38-IF(J38="convert",$D$13,0))+$D$13)*$D$13),"preference","convert") -> convert | K39: =IF(D39="preference",$C$7,0)+IF(E39="preference",$C$8,0)+IF(F39="preference",$C$9,0)+IF(G39="preference",$C$10,0)+IF(H39="preference",$C$11,0)+IF(I39="preference",$C$12,0)+IF(J39="preference",$C$13,0) -> 490000000 | L39: =IF(D39="convert",$D$7,0)+IF(E39="convert",$D$8,0)+IF(F39="convert",$D$9,0)+IF(G39="convert",$D$10,0)+IF(H39="convert",$D$11,0)+IF(I39="convert",$D$12,0)+IF(J39="convert",$D$13,0) -> 13000000
B40: Iter 2 | D40: =IF($C$7>((D$23-(K39-IF(D39="preference",$C$7,0)))/($D$19+(L39-IF(D39="convert",$D$7,0))+$D$7)*$D$7),"preference","convert") -> preference | E40: =IF($C$8>((D$23-(K39-IF(E39="preference",$C$8,0)))/($D$19+(L39-IF(E39="convert",$D$8,0))+$D$8)*$D$8),"preference","convert") -> preference | F40: =IF($C$9>((D$23-(K39-IF(F39="preference",$C$9,0)))/($D$19+(L39-IF(F39="convert",$D$9,0))+$D$9)*$D$9),"preference","convert") -> preference | G40: =IF($C$10>((D$23-(K39-IF(G39="preference",$C$10,0)))/($D$19+(L39-IF(G39="convert",$D$10,0))+$D$10)*$D$10),"preference","convert") -> preference | H40: =IF($C$11>((D$23-(K39-IF(H39="preference",$C$11,0)))/($D$19+(L39-IF(H39="convert",$D$11,0))+$D$11)*$D$11),"preference","convert") -> preference | I40: =IF($C$12>((D$23-(K39-IF(I39="preference",$C$12,0)))/($D$19+(L39-IF(I39="convert",$D$12,0))+$D$12)*$D$12),"preference","convert") -> convert | J40: =IF($C$13>((D$23-(K39-IF(J39="preference",$C$13,0)))/($D$19+(L39-IF(J39="convert",$D$13,0))+$D$13)*$D$13),"preference","convert") -> convert | K40: =IF(D40="preference",$C$7,0)+IF(E40="preference",$C$8,0)+IF(F40="preference",$C$9,0)+IF(G40="preference",$C$10,0)+IF(H40="preference",$C$11,0)+IF(I40="preference",$C$12,0)+IF(J40="preference",$C$13,0) -> 520000000 | L40: =IF(D40="convert",$D$7,0)+IF(E40="convert",$D$8,0)+IF(F40="convert",$D$9,0)+IF(G40="convert",$D$10,0)+IF(H40="convert",$D$11,0)+IF(I40="convert",$D$12,0)+IF(J40="convert",$D$13,0) -> 10000000
B41: Iter 3 | D41: =IF($C$7>((D$23-(K40-IF(D40="preference",$C$7,0)))/($D$19+(L40-IF(D40="convert",$D$7,0))+$D$7)*$D$7),"preference","convert") -> preference | E41: =IF($C$8>((D$23-(K40-IF(E40="preference",$C$8,0)))/($D$19+(L40-IF(E40="convert",$D$8,0))+$D$8)*$D$8),"preference","convert") -> preference | F41: =IF($C$9>((D$23-(K40-IF(F40="preference",$C$9,0)))/($D$19+(L40-IF(F40="convert",$D$9,0))+$D$9)*$D$9),"preference","convert") -> preference | G41: =IF($C$10>((D$23-(K40-IF(G40="preference",$C$10,0)))/($D$19+(L40-IF(G40="convert",$D$10,0))+$D$10)*$D$10),"preference","convert") -> preference | H41: =IF($C$11>((D$23-(K40-IF(H40="preference",$C$11,0)))/($D$19+(L40-IF(H40="convert",$D$11,0))+$D$11)*$D$11),"preference","convert") -> preference | I41: =IF($C$12>((D$23-(K40-IF(I40="preference",$C$12,0)))/($D$19+(L40-IF(I40="convert",$D$12,0))+$D$12)*$D$12),"preference","convert") -> convert | J41: =IF($C$13>((D$23-(K40-IF(J40="preference",$C$13,0)))/($D$19+(L40-IF(J40="convert",$D$13,0))+$D$13)*$D$13),"preference","convert") -> convert | K41: =IF(D41="preference",$C$7,0)+IF(E41="preference",$C$8,0)+IF(F41="preference",$C$9,0)+IF(G41="preference",$C$10,0)+IF(H41="preference",$C$11,0)+IF(I41="preference",$C$12,0)+IF(J41="preference",$C$13,0) -> 520000000 | L41: =IF(D41="convert",$D$7,0)+IF(E41="convert",$D$8,0)+IF(F41="convert",$D$9,0)+IF(G41="convert",$D$10,0)+IF(H41="convert",$D$11,0)+IF(I41="convert",$D$12,0)+IF(J41="convert",$D$13,0) -> 10000000
B42: Iter 4 | D42: =IF($C$7>((D$23-(K41-IF(D41="preference",$C$7,0)))/($D$19+(L41-IF(D41="convert",$D$7,0))+$D$7)*$D$7),"preference","convert") -> preference | E42: =IF($C$8>((D$23-(K41-IF(E41="preference",$C$8,0)))/($D$19+(L41-IF(E41="convert",$D$8,0))+$D$8)*$D$8),"preference","convert") -> preference | F42: =IF($C$9>((D$23-(K41-IF(F41="preference",$C$9,0)))/($D$19+(L41-IF(F41="convert",$D$9,0))+$D$9)*$D$9),"preference","convert") -> preference | G42: =IF($C$10>((D$23-(K41-IF(G41="preference",$C$10,0)))/($D$19+(L41-IF(G41="convert",$D$10,0))+$D$10)*$D$10),"preference","convert") -> preference | H42: =IF($C$11>((D$23-(K41-IF(H41="preference",$C$11,0)))/($D$19+(L41-IF(H41="convert",$D$11,0))+$D$11)*$D$11),"preference","convert") -> preference | I42: =IF($C$12>((D$23-(K41-IF(I41="preference",$C$12,0)))/($D$19+(L41-IF(I41="convert",$D$12,0))+$D$12)*$D$12),"preference","convert") -> convert | J42: =IF($C$13>((D$23-(K41-IF(J41="preference",$C$13,0)))/($D$19+(L41-IF(J41="convert",$D$13,0))+$D$13)*$D$13),"preference","convert") -> convert | K42: =IF(D42="preference",$C$7,0)+IF(E42="preference",$C$8,0)+IF(F42="preference",$C$9,0)+IF(G42="preference",$C$10,0)+IF(H42="preference",$C$11,0)+IF(I42="preference",$C$12,0)+IF(J42="preference",$C$13,0) -> 520000000 | L42: =IF(D42="convert",$D$7,0)+IF(E42="convert",$D$8,0)+IF(F42="convert",$D$9,0)+IF(G42="convert",$D$10,0)+IF(H42="convert",$D$11,0)+IF(I42="convert",$D$12,0)+IF(J42="convert",$D$13,0) -> 10000000
B43: Iter 5 | D43: =IF($C$7>((D$23-(K42-IF(D42="preference",$C$7,0)))/($D$19+(L42-IF(D42="convert",$D$7,0))+$D$7)*$D$7),"preference","convert") -> preference | E43: =IF($C$8>((D$23-(K42-IF(E42="preference",$C$8,0)))/($D$19+(L42-IF(E42="convert",$D$8,0))+$D$8)*$D$8),"preference","convert") -> preference | F43: =IF($C$9>((D$23-(K42-IF(F42="preference",$C$9,0)))/($D$19+(L42-IF(F42="convert",$D$9,0))+$D$9)*$D$9),"preference","convert") -> preference | G43: =IF($C$10>((D$23-(K42-IF(G42="preference",$C$10,0)))/($D$19+(L42-IF(G42="convert",$D$10,0))+$D$10)*$D$10),"preference","convert") -> preference | H43: =IF($C$11>((D$23-(K42-IF(H42="preference",$C$11,0)))/($D$19+(L42-IF(H42="convert",$D$11,0))+$D$11)*$D$11),"preference","convert") -> preference | I43: =IF($C$12>((D$23-(K42-IF(I42="preference",$C$12,0)))/($D$19+(L42-IF(I42="convert",$D$12,0))+$D$12)*$D$12),"preference","convert") -> convert | J43: =IF($C$13>((D$23-(K42-IF(J42="preference",$C$13,0)))/($D$19+(L42-IF(J42="convert",$D$13,0))+$D$13)*$D$13),"preference","convert") -> convert | K43: =IF(D43="preference",$C$7,0)+IF(E43="preference",$C$8,0)+IF(F43="preference",$C$9,0)+IF(G43="preference",$C$10,0)+IF(H43="preference",$C$11,0)+IF(I43="preference",$C$12,0)+IF(J43="preference",$C$13,0) -> 520000000 | L43: =IF(D43="convert",$D$7,0)+IF(E43="convert",$D$8,0)+IF(F43="convert",$D$9,0)+IF(G43="convert",$D$10,0)+IF(H43="convert",$D$11,0)+IF(I43="convert",$D$12,0)+IF(J43="convert",$D$13,0) -> 10000000
B44: PPS (post conversions) | C44: =(D$23-K43)/($D$19+L43) -> 8.3787246
B45: Class payoff ($) | D45: =IF(D43="preference",$C$7,$C$44*$D$7) -> 30000000 | E45: =IF(E43="preference",$C$8,$C$44*$D$8) -> 300000000 | F45: =IF(F43="preference",$C$9,$C$44*$D$9) -> 100000000 | G45: =IF(G43="preference",$C$10,$C$44*$D$10) -> 60000000 | H45: =IF(H43="preference",$C$11,$C$44*$D$11) -> 30000000 | I45: =IF(I43="preference",$C$12,$C$44*$D$12) -> 41893623 | J45: =IF(J43="preference",$C$13,$C$44*$D$13) -> 41893623
B46: Common + RSA payoff | C46: =$C$44*$D$15 -> 75408521
B47: Notes (A+B common-eq) payoff | C47: =$C$44*$D$16 -> 2357421.2
...
