Workbook

Sheet Assumptions
B2: Kelvin Dynamics — Series F Analysis
B3: $ in actuals; shares in actuals
B5: Round Terms
B6: Series F pre-money | C6: 1400000000 | D6: series_f_pre_money_usd
B7: Series F primary raise | C7: 30000000 | D7: series_f_primary_raise_usd
B8: Series F secondary raise | C8: 15000000 | D8: series_f_secondary_raise_usd
B9: Tender PPS multiplier | C9: 0.85 | D9: series_f_tender_pps_multiplier
B10: ESOP refresh target (% post-F FD) | C10: 0.13 | D10: esop_refresh_target_post_f
B11: Our fund check | C11: 10000000 | D11: our_fund_check_usd
B12: F_LEAD primary check | C12: 20000000 | D12: f_lead_primary_check_usd
B13: Option strike price | C13: 1 | D13: option_strike_usd
B15: Existing Equity (pre-F)
B16: Pre-F fully-diluted shares | C16: 36617961 | D16: pre_f_fd_total — also AD denominator A
B17: Pre-F options issued | C17: 2500000
B18: Pre-F options unissued | C18: 1894667
B19: Pre-F option pool total | C19: =C17+C18 -> 4394667
B21: Founders & RSAs
B22: F1 — Founder (CEO) common | C22: 4000000
B23: F2 — Founder (CTO) common | C23: 2500000
B24: F3 — Chief Scientist common | C24: 1500000
B25: Employee RSAs (E1–E10) | C25: 1000000
B26: Founder split: F1 share | C26: =C22/(C22+C23+C24) -> 0.5
B27: Founder split: F2 share | C27: =C23/(C22+C23+C24) -> 0.3125
B28: Founder split: F3 share | C28: =C24/(C22+C23+C24) -> 0.1875
B30: Prior-Round Pricing
B31: Class | C31: OCP for AD | D31: PPS issued | E31: Shares (current) | F31: Invested (USD)
B32: Seed | C32: 1 | D32: 1 | E32: 5000000 | F32: 5000000
B33: Series A | C33: 3 | D33: 3 | E33: 5000000 | F33: 15000000
B34: Series B | C34: 10 | D34: 10 | E34: 3000000 | F34: 30000000
B35: Series C | C35: 25 | D35: 25 | E35: 2400000 | F35: 60000000
B36: Series D | C36: 58.118347 | D36: 60 | E36: 1720627 | F36: 100000000
B37: Series E | C37: 49.158311 | D37: 49.158311 | E37: 6102667 | F37: 300000000
B39: Series D original issuance | C39: 1666667 | D39: orig D shares (ratio anchor)
B40: Series D original OCP | C40: 60 | D40: orig D OCP for compound ratio
B42: Convertible Notes
B43: Note | C43: Principal | D43: Cap | E43: Discount | F43: Interest
B44: Note A | C44: 5000000 | D44: 1000000000 | E44: 0.2 | F44: 0
B45: Note B | C45: 3000000 | D45: 1600000000 | E45: 0.15 | F45: 0
B47: Exit Scenarios
B48: Exit 1 | C48: 700000000
...

Sheet Pro-Forma
B2: Pro-Forma Cap Table — Post Series F
B3: Round mechanics + AD + notes + tender + cap table
B5: Round Mechanics
B6: Pre-F FD (N) | C6: =Assumptions!C16 -> 36617961
B7: ESOP target (R) | C7: =Assumptions!C10 -> 0.13
B8: Existing pool (P_existing) | C8: =Assumptions!C19 -> 4394667
B9: α = primary / pre-money | C9: =Assumptions!C7/Assumptions!C6 -> 0.021428571
B10: R(1+α) | C10: =C7*(1+C9) -> 0.13278571
B11: ESOP top-up (closed-form) | C11: =MAX(0, (C10*C6 - C8) / (1 - C10)) -> 539284.37
B12: Pre-money FD (= N + ESOP top-up) | C12: =C6+C11 -> 37157245
B13: Series F PPS | C13: =Assumptions!C6/C12 -> 37.677712
B14: Series F new shares (primary) | C14: =Assumptions!C7/C13 -> 796226.69
B15: F_LEAD primary shares | C15: =Assumptions!C12/C13 -> 530817.79
B16: Our fund primary shares | C16: =Assumptions!C11/C13 -> 265408.9
B17: Tender PPS (= 0.85 × F PPS) | C17: =Assumptions!C9*C13 -> 32.026055
B18: Tender shares (= secondary / tender PPS) | C18: =Assumptions!C8/C17 -> 468368.64
B20: Anti-Dilution Block (Broad-Based WA)
B21: Class | C21: OCP for AD | D21: Triggered? (F_PPS < OCP) | E21: NCP | F21: New ratio (compound) | G21: As-converted shares | H21: Shares delta
B22: Seed | C22: =Assumptions!C32 -> 1 | D22: =IF(C13<C22,"Yes","No") -> No | E22: =IF(C13<C22, C22*(Assumptions!C16 + Assumptions!C7/C22)/(Assumptions!C16 + Assumptions!C7/C13), C22) -> 1 | F22: =C22/E22 -> 1 | G22: =Assumptions!E32*F22 -> 5000000 | H22: =G22 - Assumptions!E32 -> 0
B23: Series A | C23: =Assumptions!C33 -> 3 | D23: =IF(C13<C23,"Yes","No") -> No | E23: =IF(C13<C23, C23*(Assumptions!C16 + Assumptions!C7/C23)/(Assumptions!C16 + Assumptions!C7/C13), C23) -> 3 | F23: =C23/E23 -> 1 | G23: =Assumptions!E33*F23 -> 5000000 | H23: =G23 - Assumptions!E33 -> 0
B24: Series B | C24: =Assumptions!C34 -> 10 | D24: =IF(C13<C24,"Yes","No") -> No | E24: =IF(C13<C24, C24*(Assumptions!C16 + Assumptions!C7/C24)/(Assumptions!C16 + Assumptions!C7/C13), C24) -> 10 | F24: =C24/E24 -> 1 | G24: =Assumptions!E34*F24 -> 3000000 | H24: =G24 - Assumptions!E34 -> 0
B25: Series C | C25: =Assumptions!C35 -> 25 | D25: =IF(C13<C25,"Yes","No") -> No | E25: =IF(C13<C25, C25*(Assumptions!C16 + Assumptions!C7/C25)/(Assumptions!C16 + Assumptions!C7/C13), C25) -> 25 | F25: =C25/E25 -> 1 | G25: =Assumptions!E35*F25 -> 2400000 | H25: =G25 - Assumptions!E35 -> 0
B26: Series D | C26: =Assumptions!C36 -> 58.118347 | D26: =IF(C13<C26,"Yes","No") -> Yes | E26: =IF(C13<C26, C26*(Assumptions!C16 + Assumptions!C7/C26)/(Assumptions!C16 + Assumptions!C7/C13), C26) -> 57.683341 | F26: =Assumptions!C40/E26 -> 1.0401617 | G26: =Assumptions!C39*F26 -> 1733603.1 | H26: =G26 - Assumptions!E36 -> 12976.107
B27: Series E | C27: =Assumptions!C37 -> 49.158311 | D27: =IF(C13<C27,"Yes","No") -> Yes | E27: =IF(C13<C27, C27*(Assumptions!C16 + Assumptions!C7/C27)/(Assumptions!C16 + Assumptions!C7/C13), C27) -> 48.913988 | F27: =C27/E27 -> 1.004995 | G27: =Assumptions!E37*F27 -> 6133149.6 | H27: =G27 - Assumptions!E37 -> 30482.568
B28: Total AD top-up shares | H28: =SUM(H22:H27) -> 43458.675
B30: Convertible Notes Block
B31: Note | C31: Cap-implied PPS | D31: Discount-implied PPS | E31: Conversion PPS | F31: Branch | G31: Shares issued | K31: Helper | L31: Disc shares only
B32: Note A | C32: =Assumptions!D44/(C12 + H28 + L33) -> 26.813693 | D32: =(1-Assumptions!E44)*C13 -> 30.14217 | E32: =MIN(C32, D32) -> 26.813693 | F32: =IF(C32<D32,"cap","discount") -> cap | G32: =Assumptions!C44/E32 -> 186471.89 | K32: Note A | L32: =Assumptions!C44/((1-Assumptions!E44)*C13) -> 165880.56
B33: Note B | C33: =Assumptions!D45/(C12 + H28 + L32) -> 42.819006 | D33: =(1-Assumptions!E45)*C13 -> 32.026055 | E33: =MIN(C33, D33) -> 32.026055 | F33: =IF(C33<D33,"cap","discount") -> discount | G33: =Assumptions!C45/E33 -> 93673.728 | K33: Note B | L33: =Assumptions!C45/((1-Assumptions!E45)*C13) -> 93673.728
B34: Total notes shares | G34: =G32+G33 -> 280145.62
B36: Secondary Tender Block
B37: Tender PPS | C37: =C17 -> 32.026055
B38: Tender shares (transferred) | C38: =C18 -> 468368.64
B39: Founders pre-tender common (total) | C39: =Assumptions!C22+Assumptions!C23+Assumptions!C24 -> 8000000
B40: F1 tender outflow | C40: =C38*Assumptions!C26 -> 234184.32
B41: F2 tender outflow | C41: =C38*Assumptions!C27 -> 146365.2
B42: F3 tender outflow | C42: =C38*Assumptions!C28 -> 87819.12
B43: F_LEAD secondary common acquired | C43: =C38 -> 468368.64
B45: Post-F Fully-Diluted Total
B46: Pre-F FD | C46: =Assumptions!C16 -> 36617961
...

Sheet Waterfall
B2: Liquidation Waterfall — Five Exit Scenarios
B3: Non-participating preferred with conversion election; sequential F→Seed; proceeds at final per-share
B5: Setup
B6: Post-F FD (T_F) | C6: ='Pro-Forma'!C52 -> 38277076
B7: Less: unissued + ESOP top-up (forfeit) | C7: =-Assumptions!C18 - 'Pro-Forma'!C11 -> -2433951.4
B8: Convert pool initial | C8: =C6+C7 -> 35843125
B9: Issued options strike | C9: =Assumptions!C13 -> 1
B11: Class / Metric | C11: Shares | D11: Preference | E11: Exit 1 ($700M) | F11: Exit 2 ($1.2B) | G11: Exit 3 ($2B) | H11: Exit 4 ($4B) | I11: Exit 5 ($8B)
B12: Exit value | E12: =Assumptions!C48 -> 700000000 | F12: =Assumptions!C49 -> 1200000000 | G12: =Assumptions!C50 -> 2000000000 | H12: =Assumptions!C51 -> 4000000000 | I12: =Assumptions!C52 -> 8000000000
B14: Series F
B15: Shares / Preference | C15: ='Pro-Forma'!C14 -> 796226.69 | D15: =Assumptions!C7 -> 30000000
B16: Residual in | E16: =$E$12 -> 700000000 | F16: =$F$12 -> 1200000000 | G16: =$G$12 -> 2000000000 | H16: =$H$12 -> 4000000000 | I16: =$I$12 -> 8000000000
B17: Pool in | E17: =$C$8 -> 35843125 | F17: =$C$8 -> 35843125 | G17: =$C$8 -> 35843125 | H17: =$C$8 -> 35843125 | I17: =$C$8 -> 35843125
B18: Convert proceeds (decision) | E18: =$C$15/E17*E16 -> 15549947 | F18: =$C$15/F17*F16 -> 26657051 | G18: =$C$15/G17*G16 -> 44428419 | H18: =$C$15/H17*H16 -> 88856838 | I18: =$C$15/I17*I16 -> 1.7771368e+08
B19: Election | E19: =IF(E18>$D$15,"convert","preference") -> preference | F19: =IF(F18>$D$15,"convert","preference") -> preference | G19: =IF(G18>$D$15,"convert","preference") -> convert | H19: =IF(H18>$D$15,"convert","preference") -> convert | I19: =IF(I18>$D$15,"convert","preference") -> convert
B20: Residual out | E20: =E16-IF(E19="preference",$D$15,0) -> 670000000 | F20: =F16-IF(F19="preference",$D$15,0) -> 1170000000 | G20: =G16-IF(G19="preference",$D$15,0) -> 2000000000 | H20: =H16-IF(H19="preference",$D$15,0) -> 4000000000 | I20: =I16-IF(I19="preference",$D$15,0) -> 8000000000
B21: Pool out | E21: =E17-IF(E19="preference",$C$15,0) -> 35046898 | F21: =F17-IF(F19="preference",$C$15,0) -> 35046898 | G21: =G17-IF(G19="preference",$C$15,0) -> 35843125 | H21: =H17-IF(H19="preference",$C$15,0) -> 35843125 | I21: =I17-IF(I19="preference",$C$15,0) -> 35843125
B23: Series E
B24: Shares / Preference | C24: ='Pro-Forma'!G27 -> 6133149.6 | D24: =Assumptions!F37 -> 300000000
B25: Residual in | E25: =$E$20 -> 670000000 | F25: =$F$20 -> 1170000000 | G25: =$G$20 -> 2000000000 | H25: =$H$20 -> 4000000000 | I25: =$I$20 -> 8000000000
B26: Pool in | E26: =$E$21 -> 35046898 | F26: =$F$21 -> 35046898 | G26: =$G$21 -> 35843125 | H26: =$H$21 -> 35843125 | I26: =$I$21 -> 35843125
B27: Convert proceeds (decision) | E27: =$C$24/E26*E25 -> 1.172489e+08 | F27: =$C$24/F26*F25 -> 2.0474808e+08 | G27: =$C$24/G26*G25 -> 3.4222181e+08 | H27: =$C$24/H26*H25 -> 6.8444362e+08 | I27: =$C$24/I26*I25 -> 1.3688872e+09
B28: Election | E28: =IF(E27>$D$24,"convert","preference") -> preference | F28: =IF(F27>$D$24,"convert","preference") -> preference | G28: =IF(G27>$D$24,"convert","preference") -> convert | H28: =IF(H27>$D$24,"convert","preference") -> convert | I28: =IF(I27>$D$24,"convert","preference") -> convert
B29: Residual out | E29: =E25-IF(E28="preference",$D$24,0) -> 370000000 | F29: =F25-IF(F28="preference",$D$24,0) -> 870000000 | G29: =G25-IF(G28="preference",$D$24,0) -> 2000000000 | H29: =H25-IF(H28="preference",$D$24,0) -> 4000000000 | I29: =I25-IF(I28="preference",$D$24,0) -> 8000000000
B30: Pool out | E30: =E26-IF(E28="preference",$C$24,0) -> 28913749 | F30: =F26-IF(F28="preference",$C$24,0) -> 28913749 | G30: =G26-IF(G28="preference",$C$24,0) -> 35843125 | H30: =H26-IF(H28="preference",$C$24,0) -> 35843125 | I30: =I26-IF(I28="preference",$C$24,0) -> 35843125
B32: Series D
B33: Shares / Preference | C33: ='Pro-Forma'!G26 -> 1733603.1 | D33: =Assumptions!F36 -> 100000000
B34: Residual in | E34: =$E$29 -> 370000000 | F34: =$F$29 -> 870000000 | G34: =$G$29 -> 2000000000 | H34: =$H$29 -> 4000000000 | I34: =$I$29 -> 8000000000
B35: Pool in | E35: =$E$30 -> 28913749 | F35: =$F$30 -> 28913749 | G35: =$G$30 -> 35843125 | H35: =$H$30 -> 35843125 | I35: =$I$30 -> 35843125
B36: Convert proceeds (decision) | E36: =$C$33/E35*E34 -> 22184365 | F36: =$C$33/F35*F34 -> 52163236 | G36: =$C$33/G35*G34 -> 96732810 | H36: =$C$33/H35*H34 -> 1.9346562e+08 | I36: =$C$33/I35*I34 -> 3.8693124e+08
B37: Election | E37: =IF(E36>$D$33,"convert","preference") -> preference | F37: =IF(F36>$D$33,"convert","preference") -> preference | G37: =IF(G36>$D$33,"convert","preference") -> preference | H37: =IF(H36>$D$33,"convert","preference") -> convert | I37: =IF(I36>$D$33,"convert","preference") -> convert
B38: Residual out | E38: =E34-IF(E37="preference",$D$33,0) -> 270000000 | F38: =F34-IF(F37="preference",$D$33,0) -> 770000000 | G38: =G34-IF(G37="preference",$D$33,0) -> 1900000000 | H38: =H34-IF(H37="preference",$D$33,0) -> 4000000000 | I38: =I34-IF(I37="preference",$D$33,0) -> 8000000000
B39: Pool out | E39: =E35-IF(E37="preference",$C$33,0) -> 27180146 | F39: =F35-IF(F37="preference",$C$33,0) -> 27180146 | G39: =G35-IF(G37="preference",$C$33,0) -> 34109522 | H39: =H35-IF(H37="preference",$C$33,0) -> 35843125 | I39: =I35-IF(I37="preference",$C$33,0) -> 35843125
B41: Series C
B42: Shares / Preference | C42: ='Pro-Forma'!G25 -> 2400000 | D42: =Assumptions!F35 -> 60000000
B43: Residual in | E43: =$E$38 -> 270000000 | F43: =$F$38 -> 770000000 | G43: =$G$38 -> 1900000000 | H43: =$H$38 -> 4000000000 | I43: =$I$38 -> 8000000000
B44: Pool in | E44: =$E$39 -> 27180146 | F44: =$F$39 -> 27180146 | G44: =$G$39 -> 34109522 | H44: =$H$39 -> 35843125 | I44: =$I$39 -> 35843125
B45: Convert proceeds (decision) | E45: =$C$42/E44*E43 -> 23840932 | F45: =$C$42/F44*F43 -> 67990806 | G45: =$C$42/G44*G43 -> 1.3368701e+08 | H45: =$C$42/H44*H43 -> 2.6783379e+08 | I45: =$C$42/I44*I43 -> 5.3566758e+08
B46: Election | E46: =IF(E45>$D$42,"convert","preference") -> preference | F46: =IF(F45>$D$42,"convert","preference") -> convert | G46: =IF(G45>$D$42,"convert","preference") -> convert | H46: =IF(H45>$D$42,"convert","preference") -> convert | I46: =IF(I45>$D$42,"convert","preference") -> convert
B47: Residual out | E47: =E43-IF(E46="preference",$D$42,0) -> 210000000 | F47: =F43-IF(F46="preference",$D$42,0) -> 770000000 | G47: =G43-IF(G46="preference",$D$42,0) -> 1900000000 | H47: =H43-IF(H46="preference",$D$42,0) -> 4000000000 | I47: =I43-IF(I46="preference",$D$42,0) -> 8000000000
...

Sheet Sensitivity
B2: Sensitivity — Our Check at $2B Exit
B3: 3×3: ESOP refresh × Series F pre-money. Each cell re-solves the full round mechanics.
B5: Sensitivity Grid | K5: Per-cell Calculations (each column = one grid cell)
K6: Combo (ESOP / Pre) | L6: low/low | M6: low/base | N6: low/high | O6: base/low | P6: base/base | Q6: base/high | R6: high/low | S6: high/base | T6: high/high
B7: ESOP refresh \ Pre-money | C7: =Assumptions!C58 -> 1200000000 | D7: =Assumptions!C59 -> 1400000000 | E7: =Assumptions!C60 -> 1800000000
B8: =TEXT(Assumptions!C55,"0.0%") & " — Our %" -> 11.0% — Our % | C8: =L43 -> 0.0080513672 | D8: =M43 -> 0.0069342187 | E8: =N43 -> 0.0054266346 | K8: ESOP rate (R) | L8: =Assumptions!C55 -> 0.11 | M8: =Assumptions!C55 -> 0.11 | N8: =Assumptions!C55 -> 0.11 | O8: =Assumptions!C56 -> 0.13 | P8: =Assumptions!C56 -> 0.13 | Q8: =Assumptions!C56 -> 0.13 | R8: =Assumptions!C57 -> 0.15 | S8: =Assumptions!C57 -> 0.15 | T8: =Assumptions!C57 -> 0.15
B9: =TEXT(Assumptions!C55,"0.0%") & " — Our $" -> 11.0% — Our $ | C9: =L97 -> 16919830 | D9: =M97 -> 14576971 | E9: =N97 -> 11412548 | K9: Pre-money | L9: =Assumptions!C58 -> 1200000000 | M9: =Assumptions!C59 -> 1400000000 | N9: =Assumptions!C60 -> 1800000000 | O9: =Assumptions!C58 -> 1200000000 | P9: =Assumptions!C59 -> 1400000000 | Q9: =Assumptions!C60 -> 1800000000 | R9: =Assumptions!C58 -> 1200000000 | S9: =Assumptions!C59 -> 1400000000 | T9: =Assumptions!C60 -> 1800000000
B10: =TEXT(Assumptions!C56,"0.0%") & " — Our %" -> 13.0% — Our % | C10: =O43 -> 0.0080509711 | D10: =P43 -> 0.0069338863 | E10: =Q43 -> 0.0054263856 | K10: α = primary / pre | L10: =Assumptions!C7/L9 -> 0.025 | M10: =Assumptions!C7/M9 -> 0.021428571 | N10: =Assumptions!C7/N9 -> 0.016666667 | O10: =Assumptions!C7/O9 -> 0.025 | P10: =Assumptions!C7/P9 -> 0.021428571 | Q10: =Assumptions!C7/Q9 -> 0.016666667 | R10: =Assumptions!C7/R9 -> 0.025 | S10: =Assumptions!C7/S9 -> 0.021428571 | T10: =Assumptions!C7/T9 -> 0.016666667
B11: =TEXT(Assumptions!C56,"0.0%") & " — Our $" -> 13.0% — Our $ | C11: =O97 -> 17167775 | D11: =P97 -> 14784051 | E11: =Q97 -> 11567742 | K11: R(1+α) | L11: =L8*(1+L10) -> 0.11275 | M11: =M8*(1+M10) -> 0.11235714 | N11: =N8*(1+N10) -> 0.11183333 | O11: =O8*(1+O10) -> 0.13325 | P11: =P8*(1+P10) -> 0.13278571 | Q11: =Q8*(1+Q10) -> 0.13216667 | R11: =R8*(1+R10) -> 0.15375 | S11: =S8*(1+S10) -> 0.15321429 | T11: =T8*(1+T10) -> 0.1525
B12: =TEXT(Assumptions!C57,"0.0%") & " — Our %" -> 15.0% — Our % | C12: =R43 -> 0.0080503578 | D12: =S43 -> 0.0069333547 | E12: =T43 -> 0.005425969 | K12: ESOP top-up | L12: =MAX(0, (L11*Assumptions!C16 - Assumptions!C19)/(1 - L11)) -> 0 | M12: =MAX(0, (M11*Assumptions!C16 - Assumptions!C19)/(1 - M11)) -> 0 | N12: =MAX(0, (N11*Assumptions!C16 - Assumptions!C19)/(1 - N11)) -> 0 | O12: =MAX(0, (O11*Assumptions!C16 - Assumptions!C19)/(1 - O11)) -> 559188.12 | P12: =MAX(0, (P11*Assumptions!C16 - Assumptions!C19)/(1 - P11)) -> 539284.37 | Q12: =MAX(0, (Q11*Assumptions!C16 - Assumptions!C19)/(1 - Q11)) -> 512779.16 | R12: =MAX(0, (R11*Assumptions!C16 - Assumptions!C19)/(1 - R11)) -> 1459786.7 | S12: =MAX(0, (S11*Assumptions!C16 - Assumptions!C19)/(1 - S11)) -> 1435697 | T12: =MAX(0, (T11*Assumptions!C16 - Assumptions!C19)/(1 - T11)) -> 1403624.8
B13: =TEXT(Assumptions!C57,"0.0%") & " — Our $" -> 15.0% — Our $ | C13: =R97 -> 17566470 | D13: =S97 -> 15127794 | E13: =T97 -> 11837064 | K13: Pre-money FD | L13: =Assumptions!C16 + L12 -> 36617961 | M13: =Assumptions!C16 + M12 -> 36617961 | N13: =Assumptions!C16 + N12 -> 36617961 | O13: =Assumptions!C16 + O12 -> 37177149 | P13: =Assumptions!C16 + P12 -> 37157245 | Q13: =Assumptions!C16 + Q12 -> 37130740 | R13: =Assumptions!C16 + R12 -> 38077748 | S13: =Assumptions!C16 + S12 -> 38053658 | T13: =Assumptions!C16 + T12 -> 38021586
K14: F_PPS | L14: =L9 / L13 -> 32.770803 | M14: =M9 / M13 -> 38.232604 | N14: =N9 / N13 -> 49.156205 | O14: =O9 / O13 -> 32.277892 | P14: =P9 / P13 -> 37.677712 | Q14: =Q9 / Q13 -> 48.477353 | R14: =R9 / R13 -> 31.514469 | S14: =S9 / S13 -> 36.790156 | T14: =T9 / T13 -> 47.341529
K15: new_F shares | L15: =Assumptions!C7/L14 -> 915449.03 | M15: =Assumptions!C7/M14 -> 784670.59 | N15: =Assumptions!C7/N14 -> 610299.35 | O15: =Assumptions!C7/O14 -> 929428.73 | P15: =Assumptions!C7/P14 -> 796226.69 | Q15: =Assumptions!C7/Q14 -> 618845.67 | R15: =Assumptions!C7/R14 -> 951943.69 | S15: =Assumptions!C7/S14 -> 815435.53 | T15: =Assumptions!C7/T14 -> 633693.1
K17: — Anti-dilution —
K18: NCP_D | L18: =IF(L14<Assumptions!C36, Assumptions!C36*(Assumptions!C16+Assumptions!C7/Assumptions!C36)/(Assumptions!C16+L15), Assumptions!C36) -> 57.500114 | M18: =IF(M14<Assumptions!C36, Assumptions!C36*(Assumptions!C16+Assumptions!C7/Assumptions!C36)/(Assumptions!C16+M15), Assumptions!C36) -> 57.701164 | N18: =IF(N14<Assumptions!C36, Assumptions!C36*(Assumptions!C16+Assumptions!C7/Assumptions!C36)/(Assumptions!C16+N15), Assumptions!C36) -> 57.971427 | O18: =IF(O14<Assumptions!C36, Assumptions!C36*(Assumptions!C16+Assumptions!C7/Assumptions!C36)/(Assumptions!C16+O15), Assumptions!C36) -> 57.478706 | P18: =IF(P14<Assumptions!C36, Assumptions!C36*(Assumptions!C16+Assumptions!C7/Assumptions!C36)/(Assumptions!C16+P15), Assumptions!C36) -> 57.683341 | Q18: =IF(Q14<Assumptions!C36, Assumptions!C36*(Assumptions!C16+Assumptions!C7/Assumptions!C36)/(Assumptions!C16+Q15), Assumptions!C36) -> 57.958121 | R18: =IF(R14<Assumptions!C36, Assumptions!C36*(Assumptions!C16+Assumptions!C7/Assumptions!C36)/(Assumptions!C16+R15), Assumptions!C36) -> 57.44426 | S18: =IF(S14<Assumptions!C36, Assumptions!C36*(Assumptions!C16+Assumptions!C7/Assumptions!C36)/(Assumptions!C16+S15), Assumptions!C36) -> 57.653741 | T18: =IF(T14<Assumptions!C36, Assumptions!C36*(Assumptions!C16+Assumptions!C7/Assumptions!C36)/(Assumptions!C16+T15), Assumptions!C36) -> 57.935021
K19: D_postF shares | L19: =Assumptions!C39*Assumptions!C40/L18 -> 1739127.3 | M19: =Assumptions!C39*Assumptions!C40/M18 -> 1733067.7 | N19: =Assumptions!C39*Assumptions!C40/N18 -> 1724988.1 | O19: =Assumptions!C39*Assumptions!C40/O18 -> 1739775.1 | P19: =Assumptions!C39*Assumptions!C40/P18 -> 1733603.1 | Q19: =Assumptions!C39*Assumptions!C40/Q18 -> 1725384.1 | R19: =Assumptions!C39*Assumptions!C40/R18 -> 1740818.3 | S19: =Assumptions!C39*Assumptions!C40/S18 -> 1734493.2 | T19: =Assumptions!C39*Assumptions!C40/T18 -> 1726072
K20: AD_D delta | L20: =L19 - Assumptions!E36 -> 18500.328 | M20: =M19 - Assumptions!E36 -> 12440.651 | N20: =N19 - Assumptions!E36 -> 4361.0811 | O20: =O19 - Assumptions!E36 -> 19148.083 | P20: =P19 - Assumptions!E36 -> 12976.107 | Q20: =Q19 - Assumptions!E36 -> 4757.0786 | R20: =R19 - Assumptions!E36 -> 20191.324 | S20: =S19 - Assumptions!E36 -> 13866.158 | T20: =T19 - Assumptions!E36 -> 5445.0409
K21: NCP_E | L21: =IF(L14<Assumptions!C37, Assumptions!C37*(Assumptions!C16+Assumptions!C7/Assumptions!C37)/(Assumptions!C16+L15), Assumptions!C37) -> 48.758616 | M21: =IF(M14<Assumptions!C37, Assumptions!C37*(Assumptions!C16+Assumptions!C7/Assumptions!C37)/(Assumptions!C16+M15), Assumptions!C37) -> 48.9291 | N21: =IF(N14<Assumptions!C37, Assumptions!C37*(Assumptions!C16+Assumptions!C7/Assumptions!C37)/(Assumptions!C16+N15), Assumptions!C37) -> 49.158276 | O21: =IF(O14<Assumptions!C37, Assumptions!C37*(Assumptions!C16+Assumptions!C7/Assumptions!C37)/(Assumptions!C16+O15), Assumptions!C37) -> 48.740462 | P21: =IF(P14<Assumptions!C37, Assumptions!C37*(Assumptions!C16+Assumptions!C7/Assumptions!C37)/(Assumptions!C16+P15), Assumptions!C37) -> 48.913988 | Q21: =IF(Q14<Assumptions!C37, Assumptions!C37*(Assumptions!C16+Assumptions!C7/Assumptions!C37)/(Assumptions!C16+Q15), Assumptions!C37) -> 49.146994 | R21: =IF(R14<Assumptions!C37, Assumptions!C37*(Assumptions!C16+Assumptions!C7/Assumptions!C37)/(Assumptions!C16+R15), Assumptions!C37) -> 48.711253 | S21: =IF(S14<Assumptions!C37, Assumptions!C37*(Assumptions!C16+Assumptions!C7/Assumptions!C37)/(Assumptions!C16+S15), Assumptions!C37) -> 48.888888 | T21: =IF(T14<Assumptions!C37, Assumptions!C37*(Assumptions!C16+Assumptions!C7/Assumptions!C37)/(Assumptions!C16+T15), Assumptions!C37) -> 49.127405
K22: E_postF shares | L22: =Assumptions!E37*Assumptions!C37/L21 -> 6152693.2 | M22: =Assumptions!E37*Assumptions!C37/M21 -> 6131255.2 | N22: =Assumptions!E37*Assumptions!C37/N21 -> 6102671.3 | O22: =Assumptions!E37*Assumptions!C37/O21 -> 6154984.8 | P22: =Assumptions!E37*Assumptions!C37/P21 -> 6133149.6 | Q22: =Assumptions!E37*Assumptions!C37/Q21 -> 6104072.2 | R22: =Assumptions!E37*Assumptions!C37/R21 -> 6158675.6 | S22: =Assumptions!E37*Assumptions!C37/S21 -> 6136298.4 | T22: =Assumptions!E37*Assumptions!C37/T21 -> 6106506.1
K23: AD_E delta | L23: =L22 - Assumptions!E37 -> 50026.182 | M23: =M22 - Assumptions!E37 -> 28588.226 | N23: =N22 - Assumptions!E37 -> 4.2858605 | O23: =O22 - Assumptions!E37 -> 52317.815 | P23: =P22 - Assumptions!E37 -> 30482.568 | Q23: =Q22 - Assumptions!E37 -> 1405.2478 | R23: =R22 - Assumptions!E37 -> 56008.598 | S23: =S22 - Assumptions!E37 -> 33631.392 | T23: =T22 - Assumptions!E37 -> 3839.1239
K24: AD total | L24: =L20+L23 -> 68526.509 | M24: =M20+M23 -> 41028.877 | N24: =N20+N23 -> 4365.367 | O24: =O20+O23 -> 71465.899 | P24: =P20+P23 -> 43458.675 | Q24: =Q20+Q23 -> 6162.3265 | R24: =R20+R23 -> 76199.923 | S24: =S20+S23 -> 47497.55 | T24: =T20+T23 -> 9284.1648
K26: — Notes (mutual solve) —
K27: Note B disc-only shares (helper) | L27: =Assumptions!C45/((1-Assumptions!E45)*L14) -> 107699.89 | M27: =Assumptions!C45/((1-Assumptions!E45)*M14) -> 92314.187 | N27: =Assumptions!C45/((1-Assumptions!E45)*N14) -> 71799.924 | O27: =Assumptions!C45/((1-Assumptions!E45)*O14) -> 109344.56 | P27: =Assumptions!C45/((1-Assumptions!E45)*P14) -> 93673.728 | Q27: =Assumptions!C45/((1-Assumptions!E45)*Q14) -> 72805.373 | R27: =Assumptions!C45/((1-Assumptions!E45)*R14) -> 111993.38 | S27: =Assumptions!C45/((1-Assumptions!E45)*S14) -> 95933.592 | T27: =Assumptions!C45/((1-Assumptions!E45)*T14) -> 74552.129
K28: Note A cap-implied PPS | L28: =Assumptions!D44/(L13 + L24 + L27) -> 27.178206 | M28: =Assumptions!D44/(M13 + M24 + M27) -> 27.209919 | N28: =Assumptions!D44/(N13 + N24 + N27) -> 27.252318 | O28: =Assumptions!D44/(O13 + O24 + O27) -> 26.768057 | P28: =Assumptions!D44/(P13 + P24 + P27) -> 26.813693 | Q28: =Assumptions!D44/(Q13 + Q24 + Q27) -> 26.874707 | R28: =Assumptions!D44/(R13 + R24 + R27) -> 26.1329 | S28: =Assumptions!D44/(S13 + S24 + S27) -> 26.180005 | T28: =Assumptions!D44/(T13 + T24 + T27) -> 26.242984
K29: Note A disc-implied PPS | L29: =(1-Assumptions!E44)*L14 -> 26.216643 | M29: =(1-Assumptions!E44)*M14 -> 30.586083 | N29: =(1-Assumptions!E44)*N14 -> 39.324964 | O29: =(1-Assumptions!E44)*O14 -> 25.822314 | P29: =(1-Assumptions!E44)*P14 -> 30.14217 | Q29: =(1-Assumptions!E44)*Q14 -> 38.781882 | R29: =(1-Assumptions!E44)*R14 -> 25.211575 | S29: =(1-Assumptions!E44)*S14 -> 29.432124 | T29: =(1-Assumptions!E44)*T14 -> 37.873223
K30: Note A conv PPS | L30: =MIN(L28,L29) -> 26.216643 | M30: =MIN(M28,M29) -> 27.209919 | N30: =MIN(N28,N29) -> 27.252318 | O30: =MIN(O28,O29) -> 25.822314 | P30: =MIN(P28,P29) -> 26.813693 | Q30: =MIN(Q28,Q29) -> 26.874707 | R30: =MIN(R28,R29) -> 25.211575 | S30: =MIN(S28,S29) -> 26.180005 | T30: =MIN(T28,T29) -> 26.242984
K31: Note A branch | L31: =IF(L28<L29,"cap","discount") -> discount | M31: =IF(M28<M29,"cap","discount") -> cap | N31: =IF(N28<N29,"cap","discount") -> cap | O31: =IF(O28<O29,"cap","discount") -> discount | P31: =IF(P28<P29,"cap","discount") -> cap | Q31: =IF(Q28<Q29,"cap","discount") -> cap | R31: =IF(R28<R29,"cap","discount") -> discount | S31: =IF(S28<S29,"cap","discount") -> cap | T31: =IF(T28<T29,"cap","discount") -> cap
K32: Note A shares | L32: =Assumptions!C44/L30 -> 190718.55 | M32: =Assumptions!C44/M30 -> 183756.52 | N32: =Assumptions!C44/N30 -> 183470.63 | O32: =Assumptions!C44/O30 -> 193630.99 | P32: =Assumptions!C44/P30 -> 186471.89 | Q32: =Assumptions!C44/Q30 -> 186048.54 | R32: =Assumptions!C44/R30 -> 198321.6 | S32: =Assumptions!C44/S30 -> 190985.45 | T32: =Assumptions!C44/T30 -> 190527.11
K33: Note A disc-only shares (helper) | L33: =Assumptions!C44/((1-Assumptions!E44)*L14) -> 190718.55 | M33: =Assumptions!C44/((1-Assumptions!E44)*M14) -> 163473.04 | N33: =Assumptions!C44/((1-Assumptions!E44)*N14) -> 127145.7 | O33: =Assumptions!C44/((1-Assumptions!E44)*O14) -> 193630.99 | P33: =Assumptions!C44/((1-Assumptions!E44)*P14) -> 165880.56 | Q33: =Assumptions!C44/((1-Assumptions!E44)*Q14) -> 128926.18 | R33: =Assumptions!C44/((1-Assumptions!E44)*R14) -> 198321.6 | S33: =Assumptions!C44/((1-Assumptions!E44)*S14) -> 169882.4 | T33: =Assumptions!C44/((1-Assumptions!E44)*T14) -> 132019.4
K34: Note B cap-implied PPS | L34: =Assumptions!D45/(L13 + L24 + L33) -> 43.387235 | M34: =Assumptions!D45/(M13 + M24 + M33) -> 43.451738 | N34: =Assumptions!D45/(N13 + N24 + N33) -> 43.53804 | O34: =Assumptions!D45/(O13 + O24 + O33) -> 42.732479 | P34: =Assumptions!D45/(P13 + P24 + P33) -> 42.819006 | Q34: =Assumptions!D45/(Q13 + Q24 + Q33) -> 42.934776 | R34: =Assumptions!D45/(R13 + R24 + R33) -> 41.718522 | S34: =Assumptions!D45/(S13 + S24 + S33) -> 41.807071 | T34: =Assumptions!D45/(T13 + T24 + T33) -> 41.925547
K35: Note B disc-implied PPS | L35: =(1-Assumptions!E45)*L14 -> 27.855183 | M35: =(1-Assumptions!E45)*M14 -> 32.497713 | N35: =(1-Assumptions!E45)*N14 -> 41.782774 | O35: =(1-Assumptions!E45)*O14 -> 27.436208 | P35: =(1-Assumptions!E45)*P14 -> 32.026055 | Q35: =(1-Assumptions!E45)*Q14 -> 41.20575 | R35: =(1-Assumptions!E45)*R14 -> 26.787299 | S35: =(1-Assumptions!E45)*S14 -> 31.271632 | T35: =(1-Assumptions!E45)*T14 -> 40.240299
K36: Note B conv PPS | L36: =MIN(L34,L35) -> 27.855183 | M36: =MIN(M34,M35) -> 32.497713 | N36: =MIN(N34,N35) -> 41.782774 | O36: =MIN(O34,O35) -> 27.436208 | P36: =MIN(P34,P35) -> 32.026055 | Q36: =MIN(Q34,Q35) -> 41.20575 | R36: =MIN(R34,R35) -> 26.787299 | S36: =MIN(S34,S35) -> 31.271632 | T36: =MIN(T34,T35) -> 40.240299
K37: Note B branch | L37: =IF(L34<L35,"cap","discount") -> discount | M37: =IF(M34<M35,"cap","discount") -> discount | N37: =IF(N34<N35,"cap","discount") -> discount | O37: =IF(O34<O35,"cap","discount") -> discount | P37: =IF(P34<P35,"cap","discount") -> discount | Q37: =IF(Q34<Q35,"cap","discount") -> discount | R37: =IF(R34<R35,"cap","discount") -> discount | S37: =IF(S34<S35,"cap","discount") -> discount | T37: =IF(T34<T35,"cap","discount") -> discount
K38: Note B shares | L38: =Assumptions!C45/L36 -> 107699.89 | M38: =Assumptions!C45/M36 -> 92314.187 | N38: =Assumptions!C45/N36 -> 71799.924 | O38: =Assumptions!C45/O36 -> 109344.56 | P38: =Assumptions!C45/P36 -> 93673.728 | Q38: =Assumptions!C45/Q36 -> 72805.373 | R38: =Assumptions!C45/R36 -> 111993.38 | S38: =Assumptions!C45/S36 -> 95933.592 | T38: =Assumptions!C45/T36 -> 74552.129
K40: T_F (post-F FD) | L40: =Assumptions!C16+L12+L24+L15+L32+L38 -> 37900355 | M40: =Assumptions!C16+M12+M24+M15+M32+M38 -> 37719731 | N40: =Assumptions!C16+N12+N24+N15+N32+N38 -> 37487896 | O40: =Assumptions!C16+O12+O24+O15+O32+O38 -> 38481019 | P40: =Assumptions!C16+P12+P24+P15+P32+P38 -> 38277076 | Q40: =Assumptions!C16+Q12+Q24+Q15+Q32+Q38 -> 38014602 | R40: =Assumptions!C16+R12+R24+R15+R32+R38 -> 39416206 | S40: =Assumptions!C16+S12+S24+S15+S32+S38 -> 39203510 | T40: =Assumptions!C16+T12+T24+T15+T32+T38 -> 38929642
K41: Convert pool initial | L41: =L40 - Assumptions!C18 - L12 -> 36005688 | M41: =M40 - Assumptions!C18 - M12 -> 35825064 | N41: =N40 - Assumptions!C18 - N12 -> 35593229 | O41: =O40 - Assumptions!C18 - O12 -> 36027164 | P41: =P40 - Assumptions!C18 - P12 -> 35843125 | Q41: =Q40 - Assumptions!C18 - Q12 -> 35607156 | R41: =R40 - Assumptions!C18 - R12 -> 36061753 | S41: =S40 - Assumptions!C18 - S12 -> 35873146 | T41: =T40 - Assumptions!C18 - T12 -> 35631351
K42: Our F shares | L42: =Assumptions!C11/L14 -> 305149.68 | M42: =Assumptions!C11/M14 -> 261556.86 | N42: =Assumptions!C11/N14 -> 203433.12 | O42: =Assumptions!C11/O14 -> 309809.58 | P42: =Assumptions!C11/P14 -> 265408.9 | Q42: =Assumptions!C11/Q14 -> 206281.89 | R42: =Assumptions!C11/R14 -> 317314.56 | S42: =Assumptions!C11/S14 -> 271811.84 | T42: =Assumptions!C11/T14 -> 211231.03
K43: Our ownership % | L43: =L42/L40 -> 0.0080513672 | M43: =M42/M40 -> 0.0069342187 | N43: =N42/N40 -> 0.0054266346 | O43: =O42/O40 -> 0.0080509711 | P43: =P42/P40 -> 0.0069338863 | Q43: =Q42/Q40 -> 0.0054263856 | R43: =R42/R40 -> 0.0080503578 | S43: =S42/S40 -> 0.0069333547 | T43: =T42/T40 -> 0.005425969
K45: — Waterfall @ $2B exit (sequential F→Seed) —
K47: F: residual_in | L47: =Assumptions!C50 -> 2000000000 | M47: =Assumptions!C50 -> 2000000000 | N47: =Assumptions!C50 -> 2000000000 | O47: =Assumptions!C50 -> 2000000000 | P47: =Assumptions!C50 -> 2000000000 | Q47: =Assumptions!C50 -> 2000000000 | R47: =Assumptions!C50 -> 2000000000 | S47: =Assumptions!C50 -> 2000000000 | T47: =Assumptions!C50 -> 2000000000
...

Sheet Return-Solver
B2: Return Solver — Required F Ownership %
B3: For each exit: solve for our post-F ownership % required to hit 3× ($30M) and 4× ($40M) on our $10M check
B5: Base Case Inputs
B6: Our check | C6: =Assumptions!C11 -> 10000000
B7: 3× target | C7: =Assumptions!C63 -> 30000000
B8: 4× target | C8: =Assumptions!C64 -> 40000000
B9: Post-F FD (T_F) | C9: ='Pro-Forma'!C52 -> 38277076
B10: F PPS | C10: ='Pro-Forma'!C13 -> 37.677712
B12: Exit Scenario | C12: Exit 1 ($700M) | D12: Exit 2 ($1.2B) | E12: Exit 3 ($2B) | F12: Exit 4 ($4B) | G12: Exit 5 ($8B)
B14: Exit value | C14: =Waterfall!E12 -> 700000000 | D14: =Waterfall!F12 -> 1200000000 | E14: =Waterfall!G12 -> 2000000000 | F14: =Waterfall!H12 -> 4000000000 | G14: =Waterfall!I12 -> 8000000000
B15: F election | C15: =Waterfall!E19 -> preference | D15: =Waterfall!F19 -> preference | E15: =Waterfall!G19 -> convert | F15: =Waterfall!H19 -> convert | G15: =Waterfall!I19 -> convert
B16: Final per-share value | C16: =Waterfall!E79 -> 8.2644076 | D16: =Waterfall!F79 -> 28.329502 | E16: =Waterfall!G79 -> 55.702921 | F16: =Waterfall!H79 -> 111.59741 | G16: =Waterfall!I79 -> 223.19482
B18: 3× Return Solve
B19: Required F shares (target / per-share) | C19: =IF(C15="convert", $C$7/C16, "n/a — F prefers") -> n/a — F prefers | D19: =IF(D15="convert", $C$7/D16, "n/a — F prefers") -> n/a — F prefers | E19: =IF(E15="convert", $C$7/E16, "n/a — F prefers") -> 538571.4 | F19: =IF(F15="convert", $C$7/F16, "n/a — F prefers") -> 268823.44 | G19: =IF(G15="convert", $C$7/G16, "n/a — F prefers") -> 134411.72
B20: Required ownership % | C20: =IF(C15="convert", $C$7/(C16*$C$9), "Infeasible — F prefers") -> Infeasible — F prefers | D20: =IF(D15="convert", $C$7/(D16*$C$9), "Infeasible — F prefers") -> Infeasible — F prefers | E20: =IF(E15="convert", $C$7/(E16*$C$9), "Infeasible — F prefers") -> 0.014070338 | F20: =IF(F15="convert", $C$7/(F16*$C$9), "Infeasible — F prefers") -> 0.0070230922 | G20: =IF(G15="convert", $C$7/(G16*$C$9), "Infeasible — F prefers") -> 0.0035115461
B21: Feasibility flag | C21: =IF(C15="preference","Infeasible (F prefers — caps at 1x)",IF(C20<=0,"Infeasible (≤ 0%)",IF(C20>1,"Infeasible (> 100%)","Feasible"))) -> Infeasible (F prefers — caps at 1x) | D21: =IF(D15="preference","Infeasible (F prefers — caps at 1x)",IF(D20<=0,"Infeasible (≤ 0%)",IF(D20>1,"Infeasible (> 100%)","Feasible"))) -> Infeasible (F prefers — caps at 1x) | E21: =IF(E15="preference","Infeasible (F prefers — caps at 1x)",IF(E20<=0,"Infeasible (≤ 0%)",IF(E20>1,"Infeasible (> 100%)","Feasible"))) -> Feasible | F21: =IF(F15="preference","Infeasible (F prefers — caps at 1x)",IF(F20<=0,"Infeasible (≤ 0%)",IF(F20>1,"Infeasible (> 100%)","Feasible"))) -> Feasible | G21: =IF(G15="preference","Infeasible (F prefers — caps at 1x)",IF(G20<=0,"Infeasible (≤ 0%)",IF(G20>1,"Infeasible (> 100%)","Feasible"))) -> Feasible
B23: 4× Return Solve
B24: Required F shares (target / per-share) | C24: =IF(C15="convert", $C$8/C16, "n/a — F prefers") -> n/a — F prefers | D24: =IF(D15="convert", $C$8/D16, "n/a — F prefers") -> n/a — F prefers | E24: =IF(E15="convert", $C$8/E16, "n/a — F prefers") -> 718095.2 | F24: =IF(F15="convert", $C$8/F16, "n/a — F prefers") -> 358431.25 | G24: =IF(G15="convert", $C$8/G16, "n/a — F prefers") -> 179215.62
B25: Required ownership % | C25: =IF(C15="convert", $C$8/(C16*$C$9), "Infeasible — F prefers") -> Infeasible — F prefers | D25: =IF(D15="convert", $C$8/(D16*$C$9), "Infeasible — F prefers") -> Infeasible — F prefers | E25: =IF(E15="convert", $C$8/(E16*$C$9), "Infeasible — F prefers") -> 0.018760451 | F25: =IF(F15="convert", $C$8/(F16*$C$9), "Infeasible — F prefers") -> 0.009364123 | G25: =IF(G15="convert", $C$8/(G16*$C$9), "Infeasible — F prefers") -> 0.0046820615
B26: Feasibility flag | C26: =IF(C15="preference","Infeasible (F prefers — caps at 1x)",IF(C25<=0,"Infeasible (≤ 0%)",IF(C25>1,"Infeasible (> 100%)","Feasible"))) -> Infeasible (F prefers — caps at 1x) | D26: =IF(D15="preference","Infeasible (F prefers — caps at 1x)",IF(D25<=0,"Infeasible (≤ 0%)",IF(D25>1,"Infeasible (> 100%)","Feasible"))) -> Infeasible (F prefers — caps at 1x) | E26: =IF(E15="preference","Infeasible (F prefers — caps at 1x)",IF(E25<=0,"Infeasible (≤ 0%)",IF(E25>1,"Infeasible (> 100%)","Feasible"))) -> Feasible | F26: =IF(F15="preference","Infeasible (F prefers — caps at 1x)",IF(F25<=0,"Infeasible (≤ 0%)",IF(F25>1,"Infeasible (> 100%)","Feasible"))) -> Feasible | G26: =IF(G15="preference","Infeasible (F prefers — caps at 1x)",IF(G25<=0,"Infeasible (≤ 0%)",IF(G25>1,"Infeasible (> 100%)","Feasible"))) -> Feasible
B28: Reference
B29: Base-case our ownership % | C29: =$C$6/$C$10/$C$9 -> 0.0069338863 | D29: =$C$6/$C$10/$C$9 -> 0.0069338863 | E29: =$C$6/$C$10/$C$9 -> 0.0069338863 | F29: =$C$6/$C$10/$C$9 -> 0.0069338863 | G29: =$C$6/$C$10/$C$9 -> 0.0069338863
B30: Base-case our $ proceeds | C30: =IF(C15="preference",$C$6,Waterfall!E82/Assumptions!C7*$C$6) -> 10000000 | D30: =IF(D15="preference",$C$6,Waterfall!F82/Assumptions!C7*$C$6) -> 10000000 | E30: =IF(E15="preference",$C$6,Waterfall!G82/Assumptions!C7*$C$6) -> 14784051 | F30: =IF(F15="preference",$C$6,Waterfall!H82/Assumptions!C7*$C$6) -> 29618946 | G30: =IF(G15="preference",$C$6,Waterfall!I82/Assumptions!C7*$C$6) -> 59237892
B31: Base-case multiple on $10M | C31: =C30/$C$6 -> 1 | D31: =D30/$C$6 -> 1 | E31: =E30/$C$6 -> 1.4784051 | F31: =F30/$C$6 -> 2.9618946 | G31: =G30/$C$6 -> 5.9237892
