Workbook

Sheet Assumptions
B2: Series F Round Assumptions
B3: Source: cap_table.xlsx (Stakeholders, Securities, Notes, RoundTerms); $ values in USD; share counts in units
B4: Round Terms
B5: Series F pre-money | C5: 1400000000 | D5: USD
B6: Series F primary raise | C6: 30000000 | D6: USD
B7: Series F secondary raise (tender) | C7: 15000000 | D7: USD
B8: Tender PPS multiplier (vs F PPS) | C8: 0.85 | D8: %
B9: ESOP refresh target (% post-F FD) | C9: 0.13 | D9: %
B10: Our fund Series F check | C10: 10000000 | D10: USD
B11: F_LEAD Series F primary check | C11: 20000000 | D11: USD
B12: Option strike price (issued options) | C12: 1 | D12: USD
B14: Pre-F Capital Structure
B15: Founder F1 (CEO) common | C15: 4000000 | D15: shares
B16: Founder F2 (CTO) common | C16: 2500000 | D16: shares
B17: Founder F3 (Chief Scientist) common | C17: 1500000 | D17: shares
B18: Employee RSAs (E1..E10, 100k each) | C18: 1000000 | D18: shares
B19: Issued options outstanding (pre-F) | C19: 2500000 | D19: shares
B20: Unissued option pool (pre-F) | C20: 1894667 | D20: shares
B21: Pre-F broad-based FD total | C21: 36617961 | D21: shares
B23: Prior-Round Preferred (Seed thru E)
B24: Seed shares | C24: 5000000 | D24: shares
B25: Seed OCP | C25: 1 | D25: USD/sh
B26: Series A shares | C26: 5000000 | D26: shares
B27: Series A OCP | C27: 3 | D27: USD/sh
B28: Series B shares | C28: 3000000 | D28: shares
B29: Series B OCP | C29: 10 | D29: USD/sh
B30: Series C shares | C30: 2400000 | D30: shares
B31: Series C OCP | C31: 25 | D31: USD/sh
B32: Series D shares (issued) | C32: 1666667 | D32: shares
B33: Series D OCP-for-AD (post-E compound NCP) | C33: 58.118347 | D33: USD/sh
B34: Series D PPS issued at (original $60) | C34: 60 | D34: USD/sh
B35: Series D as-converted post-E | C35: 1720627 | D35: shares
... B37: Series E OCP | C37: 49.158311 | D37: USD/sh
B39: Convertible Notes (zero accrued interest)
B40: Note A principal | C40: 5000000 | D40: USD
B41: Note A valuation cap | C41: 1000000000 | D41: USD
B42: Note A discount | C42: 0.2 | D42: %
B43: Note B principal | C43: 3000000 | D43: USD
B44: Note B valuation cap | C44: 1600000000 | D44: USD
B45: Note B discount | C45: 0.15 | D45: %
...

Sheet Pro-Forma
B2: Series F Pro-Forma Cap Table
B3: Post-F ownership by stakeholder and security class; values traced from Assumptions
B5: Fixed-Point Solve: F PPS, ESOP Top-Up, Note Conversions
B6: Iteration | C6: 0 | D6: 1 | E6: 2 | F6: 3 | G6: 4 | H6: 5 | I6: 6
B7: F PPS = pre-money / pre-money FD | C7: =Assumptions!C5/Assumptions!C21 -> 38.232604 | D7: =Assumptions!C5/(Assumptions!C21+C8+C11+C14) -> 37.469845 | E7: =Assumptions!C5/(Assumptions!C21+D8+D11+D14) -> 37.368016 | F7: =Assumptions!C5/(Assumptions!C21+E8+E11+E14) -> 37.354203 | G7: =Assumptions!C5/(Assumptions!C21+F8+F11+F14) -> 37.352325 | H7: =Assumptions!C5/(Assumptions!C21+G8+G11+G14) -> 37.352069 | I7: =Assumptions!C5/(Assumptions!C21+H8+H11+H14) -> 37.352035
B8: ESOP top-up (post-F target less prior pool) | C8: =MAX(0,Assumptions!C9*(Assumptions!C5+Assumptions!C6)/C7-(Assumptions!C19+Assumptions!C20)) -> 467675.11 | D8: =MAX(0,Assumptions!C9*(Assumptions!C5+Assumptions!C6)/D7-(Assumptions!C19+Assumptions!C20)) -> 566655.9 | E8: =MAX(0,Assumptions!C9*(Assumptions!C5+Assumptions!C6)/E7-(Assumptions!C19+Assumptions!C20)) -> 580175.67 | F8: =MAX(0,Assumptions!C9*(Assumptions!C5+Assumptions!C6)/F7-(Assumptions!C19+Assumptions!C20)) -> 582015.21 | G8: =MAX(0,Assumptions!C9*(Assumptions!C5+Assumptions!C6)/G7-(Assumptions!C19+Assumptions!C20)) -> 582265.51 | H8: =MAX(0,Assumptions!C9*(Assumptions!C5+Assumptions!C6)/H7-(Assumptions!C19+Assumptions!C20)) -> 582299.56 | I8: =MAX(0,Assumptions!C9*(Assumptions!C5+Assumptions!C6)/I7-(Assumptions!C19+Assumptions!C20)) -> 582304.2
B9: Note A cap-branch shares | C9: =Assumptions!C40*(Assumptions!C21+C8+0)/Assumptions!C41 -> 185428.18 | D9: =Assumptions!C40*(Assumptions!C21+D8+C14)/Assumptions!C41 -> 186384.66 | E9: =Assumptions!C40*(Assumptions!C21+E8+D14)/Assumptions!C41 -> 186461.65 | F9: =Assumptions!C40*(Assumptions!C21+F8+E14)/Assumptions!C41 -> 186472.13 | G9: =Assumptions!C40*(Assumptions!C21+G8+F14)/Assumptions!C41 -> 186473.56 | H9: =Assumptions!C40*(Assumptions!C21+H8+G14)/Assumptions!C41 -> 186473.75 | I9: =Assumptions!C40*(Assumptions!C21+I8+H14)/Assumptions!C41 -> 186473.78
B10: Note A discount-branch shares | C10: =Assumptions!C40/((1-Assumptions!C42)*C7) -> 163473.04 | D10: =Assumptions!C40/((1-Assumptions!C42)*D7) -> 166800.8 | E10: =Assumptions!C40/((1-Assumptions!C42)*E7) -> 167255.33 | F10: =Assumptions!C40/((1-Assumptions!C42)*F7) -> 167317.18 | G10: =Assumptions!C40/((1-Assumptions!C42)*G7) -> 167325.6 | H10: =Assumptions!C40/((1-Assumptions!C42)*H7) -> 167326.74 | I10: =Assumptions!C40/((1-Assumptions!C42)*I7) -> 167326.9
B11: Note A shares (= MAX of two branches) | C11: =MAX(C9,C10) -> 185428.18 | D11: =MAX(D9,D10) -> 186384.66 | E11: =MAX(E9,E10) -> 186461.65 | F11: =MAX(F9,F10) -> 186472.13 | G11: =MAX(G9,G10) -> 186473.56 | H11: =MAX(H9,H10) -> 186473.75 | I11: =MAX(I9,I10) -> 186473.78
B12: Note B cap-branch shares | C12: =Assumptions!C43*(Assumptions!C21+C8+C11)/Assumptions!C44 -> 69883.246 | D12: =Assumptions!C43*(Assumptions!C21+D8+D11)/Assumptions!C44 -> 70070.628 | E12: =Assumptions!C43*(Assumptions!C21+E8+E11)/Assumptions!C44 -> 70096.122 | F12: =Assumptions!C43*(Assumptions!C21+F8+F11)/Assumptions!C44 -> 70099.591 | G12: =Assumptions!C43*(Assumptions!C21+G8+G11)/Assumptions!C44 -> 70100.063 | H12: =Assumptions!C43*(Assumptions!C21+H8+H11)/Assumptions!C44 -> 70100.127 | I12: =Assumptions!C43*(Assumptions!C21+I8+I11)/Assumptions!C44 -> 70100.136
B13: Note B discount-branch shares | C13: =Assumptions!C43/((1-Assumptions!C45)*C7) -> 92314.187 | D13: =Assumptions!C43/((1-Assumptions!C45)*D7) -> 94193.391 | E13: =Assumptions!C43/((1-Assumptions!C45)*E7) -> 94450.071 | F13: =Assumptions!C43/((1-Assumptions!C45)*F7) -> 94484.996 | G13: =Assumptions!C43/((1-Assumptions!C45)*G7) -> 94489.748 | H13: =Assumptions!C43/((1-Assumptions!C45)*H7) -> 94490.394 | I13: =Assumptions!C43/((1-Assumptions!C45)*I7) -> 94490.482
B14: Note B shares (= MAX of two branches) | C14: =MAX(C12,C13) -> 92314.187 | D14: =MAX(D12,D13) -> 94193.391 | E14: =MAX(E12,E13) -> 94450.071 | F14: =MAX(F12,F13) -> 94484.996 | G14: =MAX(G12,G13) -> 94489.748 | H14: =MAX(H12,H13) -> 94490.394 | I14: =MAX(I12,I13) -> 94490.482
B15: Residual: F_PPS change vs prior iter | D15: =ABS(D7-C7) -> 0.76275894 | E15: =ABS(E7-D7) -> 0.10182911 | F15: =ABS(F7-E7) -> 0.013812407 | G15: =ABS(G7-F7) -> 0.0018785724 | H15: =ABS(H7-G7) -> 0.00025559014 | I15: =ABS(I7-H7) -> 3.4776165e-05
B17: Final Fixed-Point Values (from iter 6)
B18: F PPS | C18: =I7 -> 37.352035
B19: ESOP top-up shares | C19: =I8 -> 582304.2
B20: Note A converted shares | C20: =I11 -> 186473.78
B21: Note B converted shares | C21: =I14 -> 94490.482
B22: F primary new shares (= primary / F PPS) | C22: =Assumptions!C6/C18 -> 803169.1
B23: Pre-money FD basis (pre + ESOP + notes), headcount | C23: =Assumptions!C21+C19+C20+C21 -> 37481229
B24: AD uplift on D & E (as-converted excess vs headcount) | C24: =(G33-Assumptions!C35)+(G34-Assumptions!C36) -> 44917.998
B25: Total post-F FD (as-converted basis) | C25: =C23+C22+C24 -> 38329317
B26: ESOP % of post-F FD (target = 13.0%) | C26: =(Assumptions!C19+Assumptions!C20+C19)/C25 -> 0.12984764
B27: Broad-Based Weighted-Average Anti-Dilution
B28: Class | C28: OCP (used for AD) | D28: Trigger? (F PPS < OCP) | E28: New Conversion Price (NCP) | F28: New Ratio (OCP / NCP) | G28: As-converted shares
B29: Seed | C29: =Assumptions!C25 -> 1 | D29: =IF($C$18<Assumptions!C25,"trigger","dormant") -> dormant | E29: =IF($C$18<Assumptions!C25,Assumptions!C25*(Assumptions!C48+Assumptions!C6/Assumptions!C25)/(Assumptions!C48+Assumptions!C6/$C$18),Assumptions!C25) -> 1 | F29: =Assumptions!C25/E29 -> 1 | G29: =Assumptions!C24*Assumptions!C25/E29 -> 5000000
B30: Series A | C30: =Assumptions!C27 -> 3 | D30: =IF($C$18<Assumptions!C27,"trigger","dormant") -> dormant | E30: =IF($C$18<Assumptions!C27,Assumptions!C27*(Assumptions!C48+Assumptions!C6/Assumptions!C27)/(Assumptions!C48+Assumptions!C6/$C$18),Assumptions!C27) -> 3 | F30: =Assumptions!C27/E30 -> 1 | G30: =Assumptions!C26*Assumptions!C27/E30 -> 5000000
B31: Series B | C31: =Assumptions!C29 -> 10 | D31: =IF($C$18<Assumptions!C29,"trigger","dormant") -> dormant | E31: =IF($C$18<Assumptions!C29,Assumptions!C29*(Assumptions!C48+Assumptions!C6/Assumptions!C29)/(Assumptions!C48+Assumptions!C6/$C$18),Assumptions!C29) -> 10 | F31: =Assumptions!C29/E31 -> 1 | G31: =Assumptions!C28*Assumptions!C29/E31 -> 3000000
B32: Series C | C32: =Assumptions!C31 -> 25 | D32: =IF($C$18<Assumptions!C31,"trigger","dormant") -> dormant | E32: =IF($C$18<Assumptions!C31,Assumptions!C31*(Assumptions!C48+Assumptions!C6/Assumptions!C31)/(Assumptions!C48+Assumptions!C6/$C$18),Assumptions!C31) -> 25 | F32: =Assumptions!C31/E32 -> 1 | G32: =Assumptions!C30*Assumptions!C31/E32 -> 2400000
B33: Series D | C33: =Assumptions!C33 -> 58.118347 | D33: =IF($C$18<Assumptions!C33,"trigger","dormant") -> trigger | E33: =IF($C$18<Assumptions!C33,Assumptions!C33*(Assumptions!C48+Assumptions!C6/Assumptions!C33)/(Assumptions!C48+Assumptions!C6/$C$18),Assumptions!C33) -> 57.67264 | F33: =Assumptions!C33/E33 -> 1.0077282 | G33: =Assumptions!C35*Assumptions!C33/E33 -> 1733924.4
B34: Series E | C34: =Assumptions!C37 -> 49.158311 | D34: =IF($C$18<Assumptions!C37,"trigger","dormant") -> trigger | E34: =IF($C$18<Assumptions!C37,Assumptions!C37*(Assumptions!C48+Assumptions!C6/Assumptions!C37)/(Assumptions!C48+Assumptions!C6/$C$18),Assumptions!C37) -> 48.904913 | F34: =Assumptions!C37/E34 -> 1.0051814 | G34: =Assumptions!C36*Assumptions!C37/E34 -> 6134287.6
B36: Total preferred as-converted (post-F AD) | G36: =SUM(G29:G34) -> 23268212
B38: Convertible Notes Block
B39: Note | C39: Cap-implied PPS | D39: Discount-implied PPS | E39: Conversion PPS (MIN) | F39: Branch elected | G39: Shares issued
B40: Note A | C40: =Assumptions!C41/(Assumptions!C21+C19+C21) -> 26.813421 | D40: =$C$18*(1-Assumptions!C42) -> 29.881628 | E40: =MIN(C40,D40) -> 26.813421 | F40: =IF(C40<D40,"cap","discount") -> cap | G40: =Assumptions!C40/E40 -> 186473.78
B41: Note B | C41: =Assumptions!C44/(Assumptions!C21+C19+C20) -> 42.795923 | D41: =$C$18*(1-Assumptions!C45) -> 31.749229 | E41: =MIN(C41,D41) -> 31.749229 | F41: =IF(C41<D41,"cap","discount") -> discount | G41: =Assumptions!C43/E41 -> 94490.482
B42: Total notes shares | G42: =G40+G41 -> 280964.26
B43: Check vs fixed-point block (row 20-21) | G43: =ROUND((G40+G41)-(C20+C21),2) -> 0
B45: Secondary Tender (founders -> F_LEAD)
B46: Tender PPS (F PPS x multiplier) | C46: =$C$18*Assumptions!C8 -> 31.749229
...

Sheet Waterfall
B2: Series F Waterfall — 1x NP with Conversion Election
B3: Nash equilibrium under reverse-chronological seniority; F most senior, Seed most junior
B5: Class Inputs
B6: Class | C6: As-conv Shares | D6: Aggregate Pref ($) | E6: Exit 1 | F6: Exit 2 | G6: Exit 3 | H6: Exit 4 | I6: Exit 5 | J6: Proc. Ex.1 | K6: Proc. Ex.2 | L6: Proc. Ex.3 | M6: Proc. Ex.4 | N6: Proc. Ex.5
B7: Series F | C7: ='Pro-Forma'!C22 -> 803169.1 | D7: =Assumptions!C6 -> 30000000 | E7: =IF(D7>(C7*(Assumptions!C51-(E$49-IF(E38="preference",D7,0))+$C$20)/($C$19+(E$50-IF(E38="convert",C7,0))+C7)),"preference","convert") -> preference | F7: =IF(D7>(C7*(Assumptions!C52-(F$49-IF(F38="preference",D7,0))+$C$20)/($C$19+(F$50-IF(F38="convert",C7,0))+C7)),"preference","convert") -> preference | G7: =IF(D7>(C7*(Assumptions!C53-(G$49-IF(G38="preference",D7,0))+$C$20)/($C$19+(G$50-IF(G38="convert",C7,0))+C7)),"preference","convert") -> convert | H7: =IF(D7>(C7*(Assumptions!C54-(H$49-IF(H38="preference",D7,0))+$C$20)/($C$19+(H$50-IF(H38="convert",C7,0))+C7)),"preference","convert") -> convert | I7: =IF(D7>(C7*(Assumptions!C55-(I$49-IF(I38="preference",D7,0))+$C$20)/($C$19+(I$50-IF(I38="convert",C7,0))+C7)),"preference","convert") -> convert | J7: =IF(E7="preference",D7,C7*E60) -> 30000000 | K7: =IF(F7="preference",D7,C7*F60) -> 30000000 | L7: =IF(G7="preference",D7,C7*G60) -> 44786047 | M7: =IF(H7="preference",D7,C7*H60) -> 89664548 | N7: =IF(I7="preference",D7,C7*I60) -> 1.7927309e+08
B8: Series E | C8: ='Pro-Forma'!G34 -> 6134287.6 | D8: =Assumptions!C36*Assumptions!C37 -> 2.999968e+08 | E8: =IF(D8>(C8*(Assumptions!C51-(E$49-IF(E39="preference",D8,0))+$C$20)/($C$19+(E$50-IF(E39="convert",C8,0))+C8)),"preference","convert") -> preference | F8: =IF(D8>(C8*(Assumptions!C52-(F$49-IF(F39="preference",D8,0))+$C$20)/($C$19+(F$50-IF(F39="convert",C8,0))+C8)),"preference","convert") -> preference | G8: =IF(D8>(C8*(Assumptions!C53-(G$49-IF(G39="preference",D8,0))+$C$20)/($C$19+(G$50-IF(G39="convert",C8,0))+C8)),"preference","convert") -> convert | H8: =IF(D8>(C8*(Assumptions!C54-(H$49-IF(H39="preference",D8,0))+$C$20)/($C$19+(H$50-IF(H39="convert",C8,0))+C8)),"preference","convert") -> convert | I8: =IF(D8>(C8*(Assumptions!C55-(I$49-IF(I39="preference",D8,0))+$C$20)/($C$19+(I$50-IF(I39="convert",C8,0))+C8)),"preference","convert") -> convert | J8: =IF(E8="preference",D8,C8*E60) -> 2.999968e+08 | K8: =IF(F8="preference",D8,C8*F60) -> 2.999968e+08 | L8: =IF(G8="preference",D8,C8*G60) -> 3.4205809e+08 | M8: =IF(H8="preference",D8,C8*H60) -> 6.8482232e+08 | N8: =IF(I8="preference",D8,C8*I60) -> 1.3692169e+09
B9: Series D | C9: ='Pro-Forma'!G33 -> 1733924.4 | D9: =Assumptions!C32*Assumptions!C34 -> 100000020 | E9: =IF(D9>(C9*(Assumptions!C51-(E$49-IF(E40="preference",D9,0))+$C$20)/($C$19+(E$50-IF(E40="convert",C9,0))+C9)),"preference","convert") -> preference | F9: =IF(D9>(C9*(Assumptions!C52-(F$49-IF(F40="preference",D9,0))+$C$20)/($C$19+(F$50-IF(F40="convert",C9,0))+C9)),"preference","convert") -> preference | G9: =IF(D9>(C9*(Assumptions!C53-(G$49-IF(G40="preference",D9,0))+$C$20)/($C$19+(G$50-IF(G40="convert",C9,0))+C9)),"preference","convert") -> preference | H9: =IF(D9>(C9*(Assumptions!C54-(H$49-IF(H40="preference",D9,0))+$C$20)/($C$19+(H$50-IF(H40="convert",C9,0))+C9)),"preference","convert") -> convert | I9: =IF(D9>(C9*(Assumptions!C55-(I$49-IF(I40="preference",D9,0))+$C$20)/($C$19+(I$50-IF(I40="convert",C9,0))+C9)),"preference","convert") -> convert | J9: =IF(E9="preference",D9,C9*E60) -> 100000020 | K9: =IF(F9="preference",D9,C9*F60) -> 100000020 | L9: =IF(G9="preference",D9,C9*G60) -> 100000020 | M9: =IF(H9="preference",D9,C9*H60) -> 1.9357262e+08 | N9: =IF(I9="preference",D9,C9*I60) -> 3.8702433e+08
B10: Series C | C10: ='Pro-Forma'!G32 -> 2400000 | D10: =Assumptions!C30*Assumptions!C31 -> 60000000 | E10: =IF(D10>(C10*(Assumptions!C51-(E$49-IF(E41="preference",D10,0))+$C$20)/($C$19+(E$50-IF(E41="convert",C10,0))+C10)),"preference","convert") -> preference | F10: =IF(D10>(C10*(Assumptions!C52-(F$49-IF(F41="preference",D10,0))+$C$20)/($C$19+(F$50-IF(F41="convert",C10,0))+C10)),"preference","convert") -> convert | G10: =IF(D10>(C10*(Assumptions!C53-(G$49-IF(G41="preference",D10,0))+$C$20)/($C$19+(G$50-IF(G41="convert",C10,0))+C10)),"preference","convert") -> convert | H10: =IF(D10>(C10*(Assumptions!C54-(H$49-IF(H41="preference",D10,0))+$C$20)/($C$19+(H$50-IF(H41="convert",C10,0))+C10)),"preference","convert") -> convert | I10: =IF(D10>(C10*(Assumptions!C55-(I$49-IF(I41="preference",D10,0))+$C$20)/($C$19+(I$50-IF(I41="convert",C10,0))+C10)),"preference","convert") -> convert | J10: =IF(E10="preference",D10,C10*E60) -> 60000000 | K10: =IF(F10="preference",D10,C10*F60) -> 68209781 | L10: =IF(G10="preference",D10,C10*G60) -> 1.33828e+08 | M10: =IF(H10="preference",D10,C10*H60) -> 2.6793226e+08 | N10: =IF(I10="preference",D10,C10*I60) -> 5.3569717e+08
B11: Series B | C11: ='Pro-Forma'!G31 -> 3000000 | D11: =Assumptions!C28*Assumptions!C29 -> 30000000 | E11: =IF(D11>(C11*(Assumptions!C51-(E$49-IF(E42="preference",D11,0))+$C$20)/($C$19+(E$50-IF(E42="convert",C11,0))+C11)),"preference","convert") -> preference | F11: =IF(D11>(C11*(Assumptions!C52-(F$49-IF(F42="preference",D11,0))+$C$20)/($C$19+(F$50-IF(F42="convert",C11,0))+C11)),"preference","convert") -> convert | G11: =IF(D11>(C11*(Assumptions!C53-(G$49-IF(G42="preference",D11,0))+$C$20)/($C$19+(G$50-IF(G42="convert",C11,0))+C11)),"preference","convert") -> convert | H11: =IF(D11>(C11*(Assumptions!C54-(H$49-IF(H42="preference",D11,0))+$C$20)/($C$19+(H$50-IF(H42="convert",C11,0))+C11)),"preference","convert") -> convert | I11: =IF(D11>(C11*(Assumptions!C55-(I$49-IF(I42="preference",D11,0))+$C$20)/($C$19+(I$50-IF(I42="convert",C11,0))+C11)),"preference","convert") -> convert | J11: =IF(E11="preference",D11,C11*E60) -> 30000000 | K11: =IF(F11="preference",D11,C11*F60) -> 85262227 | L11: =IF(G11="preference",D11,C11*G60) -> 1.67285e+08 | M11: =IF(H11="preference",D11,C11*H60) -> 3.3491533e+08 | N11: =IF(I11="preference",D11,C11*I60) -> 6.6962146e+08
B12: Series A | C12: ='Pro-Forma'!G30 -> 5000000 | D12: =Assumptions!C26*Assumptions!C27 -> 15000000 | E12: =IF(D12>(C12*(Assumptions!C51-(E$49-IF(E43="preference",D12,0))+$C$20)/($C$19+(E$50-IF(E43="convert",C12,0))+C12)),"preference","convert") -> convert | F12: =IF(D12>(C12*(Assumptions!C52-(F$49-IF(F43="preference",D12,0))+$C$20)/($C$19+(F$50-IF(F43="convert",C12,0))+C12)),"preference","convert") -> convert | G12: =IF(D12>(C12*(Assumptions!C53-(G$49-IF(G43="preference",D12,0))+$C$20)/($C$19+(G$50-IF(G43="convert",C12,0))+C12)),"preference","convert") -> convert | H12: =IF(D12>(C12*(Assumptions!C54-(H$49-IF(H43="preference",D12,0))+$C$20)/($C$19+(H$50-IF(H43="convert",C12,0))+C12)),"preference","convert") -> convert | I12: =IF(D12>(C12*(Assumptions!C55-(I$49-IF(I43="preference",D12,0))+$C$20)/($C$19+(I$50-IF(I43="convert",C12,0))+C12)),"preference","convert") -> convert | J12: =IF(E12="preference",D12,C12*E60) -> 41895110 | K12: =IF(F12="preference",D12,C12*F60) -> 1.4210371e+08 | L12: =IF(G12="preference",D12,C12*G60) -> 2.7880833e+08 | M12: =IF(H12="preference",D12,C12*H60) -> 5.5819221e+08 | N12: =IF(I12="preference",D12,C12*I60) -> 1.1160358e+09
B13: Seed | C13: ='Pro-Forma'!G29 -> 5000000 | D13: =Assumptions!C24*Assumptions!C25 -> 5000000 | E13: =IF(D13>(C13*(Assumptions!C51-(E$49-IF(E44="preference",D13,0))+$C$20)/($C$19+(E$50-IF(E44="convert",C13,0))+C13)),"preference","convert") -> convert | F13: =IF(D13>(C13*(Assumptions!C52-(F$49-IF(F44="preference",D13,0))+$C$20)/($C$19+(F$50-IF(F44="convert",C13,0))+C13)),"preference","convert") -> convert | G13: =IF(D13>(C13*(Assumptions!C53-(G$49-IF(G44="preference",D13,0))+$C$20)/($C$19+(G$50-IF(G44="convert",C13,0))+C13)),"preference","convert") -> convert | H13: =IF(D13>(C13*(Assumptions!C54-(H$49-IF(H44="preference",D13,0))+$C$20)/($C$19+(H$50-IF(H44="convert",C13,0))+C13)),"preference","convert") -> convert | I13: =IF(D13>(C13*(Assumptions!C55-(I$49-IF(I44="preference",D13,0))+$C$20)/($C$19+(I$50-IF(I44="convert",C13,0))+C13)),"preference","convert") -> convert | J13: =IF(E13="preference",D13,C13*E60) -> 41895110 | K13: =IF(F13="preference",D13,C13*F60) -> 1.4210371e+08 | L13: =IF(G13="preference",D13,C13*G60) -> 2.7880833e+08 | M13: =IF(H13="preference",D13,C13*H60) -> 5.5819221e+08 | N13: =IF(I13="preference",D13,C13*I60) -> 1.1160358e+09
B14: Common+RSA / Notes / Options (non-class, always convert)
B15: Non-Class Pool Constants
B16: Common + RSAs (founders + F_LEAD tender + employees) | C16: =Assumptions!C15+Assumptions!C16+Assumptions!C17+Assumptions!C18 -> 9000000
B17: Issued options (assumed ITM at all 5 exits) | C17: =Assumptions!C19 -> 2500000
B18: Notes shares (Note A + Note B, common-equiv post-conv.) | C18: ='Pro-Forma'!G40+'Pro-Forma'!G41 -> 280964.26
B19: Non-class pool subtotal (rides convert pool always) | C19: =C16+C17+C18 -> 11780964
B20: Issued options strike value (added to residual on ITM) | C20: =Assumptions!C19*Assumptions!C12 -> 2500000
B22: Iteration 1 (bootstrap: assume all others convert)
B23: Class | C23: Pool if all convert | D23: Residual | E23: Exit 1 elec | F23: Exit 2 elec | G23: Exit 3 elec | H23: Exit 4 elec | I23: Exit 5 elec
B24: Series F | C24: =C19+SUM(C7:C13) -> 35852345 | E24: =IF(D7>C7*(Assumptions!C51+C20)/C24,"preference","convert") -> preference | F24: =IF(D7>C7*(Assumptions!C52+C20)/C24,"preference","convert") -> preference | G24: =IF(D7>C7*(Assumptions!C53+C20)/C24,"preference","convert") -> convert | H24: =IF(D7>C7*(Assumptions!C54+C20)/C24,"preference","convert") -> convert | I24: =IF(D7>C7*(Assumptions!C55+C20)/C24,"preference","convert") -> convert
B25: Series E | E25: =IF(D8>C8*(Assumptions!C51+C20)/C24,"preference","convert") -> preference | F25: =IF(D8>C8*(Assumptions!C52+C20)/C24,"preference","convert") -> preference | G25: =IF(D8>C8*(Assumptions!C53+C20)/C24,"preference","convert") -> convert | H25: =IF(D8>C8*(Assumptions!C54+C20)/C24,"preference","convert") -> convert | I25: =IF(D8>C8*(Assumptions!C55+C20)/C24,"preference","convert") -> convert
B26: Series D | E26: =IF(D9>C9*(Assumptions!C51+C20)/C24,"preference","convert") -> preference | F26: =IF(D9>C9*(Assumptions!C52+C20)/C24,"preference","convert") -> preference | G26: =IF(D9>C9*(Assumptions!C53+C20)/C24,"preference","convert") -> preference | H26: =IF(D9>C9*(Assumptions!C54+C20)/C24,"preference","convert") -> convert | I26: =IF(D9>C9*(Assumptions!C55+C20)/C24,"preference","convert") -> convert
B27: Series C | E27: =IF(D10>C10*(Assumptions!C51+C20)/C24,"preference","convert") -> preference | F27: =IF(D10>C10*(Assumptions!C52+C20)/C24,"preference","convert") -> convert | G27: =IF(D10>C10*(Assumptions!C53+C20)/C24,"preference","convert") -> convert | H27: =IF(D10>C10*(Assumptions!C54+C20)/C24,"preference","convert") -> convert | I27: =IF(D10>C10*(Assumptions!C55+C20)/C24,"preference","convert") -> convert
B28: Series B | E28: =IF(D11>C11*(Assumptions!C51+C20)/C24,"preference","convert") -> convert | F28: =IF(D11>C11*(Assumptions!C52+C20)/C24,"preference","convert") -> convert | G28: =IF(D11>C11*(Assumptions!C53+C20)/C24,"preference","convert") -> convert | H28: =IF(D11>C11*(Assumptions!C54+C20)/C24,"preference","convert") -> convert | I28: =IF(D11>C11*(Assumptions!C55+C20)/C24,"preference","convert") -> convert
B29: Series A | E29: =IF(D12>C12*(Assumptions!C51+C20)/C24,"preference","convert") -> convert | F29: =IF(D12>C12*(Assumptions!C52+C20)/C24,"preference","convert") -> convert | G29: =IF(D12>C12*(Assumptions!C53+C20)/C24,"preference","convert") -> convert | H29: =IF(D12>C12*(Assumptions!C54+C20)/C24,"preference","convert") -> convert | I29: =IF(D12>C12*(Assumptions!C55+C20)/C24,"preference","convert") -> convert
B30: Seed | E30: =IF(D13>C13*(Assumptions!C51+C20)/C24,"preference","convert") -> convert | F30: =IF(D13>C13*(Assumptions!C52+C20)/C24,"preference","convert") -> convert | G30: =IF(D13>C13*(Assumptions!C53+C20)/C24,"preference","convert") -> convert | H30: =IF(D13>C13*(Assumptions!C54+C20)/C24,"preference","convert") -> convert | I30: =IF(D13>C13*(Assumptions!C55+C20)/C24,"preference","convert") -> convert
B33: Iteration 2 (uses iter-1 profile of others)
B34: Per-exit aggregates from iter 1 | E34: Exit 1 | F34: Exit 2 | G34: Exit 3 | H34: Exit 4 | I34: Exit 5
B35: Total iter-1 prefs ($) | E35: =SUMPRODUCT((E24:E30="preference")*$D$7:$D$13) -> 4.8999682e+08 | F35: =SUMPRODUCT((F24:F30="preference")*$D$7:$D$13) -> 4.2999682e+08 | G35: =SUMPRODUCT((G24:G30="preference")*$D$7:$D$13) -> 100000020 | H35: =SUMPRODUCT((H24:H30="preference")*$D$7:$D$13) -> 0 | I35: =SUMPRODUCT((I24:I30="preference")*$D$7:$D$13) -> 0
B36: Total iter-1 convert shares | E36: =SUMPRODUCT((E24:E30="convert")*$C$7:$C$13) -> 13000000 | F36: =SUMPRODUCT((F24:F30="convert")*$C$7:$C$13) -> 15400000 | G36: =SUMPRODUCT((G24:G30="convert")*$C$7:$C$13) -> 22337457 | H36: =SUMPRODUCT((H24:H30="convert")*$C$7:$C$13) -> 24071381 | I36: =SUMPRODUCT((I24:I30="convert")*$C$7:$C$13) -> 24071381
B37: Iter 2 elections | E37: Exit 1 | F37: Exit 2 | G37: Exit 3 | H37: Exit 4 | I37: Exit 5
B38: Series F | E38: =IF(D7>(C7*(Assumptions!C51-(E$35-IF(E24="preference",D7,0))+$C$20)/($C$19+(E$36-IF(E24="convert",C7,0))+C7)),"preference","convert") -> preference | F38: =IF(D7>(C7*(Assumptions!C52-(F$35-IF(F24="preference",D7,0))+$C$20)/($C$19+(F$36-IF(F24="convert",C7,0))+C7)),"preference","convert") -> preference | G38: =IF(D7>(C7*(Assumptions!C53-(G$35-IF(G24="preference",D7,0))+$C$20)/($C$19+(G$36-IF(G24="convert",C7,0))+C7)),"preference","convert") -> convert | H38: =IF(D7>(C7*(Assumptions!C54-(H$35-IF(H24="preference",D7,0))+$C$20)/($C$19+(H$36-IF(H24="convert",C7,0))+C7)),"preference","convert") -> convert | I38: =IF(D7>(C7*(Assumptions!C55-(I$35-IF(I24="preference",D7,0))+$C$20)/($C$19+(I$36-IF(I24="convert",C7,0))+C7)),"preference","convert") -> convert
B39: Series E | E39: =IF(D8>(C8*(Assumptions!C51-(E$35-IF(E25="preference",D8,0))+$C$20)/($C$19+(E$36-IF(E25="convert",C8,0))+C8)),"preference","convert") -> preference | F39: =IF(D8>(C8*(Assumptions!C52-(F$35-IF(F25="preference",D8,0))+$C$20)/($C$19+(F$36-IF(F25="convert",C8,0))+C8)),"preference","convert") -> preference | G39: =IF(D8>(C8*(Assumptions!C53-(G$35-IF(G25="preference",D8,0))+$C$20)/($C$19+(G$36-IF(G25="convert",C8,0))+C8)),"preference","convert") -> convert | H39: =IF(D8>(C8*(Assumptions!C54-(H$35-IF(H25="preference",D8,0))+$C$20)/($C$19+(H$36-IF(H25="convert",C8,0))+C8)),"preference","convert") -> convert | I39: =IF(D8>(C8*(Assumptions!C55-(I$35-IF(I25="preference",D8,0))+$C$20)/($C$19+(I$36-IF(I25="convert",C8,0))+C8)),"preference","convert") -> convert
B40: Series D | E40: =IF(D9>(C9*(Assumptions!C51-(E$35-IF(E26="preference",D9,0))+$C$20)/($C$19+(E$36-IF(E26="convert",C9,0))+C9)),"preference","convert") -> preference | F40: =IF(D9>(C9*(Assumptions!C52-(F$35-IF(F26="preference",D9,0))+$C$20)/($C$19+(F$36-IF(F26="convert",C9,0))+C9)),"preference","convert") -> preference | G40: =IF(D9>(C9*(Assumptions!C53-(G$35-IF(G26="preference",D9,0))+$C$20)/($C$19+(G$36-IF(G26="convert",C9,0))+C9)),"preference","convert") -> preference | H40: =IF(D9>(C9*(Assumptions!C54-(H$35-IF(H26="preference",D9,0))+$C$20)/($C$19+(H$36-IF(H26="convert",C9,0))+C9)),"preference","convert") -> convert | I40: =IF(D9>(C9*(Assumptions!C55-(I$35-IF(I26="preference",D9,0))+$C$20)/($C$19+(I$36-IF(I26="convert",C9,0))+C9)),"preference","convert") -> convert
B41: Series C | E41: =IF(D10>(C10*(Assumptions!C51-(E$35-IF(E27="preference",D10,0))+$C$20)/($C$19+(E$36-IF(E27="convert",C10,0))+C10)),"preference","convert") -> preference | F41: =IF(D10>(C10*(Assumptions!C52-(F$35-IF(F27="preference",D10,0))+$C$20)/($C$19+(F$36-IF(F27="convert",C10,0))+C10)),"preference","convert") -> convert | G41: =IF(D10>(C10*(Assumptions!C53-(G$35-IF(G27="preference",D10,0))+$C$20)/($C$19+(G$36-IF(G27="convert",C10,0))+C10)),"preference","convert") -> convert | H41: =IF(D10>(C10*(Assumptions!C54-(H$35-IF(H27="preference",D10,0))+$C$20)/($C$19+(H$36-IF(H27="convert",C10,0))+C10)),"preference","convert") -> convert | I41: =IF(D10>(C10*(Assumptions!C55-(I$35-IF(I27="preference",D10,0))+$C$20)/($C$19+(I$36-IF(I27="convert",C10,0))+C10)),"preference","convert") -> convert
B42: Series B | E42: =IF(D11>(C11*(Assumptions!C51-(E$35-IF(E28="preference",D11,0))+$C$20)/($C$19+(E$36-IF(E28="convert",C11,0))+C11)),"preference","convert") -> preference | F42: =IF(D11>(C11*(Assumptions!C52-(F$35-IF(F28="preference",D11,0))+$C$20)/($C$19+(F$36-IF(F28="convert",C11,0))+C11)),"preference","convert") -> convert | G42: =IF(D11>(C11*(Assumptions!C53-(G$35-IF(G28="preference",D11,0))+$C$20)/($C$19+(G$36-IF(G28="convert",C11,0))+C11)),"preference","convert") -> convert | H42: =IF(D11>(C11*(Assumptions!C54-(H$35-IF(H28="preference",D11,0))+$C$20)/($C$19+(H$36-IF(H28="convert",C11,0))+C11)),"preference","convert") -> convert | I42: =IF(D11>(C11*(Assumptions!C55-(I$35-IF(I28="preference",D11,0))+$C$20)/($C$19+(I$36-IF(I28="convert",C11,0))+C11)),"preference","convert") -> convert
B43: Series A | E43: =IF(D12>(C12*(Assumptions!C51-(E$35-IF(E29="preference",D12,0))+$C$20)/($C$19+(E$36-IF(E29="convert",C12,0))+C12)),"preference","convert") -> convert | F43: =IF(D12>(C12*(Assumptions!C52-(F$35-IF(F29="preference",D12,0))+$C$20)/($C$19+(F$36-IF(F29="convert",C12,0))+C12)),"preference","convert") -> convert | G43: =IF(D12>(C12*(Assumptions!C53-(G$35-IF(G29="preference",D12,0))+$C$20)/($C$19+(G$36-IF(G29="convert",C12,0))+C12)),"preference","convert") -> convert | H43: =IF(D12>(C12*(Assumptions!C54-(H$35-IF(H29="preference",D12,0))+$C$20)/($C$19+(H$36-IF(H29="convert",C12,0))+C12)),"preference","convert") -> convert | I43: =IF(D12>(C12*(Assumptions!C55-(I$35-IF(I29="preference",D12,0))+$C$20)/($C$19+(I$36-IF(I29="convert",C12,0))+C12)),"preference","convert") -> convert
B44: Seed | E44: =IF(D13>(C13*(Assumptions!C51-(E$35-IF(E30="preference",D13,0))+$C$20)/($C$19+(E$36-IF(E30="convert",C13,0))+C13)),"preference","convert") -> convert | F44: =IF(D13>(C13*(Assumptions!C52-(F$35-IF(F30="preference",D13,0))+$C$20)/($C$19+(F$36-IF(F30="convert",C13,0))+C13)),"preference","convert") -> convert | G44: =IF(D13>(C13*(Assumptions!C53-(G$35-IF(G30="preference",D13,0))+$C$20)/($C$19+(G$36-IF(G30="convert",C13,0))+C13)),"preference","convert") -> convert | H44: =IF(D13>(C13*(Assumptions!C54-(H$35-IF(H30="preference",D13,0))+$C$20)/($C$19+(H$36-IF(H30="convert",C13,0))+C13)),"preference","convert") -> convert | I44: =IF(D13>(C13*(Assumptions!C55-(I$35-IF(I30="preference",D13,0))+$C$20)/($C$19+(I$36-IF(I30="convert",C13,0))+C13)),"preference","convert") -> convert
B47: Iteration 3 — FINAL (uses iter-2 profile of others)
...

Sheet Sensitivity
B2: Sensitivity: Our $10M Check at $2B Exit
B3: 3x3 grid: ESOP refresh % x Series F pre-money; each cell re-solves full fixed point
B5: Post-F Ownership % (Our $10M Check)
B6: ESOP \ Pre-Money | C6: =Assumptions!C61 -> 1200000000 | D6: =Assumptions!C62 -> 1400000000 | E6: =Assumptions!C63 -> 1800000000
B7: =Assumptions!C58 -> 0.11 | C7: =D104 -> 0.0081150469 | D7: =E104 -> 0.0069851711 | E7: =F104 -> 0.0054637141
B8: =Assumptions!C59 -> 0.13 | C8: =G104 -> 0.0081141505 | D8: =H104 -> 0.0069844697 | E8: =I104 -> 0.0054631986
B9: =Assumptions!C60 -> 0.15 | C9: =J104 -> 0.0081126595 | D9: =K104 -> 0.0069832552 | E9: =L104 -> 0.0054622664
B12: $ Proceeds at $2B Exit (Our $10M Check)
B13: ESOP \ Pre-Money | C13: =Assumptions!C61 -> 1200000000 | D13: =Assumptions!C62 -> 1400000000 | E13: =Assumptions!C63 -> 1800000000
B14: =Assumptions!C58 -> 0.11 | C14: =D103 -> 17075712 | D14: =E103 -> 14703203 | E14: =F103 -> 11505529
B15: =Assumptions!C59 -> 0.13 | C15: =G103 -> 17345736 | D15: =H103 -> 14927842 | E15: =I103 -> 11673414
B16: =Assumptions!C60 -> 0.15 | C16: =J103 -> 17750051 | D16: =K103 -> 15276172 | E16: =L103 -> 11946055
B19: Per-Cell Fixed-Point Solve & Waterfall (helper block)
B20: Cell parameter \ (esop, pre) | D20: 11% / $1.2B | E20: 11% / $1.4B | F20: 11% / $1.8B | G20: 13% / $1.2B | H20: 13% / $1.4B | I20: 13% / $1.8B | J20: 15% / $1.2B | K20: 15% / $1.4B | L20: 15% / $1.8B
B21: ESOP target | D21: =Assumptions!C58 -> 0.11 | E21: =Assumptions!C58 -> 0.11 | F21: =Assumptions!C58 -> 0.11 | G21: =Assumptions!C59 -> 0.13 | H21: =Assumptions!C59 -> 0.13 | I21: =Assumptions!C59 -> 0.13 | J21: =Assumptions!C60 -> 0.15 | K21: =Assumptions!C60 -> 0.15 | L21: =Assumptions!C60 -> 0.15
B22: Pre-money | D22: =Assumptions!C61 -> 1200000000 | E22: =Assumptions!C62 -> 1400000000 | F22: =Assumptions!C63 -> 1800000000 | G22: =Assumptions!C61 -> 1200000000 | H22: =Assumptions!C62 -> 1400000000 | I22: =Assumptions!C63 -> 1800000000 | J22: =Assumptions!C61 -> 1200000000 | K22: =Assumptions!C62 -> 1400000000 | L22: =Assumptions!C63 -> 1800000000
B23: Primary raise (constant) | D23: =Assumptions!C6 -> 30000000 | E23: =Assumptions!C6 -> 30000000 | F23: =Assumptions!C6 -> 30000000 | G23: =Assumptions!C6 -> 30000000 | H23: =Assumptions!C6 -> 30000000 | I23: =Assumptions!C6 -> 30000000 | J23: =Assumptions!C6 -> 30000000 | K23: =Assumptions!C6 -> 30000000 | L23: =Assumptions!C6 -> 30000000
B24: Iter 0: ESOP top-up (init=0) | D24: 0 | E24: 0 | F24: 0 | G24: 0 | H24: 0 | I24: 0 | J24: 0 | K24: 0 | L24: 0
B25: Iter 0: nA (init=0) | D25: 0 | E25: 0 | F25: 0 | G25: 0 | H25: 0 | I25: 0 | J25: 0 | K25: 0 | L25: 0
B26: Iter 0: nB (init=0) | D26: 0 | E26: 0 | F26: 0 | G26: 0 | H26: 0 | I26: 0 | J26: 0 | K26: 0 | L26: 0
B27: Iter 1: F PPS | D27: =D$22/(Assumptions!C21+D24+D25+D26) -> 32.770803 | E27: =E$22/(Assumptions!C21+E24+E25+E26) -> 38.232604 | F27: =F$22/(Assumptions!C21+F24+F25+F26) -> 49.156205 | G27: =G$22/(Assumptions!C21+G24+G25+G26) -> 32.770803 | H27: =H$22/(Assumptions!C21+H24+H25+H26) -> 38.232604 | I27: =I$22/(Assumptions!C21+I24+I25+I26) -> 49.156205 | J27: =J$22/(Assumptions!C21+J24+J25+J26) -> 32.770803 | K27: =K$22/(Assumptions!C21+K24+K25+K26) -> 38.232604 | L27: =L$22/(Assumptions!C21+L24+L25+L26) -> 49.156205
B28: Iter 1: ESOP top-up | D28: =MAX(0,D$21*(D$22+D$23)/D27-(Assumptions!C19+Assumptions!C20)) -> 0 | E28: =MAX(0,E$21*(E$22+E$23)/E27-(Assumptions!C19+Assumptions!C20)) -> 0 | F28: =MAX(0,F$21*(F$22+F$23)/F27-(Assumptions!C19+Assumptions!C20)) -> 0 | G28: =MAX(0,G$21*(G$22+G$23)/G27-(Assumptions!C19+Assumptions!C20)) -> 484676.3 | H28: =MAX(0,H$21*(H$22+H$23)/H27-(Assumptions!C19+Assumptions!C20)) -> 467675.11 | I28: =MAX(0,I$21*(I$22+I$23)/I27-(Assumptions!C19+Assumptions!C20)) -> 445006.85 | J28: =MAX(0,J$21*(J$22+J$23)/J27-(Assumptions!C19+Assumptions!C20)) -> 1235344.5 | K28: =MAX(0,K$21*(K$22+K$23)/K27-(Assumptions!C19+Assumptions!C20)) -> 1215727.7 | L28: =MAX(0,L$21*(L$22+L$23)/L27-(Assumptions!C19+Assumptions!C20)) -> 1189572.1
B29: Iter 1: nA = MAX(cap, disc) | D29: =MAX(Assumptions!C40*(Assumptions!C21+D28+D26)/Assumptions!C41,Assumptions!C40/((1-Assumptions!C42)*D27)) -> 190718.55 | E29: =MAX(Assumptions!C40*(Assumptions!C21+E28+E26)/Assumptions!C41,Assumptions!C40/((1-Assumptions!C42)*E27)) -> 183089.8 | F29: =MAX(Assumptions!C40*(Assumptions!C21+F28+F26)/Assumptions!C41,Assumptions!C40/((1-Assumptions!C42)*F27)) -> 183089.8 | G29: =MAX(Assumptions!C40*(Assumptions!C21+G28+G26)/Assumptions!C41,Assumptions!C40/((1-Assumptions!C42)*G27)) -> 190718.55 | H29: =MAX(Assumptions!C40*(Assumptions!C21+H28+H26)/Assumptions!C41,Assumptions!C40/((1-Assumptions!C42)*H27)) -> 185428.18 | I29: =MAX(Assumptions!C40*(Assumptions!C21+I28+I26)/Assumptions!C41,Assumptions!C40/((1-Assumptions!C42)*I27)) -> 185314.84 | J29: =MAX(Assumptions!C40*(Assumptions!C21+J28+J26)/Assumptions!C41,Assumptions!C40/((1-Assumptions!C42)*J27)) -> 190718.55 | K29: =MAX(Assumptions!C40*(Assumptions!C21+K28+K26)/Assumptions!C41,Assumptions!C40/((1-Assumptions!C42)*K27)) -> 189168.44 | L29: =MAX(Assumptions!C40*(Assumptions!C21+L28+L26)/Assumptions!C41,Assumptions!C40/((1-Assumptions!C42)*L27)) -> 189037.67
B30: Iter 1: nB = MAX(cap, disc) | D30: =MAX(Assumptions!C43*(Assumptions!C21+D28+D29)/Assumptions!C44,Assumptions!C43/((1-Assumptions!C45)*D27)) -> 107699.89 | E30: =MAX(Assumptions!C43*(Assumptions!C21+E28+E29)/Assumptions!C44,Assumptions!C43/((1-Assumptions!C45)*E27)) -> 92314.187 | F30: =MAX(Assumptions!C43*(Assumptions!C21+F28+F29)/Assumptions!C44,Assumptions!C43/((1-Assumptions!C45)*F27)) -> 71799.924 | G30: =MAX(Assumptions!C43*(Assumptions!C21+G28+G29)/Assumptions!C44,Assumptions!C43/((1-Assumptions!C45)*G27)) -> 107699.89 | H30: =MAX(Assumptions!C43*(Assumptions!C21+H28+H29)/Assumptions!C44,Assumptions!C43/((1-Assumptions!C45)*H27)) -> 92314.187 | I30: =MAX(Assumptions!C43*(Assumptions!C21+I28+I29)/Assumptions!C44,Assumptions!C43/((1-Assumptions!C45)*I27)) -> 71799.924 | J30: =MAX(Assumptions!C43*(Assumptions!C21+J28+J29)/Assumptions!C44,Assumptions!C43/((1-Assumptions!C45)*J27)) -> 107699.89 | K30: =MAX(Assumptions!C43*(Assumptions!C21+K28+K29)/Assumptions!C44,Assumptions!C43/((1-Assumptions!C45)*K27)) -> 92314.187 | L30: =MAX(Assumptions!C43*(Assumptions!C21+L28+L29)/Assumptions!C44,Assumptions!C43/((1-Assumptions!C45)*L27)) -> 71799.924
B31: Iter 2: F PPS | D31: =D$22/(Assumptions!C21+D28+D29+D30) -> 32.505896 | E31: =E$22/(Assumptions!C21+E28+E29+E30) -> 37.947203 | F31: =F$22/(Assumptions!C21+F28+F29+F30) -> 48.816405 | G31: =G$22/(Assumptions!C21+G28+G29+G30) -> 32.084656 | H31: =H$22/(Assumptions!C21+H28+H29+H30) -> 37.469845 | I31: =I$22/(Assumptions!C21+I28+I29+I30) -> 48.231404 | J31: =J$22/(Assumptions!C21+J28+J29+J30) -> 31.453362 | K31: =K$22/(Assumptions!C21+K28+K29+K30) -> 36.730781 | L31: =L$22/(Assumptions!C21+L28+L29+L30) -> 47.283348
B32: Iter 2: ESOP top-up | D32: =MAX(0,D$21*(D$22+D$23)/D31-(Assumptions!C19+Assumptions!C20)) -> 0 | E32: =MAX(0,E$21*(E$22+E$23)/E31-(Assumptions!C19+Assumptions!C20)) -> 0 | F32: =MAX(0,F$21*(F$22+F$23)/F31-(Assumptions!C19+Assumptions!C20)) -> 0 | G32: =MAX(0,G$21*(G$22+G$23)/G31-(Assumptions!C19+Assumptions!C20)) -> 589023.68 | H32: =MAX(0,H$21*(H$22+H$23)/H31-(Assumptions!C19+Assumptions!C20)) -> 566655.9 | I32: =MAX(0,I$21*(I$22+I$23)/I31-(Assumptions!C19+Assumptions!C20)) -> 537803.92 | J32: =MAX(0,J$21*(J$22+J$23)/J31-(Assumptions!C19+Assumptions!C20)) -> 1471160.6 | K32: =MAX(0,K$21*(K$22+K$23)/K31-(Assumptions!C19+Assumptions!C20)) -> 1445121.8 | L32: =MAX(0,L$21*(L$22+L$23)/L31-(Assumptions!C19+Assumptions!C20)) -> 1410759.5
B33: Iter 2: nA = MAX(cap, disc) | D33: =MAX(Assumptions!C40*(Assumptions!C21+D32+D30)/Assumptions!C41,Assumptions!C40/((1-Assumptions!C42)*D31)) -> 192272.81 | E33: =MAX(Assumptions!C40*(Assumptions!C21+E32+E30)/Assumptions!C41,Assumptions!C40/((1-Assumptions!C42)*E31)) -> 183551.38 | F33: =MAX(Assumptions!C40*(Assumptions!C21+F32+F30)/Assumptions!C41,Assumptions!C40/((1-Assumptions!C42)*F31)) -> 183448.8 | G33: =MAX(Assumptions!C40*(Assumptions!C21+G32+G30)/Assumptions!C41,Assumptions!C40/((1-Assumptions!C42)*G31)) -> 194797.17 | H33: =MAX(Assumptions!C40*(Assumptions!C21+H32+H30)/Assumptions!C41,Assumptions!C40/((1-Assumptions!C42)*H31)) -> 186384.66 | I33: =MAX(Assumptions!C40*(Assumptions!C21+I32+I30)/Assumptions!C41,Assumptions!C40/((1-Assumptions!C42)*I31)) -> 186137.82 | J33: =MAX(Assumptions!C40*(Assumptions!C21+J32+J30)/Assumptions!C41,Assumptions!C40/((1-Assumptions!C42)*J31)) -> 198706.9 | K33: =MAX(Assumptions!C40*(Assumptions!C21+K32+K30)/Assumptions!C41,Assumptions!C40/((1-Assumptions!C42)*K31)) -> 190776.98 | L33: =MAX(Assumptions!C40*(Assumptions!C21+L32+L30)/Assumptions!C41,Assumptions!C40/((1-Assumptions!C42)*L31)) -> 190502.6
B34: Iter 2: nB = MAX(cap, disc) | D34: =MAX(Assumptions!C43*(Assumptions!C21+D32+D33)/Assumptions!C44,Assumptions!C43/((1-Assumptions!C45)*D31)) -> 108577.59 | E34: =MAX(Assumptions!C43*(Assumptions!C21+E32+E33)/Assumptions!C44,Assumptions!C43/((1-Assumptions!C45)*E31)) -> 93008.483 | F34: =MAX(Assumptions!C43*(Assumptions!C21+F32+F33)/Assumptions!C44,Assumptions!C43/((1-Assumptions!C45)*F31)) -> 72299.707 | G34: =MAX(Assumptions!C43*(Assumptions!C21+G32+G33)/Assumptions!C44,Assumptions!C43/((1-Assumptions!C45)*G31)) -> 110003.11 | H34: =MAX(Assumptions!C43*(Assumptions!C21+H32+H33)/Assumptions!C44,Assumptions!C43/((1-Assumptions!C45)*H31)) -> 94193.391 | I34: =MAX(Assumptions!C43*(Assumptions!C21+I32+I33)/Assumptions!C44,Assumptions!C43/((1-Assumptions!C45)*I31)) -> 73176.633 | J34: =MAX(Assumptions!C43*(Assumptions!C21+J32+J33)/Assumptions!C44,Assumptions!C43/((1-Assumptions!C45)*J31)) -> 112210.95 | K34: =MAX(Assumptions!C43*(Assumptions!C21+K32+K33)/Assumptions!C44,Assumptions!C43/((1-Assumptions!C45)*K31)) -> 96088.667 | L34: =MAX(Assumptions!C43*(Assumptions!C21+L32+L33)/Assumptions!C44,Assumptions!C43/((1-Assumptions!C45)*L31)) -> 74643.864
B35: Iter 3: F PPS | D35: =D$22/(Assumptions!C21+D32+D33+D34) -> 32.503755 | E35: =E$22/(Assumptions!C21+E32+E33+E34) -> 37.946014 | F35: =F$22/(Assumptions!C21+F32+F33+F34) -> 48.815268 | G35: =G$22/(Assumptions!C21+G32+G33+G34) -> 31.989947 | H35: =H$22/(Assumptions!C21+H32+H33+H34) -> 37.368016 | I35: =I$22/(Assumptions!C21+I32+I33+I34) -> 48.108945 | J35: =J$22/(Assumptions!C21+J32+J33+J34) -> 31.249968 | K35: =K$22/(Assumptions!C21+K32+K33+K34) -> 36.505916 | L35: =L$22/(Assumptions!C21+L32+L33+L34) -> 47.004916
B36: Iter 3: ESOP top-up | D36: =MAX(0,D$21*(D$22+D$23)/D35-(Assumptions!C19+Assumptions!C20)) -> 0 | E36: =MAX(0,E$21*(E$22+E$23)/E35-(Assumptions!C19+Assumptions!C20)) -> 0 | F36: =MAX(0,F$21*(F$22+F$23)/F35-(Assumptions!C19+Assumptions!C20)) -> 0 | G36: =MAX(0,G$21*(G$22+G$23)/G35-(Assumptions!C19+Assumptions!C20)) -> 603778.34 | H36: =MAX(0,H$21*(H$22+H$23)/H35-(Assumptions!C19+Assumptions!C20)) -> 580175.67 | I36: =MAX(0,I$21*(I$22+I$23)/I35-(Assumptions!C19+Assumptions!C20)) -> 550359.32 | J36: =MAX(0,J$21*(J$22+J$23)/J35-(Assumptions!C19+Assumptions!C20)) -> 1509339.1 | K36: =MAX(0,K$21*(K$22+K$23)/K35-(Assumptions!C19+Assumptions!C20)) -> 1481093 | L36: =MAX(0,L$21*(L$22+L$23)/L35-(Assumptions!C19+Assumptions!C20)) -> 1445147.7
B37: Iter 3: nA = MAX(cap, disc) | D37: =MAX(Assumptions!C40*(Assumptions!C21+D36+D34)/Assumptions!C41,Assumptions!C40/((1-Assumptions!C42)*D35)) -> 192285.48 | E37: =MAX(Assumptions!C40*(Assumptions!C21+E36+E34)/Assumptions!C41,Assumptions!C40/((1-Assumptions!C42)*E35)) -> 183554.85 | F37: =MAX(Assumptions!C40*(Assumptions!C21+F36+F34)/Assumptions!C41,Assumptions!C40/((1-Assumptions!C42)*F35)) -> 183451.3 | G37: =MAX(Assumptions!C40*(Assumptions!C21+G36+G34)/Assumptions!C41,Assumptions!C40/((1-Assumptions!C42)*G35)) -> 195373.88 | H37: =MAX(Assumptions!C40*(Assumptions!C21+H36+H34)/Assumptions!C41,Assumptions!C40/((1-Assumptions!C42)*H35)) -> 186461.65 | I37: =MAX(Assumptions!C40*(Assumptions!C21+I36+I34)/Assumptions!C41,Assumptions!C40/((1-Assumptions!C42)*I35)) -> 186207.48 | J37: =MAX(Assumptions!C40*(Assumptions!C21+J36+J34)/Assumptions!C41,Assumptions!C40/((1-Assumptions!C42)*J35)) -> 200000.21 | K37: =MAX(Assumptions!C40*(Assumptions!C21+K36+K34)/Assumptions!C41,Assumptions!C40/((1-Assumptions!C42)*K35)) -> 190975.71 | L37: =MAX(Assumptions!C40*(Assumptions!C21+L36+L34)/Assumptions!C41,Assumptions!C40/((1-Assumptions!C42)*L35)) -> 190688.76
B38: Iter 3: nB = MAX(cap, disc) | D38: =MAX(Assumptions!C43*(Assumptions!C21+D36+D37)/Assumptions!C44,Assumptions!C43/((1-Assumptions!C45)*D35)) -> 108584.74 | E38: =MAX(Assumptions!C43*(Assumptions!C21+E36+E37)/Assumptions!C44,Assumptions!C43/((1-Assumptions!C45)*E35)) -> 93011.397 | F38: =MAX(Assumptions!C43*(Assumptions!C21+F36+F37)/Assumptions!C44,Assumptions!C43/((1-Assumptions!C45)*F35)) -> 72301.391 | G38: =MAX(Assumptions!C43*(Assumptions!C21+G36+G37)/Assumptions!C44,Assumptions!C43/((1-Assumptions!C45)*G35)) -> 110328.78 | H38: =MAX(Assumptions!C43*(Assumptions!C21+H36+H37)/Assumptions!C44,Assumptions!C43/((1-Assumptions!C45)*H35)) -> 94450.071 | I38: =MAX(Assumptions!C43*(Assumptions!C21+I36+I37)/Assumptions!C44,Assumptions!C43/((1-Assumptions!C45)*I35)) -> 73362.901 | J38: =MAX(Assumptions!C43*(Assumptions!C21+J36+J37)/Assumptions!C44,Assumptions!C43/((1-Assumptions!C45)*J35)) -> 112941.29 | K38: =MAX(Assumptions!C43*(Assumptions!C21+K36+K37)/Assumptions!C44,Assumptions!C43/((1-Assumptions!C45)*K35)) -> 96680.542 | L38: =MAX(Assumptions!C43*(Assumptions!C21+L36+L37)/Assumptions!C44,Assumptions!C43/((1-Assumptions!C45)*L35)) -> 75086.014
B39: Iter 4: F PPS | D39: =D$22/(Assumptions!C21+D36+D37+D38) -> 32.503738 | E39: =E$22/(Assumptions!C21+E36+E37+E38) -> 37.946007 | F39: =F$22/(Assumptions!C21+F36+F37+F38) -> 48.815262 | G39: =G$22/(Assumptions!C21+G36+G37+G38) -> 31.9766 | H39: =H$22/(Assumptions!C21+H36+H37+H38) -> 37.354203 | I39: =I$22/(Assumptions!C21+I36+I37+I38) -> 48.092478 | J39: =J$22/(Assumptions!C21+J36+J37+J38) -> 31.217286 | K39: =K$22/(Assumptions!C21+K36+K37+K38) -> 36.470956 | L39: =L$22/(Assumptions!C21+L36+L37+L38) -> 46.961973
B40: Iter 4: ESOP top-up | D40: =MAX(0,D$21*(D$22+D$23)/D39-(Assumptions!C19+Assumptions!C20)) -> 0 | E40: =MAX(0,E$21*(E$22+E$23)/E39-(Assumptions!C19+Assumptions!C20)) -> 0 | F40: =MAX(0,F$21*(F$22+F$23)/F39-(Assumptions!C19+Assumptions!C20)) -> 0 | G40: =MAX(0,G$21*(G$22+G$23)/G39-(Assumptions!C19+Assumptions!C20)) -> 605864.65 | H40: =MAX(0,H$21*(H$22+H$23)/H39-(Assumptions!C19+Assumptions!C20)) -> 582015.21 | I40: =MAX(0,I$21*(I$22+I$23)/I39-(Assumptions!C19+Assumptions!C20)) -> 552052.56 | J40: =MAX(0,J$21*(J$22+J$23)/J39-(Assumptions!C19+Assumptions!C20)) -> 1515520.1 | K40: =MAX(0,K$21*(K$22+K$23)/K39-(Assumptions!C19+Assumptions!C20)) -> 1486725.4 | L40: =MAX(0,L$21*(L$22+L$23)/L39-(Assumptions!C19+Assumptions!C20)) -> 1450487.7
B41: Iter 4: nA = MAX(cap, disc) | D41: =MAX(Assumptions!C40*(Assumptions!C21+D40+D38)/Assumptions!C41,Assumptions!C40/((1-Assumptions!C42)*D39)) -> 192285.58 | E41: =MAX(Assumptions!C40*(Assumptions!C21+E40+E38)/Assumptions!C41,Assumptions!C40/((1-Assumptions!C42)*E39)) -> 183554.86 | F41: =MAX(Assumptions!C40*(Assumptions!C21+F40+F38)/Assumptions!C41,Assumptions!C40/((1-Assumptions!C42)*F39)) -> 183451.31 | G41: =MAX(Assumptions!C40*(Assumptions!C21+G40+G38)/Assumptions!C41,Assumptions!C40/((1-Assumptions!C42)*G39)) -> 195455.43 | H41: =MAX(Assumptions!C40*(Assumptions!C21+H40+H38)/Assumptions!C41,Assumptions!C40/((1-Assumptions!C42)*H39)) -> 186472.13 | I41: =MAX(Assumptions!C40*(Assumptions!C21+I40+I38)/Assumptions!C41,Assumptions!C40/((1-Assumptions!C42)*I39)) -> 186216.88 | J41: =MAX(Assumptions!C40*(Assumptions!C21+J40+J38)/Assumptions!C41,Assumptions!C40/((1-Assumptions!C42)*J39)) -> 200209.59 | K41: =MAX(Assumptions!C40*(Assumptions!C21+K40+K38)/Assumptions!C41,Assumptions!C40/((1-Assumptions!C42)*K39)) -> 191006.83 | L41: =MAX(Assumptions!C40*(Assumptions!C21+L40+L38)/Assumptions!C41,Assumptions!C40/((1-Assumptions!C42)*L39)) -> 190717.67
B42: Iter 4: nB = MAX(cap, disc) | D42: =MAX(Assumptions!C43*(Assumptions!C21+D40+D41)/Assumptions!C44,Assumptions!C43/((1-Assumptions!C45)*D39)) -> 108584.8 | E42: =MAX(Assumptions!C43*(Assumptions!C21+E40+E41)/Assumptions!C44,Assumptions!C43/((1-Assumptions!C45)*E39)) -> 93011.413 | F42: =MAX(Assumptions!C43*(Assumptions!C21+F40+F41)/Assumptions!C44,Assumptions!C43/((1-Assumptions!C45)*F39)) -> 72301.399 | G42: =MAX(Assumptions!C43*(Assumptions!C21+G40+G41)/Assumptions!C44,Assumptions!C43/((1-Assumptions!C45)*G39)) -> 110374.83 | H42: =MAX(Assumptions!C43*(Assumptions!C21+H40+H41)/Assumptions!C44,Assumptions!C43/((1-Assumptions!C45)*H39)) -> 94484.996 | I42: =MAX(Assumptions!C43*(Assumptions!C21+I40+I41)/Assumptions!C44,Assumptions!C43/((1-Assumptions!C45)*I39)) -> 73388.021 | J42: =MAX(Assumptions!C43*(Assumptions!C21+J40+J41)/Assumptions!C44,Assumptions!C43/((1-Assumptions!C45)*J39)) -> 113059.53 | K42: =MAX(Assumptions!C43*(Assumptions!C21+K40+K41)/Assumptions!C44,Assumptions!C43/((1-Assumptions!C45)*K39)) -> 96773.219 | L42: =MAX(Assumptions!C43*(Assumptions!C21+L40+L41)/Assumptions!C44,Assumptions!C43/((1-Assumptions!C45)*L39)) -> 75154.674
B44: F PPS (final) | D44: =D39 -> 32.503738 | E44: =E39 -> 37.946007 | F44: =F39 -> 48.815262 | G44: =G39 -> 31.9766 | H44: =H39 -> 37.354203 | I44: =I39 -> 48.092478 | J44: =J39 -> 31.217286 | K44: =K39 -> 36.470956 | L44: =L39 -> 46.961973
B45: ESOP top-up (final) | D45: =D40 -> 0 | E45: =E40 -> 0 | F45: =F40 -> 0 | G45: =G40 -> 605864.65 | H45: =H40 -> 582015.21 | I45: =I40 -> 552052.56 | J45: =J40 -> 1515520.1 | K45: =K40 -> 1486725.4 | L45: =L40 -> 1450487.7
B46: nA (final) | D46: =D41 -> 192285.58 | E46: =E41 -> 183554.86 | F46: =F41 -> 183451.31 | G46: =G41 -> 195455.43 | H46: =H41 -> 186472.13 | I46: =I41 -> 186216.88 | J46: =J41 -> 200209.59 | K46: =K41 -> 191006.83 | L46: =L41 -> 190717.67
B47: nB (final) | D47: =D42 -> 108584.8 | E47: =E42 -> 93011.413 | F47: =F42 -> 72301.399 | G47: =G42 -> 110374.83 | H47: =H42 -> 94484.996 | I47: =I42 -> 73388.021 | J47: =J42 -> 113059.53 | K47: =K42 -> 96773.219 | L47: =L42 -> 75154.674
...

Sheet Return-Solver
B2: Return Solver: Required Series F Ownership for 3x / 4x
B3: Solves the F-class ownership % our $10M check would need; uses base-case waterfall at each exit
B5: Per-Exit Inputs (referencing Waterfall and Pro-Forma)
B6: Item | C6: Exit 1 | D6: Exit 2 | E6: Exit 3 | F6: Exit 4 | G6: Exit 5
B7: Exit value | C7: =Assumptions!C51 -> 700000000 | D7: =Assumptions!C52 -> 1200000000 | E7: =Assumptions!C53 -> 2000000000 | F7: =Assumptions!C54 -> 4000000000 | G7: =Assumptions!C55 -> 8000000000
B8: F class election (from Waterfall) | C8: =Waterfall!E7 -> preference | D8: =Waterfall!F7 -> preference | E8: =Waterfall!G7 -> convert | F8: =Waterfall!H7 -> convert | G8: =Waterfall!I7 -> convert
B9: F class total proceeds (from Waterfall) | C9: =Waterfall!J7 -> 30000000 | D9: =Waterfall!K7 -> 30000000 | E9: =Waterfall!L7 -> 44786047 | F9: =Waterfall!M7 -> 89664548 | G9: =Waterfall!N7 -> 1.7927309e+08
B10: F class total preference (= primary $30M) | C10: =Assumptions!C6 -> 30000000 | D10: =Assumptions!C6 -> 30000000 | E10: =Assumptions!C6 -> 30000000 | F10: =Assumptions!C6 -> 30000000 | G10: =Assumptions!C6 -> 30000000
B11: F class shares (post-F primary) | C11: ='Pro-Forma'!C22 -> 803169.1 | D11: ='Pro-Forma'!C22 -> 803169.1 | E11: ='Pro-Forma'!C22 -> 803169.1 | F11: ='Pro-Forma'!C22 -> 803169.1 | G11: ='Pro-Forma'!C22 -> 803169.1
B12: Per-share value at exit (Waterfall row 60) | C12: =Waterfall!E60 -> 8.379022 | D12: =Waterfall!F60 -> 28.420742 | E12: =Waterfall!G60 -> 55.761666 | F12: =Waterfall!H60 -> 111.63844 | G12: =Waterfall!I60 -> 223.20715
B13: Total post-F FD (constant) | C13: ='Pro-Forma'!C25 -> 38329317 | D13: ='Pro-Forma'!C25 -> 38329317 | E13: ='Pro-Forma'!C25 -> 38329317 | F13: ='Pro-Forma'!C25 -> 38329317 | G13: ='Pro-Forma'!C25 -> 38329317
B15: 3x Return Solver ($30M target)
B16: Item | C16: Exit 1 | D16: Exit 2 | E16: Exit 3 | F16: Exit 4 | G16: Exit 5
B17: Target proceeds ($) | C17: =Assumptions!C10*Assumptions!C66 -> 30000000 | D17: =Assumptions!C10*Assumptions!C66 -> 30000000 | E17: =Assumptions!C10*Assumptions!C66 -> 30000000 | F17: =Assumptions!C10*Assumptions!C66 -> 30000000 | G17: =Assumptions!C10*Assumptions!C66 -> 30000000
B18: Required % of F class (= target / F class proceeds) | C18: =C17/C9 -> 1 | D18: =D17/D9 -> 1 | E18: =E17/E9 -> 0.66985149 | F18: =F17/F9 -> 0.3345804 | G18: =G17/G9 -> 0.16734246
B19: Required % of post-F FD (equivalent share count) | C19: =C18*C11/C13 -> 0.020954433 | D19: =D18*D11/D13 -> 0.020954433 | E19: =E18*E11/E13 -> 0.014036358 | F19: =F18*F11/F13 -> 0.0070109426 | G19: =G18*G11/G13 -> 0.0035065664
B20: Feasibility (TRUE = achievable) | C20: =IF(AND(C18>0,C18<=1),"feasible","infeasible") -> feasible | D20: =IF(AND(D18>0,D18<=1),"feasible","infeasible") -> feasible | E20: =IF(AND(E18>0,E18<=1),"feasible","infeasible") -> feasible | F20: =IF(AND(F18>0,F18<=1),"feasible","infeasible") -> feasible | G20: =IF(AND(G18>0,G18<=1),"feasible","infeasible") -> feasible
B22: 4x Return Solver ($40M target)
B23: Item | C23: Exit 1 | D23: Exit 2 | E23: Exit 3 | F23: Exit 4 | G23: Exit 5
B24: Target proceeds ($) | C24: =Assumptions!C10*Assumptions!C67 -> 40000000 | D24: =Assumptions!C10*Assumptions!C67 -> 40000000 | E24: =Assumptions!C10*Assumptions!C67 -> 40000000 | F24: =Assumptions!C10*Assumptions!C67 -> 40000000 | G24: =Assumptions!C10*Assumptions!C67 -> 40000000
B25: Required % of F class (= target / F class proceeds) | C25: =C24/C9 -> 1.3333333 | D25: =D24/D9 -> 1.3333333 | E25: =E24/E9 -> 0.89313531 | F25: =F24/F9 -> 0.4461072 | G25: =G24/G9 -> 0.22312328
B26: Required % of post-F FD (equivalent share count) | C26: =C25*C11/C13 -> 0.027939244 | D26: =D25*D11/D13 -> 0.027939244 | E26: =E25*E11/E13 -> 0.018715144 | F26: =F25*F11/F13 -> 0.0093479234 | G26: =G25*G11/G13 -> 0.0046754219
B27: Feasibility (TRUE = achievable) | C27: =IF(AND(C25>0,C25<=1),"feasible","infeasible") -> infeasible | D27: =IF(AND(D25>0,D25<=1),"feasible","infeasible") -> infeasible | E27: =IF(AND(E25>0,E25<=1),"feasible","infeasible") -> feasible | F27: =IF(AND(F25>0,F25<=1),"feasible","infeasible") -> feasible | G27: =IF(AND(G25>0,G25<=1),"feasible","infeasible") -> feasible
B29: Reference: Current ownership (our $10M = 1/3 of F primary)
B30: Current % of F class | C30: =Assumptions!C10/Assumptions!C6 -> 0.33333333
B31: Current % of post-F FD | C31: ='Pro-Forma'!C78 -> 0.006984811
B33: Note: F class proceeds reflect Nash-equilibrium election at each exit (Waterfall row 7, cols J-N).
B34: At low exits where F elects preference, F class total = $30M; required ownership of F approaches 100% (3x) or > 100% (4x, infeasible).
B35: At high exits where F converts, F class total scales with per-share value; required ownership decreases.
