Workbook
Name round_f_pps_usd: Assumptions!$B$120
Name round_post_f_fd_shares: Assumptions!$B$121
Name round_our_fund_shares: Assumptions!$B$140
Name round_f_lead_primary_shares: Assumptions!$B$139
Name ownership_founders_pct: 'Pro-Forma'!$C$4
Name ownership_employees_pct: 'Pro-Forma'!$C$5
Name ownership_options_issued_pct: 'Pro-Forma'!$C$6
Name ownership_options_unissued_pct: 'Pro-Forma'!$C$7
Name ownership_seed_pct: 'Pro-Forma'!$C$8
Name ownership_series_a_pct: 'Pro-Forma'!$C$9
Name ownership_series_b_pct: 'Pro-Forma'!$C$10
Name ownership_series_c_pct: 'Pro-Forma'!$C$11
Name ownership_series_d_pct: 'Pro-Forma'!$C$12
Name ownership_series_e_pct: 'Pro-Forma'!$C$13
Name ownership_note_a_pct: 'Pro-Forma'!$C$14
Name ownership_note_b_pct: 'Pro-Forma'!$C$15
Name ownership_series_f_new_pct: 'Pro-Forma'!$C$16
Name ownership_f_lead_secondary_pct: 'Pro-Forma'!$C$17
Name ownership_our_fund_pct: 'Pro-Forma'!$C$18
Name antidilution_seed_new_conversion_price_usd: 'Pro-Forma'!$C$24
Name antidilution_seed_new_ratio: 'Pro-Forma'!$D$24
Name antidilution_series_a_new_conversion_price_usd: 'Pro-Forma'!$C$25
Name antidilution_series_a_new_ratio: 'Pro-Forma'!$D$25
Name antidilution_series_b_new_conversion_price_usd: 'Pro-Forma'!$C$26
Name antidilution_series_b_new_ratio: 'Pro-Forma'!$D$26
Name antidilution_series_c_new_conversion_price_usd: 'Pro-Forma'!$C$27
Name antidilution_series_c_new_ratio: 'Pro-Forma'!$D$27
Name antidilution_series_d_new_conversion_price_usd: 'Pro-Forma'!$C$28
Name antidilution_series_d_new_ratio: 'Pro-Forma'!$D$28
Name antidilution_series_e_new_conversion_price_usd: 'Pro-Forma'!$C$29
Name antidilution_series_e_new_ratio: 'Pro-Forma'!$D$29
Name notes_note_a_cap_implied_pps_usd: 'Pro-Forma'!$B$33
Name notes_note_a_discount_implied_pps_usd: 'Pro-Forma'!$C$33
Name notes_note_a_conversion_pps_usd: 'Pro-Forma'!$D$33
Name notes_note_a_conversion_branch: 'Pro-Forma'!$E$33
Name notes_note_a_shares_issued: 'Pro-Forma'!$F$33
Name notes_note_b_cap_implied_pps_usd: 'Pro-Forma'!$B$34
Name notes_note_b_discount_implied_pps_usd: 'Pro-Forma'!$C$34
Name notes_note_b_conversion_pps_usd: 'Pro-Forma'!$D$34
Name notes_note_b_conversion_branch: 'Pro-Forma'!$E$34
Name notes_note_b_shares_issued: 'Pro-Forma'!$F$34
Name tender_shares_transferred: 'Pro-Forma'!$B$37
Name tender_usd_to_founders: 'Pro-Forma'!$B$38
Name tender_f_lead_holding_secondary_shares: 'Pro-Forma'!$B$39
Name waterfall_700M_series_f_election: Waterfall!$B$7
Name waterfall_700M_series_e_election: Waterfall!$B$8
Name waterfall_700M_series_d_election: Waterfall!$B$9
Name waterfall_700M_series_c_election: Waterfall!$B$10
Name waterfall_700M_series_b_election: Waterfall!$B$11
Name waterfall_700M_series_a_election: Waterfall!$B$12
Name waterfall_700M_seed_election: Waterfall!$B$13
Name waterfall_700M_series_f_dollars: Waterfall!$B$16
Name waterfall_700M_series_e_dollars: Waterfall!$B$17
Name waterfall_700M_series_d_dollars: Waterfall!$B$18
Name waterfall_700M_series_c_dollars: Waterfall!$B$19
Name waterfall_700M_series_b_dollars: Waterfall!$B$20
Name waterfall_700M_series_a_dollars: Waterfall!$B$21
Name waterfall_700M_seed_dollars: Waterfall!$B$22
Name waterfall_700M_notes_dollars: Waterfall!$B$23
Name waterfall_700M_common_dollars: Waterfall!$B$24

Sheet Assumptions
A1: Kelvin Dynamics v4 - locked inputs and derived constants
A3: Pre-F (post-E) state, locked from v3 truth.json
A4: F1 founder shares | B4: 4000000
A5: F2 founder shares | B5: 2500000
A6: F3 founder shares | B6: 1500000
A7: Founders total | B7: =B4+B5+B6
A8: RSAs (E1-E10) | B8: 1000000
A9: Common total | B9: =B7+B8
A11: Seed shares (as-conv ratio=1) | B11: 5000000
A12: Series A shares | B12: 5000000
A13: Series B shares | B13: 3000000
A14: Series C shares | B14: 2400000
A15: Series D shares (v3-adj base) | B15: 1720627.4
A16: Series E shares (post-v3 fixed pt) | B16: 6102950.3
A17: Options issued (post-E) | B17: 2500000
A18: Options unissued (post-E) | B18: 1894124.2
A19: Pre-F FD total (T_E) | B19: 36617702
A21: Prior-round OCPs and preferences
A22: Seed OCP | B22: 1
A23: A OCP | B23: 3
A24: B OCP | B24: 10
A25: C OCP | B25: 25
A26: D OCP (v4: post-E NCP_D) | B26: 58.118347
A27: E OCP (= E PPS) | B27: 49.156553
A28: Seed preference $ | B28: 5000000
A29: A preference $ | B29: 15000000
A30: B preference $ | B30: 30000000
A31: C preference $ | B31: 60000000
A32: D preference $ | B32: 100000000
A33: E preference $ | B33: 300000000
A35: D shares (original, pre any AD) | B35: 1666667
A36: Compound r_D(v3) = adj/orig | B36: =B15/B35
A37: Options strike | B37: 0.5
A39: Series F terms
A40: F pre-money $ | B40: 1400000000
A41: F primary raise $ | B41: 30000000
A42: F post-money $ | B42: =B40+B41
A43: F secondary tender $ | B43: 15000000
A44: Tender PPS multiplier | B44: 0.85
A45: ESOP target post-F | B45: 0.13
...

Sheet Pro-Forma
A1: Pro-Forma cap table (post Series F close)
A3: Class | B3: Shares (FD) | C3: %
A4: Founders (F1+F2+F3, post-tender) | B4: =Assumptions!$B$149 | C4: =B4/Assumptions!$B$121
A5: Employees (RSAs) | B5: =Assumptions!$B$8 | C5: =B5/Assumptions!$B$121
A6: Options issued | B6: =Assumptions!$B$153 | C6: =B6/Assumptions!$B$121
A7: Options unissued | B7: =Assumptions!$B$152 | C7: =B7/Assumptions!$B$121
A8: Seed (as-conv, ratio=1) | B8: =Assumptions!$B$11 | C8: =B8/Assumptions!$B$121
A9: Series A (as-conv, ratio=1) | B9: =Assumptions!$B$12 | C9: =B9/Assumptions!$B$121
A10: Series B (as-conv, ratio=1) | B10: =Assumptions!$B$13 | C10: =B10/Assumptions!$B$121
A11: Series C (as-conv, ratio=1) | B11: =Assumptions!$B$14 | C11: =B11/Assumptions!$B$121
A12: Series D (compound v3*v4 ratio) | B12: =Assumptions!$B$129 | C12: =B12/Assumptions!$B$121
A13: Series E (v4-adjusted) | B13: =Assumptions!$B$128 | C13: =B13/Assumptions!$B$121
A14: Note A converted | B14: =Assumptions!$B$133 | C14: =B14/Assumptions!$B$121
A15: Note B converted | B15: =Assumptions!$B$137 | C15: =B15/Assumptions!$B$121
A16: Series F primary new (lead + our fund) | B16: =Assumptions!$B$141 | C16: =B16/Assumptions!$B$121
A17: F_LEAD secondary (common from founders) | B17: =Assumptions!$B$157 | C17: =B17/Assumptions!$B$121
A18: Our fund (subset of F primary) | B18: =Assumptions!$B$140 | C18: =B18/Assumptions!$B$121
A20: Sum check (rows 4-17, excludes our_fund subset) | B20: =SUM(B4:B17) | C20: =SUM(C4:C17)
A22: Anti-dilution adjustments (F_PPS vs OCP_class)
A23: Class | B23: Trigger (1=fired) | C23: new_conversion_price_usd | D23: new_ratio
A24: Seed | B24: =IF(Assumptions!$B$120<Assumptions!$B$22,1,0) | C24: =IF(Assumptions!$B$120<Assumptions!$B$22,Assumptions!$B$22*(Assumptions!$B$64+Assumptions!$B$41/Assumptions!$B$22)/(Assumptions!$B$64+Assumptions!$B$122),Assumptions!$B$22) | D24: =Assumptions!$B$22/C24
A25: Series A | B25: =IF(Assumptions!$B$120<Assumptions!$B$23,1,0) | C25: =IF(Assumptions!$B$120<Assumptions!$B$23,Assumptions!$B$23*(Assumptions!$B$64+Assumptions!$B$41/Assumptions!$B$23)/(Assumptions!$B$64+Assumptions!$B$122),Assumptions!$B$23) | D25: =Assumptions!$B$23/C25
A26: Series B | B26: =IF(Assumptions!$B$120<Assumptions!$B$24,1,0) | C26: =IF(Assumptions!$B$120<Assumptions!$B$24,Assumptions!$B$24*(Assumptions!$B$64+Assumptions!$B$41/Assumptions!$B$24)/(Assumptions!$B$64+Assumptions!$B$122),Assumptions!$B$24) | D26: =Assumptions!$B$24/C26
A27: Series C | B27: =IF(Assumptions!$B$120<Assumptions!$B$25,1,0) | C27: =IF(Assumptions!$B$120<Assumptions!$B$25,Assumptions!$B$25*(Assumptions!$B$64+Assumptions!$B$41/Assumptions!$B$25)/(Assumptions!$B$64+Assumptions!$B$122),Assumptions!$B$25) | D27: =Assumptions!$B$25/C27
A28: Series D | B28: =IF(Assumptions!$B$120<Assumptions!$B$26,1,0) | C28: =IF(Assumptions!$B$120<Assumptions!$B$26,Assumptions!$B$127,Assumptions!$B$26) | D28: =Assumptions!$B$36*Assumptions!$B$125
A29: Series E | B29: =IF(Assumptions!$B$120<Assumptions!$B$27,1,0) | C29: =IF(Assumptions!$B$120<Assumptions!$B$27,Assumptions!$B$126,Assumptions!$B$27) | D29: =Assumptions!$B$124
A31: Convertible note conversions
A32: Note | B32: cap_implied_pps_usd | C32: discount_implied_pps_usd | D32: conversion_pps_usd | E32: conversion_branch | F32: shares_issued
A33: Note A | B33: =Assumptions!$B$130 | C33: =Assumptions!$B$131 | D33: =MIN(B33,C33) | E33: =IF(B33<C33,"cap","discount") | F33: =ROUND(Assumptions!$B$50/D33,0)
A34: Note B | B34: =Assumptions!$B$134 | C34: =Assumptions!$B$135 | D34: =MIN(B34,C34) | E34: =IF(B34<C34,"cap","discount") | F34: =ROUND(Assumptions!$B$53/D34,0)
A36: Tender mechanics
A37: shares_transferred | B37: =Assumptions!$B$143
A38: usd_to_founders | B38: =Assumptions!$B$43
A39: f_lead_holding_secondary_shares | B39: =Assumptions!$B$143

Sheet Waterfall
A1: Liquidation waterfall (election iteration converges per exit)
A3: Exit | B3: 700M | C3: 1200M | D3: 2000M | E3: 4000M | F3: 8000M
A4: Exit value $ | B4: =Assumptions!$B$58 | C4: =Assumptions!$B$59 | D4: =Assumptions!$B$60 | E4: =Assumptions!$B$61 | F4: =Assumptions!$B$62
A6: Nash combo offset | B6: =MATCH(1,$AX$51:$AX$178,0) | C6: =MATCH(1,$AX$179:$AX$306,0) | D6: =MATCH(1,$AX$307:$AX$434,0) | E6: =MATCH(1,$AX$435:$AX$562,0) | F6: =MATCH(1,$AX$563:$AX$690,0)
A7: series_f_election | B7: =IF(INDEX($AY$51:$AY$178,B$6)>INDEX($BF$51:$BF$178,B$6),"preference","convert") | C7: =IF(INDEX($AY$179:$AY$306,C$6)>INDEX($BF$179:$BF$306,C$6),"preference","convert") | D7: =IF(INDEX($AY$307:$AY$434,D$6)>INDEX($BF$307:$BF$434,D$6),"preference","convert") | E7: =IF(INDEX($AY$435:$AY$562,E$6)>INDEX($BF$435:$BF$562,E$6),"preference","convert") | F7: =IF(INDEX($AY$563:$AY$690,F$6)>INDEX($BF$563:$BF$690,F$6),"preference","convert")
A8: series_e_election | B8: =IF(INDEX($AZ$51:$AZ$178,B$6)>INDEX($BG$51:$BG$178,B$6),"preference","convert") | C8: =IF(INDEX($AZ$179:$AZ$306,C$6)>INDEX($BG$179:$BG$306,C$6),"preference","convert") | D8: =IF(INDEX($AZ$307:$AZ$434,D$6)>INDEX($BG$307:$BG$434,D$6),"preference","convert") | E8: =IF(INDEX($AZ$435:$AZ$562,E$6)>INDEX($BG$435:$BG$562,E$6),"preference","convert") | F8: =IF(INDEX($AZ$563:$AZ$690,F$6)>INDEX($BG$563:$BG$690,F$6),"preference","convert")
A9: series_d_election | B9: =IF(INDEX($BA$51:$BA$178,B$6)>INDEX($BH$51:$BH$178,B$6),"preference","convert") | C9: =IF(INDEX($BA$179:$BA$306,C$6)>INDEX($BH$179:$BH$306,C$6),"preference","convert") | D9: =IF(INDEX($BA$307:$BA$434,D$6)>INDEX($BH$307:$BH$434,D$6),"preference","convert") | E9: =IF(INDEX($BA$435:$BA$562,E$6)>INDEX($BH$435:$BH$562,E$6),"preference","convert") | F9: =IF(INDEX($BA$563:$BA$690,F$6)>INDEX($BH$563:$BH$690,F$6),"preference","convert")
A10: series_c_election | B10: =IF(INDEX($BB$51:$BB$178,B$6)>INDEX($BI$51:$BI$178,B$6),"preference","convert") | C10: =IF(INDEX($BB$179:$BB$306,C$6)>INDEX($BI$179:$BI$306,C$6),"preference","convert") | D10: =IF(INDEX($BB$307:$BB$434,D$6)>INDEX($BI$307:$BI$434,D$6),"preference","convert") | E10: =IF(INDEX($BB$435:$BB$562,E$6)>INDEX($BI$435:$BI$562,E$6),"preference","convert") | F10: =IF(INDEX($BB$563:$BB$690,F$6)>INDEX($BI$563:$BI$690,F$6),"preference","convert")
A11: series_b_election | B11: =IF(INDEX($BC$51:$BC$178,B$6)>INDEX($BJ$51:$BJ$178,B$6),"preference","convert") | C11: =IF(INDEX($BC$179:$BC$306,C$6)>INDEX($BJ$179:$BJ$306,C$6),"preference","convert") | D11: =IF(INDEX($BC$307:$BC$434,D$6)>INDEX($BJ$307:$BJ$434,D$6),"preference","convert") | E11: =IF(INDEX($BC$435:$BC$562,E$6)>INDEX($BJ$435:$BJ$562,E$6),"preference","convert") | F11: =IF(INDEX($BC$563:$BC$690,F$6)>INDEX($BJ$563:$BJ$690,F$6),"preference","convert")
A12: series_a_election | B12: =IF(INDEX($BD$51:$BD$178,B$6)>INDEX($BK$51:$BK$178,B$6),"preference","convert") | C12: =IF(INDEX($BD$179:$BD$306,C$6)>INDEX($BK$179:$BK$306,C$6),"preference","convert") | D12: =IF(INDEX($BD$307:$BD$434,D$6)>INDEX($BK$307:$BK$434,D$6),"preference","convert") | E12: =IF(INDEX($BD$435:$BD$562,E$6)>INDEX($BK$435:$BK$562,E$6),"preference","convert") | F12: =IF(INDEX($BD$563:$BD$690,F$6)>INDEX($BK$563:$BK$690,F$6),"preference","convert")
A13: seed_election | B13: =IF(INDEX($BE$51:$BE$178,B$6)>INDEX($BL$51:$BL$178,B$6),"preference","convert") | C13: =IF(INDEX($BE$179:$BE$306,C$6)>INDEX($BL$179:$BL$306,C$6),"preference","convert") | D13: =IF(INDEX($BE$307:$BE$434,D$6)>INDEX($BL$307:$BL$434,D$6),"preference","convert") | E13: =IF(INDEX($BE$435:$BE$562,E$6)>INDEX($BL$435:$BL$562,E$6),"preference","convert") | F13: =IF(INDEX($BE$563:$BE$690,F$6)>INDEX($BL$563:$BL$690,F$6),"preference","convert")
A16: series_f_dollars | B16: =INDEX($Q$51:$Q$178,B$6) | C16: =INDEX($Q$179:$Q$306,C$6) | D16: =INDEX($Q$307:$Q$434,D$6) | E16: =INDEX($Q$435:$Q$562,E$6) | F16: =INDEX($Q$563:$Q$690,F$6)
A17: series_e_dollars | B17: =INDEX($R$51:$R$178,B$6) | C17: =INDEX($R$179:$R$306,C$6) | D17: =INDEX($R$307:$R$434,D$6) | E17: =INDEX($R$435:$R$562,E$6) | F17: =INDEX($R$563:$R$690,F$6)
A18: series_d_dollars | B18: =INDEX($S$51:$S$178,B$6) | C18: =INDEX($S$179:$S$306,C$6) | D18: =INDEX($S$307:$S$434,D$6) | E18: =INDEX($S$435:$S$562,E$6) | F18: =INDEX($S$563:$S$690,F$6)
A19: series_c_dollars | B19: =INDEX($T$51:$T$178,B$6) | C19: =INDEX($T$179:$T$306,C$6) | D19: =INDEX($T$307:$T$434,D$6) | E19: =INDEX($T$435:$T$562,E$6) | F19: =INDEX($T$563:$T$690,F$6)
A20: series_b_dollars | B20: =INDEX($U$51:$U$178,B$6) | C20: =INDEX($U$179:$U$306,C$6) | D20: =INDEX($U$307:$U$434,D$6) | E20: =INDEX($U$435:$U$562,E$6) | F20: =INDEX($U$563:$U$690,F$6)
A21: series_a_dollars | B21: =INDEX($V$51:$V$178,B$6) | C21: =INDEX($V$179:$V$306,C$6) | D21: =INDEX($V$307:$V$434,D$6) | E21: =INDEX($V$435:$V$562,E$6) | F21: =INDEX($V$563:$V$690,F$6)
A22: seed_dollars | B22: =INDEX($W$51:$W$178,B$6) | C22: =INDEX($W$179:$W$306,C$6) | D22: =INDEX($W$307:$W$434,D$6) | E22: =INDEX($W$435:$W$562,E$6) | F22: =INDEX($W$563:$W$690,F$6)
A23: notes_dollars | B23: =INDEX($X$51:$X$178,B$6) | C23: =INDEX($X$179:$X$306,C$6) | D23: =INDEX($X$307:$X$434,D$6) | E23: =INDEX($X$435:$X$562,E$6) | F23: =INDEX($X$563:$X$690,F$6)
A24: common_dollars | B24: =INDEX($Y$51:$Y$178,B$6) | C24: =INDEX($Y$179:$Y$306,C$6) | D24: =INDEX($Y$307:$Y$434,D$6) | E24: =INDEX($Y$435:$Y$562,E$6) | F24: =INDEX($Y$563:$Y$690,F$6)
A25: options_issued_dollars | B25: =INDEX($Z$51:$Z$178,B$6) | C25: =INDEX($Z$179:$Z$306,C$6) | D25: =INDEX($Z$307:$Z$434,D$6) | E25: =INDEX($Z$435:$Z$562,E$6) | F25: =INDEX($Z$563:$Z$690,F$6)
A26: our_fund_dollars | B26: =B16*Assumptions!$B$140/Assumptions!$B$141 | C26: =C16*Assumptions!$B$140/Assumptions!$B$141 | D26: =D16*Assumptions!$B$140/Assumptions!$B$141 | E26: =E16*Assumptions!$B$140/Assumptions!$B$141 | F26: =F16*Assumptions!$B$140/Assumptions!$B$141
A27: total_distributed | B27: =B16+B17+B18+B19+B20+B21+B22+B23+B24+B25 | C27: =C16+C17+C18+C19+C20+C21+C22+C23+C24+C25 | D27: =D16+D17+D18+D19+D20+D21+D22+D23+D24+D25 | E27: =E16+E17+E18+E19+E20+E21+E22+E23+E24+E25 | F27: =F16+F17+F18+F19+F20+F21+F22+F23+F24+F25
A50: exit_tag | B50: exit_val | C50: e_F | D50: e_E | E50: e_D | F50: e_C | G50: e_B | H50: e_A | I50: e_Seed | J50: pref_pool | K50: conv_shares | L50: pool_after_pref | M50: opts_itm | N50: denom | O50: pool_adj | P50: pps | Q50: F_usd | R50: E_usd | S50: D_usd | T50: C_usd | U50: B_usd | V50: A_usd | W50: Seed_usd | X50: notes_usd | Y50: common_usd | Z50: opts_issued_usd | AA50: total_dist | AB50: row_idx | AC50: fF | AD50: fE | AE50: fD | AF50: fC | AG50: fB | AH50: fA | AI50: fSeed | AJ50: altF | AK50: altE | AL50: altD | AM50: altC | AN50: altB | AO50: altA | AP50: altSeed | AQ50: okF | AR50: okE | AS50: okD | AT50: okC | AU50: okB | AV50: okA | AW50: okSeed | AX50: all_ok | AY50: prefF_v | AZ50: prefE_v | BA50: prefD_v | BB50: prefC_v | BC50: prefB_v | BD50: prefA_v | BE50: prefSeed_v | BF50: convF_v | BG50: convE_v | BH50: convD_v | BI50: convC_v | BJ50: convB_v | BK50: convA_v | BL50: convSeed_v
A51: 700M | B51: =Assumptions!$B$58 | C51: 0 | D51: 0 | E51: 0 | F51: 0 | G51: 0 | H51: 0 | I51: 0 | J51: =(1-C51)*Assumptions!$B$41+(1-D51)*Assumptions!$B$33+(1-E51)*Assumptions!$B$32+(1-F51)*Assumptions!$B$31+(1-G51)*Assumptions!$B$30+(1-H51)*Assumptions!$B$29+(1-I51)*Assumptions!$B$28 | K51: =C51*Assumptions!$B$141+D51*Assumptions!$B$128+E51*Assumptions!$B$129+F51*Assumptions!$B$14+G51*Assumptions!$B$13+H51*Assumptions!$B$12+I51*Assumptions!$B$11+Assumptions!$B$133+Assumptions!$B$137+Assumptions!$B$9 | L51: =B51-J51 | M51: =IF(K51>0,IF(L51/K51>=Assumptions!$B$37,1,0),0) | N51: =K51+M51*Assumptions!$B$153 | O51: =L51+M51*Assumptions!$B$153*Assumptions!$B$37 | P51: =IF(N51>0,O51/N51,0) | Q51: =IF(C51=1,P51*Assumptions!$B$141,Assumptions!$B$41) | R51: =IF(D51=1,P51*Assumptions!$B$128,Assumptions!$B$33) | S51: =IF(E51=1,P51*Assumptions!$B$129,Assumptions!$B$32) | T51: =IF(F51=1,P51*Assumptions!$B$14,Assumptions!$B$31) | U51: =IF(G51=1,P51*Assumptions!$B$13,Assumptions!$B$30) | V51: =IF(H51=1,P51*Assumptions!$B$12,Assumptions!$B$29) | W51: =IF(I51=1,P51*Assumptions!$B$11,Assumptions!$B$28) | X51: =P51*(Assumptions!$B$133+Assumptions!$B$137) | Y51: =P51*Assumptions!$B$9 | Z51: =IF(M51=1,(P51-Assumptions!$B$37)*Assumptions!$B$153,0) | AA51: =Q51+R51+S51+T51+U51+V51+W51+X51+Y51+Z51 | AB51: 0 | AC51: 64 | AD51: 32 | AE51: 16 | AF51: 8 | AG51: 4 | AH51: 2 | AI51: 1 | AJ51: =INDEX($Q$51:$Q$178,AC51+1) | AK51: =INDEX($R$51:$R$178,AD51+1) | AL51: =INDEX($S$51:$S$178,AE51+1) | AM51: =INDEX($T$51:$T$178,AF51+1) | AN51: =INDEX($U$51:$U$178,AG51+1) | AO51: =INDEX($V$51:$V$178,AH51+1) | AP51: =INDEX($W$51:$W$178,AI51+1) | AQ51: =IF(Q51>=AJ51-0.01,1,0) | AR51: =IF(R51>=AK51-0.01,1,0) | AS51: =IF(S51>=AL51-0.01,1,0) | AT51: =IF(T51>=AM51-0.01,1,0) | AU51: =IF(U51>=AN51-0.01,1,0) | AV51: =IF(V51>=AO51-0.01,1,0) | AW51: =IF(W51>=AP51-0.01,1,0) | AX51: =AQ51*AR51*AS51*AT51*AU51*AV51*AW51 | AY51: =Assumptions!$B$41 | AZ51: =Assumptions!$B$33 | BA51: =Assumptions!$B$32 | BB51: =Assumptions!$B$31 | BC51: =Assumptions!$B$30 | BD51: =Assumptions!$B$29 | BE51: =Assumptions!$B$28 | BF51: =P51*Assumptions!$B$141 | BG51: =P51*Assumptions!$B$128 | BH51: =P51*Assumptions!$B$129 | BI51: =P51*Assumptions!$B$14 | BJ51: =P51*Assumptions!$B$13 | BK51: =P51*Assumptions!$B$12 | BL51: =P51*Assumptions!$B$11
A52: 700M | B52: =Assumptions!$B$58 | C52: 0 | D52: 0 | E52: 0 | F52: 0 | G52: 0 | H52: 0 | I52: 1 | J52: =(1-C52)*Assumptions!$B$41+(1-D52)*Assumptions!$B$33+(1-E52)*Assumptions!$B$32+(1-F52)*Assumptions!$B$31+(1-G52)*Assumptions!$B$30+(1-H52)*Assumptions!$B$29+(1-I52)*Assumptions!$B$28 | K52: =C52*Assumptions!$B$141+D52*Assumptions!$B$128+E52*Assumptions!$B$129+F52*Assumptions!$B$14+G52*Assumptions!$B$13+H52*Assumptions!$B$12+I52*Assumptions!$B$11+Assumptions!$B$133+Assumptions!$B$137+Assumptions!$B$9 | L52: =B52-J52 | M52: =IF(K52>0,IF(L52/K52>=Assumptions!$B$37,1,0),0) | N52: =K52+M52*Assumptions!$B$153 | O52: =L52+M52*Assumptions!$B$153*Assumptions!$B$37 | P52: =IF(N52>0,O52/N52,0) | Q52: =IF(C52=1,P52*Assumptions!$B$141,Assumptions!$B$41) | R52: =IF(D52=1,P52*Assumptions!$B$128,Assumptions!$B$33) | S52: =IF(E52=1,P52*Assumptions!$B$129,Assumptions!$B$32) | T52: =IF(F52=1,P52*Assumptions!$B$14,Assumptions!$B$31) | U52: =IF(G52=1,P52*Assumptions!$B$13,Assumptions!$B$30) | V52: =IF(H52=1,P52*Assumptions!$B$12,Assumptions!$B$29) | W52: =IF(I52=1,P52*Assumptions!$B$11,Assumptions!$B$28) | X52: =P52*(Assumptions!$B$133+Assumptions!$B$137) | Y52: =P52*Assumptions!$B$9 | Z52: =IF(M52=1,(P52-Assumptions!$B$37)*Assumptions!$B$153,0) | AA52: =Q52+R52+S52+T52+U52+V52+W52+X52+Y52+Z52 | AB52: 1 | AC52: 65 | AD52: 33 | AE52: 17 | AF52: 9 | AG52: 5 | AH52: 3 | AI52: 0 | AJ52: =INDEX($Q$51:$Q$178,AC52+1) | AK52: =INDEX($R$51:$R$178,AD52+1) | AL52: =INDEX($S$51:$S$178,AE52+1) | AM52: =INDEX($T$51:$T$178,AF52+1) | AN52: =INDEX($U$51:$U$178,AG52+1) | AO52: =INDEX($V$51:$V$178,AH52+1) | AP52: =INDEX($W$51:$W$178,AI52+1) | AQ52: =IF(Q52>=AJ52-0.01,1,0) | AR52: =IF(R52>=AK52-0.01,1,0) | AS52: =IF(S52>=AL52-0.01,1,0) | AT52: =IF(T52>=AM52-0.01,1,0) | AU52: =IF(U52>=AN52-0.01,1,0) | AV52: =IF(V52>=AO52-0.01,1,0) | AW52: =IF(W52>=AP52-0.01,1,0) | AX52: =AQ52*AR52*AS52*AT52*AU52*AV52*AW52 | AY52: =Assumptions!$B$41 | AZ52: =Assumptions!$B$33 | BA52: =Assumptions!$B$32 | BB52: =Assumptions!$B$31 | BC52: =Assumptions!$B$30 | BD52: =Assumptions!$B$29 | BE52: =Assumptions!$B$28 | BF52: =P52*Assumptions!$B$141 | BG52: =P52*Assumptions!$B$128 | BH52: =P52*Assumptions!$B$129 | BI52: =P52*Assumptions!$B$14 | BJ52: =P52*Assumptions!$B$13 | BK52: =P52*Assumptions!$B$12 | BL52: =P52*Assumptions!$B$11
A53: 700M | B53: =Assumptions!$B$58 | C53: 0 | D53: 0 | E53: 0 | F53: 0 | G53: 0 | H53: 1 | I53: 0 | J53: =(1-C53)*Assumptions!$B$41+(1-D53)*Assumptions!$B$33+(1-E53)*Assumptions!$B$32+(1-F53)*Assumptions!$B$31+(1-G53)*Assumptions!$B$30+(1-H53)*Assumptions!$B$29+(1-I53)*Assumptions!$B$28 | K53: =C53*Assumptions!$B$141+D53*Assumptions!$B$128+E53*Assumptions!$B$129+F53*Assumptions!$B$14+G53*Assumptions!$B$13+H53*Assumptions!$B$12+I53*Assumptions!$B$11+Assumptions!$B$133+Assumptions!$B$137+Assumptions!$B$9 | L53: =B53-J53 | M53: =IF(K53>0,IF(L53/K53>=Assumptions!$B$37,1,0),0) | N53: =K53+M53*Assumptions!$B$153 | O53: =L53+M53*Assumptions!$B$153*Assumptions!$B$37 | P53: =IF(N53>0,O53/N53,0) | Q53: =IF(C53=1,P53*Assumptions!$B$141,Assumptions!$B$41) | R53: =IF(D53=1,P53*Assumptions!$B$128,Assumptions!$B$33) | S53: =IF(E53=1,P53*Assumptions!$B$129,Assumptions!$B$32) | T53: =IF(F53=1,P53*Assumptions!$B$14,Assumptions!$B$31) | U53: =IF(G53=1,P53*Assumptions!$B$13,Assumptions!$B$30) | V53: =IF(H53=1,P53*Assumptions!$B$12,Assumptions!$B$29) | W53: =IF(I53=1,P53*Assumptions!$B$11,Assumptions!$B$28) | X53: =P53*(Assumptions!$B$133+Assumptions!$B$137) | Y53: =P53*Assumptions!$B$9 | Z53: =IF(M53=1,(P53-Assumptions!$B$37)*Assumptions!$B$153,0) | AA53: =Q53+R53+S53+T53+U53+V53+W53+X53+Y53+Z53 | AB53: 2 | AC53: 66 | AD53: 34 | AE53: 18 | AF53: 10 | AG53: 6 | AH53: 0 | AI53: 3 | AJ53: =INDEX($Q$51:$Q$178,AC53+1) | AK53: =INDEX($R$51:$R$178,AD53+1) | AL53: =INDEX($S$51:$S$178,AE53+1) | AM53: =INDEX($T$51:$T$178,AF53+1) | AN53: =INDEX($U$51:$U$178,AG53+1) | AO53: =INDEX($V$51:$V$178,AH53+1) | AP53: =INDEX($W$51:$W$178,AI53+1) | AQ53: =IF(Q53>=AJ53-0.01,1,0) | AR53: =IF(R53>=AK53-0.01,1,0) | AS53: =IF(S53>=AL53-0.01,1,0) | AT53: =IF(T53>=AM53-0.01,1,0) | AU53: =IF(U53>=AN53-0.01,1,0) | AV53: =IF(V53>=AO53-0.01,1,0) | AW53: =IF(W53>=AP53-0.01,1,0) | AX53: =AQ53*AR53*AS53*AT53*AU53*AV53*AW53 | AY53: =Assumptions!$B$41 | AZ53: =Assumptions!$B$33 | BA53: =Assumptions!$B$32 | BB53: =Assumptions!$B$31 | BC53: =Assumptions!$B$30 | BD53: =Assumptions!$B$29 | BE53: =Assumptions!$B$28 | BF53: =P53*Assumptions!$B$141 | BG53: =P53*Assumptions!$B$128 | BH53: =P53*Assumptions!$B$129 | BI53: =P53*Assumptions!$B$14 | BJ53: =P53*Assumptions!$B$13 | BK53: =P53*Assumptions!$B$12 | BL53: =P53*Assumptions!$B$11
A54: 700M | B54: =Assumptions!$B$58 | C54: 0 | D54: 0 | E54: 0 | F54: 0 | G54: 0 | H54: 1 | I54: 1 | J54: =(1-C54)*Assumptions!$B$41+(1-D54)*Assumptions!$B$33+(1-E54)*Assumptions!$B$32+(1-F54)*Assumptions!$B$31+(1-G54)*Assumptions!$B$30+(1-H54)*Assumptions!$B$29+(1-I54)*Assumptions!$B$28 | K54: =C54*Assumptions!$B$141+D54*Assumptions!$B$128+E54*Assumptions!$B$129+F54*Assumptions!$B$14+G54*Assumptions!$B$13+H54*Assumptions!$B$12+I54*Assumptions!$B$11+Assumptions!$B$133+Assumptions!$B$137+Assumptions!$B$9 | L54: =B54-J54 | M54: =IF(K54>0,IF(L54/K54>=Assumptions!$B$37,1,0),0) | N54: =K54+M54*Assumptions!$B$153 | O54: =L54+M54*Assumptions!$B$153*Assumptions!$B$37 | P54: =IF(N54>0,O54/N54,0) | Q54: =IF(C54=1,P54*Assumptions!$B$141,Assumptions!$B$41) | R54: =IF(D54=1,P54*Assumptions!$B$128,Assumptions!$B$33) | S54: =IF(E54=1,P54*Assumptions!$B$129,Assumptions!$B$32) | T54: =IF(F54=1,P54*Assumptions!$B$14,Assumptions!$B$31) | U54: =IF(G54=1,P54*Assumptions!$B$13,Assumptions!$B$30) | V54: =IF(H54=1,P54*Assumptions!$B$12,Assumptions!$B$29) | W54: =IF(I54=1,P54*Assumptions!$B$11,Assumptions!$B$28) | X54: =P54*(Assumptions!$B$133+Assumptions!$B$137) | Y54: =P54*Assumptions!$B$9 | Z54: =IF(M54=1,(P54-Assumptions!$B$37)*Assumptions!$B$153,0) | AA54: =Q54+R54+S54+T54+U54+V54+W54+X54+Y54+Z54 | AB54: 3 | AC54: 67 | AD54: 35 | AE54: 19 | AF54: 11 | AG54: 7 | AH54: 1 | AI54: 2 | AJ54: =INDEX($Q$51:$Q$178,AC54+1) | AK54: =INDEX($R$51:$R$178,AD54+1) | AL54: =INDEX($S$51:$S$178,AE54+1) | AM54: =INDEX($T$51:$T$178,AF54+1) | AN54: =INDEX($U$51:$U$178,AG54+1) | AO54: =INDEX($V$51:$V$178,AH54+1) | AP54: =INDEX($W$51:$W$178,AI54+1) | AQ54: =IF(Q54>=AJ54-0.01,1,0) | AR54: =IF(R54>=AK54-0.01,1,0) | AS54: =IF(S54>=AL54-0.01,1,0) | AT54: =IF(T54>=AM54-0.01,1,0) | AU54: =IF(U54>=AN54-0.01,1,0) | AV54: =IF(V54>=AO54-0.01,1,0) | AW54: =IF(W54>=AP54-0.01,1,0) | AX54: =AQ54*AR54*AS54*AT54*AU54*AV54*AW54 | AY54: =Assumptions!$B$41 | AZ54: =Assumptions!$B$33 | BA54: =Assumptions!$B$32 | BB54: =Assumptions!$B$31 | BC54: =Assumptions!$B$30 | BD54: =Assumptions!$B$29 | BE54: =Assumptions!$B$28 | BF54: =P54*Assumptions!$B$141 | BG54: =P54*Assumptions!$B$128 | BH54: =P54*Assumptions!$B$129 | BI54: =P54*Assumptions!$B$14 | BJ54: =P54*Assumptions!$B$13 | BK54: =P54*Assumptions!$B$12 | BL54: =P54*Assumptions!$B$11
A55: 700M | B55: =Assumptions!$B$58 | C55: 0 | D55: 0 | E55: 0 | F55: 0 | G55: 1 | H55: 0 | I55: 0 | J55: =(1-C55)*Assumptions!$B$41+(1-D55)*Assumptions!$B$33+(1-E55)*Assumptions!$B$32+(1-F55)*Assumptions!$B$31+(1-G55)*Assumptions!$B$30+(1-H55)*Assumptions!$B$29+(1-I55)*Assumptions!$B$28 | K55: =C55*Assumptions!$B$141+D55*Assumptions!$B$128+E55*Assumptions!$B$129+F55*Assumptions!$B$14+G55*Assumptions!$B$13+H55*Assumptions!$B$12+I55*Assumptions!$B$11+Assumptions!$B$133+Assumptions!$B$137+Assumptions!$B$9 | L55: =B55-J55 | M55: =IF(K55>0,IF(L55/K55>=Assumptions!$B$37,1,0),0) | N55: =K55+M55*Assumptions!$B$153 | O55: =L55+M55*Assumptions!$B$153*Assumptions!$B$37 | P55: =IF(N55>0,O55/N55,0) | Q55: =IF(C55=1,P55*Assumptions!$B$141,Assumptions!$B$41) | R55: =IF(D55=1,P55*Assumptions!$B$128,Assumptions!$B$33) | S55: =IF(E55=1,P55*Assumptions!$B$129,Assumptions!$B$32) | T55: =IF(F55=1,P55*Assumptions!$B$14,Assumptions!$B$31) | U55: =IF(G55=1,P55*Assumptions!$B$13,Assumptions!$B$30) | V55: =IF(H55=1,P55*Assumptions!$B$12,Assumptions!$B$29) | W55: =IF(I55=1,P55*Assumptions!$B$11,Assumptions!$B$28) | X55: =P55*(Assumptions!$B$133+Assumptions!$B$137) | Y55: =P55*Assumptions!$B$9 | Z55: =IF(M55=1,(P55-Assumptions!$B$37)*Assumptions!$B$153,0) | AA55: =Q55+R55+S55+T55+U55+V55+W55+X55+Y55+Z55 | AB55: 4 | AC55: 68 | AD55: 36 | AE55: 20 | AF55: 12 | AG55: 0 | AH55: 6 | AI55: 5 | AJ55: =INDEX($Q$51:$Q$178,AC55+1) | AK55: =INDEX($R$51:$R$178,AD55+1) | AL55: =INDEX($S$51:$S$178,AE55+1) | AM55: =INDEX($T$51:$T$178,AF55+1) | AN55: =INDEX($U$51:$U$178,AG55+1) | AO55: =INDEX($V$51:$V$178,AH55+1) | AP55: =INDEX($W$51:$W$178,AI55+1) | AQ55: =IF(Q55>=AJ55-0.01,1,0) | AR55: =IF(R55>=AK55-0.01,1,0) | AS55: =IF(S55>=AL55-0.01,1,0) | AT55: =IF(T55>=AM55-0.01,1,0) | AU55: =IF(U55>=AN55-0.01,1,0) | AV55: =IF(V55>=AO55-0.01,1,0) | AW55: =IF(W55>=AP55-0.01,1,0) | AX55: =AQ55*AR55*AS55*AT55*AU55*AV55*AW55 | AY55: =Assumptions!$B$41 | AZ55: =Assumptions!$B$33 | BA55: =Assumptions!$B$32 | BB55: =Assumptions!$B$31 | BC55: =Assumptions!$B$30 | BD55: =Assumptions!$B$29 | BE55: =Assumptions!$B$28 | BF55: =P55*Assumptions!$B$141 | BG55: =P55*Assumptions!$B$128 | BH55: =P55*Assumptions!$B$129 | BI55: =P55*Assumptions!$B$14 | BJ55: =P55*Assumptions!$B$13 | BK55: =P55*Assumptions!$B$12 | BL55: =P55*Assumptions!$B$11
A56: 700M | B56: =Assumptions!$B$58 | C56: 0 | D56: 0 | E56: 0 | F56: 0 | G56: 1 | H56: 0 | I56: 1 | J56: =(1-C56)*Assumptions!$B$41+(1-D56)*Assumptions!$B$33+(1-E56)*Assumptions!$B$32+(1-F56)*Assumptions!$B$31+(1-G56)*Assumptions!$B$30+(1-H56)*Assumptions!$B$29+(1-I56)*Assumptions!$B$28 | K56: =C56*Assumptions!$B$141+D56*Assumptions!$B$128+E56*Assumptions!$B$129+F56*Assumptions!$B$14+G56*Assumptions!$B$13+H56*Assumptions!$B$12+I56*Assumptions!$B$11+Assumptions!$B$133+Assumptions!$B$137+Assumptions!$B$9 | L56: =B56-J56 | M56: =IF(K56>0,IF(L56/K56>=Assumptions!$B$37,1,0),0) | N56: =K56+M56*Assumptions!$B$153 | O56: =L56+M56*Assumptions!$B$153*Assumptions!$B$37 | P56: =IF(N56>0,O56/N56,0) | Q56: =IF(C56=1,P56*Assumptions!$B$141,Assumptions!$B$41) | R56: =IF(D56=1,P56*Assumptions!$B$128,Assumptions!$B$33) | S56: =IF(E56=1,P56*Assumptions!$B$129,Assumptions!$B$32) | T56: =IF(F56=1,P56*Assumptions!$B$14,Assumptions!$B$31) | U56: =IF(G56=1,P56*Assumptions!$B$13,Assumptions!$B$30) | V56: =IF(H56=1,P56*Assumptions!$B$12,Assumptions!$B$29) | W56: =IF(I56=1,P56*Assumptions!$B$11,Assumptions!$B$28) | X56: =P56*(Assumptions!$B$133+Assumptions!$B$137) | Y56: =P56*Assumptions!$B$9 | Z56: =IF(M56=1,(P56-Assumptions!$B$37)*Assumptions!$B$153,0) | AA56: =Q56+R56+S56+T56+U56+V56+W56+X56+Y56+Z56 | AB56: 5 | AC56: 69 | AD56: 37 | AE56: 21 | AF56: 13 | AG56: 1 | AH56: 7 | AI56: 4 | AJ56: =INDEX($Q$51:$Q$178,AC56+1) | AK56: =INDEX($R$51:$R$178,AD56+1) | AL56: =INDEX($S$51:$S$178,AE56+1) | AM56: =INDEX($T$51:$T$178,AF56+1) | AN56: =INDEX($U$51:$U$178,AG56+1) | AO56: =INDEX($V$51:$V$178,AH56+1) | AP56: =INDEX($W$51:$W$178,AI56+1) | AQ56: =IF(Q56>=AJ56-0.01,1,0) | AR56: =IF(R56>=AK56-0.01,1,0) | AS56: =IF(S56>=AL56-0.01,1,0) | AT56: =IF(T56>=AM56-0.01,1,0) | AU56: =IF(U56>=AN56-0.01,1,0) | AV56: =IF(V56>=AO56-0.01,1,0) | AW56: =IF(W56>=AP56-0.01,1,0) | AX56: =AQ56*AR56*AS56*AT56*AU56*AV56*AW56 | AY56: =Assumptions!$B$41 | AZ56: =Assumptions!$B$33 | BA56: =Assumptions!$B$32 | BB56: =Assumptions!$B$31 | BC56: =Assumptions!$B$30 | BD56: =Assumptions!$B$29 | BE56: =Assumptions!$B$28 | BF56: =P56*Assumptions!$B$141 | BG56: =P56*Assumptions!$B$128 | BH56: =P56*Assumptions!$B$129 | BI56: =P56*Assumptions!$B$14 | BJ56: =P56*Assumptions!$B$13 | BK56: =P56*Assumptions!$B$12 | BL56: =P56*Assumptions!$B$11
A57: 700M | B57: =Assumptions!$B$58 | C57: 0 | D57: 0 | E57: 0 | F57: 0 | G57: 1 | H57: 1 | I57: 0 | J57: =(1-C57)*Assumptions!$B$41+(1-D57)*Assumptions!$B$33+(1-E57)*Assumptions!$B$32+(1-F57)*Assumptions!$B$31+(1-G57)*Assumptions!$B$30+(1-H57)*Assumptions!$B$29+(1-I57)*Assumptions!$B$28 | K57: =C57*Assumptions!$B$141+D57*Assumptions!$B$128+E57*Assumptions!$B$129+F57*Assumptions!$B$14+G57*Assumptions!$B$13+H57*Assumptions!$B$12+I57*Assumptions!$B$11+Assumptions!$B$133+Assumptions!$B$137+Assumptions!$B$9 | L57: =B57-J57 | M57: =IF(K57>0,IF(L57/K57>=Assumptions!$B$37,1,0),0) | N57: =K57+M57*Assumptions!$B$153 | O57: =L57+M57*Assumptions!$B$153*Assumptions!$B$37 | P57: =IF(N57>0,O57/N57,0) | Q57: =IF(C57=1,P57*Assumptions!$B$141,Assumptions!$B$41) | R57: =IF(D57=1,P57*Assumptions!$B$128,Assumptions!$B$33) | S57: =IF(E57=1,P57*Assumptions!$B$129,Assumptions!$B$32) | T57: =IF(F57=1,P57*Assumptions!$B$14,Assumptions!$B$31) | U57: =IF(G57=1,P57*Assumptions!$B$13,Assumptions!$B$30) | V57: =IF(H57=1,P57*Assumptions!$B$12,Assumptions!$B$29) | W57: =IF(I57=1,P57*Assumptions!$B$11,Assumptions!$B$28) | X57: =P57*(Assumptions!$B$133+Assumptions!$B$137) | Y57: =P57*Assumptions!$B$9 | Z57: =IF(M57=1,(P57-Assumptions!$B$37)*Assumptions!$B$153,0) | AA57: =Q57+R57+S57+T57+U57+V57+W57+X57+Y57+Z57 | AB57: 6 | AC57: 70 | AD57: 38 | AE57: 22 | AF57: 14 | AG57: 2 | AH57: 4 | AI57: 7 | AJ57: =INDEX($Q$51:$Q$178,AC57+1) | AK57: =INDEX($R$51:$R$178,AD57+1) | AL57: =INDEX($S$51:$S$178,AE57+1) | AM57: =INDEX($T$51:$T$178,AF57+1) | AN57: =INDEX($U$51:$U$178,AG57+1) | AO57: =INDEX($V$51:$V$178,AH57+1) | AP57: =INDEX($W$51:$W$178,AI57+1) | AQ57: =IF(Q57>=AJ57-0.01,1,0) | AR57: =IF(R57>=AK57-0.01,1,0) | AS57: =IF(S57>=AL57-0.01,1,0) | AT57: =IF(T57>=AM57-0.01,1,0) | AU57: =IF(U57>=AN57-0.01,1,0) | AV57: =IF(V57>=AO57-0.01,1,0) | AW57: =IF(W57>=AP57-0.01,1,0) | AX57: =AQ57*AR57*AS57*AT57*AU57*AV57*AW57 | AY57: =Assumptions!$B$41 | AZ57: =Assumptions!$B$33 | BA57: =Assumptions!$B$32 | BB57: =Assumptions!$B$31 | BC57: =Assumptions!$B$30 | BD57: =Assumptions!$B$29 | BE57: =Assumptions!$B$28 | BF57: =P57*Assumptions!$B$141 | BG57: =P57*Assumptions!$B$128 | BH57: =P57*Assumptions!$B$129 | BI57: =P57*Assumptions!$B$14 | BJ57: =P57*Assumptions!$B$13 | BK57: =P57*Assumptions!$B$12 | BL57: =P57*Assumptions!$B$11
A58: 700M | B58: =Assumptions!$B$58 | C58: 0 | D58: 0 | E58: 0 | F58: 0 | G58: 1 | H58: 1 | I58: 1 | J58: =(1-C58)*Assumptions!$B$41+(1-D58)*Assumptions!$B$33+(1-E58)*Assumptions!$B$32+(1-F58)*Assumptions!$B$31+(1-G58)*Assumptions!$B$30+(1-H58)*Assumptions!$B$29+(1-I58)*Assumptions!$B$28 | K58: =C58*Assumptions!$B$141+D58*Assumptions!$B$128+E58*Assumptions!$B$129+F58*Assumptions!$B$14+G58*Assumptions!$B$13+H58*Assumptions!$B$12+I58*Assumptions!$B$11+Assumptions!$B$133+Assumptions!$B$137+Assumptions!$B$9 | L58: =B58-J58 | M58: =IF(K58>0,IF(L58/K58>=Assumptions!$B$37,1,0),0) | N58: =K58+M58*Assumptions!$B$153 | O58: =L58+M58*Assumptions!$B$153*Assumptions!$B$37 | P58: =IF(N58>0,O58/N58,0) | Q58: =IF(C58=1,P58*Assumptions!$B$141,Assumptions!$B$41) | R58: =IF(D58=1,P58*Assumptions!$B$128,Assumptions!$B$33) | S58: =IF(E58=1,P58*Assumptions!$B$129,Assumptions!$B$32) | T58: =IF(F58=1,P58*Assumptions!$B$14,Assumptions!$B$31) | U58: =IF(G58=1,P58*Assumptions!$B$13,Assumptions!$B$30) | V58: =IF(H58=1,P58*Assumptions!$B$12,Assumptions!$B$29) | W58: =IF(I58=1,P58*Assumptions!$B$11,Assumptions!$B$28) | X58: =P58*(Assumptions!$B$133+Assumptions!$B$137) | Y58: =P58*Assumptions!$B$9 | Z58: =IF(M58=1,(P58-Assumptions!$B$37)*Assumptions!$B$153,0) | AA58: =Q58+R58+S58+T58+U58+V58+W58+X58+Y58+Z58 | AB58: 7 | AC58: 71 | AD58: 39 | AE58: 23 | AF58: 15 | AG58: 3 | AH58: 5 | AI58: 6 | AJ58: =INDEX($Q$51:$Q$178,AC58+1) | AK58: =INDEX($R$51:$R$178,AD58+1) | AL58: =INDEX($S$51:$S$178,AE58+1) | AM58: =INDEX($T$51:$T$178,AF58+1) | AN58: =INDEX($U$51:$U$178,AG58+1) | AO58: =INDEX($V$51:$V$178,AH58+1) | AP58: =INDEX($W$51:$W$178,AI58+1) | AQ58: =IF(Q58>=AJ58-0.01,1,0) | AR58: =IF(R58>=AK58-0.01,1,0) | AS58: =IF(S58>=AL58-0.01,1,0) | AT58: =IF(T58>=AM58-0.01,1,0) | AU58: =IF(U58>=AN58-0.01,1,0) | AV58: =IF(V58>=AO58-0.01,1,0) | AW58: =IF(W58>=AP58-0.01,1,0) | AX58: =AQ58*AR58*AS58*AT58*AU58*AV58*AW58 | AY58: =Assumptions!$B$41 | AZ58: =Assumptions!$B$33 | BA58: =Assumptions!$B$32 | BB58: =Assumptions!$B$31 | BC58: =Assumptions!$B$30 | BD58: =Assumptions!$B$29 | BE58: =Assumptions!$B$28 | BF58: =P58*Assumptions!$B$141 | BG58: =P58*Assumptions!$B$128 | BH58: =P58*Assumptions!$B$129 | BI58: =P58*Assumptions!$B$14 | BJ58: =P58*Assumptions!$B$13 | BK58: =P58*Assumptions!$B$12 | BL58: =P58*Assumptions!$B$11
A59: 700M | B59: =Assumptions!$B$58 | C59: 0 | D59: 0 | E59: 0 | F59: 1 | G59: 0 | H59: 0 | I59: 0 | J59: =(1-C59)*Assumptions!$B$41+(1-D59)*Assumptions!$B$33+(1-E59)*Assumptions!$B$32+(1-F59)*Assumptions!$B$31+(1-G59)*Assumptions!$B$30+(1-H59)*Assumptions!$B$29+(1-I59)*Assumptions!$B$28 | K59: =C59*Assumptions!$B$141+D59*Assumptions!$B$128+E59*Assumptions!$B$129+F59*Assumptions!$B$14+G59*Assumptions!$B$13+H59*Assumptions!$B$12+I59*Assumptions!$B$11+Assumptions!$B$133+Assumptions!$B$137+Assumptions!$B$9 | L59: =B59-J59 | M59: =IF(K59>0,IF(L59/K59>=Assumptions!$B$37,1,0),0) | N59: =K59+M59*Assumptions!$B$153 | O59: =L59+M59*Assumptions!$B$153*Assumptions!$B$37 | P59: =IF(N59>0,O59/N59,0) | Q59: =IF(C59=1,P59*Assumptions!$B$141,Assumptions!$B$41) | R59: =IF(D59=1,P59*Assumptions!$B$128,Assumptions!$B$33) | S59: =IF(E59=1,P59*Assumptions!$B$129,Assumptions!$B$32) | T59: =IF(F59=1,P59*Assumptions!$B$14,Assumptions!$B$31) | U59: =IF(G59=1,P59*Assumptions!$B$13,Assumptions!$B$30) | V59: =IF(H59=1,P59*Assumptions!$B$12,Assumptions!$B$29) | W59: =IF(I59=1,P59*Assumptions!$B$11,Assumptions!$B$28) | X59: =P59*(Assumptions!$B$133+Assumptions!$B$137) | Y59: =P59*Assumptions!$B$9 | Z59: =IF(M59=1,(P59-Assumptions!$B$37)*Assumptions!$B$153,0) | AA59: =Q59+R59+S59+T59+U59+V59+W59+X59+Y59+Z59 | AB59: 8 | AC59: 72 | AD59: 40 | AE59: 24 | AF59: 0 | AG59: 12 | AH59: 10 | AI59: 9 | AJ59: =INDEX($Q$51:$Q$178,AC59+1) | AK59: =INDEX($R$51:$R$178,AD59+1) | AL59: =INDEX($S$51:$S$178,AE59+1) | AM59: =INDEX($T$51:$T$178,AF59+1) | AN59: =INDEX($U$51:$U$178,AG59+1) | AO59: =INDEX($V$51:$V$178,AH59+1) | AP59: =INDEX($W$51:$W$178,AI59+1) | AQ59: =IF(Q59>=AJ59-0.01,1,0) | AR59: =IF(R59>=AK59-0.01,1,0) | AS59: =IF(S59>=AL59-0.01,1,0) | AT59: =IF(T59>=AM59-0.01,1,0) | AU59: =IF(U59>=AN59-0.01,1,0) | AV59: =IF(V59>=AO59-0.01,1,0) | AW59: =IF(W59>=AP59-0.01,1,0) | AX59: =AQ59*AR59*AS59*AT59*AU59*AV59*AW59 | AY59: =Assumptions!$B$41 | AZ59: =Assumptions!$B$33 | BA59: =Assumptions!$B$32 | BB59: =Assumptions!$B$31 | BC59: =Assumptions!$B$30 | BD59: =Assumptions!$B$29 | BE59: =Assumptions!$B$28 | BF59: =P59*Assumptions!$B$141 | BG59: =P59*Assumptions!$B$128 | BH59: =P59*Assumptions!$B$129 | BI59: =P59*Assumptions!$B$14 | BJ59: =P59*Assumptions!$B$13 | BK59: =P59*Assumptions!$B$12 | BL59: =P59*Assumptions!$B$11
A60: 700M | B60: =Assumptions!$B$58 | C60: 0 | D60: 0 | E60: 0 | F60: 1 | G60: 0 | H60: 0 | I60: 1 | J60: =(1-C60)*Assumptions!$B$41+(1-D60)*Assumptions!$B$33+(1-E60)*Assumptions!$B$32+(1-F60)*Assumptions!$B$31+(1-G60)*Assumptions!$B$30+(1-H60)*Assumptions!$B$29+(1-I60)*Assumptions!$B$28 | K60: =C60*Assumptions!$B$141+D60*Assumptions!$B$128+E60*Assumptions!$B$129+F60*Assumptions!$B$14+G60*Assumptions!$B$13+H60*Assumptions!$B$12+I60*Assumptions!$B$11+Assumptions!$B$133+Assumptions!$B$137+Assumptions!$B$9 | L60: =B60-J60 | M60: =IF(K60>0,IF(L60/K60>=Assumptions!$B$37,1,0),0) | N60: =K60+M60*Assumptions!$B$153 | O60: =L60+M60*Assumptions!$B$153*Assumptions!$B$37 | P60: =IF(N60>0,O60/N60,0) | Q60: =IF(C60=1,P60*Assumptions!$B$141,Assumptions!$B$41) | R60: =IF(D60=1,P60*Assumptions!$B$128,Assumptions!$B$33) | S60: =IF(E60=1,P60*Assumptions!$B$129,Assumptions!$B$32) | T60: =IF(F60=1,P60*Assumptions!$B$14,Assumptions!$B$31) | U60: =IF(G60=1,P60*Assumptions!$B$13,Assumptions!$B$30) | V60: =IF(H60=1,P60*Assumptions!$B$12,Assumptions!$B$29) | W60: =IF(I60=1,P60*Assumptions!$B$11,Assumptions!$B$28) | X60: =P60*(Assumptions!$B$133+Assumptions!$B$137) | Y60: =P60*Assumptions!$B$9 | Z60: =IF(M60=1,(P60-Assumptions!$B$37)*Assumptions!$B$153,0) | AA60: =Q60+R60+S60+T60+U60+V60+W60+X60+Y60+Z60 | AB60: 9 | AC60: 73 | AD60: 41 | AE60: 25 | AF60: 1 | AG60: 13 | AH60: 11 | AI60: 8 | AJ60: =INDEX($Q$51:$Q$178,AC60+1) | AK60: =INDEX($R$51:$R$178,AD60+1) | AL60: =INDEX($S$51:$S$178,AE60+1) | AM60: =INDEX($T$51:$T$178,AF60+1) | AN60: =INDEX($U$51:$U$178,AG60+1) | AO60: =INDEX($V$51:$V$178,AH60+1) | AP60: =INDEX($W$51:$W$178,AI60+1) | AQ60: =IF(Q60>=AJ60-0.01,1,0) | AR60: =IF(R60>=AK60-0.01,1,0) | AS60: =IF(S60>=AL60-0.01,1,0) | AT60: =IF(T60>=AM60-0.01,1,0) | AU60: =IF(U60>=AN60-0.01,1,0) | AV60: =IF(V60>=AO60-0.01,1,0) | AW60: =IF(W60>=AP60-0.01,1,0) | AX60: =AQ60*AR60*AS60*AT60*AU60*AV60*AW60 | AY60: =Assumptions!$B$41 | AZ60: =Assumptions!$B$33 | BA60: =Assumptions!$B$32 | BB60: =Assumptions!$B$31 | BC60: =Assumptions!$B$30 | BD60: =Assumptions!$B$29 | BE60: =Assumptions!$B$28 | BF60: =P60*Assumptions!$B$141 | BG60: =P60*Assumptions!$B$128 | BH60: =P60*Assumptions!$B$129 | BI60: =P60*Assumptions!$B$14 | BJ60: =P60*Assumptions!$B$13 | BK60: =P60*Assumptions!$B$12 | BL60: =P60*Assumptions!$B$11
A61: 700M | B61: =Assumptions!$B$58 | C61: 0 | D61: 0 | E61: 0 | F61: 1 | G61: 0 | H61: 1 | I61: 0 | J61: =(1-C61)*Assumptions!$B$41+(1-D61)*Assumptions!$B$33+(1-E61)*Assumptions!$B$32+(1-F61)*Assumptions!$B$31+(1-G61)*Assumptions!$B$30+(1-H61)*Assumptions!$B$29+(1-I61)*Assumptions!$B$28 | K61: =C61*Assumptions!$B$141+D61*Assumptions!$B$128+E61*Assumptions!$B$129+F61*Assumptions!$B$14+G61*Assumptions!$B$13+H61*Assumptions!$B$12+I61*Assumptions!$B$11+Assumptions!$B$133+Assumptions!$B$137+Assumptions!$B$9 | L61: =B61-J61 | M61: =IF(K61>0,IF(L61/K61>=Assumptions!$B$37,1,0),0) | N61: =K61+M61*Assumptions!$B$153 | O61: =L61+M61*Assumptions!$B$153*Assumptions!$B$37 | P61: =IF(N61>0,O61/N61,0) | Q61: =IF(C61=1,P61*Assumptions!$B$141,Assumptions!$B$41) | R61: =IF(D61=1,P61*Assumptions!$B$128,Assumptions!$B$33) | S61: =IF(E61=1,P61*Assumptions!$B$129,Assumptions!$B$32) | T61: =IF(F61=1,P61*Assumptions!$B$14,Assumptions!$B$31) | U61: =IF(G61=1,P61*Assumptions!$B$13,Assumptions!$B$30) | V61: =IF(H61=1,P61*Assumptions!$B$12,Assumptions!$B$29) | W61: =IF(I61=1,P61*Assumptions!$B$11,Assumptions!$B$28) | X61: =P61*(Assumptions!$B$133+Assumptions!$B$137) | Y61: =P61*Assumptions!$B$9 | Z61: =IF(M61=1,(P61-Assumptions!$B$37)*Assumptions!$B$153,0) | AA61: =Q61+R61+S61+T61+U61+V61+W61+X61+Y61+Z61 | AB61: 10 | AC61: 74 | AD61: 42 | AE61: 26 | AF61: 2 | AG61: 14 | AH61: 8 | AI61: 11 | AJ61: =INDEX($Q$51:$Q$178,AC61+1) | AK61: =INDEX($R$51:$R$178,AD61+1) | AL61: =INDEX($S$51:$S$178,AE61+1) | AM61: =INDEX($T$51:$T$178,AF61+1) | AN61: =INDEX($U$51:$U$178,AG61+1) | AO61: =INDEX($V$51:$V$178,AH61+1) | AP61: =INDEX($W$51:$W$178,AI61+1) | AQ61: =IF(Q61>=AJ61-0.01,1,0) | AR61: =IF(R61>=AK61-0.01,1,0) | AS61: =IF(S61>=AL61-0.01,1,0) | AT61: =IF(T61>=AM61-0.01,1,0) | AU61: =IF(U61>=AN61-0.01,1,0) | AV61: =IF(V61>=AO61-0.01,1,0) | AW61: =IF(W61>=AP61-0.01,1,0) | AX61: =AQ61*AR61*AS61*AT61*AU61*AV61*AW61 | AY61: =Assumptions!$B$41 | AZ61: =Assumptions!$B$33 | BA61: =Assumptions!$B$32 | BB61: =Assumptions!$B$31 | BC61: =Assumptions!$B$30 | BD61: =Assumptions!$B$29 | BE61: =Assumptions!$B$28 | BF61: =P61*Assumptions!$B$141 | BG61: =P61*Assumptions!$B$128 | BH61: =P61*Assumptions!$B$129 | BI61: =P61*Assumptions!$B$14 | BJ61: =P61*Assumptions!$B$13 | BK61: =P61*Assumptions!$B$12 | BL61: =P61*Assumptions!$B$11
A62: 700M | B62: =Assumptions!$B$58 | C62: 0 | D62: 0 | E62: 0 | F62: 1 | G62: 0 | H62: 1 | I62: 1 | J62: =(1-C62)*Assumptions!$B$41+(1-D62)*Assumptions!$B$33+(1-E62)*Assumptions!$B$32+(1-F62)*Assumptions!$B$31+(1-G62)*Assumptions!$B$30+(1-H62)*Assumptions!$B$29+(1-I62)*Assumptions!$B$28 | K62: =C62*Assumptions!$B$141+D62*Assumptions!$B$128+E62*Assumptions!$B$129+F62*Assumptions!$B$14+G62*Assumptions!$B$13+H62*Assumptions!$B$12+I62*Assumptions!$B$11+Assumptions!$B$133+Assumptions!$B$137+Assumptions!$B$9 | L62: =B62-J62 | M62: =IF(K62>0,IF(L62/K62>=Assumptions!$B$37,1,0),0) | N62: =K62+M62*Assumptions!$B$153 | O62: =L62+M62*Assumptions!$B$153*Assumptions!$B$37 | P62: =IF(N62>0,O62/N62,0) | Q62: =IF(C62=1,P62*Assumptions!$B$141,Assumptions!$B$41) | R62: =IF(D62=1,P62*Assumptions!$B$128,Assumptions!$B$33) | S62: =IF(E62=1,P62*Assumptions!$B$129,Assumptions!$B$32) | T62: =IF(F62=1,P62*Assumptions!$B$14,Assumptions!$B$31) | U62: =IF(G62=1,P62*Assumptions!$B$13,Assumptions!$B$30) | V62: =IF(H62=1,P62*Assumptions!$B$12,Assumptions!$B$29) | W62: =IF(I62=1,P62*Assumptions!$B$11,Assumptions!$B$28) | X62: =P62*(Assumptions!$B$133+Assumptions!$B$137) | Y62: =P62*Assumptions!$B$9 | Z62: =IF(M62=1,(P62-Assumptions!$B$37)*Assumptions!$B$153,0) | AA62: =Q62+R62+S62+T62+U62+V62+W62+X62+Y62+Z62 | AB62: 11 | AC62: 75 | AD62: 43 | AE62: 27 | AF62: 3 | AG62: 15 | AH62: 9 | AI62: 10 | AJ62: =INDEX($Q$51:$Q$178,AC62+1) | AK62: =INDEX($R$51:$R$178,AD62+1) | AL62: =INDEX($S$51:$S$178,AE62+1) | AM62: =INDEX($T$51:$T$178,AF62+1) | AN62: =INDEX($U$51:$U$178,AG62+1) | AO62: =INDEX($V$51:$V$178,AH62+1) | AP62: =INDEX($W$51:$W$178,AI62+1) | AQ62: =IF(Q62>=AJ62-0.01,1,0) | AR62: =IF(R62>=AK62-0.01,1,0) | AS62: =IF(S62>=AL62-0.01,1,0) | AT62: =IF(T62>=AM62-0.01,1,0) | AU62: =IF(U62>=AN62-0.01,1,0) | AV62: =IF(V62>=AO62-0.01,1,0) | AW62: =IF(W62>=AP62-0.01,1,0) | AX62: =AQ62*AR62*AS62*AT62*AU62*AV62*AW62 | AY62: =Assumptions!$B$41 | AZ62: =Assumptions!$B$33 | BA62: =Assumptions!$B$32 | BB62: =Assumptions!$B$31 | BC62: =Assumptions!$B$30 | BD62: =Assumptions!$B$29 | BE62: =Assumptions!$B$28 | BF62: =P62*Assumptions!$B$141 | BG62: =P62*Assumptions!$B$128 | BH62: =P62*Assumptions!$B$129 | BI62: =P62*Assumptions!$B$14 | BJ62: =P62*Assumptions!$B$13 | BK62: =P62*Assumptions!$B$12 | BL62: =P62*Assumptions!$B$11
... A178: 700M | B178: =Assumptions!$B$58 | C178: 1 | D178: 1 | E178: 1 | F178: 1 | G178: 1 | H178: 1 | I178: 1 | J178: =(1-C178)*Assumptions!$B$41+(1-D178)*Assumptions!$B$33+(1-E178)*Assumptions!$B$32+(1-F178)*Assumptions!$B$31+(1-G178)*Assumptions!$B$30+(1-H178)*Assumptions!$B$29+(1-I178)*Assumptions!$B$28 | K178: =C178*Assumptions!$B$141+D178*Assumptions!$B$128+E178*Assumptions!$B$129+F178*Assumptions!$B$14+G178*Assumptions!$B$13+H178*Assumptions!$B$12+I178*Assumptions!$B$11+Assumptions!$B$133+Assumptions!$B$137+Assumptions!$B$9 | L178: =B178-J178 | M178: =IF(K178>0,IF(L178/K178>=Assumptions!$B$37,1,0),0) | N178: =K178+M178*Assumptions!$B$153 | O178: =L178+M178*Assumptions!$B$153*Assumptions!$B$37 | P178: =IF(N178>0,O178/N178,0) | Q178: =IF(C178=1,P178*Assumptions!$B$141,Assumptions!$B$41) | R178: =IF(D178=1,P178*Assumptions!$B$128,Assumptions!$B$33) | S178: =IF(E178=1,P178*Assumptions!$B$129,Assumptions!$B$32) | T178: =IF(F178=1,P178*Assumptions!$B$14,Assumptions!$B$31) | U178: =IF(G178=1,P178*Assumptions!$B$13,Assumptions!$B$30) | V178: =IF(H178=1,P178*Assumptions!$B$12,Assumptions!$B$29) | W178: =IF(I178=1,P178*Assumptions!$B$11,Assumptions!$B$28) | X178: =P178*(Assumptions!$B$133+Assumptions!$B$137) | Y178: =P178*Assumptions!$B$9 | Z178: =IF(M178=1,(P178-Assumptions!$B$37)*Assumptions!$B$153,0) | AA178: =Q178+R178+S178+T178+U178+V178+W178+X178+Y178+Z178 | AB178: 127 | AC178: 63 | AD178: 95 | AE178: 111 | AF178: 119 | AG178: 123 | AH178: 125 | AI178: 126 | AJ178: =INDEX($Q$51:$Q$178,AC178+1) | AK178: =INDEX($R$51:$R$178,AD178+1) | AL178: =INDEX($S$51:$S$178,AE178+1) | AM178: =INDEX($T$51:$T$178,AF178+1) | AN178: =INDEX($U$51:$U$178,AG178+1) | AO178: =INDEX($V$51:$V$178,AH178+1) | AP178: =INDEX($W$51:$W$178,AI178+1) | AQ178: =IF(Q178>=AJ178-0.01,1,0) | AR178: =IF(R178>=AK178-0.01,1,0) | AS178: =IF(S178>=AL178-0.01,1,0) | AT178: =IF(T178>=AM178-0.01,1,0) | AU178: =IF(U178>=AN178-0.01,1,0) | AV178: =IF(V178>=AO178-0.01,1,0) | AW178: =IF(W178>=AP178-0.01,1,0) | AX178: =AQ178*AR178*AS178*AT178*AU178*AV178*AW178 | AY178: =Assumptions!$B$41 | AZ178: =Assumptions!$B$33 | BA178: =Assumptions!$B$32 | BB178: =Assumptions!$B$31 | BC178: =Assumptions!$B$30 | BD178: =Assumptions!$B$29 | BE178: =Assumptions!$B$28 | BF178: =P178*Assumptions!$B$141 | BG178: =P178*Assumptions!$B$128 | BH178: =P178*Assumptions!$B$129 | BI178: =P178*Assumptions!$B$14 | BJ178: =P178*Assumptions!$B$13 | BK178: =P178*Assumptions!$B$12 | BL178: =P178*Assumptions!$B$11
A179: 1200M | B179: =Assumptions!$B$59 | C179: 0 | D179: 0 | E179: 0 | F179: 0 | G179: 0 | H179: 0 | I179: 0 | J179: =(1-C179)*Assumptions!$B$41+(1-D179)*Assumptions!$B$33+(1-E179)*Assumptions!$B$32+(1-F179)*Assumptions!$B$31+(1-G179)*Assumptions!$B$30+(1-H179)*Assumptions!$B$29+(1-I179)*Assumptions!$B$28 | K179: =C179*Assumptions!$B$141+D179*Assumptions!$B$128+E179*Assumptions!$B$129+F179*Assumptions!$B$14+G179*Assumptions!$B$13+H179*Assumptions!$B$12+I179*Assumptions!$B$11+Assumptions!$B$133+Assumptions!$B$137+Assumptions!$B$9 | L179: =B179-J179 | M179: =IF(K179>0,IF(L179/K179>=Assumptions!$B$37,1,0),0) | N179: =K179+M179*Assumptions!$B$153 | O179: =L179+M179*Assumptions!$B$153*Assumptions!$B$37 | P179: =IF(N179>0,O179/N179,0) | Q179: =IF(C179=1,P179*Assumptions!$B$141,Assumptions!$B$41) | R179: =IF(D179=1,P179*Assumptions!$B$128,Assumptions!$B$33) | S179: =IF(E179=1,P179*Assumptions!$B$129,Assumptions!$B$32) | T179: =IF(F179=1,P179*Assumptions!$B$14,Assumptions!$B$31) | U179: =IF(G179=1,P179*Assumptions!$B$13,Assumptions!$B$30) | V179: =IF(H179=1,P179*Assumptions!$B$12,Assumptions!$B$29) | W179: =IF(I179=1,P179*Assumptions!$B$11,Assumptions!$B$28) | X179: =P179*(Assumptions!$B$133+Assumptions!$B$137) | Y179: =P179*Assumptions!$B$9 | Z179: =IF(M179=1,(P179-Assumptions!$B$37)*Assumptions!$B$153,0) | AA179: =Q179+R179+S179+T179+U179+V179+W179+X179+Y179+Z179 | AB179: 0 | AC179: 64 | AD179: 32 | AE179: 16 | AF179: 8 | AG179: 4 | AH179: 2 | AI179: 1 | AJ179: =INDEX($Q$179:$Q$306,AC179+1) | AK179: =INDEX($R$179:$R$306,AD179+1) | AL179: =INDEX($S$179:$S$306,AE179+1) | AM179: =INDEX($T$179:$T$306,AF179+1) | AN179: =INDEX($U$179:$U$306,AG179+1) | AO179: =INDEX($V$179:$V$306,AH179+1) | AP179: =INDEX($W$179:$W$306,AI179+1) | AQ179: =IF(Q179>=AJ179-0.01,1,0) | AR179: =IF(R179>=AK179-0.01,1,0) | AS179: =IF(S179>=AL179-0.01,1,0) | AT179: =IF(T179>=AM179-0.01,1,0) | AU179: =IF(U179>=AN179-0.01,1,0) | AV179: =IF(V179>=AO179-0.01,1,0) | AW179: =IF(W179>=AP179-0.01,1,0) | AX179: =AQ179*AR179*AS179*AT179*AU179*AV179*AW179 | AY179: =Assumptions!$B$41 | AZ179: =Assumptions!$B$33 | BA179: =Assumptions!$B$32 | BB179: =Assumptions!$B$31 | BC179: =Assumptions!$B$30 | BD179: =Assumptions!$B$29 | BE179: =Assumptions!$B$28 | BF179: =P179*Assumptions!$B$141 | BG179: =P179*Assumptions!$B$128 | BH179: =P179*Assumptions!$B$129 | BI179: =P179*Assumptions!$B$14 | BJ179: =P179*Assumptions!$B$13 | BK179: =P179*Assumptions!$B$12 | BL179: =P179*Assumptions!$B$11
A180: 1200M | B180: =Assumptions!$B$59 | C180: 0 | D180: 0 | E180: 0 | F180: 0 | G180: 0 | H180: 0 | I180: 1 | J180: =(1-C180)*Assumptions!$B$41+(1-D180)*Assumptions!$B$33+(1-E180)*Assumptions!$B$32+(1-F180)*Assumptions!$B$31+(1-G180)*Assumptions!$B$30+(1-H180)*Assumptions!$B$29+(1-I180)*Assumptions!$B$28 | K180: =C180*Assumptions!$B$141+D180*Assumptions!$B$128+E180*Assumptions!$B$129+F180*Assumptions!$B$14+G180*Assumptions!$B$13+H180*Assumptions!$B$12+I180*Assumptions!$B$11+Assumptions!$B$133+Assumptions!$B$137+Assumptions!$B$9 | L180: =B180-J180 | M180: =IF(K180>0,IF(L180/K180>=Assumptions!$B$37,1,0),0) | N180: =K180+M180*Assumptions!$B$153 | O180: =L180+M180*Assumptions!$B$153*Assumptions!$B$37 | P180: =IF(N180>0,O180/N180,0) | Q180: =IF(C180=1,P180*Assumptions!$B$141,Assumptions!$B$41) | R180: =IF(D180=1,P180*Assumptions!$B$128,Assumptions!$B$33) | S180: =IF(E180=1,P180*Assumptions!$B$129,Assumptions!$B$32) | T180: =IF(F180=1,P180*Assumptions!$B$14,Assumptions!$B$31) | U180: =IF(G180=1,P180*Assumptions!$B$13,Assumptions!$B$30) | V180: =IF(H180=1,P180*Assumptions!$B$12,Assumptions!$B$29) | W180: =IF(I180=1,P180*Assumptions!$B$11,Assumptions!$B$28) | X180: =P180*(Assumptions!$B$133+Assumptions!$B$137) | Y180: =P180*Assumptions!$B$9 | Z180: =IF(M180=1,(P180-Assumptions!$B$37)*Assumptions!$B$153,0) | AA180: =Q180+R180+S180+T180+U180+V180+W180+X180+Y180+Z180 | AB180: 1 | AC180: 65 | AD180: 33 | AE180: 17 | AF180: 9 | AG180: 5 | AH180: 3 | AI180: 0 | AJ180: =INDEX($Q$179:$Q$306,AC180+1) | AK180: =INDEX($R$179:$R$306,AD180+1) | AL180: =INDEX($S$179:$S$306,AE180+1) | AM180: =INDEX($T$179:$T$306,AF180+1) | AN180: =INDEX($U$179:$U$306,AG180+1) | AO180: =INDEX($V$179:$V$306,AH180+1) | AP180: =INDEX($W$179:$W$306,AI180+1) | AQ180: =IF(Q180>=AJ180-0.01,1,0) | AR180: =IF(R180>=AK180-0.01,1,0) | AS180: =IF(S180>=AL180-0.01,1,0) | AT180: =IF(T180>=AM180-0.01,1,0) | AU180: =IF(U180>=AN180-0.01,1,0) | AV180: =IF(V180>=AO180-0.01,1,0) | AW180: =IF(W180>=AP180-0.01,1,0) | AX180: =AQ180*AR180*AS180*AT180*AU180*AV180*AW180 | AY180: =Assumptions!$B$41 | AZ180: =Assumptions!$B$33 | BA180: =Assumptions!$B$32 | BB180: =Assumptions!$B$31 | BC180: =Assumptions!$B$30 | BD180: =Assumptions!$B$29 | BE180: =Assumptions!$B$28 | BF180: =P180*Assumptions!$B$141 | BG180: =P180*Assumptions!$B$128 | BH180: =P180*Assumptions!$B$129 | BI180: =P180*Assumptions!$B$14 | BJ180: =P180*Assumptions!$B$13 | BK180: =P180*Assumptions!$B$12 | BL180: =P180*Assumptions!$B$11
A181: 1200M | B181: =Assumptions!$B$59 | C181: 0 | D181: 0 | E181: 0 | F181: 0 | G181: 0 | H181: 1 | I181: 0 | J181: =(1-C181)*Assumptions!$B$41+(1-D181)*Assumptions!$B$33+(1-E181)*Assumptions!$B$32+(1-F181)*Assumptions!$B$31+(1-G181)*Assumptions!$B$30+(1-H181)*Assumptions!$B$29+(1-I181)*Assumptions!$B$28 | K181: =C181*Assumptions!$B$141+D181*Assumptions!$B$128+E181*Assumptions!$B$129+F181*Assumptions!$B$14+G181*Assumptions!$B$13+H181*Assumptions!$B$12+I181*Assumptions!$B$11+Assumptions!$B$133+Assumptions!$B$137+Assumptions!$B$9 | L181: =B181-J181 | M181: =IF(K181>0,IF(L181/K181>=Assumptions!$B$37,1,0),0) | N181: =K181+M181*Assumptions!$B$153 | O181: =L181+M181*Assumptions!$B$153*Assumptions!$B$37 | P181: =IF(N181>0,O181/N181,0) | Q181: =IF(C181=1,P181*Assumptions!$B$141,Assumptions!$B$41) | R181: =IF(D181=1,P181*Assumptions!$B$128,Assumptions!$B$33) | S181: =IF(E181=1,P181*Assumptions!$B$129,Assumptions!$B$32) | T181: =IF(F181=1,P181*Assumptions!$B$14,Assumptions!$B$31) | U181: =IF(G181=1,P181*Assumptions!$B$13,Assumptions!$B$30) | V181: =IF(H181=1,P181*Assumptions!$B$12,Assumptions!$B$29) | W181: =IF(I181=1,P181*Assumptions!$B$11,Assumptions!$B$28) | X181: =P181*(Assumptions!$B$133+Assumptions!$B$137) | Y181: =P181*Assumptions!$B$9 | Z181: =IF(M181=1,(P181-Assumptions!$B$37)*Assumptions!$B$153,0) | AA181: =Q181+R181+S181+T181+U181+V181+W181+X181+Y181+Z181 | AB181: 2 | AC181: 66 | AD181: 34 | AE181: 18 | AF181: 10 | AG181: 6 | AH181: 0 | AI181: 3 | AJ181: =INDEX($Q$179:$Q$306,AC181+1) | AK181: =INDEX($R$179:$R$306,AD181+1) | AL181: =INDEX($S$179:$S$306,AE181+1) | AM181: =INDEX($T$179:$T$306,AF181+1) | AN181: =INDEX($U$179:$U$306,AG181+1) | AO181: =INDEX($V$179:$V$306,AH181+1) | AP181: =INDEX($W$179:$W$306,AI181+1) | AQ181: =IF(Q181>=AJ181-0.01,1,0) | AR181: =IF(R181>=AK181-0.01,1,0) | AS181: =IF(S181>=AL181-0.01,1,0) | AT181: =IF(T181>=AM181-0.01,1,0) | AU181: =IF(U181>=AN181-0.01,1,0) | AV181: =IF(V181>=AO181-0.01,1,0) | AW181: =IF(W181>=AP181-0.01,1,0) | AX181: =AQ181*AR181*AS181*AT181*AU181*AV181*AW181 | AY181: =Assumptions!$B$41 | AZ181: =Assumptions!$B$33 | BA181: =Assumptions!$B$32 | BB181: =Assumptions!$B$31 | BC181: =Assumptions!$B$30 | BD181: =Assumptions!$B$29 | BE181: =Assumptions!$B$28 | BF181: =P181*Assumptions!$B$141 | BG181: =P181*Assumptions!$B$128 | BH181: =P181*Assumptions!$B$129 | BI181: =P181*Assumptions!$B$14 | BJ181: =P181*Assumptions!$B$13 | BK181: =P181*Assumptions!$B$12 | BL181: =P181*Assumptions!$B$11
...

Sheet Sensitivity
A1: Sensitivity (3x3 grid: ESOP refresh x pre-money F)
A3: label | B3: esop | C3: pre_M | D3: our_pct | E3: dollars_at_2000M_exit
A4: esop_11_pre_1200M | B4: 0.11 | C4: 1200 | D4: =(Assumptions!$B$47/H157)/I157 | E4: =INDEX($Q$5000:$Q$5127,MATCH(1,$AX$5000:$AX$5127,0))*Assumptions!$B$47/Assumptions!$B$41
A5: esop_11_pre_1400M | B5: 0.11 | C5: 1400 | D5: =(Assumptions!$B$47/H232)/I232 | E5: =INDEX($Q$5128:$Q$5255,MATCH(1,$AX$5128:$AX$5255,0))*Assumptions!$B$47/Assumptions!$B$41
A6: esop_11_pre_1800M | B6: 0.11 | C6: 1800 | D6: =(Assumptions!$B$47/H307)/I307 | E6: =INDEX($Q$5256:$Q$5383,MATCH(1,$AX$5256:$AX$5383,0))*Assumptions!$B$47/Assumptions!$B$41
A7: esop_13_pre_1200M | B7: 0.13 | C7: 1200 | D7: =(Assumptions!$B$47/H382)/I382 | E7: =INDEX($Q$5384:$Q$5511,MATCH(1,$AX$5384:$AX$5511,0))*Assumptions!$B$47/Assumptions!$B$41
A8: esop_13_pre_1400M | B8: 0.13 | C8: 1400 | D8: =(Assumptions!$B$47/H457)/I457 | E8: =INDEX($Q$5512:$Q$5639,MATCH(1,$AX$5512:$AX$5639,0))*Assumptions!$B$47/Assumptions!$B$41
A9: esop_13_pre_1800M | B9: 0.13 | C9: 1800 | D9: =(Assumptions!$B$47/H532)/I532 | E9: =INDEX($Q$5640:$Q$5767,MATCH(1,$AX$5640:$AX$5767,0))*Assumptions!$B$47/Assumptions!$B$41
A10: esop_15_pre_1200M | B10: 0.15 | C10: 1200 | D10: =(Assumptions!$B$47/H607)/I607 | E10: =INDEX($Q$5768:$Q$5895,MATCH(1,$AX$5768:$AX$5895,0))*Assumptions!$B$47/Assumptions!$B$41
A11: esop_15_pre_1400M | B11: 0.15 | C11: 1400 | D11: =(Assumptions!$B$47/H682)/I682 | E11: =INDEX($Q$5896:$Q$6023,MATCH(1,$AX$5896:$AX$6023,0))*Assumptions!$B$47/Assumptions!$B$41
A12: esop_15_pre_1800M | B12: 0.15 | C12: 1800 | D12: =(Assumptions!$B$47/H757)/I757 | E12: =INDEX($Q$6024:$Q$6151,MATCH(1,$AX$6024:$AX$6151,0))*Assumptions!$B$47/Assumptions!$B$41
A100: Cell esop_11_pre_1200M
A101: esop | B101: 0.11
A102: pre_M ($M) | B102: 1200
A103: pre_money $ | B103: =B102*1000000
A104: post_money $ | B104: =B103+Assumptions!$B$41
A105: primary raise $ | B105: =Assumptions!$B$41
A107: iter | B107: r_E_p | C107: r_D_p | D107: N_A_p | E107: N_B_p | F107: E_adj | G107: D_adj | H107: F_PPS | I107: T_F | J107: new_F | K107: pre_FD | L107: capA | M107: discA | N107: cpA | O107: NA | P107: capB | Q107: discB | R107: cpB | S107: NB | T107: NCP_E | U107: r_E_n | V107: NCP_D | W107: r_D_n
A108: 0 | B108: 1 | C108: 1 | D108: 0 | E108: 0 | F108: =Assumptions!$B$16*B108 | G108: =Assumptions!$B$15*C108 | H108: =IF($B$101*($B$104/(($B$104*(1-$B$101)-$B$105)/((Assumptions!$B$9+Assumptions!$B$11+Assumptions!$B$12+Assumptions!$B$13+Assumptions!$B$14)+G108+F108+D108+E108)))<Assumptions!$B$65,($B$104-$B$105)/(((Assumptions!$B$9+Assumptions!$B$11+Assumptions!$B$12+Assumptions!$B$13+Assumptions!$B$14)+G108+F108+D108+E108)+Assumptions!$B$65),($B$104*(1-$B$101)-$B$105)/((Assumptions!$B$9+Assumptions!$B$11+Assumptions!$B$12+Assumptions!$B$13+Assumptions!$B$14)+G108+F108+D108+E108)) | I108: =$B$104/H108 | J108: =$B$105/H108 | K108: =I108-J108 | L108: =Assumptions!$B$51/K108 | M108: =H108*(1-Assumptions!$B$52) | N108: =MIN(L108,M108) | O108: =Assumptions!$B$50/N108 | P108: =Assumptions!$B$54/K108 | Q108: =H108*(1-Assumptions!$B$55) | R108: =MIN(P108,Q108) | S108: =Assumptions!$B$53/R108 | T108: =Assumptions!$B$27*(Assumptions!$B$64+$B$105/Assumptions!$B$27)/(Assumptions!$B$64+J108) | U108: =IF(H108<Assumptions!$B$27,Assumptions!$B$27/T108,1) | V108: =Assumptions!$B$26*(Assumptions!$B$64+$B$105/Assumptions!$B$26)/(Assumptions!$B$64+J108) | W108: =IF(H108<Assumptions!$B$26,Assumptions!$B$26/V108,1)
A109: 1 | B109: =U108 | C109: =W108 | D109: =O108 | E109: =S108 | F109: =Assumptions!$B$16*B109 | G109: =Assumptions!$B$15*C109 | H109: =IF($B$101*($B$104/(($B$104*(1-$B$101)-$B$105)/((Assumptions!$B$9+Assumptions!$B$11+Assumptions!$B$12+Assumptions!$B$13+Assumptions!$B$14)+G109+F109+D109+E109)))<Assumptions!$B$65,($B$104-$B$105)/(((Assumptions!$B$9+Assumptions!$B$11+Assumptions!$B$12+Assumptions!$B$13+Assumptions!$B$14)+G109+F109+D109+E109)+Assumptions!$B$65),($B$104*(1-$B$101)-$B$105)/((Assumptions!$B$9+Assumptions!$B$11+Assumptions!$B$12+Assumptions!$B$13+Assumptions!$B$14)+G109+F109+D109+E109)) | I109: =$B$104/H109 | J109: =$B$105/H109 | K109: =I109-J109 | L109: =Assumptions!$B$51/K109 | M109: =H109*(1-Assumptions!$B$52) | N109: =MIN(L109,M109) | O109: =Assumptions!$B$50/N109 | P109: =Assumptions!$B$54/K109 | Q109: =H109*(1-Assumptions!$B$55) | R109: =MIN(P109,Q109) | S109: =Assumptions!$B$53/R109 | T109: =Assumptions!$B$27*(Assumptions!$B$64+$B$105/Assumptions!$B$27)/(Assumptions!$B$64+J109) | U109: =IF(H109<Assumptions!$B$27,Assumptions!$B$27/T109,1) | V109: =Assumptions!$B$26*(Assumptions!$B$64+$B$105/Assumptions!$B$26)/(Assumptions!$B$64+J109) | W109: =IF(H109<Assumptions!$B$26,Assumptions!$B$26/V109,1)
A110: 2 | B110: =U109 | C110: =W109 | D110: =O109 | E110: =S109 | F110: =Assumptions!$B$16*B110 | G110: =Assumptions!$B$15*C110 | H110: =IF($B$101*($B$104/(($B$104*(1-$B$101)-$B$105)/((Assumptions!$B$9+Assumptions!$B$11+Assumptions!$B$12+Assumptions!$B$13+Assumptions!$B$14)+G110+F110+D110+E110)))<Assumptions!$B$65,($B$104-$B$105)/(((Assumptions!$B$9+Assumptions!$B$11+Assumptions!$B$12+Assumptions!$B$13+Assumptions!$B$14)+G110+F110+D110+E110)+Assumptions!$B$65),($B$104*(1-$B$101)-$B$105)/((Assumptions!$B$9+Assumptions!$B$11+Assumptions!$B$12+Assumptions!$B$13+Assumptions!$B$14)+G110+F110+D110+E110)) | I110: =$B$104/H110 | J110: =$B$105/H110 | K110: =I110-J110 | L110: =Assumptions!$B$51/K110 | M110: =H110*(1-Assumptions!$B$52) | N110: =MIN(L110,M110) | O110: =Assumptions!$B$50/N110 | P110: =Assumptions!$B$54/K110 | Q110: =H110*(1-Assumptions!$B$55) | R110: =MIN(P110,Q110) | S110: =Assumptions!$B$53/R110 | T110: =Assumptions!$B$27*(Assumptions!$B$64+$B$105/Assumptions!$B$27)/(Assumptions!$B$64+J110) | U110: =IF(H110<Assumptions!$B$27,Assumptions!$B$27/T110,1) | V110: =Assumptions!$B$26*(Assumptions!$B$64+$B$105/Assumptions!$B$26)/(Assumptions!$B$64+J110) | W110: =IF(H110<Assumptions!$B$26,Assumptions!$B$26/V110,1)
