Workbook

Sheet Assumptions
A1: Kelvin Dynamics - Series F Analysis | H1: Label library | I1: Label text
H2: label_2 | I2: Iteration
A3: Assumption / source fact | B3: Value | C3: Units | D3: Source / note | E3: Key | H3: label_3 | I3: Top-up input
A4: Formula constant: zero | B4: 0 | D4: Workbook formula helper | E4: zero | H4: label_4 | I4: F PPS
A5: Formula constant: one | B5: 1 | D5: Workbook formula helper | E5: one | H5: label_5 | I5: F primary shares
A6: series f pre money usd | B6: 1400000000 | C6: USD | D6: Series F pre-money valuation | E6: series_f_pre_money_usd | H6: label_6 | I6: Prior as-converted
A7: series f primary raise usd | B7: 30000000 | C7: USD | D7: New Series F primary capital | E7: series_f_primary_raise_usd | H7: label_7 | I7: Note A cap PPS
A8: series f secondary raise usd | B8: 15000000 | C8: USD | D8: Secondary tender from founders | E8: series_f_secondary_raise_usd | H8: label_8 | I8: Note A discount PPS
A9: series f tender pps multiplier | B9: 0.85 | C9: fraction | D9: Tender PPS = multiplier x F_PPS | E9: series_f_tender_pps_multiplier | H9: label_9 | I9: Note A conversion PPS
A10: esop refresh target post f | B10: 0.13 | C10: fraction | D10: Post-F option pool as fraction of post-F FD | E10: esop_refresh_target_post_f | H10: label_10 | I10: Note A branch
A11: our fund check usd | B11: 10000000 | C11: USD | D11: Our fund's Series F primary check (= 1/3 of primary) | E11: our_fund_check_usd | H11: label_11 | I11: Note A shares
A12: f lead primary check usd | B12: 20000000 | C12: USD | D12: F_LEAD's Series F primary check (= 2/3 of primary) | E12: f_lead_primary_check_usd | H12: label_12 | I12: Note B cap PPS
A13: option strike usd | B13: 1 | C13: USD | D13: Option exercise price for issued options at exit | E13: option_strike_usd | H13: label_13 | I13: Note B discount PPS
A14: pre f options issued | B14: 2500000 | C14: shares | D14: Issued options outstanding pre-F (carryover from v3 post-E) | E14: pre_f_options_issued | H14: label_14 | I14: Note B conversion PPS
A15: pre f options unissued | B15: 1894667 | C15: shares | D15: Unissued option pool pre-F (carryover from v3 post-E refresh) | E15: pre_f_options_unissued | H15: label_15 | I15: Note B branch
A16: pre f fd total | B16: 36617961 | C16: shares | D16: Pre-F fully-diluted share count (post-E T from v3) | E16: pre_f_fd_total | H16: label_16 | I16: Note B shares
A17: pre-F option pool (issued + unissued) | B17: =Assumptions!$B$14+Assumptions!$B$15 -> 4394667 | C17: shares | D17: Derived from RoundTerms | E17: pre_f_option_pool | H17: label_17 | I17: ESOP top-up output
A18: pre-F founder common | B18: 8000000 | C18: shares | D18: Stakeholders | E18: pre_f_founder_common | H18: label_18 | I18: Post-F FD
A19: pre-F employee RSA common | B19: 1000000 | C19: shares | D19: Stakeholders | E19: pre_f_rsa_common | H19: label_19 | I19: Seed NCP
A20: pre-F common + RSAs | B20: 9000000 | C20: shares | D20: Stakeholders | E20: pre_f_common_rsa | H20: label_20 | I20: Seed ratio
A21: Broad-based WA A: pre-F FD | B21: 36617961 | C21: shares | D21: RoundTerms | E21: ad_pre_f_broad_based_fd | H21: label_21 | I21: Seed as-converted
A22: Broad-based WA new-money numerator | B22: 30000000 | C22: USD | D22: Notes excluded from B and C | E22: ad_new_money_usd | H22: label_22 | I22: Series A NCP
A23: Notes excluded from AD B and C | B23: TRUE | C23: boolean | D23: Instruction | E23: notes_excluded_from_ad_b_c | H23: label_23 | I23: Series A ratio
A24: Exit scenario 1 | B24: 700000000 | C24: USD | D24: exit_value_1_usd | E24: exit_value_1_usd | H24: label_24 | I24: Series A as-converted
A25: Exit scenario 2 | B25: 1200000000 | C25: USD | D25: exit_value_2_usd | E25: exit_value_2_usd | H25: label_25 | I25: Series B NCP
A26: Exit scenario 3 (sensitivity reference) | B26: 2000000000 | C26: USD | D26: exit_value_3_usd | E26: exit_value_3_usd | H26: label_26 | I26: Series B ratio
A27: Exit scenario 4 | B27: 4000000000 | C27: USD | D27: exit_value_4_usd | E27: exit_value_4_usd | H27: label_27 | I27: Series B as-converted
A28: Exit scenario 5 | B28: 8000000000 | C28: USD | D28: exit_value_5_usd | E28: exit_value_5_usd | H28: label_28 | I28: Series C NCP
A29: Sensitivity grid axis: low ESOP refresh | B29: 0.11 | C29: fraction | D29: sensitivity_esop_low | E29: sensitivity_esop_low | H29: label_29 | I29: Series C ratio
A30: Sensitivity grid axis: base ESOP refresh | B30: 0.13 | C30: fraction | D30: sensitivity_esop_base | E30: sensitivity_esop_base | H30: label_30 | I30: Series C as-converted
A31: Sensitivity grid axis: high ESOP refresh | B31: 0.15 | C31: fraction | D31: sensitivity_esop_high | E31: sensitivity_esop_high | H31: label_31 | I31: Series D NCP
A32: Sensitivity grid axis: low Series F pre-money | B32: 1200000000 | C32: USD | D32: sensitivity_pre_low_usd | E32: sensitivity_pre_low_usd | H32: label_32 | I32: Series D ratio
A33: Sensitivity grid axis: base Series F pre-money | B33: 1400000000 | C33: USD | D33: sensitivity_pre_base_usd | E33: sensitivity_pre_base_usd | H33: label_33 | I33: Series D as-converted
A34: Sensitivity grid axis: high Series F pre-money | B34: 1800000000 | C34: USD | D34: sensitivity_pre_high_usd | E34: sensitivity_pre_high_usd | H34: label_34 | I34: Series E NCP
A35: Return-solver target: 3x net | B35: 3 | C35: multiple | D35: return_multiple_3x | E35: return_multiple_3x | H35: label_35 | I35: Series E ratio
... A67: Series F aggregate 1x preference | B67: 30000000 | C67: USD | D67: RoundTerms | E67: series_f_invested_usd | H67: label_67 | I67: Discount-implied PPS
A68: Our fund share of Series F primary | B68: =Assumptions!$B$11/Assumptions!$B$7 -> 0.33333333 | C68: fraction | D68: Derived from RoundTerms | E68: our_primary_fraction | H68: label_68 | I68: Conversion PPS
A69: Note A principal | B69: 5000000 | C69: USD | D69: Notes | E69: note_a_principal_usd | H69: label_69 | I69: Branch
A70: Note A valuation cap | B70: 1000000000 | C70: USD | D70: Notes | E70: note_a_cap_usd | H70: label_70 | I70: Shares issued
A71: Note A discount | B71: 0.2 | C71: fraction | D71: Notes | E71: note_a_discount | H71: label_71 | I71: Note A
...

Sheet Pro-Forma
A1: =Assumptions!$I$37 -> Kelvin Dynamics - Series F Pro-Forma
A3: =Assumptions!$I$38 -> Series F PPS | B3: =$C$172 -> 37.628498
A4: =Assumptions!$I$39 -> Series F new shares | B4: =$D$172 -> 797268.07
A5: =Assumptions!$I$40 -> Our fund Series F shares | B5: =Assumptions!$B$11/$C$172 -> 265756.02
A6: =Assumptions!$I$41 -> F_LEAD primary Series F shares | B6: =Assumptions!$B$12/$C$172 -> 531512.05
A7: =Assumptions!$I$42 -> ESOP top-up shares | B7: =$P$172 -> 587882.23
A8: =Assumptions!$I$43 -> Post-F FD shares | B8: =$Q$172 -> 38327302
A9: =Assumptions!$I$44 -> Our post-F ownership | B9: =B5/$Q$172 -> 0.0069338568
A10: =Assumptions!$I$45 -> Series F post-F ownership | B10: =$D$172/$Q$172 -> 0.02080157
A12: =Assumptions!$I$46 -> Anti-dilution block
A13: =Assumptions!$I$47 -> Series | B13: =Assumptions!$I$48 -> F PPS < OCP | C13: =Assumptions!$I$49 -> OCP | D13: =Assumptions!$I$50 -> New conversion price | E13: =Assumptions!$I$51 -> New ratio | F13: =Assumptions!$I$52 -> As-converted shares | G13: =Assumptions!$I$53 -> AD B shares | H13: =Assumptions!$I$54 -> AD C shares
A14: =Assumptions!$I$55 -> Seed | B14: =$C$172<Assumptions!$B$37 -> 0 | C14: =Assumptions!$B$37 -> 1 | D14: =$R$172 -> 1 | E14: =$S$172 -> 1 | F14: =$T$172 -> 5000000 | G14: =Assumptions!$B$22/Assumptions!$B$37 -> 30000000 | H14: =Assumptions!$B$22/$C$172 -> 797268.07
A15: =Assumptions!$I$56 -> Series A | B15: =$C$172<Assumptions!$B$42 -> 0 | C15: =Assumptions!$B$42 -> 3 | D15: =$U$172 -> 3 | E15: =$V$172 -> 1 | F15: =$W$172 -> 5000000 | G15: =Assumptions!$B$22/Assumptions!$B$42 -> 10000000 | H15: =Assumptions!$B$22/$C$172 -> 797268.07
A16: =Assumptions!$I$57 -> Series B | B16: =$C$172<Assumptions!$B$47 -> 0 | C16: =Assumptions!$B$47 -> 10 | D16: =$X$172 -> 10 | E16: =$Y$172 -> 1 | F16: =$Z$172 -> 3000000 | G16: =Assumptions!$B$22/Assumptions!$B$47 -> 3000000 | H16: =Assumptions!$B$22/$C$172 -> 797268.07
A17: =Assumptions!$I$58 -> Series C | B17: =$C$172<Assumptions!$B$52 -> 0 | C17: =Assumptions!$B$52 -> 25 | D17: =$AA$172 -> 25 | E17: =$AB$172 -> 1 | F17: =$AC$172 -> 2400000 | G17: =Assumptions!$B$22/Assumptions!$B$52 -> 1200000 | H17: =Assumptions!$B$22/$C$172 -> 797268.07
A18: =Assumptions!$I$59 -> Series D | B18: =$C$172<Assumptions!$B$57 -> 1 | C18: =Assumptions!$B$57 -> 58.118347 | D18: =$AD$172 -> 57.681736 | E18: =$AE$172 -> 1.0401906 | F18: =$AF$172 -> 1733651.4 | G18: =Assumptions!$B$22/Assumptions!$B$57 -> 516188.12 | H18: =Assumptions!$B$22/$C$172 -> 797268.07
A19: =Assumptions!$I$60 -> Series E | B19: =$C$172<Assumptions!$B$62 -> 1 | C19: =Assumptions!$B$62 -> 49.158311 | D19: =$AG$172 -> 48.912626 | E19: =$AH$172 -> 1.0050229 | F19: =$AI$172 -> 6133320.3 | G19: =Assumptions!$B$22/Assumptions!$B$62 -> 610273.2 | H19: =Assumptions!$B$22/$C$172 -> 797268.07
A22: =Assumptions!$I$61 -> Notes block
A23: =Assumptions!$I$62 -> Note | B23: =Assumptions!$I$63 -> Principal | C23: =Assumptions!$I$64 -> Cap | D23: =Assumptions!$I$65 -> Discount | E23: =Assumptions!$I$66 -> Cap-implied PPS | F23: =Assumptions!$I$67 -> Discount-implied PPS | G23: =Assumptions!$I$68 -> Conversion PPS | H23: =Assumptions!$I$69 -> Branch | I23: =Assumptions!$I$70 -> Shares issued
A24: =Assumptions!$I$71 -> Note A | B24: =Assumptions!$B$69 -> 5000000 | C24: =Assumptions!$B$70 -> 1000000000 | D24: =Assumptions!$B$71 -> 0.2 | E24: =$F$172 -> 26.778553 | F24: =$G$172 -> 30.102798 | G24: =$H$172 -> 26.778553 | H24: =IF(E24<=F24,"cap","discount") -> cap | I24: =$J$172 -> 186716.59
A25: =Assumptions!$I$72 -> Note B | B25: =Assumptions!$B$73 -> 3000000 | C25: =Assumptions!$B$74 -> 1600000000 | D25: =Assumptions!$B$75 -> 0.15 | E25: =$K$172 -> 42.739338 | F25: =$L$172 -> 31.984223 | G25: =$M$172 -> 31.984223 | H25: =IF(E25<=F25,"cap","discount") -> discount | I25: =$O$172 -> 93796.243
A29: =Assumptions!$I$73 -> Tender block
A30: =Assumptions!$I$74 -> Tender PPS | B30: =Assumptions!$B$9*$C$172 -> 31.984223
A31: =Assumptions!$I$75 -> Tender shares | B31: =Assumptions!$B$8/B30 -> 468981.22
A32: =Assumptions!$I$76 -> F1 tendered shares | B32: =B31*Assumptions!$C$87/Assumptions!$B$18 -> 234490.61
A33: =Assumptions!$I$77 -> F2 tendered shares | B33: =B31*Assumptions!$C$88/Assumptions!$B$18 -> 146556.63
A34: =Assumptions!$I$78 -> F3 tendered shares | B34: =B31*Assumptions!$C$89/Assumptions!$B$18 -> 87933.978
A35: =Assumptions!$I$79 -> F_LEAD secondary common | B35: =B31 -> 468981.22
A38: =Assumptions!$I$80 -> Post-F cap table
A39: =Assumptions!$I$81 -> Stakeholder | B39: =Assumptions!$I$82 -> Role | C39: =Assumptions!$I$83 -> Security class | D39: =Assumptions!$I$84 -> Common shares | E39: =Assumptions!$I$85 -> Preferred / note / option shares | F39: =Assumptions!$I$86 -> FD shares | G39: =Assumptions!$I$87 -> Ownership %
A40: =Assumptions!$A$87 -> F1 | B40: =Assumptions!$B$87 -> Founder (CEO) | C40: =Assumptions!$I$88 -> Common | D40: =Assumptions!$C$87-B32 -> 3765509.4 | E40: =Assumptions!$B$4 -> 0 | F40: =D40 -> 3765509.4 | G40: =F40/$Q$172 -> 0.098246138
A41: =Assumptions!$A$88 -> F2 | B41: =Assumptions!$B$88 -> Founder (CTO) | C41: =Assumptions!$I$88 -> Common | D41: =Assumptions!$C$88-B33 -> 2353443.4 | E41: =Assumptions!$B$4 -> 0 | F41: =D41 -> 2353443.4 | G41: =F41/$Q$172 -> 0.061403836
A42: =Assumptions!$A$89 -> F3 | B42: =Assumptions!$B$89 -> Founder (Chief Scientist) | C42: =Assumptions!$I$88 -> Common | D42: =Assumptions!$C$89-B34 -> 1412066 | E42: =Assumptions!$B$4 -> 0 | F42: =D42 -> 1412066 | G42: =F42/$Q$172 -> 0.036842302
A43: =Assumptions!$A$90 -> E1 | B43: =Assumptions!$B$90 -> Employee RSA | C43: =Assumptions!$I$89 -> RSA common | D43: =Assumptions!$C$90 -> 100000 | E43: =Assumptions!$B$4 -> 0 | F43: =D43 -> 100000 | G43: =F43/$Q$172 -> 0.0026091062
A44: =Assumptions!$A$91 -> E2 | B44: =Assumptions!$B$91 -> Employee RSA | C44: =Assumptions!$I$89 -> RSA common | D44: =Assumptions!$C$91 -> 100000 | E44: =Assumptions!$B$4 -> 0 | F44: =D44 -> 100000 | G44: =F44/$Q$172 -> 0.0026091062
A45: =Assumptions!$A$92 -> E3 | B45: =Assumptions!$B$92 -> Employee RSA | C45: =Assumptions!$I$89 -> RSA common | D45: =Assumptions!$C$92 -> 100000 | E45: =Assumptions!$B$4 -> 0 | F45: =D45 -> 100000 | G45: =F45/$Q$172 -> 0.0026091062
A46: =Assumptions!$A$93 -> E4 | B46: =Assumptions!$B$93 -> Employee RSA | C46: =Assumptions!$I$89 -> RSA common | D46: =Assumptions!$C$93 -> 100000 | E46: =Assumptions!$B$4 -> 0 | F46: =D46 -> 100000 | G46: =F46/$Q$172 -> 0.0026091062
A47: =Assumptions!$A$94 -> E5 | B47: =Assumptions!$B$94 -> Employee RSA | C47: =Assumptions!$I$89 -> RSA common | D47: =Assumptions!$C$94 -> 100000 | E47: =Assumptions!$B$4 -> 0 | F47: =D47 -> 100000 | G47: =F47/$Q$172 -> 0.0026091062
A48: =Assumptions!$A$95 -> E6 | B48: =Assumptions!$B$95 -> Employee RSA | C48: =Assumptions!$I$89 -> RSA common | D48: =Assumptions!$C$95 -> 100000 | E48: =Assumptions!$B$4 -> 0 | F48: =D48 -> 100000 | G48: =F48/$Q$172 -> 0.0026091062
A49: =Assumptions!$A$96 -> E7 | B49: =Assumptions!$B$96 -> Employee RSA | C49: =Assumptions!$I$89 -> RSA common | D49: =Assumptions!$C$96 -> 100000 | E49: =Assumptions!$B$4 -> 0 | F49: =D49 -> 100000 | G49: =F49/$Q$172 -> 0.0026091062
...

Sheet Waterfall
A1: =Assumptions!$I$133 -> Waterfall
B2: =Assumptions!$B$24 -> 700000000 | C2: =Assumptions!$B$25 -> 1200000000 | D2: =Assumptions!$B$26 -> 2000000000 | E2: =Assumptions!$B$27 -> 4000000000 | F2: =Assumptions!$B$28 -> 8000000000
A3: =Assumptions!$I$134 -> F election | B3: =IF(INDEX($U$131:$U$258,1+$AH$130+IF(MOD(QUOTIENT($AH$130,Assumptions!$B$77),2)=1,0,Assumptions!$B$77))>=INDEX($U$131:$U$258,1+$AH$130-IF(MOD(QUOTIENT($AH$130,Assumptions!$B$77),2)=1,Assumptions!$B$77,0)),"preference","convert") -> preference | C3: =IF(INDEX($U$263:$U$390,1+$AH$262+IF(MOD(QUOTIENT($AH$262,Assumptions!$B$77),2)=1,0,Assumptions!$B$77))>=INDEX($U$263:$U$390,1+$AH$262-IF(MOD(QUOTIENT($AH$262,Assumptions!$B$77),2)=1,Assumptions!$B$77,0)),"preference","convert") -> preference | D3: =IF(INDEX($U$395:$U$522,1+$AH$394+IF(MOD(QUOTIENT($AH$394,Assumptions!$B$77),2)=1,0,Assumptions!$B$77))>=INDEX($U$395:$U$522,1+$AH$394-IF(MOD(QUOTIENT($AH$394,Assumptions!$B$77),2)=1,Assumptions!$B$77,0)),"preference","convert") -> convert | E3: =IF(INDEX($U$527:$U$654,1+$AH$526+IF(MOD(QUOTIENT($AH$526,Assumptions!$B$77),2)=1,0,Assumptions!$B$77))>=INDEX($U$527:$U$654,1+$AH$526-IF(MOD(QUOTIENT($AH$526,Assumptions!$B$77),2)=1,Assumptions!$B$77,0)),"preference","convert") -> convert | F3: =IF(INDEX($U$659:$U$786,1+$AH$658+IF(MOD(QUOTIENT($AH$658,Assumptions!$B$77),2)=1,0,Assumptions!$B$77))>=INDEX($U$659:$U$786,1+$AH$658-IF(MOD(QUOTIENT($AH$658,Assumptions!$B$77),2)=1,Assumptions!$B$77,0)),"preference","convert") -> convert
A4: =Assumptions!$I$135 -> E election | B4: =IF(INDEX($V$131:$V$258,1+$AH$130+IF(MOD(QUOTIENT($AH$130,Assumptions!$B$78),2)=1,0,Assumptions!$B$78))>=INDEX($V$131:$V$258,1+$AH$130-IF(MOD(QUOTIENT($AH$130,Assumptions!$B$78),2)=1,Assumptions!$B$78,0)),"preference","convert") -> preference | C4: =IF(INDEX($V$263:$V$390,1+$AH$262+IF(MOD(QUOTIENT($AH$262,Assumptions!$B$78),2)=1,0,Assumptions!$B$78))>=INDEX($V$263:$V$390,1+$AH$262-IF(MOD(QUOTIENT($AH$262,Assumptions!$B$78),2)=1,Assumptions!$B$78,0)),"preference","convert") -> preference | D4: =IF(INDEX($V$395:$V$522,1+$AH$394+IF(MOD(QUOTIENT($AH$394,Assumptions!$B$78),2)=1,0,Assumptions!$B$78))>=INDEX($V$395:$V$522,1+$AH$394-IF(MOD(QUOTIENT($AH$394,Assumptions!$B$78),2)=1,Assumptions!$B$78,0)),"preference","convert") -> convert | E4: =IF(INDEX($V$527:$V$654,1+$AH$526+IF(MOD(QUOTIENT($AH$526,Assumptions!$B$78),2)=1,0,Assumptions!$B$78))>=INDEX($V$527:$V$654,1+$AH$526-IF(MOD(QUOTIENT($AH$526,Assumptions!$B$78),2)=1,Assumptions!$B$78,0)),"preference","convert") -> convert | F4: =IF(INDEX($V$659:$V$786,1+$AH$658+IF(MOD(QUOTIENT($AH$658,Assumptions!$B$78),2)=1,0,Assumptions!$B$78))>=INDEX($V$659:$V$786,1+$AH$658-IF(MOD(QUOTIENT($AH$658,Assumptions!$B$78),2)=1,Assumptions!$B$78,0)),"preference","convert") -> convert
A5: =Assumptions!$I$136 -> D election | B5: =IF(INDEX($W$131:$W$258,1+$AH$130+IF(MOD(QUOTIENT($AH$130,Assumptions!$B$79),2)=1,0,Assumptions!$B$79))>=INDEX($W$131:$W$258,1+$AH$130-IF(MOD(QUOTIENT($AH$130,Assumptions!$B$79),2)=1,Assumptions!$B$79,0)),"preference","convert") -> preference | C5: =IF(INDEX($W$263:$W$390,1+$AH$262+IF(MOD(QUOTIENT($AH$262,Assumptions!$B$79),2)=1,0,Assumptions!$B$79))>=INDEX($W$263:$W$390,1+$AH$262-IF(MOD(QUOTIENT($AH$262,Assumptions!$B$79),2)=1,Assumptions!$B$79,0)),"preference","convert") -> preference | D5: =IF(INDEX($W$395:$W$522,1+$AH$394+IF(MOD(QUOTIENT($AH$394,Assumptions!$B$79),2)=1,0,Assumptions!$B$79))>=INDEX($W$395:$W$522,1+$AH$394-IF(MOD(QUOTIENT($AH$394,Assumptions!$B$79),2)=1,Assumptions!$B$79,0)),"preference","convert") -> preference | E5: =IF(INDEX($W$527:$W$654,1+$AH$526+IF(MOD(QUOTIENT($AH$526,Assumptions!$B$79),2)=1,0,Assumptions!$B$79))>=INDEX($W$527:$W$654,1+$AH$526-IF(MOD(QUOTIENT($AH$526,Assumptions!$B$79),2)=1,Assumptions!$B$79,0)),"preference","convert") -> convert | F5: =IF(INDEX($W$659:$W$786,1+$AH$658+IF(MOD(QUOTIENT($AH$658,Assumptions!$B$79),2)=1,0,Assumptions!$B$79))>=INDEX($W$659:$W$786,1+$AH$658-IF(MOD(QUOTIENT($AH$658,Assumptions!$B$79),2)=1,Assumptions!$B$79,0)),"preference","convert") -> convert
A6: =Assumptions!$I$137 -> C election | B6: =IF(INDEX($X$131:$X$258,1+$AH$130+IF(MOD(QUOTIENT($AH$130,Assumptions!$B$80),2)=1,0,Assumptions!$B$80))>=INDEX($X$131:$X$258,1+$AH$130-IF(MOD(QUOTIENT($AH$130,Assumptions!$B$80),2)=1,Assumptions!$B$80,0)),"preference","convert") -> preference | C6: =IF(INDEX($X$263:$X$390,1+$AH$262+IF(MOD(QUOTIENT($AH$262,Assumptions!$B$80),2)=1,0,Assumptions!$B$80))>=INDEX($X$263:$X$390,1+$AH$262-IF(MOD(QUOTIENT($AH$262,Assumptions!$B$80),2)=1,Assumptions!$B$80,0)),"preference","convert") -> convert | D6: =IF(INDEX($X$395:$X$522,1+$AH$394+IF(MOD(QUOTIENT($AH$394,Assumptions!$B$80),2)=1,0,Assumptions!$B$80))>=INDEX($X$395:$X$522,1+$AH$394-IF(MOD(QUOTIENT($AH$394,Assumptions!$B$80),2)=1,Assumptions!$B$80,0)),"preference","convert") -> convert | E6: =IF(INDEX($X$527:$X$654,1+$AH$526+IF(MOD(QUOTIENT($AH$526,Assumptions!$B$80),2)=1,0,Assumptions!$B$80))>=INDEX($X$527:$X$654,1+$AH$526-IF(MOD(QUOTIENT($AH$526,Assumptions!$B$80),2)=1,Assumptions!$B$80,0)),"preference","convert") -> convert | F6: =IF(INDEX($X$659:$X$786,1+$AH$658+IF(MOD(QUOTIENT($AH$658,Assumptions!$B$80),2)=1,0,Assumptions!$B$80))>=INDEX($X$659:$X$786,1+$AH$658-IF(MOD(QUOTIENT($AH$658,Assumptions!$B$80),2)=1,Assumptions!$B$80,0)),"preference","convert") -> convert
A7: =Assumptions!$I$138 -> B election | B7: =IF(INDEX($Y$131:$Y$258,1+$AH$130+IF(MOD(QUOTIENT($AH$130,Assumptions!$B$81),2)=1,0,Assumptions!$B$81))>=INDEX($Y$131:$Y$258,1+$AH$130-IF(MOD(QUOTIENT($AH$130,Assumptions!$B$81),2)=1,Assumptions!$B$81,0)),"preference","convert") -> preference | C7: =IF(INDEX($Y$263:$Y$390,1+$AH$262+IF(MOD(QUOTIENT($AH$262,Assumptions!$B$81),2)=1,0,Assumptions!$B$81))>=INDEX($Y$263:$Y$390,1+$AH$262-IF(MOD(QUOTIENT($AH$262,Assumptions!$B$81),2)=1,Assumptions!$B$81,0)),"preference","convert") -> convert | D7: =IF(INDEX($Y$395:$Y$522,1+$AH$394+IF(MOD(QUOTIENT($AH$394,Assumptions!$B$81),2)=1,0,Assumptions!$B$81))>=INDEX($Y$395:$Y$522,1+$AH$394-IF(MOD(QUOTIENT($AH$394,Assumptions!$B$81),2)=1,Assumptions!$B$81,0)),"preference","convert") -> convert | E7: =IF(INDEX($Y$527:$Y$654,1+$AH$526+IF(MOD(QUOTIENT($AH$526,Assumptions!$B$81),2)=1,0,Assumptions!$B$81))>=INDEX($Y$527:$Y$654,1+$AH$526-IF(MOD(QUOTIENT($AH$526,Assumptions!$B$81),2)=1,Assumptions!$B$81,0)),"preference","convert") -> convert | F7: =IF(INDEX($Y$659:$Y$786,1+$AH$658+IF(MOD(QUOTIENT($AH$658,Assumptions!$B$81),2)=1,0,Assumptions!$B$81))>=INDEX($Y$659:$Y$786,1+$AH$658-IF(MOD(QUOTIENT($AH$658,Assumptions!$B$81),2)=1,Assumptions!$B$81,0)),"preference","convert") -> convert
A8: =Assumptions!$I$139 -> A election | B8: =IF(INDEX($Z$131:$Z$258,1+$AH$130+IF(MOD(QUOTIENT($AH$130,Assumptions!$B$82),2)=1,0,Assumptions!$B$82))>=INDEX($Z$131:$Z$258,1+$AH$130-IF(MOD(QUOTIENT($AH$130,Assumptions!$B$82),2)=1,Assumptions!$B$82,0)),"preference","convert") -> convert | C8: =IF(INDEX($Z$263:$Z$390,1+$AH$262+IF(MOD(QUOTIENT($AH$262,Assumptions!$B$82),2)=1,0,Assumptions!$B$82))>=INDEX($Z$263:$Z$390,1+$AH$262-IF(MOD(QUOTIENT($AH$262,Assumptions!$B$82),2)=1,Assumptions!$B$82,0)),"preference","convert") -> convert | D8: =IF(INDEX($Z$395:$Z$522,1+$AH$394+IF(MOD(QUOTIENT($AH$394,Assumptions!$B$82),2)=1,0,Assumptions!$B$82))>=INDEX($Z$395:$Z$522,1+$AH$394-IF(MOD(QUOTIENT($AH$394,Assumptions!$B$82),2)=1,Assumptions!$B$82,0)),"preference","convert") -> convert | E8: =IF(INDEX($Z$527:$Z$654,1+$AH$526+IF(MOD(QUOTIENT($AH$526,Assumptions!$B$82),2)=1,0,Assumptions!$B$82))>=INDEX($Z$527:$Z$654,1+$AH$526-IF(MOD(QUOTIENT($AH$526,Assumptions!$B$82),2)=1,Assumptions!$B$82,0)),"preference","convert") -> convert | F8: =IF(INDEX($Z$659:$Z$786,1+$AH$658+IF(MOD(QUOTIENT($AH$658,Assumptions!$B$82),2)=1,0,Assumptions!$B$82))>=INDEX($Z$659:$Z$786,1+$AH$658-IF(MOD(QUOTIENT($AH$658,Assumptions!$B$82),2)=1,Assumptions!$B$82,0)),"preference","convert") -> convert
A9: =Assumptions!$I$140 -> Seed election | B9: =IF(INDEX($AA$131:$AA$258,1+$AH$130+IF(MOD(QUOTIENT($AH$130,Assumptions!$B$83),2)=1,0,Assumptions!$B$83))>=INDEX($AA$131:$AA$258,1+$AH$130-IF(MOD(QUOTIENT($AH$130,Assumptions!$B$83),2)=1,Assumptions!$B$83,0)),"preference","convert") -> convert | C9: =IF(INDEX($AA$263:$AA$390,1+$AH$262+IF(MOD(QUOTIENT($AH$262,Assumptions!$B$83),2)=1,0,Assumptions!$B$83))>=INDEX($AA$263:$AA$390,1+$AH$262-IF(MOD(QUOTIENT($AH$262,Assumptions!$B$83),2)=1,Assumptions!$B$83,0)),"preference","convert") -> convert | D9: =IF(INDEX($AA$395:$AA$522,1+$AH$394+IF(MOD(QUOTIENT($AH$394,Assumptions!$B$83),2)=1,0,Assumptions!$B$83))>=INDEX($AA$395:$AA$522,1+$AH$394-IF(MOD(QUOTIENT($AH$394,Assumptions!$B$83),2)=1,Assumptions!$B$83,0)),"preference","convert") -> convert | E9: =IF(INDEX($AA$527:$AA$654,1+$AH$526+IF(MOD(QUOTIENT($AH$526,Assumptions!$B$83),2)=1,0,Assumptions!$B$83))>=INDEX($AA$527:$AA$654,1+$AH$526-IF(MOD(QUOTIENT($AH$526,Assumptions!$B$83),2)=1,Assumptions!$B$83,0)),"preference","convert") -> convert | F9: =IF(INDEX($AA$659:$AA$786,1+$AH$658+IF(MOD(QUOTIENT($AH$658,Assumptions!$B$83),2)=1,0,Assumptions!$B$83))>=INDEX($AA$659:$AA$786,1+$AH$658-IF(MOD(QUOTIENT($AH$658,Assumptions!$B$83),2)=1,Assumptions!$B$83,0)),"preference","convert") -> convert
A12: =Assumptions!$I$141 -> F | B12: =INDEX($U$131:$U$258,1+$AH$130) -> 30000000 | C12: =INDEX($U$263:$U$390,1+$AH$262) -> 30000000 | D12: =INDEX($U$395:$U$522,1+$AH$394) -> 44466536 | E12: =INDEX($U$527:$U$654,1+$AH$526) -> 89024619 | F12: =INDEX($U$659:$U$786,1+$AH$658) -> 1.7799363e+08
A13: =Assumptions!$I$142 -> E | B13: =INDEX($V$131:$V$258,1+$AH$130) -> 300000000 | C13: =INDEX($V$263:$V$390,1+$AH$262) -> 300000000 | D13: =INDEX($V$395:$V$522,1+$AH$394) -> 3.4207755e+08 | E13: =INDEX($V$527:$V$654,1+$AH$526) -> 6.8485936e+08 | F13: =INDEX($V$659:$V$786,1+$AH$658) -> 1.369291e+09
A14: =Assumptions!$I$143 -> D | B14: =INDEX($W$131:$W$258,1+$AH$130) -> 100000000 | C14: =INDEX($W$263:$W$390,1+$AH$262) -> 100000000 | D14: =INDEX($W$395:$W$522,1+$AH$394) -> 100000000 | E14: =INDEX($W$527:$W$654,1+$AH$526) -> 1.9358314e+08 | F14: =INDEX($W$659:$W$786,1+$AH$658) -> 3.8704536e+08
A15: =Assumptions!$I$144 -> C | B15: =INDEX($X$131:$X$258,1+$AH$130) -> 60000000 | C15: =INDEX($X$263:$X$390,1+$AH$262) -> 68210634 | D15: =INDEX($X$395:$X$522,1+$AH$394) -> 1.3385672e+08 | E15: =INDEX($X$527:$X$654,1+$AH$526) -> 2.6798902e+08 | F15: =INDEX($X$659:$X$786,1+$AH$658) -> 5.3581065e+08
A16: =Assumptions!$I$145 -> B | B16: =INDEX($Y$131:$Y$258,1+$AH$130) -> 30000000 | C16: =INDEX($Y$263:$Y$390,1+$AH$262) -> 85263292 | D16: =INDEX($Y$395:$Y$522,1+$AH$394) -> 1.673209e+08 | E16: =INDEX($Y$527:$Y$654,1+$AH$526) -> 3.3498627e+08 | F16: =INDEX($Y$659:$Y$786,1+$AH$658) -> 6.6976331e+08
A17: =Assumptions!$I$146 -> A | B17: =INDEX($Z$131:$Z$258,1+$AH$130) -> 41895249 | C17: =INDEX($Z$263:$Z$390,1+$AH$262) -> 1.4210549e+08 | D17: =INDEX($Z$395:$Z$522,1+$AH$394) -> 2.7886816e+08 | E17: =INDEX($Z$527:$Z$654,1+$AH$526) -> 5.5831045e+08 | F17: =INDEX($Z$659:$Z$786,1+$AH$658) -> 1.1162722e+09
A18: =Assumptions!$I$55 -> Seed | B18: =INDEX($AA$131:$AA$258,1+$AH$130) -> 41895249 | C18: =INDEX($AA$263:$AA$390,1+$AH$262) -> 1.4210549e+08 | D18: =INDEX($AA$395:$AA$522,1+$AH$394) -> 2.7886816e+08 | E18: =INDEX($AA$527:$AA$654,1+$AH$526) -> 5.5831045e+08 | F18: =INDEX($AA$659:$AA$786,1+$AH$658) -> 1.1162722e+09
A19: =Assumptions!$I$147 -> Notes | B19: =INDEX($AB$131:$AB$258,1+$AH$130) -> 2350430.9 | C19: =INDEX($AB$263:$AB$390,1+$AH$262) -> 7972482.4 | D19: =INDEX($AB$395:$AB$522,1+$AH$394) -> 15645219 | E19: =INDEX($AB$527:$AB$654,1+$AH$526) -> 31322649 | F19: =INDEX($AB$659:$AB$786,1+$AH$658) -> 62625733
A20: =Assumptions!$I$148 -> Common + RSAs | B20: =INDEX($AC$131:$AC$258,1+$AH$130) -> 75411448 | C20: =INDEX($AC$263:$AC$390,1+$AH$262) -> 2.5578988e+08 | D20: =INDEX($AC$395:$AC$522,1+$AH$394) -> 5.0196269e+08 | E20: =INDEX($AC$527:$AC$654,1+$AH$526) -> 1.0049588e+09 | F20: =INDEX($AC$659:$AC$786,1+$AH$658) -> 2.0092899e+09
A21: =Assumptions!$I$96 -> Issued options | B21: =INDEX($AD$131:$AD$258,1+$AH$130) -> 18447624 | C21: =INDEX($AD$263:$AD$390,1+$AH$262) -> 68552743 | D21: =INDEX($AD$395:$AD$522,1+$AH$394) -> 1.3693408e+08 | E21: =INDEX($AD$527:$AD$654,1+$AH$526) -> 2.7665523e+08 | F21: =INDEX($AD$659:$AD$786,1+$AH$658) -> 5.5563609e+08
A23: =Assumptions!$I$131 -> Total distributed | B23: =SUM(B12:B21) -> 700000000 | C23: =SUM(C12:C21) -> 1200000000 | D23: =SUM(D12:D21) -> 2000000000 | E23: =SUM(E12:E21) -> 4000000000 | F23: =SUM(F12:F21) -> 8000000000
A24: =Assumptions!$I$149 -> Reconciliation to exit | B24: =B23-B2 -> 0 | C24: =C23-C2 -> 0 | D24: =D23-D2 -> 0 | E24: =E23-E2 -> 0 | F24: =F23-F2 -> 0
A40: =Assumptions!$I$2 -> Iteration | B40: =Assumptions!$I$3 -> Top-up input | C40: =Assumptions!$I$4 -> F PPS | D40: =Assumptions!$I$5 -> F primary shares | E40: =Assumptions!$I$6 -> Prior as-converted | F40: =Assumptions!$I$7 -> Note A cap PPS | G40: =Assumptions!$I$8 -> Note A discount PPS | H40: =Assumptions!$I$9 -> Note A conversion PPS | I40: =Assumptions!$I$10 -> Note A branch | J40: =Assumptions!$I$11 -> Note A shares | K40: =Assumptions!$I$12 -> Note B cap PPS | L40: =Assumptions!$I$13 -> Note B discount PPS | M40: =Assumptions!$I$14 -> Note B conversion PPS | N40: =Assumptions!$I$15 -> Note B branch | O40: =Assumptions!$I$16 -> Note B shares | P40: =Assumptions!$I$17 -> ESOP top-up output | Q40: =Assumptions!$I$18 -> Post-F FD | R40: =Assumptions!$I$19 -> Seed NCP | S40: =Assumptions!$I$20 -> Seed ratio | T40: =Assumptions!$I$21 -> Seed as-converted | U40: =Assumptions!$I$22 -> Series A NCP | V40: =Assumptions!$I$23 -> Series A ratio | W40: =Assumptions!$I$24 -> Series A as-converted | X40: =Assumptions!$I$25 -> Series B NCP | Y40: =Assumptions!$I$26 -> Series B ratio | Z40: =Assumptions!$I$27 -> Series B as-converted | AA40: =Assumptions!$I$28 -> Series C NCP | AB40: =Assumptions!$I$29 -> Series C ratio | AC40: =Assumptions!$I$30 -> Series C as-converted | AD40: =Assumptions!$I$31 -> Series D NCP | AE40: =Assumptions!$I$32 -> Series D ratio | AF40: =Assumptions!$I$33 -> Series D as-converted | AG40: =Assumptions!$I$34 -> Series E NCP | AH40: =Assumptions!$I$35 -> Series E ratio | AI40: =Assumptions!$I$36 -> Series E as-converted
A41: =ROW()-ROW($A$41)+Assumptions!$B$4 -> 0 | B41: =Assumptions!$B$4 -> 0 | C41: =Assumptions!$B$6/(Assumptions!$B$16+$B$41) -> 38.232604 | D41: =Assumptions!$B$7/$C$41 -> 784670.59 | E41: =$T$41+$W$41+$Z$41+$AC$41+$AF$41+$AI$41 -> 23264323 | F41: =Assumptions!$B$70/(Assumptions!$B$20+Assumptions!$B$17+$B$41+$E$41+Assumptions!$B$4) -> 27.278438 | G41: =$C$41*(1-Assumptions!$B$71) -> 30.586083 | H41: =MIN($F$41,$G$41) -> 27.278438 | I41: =IF($F$41<=$G$41,"cap","discount") -> cap | J41: =Assumptions!$B$69/$H$41 -> 183294.95 | K41: =Assumptions!$B$74/(Assumptions!$B$20+Assumptions!$B$17+$B$41+$E$41+$J$41) -> 43.42836 | L41: =$C$41*(1-Assumptions!$B$75) -> 32.497713 | M41: =MIN($K$41,$L$41) -> 32.497713 | N41: =IF($K$41<=$L$41,"cap","discount") -> discount | O41: =Assumptions!$B$73/$M$41 -> 92314.187 | P41: =MAX(Assumptions!$B$4,(Assumptions!$B$10*(Assumptions!$B$20+$E$41+Assumptions!$B$17+$J$41+$O$41+$D$41)-Assumptions!$B$17)/(1-Assumptions!$B$10)) -> 584871.32 | Q41: =Assumptions!$B$20+$E$41+Assumptions!$B$17+$P$41+$J$41+$O$41+$D$41 -> 38304141 | R41: =IF($C$41<Assumptions!$B$37,Assumptions!$B$37*(Assumptions!$B$21+Assumptions!$B$22/Assumptions!$B$37)/(Assumptions!$B$21+Assumptions!$B$22/$C$41),Assumptions!$B$37) -> 1 | S41: =Assumptions!$B$38/$R$41 -> 1 | T41: =Assumptions!$B$39*$S$41 -> 5000000 | U41: =IF($C$41<Assumptions!$B$42,Assumptions!$B$42*(Assumptions!$B$21+Assumptions!$B$22/Assumptions!$B$42)/(Assumptions!$B$21+Assumptions!$B$22/$C$41),Assumptions!$B$42) -> 3 | V41: =Assumptions!$B$43/$U$41 -> 1 | W41: =Assumptions!$B$44*$V$41 -> 5000000 | X41: =IF($C$41<Assumptions!$B$47,Assumptions!$B$47*(Assumptions!$B$21+Assumptions!$B$22/Assumptions!$B$47)/(Assumptions!$B$21+Assumptions!$B$22/$C$41),Assumptions!$B$47) -> 10 | Y41: =Assumptions!$B$48/$X$41 -> 1 | Z41: =Assumptions!$B$49*$Y$41 -> 3000000 | AA41: =IF($C$41<Assumptions!$B$52,Assumptions!$B$52*(Assumptions!$B$21+Assumptions!$B$22/Assumptions!$B$52)/(Assumptions!$B$21+Assumptions!$B$22/$C$41),Assumptions!$B$52) -> 25 | AB41: =Assumptions!$B$53/$AA$41 -> 1 | AC41: =Assumptions!$B$54*$AB$41 -> 2400000 | AD41: =IF($C$41<Assumptions!$B$57,Assumptions!$B$57*(Assumptions!$B$21+Assumptions!$B$22/Assumptions!$B$57)/(Assumptions!$B$21+Assumptions!$B$22/$C$41),Assumptions!$B$57) -> 57.701164 | AE41: =Assumptions!$B$58/$AD$41 -> 1.0398404 | AF41: =Assumptions!$B$59*$AE$41 -> 1733067.7 | AG41: =IF($C$41<Assumptions!$B$62,Assumptions!$B$62*(Assumptions!$B$21+Assumptions!$B$22/Assumptions!$B$62)/(Assumptions!$B$21+Assumptions!$B$22/$C$41),Assumptions!$B$62) -> 48.9291 | AH41: =Assumptions!$B$63/$AG$41 -> 1.0046845 | AI41: =Assumptions!$B$64*$AH$41 -> 6131255.2
A42: =ROW()-ROW($A$41)+Assumptions!$B$4 -> 1 | B42: =$P$41 -> 584871.32 | C42: =Assumptions!$B$6/(Assumptions!$B$16+$B$42) -> 37.631543 | D42: =Assumptions!$B$7/$C$42 -> 797203.55 | E42: =$T$42+$W$42+$Z$42+$AC$42+$AF$42+$AI$42 -> 23266958 | F42: =Assumptions!$B$70/(Assumptions!$B$20+Assumptions!$B$17+$B$42+$E$42+$O$41) -> 26.781785 | G42: =$C$42*(1-Assumptions!$B$71) -> 30.105235 | H42: =MIN($F$42,$G$42) -> 26.781785 | I42: =IF($F$42<=$G$42,"cap","discount") -> cap | J42: =Assumptions!$B$69/$H$42 -> 186694.05 | K42: =Assumptions!$B$74/(Assumptions!$B$20+Assumptions!$B$17+$B$42+$E$42+$J$42) -> 42.742817 | L42: =$C$42*(1-Assumptions!$B$75) -> 31.986812 | M42: =MIN($K$42,$L$42) -> 31.986812 | N42: =IF($K$42<=$L$42,"cap","discount") -> discount | O42: =Assumptions!$B$73/$M$42 -> 93788.653 | P42: =MAX(Assumptions!$B$4,(Assumptions!$B$10*(Assumptions!$B$20+$E$42+Assumptions!$B$17+$J$42+$O$42+$D$42)-Assumptions!$B$17)/(1-Assumptions!$B$10)) -> 587866.06 | Q42: =Assumptions!$B$20+$E$42+Assumptions!$B$17+$P$42+$J$42+$O$42+$D$42 -> 38327177 | R42: =IF($C$42<Assumptions!$B$37,Assumptions!$B$37*(Assumptions!$B$21+Assumptions!$B$22/Assumptions!$B$37)/(Assumptions!$B$21+Assumptions!$B$22/$C$42),Assumptions!$B$37) -> 1 | S42: =Assumptions!$B$38/$R$42 -> 1 | T42: =Assumptions!$B$39*$S$42 -> 5000000 | U42: =IF($C$42<Assumptions!$B$42,Assumptions!$B$42*(Assumptions!$B$21+Assumptions!$B$22/Assumptions!$B$42)/(Assumptions!$B$21+Assumptions!$B$22/$C$42),Assumptions!$B$42) -> 3 | V42: =Assumptions!$B$43/$U$42 -> 1 | W42: =Assumptions!$B$44*$V$42 -> 5000000 | X42: =IF($C$42<Assumptions!$B$47,Assumptions!$B$47*(Assumptions!$B$21+Assumptions!$B$22/Assumptions!$B$47)/(Assumptions!$B$21+Assumptions!$B$22/$C$42),Assumptions!$B$47) -> 10 | Y42: =Assumptions!$B$48/$X$42 -> 1 | Z42: =Assumptions!$B$49*$Y$42 -> 3000000 | AA42: =IF($C$42<Assumptions!$B$52,Assumptions!$B$52*(Assumptions!$B$21+Assumptions!$B$22/Assumptions!$B$52)/(Assumptions!$B$21+Assumptions!$B$22/$C$42),Assumptions!$B$52) -> 25 | AB42: =Assumptions!$B$53/$AA$42 -> 1 | AC42: =Assumptions!$B$54*$AB$42 -> 2400000 | AD42: =IF($C$42<Assumptions!$B$57,Assumptions!$B$57*(Assumptions!$B$21+Assumptions!$B$22/Assumptions!$B$57)/(Assumptions!$B$21+Assumptions!$B$22/$C$42),Assumptions!$B$57) -> 57.681835 | AE42: =Assumptions!$B$58/$AD$42 -> 1.0401888 | AF42: =Assumptions!$B$59*$AE$42 -> 1733648.4 | AG42: =IF($C$42<Assumptions!$B$62,Assumptions!$B$62*(Assumptions!$B$21+Assumptions!$B$22/Assumptions!$B$62)/(Assumptions!$B$21+Assumptions!$B$22/$C$42),Assumptions!$B$62) -> 48.912711 | AH42: =Assumptions!$B$63/$AG$42 -> 1.0050212 | AI42: =Assumptions!$B$64*$AH$42 -> 6133309.7
A43: =ROW()-ROW($A$41)+Assumptions!$B$4 -> 2 | B43: =$P$42 -> 587866.06 | C43: =Assumptions!$B$6/(Assumptions!$B$16+$B$43) -> 37.628514 | D43: =Assumptions!$B$7/$C$43 -> 797267.72 | E43: =$T$43+$W$43+$Z$43+$AC$43+$AF$43+$AI$43 -> 23266972 | F43: =Assumptions!$B$70/(Assumptions!$B$20+Assumptions!$B$17+$B$43+$E$43+$O$42) -> 26.77857 | G43: =$C$43*(1-Assumptions!$B$71) -> 30.102812 | H43: =MIN($F$43,$G$43) -> 26.77857 | I43: =IF($F$43<=$G$43,"cap","discount") -> cap | J43: =Assumptions!$B$69/$H$43 -> 186716.47 | K43: =Assumptions!$B$74/(Assumptions!$B$20+Assumptions!$B$17+$B$43+$E$43+$J$43) -> 42.739357 | L43: =$C$43*(1-Assumptions!$B$75) -> 31.984237 | M43: =MIN($K$43,$L$43) -> 31.984237 | N43: =IF($K$43<=$L$43,"cap","discount") -> discount | O43: =Assumptions!$B$73/$M$43 -> 93796.203 | P43: =MAX(Assumptions!$B$4,(Assumptions!$B$10*(Assumptions!$B$20+$E$43+Assumptions!$B$17+$J$43+$O$43+$D$43)-Assumptions!$B$17)/(1-Assumptions!$B$10)) -> 587882.14 | Q43: =Assumptions!$B$20+$E$43+Assumptions!$B$17+$P$43+$J$43+$O$43+$D$43 -> 38327301 | R43: =IF($C$43<Assumptions!$B$37,Assumptions!$B$37*(Assumptions!$B$21+Assumptions!$B$22/Assumptions!$B$37)/(Assumptions!$B$21+Assumptions!$B$22/$C$43),Assumptions!$B$37) -> 1 | S43: =Assumptions!$B$38/$R$43 -> 1 | T43: =Assumptions!$B$39*$S$43 -> 5000000 | U43: =IF($C$43<Assumptions!$B$42,Assumptions!$B$42*(Assumptions!$B$21+Assumptions!$B$22/Assumptions!$B$42)/(Assumptions!$B$21+Assumptions!$B$22/$C$43),Assumptions!$B$42) -> 3 | V43: =Assumptions!$B$43/$U$43 -> 1 | W43: =Assumptions!$B$44*$V$43 -> 5000000 | X43: =IF($C$43<Assumptions!$B$47,Assumptions!$B$47*(Assumptions!$B$21+Assumptions!$B$22/Assumptions!$B$47)/(Assumptions!$B$21+Assumptions!$B$22/$C$43),Assumptions!$B$47) -> 10 | Y43: =Assumptions!$B$48/$X$43 -> 1 | Z43: =Assumptions!$B$49*$Y$43 -> 3000000 | AA43: =IF($C$43<Assumptions!$B$52,Assumptions!$B$52*(Assumptions!$B$21+Assumptions!$B$22/Assumptions!$B$52)/(Assumptions!$B$21+Assumptions!$B$22/$C$43),Assumptions!$B$52) -> 25 | AB43: =Assumptions!$B$53/$AA$43 -> 1 | AC43: =Assumptions!$B$54*$AB$43 -> 2400000 | AD43: =IF($C$43<Assumptions!$B$57,Assumptions!$B$57*(Assumptions!$B$21+Assumptions!$B$22/Assumptions!$B$57)/(Assumptions!$B$21+Assumptions!$B$22/$C$43),Assumptions!$B$57) -> 57.681736 | AE43: =Assumptions!$B$58/$AD$43 -> 1.0401906 | AF43: =Assumptions!$B$59*$AE$43 -> 1733651.3 | AG43: =IF($C$43<Assumptions!$B$62,Assumptions!$B$62*(Assumptions!$B$21+Assumptions!$B$22/Assumptions!$B$62)/(Assumptions!$B$21+Assumptions!$B$22/$C$43),Assumptions!$B$62) -> 48.912627 | AH43: =Assumptions!$B$63/$AG$43 -> 1.0050229 | AI43: =Assumptions!$B$64*$AH$43 -> 6133320.2
A44: =ROW()-ROW($A$41)+Assumptions!$B$4 -> 3 | B44: =$P$43 -> 587882.14 | C44: =Assumptions!$B$6/(Assumptions!$B$16+$B$44) -> 37.628498 | D44: =Assumptions!$B$7/$C$44 -> 797268.07 | E44: =$T$44+$W$44+$Z$44+$AC$44+$AF$44+$AI$44 -> 23266972 | F44: =Assumptions!$B$70/(Assumptions!$B$20+Assumptions!$B$17+$B$44+$E$44+$O$43) -> 26.778553 | G44: =$C$44*(1-Assumptions!$B$71) -> 30.102799 | H44: =MIN($F$44,$G$44) -> 26.778553 | I44: =IF($F$44<=$G$44,"cap","discount") -> cap | J44: =Assumptions!$B$69/$H$44 -> 186716.58 | K44: =Assumptions!$B$74/(Assumptions!$B$20+Assumptions!$B$17+$B$44+$E$44+$J$44) -> 42.739338 | L44: =$C$44*(1-Assumptions!$B$75) -> 31.984223 | M44: =MIN($K$44,$L$44) -> 31.984223 | N44: =IF($K$44<=$L$44,"cap","discount") -> discount | O44: =Assumptions!$B$73/$M$44 -> 93796.243 | P44: =MAX(Assumptions!$B$4,(Assumptions!$B$10*(Assumptions!$B$20+$E$44+Assumptions!$B$17+$J$44+$O$44+$D$44)-Assumptions!$B$17)/(1-Assumptions!$B$10)) -> 587882.23 | Q44: =Assumptions!$B$20+$E$44+Assumptions!$B$17+$P$44+$J$44+$O$44+$D$44 -> 38327302 | R44: =IF($C$44<Assumptions!$B$37,Assumptions!$B$37*(Assumptions!$B$21+Assumptions!$B$22/Assumptions!$B$37)/(Assumptions!$B$21+Assumptions!$B$22/$C$44),Assumptions!$B$37) -> 1 | S44: =Assumptions!$B$38/$R$44 -> 1 | T44: =Assumptions!$B$39*$S$44 -> 5000000 | U44: =IF($C$44<Assumptions!$B$42,Assumptions!$B$42*(Assumptions!$B$21+Assumptions!$B$22/Assumptions!$B$42)/(Assumptions!$B$21+Assumptions!$B$22/$C$44),Assumptions!$B$42) -> 3 | V44: =Assumptions!$B$43/$U$44 -> 1 | W44: =Assumptions!$B$44*$V$44 -> 5000000 | X44: =IF($C$44<Assumptions!$B$47,Assumptions!$B$47*(Assumptions!$B$21+Assumptions!$B$22/Assumptions!$B$47)/(Assumptions!$B$21+Assumptions!$B$22/$C$44),Assumptions!$B$47) -> 10 | Y44: =Assumptions!$B$48/$X$44 -> 1 | Z44: =Assumptions!$B$49*$Y$44 -> 3000000 | AA44: =IF($C$44<Assumptions!$B$52,Assumptions!$B$52*(Assumptions!$B$21+Assumptions!$B$22/Assumptions!$B$52)/(Assumptions!$B$21+Assumptions!$B$22/$C$44),Assumptions!$B$52) -> 25 | AB44: =Assumptions!$B$53/$AA$44 -> 1 | AC44: =Assumptions!$B$54*$AB$44 -> 2400000 | AD44: =IF($C$44<Assumptions!$B$57,Assumptions!$B$57*(Assumptions!$B$21+Assumptions!$B$22/Assumptions!$B$57)/(Assumptions!$B$21+Assumptions!$B$22/$C$44),Assumptions!$B$57) -> 57.681736 | AE44: =Assumptions!$B$58/$AD$44 -> 1.0401906 | AF44: =Assumptions!$B$59*$AE$44 -> 1733651.4 | AG44: =IF($C$44<Assumptions!$B$62,Assumptions!$B$62*(Assumptions!$B$21+Assumptions!$B$22/Assumptions!$B$62)/(Assumptions!$B$21+Assumptions!$B$22/$C$44),Assumptions!$B$62) -> 48.912626 | AH44: =Assumptions!$B$63/$AG$44 -> 1.0050229 | AI44: =Assumptions!$B$64*$AH$44 -> 6133320.3
A45: =ROW()-ROW($A$41)+Assumptions!$B$4 -> 4 | B45: =$P$44 -> 587882.23 | C45: =Assumptions!$B$6/(Assumptions!$B$16+$B$45) -> 37.628498 | D45: =Assumptions!$B$7/$C$45 -> 797268.07 | E45: =$T$45+$W$45+$Z$45+$AC$45+$AF$45+$AI$45 -> 23266972 | F45: =Assumptions!$B$70/(Assumptions!$B$20+Assumptions!$B$17+$B$45+$E$45+$O$44) -> 26.778553 | G45: =$C$45*(1-Assumptions!$B$71) -> 30.102798 | H45: =MIN($F$45,$G$45) -> 26.778553 | I45: =IF($F$45<=$G$45,"cap","discount") -> cap | J45: =Assumptions!$B$69/$H$45 -> 186716.59 | K45: =Assumptions!$B$74/(Assumptions!$B$20+Assumptions!$B$17+$B$45+$E$45+$J$45) -> 42.739338 | L45: =$C$45*(1-Assumptions!$B$75) -> 31.984223 | M45: =MIN($K$45,$L$45) -> 31.984223 | N45: =IF($K$45<=$L$45,"cap","discount") -> discount | O45: =Assumptions!$B$73/$M$45 -> 93796.243 | P45: =MAX(Assumptions!$B$4,(Assumptions!$B$10*(Assumptions!$B$20+$E$45+Assumptions!$B$17+$J$45+$O$45+$D$45)-Assumptions!$B$17)/(1-Assumptions!$B$10)) -> 587882.23 | Q45: =Assumptions!$B$20+$E$45+Assumptions!$B$17+$P$45+$J$45+$O$45+$D$45 -> 38327302 | R45: =IF($C$45<Assumptions!$B$37,Assumptions!$B$37*(Assumptions!$B$21+Assumptions!$B$22/Assumptions!$B$37)/(Assumptions!$B$21+Assumptions!$B$22/$C$45),Assumptions!$B$37) -> 1 | S45: =Assumptions!$B$38/$R$45 -> 1 | T45: =Assumptions!$B$39*$S$45 -> 5000000 | U45: =IF($C$45<Assumptions!$B$42,Assumptions!$B$42*(Assumptions!$B$21+Assumptions!$B$22/Assumptions!$B$42)/(Assumptions!$B$21+Assumptions!$B$22/$C$45),Assumptions!$B$42) -> 3 | V45: =Assumptions!$B$43/$U$45 -> 1 | W45: =Assumptions!$B$44*$V$45 -> 5000000 | X45: =IF($C$45<Assumptions!$B$47,Assumptions!$B$47*(Assumptions!$B$21+Assumptions!$B$22/Assumptions!$B$47)/(Assumptions!$B$21+Assumptions!$B$22/$C$45),Assumptions!$B$47) -> 10 | Y45: =Assumptions!$B$48/$X$45 -> 1 | Z45: =Assumptions!$B$49*$Y$45 -> 3000000 | AA45: =IF($C$45<Assumptions!$B$52,Assumptions!$B$52*(Assumptions!$B$21+Assumptions!$B$22/Assumptions!$B$52)/(Assumptions!$B$21+Assumptions!$B$22/$C$45),Assumptions!$B$52) -> 25 | AB45: =Assumptions!$B$53/$AA$45 -> 1 | AC45: =Assumptions!$B$54*$AB$45 -> 2400000 | AD45: =IF($C$45<Assumptions!$B$57,Assumptions!$B$57*(Assumptions!$B$21+Assumptions!$B$22/Assumptions!$B$57)/(Assumptions!$B$21+Assumptions!$B$22/$C$45),Assumptions!$B$57) -> 57.681736 | AE45: =Assumptions!$B$58/$AD$45 -> 1.0401906 | AF45: =Assumptions!$B$59*$AE$45 -> 1733651.4 | AG45: =IF($C$45<Assumptions!$B$62,Assumptions!$B$62*(Assumptions!$B$21+Assumptions!$B$22/Assumptions!$B$62)/(Assumptions!$B$21+Assumptions!$B$22/$C$45),Assumptions!$B$62) -> 48.912626 | AH45: =Assumptions!$B$63/$AG$45 -> 1.0050229 | AI45: =Assumptions!$B$64*$AH$45 -> 6133320.3
A46: =ROW()-ROW($A$41)+Assumptions!$B$4 -> 5 | B46: =$P$45 -> 587882.23 | C46: =Assumptions!$B$6/(Assumptions!$B$16+$B$46) -> 37.628498 | D46: =Assumptions!$B$7/$C$46 -> 797268.07 | E46: =$T$46+$W$46+$Z$46+$AC$46+$AF$46+$AI$46 -> 23266972 | F46: =Assumptions!$B$70/(Assumptions!$B$20+Assumptions!$B$17+$B$46+$E$46+$O$45) -> 26.778553 | G46: =$C$46*(1-Assumptions!$B$71) -> 30.102798 | H46: =MIN($F$46,$G$46) -> 26.778553 | I46: =IF($F$46<=$G$46,"cap","discount") -> cap | J46: =Assumptions!$B$69/$H$46 -> 186716.59 | K46: =Assumptions!$B$74/(Assumptions!$B$20+Assumptions!$B$17+$B$46+$E$46+$J$46) -> 42.739338 | L46: =$C$46*(1-Assumptions!$B$75) -> 31.984223 | M46: =MIN($K$46,$L$46) -> 31.984223 | N46: =IF($K$46<=$L$46,"cap","discount") -> discount | O46: =Assumptions!$B$73/$M$46 -> 93796.243 | P46: =MAX(Assumptions!$B$4,(Assumptions!$B$10*(Assumptions!$B$20+$E$46+Assumptions!$B$17+$J$46+$O$46+$D$46)-Assumptions!$B$17)/(1-Assumptions!$B$10)) -> 587882.23 | Q46: =Assumptions!$B$20+$E$46+Assumptions!$B$17+$P$46+$J$46+$O$46+$D$46 -> 38327302 | R46: =IF($C$46<Assumptions!$B$37,Assumptions!$B$37*(Assumptions!$B$21+Assumptions!$B$22/Assumptions!$B$37)/(Assumptions!$B$21+Assumptions!$B$22/$C$46),Assumptions!$B$37) -> 1 | S46: =Assumptions!$B$38/$R$46 -> 1 | T46: =Assumptions!$B$39*$S$46 -> 5000000 | U46: =IF($C$46<Assumptions!$B$42,Assumptions!$B$42*(Assumptions!$B$21+Assumptions!$B$22/Assumptions!$B$42)/(Assumptions!$B$21+Assumptions!$B$22/$C$46),Assumptions!$B$42) -> 3 | V46: =Assumptions!$B$43/$U$46 -> 1 | W46: =Assumptions!$B$44*$V$46 -> 5000000 | X46: =IF($C$46<Assumptions!$B$47,Assumptions!$B$47*(Assumptions!$B$21+Assumptions!$B$22/Assumptions!$B$47)/(Assumptions!$B$21+Assumptions!$B$22/$C$46),Assumptions!$B$47) -> 10 | Y46: =Assumptions!$B$48/$X$46 -> 1 | Z46: =Assumptions!$B$49*$Y$46 -> 3000000 | AA46: =IF($C$46<Assumptions!$B$52,Assumptions!$B$52*(Assumptions!$B$21+Assumptions!$B$22/Assumptions!$B$52)/(Assumptions!$B$21+Assumptions!$B$22/$C$46),Assumptions!$B$52) -> 25 | AB46: =Assumptions!$B$53/$AA$46 -> 1 | AC46: =Assumptions!$B$54*$AB$46 -> 2400000 | AD46: =IF($C$46<Assumptions!$B$57,Assumptions!$B$57*(Assumptions!$B$21+Assumptions!$B$22/Assumptions!$B$57)/(Assumptions!$B$21+Assumptions!$B$22/$C$46),Assumptions!$B$57) -> 57.681736 | AE46: =Assumptions!$B$58/$AD$46 -> 1.0401906 | AF46: =Assumptions!$B$59*$AE$46 -> 1733651.4 | AG46: =IF($C$46<Assumptions!$B$62,Assumptions!$B$62*(Assumptions!$B$21+Assumptions!$B$22/Assumptions!$B$62)/(Assumptions!$B$21+Assumptions!$B$22/$C$46),Assumptions!$B$62) -> 48.912626 | AH46: =Assumptions!$B$63/$AG$46 -> 1.0050229 | AI46: =Assumptions!$B$64*$AH$46 -> 6133320.3
A47: =ROW()-ROW($A$41)+Assumptions!$B$4 -> 6 | B47: =$P$46 -> 587882.23 | C47: =Assumptions!$B$6/(Assumptions!$B$16+$B$47) -> 37.628498 | D47: =Assumptions!$B$7/$C$47 -> 797268.07 | E47: =$T$47+$W$47+$Z$47+$AC$47+$AF$47+$AI$47 -> 23266972 | F47: =Assumptions!$B$70/(Assumptions!$B$20+Assumptions!$B$17+$B$47+$E$47+$O$46) -> 26.778553 | G47: =$C$47*(1-Assumptions!$B$71) -> 30.102798 | H47: =MIN($F$47,$G$47) -> 26.778553 | I47: =IF($F$47<=$G$47,"cap","discount") -> cap | J47: =Assumptions!$B$69/$H$47 -> 186716.59 | K47: =Assumptions!$B$74/(Assumptions!$B$20+Assumptions!$B$17+$B$47+$E$47+$J$47) -> 42.739338 | L47: =$C$47*(1-Assumptions!$B$75) -> 31.984223 | M47: =MIN($K$47,$L$47) -> 31.984223 | N47: =IF($K$47<=$L$47,"cap","discount") -> discount | O47: =Assumptions!$B$73/$M$47 -> 93796.243 | P47: =MAX(Assumptions!$B$4,(Assumptions!$B$10*(Assumptions!$B$20+$E$47+Assumptions!$B$17+$J$47+$O$47+$D$47)-Assumptions!$B$17)/(1-Assumptions!$B$10)) -> 587882.23 | Q47: =Assumptions!$B$20+$E$47+Assumptions!$B$17+$P$47+$J$47+$O$47+$D$47 -> 38327302 | R47: =IF($C$47<Assumptions!$B$37,Assumptions!$B$37*(Assumptions!$B$21+Assumptions!$B$22/Assumptions!$B$37)/(Assumptions!$B$21+Assumptions!$B$22/$C$47),Assumptions!$B$37) -> 1 | S47: =Assumptions!$B$38/$R$47 -> 1 | T47: =Assumptions!$B$39*$S$47 -> 5000000 | U47: =IF($C$47<Assumptions!$B$42,Assumptions!$B$42*(Assumptions!$B$21+Assumptions!$B$22/Assumptions!$B$42)/(Assumptions!$B$21+Assumptions!$B$22/$C$47),Assumptions!$B$42) -> 3 | V47: =Assumptions!$B$43/$U$47 -> 1 | W47: =Assumptions!$B$44*$V$47 -> 5000000 | X47: =IF($C$47<Assumptions!$B$47,Assumptions!$B$47*(Assumptions!$B$21+Assumptions!$B$22/Assumptions!$B$47)/(Assumptions!$B$21+Assumptions!$B$22/$C$47),Assumptions!$B$47) -> 10 | Y47: =Assumptions!$B$48/$X$47 -> 1 | Z47: =Assumptions!$B$49*$Y$47 -> 3000000 | AA47: =IF($C$47<Assumptions!$B$52,Assumptions!$B$52*(Assumptions!$B$21+Assumptions!$B$22/Assumptions!$B$52)/(Assumptions!$B$21+Assumptions!$B$22/$C$47),Assumptions!$B$52) -> 25 | AB47: =Assumptions!$B$53/$AA$47 -> 1 | AC47: =Assumptions!$B$54*$AB$47 -> 2400000 | AD47: =IF($C$47<Assumptions!$B$57,Assumptions!$B$57*(Assumptions!$B$21+Assumptions!$B$22/Assumptions!$B$57)/(Assumptions!$B$21+Assumptions!$B$22/$C$47),Assumptions!$B$57) -> 57.681736 | AE47: =Assumptions!$B$58/$AD$47 -> 1.0401906 | AF47: =Assumptions!$B$59*$AE$47 -> 1733651.4 | AG47: =IF($C$47<Assumptions!$B$62,Assumptions!$B$62*(Assumptions!$B$21+Assumptions!$B$22/Assumptions!$B$62)/(Assumptions!$B$21+Assumptions!$B$22/$C$47),Assumptions!$B$62) -> 48.912626 | AH47: =Assumptions!$B$63/$AG$47 -> 1.0050229 | AI47: =Assumptions!$B$64*$AH$47 -> 6133320.3
A48: =ROW()-ROW($A$41)+Assumptions!$B$4 -> 7 | B48: =$P$47 -> 587882.23 | C48: =Assumptions!$B$6/(Assumptions!$B$16+$B$48) -> 37.628498 | D48: =Assumptions!$B$7/$C$48 -> 797268.07 | E48: =$T$48+$W$48+$Z$48+$AC$48+$AF$48+$AI$48 -> 23266972 | F48: =Assumptions!$B$70/(Assumptions!$B$20+Assumptions!$B$17+$B$48+$E$48+$O$47) -> 26.778553 | G48: =$C$48*(1-Assumptions!$B$71) -> 30.102798 | H48: =MIN($F$48,$G$48) -> 26.778553 | I48: =IF($F$48<=$G$48,"cap","discount") -> cap | J48: =Assumptions!$B$69/$H$48 -> 186716.59 | K48: =Assumptions!$B$74/(Assumptions!$B$20+Assumptions!$B$17+$B$48+$E$48+$J$48) -> 42.739338 | L48: =$C$48*(1-Assumptions!$B$75) -> 31.984223 | M48: =MIN($K$48,$L$48) -> 31.984223 | N48: =IF($K$48<=$L$48,"cap","discount") -> discount | O48: =Assumptions!$B$73/$M$48 -> 93796.243 | P48: =MAX(Assumptions!$B$4,(Assumptions!$B$10*(Assumptions!$B$20+$E$48+Assumptions!$B$17+$J$48+$O$48+$D$48)-Assumptions!$B$17)/(1-Assumptions!$B$10)) -> 587882.23 | Q48: =Assumptions!$B$20+$E$48+Assumptions!$B$17+$P$48+$J$48+$O$48+$D$48 -> 38327302 | R48: =IF($C$48<Assumptions!$B$37,Assumptions!$B$37*(Assumptions!$B$21+Assumptions!$B$22/Assumptions!$B$37)/(Assumptions!$B$21+Assumptions!$B$22/$C$48),Assumptions!$B$37) -> 1 | S48: =Assumptions!$B$38/$R$48 -> 1 | T48: =Assumptions!$B$39*$S$48 -> 5000000 | U48: =IF($C$48<Assumptions!$B$42,Assumptions!$B$42*(Assumptions!$B$21+Assumptions!$B$22/Assumptions!$B$42)/(Assumptions!$B$21+Assumptions!$B$22/$C$48),Assumptions!$B$42) -> 3 | V48: =Assumptions!$B$43/$U$48 -> 1 | W48: =Assumptions!$B$44*$V$48 -> 5000000 | X48: =IF($C$48<Assumptions!$B$47,Assumptions!$B$47*(Assumptions!$B$21+Assumptions!$B$22/Assumptions!$B$47)/(Assumptions!$B$21+Assumptions!$B$22/$C$48),Assumptions!$B$47) -> 10 | Y48: =Assumptions!$B$48/$X$48 -> 1 | Z48: =Assumptions!$B$49*$Y$48 -> 3000000 | AA48: =IF($C$48<Assumptions!$B$52,Assumptions!$B$52*(Assumptions!$B$21+Assumptions!$B$22/Assumptions!$B$52)/(Assumptions!$B$21+Assumptions!$B$22/$C$48),Assumptions!$B$52) -> 25 | AB48: =Assumptions!$B$53/$AA$48 -> 1 | AC48: =Assumptions!$B$54*$AB$48 -> 2400000 | AD48: =IF($C$48<Assumptions!$B$57,Assumptions!$B$57*(Assumptions!$B$21+Assumptions!$B$22/Assumptions!$B$57)/(Assumptions!$B$21+Assumptions!$B$22/$C$48),Assumptions!$B$57) -> 57.681736 | AE48: =Assumptions!$B$58/$AD$48 -> 1.0401906 | AF48: =Assumptions!$B$59*$AE$48 -> 1733651.4 | AG48: =IF($C$48<Assumptions!$B$62,Assumptions!$B$62*(Assumptions!$B$21+Assumptions!$B$22/Assumptions!$B$62)/(Assumptions!$B$21+Assumptions!$B$22/$C$48),Assumptions!$B$62) -> 48.912626 | AH48: =Assumptions!$B$63/$AG$48 -> 1.0050229 | AI48: =Assumptions!$B$64*$AH$48 -> 6133320.3
A49: =ROW()-ROW($A$41)+Assumptions!$B$4 -> 8 | B49: =$P$48 -> 587882.23 | C49: =Assumptions!$B$6/(Assumptions!$B$16+$B$49) -> 37.628498 | D49: =Assumptions!$B$7/$C$49 -> 797268.07 | E49: =$T$49+$W$49+$Z$49+$AC$49+$AF$49+$AI$49 -> 23266972 | F49: =Assumptions!$B$70/(Assumptions!$B$20+Assumptions!$B$17+$B$49+$E$49+$O$48) -> 26.778553 | G49: =$C$49*(1-Assumptions!$B$71) -> 30.102798 | H49: =MIN($F$49,$G$49) -> 26.778553 | I49: =IF($F$49<=$G$49,"cap","discount") -> cap | J49: =Assumptions!$B$69/$H$49 -> 186716.59 | K49: =Assumptions!$B$74/(Assumptions!$B$20+Assumptions!$B$17+$B$49+$E$49+$J$49) -> 42.739338 | L49: =$C$49*(1-Assumptions!$B$75) -> 31.984223 | M49: =MIN($K$49,$L$49) -> 31.984223 | N49: =IF($K$49<=$L$49,"cap","discount") -> discount | O49: =Assumptions!$B$73/$M$49 -> 93796.243 | P49: =MAX(Assumptions!$B$4,(Assumptions!$B$10*(Assumptions!$B$20+$E$49+Assumptions!$B$17+$J$49+$O$49+$D$49)-Assumptions!$B$17)/(1-Assumptions!$B$10)) -> 587882.23 | Q49: =Assumptions!$B$20+$E$49+Assumptions!$B$17+$P$49+$J$49+$O$49+$D$49 -> 38327302 | R49: =IF($C$49<Assumptions!$B$37,Assumptions!$B$37*(Assumptions!$B$21+Assumptions!$B$22/Assumptions!$B$37)/(Assumptions!$B$21+Assumptions!$B$22/$C$49),Assumptions!$B$37) -> 1 | S49: =Assumptions!$B$38/$R$49 -> 1 | T49: =Assumptions!$B$39*$S$49 -> 5000000 | U49: =IF($C$49<Assumptions!$B$42,Assumptions!$B$42*(Assumptions!$B$21+Assumptions!$B$22/Assumptions!$B$42)/(Assumptions!$B$21+Assumptions!$B$22/$C$49),Assumptions!$B$42) -> 3 | V49: =Assumptions!$B$43/$U$49 -> 1 | W49: =Assumptions!$B$44*$V$49 -> 5000000 | X49: =IF($C$49<Assumptions!$B$47,Assumptions!$B$47*(Assumptions!$B$21+Assumptions!$B$22/Assumptions!$B$47)/(Assumptions!$B$21+Assumptions!$B$22/$C$49),Assumptions!$B$47) -> 10 | Y49: =Assumptions!$B$48/$X$49 -> 1 | Z49: =Assumptions!$B$49*$Y$49 -> 3000000 | AA49: =IF($C$49<Assumptions!$B$52,Assumptions!$B$52*(Assumptions!$B$21+Assumptions!$B$22/Assumptions!$B$52)/(Assumptions!$B$21+Assumptions!$B$22/$C$49),Assumptions!$B$52) -> 25 | AB49: =Assumptions!$B$53/$AA$49 -> 1 | AC49: =Assumptions!$B$54*$AB$49 -> 2400000 | AD49: =IF($C$49<Assumptions!$B$57,Assumptions!$B$57*(Assumptions!$B$21+Assumptions!$B$22/Assumptions!$B$57)/(Assumptions!$B$21+Assumptions!$B$22/$C$49),Assumptions!$B$57) -> 57.681736 | AE49: =Assumptions!$B$58/$AD$49 -> 1.0401906 | AF49: =Assumptions!$B$59*$AE$49 -> 1733651.4 | AG49: =IF($C$49<Assumptions!$B$62,Assumptions!$B$62*(Assumptions!$B$21+Assumptions!$B$22/Assumptions!$B$62)/(Assumptions!$B$21+Assumptions!$B$22/$C$49),Assumptions!$B$62) -> 48.912626 | AH49: =Assumptions!$B$63/$AG$49 -> 1.0050229 | AI49: =Assumptions!$B$64*$AH$49 -> 6133320.3
A50: =ROW()-ROW($A$41)+Assumptions!$B$4 -> 9 | B50: =$P$49 -> 587882.23 | C50: =Assumptions!$B$6/(Assumptions!$B$16+$B$50) -> 37.628498 | D50: =Assumptions!$B$7/$C$50 -> 797268.07 | E50: =$T$50+$W$50+$Z$50+$AC$50+$AF$50+$AI$50 -> 23266972 | F50: =Assumptions!$B$70/(Assumptions!$B$20+Assumptions!$B$17+$B$50+$E$50+$O$49) -> 26.778553 | G50: =$C$50*(1-Assumptions!$B$71) -> 30.102798 | H50: =MIN($F$50,$G$50) -> 26.778553 | I50: =IF($F$50<=$G$50,"cap","discount") -> cap | J50: =Assumptions!$B$69/$H$50 -> 186716.59 | K50: =Assumptions!$B$74/(Assumptions!$B$20+Assumptions!$B$17+$B$50+$E$50+$J$50) -> 42.739338 | L50: =$C$50*(1-Assumptions!$B$75) -> 31.984223 | M50: =MIN($K$50,$L$50) -> 31.984223 | N50: =IF($K$50<=$L$50,"cap","discount") -> discount | O50: =Assumptions!$B$73/$M$50 -> 93796.243 | P50: =MAX(Assumptions!$B$4,(Assumptions!$B$10*(Assumptions!$B$20+$E$50+Assumptions!$B$17+$J$50+$O$50+$D$50)-Assumptions!$B$17)/(1-Assumptions!$B$10)) -> 587882.23 | Q50: =Assumptions!$B$20+$E$50+Assumptions!$B$17+$P$50+$J$50+$O$50+$D$50 -> 38327302 | R50: =IF($C$50<Assumptions!$B$37,Assumptions!$B$37*(Assumptions!$B$21+Assumptions!$B$22/Assumptions!$B$37)/(Assumptions!$B$21+Assumptions!$B$22/$C$50),Assumptions!$B$37) -> 1 | S50: =Assumptions!$B$38/$R$50 -> 1 | T50: =Assumptions!$B$39*$S$50 -> 5000000 | U50: =IF($C$50<Assumptions!$B$42,Assumptions!$B$42*(Assumptions!$B$21+Assumptions!$B$22/Assumptions!$B$42)/(Assumptions!$B$21+Assumptions!$B$22/$C$50),Assumptions!$B$42) -> 3 | V50: =Assumptions!$B$43/$U$50 -> 1 | W50: =Assumptions!$B$44*$V$50 -> 5000000 | X50: =IF($C$50<Assumptions!$B$47,Assumptions!$B$47*(Assumptions!$B$21+Assumptions!$B$22/Assumptions!$B$47)/(Assumptions!$B$21+Assumptions!$B$22/$C$50),Assumptions!$B$47) -> 10 | Y50: =Assumptions!$B$48/$X$50 -> 1 | Z50: =Assumptions!$B$49*$Y$50 -> 3000000 | AA50: =IF($C$50<Assumptions!$B$52,Assumptions!$B$52*(Assumptions!$B$21+Assumptions!$B$22/Assumptions!$B$52)/(Assumptions!$B$21+Assumptions!$B$22/$C$50),Assumptions!$B$52) -> 25 | AB50: =Assumptions!$B$53/$AA$50 -> 1 | AC50: =Assumptions!$B$54*$AB$50 -> 2400000 | AD50: =IF($C$50<Assumptions!$B$57,Assumptions!$B$57*(Assumptions!$B$21+Assumptions!$B$22/Assumptions!$B$57)/(Assumptions!$B$21+Assumptions!$B$22/$C$50),Assumptions!$B$57) -> 57.681736 | AE50: =Assumptions!$B$58/$AD$50 -> 1.0401906 | AF50: =Assumptions!$B$59*$AE$50 -> 1733651.4 | AG50: =IF($C$50<Assumptions!$B$62,Assumptions!$B$62*(Assumptions!$B$21+Assumptions!$B$22/Assumptions!$B$62)/(Assumptions!$B$21+Assumptions!$B$22/$C$50),Assumptions!$B$62) -> 48.912626 | AH50: =Assumptions!$B$63/$AG$50 -> 1.0050229 | AI50: =Assumptions!$B$64*$AH$50 -> 6133320.3
A51: =ROW()-ROW($A$41)+Assumptions!$B$4 -> 10 | B51: =$P$50 -> 587882.23 | C51: =Assumptions!$B$6/(Assumptions!$B$16+$B$51) -> 37.628498 | D51: =Assumptions!$B$7/$C$51 -> 797268.07 | E51: =$T$51+$W$51+$Z$51+$AC$51+$AF$51+$AI$51 -> 23266972 | F51: =Assumptions!$B$70/(Assumptions!$B$20+Assumptions!$B$17+$B$51+$E$51+$O$50) -> 26.778553 | G51: =$C$51*(1-Assumptions!$B$71) -> 30.102798 | H51: =MIN($F$51,$G$51) -> 26.778553 | I51: =IF($F$51<=$G$51,"cap","discount") -> cap | J51: =Assumptions!$B$69/$H$51 -> 186716.59 | K51: =Assumptions!$B$74/(Assumptions!$B$20+Assumptions!$B$17+$B$51+$E$51+$J$51) -> 42.739338 | L51: =$C$51*(1-Assumptions!$B$75) -> 31.984223 | M51: =MIN($K$51,$L$51) -> 31.984223 | N51: =IF($K$51<=$L$51,"cap","discount") -> discount | O51: =Assumptions!$B$73/$M$51 -> 93796.243 | P51: =MAX(Assumptions!$B$4,(Assumptions!$B$10*(Assumptions!$B$20+$E$51+Assumptions!$B$17+$J$51+$O$51+$D$51)-Assumptions!$B$17)/(1-Assumptions!$B$10)) -> 587882.23 | Q51: =Assumptions!$B$20+$E$51+Assumptions!$B$17+$P$51+$J$51+$O$51+$D$51 -> 38327302 | R51: =IF($C$51<Assumptions!$B$37,Assumptions!$B$37*(Assumptions!$B$21+Assumptions!$B$22/Assumptions!$B$37)/(Assumptions!$B$21+Assumptions!$B$22/$C$51),Assumptions!$B$37) -> 1 | S51: =Assumptions!$B$38/$R$51 -> 1 | T51: =Assumptions!$B$39*$S$51 -> 5000000 | U51: =IF($C$51<Assumptions!$B$42,Assumptions!$B$42*(Assumptions!$B$21+Assumptions!$B$22/Assumptions!$B$42)/(Assumptions!$B$21+Assumptions!$B$22/$C$51),Assumptions!$B$42) -> 3 | V51: =Assumptions!$B$43/$U$51 -> 1 | W51: =Assumptions!$B$44*$V$51 -> 5000000 | X51: =IF($C$51<Assumptions!$B$47,Assumptions!$B$47*(Assumptions!$B$21+Assumptions!$B$22/Assumptions!$B$47)/(Assumptions!$B$21+Assumptions!$B$22/$C$51),Assumptions!$B$47) -> 10 | Y51: =Assumptions!$B$48/$X$51 -> 1 | Z51: =Assumptions!$B$49*$Y$51 -> 3000000 | AA51: =IF($C$51<Assumptions!$B$52,Assumptions!$B$52*(Assumptions!$B$21+Assumptions!$B$22/Assumptions!$B$52)/(Assumptions!$B$21+Assumptions!$B$22/$C$51),Assumptions!$B$52) -> 25 | AB51: =Assumptions!$B$53/$AA$51 -> 1 | AC51: =Assumptions!$B$54*$AB$51 -> 2400000 | AD51: =IF($C$51<Assumptions!$B$57,Assumptions!$B$57*(Assumptions!$B$21+Assumptions!$B$22/Assumptions!$B$57)/(Assumptions!$B$21+Assumptions!$B$22/$C$51),Assumptions!$B$57) -> 57.681736 | AE51: =Assumptions!$B$58/$AD$51 -> 1.0401906 | AF51: =Assumptions!$B$59*$AE$51 -> 1733651.4 | AG51: =IF($C$51<Assumptions!$B$62,Assumptions!$B$62*(Assumptions!$B$21+Assumptions!$B$22/Assumptions!$B$62)/(Assumptions!$B$21+Assumptions!$B$22/$C$51),Assumptions!$B$62) -> 48.912626 | AH51: =Assumptions!$B$63/$AG$51 -> 1.0050229 | AI51: =Assumptions!$B$64*$AH$51 -> 6133320.3
A52: =ROW()-ROW($A$41)+Assumptions!$B$4 -> 11 | B52: =$P$51 -> 587882.23 | C52: =Assumptions!$B$6/(Assumptions!$B$16+$B$52) -> 37.628498 | D52: =Assumptions!$B$7/$C$52 -> 797268.07 | E52: =$T$52+$W$52+$Z$52+$AC$52+$AF$52+$AI$52 -> 23266972 | F52: =Assumptions!$B$70/(Assumptions!$B$20+Assumptions!$B$17+$B$52+$E$52+$O$51) -> 26.778553 | G52: =$C$52*(1-Assumptions!$B$71) -> 30.102798 | H52: =MIN($F$52,$G$52) -> 26.778553 | I52: =IF($F$52<=$G$52,"cap","discount") -> cap | J52: =Assumptions!$B$69/$H$52 -> 186716.59 | K52: =Assumptions!$B$74/(Assumptions!$B$20+Assumptions!$B$17+$B$52+$E$52+$J$52) -> 42.739338 | L52: =$C$52*(1-Assumptions!$B$75) -> 31.984223 | M52: =MIN($K$52,$L$52) -> 31.984223 | N52: =IF($K$52<=$L$52,"cap","discount") -> discount | O52: =Assumptions!$B$73/$M$52 -> 93796.243 | P52: =MAX(Assumptions!$B$4,(Assumptions!$B$10*(Assumptions!$B$20+$E$52+Assumptions!$B$17+$J$52+$O$52+$D$52)-Assumptions!$B$17)/(1-Assumptions!$B$10)) -> 587882.23 | Q52: =Assumptions!$B$20+$E$52+Assumptions!$B$17+$P$52+$J$52+$O$52+$D$52 -> 38327302 | R52: =IF($C$52<Assumptions!$B$37,Assumptions!$B$37*(Assumptions!$B$21+Assumptions!$B$22/Assumptions!$B$37)/(Assumptions!$B$21+Assumptions!$B$22/$C$52),Assumptions!$B$37) -> 1 | S52: =Assumptions!$B$38/$R$52 -> 1 | T52: =Assumptions!$B$39*$S$52 -> 5000000 | U52: =IF($C$52<Assumptions!$B$42,Assumptions!$B$42*(Assumptions!$B$21+Assumptions!$B$22/Assumptions!$B$42)/(Assumptions!$B$21+Assumptions!$B$22/$C$52),Assumptions!$B$42) -> 3 | V52: =Assumptions!$B$43/$U$52 -> 1 | W52: =Assumptions!$B$44*$V$52 -> 5000000 | X52: =IF($C$52<Assumptions!$B$47,Assumptions!$B$47*(Assumptions!$B$21+Assumptions!$B$22/Assumptions!$B$47)/(Assumptions!$B$21+Assumptions!$B$22/$C$52),Assumptions!$B$47) -> 10 | Y52: =Assumptions!$B$48/$X$52 -> 1 | Z52: =Assumptions!$B$49*$Y$52 -> 3000000 | AA52: =IF($C$52<Assumptions!$B$52,Assumptions!$B$52*(Assumptions!$B$21+Assumptions!$B$22/Assumptions!$B$52)/(Assumptions!$B$21+Assumptions!$B$22/$C$52),Assumptions!$B$52) -> 25 | AB52: =Assumptions!$B$53/$AA$52 -> 1 | AC52: =Assumptions!$B$54*$AB$52 -> 2400000 | AD52: =IF($C$52<Assumptions!$B$57,Assumptions!$B$57*(Assumptions!$B$21+Assumptions!$B$22/Assumptions!$B$57)/(Assumptions!$B$21+Assumptions!$B$22/$C$52),Assumptions!$B$57) -> 57.681736 | AE52: =Assumptions!$B$58/$AD$52 -> 1.0401906 | AF52: =Assumptions!$B$59*$AE$52 -> 1733651.4 | AG52: =IF($C$52<Assumptions!$B$62,Assumptions!$B$62*(Assumptions!$B$21+Assumptions!$B$22/Assumptions!$B$62)/(Assumptions!$B$21+Assumptions!$B$22/$C$52),Assumptions!$B$62) -> 48.912626 | AH52: =Assumptions!$B$63/$AG$52 -> 1.0050229 | AI52: =Assumptions!$B$64*$AH$52 -> 6133320.3
