Workbook

Sheet Assumptions
A1: Kelvin Dynamics - Series F Analysis
A3: Model knobs
A4: Key | B4: Label | C4: Value | D4: Units | E4: Source / Notes
A5: series_f_pre_money_usd | B5: Series F pre-money | C5: 1400000000 | D5: USD | E5: Series F pre-money valuation
A6: series_f_primary_raise_usd | B6: Series F primary raise | C6: 30000000 | D6: USD | E6: New Series F primary capital
A7: series_f_secondary_raise_usd | B7: Series F secondary tender raise | C7: 15000000 | D7: USD | E7: Secondary tender from founders
A8: series_f_tender_pps_multiplier | B8: Tender PPS multiplier | C8: 0.85 | D8: fraction | E8: Tender PPS = multiplier x F_PPS
A9: esop_refresh_target_post_f | B9: ESOP refresh target % of post-F FD | C9: 0.13 | D9: fraction | E9: Post-F option pool as fraction of post-F FD
A10: our_fund_check_usd | B10: Our fund check size | C10: 10000000 | D10: USD | E10: Our fund's Series F primary check (= 1/3 of primary)
A11: f_lead_primary_check_usd | B11: F_LEAD primary check size | C11: 20000000 | D11: USD | E11: F_LEAD's Series F primary check (= 2/3 of primary)
A12: option_strike_usd | B12: Issued option strike | C12: 1 | D12: USD | E12: Option exercise price for issued options at exit
A13: pre_f_options_issued | B13: Pre-F issued options | C13: 2500000 | D13: shares | E13: Issued options outstanding pre-F (carryover from v3 post-E)
A14: pre_f_options_unissued | B14: Pre-F unissued option pool | C14: 1894667 | D14: shares | E14: Unissued option pool pre-F (carryover from v3 post-E refresh)
A15: pre_f_fd_total | B15: Pre-F broad-based FD total | C15: 36617961 | D15: shares | E15: Pre-F fully-diluted share count (post-E T from v3)
A16: pre_f_option_pool_total | B16: Pre-F total option pool | C16: =Assumptions!$C$13+Assumptions!$C$14 -> 4394667 | D16: shares | E16: Issued + unissued pre-F option pool
A17: const_one | B17: Formula constant: one | C17: 1 | D17: number | E17: Used by downstream formulas
A18: const_zero | B18: Formula constant: zero | C18: 0 | D18: number | E18: Used by downstream formulas
A19: usd_in_millions | B19: USD display divisor | C19: 1000000 | D19: USD | E19: Used by downstream display formulas
A20: exit_value_1_usd | B20: Exit value 1 | C20: 700000000 | D20: USD | E20: Exit scenario 1
A21: exit_value_2_usd | B21: Exit value 2 | C21: 1200000000 | D21: USD | E21: Exit scenario 2
A22: exit_value_3_usd | B22: Exit value 3 | C22: 2000000000 | D22: USD | E22: Exit scenario 3 (sensitivity reference)
A23: exit_value_4_usd | B23: Exit value 4 | C23: 4000000000 | D23: USD | E23: Exit scenario 4
A24: exit_value_5_usd | B24: Exit value 5 | C24: 8000000000 | D24: USD | E24: Exit scenario 5
A25: sensitivity_esop_low | B25: Sensitivity ESOP low | C25: 0.11 | D25: fraction | E25: Sensitivity grid axis: low ESOP refresh
A26: sensitivity_esop_base | B26: Sensitivity ESOP base | C26: 0.13 | D26: fraction | E26: Sensitivity grid axis: base ESOP refresh
A27: sensitivity_esop_high | B27: Sensitivity ESOP high | C27: 0.15 | D27: fraction | E27: Sensitivity grid axis: high ESOP refresh
A28: sensitivity_pre_low_usd | B28: Sensitivity pre-money low | C28: 1200000000 | D28: USD | E28: Sensitivity grid axis: low Series F pre-money
... A46: note_b_interest_usd | B46: Note B accrued interest | C46: 0 | D46: USD | E46: Notes!Interest
A47: ad_pre_f_broad_based_fd | B47: Broad-based WA A: pre-F FD | C47: =pre_f_fd_total -> 36617961 | D47: shares | E47: RoundTerms!pre_f_fd_total
A48: ad_primary_raise_usd | B48: Broad-based WA new-money numerator | C48: =series_f_primary_raise_usd -> 30000000 | D48: USD | E48: Notes excluded from B and C
A49: sensitivity_exit_usd | B49: Sensitivity waterfall exit | C49: =exit_value_3_usd -> 2000000000 | D49: USD | E49: Exit value used in Sensitivity
A52: Raw Stakeholders
A53: ID | B53: Role | C53: Common shares | D53: Preferred class | E53: Preferred shares
A54: F1 | B54: Founder (CEO) | C54: 4000000 | E54: 0
A55: F2 | B55: Founder (CTO) | C55: 2500000 | E55: 0
A56: F3 | B56: Founder (Chief Scientist) | C56: 1500000 | E56: 0
A57: E1 | B57: Employee RSA | C57: 100000 | E57: 0
A58: E2 | B58: Employee RSA | C58: 100000 | E58: 0
A59: E3 | B59: Employee RSA | C59: 100000 | E59: 0
A60: E4 | B60: Employee RSA | C60: 100000 | E60: 0
...

Sheet Pro-Forma
A1: =lbl_pro_forma -> Pro-Forma
A3: =lbl_fixed_point -> Fixed Point
A4: =lbl_f_pps -> Series F PPS | B4: ='Pro-Forma'!$V$63 -> 37.628498 | R4: =const_zero -> 0 | S4: =const_zero -> 0 | T4: =const_zero -> 0 | U4: =const_zero -> 0 | V4: =series_f_pre_money_usd/(pre_f_fd_total+'Pro-Forma'!S4) -> 38.232604 | W4: =series_f_primary_raise_usd/'Pro-Forma'!V4 -> 784670.59 | X4: =IF('Pro-Forma'!V4<class_seed_ocp,class_seed_ocp*(ad_pre_f_broad_based_fd+series_f_primary_raise_usd/class_seed_ocp)/(ad_pre_f_broad_based_fd+series_f_primary_raise_usd/'Pro-Forma'!V4),class_seed_ocp) -> 1 | Y4: =class_seed_original_shares*class_seed_issue_pps/'Pro-Forma'!X4 -> 5000000 | Z4: =IF('Pro-Forma'!V4<class_series_a_ocp,class_series_a_ocp*(ad_pre_f_broad_based_fd+series_f_primary_raise_usd/class_series_a_ocp)/(ad_pre_f_broad_based_fd+series_f_primary_raise_usd/'Pro-Forma'!V4),class_series_a_ocp) -> 3 | AA4: =class_series_a_original_shares*class_series_a_issue_pps/'Pro-Forma'!Z4 -> 5000000 | AB4: =IF('Pro-Forma'!V4<class_series_b_ocp,class_series_b_ocp*(ad_pre_f_broad_based_fd+series_f_primary_raise_usd/class_series_b_ocp)/(ad_pre_f_broad_based_fd+series_f_primary_raise_usd/'Pro-Forma'!V4),class_series_b_ocp) -> 10 | AC4: =class_series_b_original_shares*class_series_b_issue_pps/'Pro-Forma'!AB4 -> 3000000 | AD4: =IF('Pro-Forma'!V4<class_series_c_ocp,class_series_c_ocp*(ad_pre_f_broad_based_fd+series_f_primary_raise_usd/class_series_c_ocp)/(ad_pre_f_broad_based_fd+series_f_primary_raise_usd/'Pro-Forma'!V4),class_series_c_ocp) -> 25 | AE4: =class_series_c_original_shares*class_series_c_issue_pps/'Pro-Forma'!AD4 -> 2400000 | AF4: =IF('Pro-Forma'!V4<class_series_d_ocp,class_series_d_ocp*(ad_pre_f_broad_based_fd+series_f_primary_raise_usd/class_series_d_ocp)/(ad_pre_f_broad_based_fd+series_f_primary_raise_usd/'Pro-Forma'!V4),class_series_d_ocp) -> 57.701164 | AG4: =class_series_d_original_shares*class_series_d_issue_pps/'Pro-Forma'!AF4 -> 1733067.7 | AH4: =IF('Pro-Forma'!V4<class_series_e_ocp,class_series_e_ocp*(ad_pre_f_broad_based_fd+series_f_primary_raise_usd/class_series_e_ocp)/(ad_pre_f_broad_based_fd+series_f_primary_raise_usd/'Pro-Forma'!V4),class_series_e_ocp) -> 48.9291 | AI4: =class_series_e_original_shares*class_series_e_issue_pps/'Pro-Forma'!AH4 -> 6131255.2 | AJ4: ='Pro-Forma'!Y4-class_seed_current_shares+'Pro-Forma'!AA4-class_series_a_current_shares+'Pro-Forma'!AC4-class_series_b_current_shares+'Pro-Forma'!AE4-class_series_c_current_shares+'Pro-Forma'!AG4-class_series_d_current_shares+'Pro-Forma'!AI4-class_series_e_current_shares -> 41028.877 | AK4: =note_a_cap_usd/(pre_f_fd_total+'Pro-Forma'!S4+'Pro-Forma'!AJ4+'Pro-Forma'!U4) -> 27.278438 | AL4: ='Pro-Forma'!V4*(const_one-note_a_discount) -> 30.586083 | AM4: =MIN('Pro-Forma'!AK4,'Pro-Forma'!AL4) -> 27.278438 | AN4: =note_a_principal_usd/'Pro-Forma'!AM4 -> 183294.95 | AO4: =note_b_cap_usd/(pre_f_fd_total+'Pro-Forma'!S4+'Pro-Forma'!AJ4+'Pro-Forma'!T4) -> 43.645502 | AP4: ='Pro-Forma'!V4*(const_one-note_b_discount) -> 32.497713 | AQ4: =MIN('Pro-Forma'!AO4,'Pro-Forma'!AP4) -> 32.497713 | AR4: =note_b_principal_usd/'Pro-Forma'!AQ4 -> 92314.187 | AS4: =pre_f_fd_total+'Pro-Forma'!S4+'Pro-Forma'!W4+'Pro-Forma'!AN4+'Pro-Forma'!AR4+'Pro-Forma'!AJ4 -> 37719270 | AT4: =MAX(const_zero,esop_refresh_target_post_f*'Pro-Forma'!AS4-pre_f_option_pool_total) -> 508838.05
A5: =lbl_primary_shares -> Series F primary shares | B5: =series_f_primary_raise_usd/B4 -> 797268.07 | R5: ='Pro-Forma'!R4+const_one -> 1 | S5: ='Pro-Forma'!AT4 -> 508838.05 | T5: ='Pro-Forma'!AN4 -> 183294.95 | U5: ='Pro-Forma'!AR4 -> 92314.187 | V5: =series_f_pre_money_usd/(pre_f_fd_total+'Pro-Forma'!S5) -> 37.70861 | W5: =series_f_primary_raise_usd/'Pro-Forma'!V5 -> 795574.27 | X5: =IF('Pro-Forma'!V5<class_seed_ocp,class_seed_ocp*(ad_pre_f_broad_based_fd+series_f_primary_raise_usd/class_seed_ocp)/(ad_pre_f_broad_based_fd+series_f_primary_raise_usd/'Pro-Forma'!V5),class_seed_ocp) -> 1 | Y5: =class_seed_original_shares*class_seed_issue_pps/'Pro-Forma'!X5 -> 5000000 | Z5: =IF('Pro-Forma'!V5<class_series_a_ocp,class_series_a_ocp*(ad_pre_f_broad_based_fd+series_f_primary_raise_usd/class_series_a_ocp)/(ad_pre_f_broad_based_fd+series_f_primary_raise_usd/'Pro-Forma'!V5),class_series_a_ocp) -> 3 | AA5: =class_series_a_original_shares*class_series_a_issue_pps/'Pro-Forma'!Z5 -> 5000000 | AB5: =IF('Pro-Forma'!V5<class_series_b_ocp,class_series_b_ocp*(ad_pre_f_broad_based_fd+series_f_primary_raise_usd/class_series_b_ocp)/(ad_pre_f_broad_based_fd+series_f_primary_raise_usd/'Pro-Forma'!V5),class_series_b_ocp) -> 10 | AC5: =class_series_b_original_shares*class_series_b_issue_pps/'Pro-Forma'!AB5 -> 3000000 | AD5: =IF('Pro-Forma'!V5<class_series_c_ocp,class_series_c_ocp*(ad_pre_f_broad_based_fd+series_f_primary_raise_usd/class_series_c_ocp)/(ad_pre_f_broad_based_fd+series_f_primary_raise_usd/'Pro-Forma'!V5),class_series_c_ocp) -> 25 | AE5: =class_series_c_original_shares*class_series_c_issue_pps/'Pro-Forma'!AD5 -> 2400000 | AF5: =IF('Pro-Forma'!V5<class_series_d_ocp,class_series_d_ocp*(ad_pre_f_broad_based_fd+series_f_primary_raise_usd/class_series_d_ocp)/(ad_pre_f_broad_based_fd+series_f_primary_raise_usd/'Pro-Forma'!V5),class_series_d_ocp) -> 57.684347 | AG5: =class_series_d_original_shares*class_series_d_issue_pps/'Pro-Forma'!AF5 -> 1733572.9 | AH5: =IF('Pro-Forma'!V5<class_series_e_ocp,class_series_e_ocp*(ad_pre_f_broad_based_fd+series_f_primary_raise_usd/class_series_e_ocp)/(ad_pre_f_broad_based_fd+series_f_primary_raise_usd/'Pro-Forma'!V5),class_series_e_ocp) -> 48.914841 | AI5: =class_series_e_original_shares*class_series_e_issue_pps/'Pro-Forma'!AH5 -> 6133042.6 | AJ5: ='Pro-Forma'!Y5-class_seed_current_shares+'Pro-Forma'!AA5-class_series_a_current_shares+'Pro-Forma'!AC5-class_series_b_current_shares+'Pro-Forma'!AE5-class_series_c_current_shares+'Pro-Forma'!AG5-class_series_d_current_shares+'Pro-Forma'!AI5-class_series_e_current_shares -> 43321.496 | AK5: =note_a_cap_usd/(pre_f_fd_total+'Pro-Forma'!S5+'Pro-Forma'!AJ5+'Pro-Forma'!U5) -> 26.836679 | AL5: ='Pro-Forma'!V5*(const_one-note_a_discount) -> 30.166888 | AM5: =MIN('Pro-Forma'!AK5,'Pro-Forma'!AL5) -> 26.836679 | AN5: =note_a_principal_usd/'Pro-Forma'!AM5 -> 186312.17 | AO5: =note_b_cap_usd/(pre_f_fd_total+'Pro-Forma'!S5+'Pro-Forma'!AJ5+'Pro-Forma'!T5) -> 42.834102 | AP5: ='Pro-Forma'!V5*(const_one-note_b_discount) -> 32.052319 | AQ5: =MIN('Pro-Forma'!AO5,'Pro-Forma'!AP5) -> 32.052319 | AR5: =note_b_principal_usd/'Pro-Forma'!AQ5 -> 93596.972 | AS5: =pre_f_fd_total+'Pro-Forma'!S5+'Pro-Forma'!W5+'Pro-Forma'!AN5+'Pro-Forma'!AR5+'Pro-Forma'!AJ5 -> 38245604 | AT5: =MAX(const_zero,esop_refresh_target_post_f*'Pro-Forma'!AS5-pre_f_option_pool_total) -> 577261.51
A6: =lbl_our_primary_shares -> Our Series F primary shares | B6: =our_fund_check_usd/B4 -> 265756.02 | R6: ='Pro-Forma'!R5+const_one -> 2 | S6: ='Pro-Forma'!AT5 -> 577261.51 | T6: ='Pro-Forma'!AN5 -> 186312.17 | U6: ='Pro-Forma'!AR5 -> 93596.972 | V6: =series_f_pre_money_usd/(pre_f_fd_total+'Pro-Forma'!S6) -> 37.639242 | W6: =series_f_primary_raise_usd/'Pro-Forma'!V6 -> 797040.48 | X6: =IF('Pro-Forma'!V6<class_seed_ocp,class_seed_ocp*(ad_pre_f_broad_based_fd+series_f_primary_raise_usd/class_seed_ocp)/(ad_pre_f_broad_based_fd+series_f_primary_raise_usd/'Pro-Forma'!V6),class_seed_ocp) -> 1 | Y6: =class_seed_original_shares*class_seed_issue_pps/'Pro-Forma'!X6 -> 5000000 | Z6: =IF('Pro-Forma'!V6<class_series_a_ocp,class_series_a_ocp*(ad_pre_f_broad_based_fd+series_f_primary_raise_usd/class_series_a_ocp)/(ad_pre_f_broad_based_fd+series_f_primary_raise_usd/'Pro-Forma'!V6),class_series_a_ocp) -> 3 | AA6: =class_series_a_original_shares*class_series_a_issue_pps/'Pro-Forma'!Z6 -> 5000000 | AB6: =IF('Pro-Forma'!V6<class_series_b_ocp,class_series_b_ocp*(ad_pre_f_broad_based_fd+series_f_primary_raise_usd/class_series_b_ocp)/(ad_pre_f_broad_based_fd+series_f_primary_raise_usd/'Pro-Forma'!V6),class_series_b_ocp) -> 10 | AC6: =class_series_b_original_shares*class_series_b_issue_pps/'Pro-Forma'!AB6 -> 3000000 | AD6: =IF('Pro-Forma'!V6<class_series_c_ocp,class_series_c_ocp*(ad_pre_f_broad_based_fd+series_f_primary_raise_usd/class_series_c_ocp)/(ad_pre_f_broad_based_fd+series_f_primary_raise_usd/'Pro-Forma'!V6),class_series_c_ocp) -> 25 | AE6: =class_series_c_original_shares*class_series_c_issue_pps/'Pro-Forma'!AD6 -> 2400000 | AF6: =IF('Pro-Forma'!V6<class_series_d_ocp,class_series_d_ocp*(ad_pre_f_broad_based_fd+series_f_primary_raise_usd/class_series_d_ocp)/(ad_pre_f_broad_based_fd+series_f_primary_raise_usd/'Pro-Forma'!V6),class_series_d_ocp) -> 57.682087 | AG6: =class_series_d_original_shares*class_series_d_issue_pps/'Pro-Forma'!AF6 -> 1733640.8 | AH6: =IF('Pro-Forma'!V6<class_series_e_ocp,class_series_e_ocp*(ad_pre_f_broad_based_fd+series_f_primary_raise_usd/class_series_e_ocp)/(ad_pre_f_broad_based_fd+series_f_primary_raise_usd/'Pro-Forma'!V6),class_series_e_ocp) -> 48.912924 | AI6: =class_series_e_original_shares*class_series_e_issue_pps/'Pro-Forma'!AH6 -> 6133283 | AJ6: ='Pro-Forma'!Y6-class_seed_current_shares+'Pro-Forma'!AA6-class_series_a_current_shares+'Pro-Forma'!AC6-class_series_b_current_shares+'Pro-Forma'!AE6-class_series_c_current_shares+'Pro-Forma'!AG6-class_series_d_current_shares+'Pro-Forma'!AI6-class_series_e_current_shares -> 43629.785 | AK6: =note_a_cap_usd/(pre_f_fd_total+'Pro-Forma'!S6+'Pro-Forma'!AJ6+'Pro-Forma'!U6) -> 26.786349 | AL6: ='Pro-Forma'!V6*(const_one-note_a_discount) -> 30.111394 | AM6: =MIN('Pro-Forma'!AK6,'Pro-Forma'!AL6) -> 26.786349 | AN6: =note_a_principal_usd/'Pro-Forma'!AM6 -> 186662.25 | AO6: =note_b_cap_usd/(pre_f_fd_total+'Pro-Forma'!S6+'Pro-Forma'!AJ6+'Pro-Forma'!T6) -> 42.751983 | AP6: ='Pro-Forma'!V6*(const_one-note_b_discount) -> 31.993356 | AQ6: =MIN('Pro-Forma'!AO6,'Pro-Forma'!AP6) -> 31.993356 | AR6: =note_b_principal_usd/'Pro-Forma'!AQ6 -> 93769.469 | AS6: =pre_f_fd_total+'Pro-Forma'!S6+'Pro-Forma'!W6+'Pro-Forma'!AN6+'Pro-Forma'!AR6+'Pro-Forma'!AJ6 -> 38316324 | AT6: =MAX(const_zero,esop_refresh_target_post_f*'Pro-Forma'!AS6-pre_f_option_pool_total) -> 586455.18
A7: =lbl_f_lead_primary_shares -> F_LEAD Series F primary shares | B7: =f_lead_primary_check_usd/B4 -> 531512.05 | R7: ='Pro-Forma'!R6+const_one -> 3 | S7: ='Pro-Forma'!AT6 -> 586455.18 | T7: ='Pro-Forma'!AN6 -> 186662.25 | U7: ='Pro-Forma'!AR6 -> 93769.469 | V7: =series_f_pre_money_usd/(pre_f_fd_total+'Pro-Forma'!S7) -> 37.629941 | W7: =series_f_primary_raise_usd/'Pro-Forma'!V7 -> 797237.49 | X7: =IF('Pro-Forma'!V7<class_seed_ocp,class_seed_ocp*(ad_pre_f_broad_based_fd+series_f_primary_raise_usd/class_seed_ocp)/(ad_pre_f_broad_based_fd+series_f_primary_raise_usd/'Pro-Forma'!V7),class_seed_ocp) -> 1 | Y7: =class_seed_original_shares*class_seed_issue_pps/'Pro-Forma'!X7 -> 5000000 | Z7: =IF('Pro-Forma'!V7<class_series_a_ocp,class_series_a_ocp*(ad_pre_f_broad_based_fd+series_f_primary_raise_usd/class_series_a_ocp)/(ad_pre_f_broad_based_fd+series_f_primary_raise_usd/'Pro-Forma'!V7),class_series_a_ocp) -> 3 | AA7: =class_series_a_original_shares*class_series_a_issue_pps/'Pro-Forma'!Z7 -> 5000000 | AB7: =IF('Pro-Forma'!V7<class_series_b_ocp,class_series_b_ocp*(ad_pre_f_broad_based_fd+series_f_primary_raise_usd/class_series_b_ocp)/(ad_pre_f_broad_based_fd+series_f_primary_raise_usd/'Pro-Forma'!V7),class_series_b_ocp) -> 10 | AC7: =class_series_b_original_shares*class_series_b_issue_pps/'Pro-Forma'!AB7 -> 3000000 | AD7: =IF('Pro-Forma'!V7<class_series_c_ocp,class_series_c_ocp*(ad_pre_f_broad_based_fd+series_f_primary_raise_usd/class_series_c_ocp)/(ad_pre_f_broad_based_fd+series_f_primary_raise_usd/'Pro-Forma'!V7),class_series_c_ocp) -> 25 | AE7: =class_series_c_original_shares*class_series_c_issue_pps/'Pro-Forma'!AD7 -> 2400000 | AF7: =IF('Pro-Forma'!V7<class_series_d_ocp,class_series_d_ocp*(ad_pre_f_broad_based_fd+series_f_primary_raise_usd/class_series_d_ocp)/(ad_pre_f_broad_based_fd+series_f_primary_raise_usd/'Pro-Forma'!V7),class_series_d_ocp) -> 57.681783 | AG7: =class_series_d_original_shares*class_series_d_issue_pps/'Pro-Forma'!AF7 -> 1733649.9 | AH7: =IF('Pro-Forma'!V7<class_series_e_ocp,class_series_e_ocp*(ad_pre_f_broad_based_fd+series_f_primary_raise_usd/class_series_e_ocp)/(ad_pre_f_broad_based_fd+series_f_primary_raise_usd/'Pro-Forma'!V7),class_series_e_ocp) -> 48.912666 | AI7: =class_series_e_original_shares*class_series_e_issue_pps/'Pro-Forma'!AH7 -> 6133315.3 | AJ7: ='Pro-Forma'!Y7-class_seed_current_shares+'Pro-Forma'!AA7-class_series_a_current_shares+'Pro-Forma'!AC7-class_series_b_current_shares+'Pro-Forma'!AE7-class_series_c_current_shares+'Pro-Forma'!AG7-class_series_d_current_shares+'Pro-Forma'!AI7-class_series_e_current_shares -> 43671.208 | AK7: =note_a_cap_usd/(pre_f_fd_total+'Pro-Forma'!S7+'Pro-Forma'!AJ7+'Pro-Forma'!U7) -> 26.7796 | AL7: ='Pro-Forma'!V7*(const_one-note_a_discount) -> 30.103953 | AM7: =MIN('Pro-Forma'!AK7,'Pro-Forma'!AL7) -> 26.7796 | AN7: =note_a_principal_usd/'Pro-Forma'!AM7 -> 186709.28 | AO7: =note_b_cap_usd/(pre_f_fd_total+'Pro-Forma'!S7+'Pro-Forma'!AJ7+'Pro-Forma'!T7) -> 42.741036 | AP7: ='Pro-Forma'!V7*(const_one-note_b_discount) -> 31.98545 | AQ7: =MIN('Pro-Forma'!AO7,'Pro-Forma'!AP7) -> 31.98545 | AR7: =note_b_principal_usd/'Pro-Forma'!AQ7 -> 93792.646 | AS7: =pre_f_fd_total+'Pro-Forma'!S7+'Pro-Forma'!W7+'Pro-Forma'!AN7+'Pro-Forma'!AR7+'Pro-Forma'!AJ7 -> 38325827 | AT7: =MAX(const_zero,esop_refresh_target_post_f*'Pro-Forma'!AS7-pre_f_option_pool_total) -> 587690.49
A8: =lbl_esop_topup -> ESOP top-up | B8: ='Pro-Forma'!$AT$63 -> 587882.23 | R8: ='Pro-Forma'!R7+const_one -> 4 | S8: ='Pro-Forma'!AT7 -> 587690.49 | T8: ='Pro-Forma'!AN7 -> 186709.28 | U8: ='Pro-Forma'!AR7 -> 93792.646 | V8: =series_f_pre_money_usd/(pre_f_fd_total+'Pro-Forma'!S8) -> 37.628692 | W8: =series_f_primary_raise_usd/'Pro-Forma'!V8 -> 797263.96 | X8: =IF('Pro-Forma'!V8<class_seed_ocp,class_seed_ocp*(ad_pre_f_broad_based_fd+series_f_primary_raise_usd/class_seed_ocp)/(ad_pre_f_broad_based_fd+series_f_primary_raise_usd/'Pro-Forma'!V8),class_seed_ocp) -> 1 | Y8: =class_seed_original_shares*class_seed_issue_pps/'Pro-Forma'!X8 -> 5000000 | Z8: =IF('Pro-Forma'!V8<class_series_a_ocp,class_series_a_ocp*(ad_pre_f_broad_based_fd+series_f_primary_raise_usd/class_series_a_ocp)/(ad_pre_f_broad_based_fd+series_f_primary_raise_usd/'Pro-Forma'!V8),class_series_a_ocp) -> 3 | AA8: =class_series_a_original_shares*class_series_a_issue_pps/'Pro-Forma'!Z8 -> 5000000 | AB8: =IF('Pro-Forma'!V8<class_series_b_ocp,class_series_b_ocp*(ad_pre_f_broad_based_fd+series_f_primary_raise_usd/class_series_b_ocp)/(ad_pre_f_broad_based_fd+series_f_primary_raise_usd/'Pro-Forma'!V8),class_series_b_ocp) -> 10 | AC8: =class_series_b_original_shares*class_series_b_issue_pps/'Pro-Forma'!AB8 -> 3000000 | AD8: =IF('Pro-Forma'!V8<class_series_c_ocp,class_series_c_ocp*(ad_pre_f_broad_based_fd+series_f_primary_raise_usd/class_series_c_ocp)/(ad_pre_f_broad_based_fd+series_f_primary_raise_usd/'Pro-Forma'!V8),class_series_c_ocp) -> 25 | AE8: =class_series_c_original_shares*class_series_c_issue_pps/'Pro-Forma'!AD8 -> 2400000 | AF8: =IF('Pro-Forma'!V8<class_series_d_ocp,class_series_d_ocp*(ad_pre_f_broad_based_fd+series_f_primary_raise_usd/class_series_d_ocp)/(ad_pre_f_broad_based_fd+series_f_primary_raise_usd/'Pro-Forma'!V8),class_series_d_ocp) -> 57.681742 | AG8: =class_series_d_original_shares*class_series_d_issue_pps/'Pro-Forma'!AF8 -> 1733651.2 | AH8: =IF('Pro-Forma'!V8<class_series_e_ocp,class_series_e_ocp*(ad_pre_f_broad_based_fd+series_f_primary_raise_usd/class_series_e_ocp)/(ad_pre_f_broad_based_fd+series_f_primary_raise_usd/'Pro-Forma'!V8),class_series_e_ocp) -> 48.912632 | AI8: =class_series_e_original_shares*class_series_e_issue_pps/'Pro-Forma'!AH8 -> 6133319.6 | AJ8: ='Pro-Forma'!Y8-class_seed_current_shares+'Pro-Forma'!AA8-class_series_a_current_shares+'Pro-Forma'!AC8-class_series_b_current_shares+'Pro-Forma'!AE8-class_series_c_current_shares+'Pro-Forma'!AG8-class_series_d_current_shares+'Pro-Forma'!AI8-class_series_e_current_shares -> 43676.774 | AK8: =note_a_cap_usd/(pre_f_fd_total+'Pro-Forma'!S8+'Pro-Forma'!AJ8+'Pro-Forma'!U8) -> 26.778694 | AL8: ='Pro-Forma'!V8*(const_one-note_a_discount) -> 30.102954 | AM8: =MIN('Pro-Forma'!AK8,'Pro-Forma'!AL8) -> 26.778694 | AN8: =note_a_principal_usd/'Pro-Forma'!AM8 -> 186715.6 | AO8: =note_b_cap_usd/(pre_f_fd_total+'Pro-Forma'!S8+'Pro-Forma'!AJ8+'Pro-Forma'!T8) -> 42.739566 | AP8: ='Pro-Forma'!V8*(const_one-note_b_discount) -> 31.984388 | AQ8: =MIN('Pro-Forma'!AO8,'Pro-Forma'!AP8) -> 31.984388 | AR8: =note_b_principal_usd/'Pro-Forma'!AQ8 -> 93795.76 | AS8: =pre_f_fd_total+'Pro-Forma'!S8+'Pro-Forma'!W8+'Pro-Forma'!AN8+'Pro-Forma'!AR8+'Pro-Forma'!AJ8 -> 38327104 | AT8: =MAX(const_zero,esop_refresh_target_post_f*'Pro-Forma'!AS8-pre_f_option_pool_total) -> 587856.47
A9: =lbl_ad_increment -> AD incremental shares | B9: =SUM(G22:G27) -> 43677.638 | R9: ='Pro-Forma'!R8+const_one -> 5 | S9: ='Pro-Forma'!AT8 -> 587856.47 | T9: ='Pro-Forma'!AN8 -> 186715.6 | U9: ='Pro-Forma'!AR8 -> 93795.76 | V9: =series_f_pre_money_usd/(pre_f_fd_total+'Pro-Forma'!S9) -> 37.628524 | W9: =series_f_primary_raise_usd/'Pro-Forma'!V9 -> 797267.52 | X9: =IF('Pro-Forma'!V9<class_seed_ocp,class_seed_ocp*(ad_pre_f_broad_based_fd+series_f_primary_raise_usd/class_seed_ocp)/(ad_pre_f_broad_based_fd+series_f_primary_raise_usd/'Pro-Forma'!V9),class_seed_ocp) -> 1 | Y9: =class_seed_original_shares*class_seed_issue_pps/'Pro-Forma'!X9 -> 5000000 | Z9: =IF('Pro-Forma'!V9<class_series_a_ocp,class_series_a_ocp*(ad_pre_f_broad_based_fd+series_f_primary_raise_usd/class_series_a_ocp)/(ad_pre_f_broad_based_fd+series_f_primary_raise_usd/'Pro-Forma'!V9),class_series_a_ocp) -> 3 | AA9: =class_series_a_original_shares*class_series_a_issue_pps/'Pro-Forma'!Z9 -> 5000000 | AB9: =IF('Pro-Forma'!V9<class_series_b_ocp,class_series_b_ocp*(ad_pre_f_broad_based_fd+series_f_primary_raise_usd/class_series_b_ocp)/(ad_pre_f_broad_based_fd+series_f_primary_raise_usd/'Pro-Forma'!V9),class_series_b_ocp) -> 10 | AC9: =class_series_b_original_shares*class_series_b_issue_pps/'Pro-Forma'!AB9 -> 3000000 | AD9: =IF('Pro-Forma'!V9<class_series_c_ocp,class_series_c_ocp*(ad_pre_f_broad_based_fd+series_f_primary_raise_usd/class_series_c_ocp)/(ad_pre_f_broad_based_fd+series_f_primary_raise_usd/'Pro-Forma'!V9),class_series_c_ocp) -> 25 | AE9: =class_series_c_original_shares*class_series_c_issue_pps/'Pro-Forma'!AD9 -> 2400000 | AF9: =IF('Pro-Forma'!V9<class_series_d_ocp,class_series_d_ocp*(ad_pre_f_broad_based_fd+series_f_primary_raise_usd/class_series_d_ocp)/(ad_pre_f_broad_based_fd+series_f_primary_raise_usd/'Pro-Forma'!V9),class_series_d_ocp) -> 57.681737 | AG9: =class_series_d_original_shares*class_series_d_issue_pps/'Pro-Forma'!AF9 -> 1733651.3 | AH9: =IF('Pro-Forma'!V9<class_series_e_ocp,class_series_e_ocp*(ad_pre_f_broad_based_fd+series_f_primary_raise_usd/class_series_e_ocp)/(ad_pre_f_broad_based_fd+series_f_primary_raise_usd/'Pro-Forma'!V9),class_series_e_ocp) -> 48.912627 | AI9: =class_series_e_original_shares*class_series_e_issue_pps/'Pro-Forma'!AH9 -> 6133320.2 | AJ9: ='Pro-Forma'!Y9-class_seed_current_shares+'Pro-Forma'!AA9-class_series_a_current_shares+'Pro-Forma'!AC9-class_series_b_current_shares+'Pro-Forma'!AE9-class_series_c_current_shares+'Pro-Forma'!AG9-class_series_d_current_shares+'Pro-Forma'!AI9-class_series_e_current_shares -> 43677.522 | AK9: =note_a_cap_usd/(pre_f_fd_total+'Pro-Forma'!S9+'Pro-Forma'!AJ9+'Pro-Forma'!U9) -> 26.778572 | AL9: ='Pro-Forma'!V9*(const_one-note_a_discount) -> 30.102819 | AM9: =MIN('Pro-Forma'!AK9,'Pro-Forma'!AL9) -> 26.778572 | AN9: =note_a_principal_usd/'Pro-Forma'!AM9 -> 186716.45 | AO9: =note_b_cap_usd/(pre_f_fd_total+'Pro-Forma'!S9+'Pro-Forma'!AJ9+'Pro-Forma'!T9) -> 42.739369 | AP9: ='Pro-Forma'!V9*(const_one-note_b_discount) -> 31.984246 | AQ9: =MIN('Pro-Forma'!AO9,'Pro-Forma'!AP9) -> 31.984246 | AR9: =note_b_principal_usd/'Pro-Forma'!AQ9 -> 93796.178 | AS9: =pre_f_fd_total+'Pro-Forma'!S9+'Pro-Forma'!W9+'Pro-Forma'!AN9+'Pro-Forma'!AR9+'Pro-Forma'!AJ9 -> 38327275 | AT9: =MAX(const_zero,esop_refresh_target_post_f*'Pro-Forma'!AS9-pre_f_option_pool_total) -> 587878.77
A10: =lbl_note_a_shares -> Note A shares | B10: =I31 -> 186716.59 | R10: ='Pro-Forma'!R9+const_one -> 6 | S10: ='Pro-Forma'!AT9 -> 587878.77 | T10: ='Pro-Forma'!AN9 -> 186716.45 | U10: ='Pro-Forma'!AR9 -> 93796.178 | V10: =series_f_pre_money_usd/(pre_f_fd_total+'Pro-Forma'!S10) -> 37.628502 | W10: =series_f_primary_raise_usd/'Pro-Forma'!V10 -> 797268 | X10: =IF('Pro-Forma'!V10<class_seed_ocp,class_seed_ocp*(ad_pre_f_broad_based_fd+series_f_primary_raise_usd/class_seed_ocp)/(ad_pre_f_broad_based_fd+series_f_primary_raise_usd/'Pro-Forma'!V10),class_seed_ocp) -> 1 | Y10: =class_seed_original_shares*class_seed_issue_pps/'Pro-Forma'!X10 -> 5000000 | Z10: =IF('Pro-Forma'!V10<class_series_a_ocp,class_series_a_ocp*(ad_pre_f_broad_based_fd+series_f_primary_raise_usd/class_series_a_ocp)/(ad_pre_f_broad_based_fd+series_f_primary_raise_usd/'Pro-Forma'!V10),class_series_a_ocp) -> 3 | AA10: =class_series_a_original_shares*class_series_a_issue_pps/'Pro-Forma'!Z10 -> 5000000 | AB10: =IF('Pro-Forma'!V10<class_series_b_ocp,class_series_b_ocp*(ad_pre_f_broad_based_fd+series_f_primary_raise_usd/class_series_b_ocp)/(ad_pre_f_broad_based_fd+series_f_primary_raise_usd/'Pro-Forma'!V10),class_series_b_ocp) -> 10 | AC10: =class_series_b_original_shares*class_series_b_issue_pps/'Pro-Forma'!AB10 -> 3000000 | AD10: =IF('Pro-Forma'!V10<class_series_c_ocp,class_series_c_ocp*(ad_pre_f_broad_based_fd+series_f_primary_raise_usd/class_series_c_ocp)/(ad_pre_f_broad_based_fd+series_f_primary_raise_usd/'Pro-Forma'!V10),class_series_c_ocp) -> 25 | AE10: =class_series_c_original_shares*class_series_c_issue_pps/'Pro-Forma'!AD10 -> 2400000 | AF10: =IF('Pro-Forma'!V10<class_series_d_ocp,class_series_d_ocp*(ad_pre_f_broad_based_fd+series_f_primary_raise_usd/class_series_d_ocp)/(ad_pre_f_broad_based_fd+series_f_primary_raise_usd/'Pro-Forma'!V10),class_series_d_ocp) -> 57.681736 | AG10: =class_series_d_original_shares*class_series_d_issue_pps/'Pro-Forma'!AF10 -> 1733651.4 | AH10: =IF('Pro-Forma'!V10<class_series_e_ocp,class_series_e_ocp*(ad_pre_f_broad_based_fd+series_f_primary_raise_usd/class_series_e_ocp)/(ad_pre_f_broad_based_fd+series_f_primary_raise_usd/'Pro-Forma'!V10),class_series_e_ocp) -> 48.912626 | AI10: =class_series_e_original_shares*class_series_e_issue_pps/'Pro-Forma'!AH10 -> 6133320.3 | AJ10: ='Pro-Forma'!Y10-class_seed_current_shares+'Pro-Forma'!AA10-class_series_a_current_shares+'Pro-Forma'!AC10-class_series_b_current_shares+'Pro-Forma'!AE10-class_series_c_current_shares+'Pro-Forma'!AG10-class_series_d_current_shares+'Pro-Forma'!AI10-class_series_e_current_shares -> 43677.622 | AK10: =note_a_cap_usd/(pre_f_fd_total+'Pro-Forma'!S10+'Pro-Forma'!AJ10+'Pro-Forma'!U10) -> 26.778556 | AL10: ='Pro-Forma'!V10*(const_one-note_a_discount) -> 30.102801 | AM10: =MIN('Pro-Forma'!AK10,'Pro-Forma'!AL10) -> 26.778556 | AN10: =note_a_principal_usd/'Pro-Forma'!AM10 -> 186716.57 | AO10: =note_b_cap_usd/(pre_f_fd_total+'Pro-Forma'!S10+'Pro-Forma'!AJ10+'Pro-Forma'!T10) -> 42.739342 | AP10: ='Pro-Forma'!V10*(const_one-note_b_discount) -> 31.984226 | AQ10: =MIN('Pro-Forma'!AO10,'Pro-Forma'!AP10) -> 31.984226 | AR10: =note_b_principal_usd/'Pro-Forma'!AQ10 -> 93796.235 | AS10: =pre_f_fd_total+'Pro-Forma'!S10+'Pro-Forma'!W10+'Pro-Forma'!AN10+'Pro-Forma'!AR10+'Pro-Forma'!AJ10 -> 38327298 | AT10: =MAX(const_zero,esop_refresh_target_post_f*'Pro-Forma'!AS10-pre_f_option_pool_total) -> 587881.76
A11: =lbl_note_b_shares -> Note B shares | B11: =I32 -> 93796.243 | R11: ='Pro-Forma'!R10+const_one -> 7 | S11: ='Pro-Forma'!AT10 -> 587881.76 | T11: ='Pro-Forma'!AN10 -> 186716.57 | U11: ='Pro-Forma'!AR10 -> 93796.235 | V11: =series_f_pre_money_usd/(pre_f_fd_total+'Pro-Forma'!S11) -> 37.628499 | W11: =series_f_primary_raise_usd/'Pro-Forma'!V11 -> 797268.06 | X11: =IF('Pro-Forma'!V11<class_seed_ocp,class_seed_ocp*(ad_pre_f_broad_based_fd+series_f_primary_raise_usd/class_seed_ocp)/(ad_pre_f_broad_based_fd+series_f_primary_raise_usd/'Pro-Forma'!V11),class_seed_ocp) -> 1 | Y11: =class_seed_original_shares*class_seed_issue_pps/'Pro-Forma'!X11 -> 5000000 | Z11: =IF('Pro-Forma'!V11<class_series_a_ocp,class_series_a_ocp*(ad_pre_f_broad_based_fd+series_f_primary_raise_usd/class_series_a_ocp)/(ad_pre_f_broad_based_fd+series_f_primary_raise_usd/'Pro-Forma'!V11),class_series_a_ocp) -> 3 | AA11: =class_series_a_original_shares*class_series_a_issue_pps/'Pro-Forma'!Z11 -> 5000000 | AB11: =IF('Pro-Forma'!V11<class_series_b_ocp,class_series_b_ocp*(ad_pre_f_broad_based_fd+series_f_primary_raise_usd/class_series_b_ocp)/(ad_pre_f_broad_based_fd+series_f_primary_raise_usd/'Pro-Forma'!V11),class_series_b_ocp) -> 10 | AC11: =class_series_b_original_shares*class_series_b_issue_pps/'Pro-Forma'!AB11 -> 3000000 | AD11: =IF('Pro-Forma'!V11<class_series_c_ocp,class_series_c_ocp*(ad_pre_f_broad_based_fd+series_f_primary_raise_usd/class_series_c_ocp)/(ad_pre_f_broad_based_fd+series_f_primary_raise_usd/'Pro-Forma'!V11),class_series_c_ocp) -> 25 | AE11: =class_series_c_original_shares*class_series_c_issue_pps/'Pro-Forma'!AD11 -> 2400000 | AF11: =IF('Pro-Forma'!V11<class_series_d_ocp,class_series_d_ocp*(ad_pre_f_broad_based_fd+series_f_primary_raise_usd/class_series_d_ocp)/(ad_pre_f_broad_based_fd+series_f_primary_raise_usd/'Pro-Forma'!V11),class_series_d_ocp) -> 57.681736 | AG11: =class_series_d_original_shares*class_series_d_issue_pps/'Pro-Forma'!AF11 -> 1733651.4 | AH11: =IF('Pro-Forma'!V11<class_series_e_ocp,class_series_e_ocp*(ad_pre_f_broad_based_fd+series_f_primary_raise_usd/class_series_e_ocp)/(ad_pre_f_broad_based_fd+series_f_primary_raise_usd/'Pro-Forma'!V11),class_series_e_ocp) -> 48.912626 | AI11: =class_series_e_original_shares*class_series_e_issue_pps/'Pro-Forma'!AH11 -> 6133320.3 | AJ11: ='Pro-Forma'!Y11-class_seed_current_shares+'Pro-Forma'!AA11-class_series_a_current_shares+'Pro-Forma'!AC11-class_series_b_current_shares+'Pro-Forma'!AE11-class_series_c_current_shares+'Pro-Forma'!AG11-class_series_d_current_shares+'Pro-Forma'!AI11-class_series_e_current_shares -> 43677.636 | AK11: =note_a_cap_usd/(pre_f_fd_total+'Pro-Forma'!S11+'Pro-Forma'!AJ11+'Pro-Forma'!U11) -> 26.778553 | AL11: ='Pro-Forma'!V11*(const_one-note_a_discount) -> 30.102799 | AM11: =MIN('Pro-Forma'!AK11,'Pro-Forma'!AL11) -> 26.778553 | AN11: =note_a_principal_usd/'Pro-Forma'!AM11 -> 186716.58 | AO11: =note_b_cap_usd/(pre_f_fd_total+'Pro-Forma'!S11+'Pro-Forma'!AJ11+'Pro-Forma'!T11) -> 42.739338 | AP11: ='Pro-Forma'!V11*(const_one-note_b_discount) -> 31.984224 | AQ11: =MIN('Pro-Forma'!AO11,'Pro-Forma'!AP11) -> 31.984224 | AR11: =note_b_principal_usd/'Pro-Forma'!AQ11 -> 93796.242 | AS11: =pre_f_fd_total+'Pro-Forma'!S11+'Pro-Forma'!W11+'Pro-Forma'!AN11+'Pro-Forma'!AR11+'Pro-Forma'!AJ11 -> 38327301 | AT11: =MAX(const_zero,esop_refresh_target_post_f*'Pro-Forma'!AS11-pre_f_option_pool_total) -> 587882.17
A12: =lbl_f_lead_secondary -> F_LEAD secondary common | B12: =B39 -> 468981.22 | R12: ='Pro-Forma'!R11+const_one -> 8 | S12: ='Pro-Forma'!AT11 -> 587882.17 | T12: ='Pro-Forma'!AN11 -> 186716.58 | U12: ='Pro-Forma'!AR11 -> 93796.242 | V12: =series_f_pre_money_usd/(pre_f_fd_total+'Pro-Forma'!S12) -> 37.628498 | W12: =series_f_primary_raise_usd/'Pro-Forma'!V12 -> 797268.07 | X12: =IF('Pro-Forma'!V12<class_seed_ocp,class_seed_ocp*(ad_pre_f_broad_based_fd+series_f_primary_raise_usd/class_seed_ocp)/(ad_pre_f_broad_based_fd+series_f_primary_raise_usd/'Pro-Forma'!V12),class_seed_ocp) -> 1 | Y12: =class_seed_original_shares*class_seed_issue_pps/'Pro-Forma'!X12 -> 5000000 | Z12: =IF('Pro-Forma'!V12<class_series_a_ocp,class_series_a_ocp*(ad_pre_f_broad_based_fd+series_f_primary_raise_usd/class_series_a_ocp)/(ad_pre_f_broad_based_fd+series_f_primary_raise_usd/'Pro-Forma'!V12),class_series_a_ocp) -> 3 | AA12: =class_series_a_original_shares*class_series_a_issue_pps/'Pro-Forma'!Z12 -> 5000000 | AB12: =IF('Pro-Forma'!V12<class_series_b_ocp,class_series_b_ocp*(ad_pre_f_broad_based_fd+series_f_primary_raise_usd/class_series_b_ocp)/(ad_pre_f_broad_based_fd+series_f_primary_raise_usd/'Pro-Forma'!V12),class_series_b_ocp) -> 10 | AC12: =class_series_b_original_shares*class_series_b_issue_pps/'Pro-Forma'!AB12 -> 3000000 | AD12: =IF('Pro-Forma'!V12<class_series_c_ocp,class_series_c_ocp*(ad_pre_f_broad_based_fd+series_f_primary_raise_usd/class_series_c_ocp)/(ad_pre_f_broad_based_fd+series_f_primary_raise_usd/'Pro-Forma'!V12),class_series_c_ocp) -> 25 | AE12: =class_series_c_original_shares*class_series_c_issue_pps/'Pro-Forma'!AD12 -> 2400000 | AF12: =IF('Pro-Forma'!V12<class_series_d_ocp,class_series_d_ocp*(ad_pre_f_broad_based_fd+series_f_primary_raise_usd/class_series_d_ocp)/(ad_pre_f_broad_based_fd+series_f_primary_raise_usd/'Pro-Forma'!V12),class_series_d_ocp) -> 57.681736 | AG12: =class_series_d_original_shares*class_series_d_issue_pps/'Pro-Forma'!AF12 -> 1733651.4 | AH12: =IF('Pro-Forma'!V12<class_series_e_ocp,class_series_e_ocp*(ad_pre_f_broad_based_fd+series_f_primary_raise_usd/class_series_e_ocp)/(ad_pre_f_broad_based_fd+series_f_primary_raise_usd/'Pro-Forma'!V12),class_series_e_ocp) -> 48.912626 | AI12: =class_series_e_original_shares*class_series_e_issue_pps/'Pro-Forma'!AH12 -> 6133320.3 | AJ12: ='Pro-Forma'!Y12-class_seed_current_shares+'Pro-Forma'!AA12-class_series_a_current_shares+'Pro-Forma'!AC12-class_series_b_current_shares+'Pro-Forma'!AE12-class_series_c_current_shares+'Pro-Forma'!AG12-class_series_d_current_shares+'Pro-Forma'!AI12-class_series_e_current_shares -> 43677.637 | AK12: =note_a_cap_usd/(pre_f_fd_total+'Pro-Forma'!S12+'Pro-Forma'!AJ12+'Pro-Forma'!U12) -> 26.778553 | AL12: ='Pro-Forma'!V12*(const_one-note_a_discount) -> 30.102799 | AM12: =MIN('Pro-Forma'!AK12,'Pro-Forma'!AL12) -> 26.778553 | AN12: =note_a_principal_usd/'Pro-Forma'!AM12 -> 186716.59 | AO12: =note_b_cap_usd/(pre_f_fd_total+'Pro-Forma'!S12+'Pro-Forma'!AJ12+'Pro-Forma'!T12) -> 42.739338 | AP12: ='Pro-Forma'!V12*(const_one-note_b_discount) -> 31.984223 | AQ12: =MIN('Pro-Forma'!AO12,'Pro-Forma'!AP12) -> 31.984223 | AR12: =note_b_principal_usd/'Pro-Forma'!AQ12 -> 93796.243 | AS12: =pre_f_fd_total+'Pro-Forma'!S12+'Pro-Forma'!W12+'Pro-Forma'!AN12+'Pro-Forma'!AR12+'Pro-Forma'!AJ12 -> 38327302 | AT12: =MAX(const_zero,esop_refresh_target_post_f*'Pro-Forma'!AS12-pre_f_option_pool_total) -> 587882.22
A13: =lbl_common_gross_pps -> Gross common PPS | B13: =B4 -> 37.628498 | R13: ='Pro-Forma'!R12+const_one -> 9 | S13: ='Pro-Forma'!AT12 -> 587882.22 | T13: ='Pro-Forma'!AN12 -> 186716.59 | U13: ='Pro-Forma'!AR12 -> 93796.243 | V13: =series_f_pre_money_usd/(pre_f_fd_total+'Pro-Forma'!S13) -> 37.628498 | W13: =series_f_primary_raise_usd/'Pro-Forma'!V13 -> 797268.07 | X13: =IF('Pro-Forma'!V13<class_seed_ocp,class_seed_ocp*(ad_pre_f_broad_based_fd+series_f_primary_raise_usd/class_seed_ocp)/(ad_pre_f_broad_based_fd+series_f_primary_raise_usd/'Pro-Forma'!V13),class_seed_ocp) -> 1 | Y13: =class_seed_original_shares*class_seed_issue_pps/'Pro-Forma'!X13 -> 5000000 | Z13: =IF('Pro-Forma'!V13<class_series_a_ocp,class_series_a_ocp*(ad_pre_f_broad_based_fd+series_f_primary_raise_usd/class_series_a_ocp)/(ad_pre_f_broad_based_fd+series_f_primary_raise_usd/'Pro-Forma'!V13),class_series_a_ocp) -> 3 | AA13: =class_series_a_original_shares*class_series_a_issue_pps/'Pro-Forma'!Z13 -> 5000000 | AB13: =IF('Pro-Forma'!V13<class_series_b_ocp,class_series_b_ocp*(ad_pre_f_broad_based_fd+series_f_primary_raise_usd/class_series_b_ocp)/(ad_pre_f_broad_based_fd+series_f_primary_raise_usd/'Pro-Forma'!V13),class_series_b_ocp) -> 10 | AC13: =class_series_b_original_shares*class_series_b_issue_pps/'Pro-Forma'!AB13 -> 3000000 | AD13: =IF('Pro-Forma'!V13<class_series_c_ocp,class_series_c_ocp*(ad_pre_f_broad_based_fd+series_f_primary_raise_usd/class_series_c_ocp)/(ad_pre_f_broad_based_fd+series_f_primary_raise_usd/'Pro-Forma'!V13),class_series_c_ocp) -> 25 | AE13: =class_series_c_original_shares*class_series_c_issue_pps/'Pro-Forma'!AD13 -> 2400000 | AF13: =IF('Pro-Forma'!V13<class_series_d_ocp,class_series_d_ocp*(ad_pre_f_broad_based_fd+series_f_primary_raise_usd/class_series_d_ocp)/(ad_pre_f_broad_based_fd+series_f_primary_raise_usd/'Pro-Forma'!V13),class_series_d_ocp) -> 57.681736 | AG13: =class_series_d_original_shares*class_series_d_issue_pps/'Pro-Forma'!AF13 -> 1733651.4 | AH13: =IF('Pro-Forma'!V13<class_series_e_ocp,class_series_e_ocp*(ad_pre_f_broad_based_fd+series_f_primary_raise_usd/class_series_e_ocp)/(ad_pre_f_broad_based_fd+series_f_primary_raise_usd/'Pro-Forma'!V13),class_series_e_ocp) -> 48.912626 | AI13: =class_series_e_original_shares*class_series_e_issue_pps/'Pro-Forma'!AH13 -> 6133320.3 | AJ13: ='Pro-Forma'!Y13-class_seed_current_shares+'Pro-Forma'!AA13-class_series_a_current_shares+'Pro-Forma'!AC13-class_series_b_current_shares+'Pro-Forma'!AE13-class_series_c_current_shares+'Pro-Forma'!AG13-class_series_d_current_shares+'Pro-Forma'!AI13-class_series_e_current_shares -> 43677.638 | AK13: =note_a_cap_usd/(pre_f_fd_total+'Pro-Forma'!S13+'Pro-Forma'!AJ13+'Pro-Forma'!U13) -> 26.778553 | AL13: ='Pro-Forma'!V13*(const_one-note_a_discount) -> 30.102798 | AM13: =MIN('Pro-Forma'!AK13,'Pro-Forma'!AL13) -> 26.778553 | AN13: =note_a_principal_usd/'Pro-Forma'!AM13 -> 186716.59 | AO13: =note_b_cap_usd/(pre_f_fd_total+'Pro-Forma'!S13+'Pro-Forma'!AJ13+'Pro-Forma'!T13) -> 42.739338 | AP13: ='Pro-Forma'!V13*(const_one-note_b_discount) -> 31.984223 | AQ13: =MIN('Pro-Forma'!AO13,'Pro-Forma'!AP13) -> 31.984223 | AR13: =note_b_principal_usd/'Pro-Forma'!AQ13 -> 93796.243 | AS13: =pre_f_fd_total+'Pro-Forma'!S13+'Pro-Forma'!W13+'Pro-Forma'!AN13+'Pro-Forma'!AR13+'Pro-Forma'!AJ13 -> 38327302 | AT13: =MAX(const_zero,esop_refresh_target_post_f*'Pro-Forma'!AS13-pre_f_option_pool_total) -> 587882.23
A14: =lbl_post_f_fd -> Post-F FD shares | B14: =pre_f_fd_total+B8+B5+B10+B11+B9 -> 38327302 | R14: ='Pro-Forma'!R13+const_one -> 10 | S14: ='Pro-Forma'!AT13 -> 587882.23 | T14: ='Pro-Forma'!AN13 -> 186716.59 | U14: ='Pro-Forma'!AR13 -> 93796.243 | V14: =series_f_pre_money_usd/(pre_f_fd_total+'Pro-Forma'!S14) -> 37.628498 | W14: =series_f_primary_raise_usd/'Pro-Forma'!V14 -> 797268.07 | X14: =IF('Pro-Forma'!V14<class_seed_ocp,class_seed_ocp*(ad_pre_f_broad_based_fd+series_f_primary_raise_usd/class_seed_ocp)/(ad_pre_f_broad_based_fd+series_f_primary_raise_usd/'Pro-Forma'!V14),class_seed_ocp) -> 1 | Y14: =class_seed_original_shares*class_seed_issue_pps/'Pro-Forma'!X14 -> 5000000 | Z14: =IF('Pro-Forma'!V14<class_series_a_ocp,class_series_a_ocp*(ad_pre_f_broad_based_fd+series_f_primary_raise_usd/class_series_a_ocp)/(ad_pre_f_broad_based_fd+series_f_primary_raise_usd/'Pro-Forma'!V14),class_series_a_ocp) -> 3 | AA14: =class_series_a_original_shares*class_series_a_issue_pps/'Pro-Forma'!Z14 -> 5000000 | AB14: =IF('Pro-Forma'!V14<class_series_b_ocp,class_series_b_ocp*(ad_pre_f_broad_based_fd+series_f_primary_raise_usd/class_series_b_ocp)/(ad_pre_f_broad_based_fd+series_f_primary_raise_usd/'Pro-Forma'!V14),class_series_b_ocp) -> 10 | AC14: =class_series_b_original_shares*class_series_b_issue_pps/'Pro-Forma'!AB14 -> 3000000 | AD14: =IF('Pro-Forma'!V14<class_series_c_ocp,class_series_c_ocp*(ad_pre_f_broad_based_fd+series_f_primary_raise_usd/class_series_c_ocp)/(ad_pre_f_broad_based_fd+series_f_primary_raise_usd/'Pro-Forma'!V14),class_series_c_ocp) -> 25 | AE14: =class_series_c_original_shares*class_series_c_issue_pps/'Pro-Forma'!AD14 -> 2400000 | AF14: =IF('Pro-Forma'!V14<class_series_d_ocp,class_series_d_ocp*(ad_pre_f_broad_based_fd+series_f_primary_raise_usd/class_series_d_ocp)/(ad_pre_f_broad_based_fd+series_f_primary_raise_usd/'Pro-Forma'!V14),class_series_d_ocp) -> 57.681736 | AG14: =class_series_d_original_shares*class_series_d_issue_pps/'Pro-Forma'!AF14 -> 1733651.4 | AH14: =IF('Pro-Forma'!V14<class_series_e_ocp,class_series_e_ocp*(ad_pre_f_broad_based_fd+series_f_primary_raise_usd/class_series_e_ocp)/(ad_pre_f_broad_based_fd+series_f_primary_raise_usd/'Pro-Forma'!V14),class_series_e_ocp) -> 48.912626 | AI14: =class_series_e_original_shares*class_series_e_issue_pps/'Pro-Forma'!AH14 -> 6133320.3 | AJ14: ='Pro-Forma'!Y14-class_seed_current_shares+'Pro-Forma'!AA14-class_series_a_current_shares+'Pro-Forma'!AC14-class_series_b_current_shares+'Pro-Forma'!AE14-class_series_c_current_shares+'Pro-Forma'!AG14-class_series_d_current_shares+'Pro-Forma'!AI14-class_series_e_current_shares -> 43677.638 | AK14: =note_a_cap_usd/(pre_f_fd_total+'Pro-Forma'!S14+'Pro-Forma'!AJ14+'Pro-Forma'!U14) -> 26.778553 | AL14: ='Pro-Forma'!V14*(const_one-note_a_discount) -> 30.102798 | AM14: =MIN('Pro-Forma'!AK14,'Pro-Forma'!AL14) -> 26.778553 | AN14: =note_a_principal_usd/'Pro-Forma'!AM14 -> 186716.59 | AO14: =note_b_cap_usd/(pre_f_fd_total+'Pro-Forma'!S14+'Pro-Forma'!AJ14+'Pro-Forma'!T14) -> 42.739338 | AP14: ='Pro-Forma'!V14*(const_one-note_b_discount) -> 31.984223 | AQ14: =MIN('Pro-Forma'!AO14,'Pro-Forma'!AP14) -> 31.984223 | AR14: =note_b_principal_usd/'Pro-Forma'!AQ14 -> 93796.243 | AS14: =pre_f_fd_total+'Pro-Forma'!S14+'Pro-Forma'!W14+'Pro-Forma'!AN14+'Pro-Forma'!AR14+'Pro-Forma'!AJ14 -> 38327302 | AT14: =MAX(const_zero,esop_refresh_target_post_f*'Pro-Forma'!AS14-pre_f_option_pool_total) -> 587882.23
R15: ='Pro-Forma'!R14+const_one -> 11 | S15: ='Pro-Forma'!AT14 -> 587882.23 | T15: ='Pro-Forma'!AN14 -> 186716.59 | U15: ='Pro-Forma'!AR14 -> 93796.243 | V15: =series_f_pre_money_usd/(pre_f_fd_total+'Pro-Forma'!S15) -> 37.628498 | W15: =series_f_primary_raise_usd/'Pro-Forma'!V15 -> 797268.07 | X15: =IF('Pro-Forma'!V15<class_seed_ocp,class_seed_ocp*(ad_pre_f_broad_based_fd+series_f_primary_raise_usd/class_seed_ocp)/(ad_pre_f_broad_based_fd+series_f_primary_raise_usd/'Pro-Forma'!V15),class_seed_ocp) -> 1 | Y15: =class_seed_original_shares*class_seed_issue_pps/'Pro-Forma'!X15 -> 5000000 | Z15: =IF('Pro-Forma'!V15<class_series_a_ocp,class_series_a_ocp*(ad_pre_f_broad_based_fd+series_f_primary_raise_usd/class_series_a_ocp)/(ad_pre_f_broad_based_fd+series_f_primary_raise_usd/'Pro-Forma'!V15),class_series_a_ocp) -> 3 | AA15: =class_series_a_original_shares*class_series_a_issue_pps/'Pro-Forma'!Z15 -> 5000000 | AB15: =IF('Pro-Forma'!V15<class_series_b_ocp,class_series_b_ocp*(ad_pre_f_broad_based_fd+series_f_primary_raise_usd/class_series_b_ocp)/(ad_pre_f_broad_based_fd+series_f_primary_raise_usd/'Pro-Forma'!V15),class_series_b_ocp) -> 10 | AC15: =class_series_b_original_shares*class_series_b_issue_pps/'Pro-Forma'!AB15 -> 3000000 | AD15: =IF('Pro-Forma'!V15<class_series_c_ocp,class_series_c_ocp*(ad_pre_f_broad_based_fd+series_f_primary_raise_usd/class_series_c_ocp)/(ad_pre_f_broad_based_fd+series_f_primary_raise_usd/'Pro-Forma'!V15),class_series_c_ocp) -> 25 | AE15: =class_series_c_original_shares*class_series_c_issue_pps/'Pro-Forma'!AD15 -> 2400000 | AF15: =IF('Pro-Forma'!V15<class_series_d_ocp,class_series_d_ocp*(ad_pre_f_broad_based_fd+series_f_primary_raise_usd/class_series_d_ocp)/(ad_pre_f_broad_based_fd+series_f_primary_raise_usd/'Pro-Forma'!V15),class_series_d_ocp) -> 57.681736 | AG15: =class_series_d_original_shares*class_series_d_issue_pps/'Pro-Forma'!AF15 -> 1733651.4 | AH15: =IF('Pro-Forma'!V15<class_series_e_ocp,class_series_e_ocp*(ad_pre_f_broad_based_fd+series_f_primary_raise_usd/class_series_e_ocp)/(ad_pre_f_broad_based_fd+series_f_primary_raise_usd/'Pro-Forma'!V15),class_series_e_ocp) -> 48.912626 | AI15: =class_series_e_original_shares*class_series_e_issue_pps/'Pro-Forma'!AH15 -> 6133320.3 | AJ15: ='Pro-Forma'!Y15-class_seed_current_shares+'Pro-Forma'!AA15-class_series_a_current_shares+'Pro-Forma'!AC15-class_series_b_current_shares+'Pro-Forma'!AE15-class_series_c_current_shares+'Pro-Forma'!AG15-class_series_d_current_shares+'Pro-Forma'!AI15-class_series_e_current_shares -> 43677.638 | AK15: =note_a_cap_usd/(pre_f_fd_total+'Pro-Forma'!S15+'Pro-Forma'!AJ15+'Pro-Forma'!U15) -> 26.778553 | AL15: ='Pro-Forma'!V15*(const_one-note_a_discount) -> 30.102798 | AM15: =MIN('Pro-Forma'!AK15,'Pro-Forma'!AL15) -> 26.778553 | AN15: =note_a_principal_usd/'Pro-Forma'!AM15 -> 186716.59 | AO15: =note_b_cap_usd/(pre_f_fd_total+'Pro-Forma'!S15+'Pro-Forma'!AJ15+'Pro-Forma'!T15) -> 42.739338 | AP15: ='Pro-Forma'!V15*(const_one-note_b_discount) -> 31.984223 | AQ15: =MIN('Pro-Forma'!AO15,'Pro-Forma'!AP15) -> 31.984223 | AR15: =note_b_principal_usd/'Pro-Forma'!AQ15 -> 93796.243 | AS15: =pre_f_fd_total+'Pro-Forma'!S15+'Pro-Forma'!W15+'Pro-Forma'!AN15+'Pro-Forma'!AR15+'Pro-Forma'!AJ15 -> 38327302 | AT15: =MAX(const_zero,esop_refresh_target_post_f*'Pro-Forma'!AS15-pre_f_option_pool_total) -> 587882.23
R16: ='Pro-Forma'!R15+const_one -> 12 | S16: ='Pro-Forma'!AT15 -> 587882.23 | T16: ='Pro-Forma'!AN15 -> 186716.59 | U16: ='Pro-Forma'!AR15 -> 93796.243 | V16: =series_f_pre_money_usd/(pre_f_fd_total+'Pro-Forma'!S16) -> 37.628498 | W16: =series_f_primary_raise_usd/'Pro-Forma'!V16 -> 797268.07 | X16: =IF('Pro-Forma'!V16<class_seed_ocp,class_seed_ocp*(ad_pre_f_broad_based_fd+series_f_primary_raise_usd/class_seed_ocp)/(ad_pre_f_broad_based_fd+series_f_primary_raise_usd/'Pro-Forma'!V16),class_seed_ocp) -> 1 | Y16: =class_seed_original_shares*class_seed_issue_pps/'Pro-Forma'!X16 -> 5000000 | Z16: =IF('Pro-Forma'!V16<class_series_a_ocp,class_series_a_ocp*(ad_pre_f_broad_based_fd+series_f_primary_raise_usd/class_series_a_ocp)/(ad_pre_f_broad_based_fd+series_f_primary_raise_usd/'Pro-Forma'!V16),class_series_a_ocp) -> 3 | AA16: =class_series_a_original_shares*class_series_a_issue_pps/'Pro-Forma'!Z16 -> 5000000 | AB16: =IF('Pro-Forma'!V16<class_series_b_ocp,class_series_b_ocp*(ad_pre_f_broad_based_fd+series_f_primary_raise_usd/class_series_b_ocp)/(ad_pre_f_broad_based_fd+series_f_primary_raise_usd/'Pro-Forma'!V16),class_series_b_ocp) -> 10 | AC16: =class_series_b_original_shares*class_series_b_issue_pps/'Pro-Forma'!AB16 -> 3000000 | AD16: =IF('Pro-Forma'!V16<class_series_c_ocp,class_series_c_ocp*(ad_pre_f_broad_based_fd+series_f_primary_raise_usd/class_series_c_ocp)/(ad_pre_f_broad_based_fd+series_f_primary_raise_usd/'Pro-Forma'!V16),class_series_c_ocp) -> 25 | AE16: =class_series_c_original_shares*class_series_c_issue_pps/'Pro-Forma'!AD16 -> 2400000 | AF16: =IF('Pro-Forma'!V16<class_series_d_ocp,class_series_d_ocp*(ad_pre_f_broad_based_fd+series_f_primary_raise_usd/class_series_d_ocp)/(ad_pre_f_broad_based_fd+series_f_primary_raise_usd/'Pro-Forma'!V16),class_series_d_ocp) -> 57.681736 | AG16: =class_series_d_original_shares*class_series_d_issue_pps/'Pro-Forma'!AF16 -> 1733651.4 | AH16: =IF('Pro-Forma'!V16<class_series_e_ocp,class_series_e_ocp*(ad_pre_f_broad_based_fd+series_f_primary_raise_usd/class_series_e_ocp)/(ad_pre_f_broad_based_fd+series_f_primary_raise_usd/'Pro-Forma'!V16),class_series_e_ocp) -> 48.912626 | AI16: =class_series_e_original_shares*class_series_e_issue_pps/'Pro-Forma'!AH16 -> 6133320.3 | AJ16: ='Pro-Forma'!Y16-class_seed_current_shares+'Pro-Forma'!AA16-class_series_a_current_shares+'Pro-Forma'!AC16-class_series_b_current_shares+'Pro-Forma'!AE16-class_series_c_current_shares+'Pro-Forma'!AG16-class_series_d_current_shares+'Pro-Forma'!AI16-class_series_e_current_shares -> 43677.638 | AK16: =note_a_cap_usd/(pre_f_fd_total+'Pro-Forma'!S16+'Pro-Forma'!AJ16+'Pro-Forma'!U16) -> 26.778553 | AL16: ='Pro-Forma'!V16*(const_one-note_a_discount) -> 30.102798 | AM16: =MIN('Pro-Forma'!AK16,'Pro-Forma'!AL16) -> 26.778553 | AN16: =note_a_principal_usd/'Pro-Forma'!AM16 -> 186716.59 | AO16: =note_b_cap_usd/(pre_f_fd_total+'Pro-Forma'!S16+'Pro-Forma'!AJ16+'Pro-Forma'!T16) -> 42.739338 | AP16: ='Pro-Forma'!V16*(const_one-note_b_discount) -> 31.984223 | AQ16: =MIN('Pro-Forma'!AO16,'Pro-Forma'!AP16) -> 31.984223 | AR16: =note_b_principal_usd/'Pro-Forma'!AQ16 -> 93796.243 | AS16: =pre_f_fd_total+'Pro-Forma'!S16+'Pro-Forma'!W16+'Pro-Forma'!AN16+'Pro-Forma'!AR16+'Pro-Forma'!AJ16 -> 38327302 | AT16: =MAX(const_zero,esop_refresh_target_post_f*'Pro-Forma'!AS16-pre_f_option_pool_total) -> 587882.23
R17: ='Pro-Forma'!R16+const_one -> 13 | S17: ='Pro-Forma'!AT16 -> 587882.23 | T17: ='Pro-Forma'!AN16 -> 186716.59 | U17: ='Pro-Forma'!AR16 -> 93796.243 | V17: =series_f_pre_money_usd/(pre_f_fd_total+'Pro-Forma'!S17) -> 37.628498 | W17: =series_f_primary_raise_usd/'Pro-Forma'!V17 -> 797268.07 | X17: =IF('Pro-Forma'!V17<class_seed_ocp,class_seed_ocp*(ad_pre_f_broad_based_fd+series_f_primary_raise_usd/class_seed_ocp)/(ad_pre_f_broad_based_fd+series_f_primary_raise_usd/'Pro-Forma'!V17),class_seed_ocp) -> 1 | Y17: =class_seed_original_shares*class_seed_issue_pps/'Pro-Forma'!X17 -> 5000000 | Z17: =IF('Pro-Forma'!V17<class_series_a_ocp,class_series_a_ocp*(ad_pre_f_broad_based_fd+series_f_primary_raise_usd/class_series_a_ocp)/(ad_pre_f_broad_based_fd+series_f_primary_raise_usd/'Pro-Forma'!V17),class_series_a_ocp) -> 3 | AA17: =class_series_a_original_shares*class_series_a_issue_pps/'Pro-Forma'!Z17 -> 5000000 | AB17: =IF('Pro-Forma'!V17<class_series_b_ocp,class_series_b_ocp*(ad_pre_f_broad_based_fd+series_f_primary_raise_usd/class_series_b_ocp)/(ad_pre_f_broad_based_fd+series_f_primary_raise_usd/'Pro-Forma'!V17),class_series_b_ocp) -> 10 | AC17: =class_series_b_original_shares*class_series_b_issue_pps/'Pro-Forma'!AB17 -> 3000000 | AD17: =IF('Pro-Forma'!V17<class_series_c_ocp,class_series_c_ocp*(ad_pre_f_broad_based_fd+series_f_primary_raise_usd/class_series_c_ocp)/(ad_pre_f_broad_based_fd+series_f_primary_raise_usd/'Pro-Forma'!V17),class_series_c_ocp) -> 25 | AE17: =class_series_c_original_shares*class_series_c_issue_pps/'Pro-Forma'!AD17 -> 2400000 | AF17: =IF('Pro-Forma'!V17<class_series_d_ocp,class_series_d_ocp*(ad_pre_f_broad_based_fd+series_f_primary_raise_usd/class_series_d_ocp)/(ad_pre_f_broad_based_fd+series_f_primary_raise_usd/'Pro-Forma'!V17),class_series_d_ocp) -> 57.681736 | AG17: =class_series_d_original_shares*class_series_d_issue_pps/'Pro-Forma'!AF17 -> 1733651.4 | AH17: =IF('Pro-Forma'!V17<class_series_e_ocp,class_series_e_ocp*(ad_pre_f_broad_based_fd+series_f_primary_raise_usd/class_series_e_ocp)/(ad_pre_f_broad_based_fd+series_f_primary_raise_usd/'Pro-Forma'!V17),class_series_e_ocp) -> 48.912626 | AI17: =class_series_e_original_shares*class_series_e_issue_pps/'Pro-Forma'!AH17 -> 6133320.3 | AJ17: ='Pro-Forma'!Y17-class_seed_current_shares+'Pro-Forma'!AA17-class_series_a_current_shares+'Pro-Forma'!AC17-class_series_b_current_shares+'Pro-Forma'!AE17-class_series_c_current_shares+'Pro-Forma'!AG17-class_series_d_current_shares+'Pro-Forma'!AI17-class_series_e_current_shares -> 43677.638 | AK17: =note_a_cap_usd/(pre_f_fd_total+'Pro-Forma'!S17+'Pro-Forma'!AJ17+'Pro-Forma'!U17) -> 26.778553 | AL17: ='Pro-Forma'!V17*(const_one-note_a_discount) -> 30.102798 | AM17: =MIN('Pro-Forma'!AK17,'Pro-Forma'!AL17) -> 26.778553 | AN17: =note_a_principal_usd/'Pro-Forma'!AM17 -> 186716.59 | AO17: =note_b_cap_usd/(pre_f_fd_total+'Pro-Forma'!S17+'Pro-Forma'!AJ17+'Pro-Forma'!T17) -> 42.739338 | AP17: ='Pro-Forma'!V17*(const_one-note_b_discount) -> 31.984223 | AQ17: =MIN('Pro-Forma'!AO17,'Pro-Forma'!AP17) -> 31.984223 | AR17: =note_b_principal_usd/'Pro-Forma'!AQ17 -> 93796.243 | AS17: =pre_f_fd_total+'Pro-Forma'!S17+'Pro-Forma'!W17+'Pro-Forma'!AN17+'Pro-Forma'!AR17+'Pro-Forma'!AJ17 -> 38327302 | AT17: =MAX(const_zero,esop_refresh_target_post_f*'Pro-Forma'!AS17-pre_f_option_pool_total) -> 587882.23
A18: =lbl_ad_block -> Anti-Dilution Block | R18: ='Pro-Forma'!R17+const_one -> 14 | S18: ='Pro-Forma'!AT17 -> 587882.23 | T18: ='Pro-Forma'!AN17 -> 186716.59 | U18: ='Pro-Forma'!AR17 -> 93796.243 | V18: =series_f_pre_money_usd/(pre_f_fd_total+'Pro-Forma'!S18) -> 37.628498 | W18: =series_f_primary_raise_usd/'Pro-Forma'!V18 -> 797268.07 | X18: =IF('Pro-Forma'!V18<class_seed_ocp,class_seed_ocp*(ad_pre_f_broad_based_fd+series_f_primary_raise_usd/class_seed_ocp)/(ad_pre_f_broad_based_fd+series_f_primary_raise_usd/'Pro-Forma'!V18),class_seed_ocp) -> 1 | Y18: =class_seed_original_shares*class_seed_issue_pps/'Pro-Forma'!X18 -> 5000000 | Z18: =IF('Pro-Forma'!V18<class_series_a_ocp,class_series_a_ocp*(ad_pre_f_broad_based_fd+series_f_primary_raise_usd/class_series_a_ocp)/(ad_pre_f_broad_based_fd+series_f_primary_raise_usd/'Pro-Forma'!V18),class_series_a_ocp) -> 3 | AA18: =class_series_a_original_shares*class_series_a_issue_pps/'Pro-Forma'!Z18 -> 5000000 | AB18: =IF('Pro-Forma'!V18<class_series_b_ocp,class_series_b_ocp*(ad_pre_f_broad_based_fd+series_f_primary_raise_usd/class_series_b_ocp)/(ad_pre_f_broad_based_fd+series_f_primary_raise_usd/'Pro-Forma'!V18),class_series_b_ocp) -> 10 | AC18: =class_series_b_original_shares*class_series_b_issue_pps/'Pro-Forma'!AB18 -> 3000000 | AD18: =IF('Pro-Forma'!V18<class_series_c_ocp,class_series_c_ocp*(ad_pre_f_broad_based_fd+series_f_primary_raise_usd/class_series_c_ocp)/(ad_pre_f_broad_based_fd+series_f_primary_raise_usd/'Pro-Forma'!V18),class_series_c_ocp) -> 25 | AE18: =class_series_c_original_shares*class_series_c_issue_pps/'Pro-Forma'!AD18 -> 2400000 | AF18: =IF('Pro-Forma'!V18<class_series_d_ocp,class_series_d_ocp*(ad_pre_f_broad_based_fd+series_f_primary_raise_usd/class_series_d_ocp)/(ad_pre_f_broad_based_fd+series_f_primary_raise_usd/'Pro-Forma'!V18),class_series_d_ocp) -> 57.681736 | AG18: =class_series_d_original_shares*class_series_d_issue_pps/'Pro-Forma'!AF18 -> 1733651.4 | AH18: =IF('Pro-Forma'!V18<class_series_e_ocp,class_series_e_ocp*(ad_pre_f_broad_based_fd+series_f_primary_raise_usd/class_series_e_ocp)/(ad_pre_f_broad_based_fd+series_f_primary_raise_usd/'Pro-Forma'!V18),class_series_e_ocp) -> 48.912626 | AI18: =class_series_e_original_shares*class_series_e_issue_pps/'Pro-Forma'!AH18 -> 6133320.3 | AJ18: ='Pro-Forma'!Y18-class_seed_current_shares+'Pro-Forma'!AA18-class_series_a_current_shares+'Pro-Forma'!AC18-class_series_b_current_shares+'Pro-Forma'!AE18-class_series_c_current_shares+'Pro-Forma'!AG18-class_series_d_current_shares+'Pro-Forma'!AI18-class_series_e_current_shares -> 43677.638 | AK18: =note_a_cap_usd/(pre_f_fd_total+'Pro-Forma'!S18+'Pro-Forma'!AJ18+'Pro-Forma'!U18) -> 26.778553 | AL18: ='Pro-Forma'!V18*(const_one-note_a_discount) -> 30.102798 | AM18: =MIN('Pro-Forma'!AK18,'Pro-Forma'!AL18) -> 26.778553 | AN18: =note_a_principal_usd/'Pro-Forma'!AM18 -> 186716.59 | AO18: =note_b_cap_usd/(pre_f_fd_total+'Pro-Forma'!S18+'Pro-Forma'!AJ18+'Pro-Forma'!T18) -> 42.739338 | AP18: ='Pro-Forma'!V18*(const_one-note_b_discount) -> 31.984223 | AQ18: =MIN('Pro-Forma'!AO18,'Pro-Forma'!AP18) -> 31.984223 | AR18: =note_b_principal_usd/'Pro-Forma'!AQ18 -> 93796.243 | AS18: =pre_f_fd_total+'Pro-Forma'!S18+'Pro-Forma'!W18+'Pro-Forma'!AN18+'Pro-Forma'!AR18+'Pro-Forma'!AJ18 -> 38327302 | AT18: =MAX(const_zero,esop_refresh_target_post_f*'Pro-Forma'!AS18-pre_f_option_pool_total) -> 587882.23
R19: ='Pro-Forma'!R18+const_one -> 15 | S19: ='Pro-Forma'!AT18 -> 587882.23 | T19: ='Pro-Forma'!AN18 -> 186716.59 | U19: ='Pro-Forma'!AR18 -> 93796.243 | V19: =series_f_pre_money_usd/(pre_f_fd_total+'Pro-Forma'!S19) -> 37.628498 | W19: =series_f_primary_raise_usd/'Pro-Forma'!V19 -> 797268.07 | X19: =IF('Pro-Forma'!V19<class_seed_ocp,class_seed_ocp*(ad_pre_f_broad_based_fd+series_f_primary_raise_usd/class_seed_ocp)/(ad_pre_f_broad_based_fd+series_f_primary_raise_usd/'Pro-Forma'!V19),class_seed_ocp) -> 1 | Y19: =class_seed_original_shares*class_seed_issue_pps/'Pro-Forma'!X19 -> 5000000 | Z19: =IF('Pro-Forma'!V19<class_series_a_ocp,class_series_a_ocp*(ad_pre_f_broad_based_fd+series_f_primary_raise_usd/class_series_a_ocp)/(ad_pre_f_broad_based_fd+series_f_primary_raise_usd/'Pro-Forma'!V19),class_series_a_ocp) -> 3 | AA19: =class_series_a_original_shares*class_series_a_issue_pps/'Pro-Forma'!Z19 -> 5000000 | AB19: =IF('Pro-Forma'!V19<class_series_b_ocp,class_series_b_ocp*(ad_pre_f_broad_based_fd+series_f_primary_raise_usd/class_series_b_ocp)/(ad_pre_f_broad_based_fd+series_f_primary_raise_usd/'Pro-Forma'!V19),class_series_b_ocp) -> 10 | AC19: =class_series_b_original_shares*class_series_b_issue_pps/'Pro-Forma'!AB19 -> 3000000 | AD19: =IF('Pro-Forma'!V19<class_series_c_ocp,class_series_c_ocp*(ad_pre_f_broad_based_fd+series_f_primary_raise_usd/class_series_c_ocp)/(ad_pre_f_broad_based_fd+series_f_primary_raise_usd/'Pro-Forma'!V19),class_series_c_ocp) -> 25 | AE19: =class_series_c_original_shares*class_series_c_issue_pps/'Pro-Forma'!AD19 -> 2400000 | AF19: =IF('Pro-Forma'!V19<class_series_d_ocp,class_series_d_ocp*(ad_pre_f_broad_based_fd+series_f_primary_raise_usd/class_series_d_ocp)/(ad_pre_f_broad_based_fd+series_f_primary_raise_usd/'Pro-Forma'!V19),class_series_d_ocp) -> 57.681736 | AG19: =class_series_d_original_shares*class_series_d_issue_pps/'Pro-Forma'!AF19 -> 1733651.4 | AH19: =IF('Pro-Forma'!V19<class_series_e_ocp,class_series_e_ocp*(ad_pre_f_broad_based_fd+series_f_primary_raise_usd/class_series_e_ocp)/(ad_pre_f_broad_based_fd+series_f_primary_raise_usd/'Pro-Forma'!V19),class_series_e_ocp) -> 48.912626 | AI19: =class_series_e_original_shares*class_series_e_issue_pps/'Pro-Forma'!AH19 -> 6133320.3 | AJ19: ='Pro-Forma'!Y19-class_seed_current_shares+'Pro-Forma'!AA19-class_series_a_current_shares+'Pro-Forma'!AC19-class_series_b_current_shares+'Pro-Forma'!AE19-class_series_c_current_shares+'Pro-Forma'!AG19-class_series_d_current_shares+'Pro-Forma'!AI19-class_series_e_current_shares -> 43677.638 | AK19: =note_a_cap_usd/(pre_f_fd_total+'Pro-Forma'!S19+'Pro-Forma'!AJ19+'Pro-Forma'!U19) -> 26.778553 | AL19: ='Pro-Forma'!V19*(const_one-note_a_discount) -> 30.102798 | AM19: =MIN('Pro-Forma'!AK19,'Pro-Forma'!AL19) -> 26.778553 | AN19: =note_a_principal_usd/'Pro-Forma'!AM19 -> 186716.59 | AO19: =note_b_cap_usd/(pre_f_fd_total+'Pro-Forma'!S19+'Pro-Forma'!AJ19+'Pro-Forma'!T19) -> 42.739338 | AP19: ='Pro-Forma'!V19*(const_one-note_b_discount) -> 31.984223 | AQ19: =MIN('Pro-Forma'!AO19,'Pro-Forma'!AP19) -> 31.984223 | AR19: =note_b_principal_usd/'Pro-Forma'!AQ19 -> 93796.243 | AS19: =pre_f_fd_total+'Pro-Forma'!S19+'Pro-Forma'!W19+'Pro-Forma'!AN19+'Pro-Forma'!AR19+'Pro-Forma'!AJ19 -> 38327302 | AT19: =MAX(const_zero,esop_refresh_target_post_f*'Pro-Forma'!AS19-pre_f_option_pool_total) -> 587882.23
